Workbook
Name _1_: '[131]#REF'!#REF!
Name _2_: '[131]#REF'!#REF!
Name _3_: '[131]#REF'!#REF!
Name _4_: '[131]#REF'!#REF!
Name _5_0: #REF!
Name _6_0: #REF!
Name _7_?: #REF!
Name _8_?: #REF!
Name _9_?쨲?f: #REF!
Name _10_?춑_TOTAL: [54]major!#REF!
Name _11_?춑_TOTAL: [54]major!#REF!
Name _12_?춮t2: [10]현금경비중역!#REF!
Name _13_?춮t2: [10]현금경비중역!#REF!
Name _14_?춮ta: [10]현금경비중역!#REF!
Name _15_?춮ta: [10]현금경비중역!#REF!
Name _16_?춮tb: [10]현금경비중역!#REF!
Name _17_?춮tb: [10]현금경비중역!#REF!
Name _: #REF!
Name _1: #REF!
Name _2: #REF!
Name ¤·¤≪¤¤¤·¤≪¤¤: #REF!
Name ¤·¤≪¤¤¤·¤≪¤¤: #REF!
Name ±a¾E°ⓒ: #REF!
Name ±a¾E°ⓒ: #REF!
Name ±a¾EA≫: #REF!
Name ±a¾EA≫: #REF!
Name √: "SQRT"
Name ※_추후_NAVA__PROJECT는__부품_: [11]기안!$A$43
Name _18_0: '[129]#REF'!#REF!
Name _19_0: '[129]#REF'!#REF!
Name _20_0: [141]●목차!#REF!
Name _21_0: [141]●목차!#REF!
Name _22_0: '[115]2.대외공문'!#REF!
Name _23_0: '[115]2.대외공문'!#REF!
Name _24_0_0: [85]표지!#REF!
Name _25_0_0: [85]표지!#REF!
Name _26_01: '[129]#REF'!#REF!
Name _27_01: '[129]#REF'!#REF!
Name _28_02: '[129]#REF'!#REF!
Name _29_02: '[129]#REF'!#REF!
Name _30_03: '[129]#REF'!#REF!
Name _31_03: '[129]#REF'!#REF!
Name _32_04: '[129]#REF'!#REF!
Name _33_04: '[129]#REF'!#REF!
Name _34_05: '[129]#REF'!#REF!
Name _35_05: '[129]#REF'!#REF!
Name _36_06: '[129]#REF'!#REF!
Name _37_06: '[129]#REF'!#REF!
Name _38_0Crite: [142]●목차!#REF!
Name _39_0Crite: [142]●목차!#REF!
Name _40_0Extr: [142]●목차!#REF!
Name _41_0Extr: [142]●목차!#REF!
Name _42_0ㅁ: [142]●현황!#REF!
Name _43_0ㅁ: [142]●현황!#REF!
Name _44_0엉댜: '[127]#REF'!#REF!
Name _45_0엉댜: '[127]#REF'!#REF!
Name _46_0투: '[127]#REF'!#REF!
Name _47_0투: '[127]#REF'!#REF!
Name A: [10]현금경비중역!#REF!
Name A: [10]현금경비중역!#REF!

Sheet 갑지
B1: (현대/기아차 설비협력업체 견적통일양식)
B2: 見 積 書
B4: 현대위아(주) 貴下
B5: 견적일자 | D5: 46066 | G5: 업체명 : 코리아 고꾸사이㈜
B6: 견적번호 | D6: KS-225151-2 | G6: 대표이사 : 마쯔모토 시게루
B7: 납기 | C7: 입하 | D7: 46341 | G7: 주소 : 대구광역시 달서구 호림동 5-6번지
C8: 최종검수 | D8: 협의 | G8: 전화 : 053-584-9955
B9: 견적유효기간 | D9: 제출후 1개월 | G9: FAX : 053-588-9955
B10: 인도장소 | D10: PUNE PORT(FOB) | G10: 견적 담당자 : 백종엽 차장
B11: 지불조건 | D11: 귀사정기결재조건 | G11: 연락처 : 010-2520-3186
B13: 공 사 명: | D13: 현대위아(INDIA PUNE) CVJ DRIVE SHAFT 교정기(1대분) 신작
B14: 견적금액: | D14: ="一金 "&NUMBERSTRING(H33*1000,1)&"원整" -> 一金 삼억삼천오백만원整 | G14: =ROUND(H33*1000,-3) -> 335000000
B16: 번호 | C16: 상세품목내역 | E16: 견적금액 (천원) | I16: 비 고
E17: 기계부문 | F17: 전기부문 | G17: 관리/이윤 (안전관리비포함) | H17: 합 계
B18: 1 | C18: =IF('단위장비별(집계)2'!N7>0,'단위장비별(집계)2'!B7,"") -> BASE PART | E18: =IF('단위장비별(집계)2'!N7>1,('단위장비별(집계)2'!D7+'단위장비별(집계)2'!E7+'단위장비별(집계)2'!F7+'단위장비별(집계)2'!G7+'단위장비별(집계)2'!H7+'단위장비별(집계)2'!I7)/1000," ") -> 28678.02 | F18: =IF('단위장비별(집계)2'!N7>0,'단위장비별(집계)2'!K22/1000,"") -> 133557.44 | G18: =IF('단위장비별(집계)2'!N7>0,('단위장비별(집계)2'!L7+'단위장비별(집계)2'!M7)/1000,"") -> 773.43795 | H18: =IF('단위장비별(집계)2'!N7>0,'단위장비별(집계)2'!N7/1000,"") -> 48977.887
B19: 2 | C19: =IF('단위장비별(집계)2'!N8>0,'단위장비별(집계)2'!B8,"") -> TRANSFER PART | E19: =IF('단위장비별(집계)2'!N8>1,('단위장비별(집계)2'!D8+'단위장비별(집계)2'!E8+'단위장비별(집계)2'!F8+'단위장비별(집계)2'!G8+'단위장비별(집계)2'!H8+'단위장비별(집계)2'!I8)/1000," ") -> 29231.328 | G19: =IF('단위장비별(집계)2'!N8>0,('단위장비별(집계)2'!L8+'단위장비별(집계)2'!M8)/1000,"") -> 4288.5207 | H19: =IF('단위장비별(집계)2'!N8>0,'단위장비별(집계)2'!N8/1000,"") -> 55743.636
B20: 3 | C20: =IF('단위장비별(집계)2'!N9>0,'단위장비별(집계)2'!B9,"") -> JIG PART | E20: =IF('단위장비별(집계)2'!N9>1,('단위장비별(집계)2'!D9+'단위장비별(집계)2'!E9+'단위장비별(집계)2'!F9+'단위장비별(집계)2'!G9+'단위장비별(집계)2'!H9+'단위장비별(집계)2'!I9)/1000," ") -> 17477.34 | G20: =IF('단위장비별(집계)2'!N9>0,('단위장비별(집계)2'!L9+'단위장비별(집계)2'!M9)/1000,"") -> 2564.0962 | H20: =IF('단위장비별(집계)2'!N9>0,'단위장비별(집계)2'!N9/1000,"") -> 33328.985
B21: 4 | C21: ='단위장비별(집계)2'!B10 -> 0 | E21: =IF('단위장비별(집계)2'!N10>1,('단위장비별(집계)2'!D10+'단위장비별(집계)2'!E10+'단위장비별(집계)2'!F10+'단위장비별(집계)2'!G10+'단위장비별(집계)2'!H10+'단위장비별(집계)2'!I10)/1000," ") | G21: =IF('단위장비별(집계)2'!N10>0,('단위장비별(집계)2'!L10+'단위장비별(집계)2'!M10)/1000,"") | H21: =IF('단위장비별(집계)2'!N10>0,'단위장비별(집계)2'!N10/1000,"")
B22: 5 | C22: ='단위장비별(집계)2'!B11 -> MEASURING PART | E22: =IF('단위장비별(집계)2'!N11>1,('단위장비별(집계)2'!D11+'단위장비별(집계)2'!E11+'단위장비별(집계)2'!F11+'단위장비별(집계)2'!G11+'단위장비별(집계)2'!H11+'단위장비별(집계)2'!I11)/1000," ") -> 45953.317 | G22: =IF('단위장비별(집계)2'!N11>0,('단위장비별(집계)2'!L11+'단위장비별(집계)2'!M11)/1000,"") -> 6741.7996 | H22: =IF('단위장비별(집계)2'!N11>0,'단위장비별(집계)2'!N11/1000,"") -> 87632.18
B23: 6 | C23: ='단위장비별(집계)2'!B12 -> RAM PART | E23: =IF('단위장비별(집계)2'!N12>1,('단위장비별(집계)2'!D12+'단위장비별(집계)2'!E12+'단위장비별(집계)2'!F12+'단위장비별(집계)2'!G12+'단위장비별(집계)2'!H12+'단위장비별(집계)2'!I12)/1000," ") -> 39791.425 | G23: =IF('단위장비별(집계)2'!N12>0,('단위장비별(집계)2'!L12+'단위장비별(집계)2'!M12)/1000,"") -> 5837.7899 | H23: =IF('단위장비별(집계)2'!N12>0,'단위장비별(집계)2'!N12/1000,"") -> 75881.558
B24: 7 | C24: ='단위장비별(집계)2'!B13 -> MASTER/NG PART | E24: =IF('단위장비별(집계)2'!N13>1,('단위장비별(집계)2'!D13+'단위장비별(집계)2'!E13+'단위장비별(집계)2'!F13+'단위장비별(집계)2'!G13+'단위장비별(집계)2'!H13+'단위장비별(집계)2'!I13)/1000," ") -> 7689.2428 | G24: =IF('단위장비별(집계)2'!N13>0,('단위장비별(집계)2'!L13+'단위장비별(집계)2'!M13)/1000,"") -> 1128.0869 | H24: =IF('단위장비별(집계)2'!N13>0,'단위장비별(집계)2'!N13/1000,"") -> 14663.253
B25: 8 | C25: ='단위장비별(집계)2'!B14 -> DOOR&COVER PART | E25: =IF('단위장비별(집계)2'!N14>1,('단위장비별(집계)2'!D14+'단위장비별(집계)2'!E14+'단위장비별(집계)2'!F14+'단위장비별(집계)2'!G14+'단위장비별(집계)2'!H14+'단위장비별(집계)2'!I14)/1000," ") -> 4712.7939 | G25: =IF('단위장비별(집계)2'!N14>0,('단위장비별(집계)2'!L14+'단위장비별(집계)2'!M14)/1000,"") -> 691.41279 | H25: =IF('단위장비별(집계)2'!N14>0,'단위장비별(집계)2'!N14/1000,"") -> 8987.2162
B26: 9 | C26: ='단위장비별(집계)2'!B15 -> AIR CIRCUIT PART | E26: =IF('단위장비별(집계)2'!N15>1,('단위장비별(집계)2'!D15+'단위장비별(집계)2'!E15+'단위장비별(집계)2'!F15+'단위장비별(집계)2'!G15+'단위장비별(집계)2'!H15+'단위장비별(집계)2'!I15)/1000," ") -> 5131.4871 | G26: =IF('단위장비별(집계)2'!N15>0,('단위장비별(집계)2'!L15+'단위장비별(집계)2'!M15)/1000,"") -> 752.83917 | H26: =IF('단위장비별(집계)2'!N15>0,'단위장비별(집계)2'!N15/1000,"") -> 9785.657
B27: 10 | C27: ='단위장비별(집계)2'!B16 -> 0 | E27: =IF('단위장비별(집계)2'!N16>1,('단위장비별(집계)2'!D16+'단위장비별(집계)2'!E16+'단위장비별(집계)2'!F16+'단위장비별(집계)2'!G16+'단위장비별(집계)2'!H16+'단위장비별(집계)2'!I16)/1000," ") | G27: =IF('단위장비별(집계)2'!N16>0,('단위장비별(집계)2'!L16+'단위장비별(집계)2'!M16)/1000,"") | H27: =IF('단위장비별(집계)2'!N16>0,'단위장비별(집계)2'!N16/1000,"")
B28: 11 | C28: ='단위장비별(집계)2'!B17 -> 0 | E28: =IF('단위장비별(집계)2'!N17>1,('단위장비별(집계)2'!D17+'단위장비별(집계)2'!E17+'단위장비별(집계)2'!F17+'단위장비별(집계)2'!G17+'단위장비별(집계)2'!H17+'단위장비별(집계)2'!I17)/1000," ") | G28: =IF('단위장비별(집계)2'!N17>0,('단위장비별(집계)2'!L17+'단위장비별(집계)2'!M17)/1000,"") | H28: =IF('단위장비별(집계)2'!N17>0,'단위장비별(집계)2'!N17/1000,"")
B29: 12 | C29: ='단위장비별(집계)2'!B18 -> 0 | E29: =IF('단위장비별(집계)2'!N18>1,('단위장비별(집계)2'!D18+'단위장비별(집계)2'!E18+'단위장비별(집계)2'!F18+'단위장비별(집계)2'!G18+'단위장비별(집계)2'!H18+'단위장비별(집계)2'!I18)/1000," ") | G29: =IF('단위장비별(집계)2'!N18>0,('단위장비별(집계)2'!L18+'단위장비별(집계)2'!M18)/1000,"") | H29: =IF('단위장비별(집계)2'!N18>0,'단위장비별(집계)2'!N18/1000,"")
B30: 13 | C30: ='단위장비별(집계)2'!B19 -> 0 | E30: =IF('단위장비별(집계)2'!N19>1,('단위장비별(집계)2'!D19+'단위장비별(집계)2'!E19+'단위장비별(집계)2'!F19+'단위장비별(집계)2'!G19+'단위장비별(집계)2'!H19+'단위장비별(집계)2'!I19)/1000," ") | G30: =IF('단위장비별(집계)2'!N19>0,('단위장비별(집계)2'!L19+'단위장비별(집계)2'!M19)/1000,"") | H30: =IF('단위장비별(집계)2'!N19>0,'단위장비별(집계)2'!N19/1000,"")
B31: 14 | C31: ='단위장비별(집계)2'!B20 -> 0 | E31: =IF('단위장비별(집계)2'!N20>1,('단위장비별(집계)2'!D20+'단위장비별(집계)2'!E20+'단위장비별(집계)2'!F20+'단위장비별(집계)2'!G20+'단위장비별(집계)2'!H20+'단위장비별(집계)2'!I20)/1000," ") | G31: =IF('단위장비별(집계)2'!N20>0,('단위장비별(집계)2'!L20+'단위장비별(집계)2'!M20)/1000,"") | H31: =IF('단위장비별(집계)2'!N20>0,'단위장비별(집계)2'!N20/1000,"")
B32: 15 | E32: =IF('단위장비별(집계)2'!N21>1,('단위장비별(집계)2'!D21+'단위장비별(집계)2'!E21+'단위장비별(집계)2'!F21+'단위장비별(집계)2'!G21+'단위장비별(집계)2'!H21+'단위장비별(집계)2'!I21)/1000," ") | G32: =IF('단위장비별(집계)2'!N21>0,('단위장비별(집계)2'!L21+'단위장비별(집계)2'!M21)/1000,"") | H32: =IF('단위장비별(집계)2'!N21>0,'단위장비별(집계)2'!N21/1000,"")
B33: 견적 합계 | E33: =SUM(E18:E29) -> 178664.95 | F33: =SUM(F18:F29) -> 133557.44 | G33: =SUM(G18:G29) -> 22777.983 | H33: =ROUND(SUM(H18:H32),0) -> 335000
F35: 공개입찰가 (견적時 공란)
B37: 특기사항 | C37: 1. VAT 제외 | F37: 외주계획 업체명 (자작時 공란)
C38: 2. 기본 유틸리티공사 제외 | F38: 설계외주
C39: 3. QASS CRACK UNIT 추가 | F39: 제작외주
F40: 전기외주
F41: 설치외주

Sheet 원가항목별(집계)1
B2: 1. 원가항목별 견적가 종합(상세견적 첨부)
B6: 순번 | C6: 원가구분 | F6: 단위 | G6: 수량 | H6: 단가 | I6: 금 액(원) | J6: 비 고
B7: 1 | C7: 기계 부문 | D7: 자재비 | E7: 철자재(SS.SUS등) | F7: kg | G7: =단위장비1!F8+단위장비2!F13+단위장비3!F6+단위장비4!F8+단위장비5!F88+단위장비6!F8+단위장비7!F15+단위장비8!F28+단위장비9!F20+단위장비10!F15+단위장비11!F28+단위장비12!F23+단위장비13!F14+단위장비14!F14+단위장비15!F8 -> 121 | I7: =단위장비1!H14+단위장비2!H13+단위장비3!H6+단위장비4!H8+단위장비5!H10+단위장비6!H11+단위장비7!H15+단위장비8!H28+단위장비9!H20+단위장비10!H15+단위장비11!H28+단위장비12!H23+단위장비13!H14+단위장비14!H14+단위장비15!H8 -> 2096000 | J7: 加工必要資材
E8: 일반구매품 | F8: 식 | G8: 1 | I8: =단위장비1!H104+단위장비2!H107+단위장비3!H97+단위장비4!H37+단위장비5!H137+단위장비6!H33+단위장비7!H41+단위장비8!H52+단위장비9!H51+단위장비10!H52+단위장비11!H53+단위장비12!H48+단위장비13!H34+단위장비14!H33+단위장비15!H24 -> 66866354 | J8: 加工不要資材
E9: 외주제작품 | F9: 식 | G9: 1 | I9: =단위장비1!H200+단위장비2!H229+단위장비3!H255+단위장비4!H61+단위장비5!H326+단위장비6!H71+단위장비7!H78+단위장비8!H104+단위장비9!H67+단위장비10!H139+단위장비11!H61+단위장비12!H56+단위장비13!H42+단위장비14!H45+단위장비15!H59 -> 75802600 | J9: 旣加工SUB資材
E10: 설치/해체 공사 자재 | F10: 식 | G10: 1 | I10: =[151]단위장비1!H10 -> 0 | J10: 시운전 자재 포함
E11: 소계 | I11: =SUM(I7:I9) -> 144764954
D12: 노무비 | E12: 기존설비 철거 | F12: M/D | G12: =단위장비1!F202+단위장비2!F231+단위장비3!F257+단위장비4!F63+단위장비5!F328+단위장비6!F73+단위장비7!F80+단위장비8!F106+단위장비9!F69+단위장비10!F141+단위장비11!F63+단위장비12!F58+단위장비13!F44+단위장비14!F47+단위장비15!F61 -> 0 | H12: =IF(단위장비1!G202>0,단위장비1!G202,"") | I12: =SUM(단위장비1!H202+단위장비2!H231+단위장비3!H257+단위장비4!H63+단위장비5!H328+단위장비6!H73+단위장비7!H80+단위장비8!H106+단위장비9!H69+단위장비10!H141+단위장비11!H63+단위장비12!H58+단위장비13!H44)+단위장비14!H47+단위장비15!H61 -> 0
E13: 설계 | F13: M/D | G13: =단위장비1!F203+단위장비2!F232+단위장비3!F258+단위장비4!F64+단위장비5!F329+단위장비6!F74+단위장비7!F81+단위장비8!F107+단위장비9!F70+단위장비10!F142+단위장비11!F64+단위장비12!F59+단위장비13!F45+단위장비14!F48+단위장비15!F62 -> 11 | H13: =IF(단위장비1!G203>0,단위장비1!G203,"") -> 350000 | I13: =단위장비1!H203+단위장비2!H232+단위장비3!H258+단위장비4!H64+단위장비5!H329+단위장비6!H74+단위장비7!H81+단위장비8!H107+단위장비9!H70+단위장비10!H142+단위장비11!H64+단위장비12!H59+단위장비13!H45+단위장비14!H48+단위장비15!H62 -> 3850000
E14: 제작(제관,가공) | F14: M/D | G14: =단위장비1!F204+단위장비2!F233+단위장비3!F259+단위장비4!F65+단위장비5!F330+단위장비7!F82+단위장비8!F108+단위장비9!F71+단위장비10!F143+단위장비11!F65+단위장비12!F60+단위장비13!F46+단위장비14!F49+단위장비15!F63 -> 24 | H14: =IF(단위장비1!G204>0,단위장비1!G204,"") -> 350000 | I14: =단위장비1!H204+단위장비2!H233+단위장비3!H259+단위장비4!H65+단위장비5!H330+단위장비6!H75+단위장비7!H82+단위장비8!H108+단위장비9!H71+단위장비10!H143+단위장비11!H65+단위장비12!H60+단위장비13!H46+단위장비14!H49+단위장비15!H63 -> 9800000
E15: 조립 | F15: M/D | G15: =단위장비1!F205+단위장비2!F234+단위장비3!F260+단위장비4!F66+단위장비5!F331+단위장비7!F83+단위장비8!F109+단위장비9!F72+단위장비10!F144+단위장비11!F66+단위장비12!F61+단위장비13!F47+단위장비14!F49+단위장비15!F64 -> 11 | H15: =IF(단위장비1!G205>0,단위장비1!G205,"") -> 350000 | I15: =단위장비1!H205+단위장비2!H234+단위장비3!H260+단위장비4!H66+단위장비5!H331+단위장비6!H76+단위장비7!H83+단위장비8!H109+단위장비9!H72+단위장비10!H144+단위장비11!H66+단위장비12!H61+단위장비13!H47+단위장비14!H50+단위장비15!H64 -> 4550000
E16: 설치 | F16: M/D | G16: =단위장비1!F206+단위장비2!F235+단위장비3!F261+단위장비4!F67+단위장비5!F332+단위장비6!F77+단위장비7!F84+단위장비8!F110+단위장비9!F73+단위장비10!F145+단위장비11!F67+단위장비12!F62+단위장비13!F48+단위장비14!F51+단위장비15!F65 -> 9 | H16: =IF(단위장비1!G206>0,단위장비1!G206,"") -> 350000 | I16: =단위장비1!H206+단위장비2!H235+단위장비3!H261+단위장비4!H67+단위장비5!H332+단위장비6!H77+단위장비7!H84+단위장비8!H110+단위장비9!H73+단위장비10!H145+단위장비11!H67+단위장비12!H62+단위장비13!H48+단위장비14!H51+단위장비15!H65 -> 3150000
E17: 시운전 | F17: M/D | G17: =단위장비1!F207+단위장비2!F236+단위장비3!F262+단위장비4!F68+단위장비5!F333+단위장비6!F78+단위장비7!F85+단위장비8!F111+단위장비9!F74+단위장비10!F146+단위장비11!F68+단위장비12!F63+단위장비13!F49+단위장비14!F52+단위장비15!F66 -> 4 | H17: =IF(단위장비1!G207>0,단위장비1!G207,"") -> 350000 | I17: =단위장비1!H207+단위장비2!H236+단위장비3!H262+단위장비4!H68+단위장비5!H333+단위장비6!H78+단위장비7!H85+단위장비8!H111+단위장비9!H74+단위장비10!H146+단위장비11!H68+단위장비12!H63+단위장비13!H49+단위장비14!H52+단위장비15!H66 -> 1400000
E18: 양산대응 | F18: M/D | G18: =단위장비1!F208+단위장비2!F237+단위장비3!F263+단위장비4!F69+단위장비5!F334+단위장비6!F79+단위장비7!F86+단위장비8!F112+단위장비9!F75+단위장비10!F147+단위장비11!F69+단위장비12!F64+단위장비13!F50+단위장비14!F53+단위장비15!F67 -> 0 | H18: =IF(단위장비1!G208>0,단위장비1!G208,"") -> 350000 | I18: =단위장비1!H208+단위장비2!H237+단위장비3!H263+단위장비4!H69+단위장비5!H334+단위장비6!H79+단위장비7!H86+단위장비8!H112+단위장비9!H75+단위장비10!H147+단위장비11!H69+단위장비12!H64+단위장비13!H50+단위장비14!H53+단위장비15!H67 -> 0
E19: 도장 | F19: M/D | G19: =단위장비1!F209+단위장비2!F238+단위장비3!F264+단위장비4!F70+단위장비5!F335+단위장비6!F80+단위장비7!F87+단위장비8!F113+단위장비9!F76+단위장비10!F148+단위장비11!F70+단위장비12!F65+단위장비13!F51+단위장비14!F54+단위장비15!F68 -> 9 | H19: =IF(단위장비1!G209>0,단위장비1!G209,"") -> 350000 | I19: =단위장비1!H209+단위장비2!H238+단위장비3!H264+단위장비4!H70+단위장비5!H335+단위장비6!H80+단위장비7!H87+단위장비8!H113+단위장비9!H76+단위장비10!H148+단위장비11!H70+단위장비12!H65+단위장비13!H51+단위장비14!H54+단위장비15!H68 -> 3150000
E20: 소계 | I20: =SUM(I12:I19) -> 25900000
D21: 일반관리 및 이윤 | I21: =단위장비1!H212+단위장비1!H213+단위장비2!H241+단위장비2!H242+단위장비3!H267+단위장비3!H268+단위장비4!H73+단위장비4!H74+단위장비5!H338+단위장비5!H339+단위장비6!H83+단위장비6!H84+단위장비7!H90+단위장비7!H91+단위장비8!H116+단위장비8!H117+단위장비9!H79+단위장비9!H80+단위장비10!H151+단위장비10!H152+단위장비11!H73+단위장비11!H74+단위장비12!H68+단위장비12!H69+단위장비13!H54+단위장비13!H55+단위장비14!H57+단위장비14!H58+단위장비15!H71+단위장비15!H72 -> 22155983
E22: 기계 소계 | I22: =I20+I11+I21 -> 1.9282094e+08
B23: 2 | C23: 전기 부문 | D23: 자재비 | E23: 기계/전기자재 | F23: 식 | G23: 1 | I23: =전기!H152 -> 83586900
E24: 설치/해체 공사 자재 | F24: 식 | G24: 1 | I24: =[151]단위장비1!H24 -> 0
D25: 노무비 | E25: 철거(개조시) | F25: M/D | G25: =전기!F153 -> 0 | H25: =IF(전기!G153>0,전기!G153,"") | I25: =전기!H153 -> 0
E26: 설계,프로그램 | F26: M/D | G26: =전기!F154 -> 7 | H26: =IF(전기!G154>0,전기!G154,"") -> 350000 | I26: =전기!H154 -> 2450000
E27: 제작 | F27: M/D | G27: =전기!F155 -> 7 | H27: =IF(전기!G155>0,전기!G155,"") -> 350000 | I27: =전기!H155 -> 2450000
E28: 조립 | F28: M/D | G28: =전기!F156 -> 7 | H28: =IF(전기!G156>0,전기!G156,"") -> 350000 | I28: =전기!H156 -> 2450000
E29: 설치 | F29: M/D | G29: =전기!F157 -> 7 | H29: =IF(전기!G157>0,전기!G157,"") -> 350000 | I29: =전기!H157 -> 2450000
E30: 시운전 | F30: M/D | G30: =전기!F158 -> 15 | H30: =IF(전기!G158>0,전기!G158,"") -> 650000 | I30: =전기!H158 -> 9750000
E31: 양산대응 | F31: M/D | G31: =전기!F159 -> 20 | H31: =IF(전기!G159>0,전기!G159,"") -> 650000 | I31: =전기!H159 -> 13000000
E32: 소계 | I32: =SUM(I25:I31) -> 32550000
D33: 일반관리 및 이윤 | I33: =전기!H162+전기!H163 -> 17420535
E34: 전기 소계 | I34: =I32+I23+I33 -> 133557435
B35: 3 | C35: 자재비 합계 | I35: =I23+I11 -> 228351854
C36: 노무비 합계 | I36: =I32+I20 -> 58450000
C37: 중간 합계 | I37: =I36+I35 -> 286801854
B38: 4 | C38: 포장,운송 및 중장비 사용료 | I38: 8000000
B39: 5 | C39: 표준안전관리비 | F39: 설치/철거/수리금액 기준 | I39: =CEILING(MIN(I48:I49),1000) -> 622000 | J39: =I30+I29+I25+I24+I17+I16+I12+I10 -> 16750000
B40: 6 | C40: 일반관리비 | I40: =전기!H162+단위장비1!H212+단위장비2!H241+단위장비3!H267+단위장비4!H73+단위장비5!H338+단위장비6!H83+단위장비7!H90+단위장비8!H116+단위장비9!H79+단위장비10!H151+단위장비11!H73+단위장비12!H68+단위장비13!H54+단위장비14!H57+단위장비15!H71 -> 13192173
B41: 7 | C41: 이 윤 | I41: =전기!H163+단위장비1!H213+단위장비2!H242+단위장비3!H268+단위장비4!H74+단위장비5!H339+단위장비6!H84+단위장비7!H91+단위장비8!H117+단위장비9!H80+단위장비10!H152+단위장비11!H74+단위장비12!H69+단위장비13!H55+단위장비14!H58+단위장비15!H72 -> 26384345
C42: 합 계 | F42: 3~7항 합계 | I42: =I22+I34+I38+I39 -> 3.3500037e+08
B43: 주1. 표준안전관리비:(재료비+직접노무비)의 ⓐ2.66%,ⓑ1.95%+기초액,ⓒ2.02%(50억 이상일경우)
B44: 주2. 제작을 전량 외주할경우 자재비중 [외주제작품] 항목은 삭제함
...

Sheet 단위장비별(집계)2
A2: 2. 단위장비별 견적가 종합(상세견적 첨부)
N3: 단위:원
I5: 포장/운송 | L5: 표준안전 | M5: 일반관리비
A6: 순번 | B6: 단위장비명 | C6: 수량 | D6: 자재비 | E6: 철거 | F6: 제작 | G6: 설치/시운전 | H6: 양산대응 | I6: 중장비사용 | J6: 기계소계 | K6: 전기소계 | L6: 관리비 | M6: 이윤(기계) | N6: 합 계 | O6: 비 고
A7: =IF(B7>0,1,"") -> 1 | B7: =단위장비1!C$1 -> BASE PART | C7: 2식 | D7: =단위장비1!H201 -> 22958400 | E7: =단위장비1!H202 -> 0 | F7: =단위장비1!H203+단위장비1!H204+단위장비1!H205+단위장비1!H209 -> 3850000 | G7: =단위장비1!H206+단위장비1!H207 -> 700000 | H7: =단위장비1!H208 -> 0 | I7: =IF($B7>0,'원가항목별(집계)1'!I$38*$P7/$P$22,0) -> 1169619.9 | J7: =SUM(D7:I7) -> 28678020 | K7: =IF(B7>0,'원가항목별(집계)1'!I$34*P7/P$22,0) -> 19526429 | L7: =IF($B7>0,'원가항목별(집계)1'!I$39*$P7/$P$22,0) -> 90937.945 | M7: =단위장비1!H212+단위장비1!H213 -> 682500 | N7: =SUM(J7:M7) -> 48977887 | P7: =D7+E7+F7+G7+H7+M7 -> 28190900
A8: =IF(B8>0,A7+1,"") -> 2 | B8: =단위장비2!C$1 -> TRANSFER PART | C8: 2식 | D8: =단위장비2!H230 -> 25100138 | E8: =단위장비2!H231 -> 0 | F8: =단위장비2!H232+단위장비2!H233+단위장비2!H234+단위장비2!H238 -> 2100000 | G8: =단위장비2!H235+단위장비2!H236 -> 700000 | H8: =단위장비2!H237 -> 0 | I8: =IF($B8>0,'원가항목별(집계)1'!I$38*$P8/$P$22,0) -> 1331189.8 | J8: =SUM(D8:I8) -> 29231328 | K8: =IF(B8>0,'원가항목별(집계)1'!I$34*P8/P$22,0) -> 22223787 | L8: =IF($B8>0,'원가항목별(집계)1'!I$39*$P8/$P$22,0) -> 103500.01 | M8: =단위장비2!H241+단위장비2!H242 -> 4185020.7 | N8: =SUM(J8:M8) -> 55743636 | P8: =D8+E8+F8+G8+H8+M8 -> 32085159
A9: =IF(B9>0,A8+1,"") -> 3 | B9: =단위장비3!C$1 -> JIG PART | C9: 2식 | D9: =단위장비3!H256 -> 13531425 | E9: =단위장비3!H257 -> 0 | F9: =단위장비3!H258+단위장비3!H259+단위장비3!H260+단위장비3!H264 -> 2450000 | G9: =단위장비3!H261+단위장비3!H262 -> 700000 | H9: =단위장비3!H263 -> 0 | I9: =IF($B9>0,'원가항목별(집계)1'!I$38*$P9/$P$22,0) -> 795915.18 | J9: =SUM(D9:I9) -> 17477340 | K9: =IF(B9>0,'원가항목별(집계)1'!I$34*P9/P$22,0) -> 13287549 | L9: =IF($B9>0,'원가항목별(집계)1'!I$39*$P9/$P$22,0) -> 61882.405 | M9: =단위장비3!H267+단위장비3!H268 -> 2502213.8 | N9: =SUM(J9:M9) -> 33328985 | P9: =D9+E9+F9+G9+H9+M9 -> 19183639
A10: 4 | B10: =단위장비4!C1 -> 0 | C10: 2식 | D10: =단위장비4!H62 -> 0 | E10: =단위장비4!H63 -> 0 | F10: =단위장비4!H64+단위장비4!H65+단위장비4!H66+단위장비4!H70 -> 0 | G10: =단위장비4!H67+단위장비4!H68 -> 0 | H10: =단위장비4!H69 -> 0 | I10: =IF($B10>0,'원가항목별(집계)1'!I$38*$P10/$P$22,0) -> 0 | J10: =SUM(D10:I10) -> 0 | K10: =IF(B10>0,'원가항목별(집계)1'!I$34*P10/P$22,0) -> 0 | L10: =IF($B10>0,'원가항목별(집계)1'!I$39*$P10/$P$22,0) -> 0 | M10: =단위장비4!H73+단위장비4!H74 -> 0 | N10: =SUM(J10:M10) -> 0 | P10: =D10+E10+F10+G10+H10+M10 -> 0
A11: =IF(B11>0,A10+1,"") -> 5 | B11: =단위장비5!C$1 -> MEASURING PART | C11: 4식 | D11: =단위장비5!H327 -> 38610611 | E11: =단위장비5!H328 -> 0 | F11: =단위장비5!H329+단위장비5!H330+단위장비5!H331+단위장비5!H335 -> 4200000 | G11: =단위장비5!H332+단위장비5!H333 -> 1050000 | H11: =단위장비5!H334 -> 0 | I11: =IF($B11>0,'원가항목별(집계)1'!I$38*$P11/$P$22,0) -> 2092706.5 | J11: =SUM(D11:I11) -> 45953317 | K11: =IF(B11>0,'원가항목별(집계)1'!I$34*P11/P$22,0) -> 34937063 | L11: =IF($B11>0,'원가항목별(집계)1'!I$39*$P11/$P$22,0) -> 162707.93 | M11: =단위장비5!H338+단위장비5!H339 -> 6579091.7 | N11: =SUM(J11:M11) -> 87632180 | P11: =D11+E11+F11+G11+H11+M11 -> 50439703
A12: =IF(B12>0,A11+1,"") -> 6 | B12: =단위장비6!C$1 -> RAM PART | C12: 4식 | D12: =단위장비6!H72 -> 33779330 | E12: =단위장비6!H73 -> 0 | F12: =단위장비6!H74+단위장비6!H75+단위장비6!H76+단위장비6!H80 -> 3500000 | G12: =단위장비6!H77+단위장비6!H78 -> 700000 | H12: =단위장비6!H79 -> 0 | I12: =IF($B12>0,'원가항목별(집계)1'!I$38*$P12/$P$22,0) -> 1812094.9 | J12: =SUM(D12:I12) -> 39791425 | K12: =IF(B12>0,'원가항목별(집계)1'!I$34*P12/P$22,0) -> 30252343 | L12: =IF($B12>0,'원가항목별(집계)1'!I$39*$P12/$P$22,0) -> 140890.38 | M12: =단위장비6!H83+단위장비6!H84 -> 5696899.5 | N12: =SUM(J12:M12) -> 75881558 | P12: =D12+E12+F12+G12+H12+M12 -> 43676230
A13: =IF(B13>0,A12+1,"") -> 7 | B13: =단위장비7!C$1 -> MASTER/NG PART | C13: 2식 | D13: =단위장비7!H79 -> 5239076 | E13: =단위장비7!H80 -> 0 | F13: =단위장비7!H81+단위장비7!H82+단위장비7!H83+단위장비7!H87 -> 2100000 | G13: =단위장비7!H84+단위장비7!H85 -> 0 | H13: =단위장비7!H86 -> 0 | I13: =IF($B13>0,'원가항목별(집계)1'!I$38*$P13/$P$22,0) -> 350166.85 | J13: =SUM(D13:I13) -> 7689242.8 | K13: =IF(B13>0,'원가항목별(집계)1'!I$34*P13/P$22,0) -> 5845923.2 | L13: =IF($B13>0,'원가항목별(집계)1'!I$39*$P13/$P$22,0) -> 27225.472 | M13: =단위장비7!H90+단위장비7!H91 -> 1100861.4 | N13: =SUM(J13:M13) -> 14663253 | P13: =D13+E13+F13+G13+H13+M13 -> 8439937.4
A14: =IF(B14>0,A13+1,"") -> 8 | B14: =단위장비8!C$1 -> DOOR&COVER PART | C14: 1식 | D14: =단위장비8!H105 -> 2748174 | E14: =단위장비8!H106 -> 0 | F14: =단위장비8!H107+단위장비8!H108+단위장비8!H109 -> 1400000 | G14: =단위장비8!H110+단위장비8!H111 -> 350000 | H14: =단위장비8!H112 -> 0 | I14: =IF($B14>0,'원가항목별(집계)1'!I$38*$P14/$P$22,0) -> 214619.85 | J14: =SUM(D14:I14) -> 4712793.9 | K14: =IF(B14>0,'원가항목별(집계)1'!I$34*P14/P$22,0) -> 3583009.6 | L14: =IF($B14>0,'원가항목별(집계)1'!I$39*$P14/$P$22,0) -> 16686.693 | M14: =단위장비8!H116+단위장비8!H117 -> 674726.1 | N14: =SUM(J14:M14) -> 8987216.2 | P14: =D14+E14+F14+G14+H14+M14 -> 5172900.1
A15: =IF(B15>0,A14+1,"") -> 9 | B15: =단위장비9!C$1 -> AIR CIRCUIT PART | C15: 2식 | D15: =단위장비9!H68 -> 2797800 | E15: =단위장비9!H69 -> 0 | F15: =단위장비9!H70+단위장비9!H71+단위장비9!H72+단위장비9!H76 -> 1750000 | G15: =단위장비9!H73+단위장비9!H74 -> 350000 | H15: =단위장비9!H75 -> 0 | I15: =IF($B15>0,'원가항목별(집계)1'!I$38*$P15/$P$22,0) -> 233687.07 | J15: =SUM(D15:I15) -> 5131487.1 | K15: =IF(B15>0,'원가항목별(집계)1'!I$34*P15/P$22,0) -> 3901330.7 | L15: =IF($B15>0,'원가항목별(집계)1'!I$39*$P15/$P$22,0) -> 18169.17 | M15: =단위장비9!H79+단위장비9!H80 -> 734670 | N15: =SUM(J15:M15) -> 9785657 | P15: =D15+E15+F15+G15+H15+M15 -> 5632470
A16: 10 | B16: =단위장비10!C$1 -> 0 | C16: 2식 | D16: =단위장비10!H140 -> 0 | E16: =단위장비10!H141 -> 0 | F16: =단위장비10!H142+단위장비10!H143+단위장비10!H144+단위장비10!H148 -> 0 | G16: =단위장비10!H145+단위장비10!H146 -> 0 | H16: =단위장비10!H147 -> 0 | I16: =IF($B16>0,'원가항목별(집계)1'!I$38*$P16/$P$22,0) -> 0 | J16: =SUM(D16:I16) -> 0 | K16: =IF(B16>0,'원가항목별(집계)1'!I$34*P16/P$22,0) -> 0 | L16: =IF($B16>0,'원가항목별(집계)1'!I$39*$P16/$P$22,0) -> 0 | M16: =단위장비10!H151+단위장비10!H152 -> 0 | N16: =SUM(J16:M16) -> 0 | P16: =D16+E16+F16+G16+H16+M16 -> 0
A17: 11 | B17: =단위장비11!C$1 -> 0 | C17: 2식 | D17: =단위장비11!H62 -> 0 | E17: =단위장비11!H63 -> 0 | F17: =단위장비11!H64+단위장비11!H65+단위장비11!H66+단위장비11!H70 -> 0 | G17: =단위장비11!H67+단위장비11!H68 -> 0 | H17: =단위장비11!H69 -> 0 | I17: =IF($B17>0,'원가항목별(집계)1'!I$38*$P17/$P$22,0) -> 0 | J17: =SUM(D17:I17) -> 0 | K17: =IF(B17>0,'원가항목별(집계)1'!I$34*P17/P$22,0) -> 0 | L17: =IF($B17>0,'원가항목별(집계)1'!I$39*$P17/$P$22,0) -> 0 | M17: =단위장비11!H73+단위장비11!H74 -> 0 | N17: =SUM(J17:M17) -> 0 | P17: =D17+E17+F17+G17+H17+M17 -> 0
A18: 12 | B18: =단위장비12!C$1 -> 0 | C18: 2식 | D18: =단위장비12!H57 -> 0 | E18: =단위장비12!H58 -> 0 | F18: =단위장비12!H59+단위장비12!H60+단위장비12!H61+단위장비12!H65 -> 0 | G18: =단위장비12!H62+단위장비12!H63 -> 0 | H18: =단위장비12!H64 -> 0 | I18: =IF($B18>0,'원가항목별(집계)1'!I$38*$P18/$P$22,0) -> 0 | J18: =SUM(D18:I18) -> 0 | K18: =IF(B18>0,'원가항목별(집계)1'!I$34*P18/P$22,0) -> 0 | L18: =IF($B18>0,'원가항목별(집계)1'!I$39*$P18/$P$22,0) -> 0 | M18: =단위장비12!H68+단위장비12!H69 -> 0 | N18: =SUM(J18:M18) -> 0 | P18: =D18+E18+F18+G18+H18+M18 -> 0
A19: 13 | B19: =단위장비13!C$1 -> 0 | C19: 2식 | D19: =단위장비13!H43 -> 0 | E19: =단위장비13!H44 -> 0 | F19: =단위장비13!H45+단위장비13!H46+단위장비13!H47+단위장비13!H51 -> 0 | G19: =단위장비13!H48+단위장비13!H49 -> 0 | H19: =단위장비13!H50 -> 0 | I19: =IF($B19>0,'원가항목별(집계)1'!I$38*$P19/$P$22,0) -> 0 | J19: =SUM(D19:I19) -> 0 | K19: =IF(B19>0,'원가항목별(집계)1'!I$34*P19/P$22,0) -> 0 | L19: =IF($B19>0,'원가항목별(집계)1'!I$39*$P19/$P$22,0) -> 0 | M19: =단위장비13!H54+단위장비13!H55 -> 0 | N19: =SUM(J19:M19) -> 0 | P19: =D19+E19+F19+G19+H19+M19 -> 0
A20: 14 | B20: =단위장비14!C1 -> 0 | C20: 1식 | D20: =단위장비14!H46 -> 0 | E20: =단위장비14!H47 -> 0 | F20: =단위장비14!H48+단위장비14!H49+단위장비14!H50+단위장비14!H54 -> 0 | G20: =단위장비14!H51+단위장비14!H52 -> 0 | H20: =단위장비14!H53 -> 0 | I20: =IF($B20>0,'원가항목별(집계)1'!I$38*$P20/$P$22,0) -> 0 | J20: =SUM(D20:I20) -> 0 | K20: =IF(B20>0,'원가항목별(집계)1'!I$34*P20/P$22,0) -> 0 | L20: =IF($B20>0,'원가항목별(집계)1'!I$39*$P20/$P$22,0) -> 0 | M20: =단위장비14!H57+단위장비14!H58 -> 0 | N20: =SUM(J20:M20) -> 0 | P20: =D20+E20+F20+G20+H20+M20 -> 0
A21: 15 | B21: 0 | C21: 4식 | D21: =단위장비15!H60 -> 0 | E21: =단위장비15!H61 -> 0 | F21: =단위장비15!H62+단위장비15!H63+단위장비15!H64+단위장비15!H68 -> 0 | G21: =단위장비15!H65+단위장비15!H66 -> 0 | H21: =단위장비15!H67 -> 0 | I21: =IF($B21>0,'원가항목별(집계)1'!I$38*$P21/$P$22,0) -> 0 | J21: =SUM(D21:I21) -> 0 | K21: =IF(B21>0,'원가항목별(집계)1'!I$34*P21/P$22,0) -> 0 | L21: =IF($B21>0,'원가항목별(집계)1'!I$39*$P21/$P$22,0) -> 0 | M21: =단위장비15!H71+단위장비15!H72 -> 0 | N21: =SUM(J21:M21) -> 0 | P21: =D21+E21+F21+G21+H21+M21 -> 0
A22: 합 계 | D22: =SUM(D7:D21) -> 144764954 | E22: =SUM(E7:E21) -> 0 | F22: =SUM(F7:F21) -> 21350000 | G22: =SUM(G7:G21) -> 4550000 | H22: =SUM(H7:H21) -> 0 | I22: =SUM(I7:I21) -> 8000000 | J22: =SUM(D22:I22) -> 178664954 | K22: =SUM(K7:K21) -> 1.3355744e+08 | L22: =SUM(L7:L21) -> 622000 | M22: =SUM(M7:M21) -> 22155983 | N22: =SUM(N7:N21) -> 3.3500037e+08 | P22: =D22+E22+F22+G22+H22+M22 -> 1.9282094e+08
D23: =IF(D22=0,"",D22/$N22) -> 0.43213371 | E23: =IF(E22=0,"",E22/$N22) | F23: =IF(F22=0,"",F22/$N22) -> 0.063731272 | G23: =IF(G22=0,"",G22/$N22) -> 0.013582074 | H23: =IF(H22=0,"",H22/$N22) | I23: =IF(I22=0,"",I22/$N22) -> 0.02388057 | J23: =IF(J22=0,"",J22/$N22) -> 0.53332763 | K23: =IF(K22=0,"",K22/$N22) -> 0.39867847 | ... N23: =IF(N22=0,"",N22/$N22) -> 1
A24: 주) 전기비용은 턴키장비의 공통비용으로서 총 전기비용을 단위장비별 기계금액의 비율에 따라 배분함 | N24: ='원가항목별(집계)1'!I42-'단위장비별(집계)2'!N22 -> 0
J25: =N25 | N25: =IF('원가항목별(집계)1'!I42='단위장비별(집계)2'!N22,"","DATA오류입니다!")

Sheet 전기
A1: 4. 전기부문: | C1: 전기부문(공통) | I1: (첨부)
A2: 구분 | C2: 품 명 | D2: 규격 | E2: 단위 | F2: 수량 | G2: 단가(원) | H2: 금액(원) | I2: 原MAKER
A3: 자 재 비 | B3: 철자재 | C3: MAIN CONTROL BOX | D3: 1790*2000*600 | E3: 〃 | F3: 1 | G3: 7500000 | H3: =G3*F3 -> 7500000 | I3: KOREA KOKUSAI
C4: OP PANEL BOX | D4: 794*2000*600 | E4: 〃 | F4: 1 | G4: 3800000 | H4: =G4*F4 -> 3800000 | I4: KOREA KOKUSAI
C5: REMOTE BOX1 | D5: 775*400*160 | E5: 〃 | F5: 1 | G5: 625000 | H5: =G5*F5 -> 625000 | I5: KOREA KOKUSAI
C6: REMOTE BOX3 | D6: 1000*700*250 | E6: 〃 | F6: 1 | G6: 680000 | H6: =G6*F6 -> 680000 | I6: KOREA KOKUSAI | O6: 300000
C7: REMOTE BOX3 | D7: 1000*400*160 | E7: 〃 | F7: 1 | G7: 610000 | H7: =G7*F7 -> 610000 | I7: KOREA KOKUSAI
C8: REMOTE BOX3 | D8: 966*400*160 | E8: 〃 | F8: 1 | G8: 610000 | H8: =G8*F8 -> 610000 | I8: KOREA KOKUSAI
C9: TB BOX | D9: 180*450*90 | E9: 〃 | F9: 1 | G9: 125000 | H9: =G9*F9 -> 125000 | I9: KOREA KOKUSAI
C10: TB BOX | D10: 350*180*90 | E10: 〃 | F10: 1 | G10: 112000 | H10: =G10*F10 -> 112000 | I10: KOREA KOKUSAI
C11: TB BOX | D11: 120*250*90 | E11: 〃 | F11: 1 | G11: 90000 | H11: =G11*F11 -> 90000 | I11: KOREA KOKUSAI
C12: TB BOX | D12: 200*150*90 | E12: 〃 | F12: 1 | G12: 9000 | H12: =G12*F12 -> 9000 | I12: KOREA KOKUSAI
C13: 메인 MCCE 취부 | D13: 910*250*450 | E13: 〃 | F13: 1 | G13: 260000 | H13: =G13*F13 -> 260000 | I13: KOREA KOKUSAI
C14: PANEL DUCT | D14: TA2307044 | E14: 〃 | F14: 1 | G14: 200000 | H14: =G14*F14 -> 200000 | I14: KOREA KOKUSAI
C15: PANEL DUCT COVER | D15: TA2307045 | E15: 〃 | F15: 2 | G15: 40000 | H15: =G15*F15 -> 80000 | I15: KOREA KOKUSAI
C16: 상부 DUCT A | D16: TA2307046 | E16: 〃 | F16: 1 | G16: 170000 | H16: =G16*F16 -> 170000 | I16: KOREA KOKUSAI
C17: 상부 DUCT SUPPORT BRACKET | D17: TA2307047 | E17: 〃 | F17: 2 | G17: 50000 | H17: =G17*F17 -> 100000 | I17: KOREA KOKUSAI
C18: 상부 DUCT B | D18: TA2307048 | E18: 〃 | F18: 1 | G18: 440000 | H18: =G18*F18 -> 440000 | I18: KOREA KOKUSAI
C19: 상부 DUCT C | D19: TA2307049 | E19: 〃 | F19: 1 | G19: 650000 | H19: =G19*F19 -> 650000 | I19: KOREA KOKUSAI
C20: DUCT SUPPORT BRACKET | D20: TA2307050 | E20: 〃 | F20: 2 | G20: 188000 | H20: =G20*F20 -> 376000 | I20: KOREA KOKUSAI
C21: DUCT COVER 1 | D21: TA2307051 | E21: 〃 | F21: 1 | G21: 50000 | H21: =G21*F21 -> 50000 | I21: KOREA KOKUSAI
C22: DUCT COVER 2 | D22: TA2307052 | E22: 〃 | F22: 1 | G22: 50000 | H22: =G22*F22 -> 50000 | I22: KOREA KOKUSAI
C23: DUCT SUPPORT BRACKET | D23: TA2307053 | E23: 〃 | F23: 1 | G23: 64000 | H23: =G23*F23 -> 64000 | I23: KOREA KOKUSAI
C24: WASHER | D24: TA2307059 | E24: 〃 | F24: 10 | G24: 4000 | H24: =G24*F24 -> 40000 | I24: KOREA KOKUSAI
C25: 연결 DUCT | D25: TA2307061 | E25: 〃 | F25: 1 | G25: 260000 | H25: =G25*F25 -> 260000 | I25: KOREA KOKUSAI
C26: END BRACKET | D26: TA2307062 | E26: 〃 | F26: 1 | G26: 50000 | H26: =G26*F26 -> 50000 | I26: KOREA KOKUSAI
C27: AIR PIPE SUPPORT BRACKET 1 | D27: TA2307065 | E27: 〃 | F27: 5 | G27: 40000 | H27: =G27*F27 -> 200000 | I27: KOREA KOKUSAI
E28: 〃 | H28: =G28*F28 -> 0
E29: 〃 | H29: =G29*F29 -> 0
E30: 〃 | H30: =IF(F30=0,G30,G30*F30) -> 0
E31: 〃 | H31: =IF(F31=0,G31,G31*F31) -> 0
E32: 〃 | H32: =IF(F32=0,G32,G32*F32) -> 0
E33: 〃 | H33: =IF(F33=0,G33,G33*F33) -> 0
E34: 〃 | H34: =IF(F34=0,G34,G34*F34) -> 0
E35: 〃 | H35: =IF(F35=0,G35,G35*F35) -> 0
E36: 〃 | H36: =IF(F36=0,G36,G36*F36) -> 0
E37: 〃 | H37: =IF(F37=0,G37,G37*F37) -> 0
E38: 〃 | H38: =IF(F38=0,G38,G38*F38) -> 0
E39: 〃 | H39: =IF(F39=0,G39,G39*F39) -> 0
H42: =SUM(H3:H41) -> 17151000
...

Sheet 단위장비1
A1: 3-1.단위장비명(전기제외): | C1: BASE PART | I1: (첨부)
A2: 구분 | C2: 품 명 | D2: 규격 | E2: 단위 | F2: 수량 | G2: 단가(원) | H2: 금액(원) | I2: 原MAKER
A3: 자 재 비 | B3: 철자재 | C3: PLATE | E3: KG | F3: 500 | G3: 1200 | H3: =IF(F3=0,G3,G3*F3) -> 600000
C4: 배관자재 | E4: M | F4: 6 | G4: 12000 | H4: =IF(F4=0,G4,G4*F4) -> 72000
H5: =IF(F5=0,G5,G5*F5) -> 0
H6: =IF(F6=0,G6,G6*F6) -> 0
H7: =IF(F7=0,G7,G7*F7) -> 0
H8: =IF(F8=0,G8,G8*F8) -> 0
H9: =IF(F9=0,G9,G9*F9) -> 0
H10: =IF(F10=0,G10,G10*F10) -> 0
H11: =IF(F11=0,G11,G11*F11) -> 0
H12: =IF(F12=0,G12,G12*F12) -> 0
C13: 기타자재 | E13: KG | F13: 20 | G13: 10000 | H13: =IF(F13=0,G13,G13*F13) -> 200000
F14: =SUM(F3:F13) -> 526 | H14: =SUM(H3:H13) -> 872000
B15: 구매품 | H15: =IF(F15=0,G15,G15*F15) -> 0
B16: (유공압품외) | H16: =IF(F16=0,G16,G16*F16) -> 0
B17: BRUSHING M/C | C17: LEVEL FOOT | D17: MF78-20-100 | E17: EA | F17: 4 | G17: 20300 | H17: =IF(F17=0,G17,G17*F17) -> 81200 | I17: WOOIL
H18: =IF(F18=0,G18,G18*F18) -> 0
H19: =IF(F19=0,G19,G19*F19) -> 0
B20: STRAIGHTENING M/C | C20: AREA SENSOR | D20: BW20-12 | E20: EA | F20: 2 | G20: 365000 | H20: =IF(F20=0,G20,G20*F20) -> 730000 | I20: AUTONICS
C21: CABLE | D21: CID4-5R | E21: EA | F21: 2 | G21: 14800 | H21: =IF(F21=0,G21,G21*F21) -> 29600 | I21: AUTONICS
C22: CABLE | D22: CID4-5T | E22: EA | F22: 2 | G22: 14800 | H22: =IF(F22=0,G22,G22*F22) -> 29600 | I22: AUTONICS
E23: 〃 | H23: =IF(F23=0,G23,G23*F23) -> 0
E24: 〃 | H24: =IF(F24=0,G24,G24*F24) -> 0
E25: 〃 | H25: =IF(F25=0,G25,G25*F25) -> 0
E26: 〃 | H26: =IF(F26=0,G26,G26*F26) -> 0
E27: 〃 | H27: =IF(F27=0,G27,G27*F27) -> 0
E28: 〃 | H28: =IF(F28=0,G28,G28*F28) -> 0
E29: 〃 | H29: =IF(F29=0,G29,G29*F29) -> 0
H30: =IF(F30=0,G30,G30*F30) -> 0
E31: 〃 | H31: =IF(F31=0,G31,G31*F31) -> 0
E32: 〃 | H32: =IF(F32=0,G32,G32*F32) -> 0
E33: 〃 | H33: =IF(F33=0,G33,G33*F33) -> 0
E34: 〃 | H34: =IF(F34=0,G34,G34*F34) -> 0
E35: 〃 | H35: =IF(F35=0,G35,G35*F35) -> 0
E36: 〃 | H36: =IF(F36=0,G36,G36*F36) -> 0
E37: 〃 | H37: =IF(F37=0,G37,G37*F37) -> 0
E38: 〃 | H38: =IF(F38=0,G38,G38*F38) -> 0
E39: 〃 | H39: =IF(F39=0,G39,G39*F39) -> 0
E40: 〃 | H40: =IF(F40=0,G40,G40*F40) -> 0
...

Sheet 단위장비2
A1: 3-2.단위장비명(전기제외): | C1: TRANSFER PART | I1: (첨부)
A2: 구분 | C2: 품 명 | D2: 규격 | E2: 단위 | F2: 수량 | G2: 단가(원) | H2: 금액(원) | I2: 原MAKER
A3: 자 재 비 | B3: 철자재 | C3: PLATE | E3: KG | F3: 20 | G3: 1200 | H3: =IF(F3=0,G3,G3*F3) -> 24000
C4: 배관자재 | E4: M | H4: =IF(F4=0,G4,G4*F4) -> 0
H5: =IF(F5=0,G5,G5*F5) -> 0
H6: =IF(F6=0,G6,G6*F6) -> 0
H7: =IF(F7=0,G7,G7*F7) -> 0
H8: =IF(F8=0,G8,G8*F8) -> 0
H9: =IF(F9=0,G9,G9*F9) -> 0
H10: =IF(F10=0,G10,G10*F10) -> 0
H11: =IF(F11=0,G11,G11*F11) -> 0
C12: 기타자재 | E12: KG | F12: 10 | G12: 10000 | H12: =IF(F12=0,G12,G12*F12) -> 100000
F13: =SUM(F3:F12) -> 30 | H13: =SUM(H3:H12) -> 124000
B14: 구매품 | H14: =G14*F14 -> 0
B15: (유공압품외) | H15: =G15*F15 -> 0
B16: BRUSHING M/C | C16: AIR CYLINDER | D16: CY1SG32-100BZ | E16: EA | F16: 1 | G16: 498000 | H16: =G16*F16 -> 498000 | I16: SMC
C17: SPEED CON' | D17: AS2201F-02-08S | E17: EA | F17: 2 | G17: 4290 | H17: =G17*F17 -> 8580 | I17: SMC
C18: LM GUIDE | D18: HSR25RQZ2UU+1360(G:20) | E18: EA | F18: 4 | G18: 198000 | H18: =G18*F18 -> 792000 | I18: THK
C19: LM GUIDE | D19: HSR25RQZ2UU+880(G:20) | E19: EA | F19: 2 | G19: 195000 | H19: =G19*F19 -> 390000 | I19: THK
C20: SET COLLAR | D20: PSCS25-15 | E20: EA | F20: 2 | G20: 5347 | H20: =G20*F20 -> 10694 | I20: MISUMI
C21: BALL BUSH | D21: SC20UU | E21: EA | F21: 4 | G21: 9610 | H21: =G21*F21 -> 38440 | I21: THK
C22: SHAFT | D22: PSFJ20-238L | E22: EA | F22: 4 | G22: 9190 | H22: =IF(F22=0,G22,G22*F22) -> 36760 | I22: MISUMI
C23: PHOTO SENSOR | D23: E3Z-T66 | E23: EA | F23: 1 | G23: 55000 | H23: =IF(F23=0,G23,G23*F23) -> 55000 | I23: OMRON
C24: CABLE | D24: XS3F-M421-405-A | E24: EA | F24: 2 | G24: 10700 | H24: =IF(F24=0,G24,G24*F24) -> 21400 | I24: OMRON
C25: BALL BUSH | D25: LM25UU | E25: EA | F25: 8 | G25: 5170 | H25: =IF(F25=0,G25,G25*F25) -> 41360 | I25: THK
C26: SNAP RING | D26: S-40 | E26: EA | F26: 16 | G26: 130 | H26: =IF(F26=0,G26,G26*F26) -> 2080 | I26: KS
C27: SHAFT | D27: PSFJT25-320-M8 | E27: EA | F27: 3 | G27: 25250 | H27: =IF(F27=0,G27,G27*F27) -> 75750 | I27: MISUMI
C28: SHAFT | D28: PSFJT25-420-M8 | E28: EA | F28: 1 | G28: 31870 | H28: =IF(F28=0,G28,G28*F28) -> 31870 | I28: MISUMI
C29: PROXIMITY SENSOR | D29: E2E-X3D1-M1G | E29: EA | F29: 4 | G29: 27800 | H29: =IF(F29=0,G29,G29*F29) -> 111200 | I29: OMRON
C30: SENSOR CABLE | D30: XS2F-D422-GA0-A | E30: EA | F30: 4 | G30: 8400 | H30: =IF(F30=0,G30,G30*F30) -> 33600 | I30: OMRON
C31: LM GUIDE CLAMP | D31: SVCN33 | E31: EA | F31: 12 | G31: 90340 | H31: =IF(F31=0,G31,G31*F31) -> 1084080 | I31: MISUMI
C32: FLOATING JOINT | D32: JAF80-22-150 | E32: EA | F32: 2 | G32: 47130 | H32: =IF(F32=0,G32,G32*F32) -> 94260 | I32: SMC
C33: AIR CYLINDER | D33: CG1LA80-50Z | E33: EA | F33: 2 | G33: 117360 | H33: =IF(F33=0,G33,G33*F33) -> 234720 | I33: SMC
C34: SPEED CON' | D34: AS3201F-03-08S | E34: EA | F34: 4 | G34: 6250 | H34: =IF(F34=0,G34,G34*F34) -> 25000 | I34: SMC
H35: =IF(F35=0,G35,G35*F35) -> 0
B36: STRAIGHTENING M/C | C36: AIR CYLINDER | D36: CY1SG32-100BZ | E36: EA | F36: 1 | G36: 456200 | H36: =IF(F36=0,G36,G36*F36) -> 456200 | I36: SMC
C37: SPEED CON' | D37: AS2201F-02-08S | E37: EA | F37: 2 | G37: 4290 | H37: =IF(F37=0,G37,G37*F37) -> 8580 | I37: SMC
C38: SET COLLAR | D38: PSCS25-15 | E38: EA | F38: 2 | G38: 5347 | H38: =IF(F38=0,G38,G38*F38) -> 10694 | I38: MISUMI
C39: LM GUIDE | D39: HSR25RQZ2UU+1360L(G:20) | E39: EA | F39: 4 | G39: 198900 | H39: =SUM(G39*F39) -> 795600 | I39: THK
C40: LM GUIDE | D40: HSR25RQZ2UU+880L(G:20) | E40: EA | F40: 2 | G40: 197400 | H40: =SUM(G40*F40) -> 394800 | I40: THK
...

Sheet 단위장비3
A1: 3-3.단위장비명(전기제외): | C1: JIG PART | I1: (첨부)
A2: 구분 | C2: 품 명 | D2: 규격 | E2: 단위 | F2: 수량 | G2: 단가(원) | H2: 금액(원) | I2: 原MAKER
A3: 자 재 비 | B3: 철자재 | C3: PALTE | E3: KG | F3: 20 | G3: 1200 | H3: =IF(F3=0,G3,G3*F3) -> 24000
C4: 배관자재 | E4: M | H4: =IF(F4=0,G4,G4*F4) -> 0
C5: 기타자재 | E5: KG | F5: 10 | G5: 10000 | H5: =IF(F5=0,G5,G5*F5) -> 100000
F6: =SUM(F3:F5) -> 30 | H6: =SUM(H3:H5) -> 124000
B7: 구매품 | H7: =G7*F7 -> 0
B8: (유공압품외) | H8: =G8*F8 -> 0
B9: BRUSHING M/C | C9: SLIDE COVER | D9: ST4323001 | E9: EA | F9: 1 | G9: 450000 | H9: =G9*F9 -> 450000 | I9: 한성
C10: JABARA COVER | D10: ST4323002 | E10: EA | F10: 1 | G10: 250000 | H10: =G10*F10 -> 250000 | I10: 한성
C11: TM SHAFT | D11: ST4312006-001 | E11: EA | F11: 1 | G11: 145000 | H11: =G11*F11 -> 145000 | I11: MIISUMI
C12: LM GUIDE | D12: HSR20R 3QZ UU+1480 | E12: EA | F12: 2 | G12: 553200 | H12: =G12*F12 -> 1106400 | I12: THK
C13: LEVER | D13: CLDM8-32-B | E13: EA | F13: 6 | G13: 35000 | H13: =G13*F13 -> 210000 | I13: MISUMI
C14: HANDLE | D14: AHTN125-KC12 | E14: EA | F14: 1 | G14: 68900 | H14: =G14*F14 -> 68900 | I14: MISUMI
C15: BEARING HOLDER | D15: BGSCB60002ZZ-30 | E15: EA | F15: 2 | G15: 25350 | H15: =G15*F15 -> 50700 | I15: MISUMI
C16: U-NUT | D16: FU02 | E16: EA | F16: 2 | G16: 7000 | H16: =G16*F16 -> 14000 | I16: FUKUDA
C17: KEY | D17: KES4-20 | E17: EA | F17: 1 | G17: 500 | H17: =G17*F17 -> 500 | I17: FUKUDA
C18: COLLAR | D18: CLBUM15-19-4 | E18: EA | F18: 2 | G18: 7543 | H18: =G18*F18 -> 15086 | I18: MISUMI
C19: BALL SCREW COVER | D19: SF40/900/60(V) | E19: EA | F19: 2 | G19: 180000 | H19: =G19*F19 -> 360000 | I19: 한성
C20: LIMIT SWITCH | D20: WLG2-LDK43 | E20: EA | F20: 1 | G20: 47000 | H20: =G20*F20 -> 47000 | I20: OMRON
C21: PROXIMITY SENSOR | D21: E2E-X10D1-M1G | E21: EA | F21: 1 | G21: 70400 | H21: =G21*F21 -> 70400 | I21: OMRON
... C23: SCREW NUT | D23: MTBLR20 | E23: EA | F23: 1 | G23: 146446 | H23: =G23*F23 -> 146446 | I23: MISUMI
H24: =G24*F24 -> 0
B25: STRAIGHTENING M/C | C25: LEVER | D25: CLRA10-32-B | E25: EA | F25: 3 | G25: 29145 | H25: =G25*F25 -> 87435 | I25: MISUMI
C26: AIR CYLINDER | D26: CDQ2B32-40-A93L | E26: EA | F26: 3 | G26: 61580 | H26: =G26*F26 -> 184740 | I26: SMC
C27: SPEED CON | D27: AS2201F-01-06S | E27: EA | F27: 6 | G27: 4290 | H27: =G27*F27 -> 25740 | I27: SMC
C28: SPRING | D28: WF6-20 | E28: EA | F28: 6 | G28: 1558 | H28: =G28*F28 -> 9348 | I28: MISUMI
C29: DOWEL PIN | D29: MST8-20 | E29: EA | F29: 6 | G29: 2987 | H29: =G29*F29 -> 17922 | I29: MISUMI
C30: PARALLEL PIN | D30: MSY4-15 | E30: EA | F30: 50 | G30: 2947 | H30: =G30*F30 -> 147350 | I30: MISUMI
C31: DOWEL PIN | D31: MST10-35 | E31: EA | F31: 4 | G31: 3205 | H31: =G31*F31 -> 12820 | I31: MISUMI
C32: DOWEL PIN | D32: MST8-20 | E32: EA | F32: 4 | G32: 3987 | H32: =G32*F32 -> 15948 | I32: MISUMI
C33: LEVER | D33: CLRA10-32-B | E33: EA | F33: 2 | G33: 29145 | H33: =G33*F33 -> 58290 | I33: MISUMI
C34: PHOTO SENSOR | D34: E3T-ST12 | E34: EA | F34: 1 | G34: 86000 | H34: =G34*F34 -> 86000 | I34: OMRON
E35: 〃 | H35: =G35*F35 -> 0
E36: 〃 | H36: =G36*F36 -> 0
E37: 〃 | H37: =G37*F37 -> 0
E38: 〃 | H38: =G38*F38 -> 0
E39: 〃 | H39: =G39*F39 -> 0
E40: 〃 | H40: =G40*F40 -> 0
E41: 〃 | H41: =G41*F41 -> 0
...

Sheet 단위장비4
A1: 3-4.단위장비명(전기제외): | I1: (첨부)
A2: 구분 | C2: 품 명 | D2: 규격 | E2: 단위 | F2: 수량 | G2: 단가(원) | H2: 금액(원) | I2: 原MAKER
A3: 자 재 비 | B3: 철자재
F8: =SUM(F3:F7) -> 0 | H8: =SUM(H3:H7) -> 0
B9: 구매품 | H9: =G9*F9 -> 0
B10: (유공압품외) | H10: =G10*F10 -> 0
H11: =G11*F11 -> 0
H12: =G12*F12 -> 0
H13: =G13*F13 -> 0
H14: =G14*F14 -> 0
H15: =G15*F15 -> 0
H16: =G16*F16 -> 0
H25: =G25*F25 -> 0
H26: =G26*F26 -> 0
H27: =G27*F27 -> 0
H29: =G29*F29 -> 0
H31: =G31*F31 -> 0
H32: =G32*F32 -> 0
H33: =G33*F33 -> 0
H37: =SUM(H9:H36) -> 0
B38: 외주제작품
H61: =SUM(H38:H60) -> 0
B62: 자재비 소계 | H62: =SUM(H61,H37,H8) -> 0
A63: 노 무 비 | B63: 기존설비 철거 | E63: M/D | G63: 250000 | H63: =F63*G63 -> 0
B64: 기계 설계 | E64: M/D | G64: 200000 | H64: =F64*G64 -> 0
B65: 기계 제작(제관,가공) | E65: M/D | G65: 250000 | H65: =F65*G65 -> 0
B66: 기계 조립 | E66: M/D | G66: 250000 | H66: =F66*G66 -> 0
B67: 기계 설치 | E67: M/D | G67: 300000 | H67: =F67*G67 -> 0
B68: 기계 시운전 | E68: M/D | G68: 300000 | H68: =F68*G68 -> 0
B69: 기계 양산대응 | E69: M/D | G69: 300000 | H69: =F69*G69 -> 0
B70: 기계 도장 | E70: M/D | G70: 200000 | H70: =F70*G70 -> 0
B71: 노무비 소계 | H71: =SUM(H63:H70) -> 0
B72: 운반및중장비사용,표준안전관리비 | H72: ='단위장비별(집계)2'!L9+'단위장비별(집계)2'!I9 -> 857797.58
B73: 일반관리비 | E73: % | F73: 5 | H73: =(H62+H71)*0.05 -> 0
B74: 이 윤 | E74: % | F74: 10 | H74: =(H62+H71)*0.1 -> 0
B75: 합 계 | H75: =H62+H71+H72+H73+H74 -> 857797.58

Sheet 단위장비5
A1: 3-5.단위장비명(전기제외): | C1: MEASURING PART | I1: (첨부)
A2: 구분 | C2: 품 명 | D2: 규격 | E2: 단위 | F2: 수량 | G2: 단가(원) | H2: 금액(원) | I2: 原MAKER
A3: 자 재 비 | B3: 철자재 | C3: PLATE | E3: KG | F3: 300 | G3: 1200 | H3: =IF(F3=0,G3,G3*F3) -> 360000
C4: 배관자재 | E4: M | F4: 3 | G4: 12000 | H4: =IF(F4=0,G4,G4*F4) -> 36000
C9: 기타자재 | E9: KG | F9: 15 | G9: 10000 | H9: =IF(F9=0,G9,G9*F9) -> 150000
F10: =SUM(F3:F9) -> 318 | H10: =SUM(H3:H9) -> 546000
B11: 구매품 | H11: =G11*F11 -> 0
B12: (유공압품외) | H12: =IF(F12=0,G12,G12*F12) -> 0
B13: BRUSHING M/C | C13: PROXIMITY SENSOR | D13: E2E-X3D1-M1G | E13: EA | F13: 2 | G13: 47800 | H13: =IF(F13=0,G13,G13*F13) -> 95600 | I13: OMRON
B14: CENTER | C14: SENSOR CABLE | D14: XS2F-D422-GA0-A | E14: EA | F14: 2 | G14: 16500 | H14: =IF(F14=0,G14,G14*F14) -> 33000 | I14: OMRON
C15: SPEED CONTROLLER | D15: AS2201F-02-06S | E15: EA | F15: 2 | G15: 8900 | H15: =IF(F15=0,G15,G15*F15) -> 17800 | I15: SMC
C16: AIR CYLINDER | D16: CDQ2B50-35DM | E16: EA | F16: 1 | G16: 125000 | H16: =IF(F16=0,G16,G16*F16) -> 125000 | I16: SMC
C17: FLOATING JOINT | D17: J-1815 | E17: EA | F17: 1 | G17: 94500 | H17: =IF(F17=0,G17,G17*F17) -> 94500 | I17: HAGASA
C18: DUST SEAL | D18: ORA45 | E18: EA | F18: 2 | G18: 10800 | H18: =IF(F18=0,G18,G18*F18) -> 21600 | I18: KYOWA
C19: LIVE CENTER | D19: KSA1-18-C014JOO | E19: EA | F19: 2 | G19: 400000 | H19: =IF(F19=0,G19,G19*F19) -> 800000 | I19: POINTTECH
C20: DU BUSH | D20: MB1215DU | E20: EA | F20: 1 | G20: 560 | H20: =IF(F20=0,G20,G20*F20) -> 560 | I20: LUBO
H21: =IF(F21=0,G21,G21*F21) -> 0
B22: SPINDLE | C22: OIL SEAL | D22: SC55709 | E22: EA | F22: 1 | G22: 16000 | H22: =IF(F22=0,G22,G22*F22) -> 16000 | I22: NOK
C23: TAPER ROLLER BEARING | D23: HR30206J P5 | E23: EA | F23: 2 | G23: 17000 | H23: =IF(F23=0,G23,G23*F23) -> 34000 | I23: NSK
C24: OIL SEAL | D24: SC45609 | E24: EA | F24: 1 | G24: 11900 | H24: =IF(F24=0,G24,G24*F24) -> 11900 | I24: NOK
C25: ZM NUT | D25: ZM 30 | E25: EA | F25: 1 | G25: 14400 | H25: =IF(F25=0,G25,G25*F25) -> 14400 | I25: FUKUDA
C26: INDUCTION MOTOR | D26: TEFC-80 | E26: EA | F26: 1 | G26: 654000 | H26: =IF(F26=0,G26,G26*F26) -> 654000 | I26: HYOSUNG
C27: TIIMING BELT | D27: 250 S5M 600 | E27: EA | F27: 1 | G27: 34000 | H27: =IF(F27=0,G27,G27*F27) -> 34000 | I27: MITSUBOSHI
C28: POWER LOCK | D28: MLM25 | E28: EA | F28: 1 | G28: 108000 | H28: =IF(F28=0,G28,G28*F28) -> 108000 | I28: MISUMI
C29: FLOATING JOINT | D29: JAL80-22-150 | E29: EA | F29: 1 | G29: 96000 | H29: =IF(F29=0,G29,G29*F29) -> 96000 | I29: SMC
C30: AIR CYLINDER | D30: CDQ2B80-50DM-A73L | E30: EA | F30: 1 | G30: 223200 | H30: =IF(F30=0,G30,G30*F30) -> 223200 | I30: SMC
C31: SPEED CONTROLLER V/V | D31: AS3201F-02-08S | E31: EA | F31: 2 | G31: 12500 | H31: =IF(F31=0,G31,G31*F31) -> 25000 | I31: SMC
C32: LM GUIDE | D32: HSR25R2QZ UU+330L | E32: EA | F32: 2 | G32: 206800 | H32: =IF(F32=0,G32,G32*F32) -> 413600 | I32: THK
H33: =IF(F33=0,G33,G33*F33) -> 0
B34: AUTO LOADER | C34: HANDLE | D34: AHTN140-KC15 | E34: EA | F34: 1 | G34: 78900 | H34: =IF(F34=0,G34,G34*F34) -> 78900 | I34: MISUMI
C35: SCREW NUT | D35: MTBLR20 | E35: EA | F35: 1 | G35: 288800 | H35: =IF(F35=0,G35,G35*F35) -> 288800 | I35: MISUMI
C36: BALL BEARING | D36: 6002ZZ | E36: EA | F36: 2 | G36: 2500 | H36: =IF(F36=0,G36,G36*F36) -> 5000 | I36: NSK
C37: U NUT | D37: FU02 | E37: EA | F37: 1 | G37: 14000 | H37: =IF(F37=0,G37,G37*F37) -> 14000 | I37: FUKUDA
C38: PROXIMITY SENSOR | D38: E2E-X3D1-M1G | E38: EA | F38: 2 | G38: 44800 | H38: =IF(F38=0,G38,G38*F38) -> 89600 | I38: OMRON
C39: SENSOR CABLE | D39: XS2F-D422-GA0-F | E39: EA | F39: 5 | G39: 16800 | H39: =IF(F39=0,G39,G39*F39) -> 84000 | I39: OMRON
C40: SET COLLAR | D40: PSCS12-12 | E40: EA | F40: 2 | G40: 8990 | H40: =IF(F40=0,G40,G40*F40) -> 17980 | I40: MISUMI
C41: LM GUIDE | D41: HSR20R 2QZ UU+340L | E41: EA | F41: 2 | G41: 310000 | H41: =IF(F41=0,G41,G41*F41) -> 620000 | I41: THK
C42: LM GUIDE | D42: HSR20R 2QZ UU+280L | E42: EA | F42: 2 | G42: 309000 | H42: =IF(F42=0,G42,G42*F42) -> 618000 | I42: THK
C43: AIR CYLINDER | D43: CBA2F63-100HN | E43: EA | F43: 1 | G43: 389000 | H43: =IF(F43=0,G43,G43*F43) -> 389000 | I43: SMC
C44: SPEED CONTROL V/V | D44: AS3201F-03-08S | E44: EA | F44: 2 | G44: 12450 | H44: =IF(F44=0,G44,G44*F44) -> 24900 | I44: SMC
...

Sheet 단위장비6
A1: 3-6.단위장비명(전기제외): | C1: RAM PART | I1: (첨부)
A2: 구분 | C2: 품 명 | D2: 규격 | E2: 단위 | F2: 수량 | G2: 단가(원) | H2: 금액(원) | I2: 原MAKER
A3: 자 재 비 | B3: 철자재 | C3: PLATE | E3: KG | F3: 50 | G3: 1500 | H3: =IF(F3=0,G3,G3*F3) -> 75000
H4: =IF(F4=0,G4,G4*F4) -> 0
H5: =IF(F5=0,G5,G5*F5) -> 0
H6: =IF(F6=0,G6,G6*F6) -> 0
H7: =IF(F7=0,G7,G7*F7) -> 0
H8: =IF(F8=0,G8,G8*F8) -> 0
H9: =IF(F9=0,G9,G9*F9) -> 0
C10: 기타자재 | E10: SET | F10: 20 | G10: 8000 | H10: =IF(F10=0,G10,G10*F10) -> 160000
F11: =SUM(F3:F10) -> 70 | H11: =SUM(H3:H10) -> 235000
B12: 구매품 | E12: EA | H12: =IF(F12=0,G12,G12*F12) -> 0
B13: (유공압품외) | E13: 〃 | H13: =IF(F13=0,G13,G13*F13) -> 0
B14: STRAIGHTENING M/C | C14: HYD CYLINDER | D14: CJT140-FA140B100N-BND | E14: EA | F14: 1 | G14: 1014000 | H14: =IF(F14=0,G14,G14*F14) -> 1014000 | I14: YUKEN
C15: LM GUIDE | D15: HSR55LR1QZUU+1380L | E15: EA | F15: 2 | G15: 721300 | H15: =IF(F15=0,G15,G15*F15) -> 1442600 | I15: THK
C16: BALL SCREW | D16: BLK2525-3.6ZZ-1564 | E16: EA | F16: 1 | G16: 618450 | H16: =IF(F16=0,G16,G16*F16) -> 618450 | I16: THK
C17: SERVO MOTOR | D17: HG-KR43 | E17: EA | F17: 1 | G17: 275000 | H17: =IF(F17=0,G17,G17*F17) -> 275000 | I17: MITSUBISHI
C18: BALL BUSH | D18: LMF30UU | E18: EA | F18: 1 | G18: 14380 | H18: =IF(F18=0,G18,G18*F18) -> 14380 | I18: THK
C19: SWITCH | D19: ZC-Q2255 | E19: EA | F19: 3 | G19: 15500 | H19: =IF(F19=0,G19,G19*F19) -> 46500 | I19: OMRON
C20: PROXIMITY SENSOR | D20: E2E-X3D1-M1G | E20: EA | F20: 3 | G20: 25800 | H20: =IF(F20=0,G20,G20*F20) -> 77400 | I20: OMRON
C21: CONNECTOR | D21: XS2F-D422-GA0-A | E21: EA | F21: 3 | G21: 8000 | H21: =IF(F21=0,G21,G21*F21) -> 24000 | I21: OMRON
C22: SUPPORT | D22: FK20 | E22: EA | F22: 1 | G22: 59250 | H22: =IF(F22=0,G22,G22*F22) -> 59250 | I22: THK
C23: SUPPORT | D23: FF20 | E23: EA | F23: 1 | G23: 18290 | H23: =IF(F23=0,G23,G23*F23) -> 18290 | I23: THK
C24: TIMING BELT | D24: B150-S5M-690L | E24: EA | F24: 1 | G24: 12000 | H24: =IF(F24=0,G24,G24*F24) -> 12000 | I24: MITSUBOSHI
C25: SWIBEL ELBOW | D25: SLO-1404 | E25: EA | F25: 2 | G25: 60000 | H25: =IF(F25=0,G25,G25*F25) -> 120000 | I25: KOKUSAI
C26: REDUCER | D26: HSS0601A-005-K-S | E26: EA | F26: 1 | G26: 183000 | H26: =IF(F26=0,G26,G26*F26) -> 183000 | I26: LS
... C28: POWER MEISTER | D28: UPS-1A-11V35C1S4 | E28: SET | F28: 1 | G28: 28000000 | H28: =IF(F28=0,G28,G28*F28) -> 28000000 | I28: JAPAN KOKUSAI
E29: 〃 | H29: =IF(F29=0,G29,G29*F29) -> 0
E31: 〃
C32: 배선자재 | E32: SET | F32: 1 | H32: 420000
H33: =SUM(H12:H32) -> 32340430
B34: 외주제작품 | H34: =G34*F34 -> 0
B35: STRAIGHTENING M/C | C35: CYL PLATE | D35: ST1107001-004 | E35: EA | F35: 1 | G35: 180000 | H35: =G35*F35 -> 180000 | I35: KOREA KOKUSAI
C36: ROD END BLOCK | D36: ST1108015-001 | E36: EA | F36: 1 | G36: 120000 | H36: =G36*F36 -> 120000 | I36: KOREA KOKUSAI
C37: 절연 PLATE | D37: ST1108016-001 | E37: EA | F37: 1 | G37: 15000 | H37: =G37*F37 -> 15000 | I37: KOREA KOKUSAI
C38: PUNCH(HEAT) | D38: ST1108018-001 | E38: EA | F38: 1 | G38: 32000 | H38: =G38*F38 -> 32000 | I38: KOREA KOKUSAI
C39: PUNCH(NO HEAT) | D39: ST1108018-002 | E39: EA | F39: 1 | G39: 32000 | H39: =G39*F39 -> 32000 | I39: KOREA KOKUSAI
C40: 절연 PLATE | D40: ST1108019-000 | E40: EA | F40: 1 | G40: 20000 | H40: =G40*F40 -> 20000 | I40: KOREA KOKUSAI
C41: GUIDE BLOCK(1) | D41: ST1107007-003 | E41: EA | F41: 1 | G41: 33000 | H41: =G41*F41 -> 33000 | I41: KOREA KOKUSAI
C42: SENSOR BRACKET | D42: ST1108021-002 | E42: EA | F42: 1 | G42: 40000 | H42: =G42*F42 -> 40000 | I42: KOREA KOKUSAI
...

Sheet 단위장비7
A1: 3-7.단위공사명(전기제외): | C1: MASTER/NG PART | I1: (첨부)
A2: 구분 | C2: 품 명 | D2: 규격 | E2: 단위 | F2: 수량 | G2: 단가(원) | H2: 금액(원) | I2: 原MAKER
A3: 자 재 비 | B3: 철자재 | C3: PLATE | E3: KG | F3: 50 | G3: 1500 | H3: =IF(F3=0,G3,G3*F3) -> 75000
H4: =IF(F4=0,G4,G4*F4) -> 0
H5: =IF(F5=0,G5,G5*F5) -> 0
H6: =IF(F6=0,G6,G6*F6) -> 0
H7: =IF(F7=0,G7,G7*F7) -> 0
H8: =IF(F8=0,G8,G8*F8) -> 0
H9: =IF(F9=0,G9,G9*F9) -> 0
H10: =IF(F10=0,G10,G10*F10) -> 0
H11: =IF(F11=0,G11,G11*F11) -> 0
H12: =IF(F12=0,G12,G12*F12) -> 0
H13: =IF(F13=0,G13,G13*F13) -> 0
C14: 기타자재 | E14: SET | H14: =IF(F14=0,G14,G14*F14) -> 0
H15: =SUM(H3:H14) -> 75000
B16: 구매품 | H16: =G16*F16 -> 0
B17: (유공압품외) | H17: =G17*F17 -> 0
B18: STRAIGHTENING M/C | C18: LM GUIDE | D18: HSR20AQZ1UU+360 | E18: EA | F18: 2 | G18: 100000 | H18: =G18*F18 -> 200000 | I18: THK
B19: NG PART | C19: PROXIMITY SENSOR | D19: E2E-X10D1-M1G | E19: EA | F19: 2 | G19: 60000 | H19: =G19*F19 -> 120000 | I19: OMRON
C20: PROXIMITY SENSOR | D20: E2E-X3D1-M1G | E20: EA | F20: 2 | G20: 21500 | H20: =G20*F20 -> 43000 | I20: OMRON
C21: SENSOR CABLE | D21: XS2F-D422-GA0-A | E21: EA | F21: 2 | G21: 6500 | H21: =G21*F21 -> 13000 | I21: OMRON
C22: SPRING | D22: AWU6-30 | E22: EA | F22: 2 | G22: 1180 | H22: =G22*F22 -> 2360 | I22: MISUMI
C23: POST | D23: ASP04-25 | E23: EA | F23: 4 | G23: 1500 | H23: =G23*F23 -> 6000 | I23: MISUMI
C24: FLOATING JOINT | D24: JAF40-14-150 | E24: EA | F24: 1 | G24: 26000 | H24: =G24*F24 -> 26000 | I24: SMC
C25: AIR CYLINDER | D25: CG1FA40-250Z | E25: EA | F25: 1 | G25: 72100 | H25: =G25*F25 -> 72100 | I25: SMC
C26: SPEED CON' | D26: AS2201F-01-06SA | E26: EA | F26: 2 | G26: 4290 | H26: =G26*F26 -> 8580 | I26: SMC
C27: LM GUIDE | D27: HSR25RQZ2UU-880L | E27: EA | F27: 1 | G27: 275000 | H27: =G27*F27 -> 275000 | I27: THK
C28: KNOB | D28: NKSM8-40 | E28: EA | F28: 2 | G28: 2968 | H28: =G28*F28 -> 5936 | I28: MISUMI
C29: MARKER PIN | D29: JPLB5-P8-B8 | E29: EA | F29: 2 | G29: 10550 | H29: =G29*F29 -> 21100 | I29: MISUMI
C30: SET COLLAR | D30: PSCS16-12 | E30: EA | F30: 2 | G30: 5500 | H30: =G30*F30 -> 11000 | I30: MISUMI
H31: =G31*F31 -> 0
B32: MASTER PART | C32: TOOL BOX | D32: RTP119T3D | E32: EA | F32: 1 | G32: 650000 | H32: =G32*F32 -> 650000 | I32: ROCKY
H33: =G33*F33 -> 0
H34: =G34*F34 -> 0
H35: =G35*F35 -> 0
H36: =G36*F36 -> 0
H37: =G37*F37 -> 0
C40: 기타자재 | E40: LOT | H40: =G40*F40 -> 0
H41: =SUM(H16:H40) -> 1454076
B42: 외주제작품 | H42: =G42*F42 -> 0
...

Sheet 단위장비8
A1: 3-8.단위장비명(전기제외): | C1: DOOR&COVER PART | I1: (첨부)
A2: 구분 | C2: 품 명 | D2: 규격 | E2: 단위 | F2: 수량 | G2: 단가(원) | H2: 금액(원) | I2: 原MAKER
A3: 자 재 비 | B3: 철자재 | H3: =IF(F3=0,G3,G3*F3) -> 0
H4: =IF(F4=0,G4,G4*F4) -> 0
H5: =IF(F5=0,G5,G5*F5) -> 0
H6: =IF(F6=0,G6,G6*F6) -> 0
H7: =IF(F7=0,G7,G7*F7) -> 0
H8: =IF(F8=0,G8,G8*F8) -> 0
H9: =IF(F9=0,G9,G9*F9) -> 0
H10: =IF(F10=0,G10,G10*F10) -> 0
H11: =IF(F11=0,G11,G11*F11) -> 0
H12: =IF(F12=0,G12,G12*F12) -> 0
H13: =IF(F13=0,G13,G13*F13) -> 0
H14: =IF(F14=0,G14,G14*F14) -> 0
H15: =IF(F15=0,G15,G15*F15) -> 0
... H26: =IF(F26=0,G26,G26*F26) -> 0
H27: 0
F28: =SUM(F3:F27) -> 0 | H28: =SUM(H3:H27) -> 0
B29: 구매품 | E29: EA | H29: =SUM(F29*G29) -> 0
B30: (유공압품외) | H30: =IF(F30=0,G30,G30*F30) -> 0
B31: BRUSHING M/C | C31: STAINLESS HINGE | D31: SHHPSD6-3 | E31: EA | F31: 12 | G31: 8880 | H31: =IF(F31=0,G31,G31*F31) -> 106560 | I31: MISUMI
B32: MC COVER | C32: PULL | D32: UWANG100 | E32: EA | F32: 4 | G32: 8151 | H32: =IF(F32=0,G32,G32*F32) -> 32604 | I32: MISUMI
C33: STAINLESS HAPS | D33: C1249-3 | E33: EA | F33: 4 | G33: 12000 | H33: =IF(F33=0,G33,G33*F33) -> 48000 | I33: TAKIGEN
C34: MAGNET CATCHES | D34: MGCE1 | E34: EA | F34: 8 | G34: 2498 | H34: =IF(F34=0,G34,G34*F34) -> 19984 | I34: MISUMI
H35: =IF(F35=0,G35,G35*F35) -> 0
H36: =IF(F36=0,G36,G36*F36) -> 0
H37: =IF(F37=0,G37,G37*F37) -> 0
B38: STRAIGHTENING M/C | C38: HASPS | D38: HSUKJ6 | E38: EA | F38: 2 | G38: 7952 | H38: =IF(F38=0,G38,G38*F38) -> 15904 | I38: MISUMI
B39: FRONT DOOR | C39: HINGE | D39: HHPSNA5 | E39: EA | F39: 8 | G39: 3908 | H39: =IF(F39=0,G39,G39*F39) -> 31264 | I39: MISUMI
C40: POOLS | D40: UPCN21-B-36 | E40: EA | F40: 4 | G40: 3752 | H40: =IF(F40=0,G40,G40*F40) -> 15008 | I40: MISUMI
C41: MAGNET | D41: MGCE2 | E41: EA | F41: 2 | G41: 4025 | H41: =IF(F41=0,G41,G41*F41) -> 8050 | I41: MISUMI
H45: =IF(F45=0,G45,G45*F45) -> 0
H46: =IF(F46=0,G46,G46*F46) -> 0
H47: =IF(F47=0,G47,G47*F47) -> 0
H48: =IF(F48=0,G48,G48*F48) -> 0
H49: =IF(F49=0,G49,G49*F49) -> 0
H50: =IF(F50=0,G50,G50*F50) -> 0
C51: 기타자재 | E51: SET
H52: =SUM(H29:H51) -> 277374
B53: 외주제작품 | H53: =G53*F53 -> 0
...

Sheet 단위장비9
A1: 3-9.단위장비명(전기제외): | C1: AIR CIRCUIT PART | I1: (첨부)
A2: 구분 | C2: 품 명 | D2: 규격 | E2: 단위 | F2: 수량 | G2: 단가(원) | H2: 금액(원) | I2: 原MAKER
A3: 자 재 비 | B3: 철자재 | C3: PLATE | E3: KG | F3: 50 | G3: 1200 | H3: =IF(F3=0,G3,G3*F3) -> 60000
H4: =IF(F4=0,G4,G4*F4) -> 0
H5: =IF(F5=0,G5,G5*F5) -> 0
H6: =IF(F6=0,G6,G6*F6) -> 0
H7: =IF(F7=0,G7,G7*F7) -> 0
H8: =IF(F8=0,G8,G8*F8) -> 0
H9: =IF(F9=0,G9,G9*F9) -> 0
H10: =IF(F10=0,G10,G10*F10) -> 0
H11: =IF(F11=0,G11,G11*F11) -> 0
H12: =IF(F12=0,G12,G12*F12) -> 0
H13: =IF(F13=0,G13,G13*F13) -> 0
H14: =IF(F14=0,G14,G14*F14) -> 0
H15: =IF(F15=0,G15,G15*F15) -> 0
... H18: =IF(F18=0,G18,G18*F18) -> 0
C19: 기타자재 | E19: KG | F19: 10 | G19: 6000 | H19: =IF(F19=0,G19,G19*F19) -> 60000
F20: =SUM(F3:F19) -> 60 | H20: =SUM(H3:H19) -> 120000
B21: 구매품 | H21: =IF(F21=0,G21,G21*F21) -> 0
B22: (유공압품외) | H22: =IF(F22=0,G22,G22*F22) -> 0
B23: BRUSHING M/C | C23: AIR UNIT | D23: AC40-04DM-SV | E23: EA | F23: 1 | G23: 167400 | H23: =IF(F23=0,G23,G23*F23) -> 167400 | I23: SMC
C24: SILENCER | D24: AN200-02 | E24: EA | F24: 2 | G24: 35400 | H24: =IF(F24=0,G24,G24*F24) -> 70800 | I24: SMC
C25: REGULATOR | D25: AR20K-02BM | E25: EA | F25: 2 | G25: 31000 | H25: =IF(F25=0,G25,G25*F25) -> 62000 | I25: SMC
C26: SOLENOIDE VALVE | D26: VFS2300-5FZA | E26: EA | F26: 1 | G26: 108000 | H26: =IF(F26=0,G26,G26*F26) -> 108000 | I26: SMC
C27: SOLENOIDE VALVE | D27: VFS2200-RFZA | E27: EA | F27: 4 | G27: 108900 | H27: =IF(F27=0,G27,G27*F27) -> 435600 | I27: SMC
C28: MANIFOLD | D28: VV5FS2-01T-081-02 | E28: EA | F28: 1 | G28: 254000 | H28: =IF(F28=0,G28,G28*F28) -> 254000 | I28: SMC
C29: SILENCER | D29: AN101-01 | E29: EA | F29: 2 | G29: 4400 | H29: =IF(F29=0,G29,G29*F29) -> 8800 | I29: SMC
C30: SILENCER | D30: AN400-04 | E30: EA | F30: 1 | G30: 23700 | H30: =IF(F30=0,G30,G30*F30) -> 23700 | I30: SMC
C31: BLANKING PLATE | D31: VVFS2000-10A | E31: EA | F31: 2 | G31: 7890 | H31: =IF(F31=0,G31,G31*F31) -> 15780 | I31: SMC
C32: SOLENOIDE VALVE | D32: VFS2100-5FZA | E32: EA | F32: 1 | G32: 69150 | H32: =IF(F32=0,G32,G32*F32) -> 69150 | I32: SMC
H33: =IF(F33=0,G33,G33*F33) -> 0
B34: STRAIGHTENING M/C | C34: AIR UNIT | D34: AC40-04DM-SV-A | E34: EA | F34: 1 | G34: 167800 | H34: =IF(F34=0,G34,G34*F34) -> 167800 | I34: SMC
C35: SOLENOIDE VALVE | D35: VFS2200-RFZA | E35: EA | F35: 8 | G35: 89500 | H35: =IF(F35=0,G35,G35*F35) -> 716000 | I35: SMC
C36: BLANKING PLATE | D36: VVFS2000-10A | E36: EA | F36: 2 | G36: 4990 | H36: =IF(F36=0,G36,G36*F36) -> 9980 | I36: SMC
C37: MANIFOLD | D37: VV5FS2-01T-101-02 | E37: EA | F37: 1 | G37: 288000 | H37: =IF(F37=0,G37,G37*F37) -> 288000 | I37: SMC
C38: SILENCER | D38: AN200-02 | E38: EA | F38: 3 | G38: 22000 | H38: =IF(F38=0,G38,G38*F38) -> 66000 | I38: SMC
C39: SILENCER | D39: AN101-01 | E39: EA | F39: 1 | G39: 4790 | H39: =IF(F39=0,G39,G39*F39) -> 4790 | I39: SMC
C40: REGULATOR | D40: AR20K-02BM | E40: EA | F40: 2 | G40: 55000 | H40: =IF(F40=0,G40,G40*F40) -> 110000 | I40: SMC
E41: 〃 | H41: =IF(F41=0,G41,G41*F41) -> 0
E42: 〃 | H42: =IF(F42=0,G42,G42*F42) -> 0
...

Sheet 단위장비10
A1: 3-10.단위장비명(전기제외): | I1: (첨부)
A2: 구분 | C2: 품 명 | D2: 규격 | E2: 단위 | F2: 수량 | G2: 단가(원) | H2: 금액(원) | I2: 原MAKER
A3: 자 재 비 | B3: 철자재 | C3: PLATE | E3: KG | H3: =IF(F3=0,G3,G3*F3) -> 0
C14: 기타자재 | E14: SET | H14: =IF(F14=0,G14,G14*F14) -> 0
F15: =SUM(F3:F14) -> 0 | H15: =SUM(H3:H14) -> 0
B16: 구매품 | E16: EA | H16: =SUM(F16*G16) -> 0 | I16: SMC
B17: (유공압품외) | E17: EA | H17: =SUM(F17*G17) -> 0 | I17: SMC
E18: EA | H18: =SUM(F18*G18) -> 0 | I18: SMC
E19: EA | H19: =SUM(F19*G19) -> 0 | I19: NSK
E20: EA | H20: =SUM(F20*G20) -> 0 | I20: KOYO
E21: EA | H21: =SUM(F21*G21) -> 0 | I21: KOYO
E22: EA | H22: =SUM(F22*G22) -> 0 | I22: LUBO
E23: EA | H23: =SUM(F23*G23) -> 0 | I23: MISUMI
E24: EA | H24: =SUM(F24*G24) -> 0 | I24: DONG IL
E25: EA | H25: =SUM(F25*G25) -> 0 | I25: SUMITOMO
E26: EA | H26: =SUM(F26*G26) -> 0 | I26: OMRON
E27: EA | H27: =SUM(F27*G27) -> 0 | I27: OMRON
E28: EA | H28: =SUM(F28*G28) -> 0 | I28: KS
E29: EA | H29: =SUM(F29*G29) -> 0 | I29: MISUMI
... E50: EA | H50: =SUM(F50*G50) -> 0 | I50: OMRON
H51: =SUM(F51*G51) -> 0
H52: =SUM(H16:H51) -> 0
B53: 외주제작품 | E53: EA | H53: =SUM(F53*G53) -> 0 | I53: KOREA KOKUSAI
E54: EA | H54: =SUM(F54*G54) -> 0 | I54: KOREA KOKUSAI
E55: EA | H55: =SUM(F55*G55) -> 0 | I55: KOREA KOKUSAI
E56: EA | H56: =SUM(F56*G56) -> 0 | I56: KOREA KOKUSAI
E57: EA | H57: =SUM(F57*G57) -> 0 | I57: KOREA KOKUSAI
E58: EA | H58: =SUM(F58*G58) -> 0 | I58: KOREA KOKUSAI
E59: EA | H59: =SUM(F59*G59) -> 0 | I59: KOREA KOKUSAI
E60: EA | H60: =SUM(F60*G60) -> 0 | I60: KOREA KOKUSAI
E61: EA | H61: =SUM(F61*G61) -> 0 | I61: KOREA KOKUSAI
E62: EA | H62: =SUM(F62*G62) -> 0 | I62: KOREA KOKUSAI
E63: EA | H63: =SUM(F63*G63) -> 0 | I63: KOREA KOKUSAI
E64: EA | H64: =SUM(F64*G64) -> 0 | I64: KOREA KOKUSAI
E65: EA | H65: =SUM(F65*G65) -> 0 | I65: KOREA KOKUSAI
... E129: EA | H129: =SUM(F129*G129) -> 0 | I129: KOREA KOKUSAI
H139: =SUM(H53:H138) -> 0
B140: 자재비 소계
A141: 노 무 비 | B141: 기존설비 철거 | E141: M/D | H141: =F141*G141 -> 0
B142: 기계 설계 | E142: M/D | G142: 350000 | H142: =F142*G142 -> 0
...

Sheet 단위장비11
A1: 3-11.단위장비명(전기제외): | I1: (첨부)
A2: 구분 | C2: 품 명 | D2: 규격 | E2: 단위 | F2: 수량 | G2: 단가(원) | H2: 금액(원) | I2: 原MAKER
A3: 자 재 비 | B3: 철자재 | H3: =IF(F3=0,G3,G3*F3) -> 0
H4: =IF(F4=0,G4,G4*F4) -> 0
H5: =IF(F5=0,G5,G5*F5) -> 0
H6: =IF(F6=0,G6,G6*F6) -> 0
H7: =IF(F7=0,G7,G7*F7) -> 0
H8: =IF(F8=0,G8,G8*F8) -> 0
H9: =IF(F9=0,G9,G9*F9) -> 0
H10: =IF(F10=0,G10,G10*F10) -> 0
H11: =IF(F11=0,G11,G11*F11) -> 0
H12: =IF(F12=0,G12,G12*F12) -> 0
H13: =IF(F13=0,G13,G13*F13) -> 0
H14: =IF(F14=0,G14,G14*F14) -> 0
H15: =IF(F15=0,G15,G15*F15) -> 0
... H27: =IF(F27=0,G27,G27*F27) -> 0
F28: =SUM(F3:F27) -> 0 | H28: =SUM(H3:H27) -> 0
B29: 구매품 | E29: EA | H29: =G29*F29 -> 0 | I29: SMC
B30: (유공압품외) | E30: 〃 | H30: =G30*F30 -> 0 | I30: 〃
E31: 〃 | H31: =G31*F31 -> 0 | I31: 〃
E32: 〃 | H32: =G32*F32 -> 0 | I32: 〃
E33: 〃 | H33: =IF(F33=0,G33,G33*F33) -> 0 | I33: 〃
E34: 〃 | H34: =IF(F34=0,G34,G34*F34) -> 0 | I34: 〃
E35: 〃 | H35: =IF(F35=0,G35,G35*F35) -> 0 | I35: 〃
E36: 〃 | H36: =IF(F36=0,G36,G36*F36) -> 0 | I36: 〃
E37: 〃 | H37: =IF(F37=0,G37,G37*F37) -> 0 | I37: 〃
E38: 〃 | H38: =IF(F38=0,G38,G38*F38) -> 0 | I38: 〃
E39: 〃 | H39: =IF(F39=0,G39,G39*F39) -> 0 | I39: 〃
E40: 〃 | H40: =IF(F40=0,G40,G40*F40) -> 0 | I40: 〃
E41: 〃 | H41: =IF(F41=0,G41,G41*F41) -> 0 | I41: 〃
E42: 〃 | H42: =IF(F42=0,G42,G42*F42) -> 0 | I42: 〃
E43: 〃 | H43: =IF(F43=0,G43,G43*F43) -> 0 | I43: 〃
E44: 〃 | H44: =IF(F44=0,G44,G44*F44) -> 0 | I44: 〃
... E50: 〃 | H50: =IF(F50=0,G50,G50*F50) -> 0 | I50: 〃
C52: 기타 배관자재 | E52: SET | F52: 1
H53: =SUM(H29:H52) -> 0
B54: 외주제작품 | H54: =IF(F54=0,G54,G54*F54) -> 0
H55: =IF(F55=0,G55,G55*F55) -> 0
H56: =IF(F56=0,G56,G56*F56) -> 0
H57: =IF(F57=0,G57,G57*F57) -> 0
...

Sheet 단위장비12
A1: 3-12.단위장비명(전기제외): | I1: (첨부)
A2: 구분 | C2: 품 명 | D2: 규격 | E2: 단위 | F2: 수량 | G2: 단가(원) | H2: 금액(원) | I2: 原MAKER
A3: 자 재 비 | B3: 철자재 | H3: =IF(F3=0,G3,G3*F3) -> 0
H4: =IF(F4=0,G4,G4*F4) -> 0
H5: =IF(F5=0,G5,G5*F5) -> 0
H6: =IF(F6=0,G6,G6*F6) -> 0
H7: =IF(F7=0,G7,G7*F7) -> 0
H8: =IF(F8=0,G8,G8*F8) -> 0
H9: =IF(F9=0,G9,G9*F9) -> 0
H10: =IF(F10=0,G10,G10*F10) -> 0
H11: =IF(F11=0,G11,G11*F11) -> 0
H12: =IF(F12=0,G12,G12*F12) -> 0
H13: =IF(F13=0,G13,G13*F13) -> 0
H14: =IF(F14=0,G14,G14*F14) -> 0
H15: =IF(F15=0,G15,G15*F15) -> 0
... H21: =IF(F21=0,G21,G21*F21) -> 0
H22: 0
F23: =SUM(F3:F22) -> 0 | H23: =SUM(H3:H22) -> 0
B24: 구매품 | E24: EA | H24: =F24*G24 -> 0 | I24: JAPAN KOKUSAI
B25: (유공압품외) | I25: 〃
I26: 〃
I27: 〃
I28: 〃
I29: 〃
I30: 〃
I31: 〃
H32: =G32*F32 -> 0 | I32: 〃
I33: 〃
I34: 〃
H35: =SUM(F35*G35) -> 0 | I35: 〃
I36: 〃
I37: 〃
H38: =F38*G38 -> 0 | I38: 〃
H39: =F39*G39 -> 0 | I39: 〃
H40: =F40*G40 -> 0 | I40: 〃
H41: =F41*G41 -> 0 | I41: 〃
H42: =F42*G42 -> 0 | I42: 〃
H43: =F43*G43 -> 0 | I43: 〃
I44: 〃
H45: =SUM(F45*G45) -> 0 | I45: 〃
...

Sheet 단위장비13
A1: 3-13.단위장비명(전기제외): | I1: (첨부)
A2: 구분 | C2: 품 명 | D2: 규격 | E2: 단위 | F2: 수량 | G2: 단가(원) | H2: 금액(원) | I2: 原MAKER
A3: 자 재 비 | B3: 철자재 | C3: PLATE | E3: KG | H3: =IF(F3=0,G3,G3*F3) -> 0
H12: =IF(F12=0,G12,G12*F12) -> 0
C13: 기타자재 | E13: SET
F14: =SUM(F3:F13) -> 0 | H14: =SUM(H3:H13) -> 0
B15: 구매품
B16: (유공압품외)
H34: =SUM(H15:H33) -> 0
B35: 외주제작품 | E35: EA | H35: =SUM(F35*G35) -> 0 | I35: Korea kokusai
E36: 〃 | H36: =SUM(F36*G36) -> 0 | I36: 〃
E37: 〃 | I37: 〃
E41: 식
H42: =SUM(H35:H41) -> 0
B43: 자재비 소계 | H43: =SUM(H42,H34,H14) -> 0
A44: 노 무 비 | B44: 기존설비 철거 | E44: M/D | H44: =F44*G44 -> 0
B45: 기계 설계 | E45: M/D | G45: 350000 | H45: =G45*F45 -> 0
B46: 기계 제작(제관,가공) | E46: M/D | G46: 350000 | H46: =G46*F46 -> 0
B47: 기계 조립 | E47: M/D | G47: 350000 | H47: =G47*F47 -> 0
B48: 기계 설치 | E48: M/D | G48: 450000 | H48: =G48*F48 -> 0
B49: 기계 시운전 | E49: M/D | G49: 450000 | H49: =G49*F49 -> 0
B50: 기계 양산대응 | E50: M/D | G50: 450000 | H50: =G50*F50 -> 0
B51: 기계 도장 | E51: M/D | G51: 300000 | H51: =G51*F51 -> 0
B52: 노무비 소계 | H52: =SUM(H44:H51) -> 0
B53: 운반및중장비사용,표준안전관리비 | H53: ='단위장비별(집계)2'!L19+'단위장비별(집계)2'!I19 -> 0
B54: 일반관리비 | H54: =(H43+H52)*0.05 -> 0
B55: 이 윤 | H55: =(H43+H52)*0.1 -> 0
B56: 합 계 | H56: =H43+H52+H53+H54+H55 -> 0

Sheet 단위장비14
A1: 3-14.단위장비명(전기제외): | I1: (첨부)
A2: 구분 | C2: 품 명 | D2: 규격 | E2: 단위 | F2: 수량 | G2: 단가(원) | H2: 금액(원) | I2: 原MAKER
A3: 자 재 비 | B3: 철자재
H14: =SUM(H3:H13) -> 0
B15: 구매품 | E15: SET
B16: (유공압품외) | E16: EA
E17: EA
E18: SET
E19: EA
E20: EA
E21: EA
E22: EA
H33: =SUM(H15:H32) -> 0
B34: 외주제작품
H35: =G35*F35 -> 0
H36: =G36*F36 -> 0
H37: =G37*F37 -> 0
H45: =SUM(H34:H44) -> 0
B46: 자재비 소계 | H46: =SUM(H45,H33,H14) -> 0
A47: 노 무 비 | B47: 기존설비 철거 | E47: M/D | G47: 450000 | H47: =F47*G47 -> 0
B48: 전기 설계 | E48: M/D | G48: 350000 | H48: =SUM(F48*G48) -> 0
B49: 전기 제작(제관,가공) | E49: M/D | G49: 350000 | H49: =SUM(F49*G49) -> 0
B50: 전기 조립 | E50: M/D | G50: 350000 | H50: =SUM(F50*G50) -> 0
B51: 전기 설치 | E51: M/D | G51: 450000 | H51: =SUM(F51*G51) -> 0
B52: 시운전 | E52: M/D | G52: 450000 | H52: =SUM(F52*G52) -> 0
B53: 양산대응 | E53: M/D | G53: 450000 | H53: =SUM(F53*G53) -> 0
B54: 기계 도장 | E54: M/D | G54: 300000 | H54: =SUM(F54*G54) -> 0
B55: 노무비 소계 | H55: =SUM(H47:H54) -> 0
