Workbook

Sheet 갑지
B1: (현대/기아차 설비협력업체 견적통일양식)
B2: 見 積 書
B4: 현대 위아 貴下 | G4: ㈜지이엠
B5: 견적일자 | D5: 43787 | G5: 대표 : 송 칠 영 (인)
B6: 견적번호 | D6: GD1_191118-001 | G6: 주소 : 경남 창원시 성산구
B7: 납기 | C7: 입하 | G7: 성산패총로24번길 1
C8: 최종검수 | G8: 전화: 055-282-9488
B9: 견적유효기간 | D9: 견적일로부터30일 | G9: Fax: 055-282-9484 / 9490
B10: 인도장소 | D10: 현대위아 공장 | G10: 견적담당: | H10: 정대헌부장
B11: 지불조건 | D11: 현대위아 기준 | G11: 연 락 처 : | H11: 010-3452-0737
B13: 견적금액: 一金이십이억육천팔백만원整(\2,268,000,000 )
B15: 번호 | C15: 상세품목내역 | E15: 견적금액 (천원) | I15: 비 고
E16: 기계부분 | F16: 전기부문 | G16: 관리/이윤 (안전관리비포함) | H16: 합 계
B17: 1 | C17: =IF('단위공사별(집계)'!N7>0,'단위공사별(집계)'!B7,"") -> 허브 아웃터 공급장치 | E17: =IF('단위공사별(집계)'!N7>1,('단위공사별(집계)'!D7+'단위공사별(집계)'!E7+'단위공사별(집계)'!F7+'단위공사별(집계)'!G7+'단위공사별(집계)'!H7+'단위공사별(집계)'!I7)/1000," ") -> 109041.85 | F17: =IF('단위공사별(집계)'!N7>0,'단위공사별(집계)'!K37/1000,"") -> 362300 | G17: =IF('단위공사별(집계)'!N7>0,('단위공사별(집계)'!L7+'단위공사별(집계)'!M7)/1000,"") -> 166.57667 | H17: =IF('단위공사별(집계)'!N7>0,'단위공사별(집계)'!N7/1000,"") -> 129961.77
B18: 2 | C18: =IF('단위공사별(집계)'!N8>0,'단위공사별(집계)'!B8,"") -> O/B선별기 | E18: =IF('단위공사별(집계)'!N8>1,('단위공사별(집계)'!D8+'단위공사별(집계)'!E8+'단위공사별(집계)'!F8+'단위공사별(집계)'!G8+'단위공사별(집계)'!H8+'단위공사별(집계)'!I8)/1000," ") -> 43308.252 | G18: =IF('단위공사별(집계)'!N8>0,('단위공사별(집계)'!L8+'단위공사별(집계)'!M8)/1000,"") -> 66.159414 | H18: =IF('단위공사별(집계)'!N8>0,'단위공사별(집계)'!N8/1000,"") -> 51617.038
B19: 3 | C19: =IF('단위공사별(집계)'!N9>0,'단위공사별(집계)'!B9,"") -> GRV정렬 | E19: =IF('단위공사별(집계)'!N9>1,('단위공사별(집계)'!D9+'단위공사별(집계)'!E9+'단위공사별(집계)'!F9+'단위공사별(집계)'!G9+'단위공사별(집계)'!H9+'단위공사별(집계)'!I9)/1000," ") -> 22675.736 | G19: =IF('단위공사별(집계)'!N9>0,('단위공사별(집계)'!L9+'단위공사별(집계)'!M9)/1000,"") -> 34.640359 | H19: =IF('단위공사별(집계)'!N9>0,'단위공사별(집계)'!N9/1000,"") -> 27026.127
B20: 4 | C20: =IF('단위공사별(집계)'!N10>0,'단위공사별(집계)'!B10,"") -> 선별기 | E20: =IF('단위공사별(집계)'!N10>1,('단위공사별(집계)'!D10+'단위공사별(집계)'!E10+'단위공사별(집계)'!F10+'단위공사별(집계)'!G10+'단위공사별(집계)'!H10+'단위공사별(집계)'!I10)/1000," ") -> 37268.734 | G20: =IF('단위공사별(집계)'!N10>0,('단위공사별(집계)'!L10+'단위공사별(집계)'!M10)/1000,"") -> 56.933205 | H20: =IF('단위공사별(집계)'!N10>0,'단위공사별(집계)'!N10/1000,"") -> 44418.824
B21: 5 | C21: =IF('단위공사별(집계)'!N11>0,'단위공사별(집계)'!B11,"") -> 마킹 | E21: =IF('단위공사별(집계)'!N11>1,('단위공사별(집계)'!D11+'단위공사별(집계)'!E11+'단위공사별(집계)'!F11+'단위공사별(집계)'!G11+'단위공사별(집계)'!H11+'단위공사별(집계)'!I11)/1000," ") -> 31409.5 | G21: =IF('단위공사별(집계)'!N11>0,('단위공사별(집계)'!L11+'단위공사별(집계)'!M11)/1000,"") -> 47.982405 | H21: =IF('단위공사별(집계)'!N11>0,'단위공사별(집계)'!N11/1000,"") -> 37435.483
B22: 6 | C22: =IF('단위공사별(집계)'!N12>0,'단위공사별(집계)'!B12,"") -> 허버볼트 공급장치 | E22: =IF('단위공사별(집계)'!N12>1,('단위공사별(집계)'!D12+'단위공사별(집계)'!E12+'단위공사별(집계)'!F12+'단위공사별(집계)'!G12+'단위공사별(집계)'!H12+'단위공사별(집계)'!I12)/1000," ") -> 99677.088 | G22: =IF('단위공사별(집계)'!N12>0,('단위공사별(집계)'!L12+'단위공사별(집계)'!M12)/1000,"") -> 152.27069 | H22: =IF('단위공사별(집계)'!N12>0,'단위공사별(집계)'!N12/1000,"") -> 118800.36
B23: 7 | C23: =IF('단위공사별(집계)'!N13>0,'단위공사별(집계)'!B13,"") -> BOLT압입 | E23: =IF('단위공사별(집계)'!N13>1,('단위공사별(집계)'!D13+'단위공사별(집계)'!E13+'단위공사별(집계)'!F13+'단위공사별(집계)'!G13+'단위공사별(집계)'!H13+'단위공사별(집계)'!I13)/1000," ") -> 105416.13 | G23: =IF('단위공사별(집계)'!N13>0,('단위공사별(집계)'!L13+'단위공사별(집계)'!M13)/1000,"") -> 161.03789 | H23: =IF('단위공사별(집계)'!N13>0,'단위공사별(집계)'!N13/1000,"") -> 125640.45
B24: 8 | C24: =IF('단위공사별(집계)'!N14>0,'단위공사별(집계)'!B14,"") -> 허버볼트 직각도 검사 | E24: =IF('단위공사별(집계)'!N14>1,('단위공사별(집계)'!D14+'단위공사별(집계)'!E14+'단위공사별(집계)'!F14+'단위공사별(집계)'!G14+'단위공사별(집계)'!H14+'단위공사별(집계)'!I14)/1000," ") -> 72804.738 | G24: =IF('단위공사별(집계)'!N14>0,('단위공사별(집계)'!L14+'단위공사별(집계)'!M14)/1000,"") -> 111.21942 | H24: =IF('단위공사별(집계)'!N14>0,'단위공사별(집계)'!N14/1000,"") -> 86772.49
B25: 9 | C25: =IF('단위공사별(집계)'!N15>0,'단위공사별(집계)'!B15,"") -> 베어링 공급 및 압입기 | E25: =IF('단위공사별(집계)'!N15>1,('단위공사별(집계)'!D15+'단위공사별(집계)'!E15+'단위공사별(집계)'!F15+'단위공사별(집계)'!G15+'단위공사별(집계)'!H15+'단위공사별(집계)'!I15)/1000," ") -> 130195.18 | G25: =IF('단위공사별(집계)'!N15>0,('단위공사별(집계)'!L15+'단위공사별(집계)'!M15)/1000,"") -> 198.89135 | H25: =IF('단위공사별(집계)'!N15>0,'단위공사별(집계)'!N15/1000,"") -> 155173.42
B26: 10 | C26: =IF('단위공사별(집계)'!N16>0,'단위공사별(집계)'!B16,"") -> 로크너트가체결/체결 | E26: =IF('단위공사별(집계)'!N16>1,('단위공사별(집계)'!D16+'단위공사별(집계)'!E16+'단위공사별(집계)'!F16+'단위공사별(집계)'!G16+'단위공사별(집계)'!H16+'단위공사별(집계)'!I16)/1000," ") -> 73455.764 | G26: =IF('단위공사별(집계)'!N16>0,('단위공사별(집계)'!L16+'단위공사별(집계)'!M16)/1000,"") -> 112.21395 | H26: =IF('단위공사별(집계)'!N16>0,'단위공사별(집계)'!N16/1000,"") -> 87548.417
B27: 11 | C27: =IF('단위공사별(집계)'!N17>0,'단위공사별(집계)'!B17,"") -> 로크링조립 및 로크링볼트체결 | E27: =IF('단위공사별(집계)'!N17>1,('단위공사별(집계)'!D17+'단위공사별(집계)'!E17+'단위공사별(집계)'!F17+'단위공사별(집계)'!G17+'단위공사별(집계)'!H17+'단위공사별(집계)'!I17)/1000," ") -> 59583.902 | G27: =IF('단위공사별(집계)'!N17>0,('단위공사별(집계)'!L17+'단위공사별(집계)'!M17)/1000,"") -> 91.022746 | H27: =IF('단위공사별(집계)'!N17>0,'단위공사별(집계)'!N17/1000,"") -> 71015.207
B28: 12 | C28: =IF('단위공사별(집계)'!N18>0,'단위공사별(집계)'!B18,"") -> 휠가이드공급 및 압입 | E28: =IF('단위공사별(집계)'!N18>1,('단위공사별(집계)'!D18+'단위공사별(집계)'!E18+'단위공사별(집계)'!F18+'단위공사별(집계)'!G18+'단위공사별(집계)'!H18+'단위공사별(집계)'!I18)/1000," ") -> 87107.278 | G28: =IF('단위공사별(집계)'!N18>0,('단위공사별(집계)'!L18+'단위공사별(집계)'!M18)/1000,"") -> 133.06855 | H28: =IF('단위공사별(집계)'!N18>0,'단위공사별(집계)'!N18/1000,"") -> 103819
B29: 13 | C29: =IF('단위공사별(집계)'!N19>0,'단위공사별(집계)'!B19,"") -> BUFFER CON'V | E29: =IF('단위공사별(집계)'!N19>1,('단위공사별(집계)'!D19+'단위공사별(집계)'!E19+'단위공사별(집계)'!F19+'단위공사별(집계)'!G19+'단위공사별(집계)'!H19+'단위공사별(집계)'!I19)/1000," ") -> 67125.788 | G29: =IF('단위공사별(집계)'!N19>0,('단위공사별(집계)'!L19+'단위공사별(집계)'!M19)/1000,"") -> 102.54403 | H29: =IF('단위공사별(집계)'!N19>0,'단위공사별(집계)'!N19/1000,"") -> 80004.021
... B46: 30 | C46: =IF('단위공사별(집계)'!N36>0,'단위공사별(집계)'!B36,"") -> LMS/RFID | E46: =IF('단위공사별(집계)'!N36>1,('단위공사별(집계)'!D36+'단위공사별(집계)'!E36+'단위공사별(집계)'!F36+'단위공사별(집계)'!G36+'단위공사별(집계)'!H36+'단위공사별(집계)'!I36)/1000," ") -> 55086.815 | G46: =IF('단위공사별(집계)'!N36>0,('단위공사별(집계)'!L36+'단위공사별(집계)'!M36)/1000,"") -> 84.152816 | H46: =IF('단위공사별(집계)'!N36>0,'단위공사별(집계)'!N36/1000,"") -> 65655.344
B47: 견적 합계 | E47: =SUM(E17:E46) -> 1903590 | F47: =SUM(F17:F46) -> 362300 | G47: =SUM(G17:G46) -> 2908 | H47: =ROUNDDOWN(SUM(H17:H46),-3) -> 2268000
F49: 공개입찰가 (견적時 공란) | H49: 2268000
B51: 특기사항 | C51: 1. VAT 제외 | F51: 외주계획 업체명 (자작時 공란)
C52: 2. 기본 유틸리티공사 제외 | F52: 설계외주
C53: ='원가항목별(집계)'!I39 -> 2908000 | F53: 제작외주
F54: 전기외주
F55: 설치외주

Sheet 원가항목별(집계)
C2: A. 원가항목별 견적가 종합(상세견적 첨부)
B4: □ 현대/기아 요구사양과 견적조건 일치여부 CHECK: 1.일치함 2.일부상이(상이내역 첨부참조)
B6: 순번 | C6: 원가구분 | F6: 단위 | G6: 수량 | H6: 단가 | I6: 금 액(원) | J6: 비 고
B7: 1 | C7: 기계 부문 | D7: 자재비 | E7: 철자재(SS.SUS등) | F7: kg | G7: ='#10'!F19+'#20'!F17+'#30'!F19+'#40'!F19+'#50'!F17+'#60'!F20+'#70'!F19+'#80'!F19+'#90'!F18+'#100'!F21+'#110'!F18+'#120'!F21+'#130'!F19+'#140'!F20+'#150'!F22+'#160'!F18+'#170'!F19+'#180'!F18+'#190'!F19+'#200'!F18+'#210'!G17+'#220'!F17+'#230'!F19+'#240'!F19+'[1]#250'!F17+'[1]#260'!F20+'[1]#270'!F20+'[1]#280'!F19+'[1]#290'!F18+'[1]#300'!F18 -> 0 | I7: ='#10'!H16+'#20'!H14+'#30'!H13+'#40'!H13+'#50'!H13+'#60'!H14+'#70'!H13+'#80'!H13+'#90'!H14+'#100'!H15+'#110'!H12+'#120'!H15+'#130'!H13+'#140'!H14+'#150'!H16+'#160'!H12+'#170'!H13+'#180'!H12+'#190'!H13+'#200'!H12+'#210'!H11+'#220'!H14+'#230'!H13+'#240'!H13+'[1]#250'!H13+'[1]#260'!H14+'[1]#270'!H14+'[1]#280'!H13+'[1]#290'!H12+'[1]#300'!H12 -> 479260000 | J7: 加工必要資材
E8: 일반구매품 | F8: 식 | G8: 1 | I8: ='#10'!H50+'#20'!H33+'#30'!H34+'#40'!H39+'#50'!H32+'#60'!H42+'#70'!H45+'#80'!H38+'#90'!H53+'#100'!H44+'#110'!H40+'#120'!H56+'#130'!H38+'#140'!H35+'#150'!H57+'#160'!H38+'#170'!H43+'#180'!H40+'#190'!H41+'#200'!H35+'#210'!H36+'#220'!H40+'#230'!H41+'#240'!H39+'[1]#250'!H40+'[1]#260'!H42+'[1]#270'!H42+'[1]#280'!H38+'[1]#290'!H40+'[1]#300'!H40 -> 800230000 | J8: 加工不要資材
E9: 외주제작품 | F9: 식 | G9: 1 | I9: ='#10'!H54+'#20'!H41+'#30'!H39+'#40'!H47+'#50'!H35+'#60'!H50+'#70'!H53+'#80'!H46+'#90'!H61+'#100'!H52+'#110'!H48+'#120'!H64+'#130'!H46+'#140'!H40+'#150'!H65+'#160'!H46+'#170'!H51+'#180'!H48+'#190'!H49+'#200'!H43+'#210'!H44+'#220'!H48+'#230'!H49+'#240'!H47+'[1]#250'!H48+'[1]#260'!H50+'[1]#270'!H50+'[1]#280'!H46+'[1]#290'!H48+'[1]#300'!H48 -> 113000000 | J9: 旣加工SUB資材
E10: 설치/해체 공사 자재 | F10: 식 | G10: 1 | I10: ='#10'!H19+'#20'!H17+'#30'!H19+'#40'!H19+'#50'!H17+'#60'!H20+'#70'!H19+'#80'!H19+'#90'!H18+'#100'!H21+'#110'!H18+'#120'!H21+'#130'!H19+'#140'!H20+'#150'!H22+'#160'!H18+'#170'!H19+'#180'!H18+'#190'!H19+'#200'!H18+'#210'!H17+'#220'!H17+'#230'!H19+'#240'!H19+'[1]#250'!H17+'[1]#260'!H20+'[1]#270'!H20+'[1]#280'!H19+'[1]#290'!H18+'[1]#300'!H18 -> 0 | J10: 시운전 자재 포함
E11: 소계 | I11: =SUM(I7:I10) -> 1392490000
D12: 노무비 | E12: 기존설비 철거 | F12: M/D | G12: ='#10'!F56+'#20'!F43+'#30'!F41+'#40'!F49+'#50'!F37+'#60'!F52+'#70'!F55+'#80'!F48+'#90'!F63+'#100'!F54+'#110'!F50+'#120'!F66+'#130'!F48+'#140'!F42+'#150'!F67+'#160'!F48+'#170'!F53+'#180'!F50+'#190'!F51+'#200'!F45+'#210'!F46+'#220'!F50+'#230'!F51+'#240'!F49+'[1]#250'!F50+'[1]#260'!F52+'[1]#270'!F52+'[1]#280'!F48+'[1]#290'!F50+'[1]#300'!F50 -> 0 | H12: =IF('#10'!G56>0,'#10'!G56,"") -> 250000 | I12: ='#10'!H56+'#20'!H43+'#30'!H41+'#40'!H49+'#50'!H37+'#60'!H52+'#70'!H55+'#80'!H48+'#90'!H63+'#100'!H54+'#110'!H50+'#120'!H66+'#130'!H48+'#140'!H42+'#150'!H67+'#160'!H48+'#170'!H53+'#180'!H50+'#190'!H51+'#200'!H45 -> 0 | J12: 개조공사時
E13: 설계 | F13: M/D | G13: ='#10'!F57+'#20'!F44+'#30'!F42+'#40'!F50+'#50'!F38+'#60'!F53+'#70'!F56+'#80'!F49+'#90'!F64+'#100'!F55+'#110'!F51+'#120'!F67+'#130'!F49+'#140'!F43+'#150'!F68+'#160'!F49+'#170'!F54+'#180'!F51+'#190'!F52+'#200'!F46+'#210'!F47+'#220'!F51+'#230'!F52+'#240'!F50+'[1]#250'!F51+'[1]#260'!F53+'[1]#270'!F53+'[1]#280'!F49+'[1]#290'!F51+'[1]#300'!F51 -> 690 | H13: =IF('#10'!G57>0,'#10'!G57,"") -> 300000 | I13: ='#10'!H57+'#20'!H44+'#30'!H42+'#40'!H50+'#50'!H38+'#60'!H53+'#70'!H56+'#80'!H49+'#90'!H64+'#100'!H55+'#110'!H51+'#120'!H67+'#130'!H49+'#140'!H43+'#150'!H68+'#160'!H49+'#170'!H54+'#180'!H51+'#190'!H52+'#200'!H46+'#210'!H47+'#220'!H51+'#230'!H52+'#240'!H50+'[1]#250'!H51+'[1]#260'!H53+'[1]#270'!H53+'[1]#280'!H49+'[1]#290'!H51+'[1]#300'!H51 -> 207000000
E14: 제작(제관,가공) | F14: M/D | G14: ='#10'!F58+'#20'!F45+'#30'!F43+'#40'!F51+'#50'!F39+'#60'!F54+'#70'!F57+'#80'!F50+'#90'!F65+'#100'!F56+'#110'!F52+'#120'!F68+'#130'!F50+'#140'!F44+'#150'!F69+'#160'!F50+'#170'!F55+'#180'!F52+'#190'!F53+'#200'!F47+'#210'!F48+'#220'!F52+'#230'!F53+'#240'!F51+'[1]#250'!F52+'[1]#260'!F54+'[1]#270'!F54+'[1]#280'!F50+'[1]#290'!F52+'[1]#300'!F52 -> 97 | H14: =IF('#10'!G58>0,'#10'!G58,"") -> 250000 | I14: ='#10'!H58+'#20'!H45+'#30'!H43+'#40'!H51+'#50'!H39+'#60'!H54+'#70'!H57+'#80'!H50+'#90'!H65+'#100'!H56+'#110'!H52+'#120'!H68+'#130'!H50+'#140'!H44+'#150'!H69+'#160'!H50+'#170'!H55+'#180'!H52+'#190'!H53+'#200'!H47+'#210'!H48+'#220'!H52+'#230'!H53+'#240'!H51+'[1]#250'!H52+'[1]#260'!H54+'[1]#270'!H54+'[1]#280'!H50+'[1]#290'!H52+'[1]#300'!H52 -> 24250000
E15: 조립 | F15: M/D | G15: ='#10'!F59+'#20'!F46+'#30'!F44+'#40'!F52+'#50'!F40+'#60'!F55+'#70'!F58+'#80'!F51+'#90'!F66+'#100'!F57+'#110'!F53+'#120'!F69+'#130'!F51+'#140'!F45+'#150'!F70+'#160'!F51+'#170'!F56+'#180'!F53+'#190'!F54+'#200'!F48+'#210'!F49+'#220'!F53+'#230'!F54+'#240'!F52+'[1]#250'!F53+'[1]#260'!F55+'[1]#270'!F55+'[1]#280'!F51+'[1]#290'!F53+'[1]#300'!F53 -> 715 | H15: =IF('#10'!G59>0,'#10'!G59,"") -> 250000 | I15: ='#10'!H59+'#20'!H46+'#30'!H44+'#40'!H52+'#50'!H40+'#60'!H55+'#70'!H58+'#80'!H51+'#90'!H66+'#100'!H57+'#110'!H53+'#120'!H69+'#130'!H51+'#140'!H45+'#150'!H70+'#160'!H51+'#170'!H56+'#180'!H53+'#190'!H54+'#200'!H48+'#210'!H49+'#220'!H53+'#230'!H54+'#240'!H52+'[1]#250'!H53+'[1]#260'!H55+'[1]#270'!H55+'[1]#280'!H51+'[1]#290'!H53+'[1]#300'!H53 -> 178750000 | J15: 정도검사포함
E16: 설치 | F16: M/D | G16: ='#10'!F60+'#20'!F47+'#30'!F45+'#40'!F53+'#50'!F41+'#60'!F56+'#70'!F59+'#80'!F52+'#90'!F67+'#100'!F58+'#110'!F54+'#120'!F70+'#130'!F52+'#140'!F46+'#150'!F71+'#160'!F52+'#170'!F57+'#180'!F54+'#190'!F55+'#200'!F49+'#210'!F50+'#220'!F54+'#230'!F55+'#240'!F53+'[1]#250'!F54+'[1]#260'!F56+'[1]#270'!F56+'[1]#280'!F52+'[1]#290'!F54+'[1]#300'!F54 -> 86 | H16: =IF('#10'!G60>0,'#10'!G60,"") -> 300000 | I16: ='#10'!H60+'#20'!H47+'#30'!H45+'#40'!H53+'#50'!H41+'#60'!H56+'#70'!H59+'#80'!H52+'#90'!H67+'#100'!H58+'#110'!H54+'#120'!H70+'#130'!H52+'#140'!H46+'#150'!H71+'#160'!H52+'#170'!H57+'#180'!H54+'#190'!H55+'#200'!H49+'#210'!H50+'#220'!H54+'#230'!H55+'#240'!H53+'[1]#250'!H54+'[1]#260'!H56+'[1]#270'!H56+'[1]#280'!H52+'[1]#290'!H54+'[1]#300'!H54 -> 25800000
E17: 시운전 | F17: M/D | G17: ='#10'!F61+'#20'!F48+'#30'!F46+'#40'!F54+'#50'!F42+'#60'!F57+'#70'!F60+'#80'!F53+'#90'!F68+'#100'!F59+'#110'!F55+'#120'!F71+'#130'!F53+'#140'!F47+'#150'!F72+'#160'!F53+'#170'!F58+'#180'!F55+'#190'!F56+'#200'!F50+'#210'!F51+'#220'!F55+'#230'!F56+'#240'!F54+'[1]#250'!F55+'[1]#260'!F57+'[1]#270'!F57+'[1]#280'!F53+'[1]#290'!F55+'[1]#300'!F55 -> 117 | H17: =IF('#10'!G61>0,'#10'!G61,"") -> 300000 | I17: ='#10'!H61+'#20'!H48+'#30'!H46+'#40'!H54+'#50'!H42+'#60'!H57+'#70'!H60+'#80'!H53+'#90'!H68+'#100'!H59+'#110'!H55+'#120'!H71+'#130'!H53+'#140'!H47+'#150'!H72+'#160'!H53+'#170'!H58+'#180'!H55+'#190'!H56+'#200'!H50+'#210'!H51+'#220'!H55+'#230'!H56+'#240'!H54+'[1]#250'!H55+'[1]#260'!H57+'[1]#270'!H57+'[1]#280'!H53+'[1]#290'!H55+'[1]#300'!H55 -> 35100000
E18: 양산대응 | F18: M/D | G18: ='#10'!F62+'#20'!F49+'#30'!F47+'#40'!F55+'#50'!F43+'#60'!F58+'#70'!F61+'#80'!F54+'#90'!F69+'#100'!F60+'#110'!F56+'#120'!F72+'#130'!F54+'#140'!F48+'#150'!F73+'#160'!F54+'#170'!F59+'#180'!F56+'#190'!F57+'#200'!F51+'#210'!F52+'#220'!F56+'#230'!F57+'#240'!F55+'[1]#250'!F56+'[1]#260'!F58+'[1]#270'!F58+'[1]#280'!F54+'[1]#290'!F56+'[1]#300'!F56 -> 49 | H18: =IF('#10'!G62>0,'#10'!G62,"") -> 300000 | I18: ='#10'!H62+'#20'!H49+'#30'!H47+'#40'!H55+'#50'!H43+'#60'!H58+'#70'!H61+'#80'!H54+'#90'!H69+'#100'!H60+'#110'!H56+'#120'!H72+'#130'!H54+'#140'!H48+'#150'!H73+'#160'!H54+'#170'!H59+'#180'!H56+'#190'!H57+'#200'!H51+'#210'!H52+'#220'!H56+'#230'!H57+'#240'!H55+'[1]#250'!H56+'[1]#260'!H58+'[1]#270'!H58+'[1]#280'!H54+'[1]#290'!H56+'[1]#300'!H56 -> 14700000
E19: 도장 | F19: M/D | G19: ='#10'!F63+'#20'!F50+'#30'!F48+'#40'!F56+'#50'!F44+'#60'!F59+'#70'!F62+'#80'!F55+'#90'!F70+'#100'!F61+'#110'!F57+'#120'!F73+'#130'!F55+'#140'!F49+'#150'!F74+'#160'!F55+'#170'!F60+'#180'!F57+'#190'!F58+'#200'!F52+'#210'!F53+'#220'!F57+'#230'!F58+'#240'!F56+'[1]#250'!F57+'[1]#260'!F59+'[1]#270'!F59+'[1]#280'!F55+'[1]#290'!F57+'[1]#300'!F57 -> 90 | H19: =IF('#10'!G63>0,'#10'!G63,"") -> 250000 | I19: ='#10'!H63+'#20'!H50+'#30'!H48+'#40'!H56+'#50'!H44+'#60'!H59+'#70'!H62+'#80'!H55+'#90'!H70+'#100'!H61+'#110'!H57+'#120'!H73+'#130'!H55+'#140'!H49+'#150'!H74+'#160'!H55+'#170'!H60+'#180'!H57+'#190'!H58+'#200'!H52+'#210'!H53+'#220'!H57+'#230'!H58+'#240'!H56+'[1]#250'!H57+'[1]#260'!H59+'[1]#270'!H59+'[1]#280'!H55+'[1]#290'!H57+'[1]#300'!H57 -> 22500000
E20: 소계 | I20: =SUM(I12:I19) -> 508100000
D21: 일반관리 및 이윤 | I21: ='#10'!H66+'#10'!H67+'#20'!H53+'#20'!H54+'#30'!H51+'#30'!H52+'#40'!H59+'#40'!H60+'#50'!H47+'#50'!H48+'#60'!H62+'#60'!H63+'#70'!H65+'#70'!H66+'#80'!H58+'#80'!H59+'#90'!H73+'#90'!H74+'#100'!H64+'#100'!H65+'#110'!H60+'#110'!H61+'#120'!H76+'#120'!H77+'#130'!H58+'#130'!H59+'#140'!H52+'#140'!H53+'#150'!H77+'#150'!H78+'#160'!H58+'#160'!H59+'#170'!H63+'#170'!H64+'#180'!H60+'#180'!H61+'#190'!H61+'#190'!H62+'#200'!H55+'#200'!H56+'#210'!H56+'#210'!H57+'#220'!H60+'#220'!H61+'#230'!H61+'#230'!H62+'#240'!H59+'#240'!H60+'[1]#250'!H60+'[1]#250'!H61+'[1]#260'!H62+'[1]#260'!H63+'[1]#270'!H62+'[1]#270'!H63+'[1]#280'!H58+'[1]#280'!H59+'[1]#290'!H60+'[1]#290'!H61+'[1]#300'!H60+'[1]#300'!H61 -> 0
E22: 기계 소계 | I22: =I20+I11+I21 -> 1900590000
B23: 2 | C23: 전기 부문 | D23: 자재비 | E23: 기계/전기자재 | F23: 식 | G23: 1 | I23: =전기!H27-I24 -> 260000000
E24: 설치/해체 공사 자재 | F24: 식 | G24: 1 | I24: =전기!H16 -> 0 | J24: 시운전 자재 포함
D25: 노무비 | E25: 철거(개조시) | F25: M/D | G25: =전기!F28 -> 10 | H25: =IF(전기!G28>0,전기!G28,"") -> 250000 | I25: =전기!H28 -> 2500000
E26: 설계,프로그램 | F26: M/D | G26: =전기!F29 -> 120 | H26: =IF(전기!G29>0,전기!G29,"") -> 300000 | I26: =전기!H29 -> 36000000
E27: 제작 | F27: M/D | G27: =전기!F30 -> 90 | H27: =IF(전기!G30>0,전기!G30,"") -> 250000 | I27: =전기!H30 -> 22500000
E28: 조립 | F28: M/D | G28: =전기!F31 -> 80 | H28: =IF(전기!G31>0,전기!G31,"") -> 250000 | I28: =전기!H31 -> 20000000
E29: 설치 | F29: M/D | G29: =전기!F32 -> 20 | H29: =IF(전기!G32>0,전기!G32,"") -> 300000 | I29: =전기!H32 -> 6000000
E30: 시운전 | F30: M/D | G30: =전기!F33 -> 30 | H30: =IF(전기!G33>0,전기!G33,"") -> 300000 | I30: =전기!H33 -> 9000000
E31: 양산대응 | F31: M/D | G31: =전기!F34 -> 21 | H31: =IF(전기!G34>0,전기!G34,"") -> 300000 | I31: =전기!H34 -> 6300000
E32: 소계 | I32: =SUM(I25:I31) -> 102300000
D33: 일반관리 및 이윤 | I33: =전기!H37+전기!H38 -> 0
E34: 전기 소계 | I34: =I32+I23+I33+I24 -> 362300000
B35: 3 | C35: 자재비 합계 | I35: =I23+I11+I24 -> 1652490000
C36: 노무비 합계 | I36: =I32+I20 -> 610400000
C37: 중간 합계 | I37: =I36+I35 -> 2262890000
B38: 4 | C38: 포장,운송 및 중장비 사용료 | I38: 3000000
B39: 5 | C39: 표준안전관리비 | F39: 설치/철거/수리금액 기준 | I39: =CEILING(MIN(I47:I48),1000) -> 2908000 | J39: =I30+I29+I25+I24+I17+I16+I12+I10 -> 78400000
B40: 6 | C40: 일반관리비 | I40: =전기!H37+'#10'!H66+'#20'!H53+'#30'!H51+'#40'!H59+'#50'!H47+'#60'!H62+'#70'!H65+'#80'!H58+'#90'!H73+'#100'!H64+'#110'!H60+'#120'!H76+'#130'!H58+'#140'!H52+'#150'!H77+'#160'!H58+'#170'!H63+'#180'!H60+'#190'!H61+'#200'!H55+'#210'!H56+'#220'!H60+'#230'!H61+'#240'!H59+'[1]#250'!H60+'[1]#260'!H62+'[1]#270'!H62+'[1]#280'!H58+'[1]#290'!H60+'[1]#300'!H60 -> 0
B41: 7 | C41: 이 윤 | I41: =전기!H38+'#10'!H67+'#20'!H54+'#30'!H52+'#40'!H60+'#50'!H48+'#60'!H63+'#70'!H66+'#80'!H59+'#90'!H74+'#100'!H65+'#110'!H61+'#120'!H77+'#130'!H59+'#140'!H53+'#150'!H78+'#160'!H59+'#170'!H64+'#180'!H61+'#190'!H62+'#200'!H56+'#210'!H57+'#220'!H61+'#230'!H62+'#240'!H60+'[1]#250'!H61+'[1]#260'!H63+'[1]#270'!H63+'[1]#280'!H59+'[1]#290'!H61+'[1]#300'!H61 -> 0
C42: 합 계 | F42: 3~7항 합계 | I42: =I22+I34+I38+I39 -> 2268798000
B43: 주1. 표준안전관리비:(설치/철거/시운전 공사 관련 금액)의 ⓐ2.66%,ⓑ1.95%+기초액,ⓒ2.02%(50억 이상일경우)
...

Sheet 단위공사별(집계)
A2: B. 단위장비별 견적가 종합(상세견적 첨부)
N3: 단위:원
I5: 포장/운송 | L5: 표준안전 | M5: 일반관리비
A6: 순번 | B6: 단위장비명 | C6: 수량 | D6: 자재비 | E6: 철거 | F6: 제작 | G6: 설치/시운전 | H6: 양산대응 | I6: 중장비사용 | J6: 기계소계 | K6: 전기소계 | L6: 관리비 | M6: 이윤 | N6: 합 계 | O6: 비 고
A7: =IF(B7>0,1,"") -> 1 | B7: ='#10'!C$1 -> 허브 아웃터 공급장치 | C7: 1식 | D7: ='#10'!H55 -> 90520000 | E7: ='#10'!H56 -> 0 | F7: ='#10'!H57+'#10'!H58+'#10'!H59+'#10'!H63 -> 14750000 | G7: ='#10'!H60+'#10'!H61 -> 3000000 | H7: ='#10'!H62 -> 600000 | I7: =IF($B7>0,'원가항목별(집계)'!I$38*$P7/$P$37,0) -> 171846.64 | J7: =SUM(D7:I7) -> 1.0904185e+08 | K7: =IF(B7>0,'원가항목별(집계)'!I$34*P7/P$37,0) -> 20753346 | L7: =IF($B7>0,'원가항목별(집계)'!I$39*$P7/$P$37,0) -> 166576.67 | M7: ='#10'!H66+'#10'!H67 -> 0 | N7: =SUM(J7:M7) -> 1.2996177e+08 | P7: =D7+E7+F7+G7+H7+M7 -> 108870000
A8: =IF(B8>0,A7+1,"") -> 2 | B8: ='#20'!C$1 -> O/B선별기 | C8: 1식 | D8: ='#20'!H42 -> 27890000 | E8: ='#20'!H43 -> 0 | F8: ='#20'!H44+'#20'!H45+'#20'!H46+'#20'!H50 -> 13250000 | G8: ='#20'!H47+'#20'!H48 -> 1800000 | H8: ='#20'!H49 -> 300000 | I8: =IF($B8>0,'원가항목별(집계)'!I$38*$P8/$P$37,0) -> 68252.49 | J8: =SUM(D8:I8) -> 43308252 | K8: =IF(B8>0,'원가항목별(집계)'!I$34*P8/P$37,0) -> 8242625.7 | L8: =IF($B8>0,'원가항목별(집계)'!I$39*$P8/$P$37,0) -> 66159.414 | M8: ='#20'!H53+'#20'!H54 -> 0 | N8: =SUM(J8:M8) -> 51617038 | P8: =D8+E8+F8+G8+H8+M8 -> 43240000
A9: =IF(B9>0,A8+1,"") -> 3 | B9: ='#30'!C$1 -> GRV정렬 | C9: 1식 | D9: ='#30'!H40 -> 7290000 | E9: ='#30'!H41 -> 0 | F9: ='#30'!H42+'#30'!H43+'#30'!H44+'#30'!H48 -> 13250000 | G9: ='#30'!H45+'#30'!H46 -> 1800000 | H9: ='#30'!H47 -> 300000 | I9: =IF($B9>0,'원가항목별(집계)'!I$38*$P9/$P$37,0) -> 35736.271 | J9: =SUM(D9:I9) -> 22675736 | K9: =IF(B9>0,'원가항목별(집계)'!I$34*P9/P$37,0) -> 4315750.4 | L9: =IF($B9>0,'원가항목별(집계)'!I$39*$P9/$P$37,0) -> 34640.359 | M9: ='#30'!H51+'#30'!H52 -> 0 | N9: =SUM(J9:M9) -> 27026127 | P9: =D9+E9+F9+G9+H9+M9 -> 22640000
A10: =IF(B10>0,A9+1,"") -> 4 | B10: ='#40'!C$1 -> 선별기 | C10: 1식 | D10: ='#40'!H48 -> 22210000 | E10: ='#40'!H49 -> 0 | F10: ='#40'!H50+'#40'!H51+'#40'!H52+'#40'!H56 -> 12000000 | G10: ='#40'!H53+'#40'!H54 -> 2700000 | H10: ='#40'!H55 -> 300000 | I10: =IF($B10>0,'원가항목별(집계)'!I$38*$P10/$P$37,0) -> 58734.393 | J10: =SUM(D10:I10) -> 37268734 | K10: =IF(B10>0,'원가항목별(집계)'!I$34*P10/P$37,0) -> 7093156.9 | L10: =IF($B10>0,'원가항목별(집계)'!I$39*$P10/$P$37,0) -> 56933.205 | M10: ='#40'!H59+'#40'!H60 -> 0 | N10: =SUM(J10:M10) -> 44418824 | P10: =D10+E10+F10+G10+H10+M10 -> 37210000
A11: =IF(B11>0,A10+1,"") -> 5 | B11: ='#50'!C$1 -> 마킹 | C11: 1식 | D11: ='#50'!H36 -> 20010000 | E11: ='#50'!H37 -> 0 | F11: ='#50'!H38+'#50'!H39+'#50'!H40+'#50'!H44 -> 9250000 | G11: ='#50'!H41+'#50'!H42 -> 1500000 | H11: ='#50'!H43 -> 600000 | I11: =IF($B11>0,'원가항목별(집계)'!I$38*$P11/$P$37,0) -> 49500.418 | J11: =SUM(D11:I11) -> 31409500 | K11: =IF(B11>0,'원가항목별(집계)'!I$34*P11/P$37,0) -> 5978000.5 | L11: =IF($B11>0,'원가항목별(집계)'!I$39*$P11/$P$37,0) -> 47982.405 | M11: ='#50'!H47+'#50'!H48 -> 0 | N11: =SUM(J11:M11) -> 37435483 | P11: =D11+E11+F11+G11+H11+M11 -> 31360000
A12: =IF(B12>0,A11+1,"") -> 6 | B12: ='#60'!C$1 -> 허버볼트 공급장치 | C12: 1식 | D12: ='#60'!H51 -> 79620000 | E12: ='#60'!H52 -> 0 | F12: ='#60'!H53+'#60'!H54+'#60'!H55+'#60'!H59 -> 17500000 | G12: ='#60'!H56+'#60'!H57 -> 1800000 | H12: ='#60'!H58 -> 600000 | I12: =IF($B12>0,'원가항목별(집계)'!I$38*$P12/$P$37,0) -> 157088.06 | J12: =SUM(D12:I12) -> 99677088 | K12: =IF(B12>0,'원가항목별(집계)'!I$34*P12/P$37,0) -> 18971002 | L12: =IF($B12>0,'원가항목별(집계)'!I$39*$P12/$P$37,0) -> 152270.69 | M12: ='#60'!H62+'#60'!H63 -> 0 | N12: =SUM(J12:M12) -> 1.1880036e+08 | P12: =D12+E12+F12+G12+H12+M12 -> 99520000
A13: =IF(B13>0,A12+1,"") -> 7 | B13: ='#70'!C$1 -> BOLT압입 | C13: 1식 | D13: ='#70'!H54 -> 84150000 | E13: ='#70'!H55 -> 0 | F13: ='#70'!H56+'#70'!H57+'#70'!H58+'#70'!H62 -> 19000000 | G13: ='#70'!H59+'#70'!H60 -> 1800000 | H13: ='#70'!H61 -> 300000 | I13: =IF($B13>0,'원가항목별(집계)'!I$38*$P13/$P$37,0) -> 166132.62 | J13: =SUM(D13:I13) -> 1.0541613e+08 | K13: =IF(B13>0,'원가항목별(집계)'!I$34*P13/P$37,0) -> 20063283 | L13: =IF($B13>0,'원가항목별(집계)'!I$39*$P13/$P$37,0) -> 161037.89 | M13: ='#70'!H65+'#70'!H66 -> 0 | N13: =SUM(J13:M13) -> 1.2564045e+08 | P13: =D13+E13+F13+G13+H13+M13 -> 105250000
A14: =IF(B14>0,A13+1,"") -> 8 | B14: ='#80'!C$1 -> 허버볼트 직각도 검사 | C14: 1식 | D14: ='#80'!H47 -> 50290000 | E14: ='#80'!H48 -> 0 | F14: ='#80'!H49+'#80'!H50+'#80'!H51+'#80'!H55 -> 20000000 | G14: ='#80'!H52+'#80'!H53 -> 1800000 | H14: ='#80'!H54 -> 600000 | I14: =IF($B14>0,'원가항목별(집계)'!I$38*$P14/$P$37,0) -> 114738.06 | J14: =SUM(D14:I14) -> 72804738 | K14: =IF(B14>0,'원가항목별(집계)'!I$34*P14/P$37,0) -> 13856532 | L14: =IF($B14>0,'원가항목별(집계)'!I$39*$P14/$P$37,0) -> 111219.42 | M14: ='#80'!H58+'#80'!H59 -> 0 | N14: =SUM(J14:M14) -> 86772490 | P14: =D14+E14+F14+G14+H14+M14 -> 72690000
A15: =IF(B15>0,A14+1,"") -> 9 | B15: ='#90'!C$1 -> 베어링 공급 및 압입기 | C15: 1식 | D15: ='#90'!H62 -> 106440000 | E15: ='#90'!H63 -> 0 | F15: ='#90'!H64+'#90'!H65+'#90'!H66+'#90'!H70 -> 20250000 | G15: ='#90'!H67+'#90'!H68 -> 3000000 | H15: ='#90'!H69 -> 300000 | I15: =IF($B15>0,'원가항목별(집계)'!I$38*$P15/$P$37,0) -> 205183.65 | J15: =SUM(D15:I15) -> 1.3019518e+08 | K15: =IF(B15>0,'원가항목별(집계)'!I$34*P15/P$37,0) -> 24779346 | L15: =IF($B15>0,'원가항목별(집계)'!I$39*$P15/$P$37,0) -> 198891.35 | M15: ='#90'!H73+'#90'!H74 -> 0 | N15: =SUM(J15:M15) -> 1.5517342e+08 | P15: =D15+E15+F15+G15+H15+M15 -> 129990000
A16: =IF(B16>0,A15+1,"") -> 10 | B16: ='#100'!C$1 -> 로크너트가체결/체결 | C16: 1식 | D16: ='#100'!H53 -> 50440000 | E16: ='#100'!H54 -> 0 | F16: ='#100'!H55+'#100'!H56+'#100'!H57+'#100'!H61 -> 20500000 | G16: ='#100'!H58+'#100'!H59 -> 1800000 | H16: ='#100'!H60 -> 600000 | I16: =IF($B16>0,'원가항목별(집계)'!I$38*$P16/$P$37,0) -> 115764.05 | J16: =SUM(D16:I16) -> 73455764 | K16: =IF(B16>0,'원가항목별(집계)'!I$34*P16/P$37,0) -> 13980439 | L16: =IF($B16>0,'원가항목별(집계)'!I$39*$P16/$P$37,0) -> 112213.95 | M16: ='#100'!H64+'#100'!H65 -> 0 | N16: =SUM(J16:M16) -> 87548417 | P16: =D16+E16+F16+G16+H16+M16 -> 73340000
A17: =IF(B17>0,A16+1,"") -> 11 | B17: ='#110'!C$1 -> 로크링조립 및 로크링볼트체결 | C17: 1식 | D17: ='#110'!H49 -> 36890000 | E17: ='#110'!H50 -> 0 | F17: ='#110'!H51+'#110'!H52+'#110'!H53+'#110'!H57 -> 20500000 | G17: ='#110'!H54+'#110'!H55 -> 1800000 | H17: ='#110'!H56 -> 300000 | I17: =IF($B17>0,'원가항목별(집계)'!I$38*$P17/$P$37,0) -> 93902.42 | J17: =SUM(D17:I17) -> 59583902 | K17: =IF(B17>0,'원가항목별(집계)'!I$34*P17/P$37,0) -> 11340282 | L17: =IF($B17>0,'원가항목별(집계)'!I$39*$P17/$P$37,0) -> 91022.746 | M17: ='#110'!H60+'#110'!H61 -> 0 | N17: =SUM(J17:M17) -> 71015207 | P17: =D17+E17+F17+G17+H17+M17 -> 59490000
A18: =IF(B18>0,A17+1,"") -> 12 | B18: ='#120'!C$1 -> 휠가이드공급 및 압입 | C18: 1식 | D18: ='#120'!H65 -> 67370000 | E18: ='#120'!H66 -> 0 | F18: ='#120'!H67+'#120'!H68+'#120'!H69+'#120'!H73 -> 17500000 | G18: ='#120'!H70+'#120'!H71 -> 1800000 | H18: ='#120'!H72 -> 300000 | I18: =IF($B18>0,'원가항목별(집계)'!I$38*$P18/$P$37,0) -> 137278.42 | J18: =SUM(D18:I18) -> 87107278 | K18: =IF(B18>0,'원가항목별(집계)'!I$34*P18/P$37,0) -> 16578658 | L18: =IF($B18>0,'원가항목별(집계)'!I$39*$P18/$P$37,0) -> 133068.55 | M18: ='#120'!H76+'#120'!H77 -> 0 | N18: =SUM(J18:M18) -> 1.03819e+08 | P18: =D18+E18+F18+G18+H18+M18 -> 86970000
A19: =IF(B19>0,A18+1,"") -> 13 | B19: ='#130'!C$1 -> BUFFER CON'V | C19: 1식 | D19: ='#130'!H47 -> 55670000 | E19: ='#130'!H48 -> 0 | F19: ='#130'!H49+'#130'!H50+'#130'!H51+'#130'!H55 -> 9250000 | G19: ='#130'!H52+'#130'!H53 -> 1800000 | H19: ='#130'!H54 -> 300000 | I19: =IF($B19>0,'원가항목별(집계)'!I$38*$P19/$P$37,0) -> 105788.2 | J19: =SUM(D19:I19) -> 67125788 | K19: =IF(B19>0,'원가항목별(집계)'!I$34*P19/P$37,0) -> 12775689 | L19: =IF($B19>0,'원가항목별(집계)'!I$39*$P19/$P$37,0) -> 102544.03 | M19: ='#130'!H58+'#130'!H59 -> 0 | N19: =SUM(J19:M19) -> 80004021 | P19: =D19+E19+F19+G19+H19+M19 -> 67020000
A20: =IF(B20>0,A19+1,"") -> 14 | B20: ='#140'!C$1 -> MAIN 컨베어/파렛트 | C20: 1식 | D20: ='#140'!H41 -> 68380000 | E20: ='#140'!H42 -> 0 | F20: ='#140'!H43+'#140'!H44+'#140'!H45+'#140'!H49 -> 6500000 | G20: ='#140'!H46+'#140'!H47 -> 3900000 | H20: ='#140'!H48 -> 0 | I20: =IF($B20>0,'원가항목별(집계)'!I$38*$P20/$P$37,0) -> 124350.86 | J20: =SUM(D20:I20) -> 78904351 | K20: =IF(B20>0,'원가항목별(집계)'!I$34*P20/P$37,0) -> 15017439 | L20: =IF($B20>0,'원가항목별(집계)'!I$39*$P20/$P$37,0) -> 120537.43 | M20: ='#140'!H52+'#140'!H53 -> 0 | N20: =SUM(J20:M20) -> 94042327 | P20: =D20+E20+F20+G20+H20+M20 -> 78780000
A21: =IF(B21>0,A20+1,"") -> 15 | B21: ='#150'!C$1 -> PALLETS | C21: 1식 | D21: ='#150'!H66 -> 50000000 | E21: ='#150'!H67 -> 0 | F21: ='#150'!H68+'#150'!H69+'#150'!H70+'#150'!H74 -> 6500000 | G21: ='#150'!H71+'#150'!H72 -> 2100000 | H21: ='#150'!H73 -> 0 | I21: =IF($B21>0,'원가항목별(집계)'!I$38*$P21/$P$37,0) -> 92497.593 | J21: =SUM(D21:I21) -> 58692498 | K21: =IF(B21>0,'원가항목별(집계)'!I$34*P21/P$37,0) -> 11170626 | L21: =IF($B21>0,'원가항목별(집계)'!I$39*$P21/$P$37,0) -> 89661 | M21: ='#150'!H77+'#150'!H78 -> 0 | N21: =SUM(J21:M21) -> 69952785 | P21: =D21+E21+F21+G21+H21+M21 -> 58600000
A22: =IF(B22>0,A21+1,"") -> 16 | B22: ='#160'!C$1 -> 런아웃투입배출 | C22: 1식 | D22: ='#160'!H47 -> 28200000 | E22: ='#160'!H48 -> 0 | F22: ='#160'!H49+'#160'!H50+'#160'!H51+'#160'!H55 -> 13250000 | G22: ='#160'!H52+'#160'!H53 -> 1800000 | H22: ='#160'!H54 -> 600000 | I22: =IF($B22>0,'원가항목별(집계)'!I$38*$P22/$P$37,0) -> 69215.349 | J22: =SUM(D22:I22) -> 43919215 | K22: =IF(B22>0,'원가항목별(집계)'!I$34*P22/P$37,0) -> 8358907 | L22: =IF($B22>0,'원가항목별(집계)'!I$39*$P22/$P$37,0) -> 67092.745 | M22: ='#160'!H58+'#160'!H59 -> 0 | N22: =SUM(J22:M22) -> 52345215 | P22: =D22+E22+F22+G22+H22+M22 -> 43850000
A23: =IF(B23>0,A22+1,"") -> 17 | B23: ='#170'!C$1 -> 2D리딩및 소재 반전 | C23: 1식 | D23: ='#170'!H52 -> 32790000 | E23: ='#170'!H53 -> 0 | F23: ='#170'!H54+'#170'!H55+'#170'!H56+'#170'!H60 -> 12000000 | G23: ='#170'!H57+'#170'!H58 -> 1800000 | H23: ='#170'!H59 -> 300000 | I23: =IF($B23>0,'원가항목별(집계)'!I$38*$P23/$P$37,0) -> 74013.859 | J23: =SUM(D23:I23) -> 46964014 | K23: =IF(B23>0,'원가항목별(집계)'!I$34*P23/P$37,0) -> 8938407 | L23: =IF($B23>0,'원가항목별(집계)'!I$39*$P23/$P$37,0) -> 71744.101 | M23: ='#170'!H63+'#170'!H64 -> 0 | N23: =SUM(J23:M23) -> 55974165 | P23: =D23+E23+F23+G23+H23+M23 -> 46890000
A24: =IF(B24>0,A23+1,"") -> 18 | B24: ='#180'!C$1 -> 베어링토크측정 | C24: 1식 | D24: ='#180'!H49 -> 43590000 | E24: ='#180'!H50 -> 0 | F24: ='#180'!H51+'#180'!H52+'#180'!H53+'#180'!H57 -> 17500000 | G24: ='#180'!H54+'#180'!H55 -> 4200000 | H24: ='#180'!H56 -> 300000 | I24: =IF($B24>0,'원가항목별(집계)'!I$38*$P24/$P$37,0) -> 103531.01 | J24: =SUM(D24:I24) -> 65693531 | K24: =IF(B24>0,'원가항목별(집계)'!I$34*P24/P$37,0) -> 12503095 | L24: =IF($B24>0,'원가항목별(집계)'!I$39*$P24/$P$37,0) -> 100356.06 | M24: ='#180'!H60+'#180'!H61 -> 0 | N24: =SUM(J24:M24) -> 78296982 | P24: =D24+E24+F24+G24+H24+M24 -> 65590000
A25: =IF(B25>0,A24+1,"") -> 19 | B25: ='#190'!C$1 -> 런아웃측정 | C25: 1식 | D25: ='#190'!H50 -> 46670000 | E25: ='#190'!H51 -> 0 | F25: ='#190'!H52+'#190'!H53+'#190'!H54+'#190'!H58 -> 21500000 | G25: ='#190'!H55+'#190'!H56 -> 1800000 | H25: ='#190'!H57 -> 600000 | I25: =IF($B25>0,'원가항목별(집계)'!I$38*$P25/$P$37,0) -> 111391.73 | J25: =SUM(D25:I25) -> 70681392 | K25: =IF(B25>0,'원가항목별(집계)'!I$34*P25/P$37,0) -> 13452407 | L25: =IF($B25>0,'원가항목별(집계)'!I$39*$P25/$P$37,0) -> 107975.71 | M25: ='#190'!H61+'#190'!H62 -> 0 | N25: =SUM(J25:M25) -> 84241775 | P25: =D25+E25+F25+G25+H25+M25 -> 70570000
A26: =IF(B26>0,A25+1,"") -> 20 | B26: ='#200'!C$1 -> 불량배출 | C26: 1식 | D26: ='#200'!H44 -> 30260000 | E26: ='#200'!H45 -> 0 | F26: ='#200'!H46+'#200'!H47+'#200'!H48+'#200'!H52 -> 17500000 | G26: ='#200'!H49+'#200'!H50 -> 3000000 | H26: ='#200'!H51 -> 600000 | I26: =IF($B26>0,'원가항목별(집계)'!I$38*$P26/$P$37,0) -> 81069.563 | J26: =SUM(D26:I26) -> 51441070 | K26: =IF(B26>0,'원가항목별(집계)'!I$34*P26/P$37,0) -> 9790500.8 | L26: =IF($B26>0,'원가항목별(집계)'!I$39*$P26/$P$37,0) -> 78583.429 | M26: ='#200'!H55+'#200'!H56 -> 0 | N26: =SUM(J26:M26) -> 61310154 | P26: =D26+E26+F26+G26+H26+M26 -> 51360000
A27: =IF(B27>0,A26+1,"") -> 21 | B27: ='#210'!C$1 -> 소재 반전 | C27: 1식 | D27: ='#210'!H45 -> 23090000 | E27: ='#210'!H46 -> 0 | F27: ='#210'!H47+'#210'!H48+'#210'!H49+'#210'!H53 -> 12000000 | G27: ='#210'!H50+'#210'!H51 -> 1800000 | H27: ='#210'!H52 -> 300000 | I27: =IF($B27>0,'원가항목별(집계)'!I$38*$P27/$P$37,0) -> 58702.824 | J27: =SUM(D27:I27) -> 37248703 | K27: =IF(B27>0,'원가항목별(집계)'!I$34*P27/P$37,0) -> 7089344.4 | L27: =IF($B27>0,'원가항목별(집계)'!I$39*$P27/$P$37,0) -> 56902.604 | M27: ='#210'!H56+'#210'!H57 -> 0 | N27: =SUM(J27:M27) -> 44394950 | P27: =D27+E27+F27+G27+H27+M27 -> 37190000
A28: =IF(B28>0,A27+1,"") -> 22 | B28: ='#220'!C$1 -> I/R공급 및 방향정렬 | C28: 1식 | D28: ='#220'!H49 -> 41170000 | E28: ='#220'!H50 -> 0 | F28: ='#220'!H51+'#220'!H52+'#220'!H53+'#220'!H57 -> 12000000 | G28: ='#220'!H54+'#220'!H55 -> 1800000 | H28: ='#220'!H56 -> 300000 | I28: =IF($B28>0,'원가항목별(집계)'!I$38*$P28/$P$37,0) -> 87241.33 | J28: =SUM(D28:I28) -> 55357241 | K28: =IF(B28>0,'원가항목별(집계)'!I$34*P28/P$37,0) -> 10535845 | L28: =IF($B28>0,'원가항목별(집계)'!I$39*$P28/$P$37,0) -> 84565.93 | M28: ='#220'!H60+'#220'!H61 -> 0 | N28: =SUM(J28:M28) -> 65977652 | P28: =D28+E28+F28+G28+H28+M28 -> 55270000
A29: =IF(B29>0,A28+1,"") -> 23 | B29: ='#230'!C$1 -> O/B볼 자동 공급 | C29: 1식 | D29: ='#230'!H50 -> 32370000 | E29: ='#230'!H51 -> 0 | F29: ='#230'!H52+'#230'!H53+'#230'!H54+'#230'!H58 -> 16250000 | G29: ='#230'!H55+'#230'!H56 -> 1800000 | H29: ='#230'!H57 -> 600000 | I29: =IF($B29>0,'원가항목별(집계)'!I$38*$P29/$P$37,0) -> 80532.887 | J29: =SUM(D29:I29) -> 51100533 | K29: =IF(B29>0,'원가항목별(집계)'!I$34*P29/P$37,0) -> 9725688.3 | L29: =IF($B29>0,'원가항목별(집계)'!I$39*$P29/$P$37,0) -> 78063.212 | M29: ='#230'!H61+'#230'!H62 -> 0 | N29: =SUM(J29:M29) -> 60904284 | P29: =D29+E29+F29+G29+H29+M29 -> 51020000
A30: =IF(B30>0,A29+1,"") -> 24 | B30: ='#240'!C$1 -> O/B SUB 자동 조립 | C30: 1식 | D30: ='#240'!H48 -> 26010000 | E30: ='#240'!H49 -> 0 | F30: ='#240'!H50+'#240'!H51+'#240'!H52+'#240'!H56 -> 22500000 | G30: ='#240'!H53+'#240'!H54 -> 3000000 | H30: ='#240'!H55 -> 1200000 | I30: =IF($B30>0,'원가항목별(집계)'!I$38*$P30/$P$37,0) -> 83200.48 | J30: =SUM(D30:I30) -> 52793200 | K30: =IF(B30>0,'원가항목별(집계)'!I$34*P30/P$37,0) -> 10047845 | L30: =IF($B30>0,'원가항목별(집계)'!I$39*$P30/$P$37,0) -> 80648.998 | M30: ='#240'!H59+'#240'!H60 -> 0 | N30: =SUM(J30:M30) -> 62921694 | P30: =D30+E30+F30+G30+H30+M30 -> 52710000
A31: =IF(B31>0,A30+1,"") -> 25 | B31: ='[1]#250'!C$1 -> O/B 스토퍼링 조립 | C31: 1식 | D31: ='[1]#250'!H49 -> 43120000 | E31: ='[1]#250'!H50 -> 0 | F31: ='[1]#250'!H51+'[1]#250'!H52+'[1]#250'!H53+'[1]#250'!H57 -> 14750000 | G31: ='[1]#250'!H54+'[1]#250'!H55 -> 1800000 | H31: ='[1]#250'!H56 -> 900000 | I31: =IF($B31>0,'원가항목별(집계)'!I$38*$P31/$P$37,0) -> 95607.154 | J31: =SUM(D31:I31) -> 60665607 | K31: =IF(B31>0,'원가항목별(집계)'!I$34*P31/P$37,0) -> 11546157 | L31: =IF($B31>0,'원가항목별(집계)'!I$39*$P31/$P$37,0) -> 92675.201 | M31: ='[1]#250'!H60+'[1]#250'!H61 -> 0 | N31: =SUM(J31:M31) -> 72304440 | P31: =D31+E31+F31+G31+H31+M31 -> 60570000
A32: =IF(B32>0,A31+1,"") -> 26 | B32: ='[1]#260'!C$1 -> O/B 로더테스트 | C32: 1식 | D32: ='[1]#260'!H51 -> 23590000 | E32: ='[1]#260'!H52 -> 0 | F32: ='[1]#260'!H53+'[1]#260'!H54+'[1]#260'!H55+'[1]#260'!H59 -> 22750000 | G32: ='[1]#260'!H56+'[1]#260'!H57 -> 1800000 | H32: ='[1]#260'!H58 -> 300000 | I32: =IF($B32>0,'원가항목별(집계)'!I$38*$P32/$P$37,0) -> 76460.468 | J32: =SUM(D32:I32) -> 48516460 | K32: =IF(B32>0,'원가항목별(집계)'!I$34*P32/P$37,0) -> 9233875.8 | L32: =IF($B32>0,'원가항목별(집계)'!I$39*$P32/$P$37,0) -> 74115.68 | M32: ='[1]#260'!H62+'[1]#260'!H63 -> 0 | N32: =SUM(J32:M32) -> 57824452 | P32: =D32+E32+F32+G32+H32+M32 -> 48440000
A33: =IF(B33>0,A32+1,"") -> 27 | B33: ='[1]#270'!C$1 -> BUFFER CON'V | C33: 1식 | D33: ='[1]#270'!H51 -> 63670000 | E33: ='[1]#270'!H52 -> 0 | F33: ='[1]#270'!H53+'[1]#270'!H54+'[1]#270'!H55+'[1]#270'!H59 -> 14750000 | G33: ='[1]#270'!H56+'[1]#270'!H57 -> 1800000 | H33: ='[1]#270'!H58 -> 300000 | I33: =IF($B33>0,'원가항목별(집계)'!I$38*$P33/$P$37,0) -> 127097.38 | J33: =SUM(D33:I33) -> 80647097 | K33: =IF(B33>0,'원가항목별(집계)'!I$34*P33/P$37,0) -> 15349126 | L33: =IF($B33>0,'원가항목별(집계)'!I$39*$P33/$P$37,0) -> 123199.72 | M33: ='[1]#270'!H62+'[1]#270'!H63 -> 0 | N33: =SUM(J33:M33) -> 96119423 | P33: =D33+E33+F33+G33+H33+M33 -> 80520000
A34: =IF(B34>0,A33+1,"") -> 28 | B34: ='[1]#280'!C$1 -> MAIN CONVEYOR/PALLET | C34: 1식 | D34: ='[1]#280'!H47 -> 60790000 | E34: ='[1]#280'!H48 -> 0 | F34: ='[1]#280'!H49+'[1]#280'!H50+'[1]#280'!H51+'[1]#280'!H55 -> 9250000 | G34: ='[1]#280'!H52+'[1]#280'!H53 -> 1500000 | H34: ='[1]#280'!H54 -> 1500000 | I34: =IF($B34>0,'원가항목별(집계)'!I$38*$P34/$P$37,0) -> 115290.52 | J34: =SUM(D34:I34) -> 73155291 | K34: =IF(B34>0,'원가항목별(집계)'!I$34*P34/P$37,0) -> 13923251 | L34: =IF($B34>0,'원가항목별(집계)'!I$39*$P34/$P$37,0) -> 111754.94 | M34: ='[1]#280'!H58+'[1]#280'!H59 -> 0 | N34: =SUM(J34:M34) -> 87190297 | P34: =D34+E34+F34+G34+H34+M34 -> 73040000
A35: =IF(B35>0,A34+1,"") -> 29 | B35: ='[1]#290'!C$1 -> PALLETS | C35: 1식 | D35: ='[1]#290'!H49 -> 25000000 | E35: ='[1]#290'!H50 -> 0 | F35: ='[1]#290'!H51+'[1]#290'!H52+'[1]#290'!H53+'[1]#290'!H57 -> 6500000 | G35: ='[1]#290'!H54+'[1]#290'!H55 -> 600000 | H35: ='[1]#290'!H56 -> 1500000 | I35: =IF($B35>0,'원가항목별(집계)'!I$38*$P35/$P$37,0) -> 53036.162 | J35: =SUM(D35:I35) -> 33653036 | K35: =IF(B35>0,'원가항목별(집계)'!I$34*P35/P$37,0) -> 6405000.6 | L35: =IF($B35>0,'원가항목별(집계)'!I$39*$P35/$P$37,0) -> 51409.72 | M35: ='[1]#290'!H60+'[1]#290'!H61 -> 0 | N35: =SUM(J35:M35) -> 40109446 | P35: =D35+E35+F35+G35+H35+M35 -> 33600000
A36: =IF(B36>0,A35+1,"") -> 30 | B36: ='[1]#300'!C$1 -> LMS/RFID | C36: 1식 | D36: ='[1]#300'!H49 -> 55000000 | E36: ='[1]#300'!H50 -> 0 | F36: ='[1]#300'!H51+'[1]#300'!H52+'[1]#300'!H53+'[1]#300'!H57 -> 0 | G36: ='[1]#300'!H54+'[1]#300'!H55 -> 0 | H36: ='[1]#300'!H56 -> 0 | I36: =IF($B36>0,'원가항목별(집계)'!I$38*$P36/$P$37,0) -> 86815.147 | J36: =SUM(D36:I36) -> 55086815 | K36: =IF(B36>0,'원가항목별(집계)'!I$34*P36/P$37,0) -> 10484376 | L36: =IF($B36>0,'원가항목별(집계)'!I$39*$P36/$P$37,0) -> 84152.816 | M36: ='[1]#300'!H60+'[1]#300'!H61 -> 0 | N36: =SUM(J36:M36) -> 65655344 | P36: =D36+E36+F36+G36+H36+M36 -> 55000000
A37: 합 계 | D37: =SUM(D7:D36) -> 1392490000 | E37: =SUM(E7:E36) -> 0 | F37: =SUM(F7:F36) -> 432500000 | G37: =SUM(G7:G36) -> 60900000 | H37: =SUM(H7:H36) -> 14700000 | I37: =SUM(I7:I36) -> 3000000 | J37: =SUM(D37:I37) -> 1903590000 | K37: =SUM(K7:K36) -> 3.623e+08 | L37: =SUM(L7:L36) -> 2908000 | M37: =SUM(M7:M36) -> 0 | N37: =SUM(N7:N36) -> 2.268798e+09 | P37: =SUM(P7:P36) -> 1900590000
D38: =IF(D37=0,"",D37/$N37) -> 0.61375671 | E38: =IF(E37=0,"",E37/$N37) | F38: =IF(F37=0,"",F37/$N37) -> 0.19062958 | G38: =IF(G37=0,"",G37/$N37) -> 0.026842407 | H38: =IF(H37=0,"",H37/$N37) -> 0.0064792018 | I38: =IF(I37=0,"",I37/$N37) -> 0.0013222861 | J38: =SUM(D38:I38) -> 0.83903018 | K38: =IF(K37=0,"",K37/$N37) -> 0.15968808 | L38: =IF(L37=0,"",L37/$N37) -> 0.001281736 | M38: =IF(M37=0,"",M37/$N37) | N38: =IF(N37=0,"",N37/$N37) -> 1
A39: 주) 전기비용은 턴키장비의 공통비용으로서 총 전기비용을 단위장비별 기계금액의 비율에 따라 배분함
N40: =IF('원가항목별(집계)'!I42='단위공사별(집계)'!N37,"","DATA오류입니다!")

Sheet 전기
B1: □ 전기부문: | C1: 전기부문(공통) | I1: (첨부)
A2: 구분 | C2: 품 명 | D2: 규격 | E2: 단위 | F2: 수량 | G2: 단가(원) | H2: 금액(원) | I2: 原MAKER
A3: 자 재 비 | B3: 철자재 | C3: 제작품 | D3: 콘트롤박스등 | E3: 식 | F3: 1 | G3: 8000000 | H3: =IF(F3=0,G3,G3*F3) -> 8000000
H4: =IF(F4=0,G4,G4*F4) -> 0
H5: =IF(F5=0,G5,G5*F5) -> 0
H6: =IF(F6=0,G6,G6*F6) -> 0
H7: =IF(F7=0,G7,G7*F7) -> 0
H8: =IF(F8=0,G8,G8*F8) -> 0
H9: =SUM(H3:H8) -> 8000000
B10: 설치/해체/ | H10: =IF(F10=0,G10,G10*F10) -> 0
B11: 시운전 공사 | H11: =IF(F11=0,G11,G11*F11) -> 0
B12: 자재 | H12: =IF(F12=0,G12,G12*F12) -> 0
H13: =IF(F13=0,G13,G13*F13) -> 0
H14: =IF(F14=0,G14,G14*F14) -> 0
H15: =IF(F15=0,G15,G15*F15) -> 0
H16: =SUM(H10:H15) -> 0
B17: 전기자재 | C17: ■PLC구매품 | D17: PLC등 | E17: 식 | F17: 1 | G17: 180000000 | H17: =IF(F17=0,G17,G17*F17) -> 180000000
H18: =IF(F18=0,G18,G18*F18) -> 0
C19: ■PC구매품 | D19: PC등 | E19: 식 | F19: 1 | G19: 20000000 | H19: =IF(F19=0,G19,G19*F19) -> 20000000
C20: ■PC P/G | E20: 식 | F20: 1 | G20: 50000000 | H20: =IF(F20=0,G20,G20*F20) -> 50000000
H21: =IF(F21=0,G21,G21*F21) -> 0
H23: =IF(F23=0,G23,G23*F23) -> 0
H24: =IF(F24=0,G24,G24*F24) -> 0
C25: 기타 잡자재 | E25: 식 | F25: 1 | G25: 2000000 | H25: =IF(F25=0,G25,G25*F25) -> 2000000
H26: =SUM(H17:H25) -> 252000000
B27: 자재비 소계 | H27: =SUM(H26,H9,H16) -> 260000000
A28: 노 무 비 | B28: 기존설비 철거 | E28: M/D | F28: 10 | G28: 250000 | H28: =F28*G28 -> 2500000
B29: 전기 설계/프로그램 | E29: M/D | F29: 120 | G29: 300000 | H29: =F29*G29 -> 36000000
B30: 전기 제작 | E30: M/D | F30: 90 | G30: 250000 | H30: =F30*G30 -> 22500000
B31: 전기 조립 | E31: M/D | F31: 80 | G31: 250000 | H31: =F31*G31 -> 20000000
B32: 전기 설치 | E32: M/D | F32: 20 | G32: 300000 | H32: =F32*G32 -> 6000000
B33: 전기 시운전 | E33: M/D | F33: 30 | G33: 300000 | H33: =F33*G33 -> 9000000
B34: 전기 양산대응 | E34: M/D | F34: 21 | G34: 300000 | H34: =F34*G34 -> 6300000
B35: 노무비 소계 | H35: =SUM(H28:H34) -> 102300000
B36: 운반및중장비사용,표준안전관리비 | G36: * 기계부문에 포함시킴 | H36: 0
B37: 일반관리비 | H37: 0
B38: 이 윤 | H38: 0
B39: 합 계 | H39: =H27+H35+H36+H37+H38 -> 362300000

Sheet #10
B1: □ 단위공사명(전기제외): | C1: 허브 아웃터 공급장치 | I1: (첨부)
A2: 구분 | C2: 품 명 | D2: 규격 | E2: 단위 | F2: 수량 | G2: 단가(원) | H2: 금액(원) | I2: 原MAKER
A3: 자 재 비 | B3: 철자재 | C3: ■BASE | D3: 제관,가공 | E3: 식 | F3: 3 | G3: 2000000 | H3: =IF(F3=0,G3,G3*F3) -> 6000000
C4: ■FRAME | D4: 제관,가공 | E4: 식 | F4: 3 | G4: 1500000 | H4: =IF(F4=0,G4,G4*F4) -> 4500000
C5: ■상측 COVER | D5: 제관,가공 | E5: 식 | F5: 3 | G5: 1500000 | H5: =IF(F5=0,G5,G5*F5) -> 4500000
C6: ■OP POST | E6: 식 | F6: 1 | G6: 600000 | H6: =IF(F6=0,G6,G6*F6) -> 600000
C7: ■이종확인 | D7: 제관,가공 | E7: 식 | F7: 1 | G7: 2000000 | H7: =IF(F7=0,G7,G7*F7) -> 2000000
C8: ■공급 파레타이징 | D8: 제관,가공 | E8: 식 | F8: 1 | G8: 19500000 | H8: =IF(F8=0,G8,G8*F8) -> 19500000
C9: ■소재 공급 | D9: 직교 로봇 FRAME등 | E9: 식 | F9: 1 | G9: 650000 | H9: =IF(F9=0,G9,G9*F9) -> 650000
D10: 그리퍼 및 HEAD | E10: 식 | F10: 1 | G10: 1500000 | H10: =IF(F10=0,G10,G10*F10) -> 1500000
D11: 회전 | E11: 식 | F11: 1 | G11: 500000 | H11: =IF(F11=0,G11,G11*F11) -> 500000
E12: 식 | H12: =IF(F12=0,G12,G12*F12) -> 0
E13: 식 | H13: =IF(F13=0,G13,G13*F13) -> 0
E14: 식 | H14: =IF(F14=0,G14,G14*F14) -> 0
C15: 기타 | E15: 식 | F15: 1 | G15: 500000 | H15: 0
H16: =SUM(H3:H15) -> 39750000
B17: 설치/해체/시운전 | H17: =IF(F17=0,G17,G17*F17) -> 0
B18: 공사 관련 자재 | H18: =IF(F18=0,G18,G18*F18) -> 0
H19: =SUM(H17:H18) -> 0
B20: 구매품 | C20: ■이종확인 | H20: =IF(F20=0,G20,G20*F20) -> 0
B21: (유공압품외) | C21: LVDT | E21: 식 | F21: 1 | G21: 1860000 | H21: =IF(F21=0,G21,G21*F21) -> 1860000
C22: ■공급 파레타이징 | H22: =IF(F22=0,G22,G22*F22) -> 0
C23: #팔레트 투입/이송 | D23: 공압 CYL'류 | E23: 식 | F23: 1 | G23: 3400000 | H23: =IF(F23=0,G23,G23*F23) -> 3400000
D24: 센스류 | E24: 식 | F24: 1 | G24: 800000 | H24: =IF(F24=0,G24,G24*F24) -> 800000
D25: 기타(LM,압쇼버등) | E25: 식 | F25: 1 | G25: 1500000 | H25: =IF(F25=0,G25,G25*F25) -> 1500000
C26: #팔레트 로딩 | D26: 공압 CYL'류 | E26: 식 | F26: 1 | G26: 3800000 | H26: =IF(F26=0,G26,G26*F26) -> 3800000
D27: 센스류 | E27: 식 | F27: 1 | G27: 1000000 | H27: =IF(F27=0,G27,G27*F27) -> 1000000
C28: #엘리베이트 | D28: 서보실린더 | E28: 식 | F28: 1 | G28: 2500000 | H28: =IF(F28=0,G28,G28*F28) -> 2500000
D29: 서버모타 ASS'Y | E29: 식 | F29: 1 | G29: 3000000 | H29: =IF(F29=0,G29,G29*F29) -> 3000000
D30: 감속기 | E30: 식 | F30: 1 | G30: 600000 | H30: =IF(F30=0,G30,G30*F30) -> 600000
D31: 기타(LM,압쇼버등) | E31: 식 | F31: 1 | G31: 1800000 | H31: =IF(F31=0,G31,G31*F31) -> 1800000
C32: #배출 | D32: 서버모타 ASS'Y | E32: 식 | F32: 1 | G32: 3000000 | H32: =IF(F32=0,G32,G32*F32) -> 3000000
D33: 감속기 | E33: 식 | F33: 1 | G33: 600000 | H33: =IF(F33=0,G33,G33*F33) -> 600000
D34: 기타(LM,압쇼버등) | E34: 식 | F34: 1 | G34: 200000 | H34: =IF(F34=0,G34,G34*F34) -> 200000
C35: ■소재 공급 | H35: =IF(F35=0,G35,G35*F35) -> 0
C36: 직교 로봇 | D36: 3축(로보스타) | E36: 식 | F36: 1 | G36: 20000000 | H36: =IF(F36=0,G36,G36*F36) -> 20000000
C37: 그리퍼 CYL' | E37: EA | F37: 1 | G37: 800000 | H37: =IF(F37=0,G37,G37*F37) -> 800000
C38: PROXIMITY SENSOR | E38: EA | F38: 2 | G38: 40000 | H38: =IF(F38=0,G38,G38*F38) -> 80000
C39: 기타 | E39: 식 | F39: 1 | G39: 500000 | H39: =IF(F39=0,G39,G39*F39) -> 500000
C40: 회전실린더 | E40: 식 | F40: 1 | G40: 1100000 | H40: =IF(F40=0,G40,G40*F40) -> 1100000
...

Sheet #20
B1: □ 단위공사명(전기제외): | C1: O/B선별기 | I1: (첨부)
A2: 구분 | C2: 품 명 | D2: 규격 | E2: 단위 | F2: 수량 | G2: 단가(원) | H2: 금액(원) | I2: 原MAKER
A3: 자 재 비 | B3: 철자재 | C3: ■BASE | D3: 제관,가공 | E3: 식 | F3: 1 | G3: 2000000 | H3: =IF(F3=0,G3,G3*F3) -> 2000000
C4: ■FRAME | D4: 제관,가공 | E4: 식 | F4: 1 | G4: 1500000 | H4: =IF(F4=0,G4,G4*F4) -> 1500000
C5: ■상측 COVER | D5: 제관,가공 | E5: 식 | F5: 1 | G5: 1500000 | H5: =IF(F5=0,G5,G5*F5) -> 1500000
C6: ■OP POST | E6: 식 | F6: 1 | G6: 600000 | H6: =IF(F6=0,G6,G6*F6) -> 600000
C7: ■트랜스퍼이송장치 | H7: =IF(F7=0,G7,G7*F7) -> 0
C8: 상하이송unit | E8: 식 | F8: 1 | G8: 2000000 | H8: =IF(F8=0,G8,G8*F8) -> 2000000
C9: 전후이송unit | E9: 식 | F9: 1 | G9: 2000000 | H9: =IF(F9=0,G9,G9*F9) -> 2000000
C10: 좌우이송unit | E10: 식 | F10: 1 | G10: 2000000 | H10: =IF(F10=0,G10,G10*F10) -> 2000000
C11: 그리퍼unit | E11: 식 | F11: 1 | G11: 2000000 | H11: =IF(F11=0,G11,G11*F11) -> 2000000
H12: =IF(F12=0,G12,G12*F12) -> 0
C13: 기타 가공물 | E13: 식 | F13: 1 | G13: 500000 | H13: 0
H14: =SUM(H3:H13) -> 13600000
B15: 설치/해체/시운전 | H15: =IF(F15=0,G15,G15*F15) -> 0
B16: 공사 관련 자재 | H16: =IF(F16=0,G16,G16*F16) -> 0
H17: =SUM(H15:H16) -> 0
B18: 구매품 | C18: ■트랜스퍼이송장치 | H18: =IF(F18=0,G18,G18*F18) -> 0
B19: (유공압품외) | C19: 상하이송unit | E19: 식 | F19: 1 | G19: 2700000 | H19: =IF(F19=0,G19,G19*F19) -> 2700000
C20: 전후이송unit | E20: 식 | F20: 1 | G20: 2450000 | H20: =IF(F20=0,G20,G20*F20) -> 2450000
C21: 좌우이송unit | E21: 식 | F21: 1 | G21: 2450000 | H21: =IF(F21=0,G21,G21*F21) -> 2450000
C22: 그리퍼unit | E22: 식 | F22: 1 | G22: 2800000 | H22: =IF(F22=0,G22,G22*F22) -> 2800000
H23: =IF(F23=0,G23,G23*F23) -> 0
C24: ■일반 자재류 | H24: =IF(F24=0,G24,G24*F24) -> 0
C25: F.R.L Unit | D25: AV4000 | E25: 식 | F25: 1 | G25: 350000 | H25: =IF(F25=0,G25,G25*F25) -> 350000
C26: SOL V/V | D26: VQC4201 | E26: 식 | F26: 20 | G26: 75000 | H26: =IF(F26=0,G26,G26*F26) -> 1500000
C27: Manifold | D27: VV5QC41 | E27: 식 | F27: 2 | G27: 850000 | H27: =IF(F27=0,G27,G27*F27) -> 1700000
C28: Speed Con | E28: 식 | F28: 20 | G28: 7000 | H28: =IF(F28=0,G28,G28*F28) -> 140000
C29: 배관자재 | E29: 식 | F29: 1 | G29: 100000 | H29: =IF(F29=0,G29,G29*F29) -> 100000
C30: 잡자재 | E30: 식 | F30: 1 | G30: 100000 | H30: =IF(F30=0,G30,G30*F30) -> 100000
H31: =IF(F31=0,G31,G31*F31) -> 0
C32: 기타자재 | E32: 식 | F32: 1 | G32: 500000 | H32: 0
H33: =SUM(H18:H32) -> 14290000
B34: 외주제작품 | H34: =IF(F34=0,G34,G34*F34) -> 0
H35: =IF(F35=0,G35,G35*F35) -> 0
H36: =IF(F36=0,G36,G36*F36) -> 0
H37: =IF(F37=0,G37,G37*F37) -> 0
H38: =IF(F38=0,G38,G38*F38) -> 0
H39: =IF(F39=0,G39,G39*F39) -> 0
H40: =IF(F40=0,G40,G40*F40) -> 0
...

Sheet #30
B1: □ 단위공사명(전기제외): | C1: GRV정렬 | I1: (첨부)
A2: 구분 | C2: 품 명 | D2: 규격 | E2: 단위 | F2: 수량 | G2: 단가(원) | H2: 금액(원) | I2: 原MAKER
A3: 자 재 비 | B3: 철자재 | C3: ■GRV정렬 | E3: 식 | F3: 1 | G3: 2500000 | H3: =IF(F3=0,G3,G3*F3) -> 2500000
H4: =IF(F4=0,G4,G4*F4) -> 0
H5: =IF(F5=0,G5,G5*F5) -> 0
H6: =IF(F6=0,G6,G6*F6) -> 0
H7: =IF(F7=0,G7,G7*F7) -> 0
H8: =IF(F8=0,G8,G8*F8) -> 0
H9: =IF(F9=0,G9,G9*F9) -> 0
H10: =IF(F10=0,G10,G10*F10) -> 0
H11: =IF(F11=0,G11,G11*F11) -> 0
C12: 기타 가공물 | E12: 식 | F12: 1 | G12: 500000 | H12: 0
H13: =SUM(H3:H12) -> 2500000
B14: 설치/해체/시운전 | H14: =IF(F14=0,G14,G14*F14) -> 0
B15: 공사 관련 자재 | H15: =IF(F15=0,G15,G15*F15) -> 0
H16: =IF(F16=0,G16,G16*F16) -> 0
H17: =IF(F17=0,G17,G17*F17) -> 0
H18: =IF(F18=0,G18,G18*F18) -> 0
H19: =SUM(H14:H18) -> 0
B20: 구매품 | C20: ■GRV정렬 | H20: =IF(F20=0,G20,G20*F20) -> 0
B21: (유공압품외) | C21: 상측상하 1축 | D21: LM2EA,CYL',압쇼버,센스,케이블베어등 | E21: 식 | F21: 1 | G21: 1000000 | H21: =IF(F21=0,G21,G21*F21) -> 1000000
C22: 하측상하 1축 | D22: 모타,CYL,LM BUSH등 | E22: 식 | F22: 1 | G22: 1000000 | H22: =IF(F22=0,G22,G22*F22) -> 1000000
C23: 기타 | E23: 식 | F23: 1 | G23: 500000 | H23: =IF(F23=0,G23,G23*F23) -> 500000
H24: =IF(F24=0,G24,G24*F24) -> 0
C25: ■일반 자재류 | H25: =IF(F25=0,G25,G25*F25) -> 0
C26: F.R.L Unit | D26: AV4000 | E26: 식 | F26: 1 | G26: 350000 | H26: =IF(F26=0,G26,G26*F26) -> 350000
C27: SOL V/V | D27: VQC4201 | E27: 식 | F27: 10 | G27: 75000 | H27: =IF(F27=0,G27,G27*F27) -> 750000
C28: Manifold | D28: VV5QC41 | E28: 식 | F28: 1 | G28: 850000 | H28: =IF(F28=0,G28,G28*F28) -> 850000
C29: Speed Con | E29: 식 | F29: 20 | G29: 7000 | H29: =IF(F29=0,G29,G29*F29) -> 140000
C30: 배관자재 | E30: 식 | F30: 1 | G30: 100000 | H30: =IF(F30=0,G30,G30*F30) -> 100000
C31: 잡자재 | E31: 식 | F31: 1 | G31: 100000 | H31: =IF(F31=0,G31,G31*F31) -> 100000
H32: =IF(F32=0,G32,G32*F32) -> 0
C33: 기타자재 | E33: 식 | F33: 1 | G33: 500000 | H33: 0
H34: =SUM(H20:H33) -> 4790000
B35: 외주제작품 | H35: =IF(F35=0,G35,G35*F35) -> 0
H36: =IF(F36=0,G36,G36*F36) -> 0
H37: =IF(F37=0,G37,G37*F37) -> 0
H38: =IF(F38=0,G38,G38*F38) -> 0
H39: =SUM(H35:H38) -> 0
B40: 자재비 소계 | H40: =SUM(H39,H34,H19,H13) -> 7290000
...

Sheet #40
B1: □ 단위공사명(전기제외): | C1: 선별기 | I1: (첨부)
A2: 구분 | C2: 품 명 | D2: 규격 | E2: 단위 | F2: 수량 | G2: 단가(원) | H2: 금액(원) | I2: 原MAKER
A3: 자 재 비 | B3: 철자재 | C3: ■O/R선별 | E3: 식 | F3: 1 | G3: 5000000 | H3: =IF(F3=0,G3,G3*F3) -> 5000000
H4: =IF(F4=0,G4,G4*F4) -> 0
H5: =IF(F5=0,G5,G5*F5) -> 0
H6: =IF(F6=0,G6,G6*F6) -> 0
H7: =IF(F7=0,G7,G7*F7) -> 0
H8: =IF(F8=0,G8,G8*F8) -> 0
H9: =IF(F9=0,G9,G9*F9) -> 0
H10: =IF(F10=0,G10,G10*F10) -> 0
H11: =IF(F11=0,G11,G11*F11) -> 0
C12: 기타 | E12: 식 | F12: 1 | G12: 500000 | H12: 0
H13: =SUM(H3:H12) -> 5000000
B14: 설치/해체/시운전 | H14: =IF(F14=0,G14,G14*F14) -> 0
B15: 공사 관련 자재 | H15: =IF(F15=0,G15,G15*F15) -> 0
H16: =IF(F16=0,G16,G16*F16) -> 0
H17: =IF(F17=0,G17,G17*F17) -> 0
C18: 기타자재 | H18: =IF(F18=0,G18,G18*F18) -> 0
H19: =SUM(H14:H18) -> 0
B20: 구매품 | C20: ■O/RACE등급선별(2->1대) | H20: =IF(F20=0,G20,G20*F20) -> 0
B21: (유공압품외) | C21: LVDT | E21: EA | F21: 6 | G21: 1800000 | H21: =IF(F21=0,G21,G21*F21) -> 10800000
C22: CYL'(측정부) | D22: 공압 | E22: EA | F22: 6 | G22: 60000 | H22: =IF(F22=0,G22,G22*F22) -> 360000
C23: LM GUIDE(측정부) | D23: THK | E23: EA | F23: 12 | G23: 60000 | H23: =IF(F23=0,G23,G23*F23) -> 720000
C24: 상측상하 1축 | D24: LM2EA,CYL',압쇼버,센스,케이블베어등 | E24: 식 | F24: 1 | G24: 1000000 | H24: =IF(F24=0,G24,G24*F24) -> 1000000
C25: 하측상하 1축 | D25: LM3EA,CYL',압쇼버,센스,케이블베어등 | E25: 식 | F25: 1 | G25: 1000000 | H25: =IF(F25=0,G25,G25*F25) -> 1000000
C26: PROXIMITY SENSOR | E26: EA | F26: 16 | G26: 40000 | H26: =IF(F26=0,G26,G26*F26) -> 640000
C27: 소재 감지 센스 | E27: EA | F27: 1 | G27: 100000 | H27: =IF(F27=0,G27,G27*F27) -> 100000
C28: 일반구입물 | E28: 식 | F28: 1 | G28: 300000 | H28: =IF(F28=0,G28,G28*F28) -> 300000
H29: =IF(F29=0,G29,G29*F29) -> 0
C30: ■일반 자재류 | H30: =IF(F30=0,G30,G30*F30) -> 0
C31: F.R.L Unit | D31: AV4000 | E31: 식 | F31: 1 | G31: 350000 | H31: =IF(F31=0,G31,G31*F31) -> 350000
C32: SOL V/V | D32: VQC4201 | E32: 식 | F32: 10 | G32: 75000 | H32: =IF(F32=0,G32,G32*F32) -> 750000
C33: Manifold | D33: VV5QC41 | E33: 식 | F33: 1 | G33: 850000 | H33: =IF(F33=0,G33,G33*F33) -> 850000
C34: Speed Con | E34: 식 | F34: 20 | G34: 7000 | H34: =IF(F34=0,G34,G34*F34) -> 140000
C35: 배관자재 | E35: 식 | F35: 1 | G35: 100000 | H35: =IF(F35=0,G35,G35*F35) -> 100000
C36: 잡자재 | E36: 식 | F36: 1 | G36: 100000 | H36: =IF(F36=0,G36,G36*F36) -> 100000
H37: =IF(F37=0,G37,G37*F37) -> 0
C38: 기타자재 | E38: 식 | F38: 1 | G38: 500000 | H38: 0
H39: =SUM(H20:H38) -> 17210000
B40: 외주제작품 | H40: =IF(F40=0,G40,G40*F40) -> 0
...

Sheet #50
B1: □ 단위공사명(전기제외): | C1: 마킹 | I1: (첨부)
A2: 구분 | C2: 품 명 | D2: 규격 | E2: 단위 | F2: 수량 | G2: 단가(원) | H2: 금액(원) | I2: 原MAKER
A3: 자 재 비 | B3: 철자재 | C3: ■상측 COVER | D3: 제관,가공 | E3: 식 | F3: 1 | G3: 1500000 | H3: =IF(F3=0,G3,G3*F3) -> 1500000
C4: ■상하1축 | E4: 식 | F4: 1 | G4: 2500000 | H4: =IF(F4=0,G4,G4*F4) -> 2500000
H5: =IF(F5=0,G5,G5*F5) -> 0
H6: =IF(F6=0,G6,G6*F6) -> 0
H7: =IF(F7=0,G7,G7*F7) -> 0
H8: =IF(F8=0,G8,G8*F8) -> 0
H9: =IF(F9=0,G9,G9*F9) -> 0
H10: =IF(F10=0,G10,G10*F10) -> 0
H11: =IF(F11=0,G11,G11*F11) -> 0
C12: 기타 가공물 | E12: 식 | F12: 1 | G12: 500000 | H12: 0
H13: =SUM(H3:H12) -> 4000000
B14: 설치/해체/시운전 | H14: =IF(F14=0,G14,G14*F14) -> 0
B15: 공사 관련 자재 | H15: =IF(F15=0,G15,G15*F15) -> 0
C16: 기타자재 | H16: =IF(F16=0,G16,G16*F16) -> 0
H17: =SUM(H14:H16) -> 0
B18: 구매품 | C18: ■마킹기 | D18: 20w | E18: 식 | F18: 1 | G18: 40000000 | H18: 0
B19: (유공압품외) | C19: ■상하1축 | D19: 서보 | E19: 식 | F19: 1 | G19: 3600000 | H19: =IF(F19=0,G19,G19*F19) -> 3600000
C20: ■PROXIMITY SENSOR | E20: EA | F20: 3 | G20: 40000 | H20: =IF(F20=0,G20,G20*F20) -> 120000
C21: ■2D 리더기 | D21: 코그넥스 | E21: 식 | F21: 1 | G21: 5000000 | H21: =IF(F21=0,G21,G21*F21) -> 5000000
H22: =IF(F22=0,G22,G22*F22) -> 0
C23: ■일반 자재류 | H23: =IF(F23=0,G23,G23*F23) -> 0
C24: F.R.L Unit | D24: AV4000 | E24: 식 | F24: 1 | G24: 350000 | H24: =IF(F24=0,G24,G24*F24) -> 350000
C25: SOL V/V | D25: VQC4201 | E25: 식 | F25: 10 | G25: 75000 | H25: =IF(F25=0,G25,G25*F25) -> 750000
C26: Manifold | D26: VV5QC41 | E26: 식 | F26: 1 | G26: 850000 | H26: =IF(F26=0,G26,G26*F26) -> 850000
C27: Speed Con | E27: 식 | F27: 20 | G27: 7000 | H27: =IF(F27=0,G27,G27*F27) -> 140000
C28: 배관자재 | E28: 식 | F28: 1 | G28: 100000 | H28: =IF(F28=0,G28,G28*F28) -> 100000
C29: 잡자재 | E29: 식 | F29: 1 | G29: 100000 | H29: =IF(F29=0,G29,G29*F29) -> 100000
H30: =IF(F30=0,G30,G30*F30) -> 0
C31: 기타자재 | E31: 식 | F31: 1 | G31: 500000 | H31: 0
H32: =SUM(H18:H31) -> 11010000
B33: 외주제작품 | C33: 불량 배출 컨베어 | E33: 식 | F33: 1 | G33: 5000000 | H33: =IF(F33=0,G33,G33*F33) -> 5000000
H34: =IF(F34=0,G34,G34*F34) -> 0
H35: =SUM(H33:H34) -> 5000000
B36: 자재비 소계 | H36: =SUM(H35,H32,H17,H13) -> 20010000
A37: 노 무 비 | B37: 기존설비 철거 | E37: M/D | F37: 0 | G37: 250000 | H37: =F37*G37 -> 0
B38: 기계 설계 | E38: M/D | F38: 15 | G38: 300000 | H38: =F38*G38 -> 4500000
B39: 기계 제작(제관,가공) | E39: M/D | F39: 2 | G39: 250000 | H39: =F39*G39 -> 500000
B40: 기계 조립 | E40: M/D | F40: 15 | G40: 250000 | H40: =F40*G40 -> 3750000
...

Sheet #60
B1: □ 단위공사명(전기제외): | C1: 허버볼트 공급장치 | I1: (첨부)
A2: 구분 | C2: 품 명 | D2: 규격 | E2: 단위 | F2: 수량 | G2: 단가(원) | H2: 금액(원) | I2: 原MAKER
A3: 자 재 비 | B3: 철자재 | C3: ■BASE | D3: 제관,가공 | E3: 식 | F3: 1 | G3: 2000000 | H3: =IF(F3=0,G3,G3*F3) -> 2000000
C4: ■FRAME | D4: 제관,가공 | E4: 식 | F4: 1 | G4: 1500000 | H4: =IF(F4=0,G4,G4*F4) -> 1500000
C5: ■상측 COVER | D5: 제관,가공 | E5: 식 | F5: 1 | G5: 1500000 | H5: =IF(F5=0,G5,G5*F5) -> 1500000
C6: ■OP POST | E6: 식 | F6: 1 | G6: 600000 | H6: =IF(F6=0,G6,G6*F6) -> 600000
C7: ■볼트공급정렬장치 | E7: 식 | F7: 1 | G7: 4700000 | H7: =IF(F7=0,G7,G7*F7) -> 4700000
C8: ■볼트공급 | E8: 식 | F8: 1 | G8: 3500000 | H8: =IF(F8=0,G8,G8*F8) -> 3500000
C9: ■직교로봇 | E9: 식 | F9: 1 | G9: 3000000 | H9: =IF(F9=0,G9,G9*F9) -> 3000000
C10: ■데크 | E10: 식 | F10: 1 | G10: 6200000 | H10: =IF(F10=0,G10,G10*F10) -> 6200000
C11: ■LIFTER UNIT | E11: 식 | F11: 1 | G11: 1300000 | H11: =IF(F11=0,G11,G11*F11) -> 1300000
H12: =IF(F12=0,G12,G12*F12) -> 0
C13: 기타 자재 | E13: 식 | F13: 1 | G13: 200000 | H13: 0
H14: =SUM(H3:H13) -> 24300000
B15: 설치/해체/시운전 | H15: =IF(F15=0,G15,G15*F15) -> 0
B16: 공사 관련 자재 | H16: =IF(F16=0,G16,G16*F16) -> 0
H17: =IF(F17=0,G17,G17*F17) -> 0
H18: =IF(F18=0,G18,G18*F18) -> 0
C19: 기타자재 | H19: =IF(F19=0,G19,G19*F19) -> 0
H20: =SUM(H15:H19) -> 0
B21: 구매품 | C21: ■허버볼트공급 | H21: =IF(F21=0,G21,G21*F21) -> 0
B22: (유공압품외) | C22: PART FEEDER | E22: 식 | F22: 1 | G22: 19000000 | H22: =IF(F22=0,G22,G22*F22) -> 19000000
C23: 리프트 컨베어 | E23: 식 | F23: 0 | G23: 11500000 | H23: 0
C24: 기타 | E24: 식 | F24: 1 | G24: 2000000 | H24: =IF(F24=0,G24,G24*F24) -> 2000000
C25: ■소재 공급 | H25: =IF(F25=0,G25,G25*F25) -> 0
C26: 직교 로봇 | D26: 3축 | E26: 식 | F26: 1 | G26: 20000000 | H26: =IF(F26=0,G26,G26*F26) -> 20000000
C27: Y척 | E27: 식 | F27: 1 | G27: 8000000 | H27: =IF(F27=0,G27,G27*F27) -> 8000000
C28: 실린더류 | E28: 식 | F28: 1 | G28: 2000000 | H28: =IF(F28=0,G28,G28*F28) -> 2000000
C29: PROXIMITY SENSOR | E29: 식 | F29: 1 | G29: 1000000 | H29: =IF(F29=0,G29,G29*F29) -> 1000000
C30: 기타 | E30: 식 | F30: 1 | G30: 500000 | H30: =IF(F30=0,G30,G30*F30) -> 500000
C31: ■LIFTER UNIT | E31: 식 | F31: 1 | G31: 600000 | H31: =IF(F31=0,G31,G31*F31) -> 600000
H32: =IF(F32=0,G32,G32*F32) -> 0
C33: ■일반 자재류 | H33: =IF(F33=0,G33,G33*F33) -> 0
C34: F.R.L Unit | D34: AV4000 | E34: 식 | F34: 1 | G34: 350000 | H34: =IF(F34=0,G34,G34*F34) -> 350000
C35: SOL V/V | D35: VQC4201 | E35: 식 | F35: 10 | G35: 75000 | H35: =IF(F35=0,G35,G35*F35) -> 750000
C36: Manifold | D36: VV5QC41 | E36: 식 | F36: 1 | G36: 850000 | H36: =IF(F36=0,G36,G36*F36) -> 850000
C37: Speed Con | E37: 식 | F37: 10 | G37: 7000 | H37: =IF(F37=0,G37,G37*F37) -> 70000
C38: 배관자재 | E38: 식 | F38: 1 | G38: 100000 | H38: =IF(F38=0,G38,G38*F38) -> 100000
C39: 잡자재 | E39: 식 | F39: 1 | G39: 100000 | H39: =IF(F39=0,G39,G39*F39) -> 100000
H40: =IF(F40=0,G40,G40*F40) -> 0
...

Sheet #70
B1: □ 단위공사명(전기제외): | C1: BOLT압입 | I1: (첨부)
A2: 구분 | C2: 품 명 | D2: 규격 | E2: 단위 | F2: 수량 | G2: 단가(원) | H2: 금액(원) | I2: 原MAKER
A3: 자 재 비 | B3: 철자재 | C3: ■BASE | D3: 제관,가공 | E3: 식 | F3: 1 | G3: 2000000 | H3: =IF(F3=0,G3,G3*F3) -> 2000000
C4: ■FRAME | D4: 제관,가공 | E4: 식 | F4: 1 | G4: 1500000 | H4: =IF(F4=0,G4,G4*F4) -> 1500000
C5: ■상측 COVER | D5: 제관,가공 | E5: 식 | F5: 1 | G5: 1500000 | H5: =IF(F5=0,G5,G5*F5) -> 1500000
C6: ■OP POST | E6: 식 | F6: 1 | G6: 600000 | H6: =IF(F6=0,G6,G6*F6) -> 600000
C7: ■압입부 | E7: 식 | F7: 2 | G7: 2000000 | H7: =IF(F7=0,G7,G7*F7) -> 4000000
C8: ■소재이송 | E8: 식 | F8: 2 | G8: 2000000 | H8: =IF(F8=0,G8,G8*F8) -> 4000000
C9: ■소재안착 | E9: 식 | F9: 2 | G9: 2500000 | H9: =IF(F9=0,G9,G9*F9) -> 5000000
C10: ■LIFTER UNIT | E10: 식 | F10: 2 | G10: 1300000 | H10: =IF(F10=0,G10,G10*F10) -> 2600000
H11: =IF(F11=0,G11,G11*F11) -> 0
C12: 기타 가공물 | E12: 식 | F12: 2 | G12: 200000 | H12: 0
H13: =SUM(H3:H12) -> 21200000
B14: 설치/해체/시운전 | H14: =IF(F14=0,G14,G14*F14) -> 0
B15: 공사 관련 자재 | H15: =IF(F15=0,G15,G15*F15) -> 0
H16: =IF(F16=0,G16,G16*F16) -> 0
H17: =IF(F17=0,G17,G17*F17) -> 0
C18: 기타자재 | H18: =IF(F18=0,G18,G18*F18) -> 0
H19: =SUM(H14:H18) -> 0
B20: 구매품 | C20: ■압입부 | H20: =IF(F20=0,G20,G20*F20) -> 0
B21: (유공압품외) | C21: 서보프레스 | D21: 5t | E21: 식 | F21: 2 | G21: 24000000 | H21: =IF(F21=0,G21,G21*F21) -> 48000000
C22: ■소재이송 | H22: =IF(F22=0,G22,G22*F22) -> 0
C23: 전후이송 | D23: 실린더1축 | E23: 식 | F23: 2 | G23: 1200000 | H23: =IF(F23=0,G23,G23*F23) -> 2400000
C24: 그리퍼 | E24: 식 | F24: 2 | G24: 1000000 | H24: =IF(F24=0,G24,G24*F24) -> 2000000
C25: PROXIMITY SENSOR | E25: 식 | F25: 2 | G25: 160000 | H25: =IF(F25=0,G25,G25*F25) -> 320000
C26: 소재 감지 SENSOR | E26: 식 | F26: 2 | G26: 100000 | H26: =IF(F26=0,G26,G26*F26) -> 200000
C27: 일반구입물 | E27: 식 | F27: 2 | G27: 500000 | H27: =IF(F27=0,G27,G27*F27) -> 1000000
C28: ■소재안착 | H28: =IF(F28=0,G28,G28*F28) -> 0
C29: 회전부 | D29: 모타1축 | E29: 식 | F29: 2 | G29: 800000 | H29: =IF(F29=0,G29,G29*F29) -> 1600000
C30: BACK UP | E30: 식 | F30: 2 | G30: 400000 | H30: =IF(F30=0,G30,G30*F30) -> 800000
C31: PROXIMITY SENSOR | E31: 식 | F31: 2 | G31: 160000 | H31: =IF(F31=0,G31,G31*F31) -> 320000
C32: 소재 감지 SENSOR | E32: 식 | F32: 2 | G32: 100000 | H32: =IF(F32=0,G32,G32*F32) -> 200000
C33: 일반구입물 | E33: 식 | F33: 2 | G33: 200000 | H33: =IF(F33=0,G33,G33*F33) -> 400000
C34: ■LIFTER UNIT | E34: 식 | F34: 2 | G34: 600000 | H34: =IF(F34=0,G34,G34*F34) -> 1200000
H35: =IF(F35=0,G35,G35*F35) -> 0
C36: ■일반 자재류 | H36: =IF(F36=0,G36,G36*F36) -> 0
C37: F.R.L Unit | D37: AV4000 | E37: 식 | F37: 2 | G37: 350000 | H37: =IF(F37=0,G37,G37*F37) -> 700000
C38: SOL V/V | D38: VQC4201 | E38: 식 | F38: 20 | G38: 75000 | H38: =IF(F38=0,G38,G38*F38) -> 1500000
C39: Manifold | D39: VV5QC41 | E39: 식 | F39: 2 | G39: 850000 | H39: =IF(F39=0,G39,G39*F39) -> 1700000
C40: Speed Con | E40: 식 | F40: 30 | G40: 7000 | H40: =IF(F40=0,G40,G40*F40) -> 210000
...

Sheet #80
B1: □ 단위공사명(전기제외): | C1: 허버볼트 직각도 검사 | I1: (첨부)
A2: 구분 | C2: 품 명 | D2: 규격 | E2: 단위 | F2: 수량 | G2: 단가(원) | H2: 금액(원) | I2: 原MAKER
A3: 자 재 비 | B3: 철자재 | C3: ■BASE | D3: 제관,가공 | E3: 식 | F3: 1 | G3: 2000000 | H3: =IF(F3=0,G3,G3*F3) -> 2000000
C4: ■FRAME | D4: 제관,가공 | E4: 식 | F4: 1 | G4: 1500000 | H4: =IF(F4=0,G4,G4*F4) -> 1500000
C5: ■상측 COVER | D5: 제관,가공 | E5: 식 | F5: 1 | G5: 1500000 | H5: =IF(F5=0,G5,G5*F5) -> 1500000
C6: ■OP POST | E6: 식 | F6: 1 | G6: 600000 | H6: =IF(F6=0,G6,G6*F6) -> 600000
C7: ■V-SLIDE부 | E7: 식 | F7: 1 | G7: 6500000 | H7: =IF(F7=0,G7,G7*F7) -> 6500000
C8: ■측정헤드 | E8: 식 | F8: 1 | G8: 5800000 | H8: =IF(F8=0,G8,G8*F8) -> 5800000
C9: ■측정헤드 슬라이드장치 | E9: 식 | F9: 1 | G9: 4600000 | H9: =IF(F9=0,G9,G9*F9) -> 4600000
C10: ■LIFTER UNIT | E10: 식 | F10: 1 | G10: 1300000 | H10: =IF(F10=0,G10,G10*F10) -> 1300000
H11: =IF(F11=0,G11,G11*F11) -> 0
C12: 기타 | E12: 식 | F12: 1 | G12: 1000000 | H12: 0
H13: =SUM(H3:H12) -> 23800000
B14: 설치/해체/시운전 | H14: =IF(F14=0,G14,G14*F14) -> 0
B15: 공사 관련 자재 | H15: =IF(F15=0,G15,G15*F15) -> 0
H16: =IF(F16=0,G16,G16*F16) -> 0
H17: =IF(F17=0,G17,G17*F17) -> 0
C18: 기타자재 | H18: =IF(F18=0,G18,G18*F18) -> 0
H19: =SUM(H14:H18) -> 0
B20: 구매품 | C20: ■AIR CYL'류 | E20: 식 | F20: 1 | G20: 1500000 | H20: =IF(F20=0,G20,G20*F20) -> 1500000
B21: (유공압품외) | C21: ■체인 | E21: 식 | F21: 1 | G21: 400000 | H21: =IF(F21=0,G21,G21*F21) -> 400000
C22: ■LM 및 BEARING | E22: 식 | F22: 1 | G22: 1000000 | H22: =IF(F22=0,G22,G22*F22) -> 1000000
C23: ■LVDT | E23: 식 | F23: 10 | G23: 1860000 | H23: =IF(F23=0,G23,G23*F23) -> 18600000
C24: ■도어센스 | E24: 식 | F24: 1 | G24: 500000 | H24: =IF(F24=0,G24,G24*F24) -> 500000
C25: ■PROXIMITY SENSOR | E25: EA | F25: 20 | G25: 40000 | H25: =IF(F25=0,G25,G25*F25) -> 800000
C26: ■소재 감지 센스 | E26: EA | F26: 8 | G26: 100000 | H26: =IF(F26=0,G26,G26*F26) -> 800000
C27: ■LIFTER UNIT | E27: 식 | F27: 1 | G27: 600000 | H27: =IF(F27=0,G27,G27*F27) -> 600000
H28: =IF(F28=0,G28,G28*F28) -> 0
C29: ■일반 자재류 | H29: =IF(F29=0,G29,G29*F29) -> 0
C30: F.R.L Unit | D30: AV4000 | E30: 식 | F30: 1 | G30: 350000 | H30: =IF(F30=0,G30,G30*F30) -> 350000
C31: SOL V/V | D31: VQC4201 | E31: 식 | F31: 10 | G31: 75000 | H31: =IF(F31=0,G31,G31*F31) -> 750000
C32: Manifold | D32: VV5QC41 | E32: 식 | F32: 1 | G32: 850000 | H32: =IF(F32=0,G32,G32*F32) -> 850000
C33: Speed Con | E33: 식 | F33: 20 | G33: 7000 | H33: =IF(F33=0,G33,G33*F33) -> 140000
C34: 배관자재 | E34: 식 | F34: 1 | G34: 100000 | H34: =IF(F34=0,G34,G34*F34) -> 100000
C35: 잡자재 | E35: 식 | F35: 1 | G35: 100000 | H35: =IF(F35=0,G35,G35*F35) -> 100000
H36: =IF(F36=0,G36,G36*F36) -> 0
C37: 기타자재 | E37: 식 | F37: 1 | G37: 1000000 | H37: 0
H38: =SUM(H20:H37) -> 26490000
B39: 외주제작품 | H39: =IF(F39=0,G39,G39*F39) -> 0
H40: =IF(F40=0,G40,G40*F40) -> 0
...

Sheet #90
B1: □ 단위공사명(전기제외): | C1: 베어링 공급 및 압입기 | I1: (첨부)
A2: 구분 | C2: 품 명 | D2: 규격 | E2: 단위 | F2: 수량 | G2: 단가(원) | H2: 금액(원) | I2: 原MAKER
A3: 자 재 비 | B3: 철자재 | C3: ■BASE | D3: 제관,가공 | E3: 식 | F3: 1 | G3: 2000000 | H3: =IF(F3=0,G3,G3*F3) -> 2000000
C4: ■FRAME | D4: 제관,가공 | E4: 식 | F4: 1 | G4: 1500000 | H4: =IF(F4=0,G4,G4*F4) -> 1500000
C5: ■상측 COVER | D5: 제관,가공 | E5: 식 | F5: 1 | G5: 1500000 | H5: =IF(F5=0,G5,G5*F5) -> 1500000
C6: ■OP POST | E6: 식 | F6: 1 | G6: 600000 | H6: =IF(F6=0,G6,G6*F6) -> 600000
