Workbook

Sheet 갑지
B1: (현대/기아차 설비협력업체 견적통일양식)
B2: 見 積 書
B4: 현대 위아 貴下 | G4: ㈜지이엠
B5: 견적일자 | D5: 43787 | G5: 대표 : 송 칠 영 (인)
B6: 견적번호 | D6: GD1_191118-003 | G6: 주소 : 경남 창원시 성산구
B7: 납기 | C7: 입하 | G7: 성산패총로24번길 1
C8: 최종검수 | G8: 전화: 055-282-9488
B9: 견적유효기간 | D9: 견적일로부터30일 | G9: Fax: 055-282-9484 / 9490
B10: 인도장소 | D10: 현대위아 공장 | G10: 견적담당: | H10: 정대헌부장
B11: 지불조건 | D11: 현대위아 기준 | G11: 연 락 처 : | H11: 010-3452-0737
B13: 견적금액: 一金일십일억일천삼백만원整(\1,113,000,000 )
B15: 번호 | C15: 상세품목내역 | E15: 견적금액 (천원) | I15: 비 고
E16: 기계부분 | F16: 전기부문 | G16: 관리/이윤 (안전관리비포함) | H16: 합 계
B17: 1 | C17: =IF('단위공사별(집계)'!N7>0,'단위공사별(집계)'!B7,"") -> OB 비젼검사/그리스 주입 | E17: =IF('단위공사별(집계)'!N7>1,('단위공사별(집계)'!D7+'단위공사별(집계)'!E7+'단위공사별(집계)'!F7+'단위공사별(집계)'!G7+'단위공사별(집계)'!H7+'단위공사별(집계)'!I7)/1000," ") -> 68745.811 | F17: =IF('단위공사별(집계)'!N7>0,'단위공사별(집계)'!K27/1000,"") -> 198500 | G17: =IF('단위공사별(집계)'!N7>0,('단위공사별(집계)'!L7+'단위공사별(집계)'!M7)/1000,"") -> 101.61482 | H17: =IF('단위공사별(집계)'!N7>0,'단위공사별(집계)'!N7/1000,"") -> 83788.567
B18: 2 | C18: =IF('단위공사별(집계)'!N8>0,'단위공사별(집계)'!B8,"") -> BOOT조립기 | E18: =IF('단위공사별(집계)'!N8>1,('단위공사별(집계)'!D8+'단위공사별(집계)'!E8+'단위공사별(집계)'!F8+'단위공사별(집계)'!G8+'단위공사별(집계)'!H8+'단위공사별(집계)'!I8)/1000," ") -> 182338.93 | G18: =IF('단위공사별(집계)'!N8>0,('단위공사별(집계)'!L8+'단위공사별(집계)'!M8)/1000,"") -> 269.51951 | H18: =IF('단위공사별(집계)'!N8>0,'단위공사별(집계)'!N8/1000,"") -> 222237.8
B19: 3 | C19: =IF('단위공사별(집계)'!N9>0,'단위공사별(집계)'!B9,"") -> D/SHAFT 가조립 | E19: =IF('단위공사별(집계)'!N9>1,('단위공사별(집계)'!D9+'단위공사별(집계)'!E9+'단위공사별(집계)'!F9+'단위공사별(집계)'!G9+'단위공사별(집계)'!H9+'단위공사별(집계)'!I9)/1000," ") -> 19614.428 | G19: =IF('단위공사별(집계)'!N9>0,('단위공사별(집계)'!L9+'단위공사별(집계)'!M9)/1000,"") -> 28.992552 | H19: =IF('단위공사별(집계)'!N9>0,'단위공사별(집계)'!N9/1000,"") -> 23906.399
B20: 4 | C20: =IF('단위공사별(집계)'!N10>0,'단위공사별(집계)'!B10,"") -> D/SHAFT 압입 | E20: =IF('단위공사별(집계)'!N10>1,('단위공사별(집계)'!D10+'단위공사별(집계)'!E10+'단위공사별(집계)'!F10+'단위공사별(집계)'!G10+'단위공사별(집계)'!H10+'단위공사별(집계)'!I10)/1000," ") -> 49633.031 | G20: =IF('단위공사별(집계)'!N10>0,('단위공사별(집계)'!L10+'단위공사별(집계)'!M10)/1000,"") -> 73.363762 | H20: =IF('단위공사별(집계)'!N10>0,'단위공사별(집계)'!N10/1000,"") -> 60493.585
B21: 5 | C21: =IF('단위공사별(집계)'!N11>0,'단위공사별(집계)'!B11,"") -> I/B 가조립 | E21: =IF('단위공사별(집계)'!N11>1,('단위공사별(집계)'!D11+'단위공사별(집계)'!E11+'단위공사별(집계)'!F11+'단위공사별(집계)'!G11+'단위공사별(집계)'!H11+'단위공사별(집계)'!I11)/1000," ") -> 24781.4 | G21: =IF('단위공사별(집계)'!N11>0,('단위공사별(집계)'!L11+'단위공사별(집계)'!M11)/1000,"") -> 36.629976 | H21: =IF('단위공사별(집계)'!N11>0,'단위공사별(집계)'!N11/1000,"") -> 30203.993
B22: 6 | C22: =IF('단위공사별(집계)'!N12>0,'단위공사별(집계)'!B12,"") -> I/B 압입 | E22: =IF('단위공사별(집계)'!N12>1,('단위공사별(집계)'!D12+'단위공사별(집계)'!E12+'단위공사별(집계)'!F12+'단위공사별(집계)'!G12+'단위공사별(집계)'!H12+'단위공사별(집계)'!I12)/1000," ") -> 49552.767 | G22: =IF('단위공사별(집계)'!N12>0,('단위공사별(집계)'!L12+'단위공사별(집계)'!M12)/1000,"") -> 73.245123 | H22: =IF('단위공사별(집계)'!N12>0,'단위공사별(집계)'!N12/1000,"") -> 60395.758
B23: 7 | C23: =IF('단위공사별(집계)'!N13>0,'단위공사별(집계)'!B13,"") -> 대경 밴드체결 | E23: =IF('단위공사별(집계)'!N13>1,('단위공사별(집계)'!D13+'단위공사별(집계)'!E13+'단위공사별(집계)'!F13+'단위공사별(집계)'!G13+'단위공사별(집계)'!H13+'단위공사별(집계)'!I13)/1000," ") -> 34352.839 | G23: =IF('단위공사별(집계)'!N13>0,('단위공사별(집계)'!L13+'단위공사별(집계)'!M13)/1000,"") -> 50.777748 | H23: =IF('단위공사별(집계)'!N13>0,'단위공사별(집계)'!N13/1000,"") -> 41869.827
B24: 8 | C24: =IF('단위공사별(집계)'!N14>0,'단위공사별(집계)'!B14,"") -> 완성비젼 | E24: =IF('단위공사별(집계)'!N14>1,('단위공사별(집계)'!D14+'단위공사별(집계)'!E14+'단위공사별(집계)'!F14+'단위공사별(집계)'!G14+'단위공사별(집계)'!H14+'단위공사별(집계)'!I14)/1000," ") -> 69598.612 | G24: =IF('단위공사별(집계)'!N14>0,('단위공사별(집계)'!L14+'단위공사별(집계)'!M14)/1000,"") -> 102.87536 | H24: =IF('단위공사별(집계)'!N14>0,'단위공사별(집계)'!N14/1000,"") -> 84827.976
B25: 9 | C25: =IF('단위공사별(집계)'!N15>0,'단위공사별(집계)'!B15,"") -> UN-LOADING 배출 및 적재 | E25: =IF('단위공사별(집계)'!N15>1,('단위공사별(집계)'!D15+'단위공사별(집계)'!E15+'단위공사별(집계)'!F15+'단위공사별(집계)'!G15+'단위공사별(집계)'!H15+'단위공사별(집계)'!I15)/1000," ") -> 104713.96 | G25: =IF('단위공사별(집계)'!N15>0,('단위공사별(집계)'!L15+'단위공사별(집계)'!M15)/1000,"") -> 154.78019 | H25: =IF('단위공사별(집계)'!N15>0,'단위공사별(집계)'!N15/1000,"") -> 127627.16
B26: 10 | C26: =IF('단위공사별(집계)'!N16>0,'단위공사별(집계)'!B16,"") -> MAIN CONVEYOR | E26: =IF('단위공사별(집계)'!N16>1,('단위공사별(집계)'!D16+'단위공사별(집계)'!E16+'단위공사별(집계)'!F16+'단위공사별(집계)'!G16+'단위공사별(집계)'!H16+'단위공사별(집계)'!I16)/1000," ") -> 117656.47 | G26: =IF('단위공사별(집계)'!N16>0,('단위공사별(집계)'!L16+'단위공사별(집계)'!M16)/1000,"") -> 173.91082 | H26: =IF('단위공사별(집계)'!N16>0,'단위공사별(집계)'!N16/1000,"") -> 143401.71
B27: 11 | C27: =IF('단위공사별(집계)'!N17>0,'단위공사별(집계)'!B17,"") -> PALLETS | E27: =IF('단위공사별(집계)'!N17>1,('단위공사별(집계)'!D17+'단위공사별(집계)'!E17+'단위공사별(집계)'!F17+'단위공사별(집계)'!G17+'단위공사별(집계)'!H17+'단위공사별(집계)'!I17)/1000," ") -> 103038.45 | G27: =IF('단위공사별(집계)'!N17>0,('단위공사별(집계)'!L17+'단위공사별(집계)'!M17)/1000,"") -> 152.30359 | H27: =IF('단위공사별(집계)'!N17>0,'단위공사별(집계)'!N17/1000,"") -> 125585.02
B28: 12 | C28: =IF('단위공사별(집계)'!N18>0,'단위공사별(집계)'!B18,"") -> GREASE PUMP SYSTEM | E28: =IF('단위공사별(집계)'!N18>1,('단위공사별(집계)'!D18+'단위공사별(집계)'!E18+'단위공사별(집계)'!F18+'단위공사별(집계)'!G18+'단위공사별(집계)'!H18+'단위공사별(집계)'!I18)/1000," ") -> 43141.708 | G28: =IF('단위공사별(집계)'!N18>0,('단위공사별(집계)'!L18+'단위공사별(집계)'!M18)/1000,"") -> 63.768785 | H28: =IF('단위공사별(집계)'!N18>0,'단위공사별(집계)'!N18/1000,"") -> 52581.85
B29: 13 | C29: =IF('단위공사별(집계)'!N19>0,'단위공사별(집계)'!B19,"") -> LMS SYSTEM | E29: =IF('단위공사별(집계)'!N19>1,('단위공사별(집계)'!D19+'단위공사별(집계)'!E19+'단위공사별(집계)'!F19+'단위공사별(집계)'!G19+'단위공사별(집계)'!H19+'단위공사별(집계)'!I19)/1000," ") -> 30098.866 | G29: =IF('단위공사별(집계)'!N19>0,('단위공사별(집계)'!L19+'단위공사별(집계)'!M19)/1000,"") -> 44.48985 | H29: =IF('단위공사별(집계)'!N19>0,'단위공사별(집계)'!N19/1000,"") -> 36685.012
... B36: 20 | C36: =IF('단위공사별(집계)'!N26>0,'단위공사별(집계)'!B26,"") | E36: =IF('단위공사별(집계)'!N26>1,('단위공사별(집계)'!D26+'단위공사별(집계)'!E26+'단위공사별(집계)'!F26+'단위공사별(집계)'!G26+'단위공사별(집계)'!H26+'단위공사별(집계)'!I26)/1000," ") | G36: =IF('단위공사별(집계)'!N26>0,('단위공사별(집계)'!L26+'단위공사별(집계)'!M26)/1000,"") | H36: =IF('단위공사별(집계)'!N26>0,'단위공사별(집계)'!N26/1000,"")
B37: 견적 합계 | E37: =SUM(E17:E36) -> 913320 | F37: =SUM(F17:F36) -> 198500 | G37: =SUM(G17:G36) -> 1350 | H37: =ROUNDDOWN(SUM(H17:H36),-3) -> 1113000
F39: 공개입찰가 (견적時 공란) | H39: 1113000
B41: 특기사항 | C41: 1. VAT 제외 | F41: 외주계획 업체명 (자작時 공란)
C42: 2. 기본 유틸리티공사 제외 | F42: 설계외주
C43: ='원가항목별(집계)'!I39 -> 1350000 | F43: 제작외주
F44: 전기외주
F45: 설치외주

Sheet 원가항목별(집계)
C2: A. 원가항목별 견적가 종합(상세견적 첨부)
B4: □ 현대/기아 요구사양과 견적조건 일치여부 CHECK: 1.일치함 2.일부상이(상이내역 첨부참조)
B6: 순번 | C6: 원가구분 | F6: 단위 | G6: 수량 | H6: 단가 | I6: 금 액(원) | J6: 비 고
B7: 1 | C7: 기계 부문 | D7: 자재비 | E7: 철자재(SS.SUS등) | F7: kg | G7: ='#10'!F27+'#20'!F51+'#30'!F22+'#40'!F20+'#50'!F18+'#60'!F21+'#70'!F19+'#80'!F18+'#90'!F23+'#100'!F23 -> 0 | I7: ='#10'!H21+'#20'!H47+'#30'!H16+'#40'!H14+'#50'!H12+'#60'!H15+'#70'!H13+'#80'!H12+'#90'!H17+'#100'!H17+'#110'!I47+'#120'!H19+'#130'!H19+'#140'!H20+'#150'!H20+'#160'!H20+'#170'!H20+'#180'!H20+'#190'!H20+'#200'!H20 -> 246050000 | J7: 加工必要資材
E8: 일반구매품 | F8: 식 | G8: 1 | I8: ='#10'!H48+'#20'!H103+'#30'!H39+'#40'!H40+'#50'!H32+'#60'!H47+'#70'!H46+'#80'!H42+'#90'!H54+'#100'!H45+'#110'!I103+'#120'!H46+'#130'!H46+'#140'!H47+'#150'!H47+'#160'!H46+'#170'!H47+'#180'!H46+'#190'!H46+'#200'!H46 -> 446970000 | J8: 加工不要資材
E9: 외주제작품 | F9: 식 | G9: 1 | I9: ='#10'!H56+'#20'!H111+'#30'!H47+'#40'!H48+'#50'!H40+'#60'!H55+'#70'!H54+'#80'!H50+'#90'!H62+'#100'!H53+'#110'!I106+'#120'!H54+'#130'!H54+'#140'!H55+'#150'!H55+'#160'!H54+'#170'!H55+'#180'!H54+'#190'!H54+'#200'!H54 -> 85000000 | J9: 旣加工SUB資材
E10: 설치/해체 공사 자재 | F10: 식 | G10: 1 | I10: ='#10'!H27+'#20'!H51+'#30'!H22+'#40'!H20+'#50'!H18+'#60'!H21+'#70'!H19+'#80'!H18+'#90'!H23+'#100'!H23+'#110'!I51+'#120'!H25+'#130'!H25+'#140'!H26+'#150'!H26+'#160'!H26+'#170'!H26+'#180'!H26+'#190'!H26+'#200'!H26 -> 0 | J10: 시운전 자재 포함
E11: 소계 | I11: =SUM(I7:I10) -> 778020000
D12: 노무비 | E12: 기존설비 철거 | F12: M/D | G12: ='#10'!F58+'#20'!F113+'#30'!F49+'#40'!F50+'#50'!F42+'#60'!F57+'#70'!F56+'#80'!F52+'#90'!F64+'#100'!F55+'#110'!G108+'#120'!F56+'#130'!F56+'#140'!F57+'#150'!F57+'#160'!F56+'#170'!F57+'#180'!F56 -> 0 | H12: =IF('#10'!G58>0,'#10'!G58,"") -> 250000 | I12: ='#10'!H58+'#20'!H113+'#30'!H49+'#40'!H50+'#50'!H42+'#60'!H57+'#70'!H56+'#80'!H52+'#90'!H64+'#100'!H55+'#110'!I108+'#120'!H56+'#130'!H56+'#140'!H57+'#150'!H57+'#160'!H56+'#170'!H57+'#180'!H56+'#190'!H56+'#200'!H56 -> 0 | J12: 개조공사時
E13: 설계 | F13: M/D | G13: ='#10'!F59+'#20'!F114+'#30'!F50+'#40'!F51+'#50'!F43+'#60'!F58+'#70'!F57+'#80'!F53+'#90'!F65+'#100'!F56+'#110'!G109+'#120'!F57+'#130'!F57+'#140'!F58+'#150'!F58+'#160'!F57+'#170'!F58+'#180'!F57 -> 160 | H13: =IF('#10'!G59>0,'#10'!G59,"") -> 300000 | I13: ='#10'!H59+'#20'!H114+'#30'!H50+'#40'!H51+'#50'!H43+'#60'!H58+'#70'!H57+'#80'!H53+'#90'!H65+'#100'!H56+'#110'!I109+'#120'!H57+'#130'!H57+'#140'!H58+'#150'!H58+'#160'!H57+'#170'!H58+'#180'!H57+'#190'!H57+'#200'!H57 -> 48000000
E14: 제작(제관,가공) | F14: M/D | G14: ='#10'!F60+'#20'!F115+'#30'!F51+'#40'!F52+'#50'!F44+'#60'!F59+'#70'!F58+'#80'!F54+'#90'!F66+'#100'!F57+'#110'!G110+'#120'!F58+'#130'!F58+'#140'!F59+'#150'!F59+'#160'!F58+'#170'!F59+'#180'!F58 -> 33 | H14: =IF('#10'!G60>0,'#10'!G60,"") -> 250000 | I14: ='#10'!H60+'#20'!H115+'#30'!H51+'#40'!H52+'#50'!H44+'#60'!H59+'#70'!H58+'#80'!H54+'#90'!H66+'#100'!H57+'#110'!I110+'#120'!H58+'#130'!H58+'#140'!H59+'#150'!H59+'#160'!H58+'#170'!H59+'#180'!H58+'#190'!H58+'#200'!H58 -> 8250000
E15: 조립 | F15: M/D | G15: ='#10'!F61+'#20'!F116+'#30'!F52+'#40'!F53+'#50'!F45+'#60'!F60+'#70'!F59+'#80'!F55+'#90'!F67+'#100'!F58+'#110'!G111+'#120'!F59+'#130'!F59+'#140'!F60+'#150'!F60+'#160'!F59+'#170'!F60+'#180'!F59 -> 175 | H15: =IF('#10'!G61>0,'#10'!G61,"") -> 250000 | I15: ='#10'!H61+'#20'!H116+'#30'!H52+'#40'!H53+'#50'!H45+'#60'!H60+'#70'!H59+'#80'!H55+'#90'!H67+'#100'!H58+'#110'!I111+'#120'!H59+'#130'!H59+'#140'!H60+'#150'!H60+'#160'!H59+'#170'!H60+'#180'!H59+'#190'!H59+'#200'!H59 -> 43750000 | J15: 정도검사포함
E16: 설치 | F16: M/D | G16: ='#10'!F62+'#20'!F117+'#30'!F53+'#40'!F54+'#50'!F46+'#60'!F61+'#70'!F60+'#80'!F56+'#90'!F68+'#100'!F59+'#110'!G112+'#120'!F60+'#130'!F60+'#140'!F61+'#150'!F61+'#160'!F60+'#170'!F61+'#180'!F60 -> 36 | H16: =IF('#10'!G62>0,'#10'!G62,"") -> 300000 | I16: ='#10'!H62+'#20'!H117+'#30'!H53+'#40'!H54+'#50'!H46+'#60'!H61+'#70'!H60+'#80'!H56+'#90'!H68+'#100'!H59+'#110'!I112+'#120'!H60+'#130'!H60+'#140'!H61+'#150'!H61+'#160'!H60+'#170'!H61+'#180'!H60+'#190'!H60+'#200'!H60 -> 10800000
E17: 시운전 | F17: M/D | G17: ='#10'!F63+'#20'!F118+'#30'!F54+'#40'!F55+'#50'!F47+'#60'!F62+'#70'!F61+'#80'!F57+'#90'!F69+'#100'!F60+'#110'!G113+'#120'!F61+'#130'!F61+'#140'!F62+'#150'!F62+'#160'!F61+'#170'!F62+'#180'!F61 -> 37 | H17: =IF('#10'!G63>0,'#10'!G63,"") -> 300000 | I17: ='#10'!H63+'#20'!H118+'#30'!H54+'#40'!H55+'#50'!H47+'#60'!H62+'#70'!H61+'#80'!H57+'#90'!H69+'#100'!H60+'#110'!I113+'#120'!H61+'#130'!H61+'#140'!H62+'#150'!H62+'#160'!H61+'#170'!H62+'#180'!H61+'#190'!H61+'#200'!H61 -> 11100000
E18: 양산대응 | F18: M/D | G18: ='#10'!F64+'#20'!F119+'#30'!F55+'#40'!F56+'#50'!F48+'#60'!F63+'#70'!F62+'#80'!F58+'#90'!F70+'#100'!F61+'#110'!G114+'#120'!F62+'#130'!F62+'#140'!F63+'#150'!F63+'#160'!F62+'#170'!F63+'#180'!F62 -> 13 | H18: =IF('#10'!G64>0,'#10'!G64,"") -> 300000 | I18: ='#10'!H64+'#20'!H119+'#30'!H55+'#40'!H56+'#50'!H48+'#60'!H63+'#70'!H62+'#80'!H58+'#90'!H70+'#100'!H61+'#110'!I114+'#120'!H62+'#130'!H62+'#140'!H63+'#150'!H63+'#160'!H62+'#170'!H63+'#180'!H62+'#190'!H62+'#200'!H62 -> 3900000
E19: 도장 | F19: M/D | G19: ='#10'!F65+'#20'!F120+'#30'!F56+'#40'!F57+'#50'!F49+'#60'!F64+'#70'!F63+'#80'!F59+'#90'!F71+'#100'!F62+'#110'!G115+'#120'!F63+'#130'!F63+'#140'!F64+'#150'!F64+'#160'!F63+'#170'!F64+'#180'!F63 -> 26 | H19: =IF('#10'!G65>0,'#10'!G65,"") -> 250000 | I19: ='#10'!H65+'#20'!H120+'#30'!H56+'#40'!H57+'#50'!H49+'#60'!H64+'#70'!H63+'#80'!H59+'#90'!H71+'#100'!H62+'#110'!I115+'#120'!H63+'#130'!H63+'#140'!H64+'#150'!H64+'#160'!H63+'#170'!H64+'#180'!H63+'#190'!H63+'#200'!H63 -> 6500000
E20: 소계 | I20: =SUM(I12:I19) -> 132300000
D21: 일반관리 및 이윤 | I21: ='#10'!H68+'#10'!H69+'#20'!H123+'#20'!H124+'#30'!H59+'#30'!H60+'#40'!H60+'#40'!H61+'#50'!H52+'#50'!H53+'#60'!H67+'#60'!H68+'#70'!H66+'#70'!H67+'#80'!H62+'#80'!H63+'#90'!H74+'#90'!H75+'#100'!H65+'#100'!H66+'#110'!I118+'#110'!I119+'#120'!H66+'#120'!H67+'#130'!H66+'#130'!H67+'#140'!H67+'#140'!H68+'#150'!H67+'#150'!H68+'#160'!H66+'#160'!H67+'#170'!H67+'#170'!H68+'#180'!H66+'#180'!H67+'#190'!H66+'#190'!H67+'#200'!H66+'#200'!H67 -> 0
E22: 기계 소계 | I22: =I20+I11+I21 -> 910320000
B23: 2 | C23: 전기 부문 | D23: 자재비 | E23: 기계/전기자재 | F23: 식 | G23: 1 | I23: =전기!H35-I24 -> 145000000
E24: 설치/해체 공사 자재 | F24: 식 | G24: 1 | I24: =전기!H16 -> 0 | J24: 시운전 자재 포함
D25: 노무비 | E25: 철거(개조시) | F25: M/D | G25: =전기!F36 -> 10 | H25: =IF(전기!G36>0,전기!G36,"") -> 250000 | I25: =전기!H36 -> 2500000
E26: 설계,프로그램 | F26: M/D | G26: =전기!F37 -> 50 | H26: =IF(전기!G37>0,전기!G37,"") -> 300000 | I26: =전기!H37 -> 15000000
E27: 제작 | F27: M/D | G27: =전기!F38 -> 30 | H27: =IF(전기!G38>0,전기!G38,"") -> 250000 | I27: =전기!H38 -> 7500000
E28: 조립 | F28: M/D | G28: =전기!F39 -> 30 | H28: =IF(전기!G39>0,전기!G39,"") -> 250000 | I28: =전기!H39 -> 7500000
E29: 설치 | F29: M/D | G29: =전기!F40 -> 20 | H29: =IF(전기!G40>0,전기!G40,"") -> 300000 | I29: =전기!H40 -> 6000000
E30: 시운전 | F30: M/D | G30: =전기!F41 -> 20 | H30: =IF(전기!G41>0,전기!G41,"") -> 300000 | I30: =전기!H41 -> 6000000
E31: 양산대응 | F31: M/D | G31: =전기!F42 -> 30 | H31: =IF(전기!G42>0,전기!G42,"") -> 300000 | I31: =전기!H42 -> 9000000
E32: 소계 | I32: =SUM(I25:I31) -> 53500000
D33: 일반관리 및 이윤 | I33: =전기!H45+전기!H46 -> 0
E34: 전기 소계 | I34: =I32+I23+I33+I24 -> 198500000
B35: 3 | C35: 자재비 합계 | I35: =I23+I11+I24 -> 923020000
C36: 노무비 합계 | I36: =I32+I20 -> 185800000
C37: 중간 합계 | I37: =I36+I35 -> 1108820000
B38: 4 | C38: 포장,운송 및 중장비 사용료 | I38: 3000000
B39: 5 | C39: 표준안전관리비 | F39: 설치/철거/수리금액 기준 | I39: =CEILING(MIN(I47:I48),1000) -> 1350000 | J39: =I30+I29+I25+I24+I17+I16+I12+I10 -> 36400000
B40: 6 | C40: 일반관리비 | I40: =전기!H45+'#10'!H68+'#20'!H123+'#30'!H59+'#40'!H60+'#50'!H52+'#60'!H67+'#70'!H66+'#80'!H62+'#90'!H74+'#100'!H65+'#110'!I118+'#120'!H66+'#130'!H66+'#140'!H67+'#150'!H67+'#160'!H66+'#170'!H67+'#180'!H66+'#190'!H66+'#200'!H66 -> 0
B41: 7 | C41: 이 윤 | I41: =전기!H46+'#10'!H69+'#20'!H124+'#30'!H60+'#40'!H61+'#50'!H53+'#60'!H68+'#70'!H67+'#80'!H63+'#90'!H75+'#100'!H66+'#110'!I119+'#120'!H67+'#130'!H67+'#140'!H68+'#150'!H68+'#160'!H67+'#170'!H68+'#180'!H67+'#190'!H67+'#200'!H67 -> 0
C42: 합 계 | F42: 3~7항 합계 | I42: =I22+I34+I38+I39 -> 1113170000
B43: 주1. 표준안전관리비:(설치/철거/시운전 공사 관련 금액)의 ⓐ2.66%,ⓑ1.95%+기초액,ⓒ2.02%(50억 이상일경우)
...

Sheet 단위공사별(집계)
A2: B. 단위장비별 견적가 종합(상세견적 첨부)
N3: 단위:원
I5: 포장/운송 | L5: 표준안전 | M5: 일반관리비
A6: 순번 | B6: 단위장비명 | C6: 수량 | D6: 자재비 | E6: 철거 | F6: 제작 | G6: 설치/시운전 | H6: 양산대응 | I6: 중장비사용 | J6: 기계소계 | K6: 전기소계 | L6: 관리비 | M6: 이윤 | N6: 합 계 | O6: 비 고
A7: =IF(B7>0,1,"") -> 1 | B7: ='#10'!C$1 -> OB 비젼검사/그리스 주입 | C7: 1식 | D7: ='#10'!H57 -> 55570000 | E7: ='#10'!H58 -> 0 | F7: ='#10'!H59+'#10'!H60+'#10'!H61+'#10'!H65 -> 10250000 | G7: ='#10'!H62+'#10'!H63 -> 1800000 | H7: ='#10'!H64 -> 900000 | I7: =IF($B7>0,'원가항목별(집계)'!I$38*$P7/$P$27,0) -> 225810.7 | J7: =SUM(D7:I7) -> 68745811 | K7: =IF(B7>0,'원가항목별(집계)'!I$34*P7/P$27,0) -> 14941142 | L7: =IF($B7>0,'원가항목별(집계)'!I$39*$P7/$P$27,0) -> 101614.82 | M7: ='#10'!H68+'#10'!H69 -> 0 | N7: =SUM(J7:M7) -> 83788567 | P7: =D7+E7+F7+G7+H7+M7 -> 68520000
A8: =IF(B8>0,A7+1,"") -> 2 | B8: ='#20'!C$1 -> BOOT조립기 | C8: 1식 | D8: ='#20'!H112 -> 161040000 | E8: ='#20'!H113 -> 0 | F8: ='#20'!H114+'#20'!H115+'#20'!H116+'#20'!H120 -> 18000000 | G8: ='#20'!H117+'#20'!H118 -> 2400000 | H8: ='#20'!H119 -> 300000 | I8: =IF($B8>0,'원가항목별(집계)'!I$38*$P8/$P$27,0) -> 598932.24 | J8: =SUM(D8:I8) -> 1.8233893e+08 | K8: =IF(B8>0,'원가항목별(집계)'!I$34*P8/P$27,0) -> 39629350 | L8: =IF($B8>0,'원가항목별(집계)'!I$39*$P8/$P$27,0) -> 269519.51 | M8: ='#20'!H123+'#20'!H124 -> 0 | N8: =SUM(J8:M8) -> 2.222378e+08 | P8: =D8+E8+F8+G8+H8+M8 -> 181740000
A9: =IF(B9>0,A8+1,"") -> 3 | B9: ='#30'!C$1 -> D/SHAFT 가조립 | C9: 1식 | D9: ='#30'!H48 -> 16800000 | E9: ='#30'!H49 -> 0 | F9: ='#30'!H50+'#30'!H51+'#30'!H52+'#30'!H56 -> 2750000 | G9: ='#30'!H53+'#30'!H54 -> 0 | H9: ='#30'!H55 -> 0 | I9: =IF($B9>0,'원가항목별(집계)'!I$38*$P9/$P$27,0) -> 64427.893 | J9: =SUM(D9:I9) -> 19614428 | K9: =IF(B9>0,'원가항목별(집계)'!I$34*P9/P$27,0) -> 4262979 | L9: =IF($B9>0,'원가항목별(집계)'!I$39*$P9/$P$27,0) -> 28992.552 | M9: ='#30'!H59+'#30'!H60 -> 0 | N9: =SUM(J9:M9) -> 23906399 | P9: =D9+E9+F9+G9+H9+M9 -> 19550000
A10: =IF(B10>0,A9+1,"") -> 4 | B10: ='#40'!C$1 -> D/SHAFT 압입 | C10: 1식 | D10: ='#40'!H49 -> 37070000 | E10: ='#40'!H50 -> 0 | F10: ='#40'!H51+'#40'!H52+'#40'!H53+'#40'!H57 -> 10000000 | G10: ='#40'!H54+'#40'!H55 -> 1800000 | H10: ='#40'!H56 -> 600000 | I10: =IF($B10>0,'원가항목별(집계)'!I$38*$P10/$P$27,0) -> 163030.58 | J10: =SUM(D10:I10) -> 49633031 | K10: =IF(B10>0,'원가항목별(집계)'!I$34*P10/P$27,0) -> 10787190 | L10: =IF($B10>0,'원가항목별(집계)'!I$39*$P10/$P$27,0) -> 73363.762 | M10: ='#40'!H60+'#40'!H61 -> 0 | N10: =SUM(J10:M10) -> 60493585 | P10: =D10+E10+F10+G10+H10+M10 -> 49470000
A11: =IF(B11>0,A10+1,"") -> 5 | B11: ='#50'!C$1 -> I/B 가조립 | C11: 1식 | D11: ='#50'!H41 -> 16800000 | E11: ='#50'!H42 -> 0 | F11: ='#50'!H43+'#50'!H44+'#50'!H45+'#50'!H49 -> 5500000 | G11: ='#50'!H46+'#50'!H47 -> 1800000 | H11: ='#50'!H48 -> 600000 | I11: =IF($B11>0,'원가항목별(집계)'!I$38*$P11/$P$27,0) -> 81399.947 | J11: =SUM(D11:I11) -> 24781400 | K11: =IF(B11>0,'원가항목별(집계)'!I$34*P11/P$27,0) -> 5385963.2 | L11: =IF($B11>0,'원가항목별(집계)'!I$39*$P11/$P$27,0) -> 36629.976 | M11: ='#50'!H52+'#50'!H53 -> 0 | N11: =SUM(J11:M11) -> 30203993 | P11: =D11+E11+F11+G11+H11+M11 -> 24700000
A12: =IF(B12>0,A11+1,"") -> 6 | B12: ='#60'!C$1 -> I/B 압입 | C12: 1식 | D12: ='#60'!H56 -> 36990000 | E12: ='#60'!H57 -> 0 | F12: ='#60'!H58+'#60'!H59+'#60'!H60+'#60'!H64 -> 10000000 | G12: ='#60'!H61+'#60'!H62 -> 1800000 | H12: ='#60'!H63 -> 600000 | I12: =IF($B12>0,'원가항목별(집계)'!I$38*$P12/$P$27,0) -> 162766.94 | J12: =SUM(D12:I12) -> 49552767 | K12: =IF(B12>0,'원가항목별(집계)'!I$34*P12/P$27,0) -> 10769746 | L12: =IF($B12>0,'원가항목별(집계)'!I$39*$P12/$P$27,0) -> 73245.123 | M12: ='#60'!H67+'#60'!H68 -> 0 | N12: =SUM(J12:M12) -> 60395758 | P12: =D12+E12+F12+G12+H12+M12 -> 49390000
A13: =IF(B13>0,A12+1,"") -> 7 | B13: ='#70'!C$1 -> 대경 밴드체결 | C13: 1식 | D13: ='#70'!H55 -> 23390000 | E13: ='#70'!H56 -> 0 | F13: ='#70'!H57+'#70'!H58+'#70'!H59+'#70'!H63 -> 8750000 | G13: ='#70'!H60+'#70'!H61 -> 1800000 | H13: ='#70'!H62 -> 300000 | I13: =IF($B13>0,'원가항목별(집계)'!I$38*$P13/$P$27,0) -> 112839.44 | J13: =SUM(D13:I13) -> 34352839 | K13: =IF(B13>0,'원가항목별(집계)'!I$34*P13/P$27,0) -> 7466209.7 | L13: =IF($B13>0,'원가항목별(집계)'!I$39*$P13/$P$27,0) -> 50777.748 | M13: ='#70'!H66+'#70'!H67 -> 0 | N13: =SUM(J13:M13) -> 41869827 | P13: =D13+E13+F13+G13+H13+M13 -> 34240000
A14: =IF(B14>0,A13+1,"") -> 8 | B14: ='#80'!C$1 -> 완성비젼 | C14: 1식 | D14: ='#80'!H51 -> 54520000 | E14: ='#80'!H52 -> 0 | F14: ='#80'!H53+'#80'!H54+'#80'!H55+'#80'!H59 -> 12750000 | G14: ='#80'!H56+'#80'!H57 -> 1800000 | H14: ='#80'!H58 -> 300000 | I14: =IF($B14>0,'원가항목별(집계)'!I$38*$P14/$P$27,0) -> 228611.92 | J14: =SUM(D14:I14) -> 69598612 | K14: =IF(B14>0,'원가항목별(집계)'!I$34*P14/P$27,0) -> 15126488 | L14: =IF($B14>0,'원가항목별(집계)'!I$39*$P14/$P$27,0) -> 102875.36 | M14: ='#80'!H62+'#80'!H63 -> 0 | N14: =SUM(J14:M14) -> 84827976 | P14: =D14+E14+F14+G14+H14+M14 -> 69370000
A15: =IF(B15>0,A14+1,"") -> 9 | B15: ='#90'!C$1 -> UN-LOADING 배출 및 적재 | C15: 1식 | D15: ='#90'!H63 -> 85120000 | E15: ='#90'!H64 -> 0 | F15: ='#90'!H65+'#90'!H66+'#90'!H67+'#90'!H71 -> 14750000 | G15: ='#90'!H68+'#90'!H69 -> 4200000 | H15: ='#90'!H70 -> 300000 | I15: =IF($B15>0,'원가항목별(집계)'!I$38*$P15/$P$27,0) -> 343955.97 | J15: =SUM(D15:I15) -> 1.0471396e+08 | K15: =IF(B15>0,'원가항목별(집계)'!I$34*P15/P$27,0) -> 22758420 | L15: =IF($B15>0,'원가항목별(집계)'!I$39*$P15/$P$27,0) -> 154780.19 | M15: ='#90'!H74+'#90'!H75 -> 0 | N15: =SUM(J15:M15) -> 1.2762716e+08 | P15: =D15+E15+F15+G15+H15+M15 -> 104370000
A16: =IF(B16>0,A15+1,"") -> 10 | B16: ='#100'!C$1 -> MAIN CONVEYOR | C16: 1식 | D16: ='#100'!H54 -> 106720000 | E16: ='#100'!H55 -> 0 | F16: ='#100'!H56+'#100'!H57+'#100'!H58+'#100'!H62 -> 7250000 | G16: ='#100'!H59+'#100'!H60 -> 3300000 | H16: ='#100'!H61 -> 0 | I16: =IF($B16>0,'원가항목별(집계)'!I$38*$P16/$P$27,0) -> 386468.49 | J16: =SUM(D16:I16) -> 1.1765647e+08 | K16: =IF(B16>0,'원가항목별(집계)'!I$34*P16/P$27,0) -> 25571332 | L16: =IF($B16>0,'원가항목별(집계)'!I$39*$P16/$P$27,0) -> 173910.82 | M16: ='#100'!H65+'#100'!H66 -> 0 | N16: =SUM(J16:M16) -> 1.4340171e+08 | P16: =D16+E16+F16+G16+H16+M16 -> 117270000
A17: =IF(B17>0,A16+1,"") -> 11 | B17: ='#110'!D$1 -> PALLETS | C17: 1식 | D17: ='#110'!I107 -> 95000000 | E17: ='#110'!I108 -> 0 | F17: ='#110'!I109+'#110'!I110+'#110'!I111+'#110'!I115 -> 6500000 | G17: ='#110'!I112+'#110'!I113 -> 1200000 | H17: ='#110'!I114 -> 0 | I17: =IF($B17>0,'원가항목별(집계)'!I$38*$P17/$P$27,0) -> 338452.41 | J17: =SUM(D17:I17) -> 1.0303845e+08 | K17: =IF(B17>0,'원가항목별(집계)'!I$34*P17/P$27,0) -> 22394268 | L17: =IF($B17>0,'원가항목별(집계)'!I$39*$P17/$P$27,0) -> 152303.59 | M17: ='#110'!I118+'#110'!I119 -> 0 | N17: =SUM(J17:M17) -> 1.2558502e+08 | P17: =D17+E17+F17+G17+H17+M17 -> 102700000
A18: =IF(B18>0,A17+1,"") -> 12 | B18: ='#120'!C$1 -> GREASE PUMP SYSTEM | C18: 1식 | D18: ='#120'!H55 -> 43000000 | E18: ='#120'!H56 -> 0 | F18: ='#120'!H57+'#120'!H58+'#120'!H59+'#120'!H63 -> 0 | G18: ='#120'!H60+'#120'!H61 -> 0 | H18: ='#120'!H62 -> 0 | I18: =IF($B18>0,'원가항목별(집계)'!I$38*$P18/$P$27,0) -> 141708.41 | J18: =SUM(D18:I18) -> 43141708 | K18: =IF(B18>0,'원가항목별(집계)'!I$34*P18/P$27,0) -> 9376373.1 | L18: =IF($B18>0,'원가항목별(집계)'!I$39*$P18/$P$27,0) -> 63768.785 | M18: ='#120'!H66+'#120'!H67 -> 0 | N18: =SUM(J18:M18) -> 52581850 | P18: =D18+E18+F18+G18+H18+M18 -> 43000000
A19: =IF(B19>0,A18+1,"") -> 13 | B19: ='#130'!C$1 -> LMS SYSTEM | C19: 1식 | D19: ='#130'!H55 -> 30000000 | E19: ='#130'!H56 -> 0 | F19: ='#130'!H57+'#130'!H58+'#130'!H59+'#130'!H63 -> 0 | G19: ='#130'!H60+'#130'!H61 -> 0 | H19: ='#130'!H62 -> 0 | I19: =IF($B19>0,'원가항목별(집계)'!I$38*$P19/$P$27,0) -> 98866.333 | J19: =SUM(D19:I19) -> 30098866 | K19: =IF(B19>0,'원가항목별(집계)'!I$34*P19/P$27,0) -> 6541655.7 | L19: =IF($B19>0,'원가항목별(집계)'!I$39*$P19/$P$27,0) -> 44489.85 | M19: ='#130'!H66+'#130'!H67 -> 0 | N19: =SUM(J19:M19) -> 36685012 | P19: =D19+E19+F19+G19+H19+M19 -> 30000000
A20: =IF(B20>0,A19+1,"") -> 14 | B20: ='#140'!C$1 -> RFID | C20: 1식 | D20: ='#140'!H56 -> 16000000 | E20: ='#140'!H57 -> 0 | F20: ='#140'!H58+'#140'!H59+'#140'!H60+'#140'!H64 -> 0 | G20: ='#140'!H61+'#140'!H62 -> 0 | H20: ='#140'!H63 -> 0 | I20: =IF($B20>0,'원가항목별(집계)'!I$38*$P20/$P$27,0) -> 52728.711 | J20: =SUM(D20:I20) -> 16052729 | K20: =IF(B20>0,'원가항목별(집계)'!I$34*P20/P$27,0) -> 3488883 | L20: =IF($B20>0,'원가항목별(집계)'!I$39*$P20/$P$27,0) -> 23727.92 | M20: ='#140'!H67+'#140'!H68 -> 0 | N20: =SUM(J20:M20) -> 19565340 | P20: =D20+E20+F20+G20+H20+M20 -> 16000000
A21: =IF(B21>0,A20+1,"") | B21: ='#150'!C$1 -> 0 | C21: 1식 | D21: ='#150'!H56 -> 0 | E21: ='#150'!H57 -> 0 | F21: ='#150'!H58+'#150'!H59+'#150'!H60+'#150'!H64 -> 0 | G21: ='#150'!H61+'#150'!H62 -> 0 | H21: ='#150'!H63 -> 0 | I21: =IF($B21>0,'원가항목별(집계)'!I$38*$P21/$P$27,0) -> 0 | J21: =SUM(D21:I21) -> 0 | K21: =IF(B21>0,'원가항목별(집계)'!I$34*P21/P$27,0) -> 0 | L21: =IF($B21>0,'원가항목별(집계)'!I$39*$P21/$P$27,0) -> 0 | M21: ='#150'!H67+'#150'!H68 -> 0 | N21: =SUM(J21:M21) -> 0 | P21: =D21+E21+F21+G21+H21+M21 -> 0
A22: =IF(B22>0,A21+1,"") | B22: ='#160'!C$1 -> 0 | C22: 1식 | D22: ='#160'!H55 -> 0 | E22: ='#160'!H56 -> 0 | F22: ='#160'!H57+'#160'!H58+'#160'!H59+'#160'!H63 -> 0 | G22: ='#160'!H60+'#160'!H61 -> 0 | H22: ='#160'!H62 -> 0 | I22: =IF($B22>0,'원가항목별(집계)'!I$38*$P22/$P$27,0) -> 0 | J22: =SUM(D22:I22) -> 0 | K22: =IF(B22>0,'원가항목별(집계)'!I$34*P22/P$27,0) -> 0 | L22: =IF($B22>0,'원가항목별(집계)'!I$39*$P22/$P$27,0) -> 0 | M22: ='#160'!H66+'#160'!H67 -> 0 | N22: =SUM(J22:M22) -> 0 | P22: =D22+E22+F22+G22+H22+M22 -> 0
A23: =IF(B23>0,A22+1,"") | B23: ='#170'!C$1 -> 0 | C23: 1식 | D23: ='#170'!H56 -> 0 | E23: ='#170'!H57 -> 0 | F23: ='#170'!H58+'#170'!H59+'#170'!H60+'#170'!H64 -> 0 | G23: ='#170'!H61+'#170'!H62 -> 0 | H23: ='#170'!H63 -> 0 | I23: =IF($B23>0,'원가항목별(집계)'!I$38*$P23/$P$27,0) -> 0 | J23: =SUM(D23:I23) -> 0 | K23: =IF(B23>0,'원가항목별(집계)'!I$34*P23/P$27,0) -> 0 | L23: =IF($B23>0,'원가항목별(집계)'!I$39*$P23/$P$27,0) -> 0 | M23: ='#170'!H67+'#170'!H68 -> 0 | N23: =SUM(J23:M23) -> 0 | P23: =D23+E23+F23+G23+H23+M23 -> 0
A24: =IF(B24>0,A23+1,"") | B24: ='#180'!C$1 -> 0 | C24: 1식 | D24: ='#180'!H55 -> 0 | E24: ='#180'!H56 -> 0 | F24: ='#180'!H57+'#180'!H58+'#180'!H59+'#180'!H63 -> 0 | G24: ='#180'!H60+'#180'!H61 -> 0 | H24: ='#180'!H62 -> 0 | I24: =IF($B24>0,'원가항목별(집계)'!I$38*$P24/$P$27,0) -> 0 | J24: =SUM(D24:I24) -> 0 | K24: =IF(B24>0,'원가항목별(집계)'!I$34*P24/P$27,0) -> 0 | L24: =IF($B24>0,'원가항목별(집계)'!I$39*$P24/$P$27,0) -> 0 | M24: ='#180'!H66+'#180'!H67 -> 0 | N24: =SUM(J24:M24) -> 0 | P24: =D24+E24+F24+G24+H24+M24 -> 0
A25: =IF(B25>0,A24+1,"") | B25: ='#190'!C$1 -> 0 | C25: 1식 | D25: ='#190'!H55 -> 0 | E25: ='#190'!H56 -> 0 | F25: ='#190'!H57+'#190'!H58+'#190'!H59+'#190'!H63 -> 0 | G25: ='#190'!H60+'#190'!H61 -> 0 | H25: ='#190'!H62 -> 0 | I25: =IF($B25>0,'원가항목별(집계)'!I$38*$P25/$P$27,0) -> 0 | J25: =SUM(D25:I25) -> 0 | K25: =IF(B25>0,'원가항목별(집계)'!I$34*P25/P$27,0) -> 0 | L25: =IF($B25>0,'원가항목별(집계)'!I$39*$P25/$P$27,0) -> 0 | M25: ='#190'!H66+'#190'!H67 -> 0 | N25: =SUM(J25:M25) -> 0 | P25: =D25+E25+F25+G25+H25+M25 -> 0
A26: =IF(B26>0,A25+1,"") | B26: ='#200'!C$1 -> 0 | C26: 1식 | D26: ='#200'!H55 -> 0 | E26: ='#200'!H56 -> 0 | F26: ='#200'!H57+'#200'!H58+'#200'!H59+'#200'!H63 -> 0 | G26: ='#200'!H60+'#200'!H61 -> 0 | H26: ='#200'!H62 -> 0 | I26: =IF($B26>0,'원가항목별(집계)'!I$38*$P26/$P$27,0) -> 0 | J26: =SUM(D26:I26) -> 0 | K26: =IF(B26>0,'원가항목별(집계)'!I$34*P26/P$27,0) -> 0 | L26: =IF($B26>0,'원가항목별(집계)'!I$39*$P26/$P$27,0) -> 0 | M26: ='#200'!H66+'#200'!H67 -> 0 | N26: =SUM(J26:M26) -> 0 | P26: =D26+E26+F26+G26+H26+M26 -> 0
A27: 합 계 | D27: =SUM(D7:D26) -> 778020000 | E27: =SUM(E7:E26) -> 0 | F27: =SUM(F7:F26) -> 106500000 | G27: =SUM(G7:G26) -> 21900000 | H27: =SUM(H7:H26) -> 3900000 | I27: =SUM(I7:I26) -> 3000000 | J27: =SUM(D27:I27) -> 913320000 | K27: =SUM(K7:K26) -> 1.985e+08 | L27: =SUM(L7:L26) -> 1350000 | M27: =SUM(M7:M26) -> 0 | N27: =SUM(N7:N26) -> 1113170000 | P27: =SUM(P7:P26) -> 910320000
D28: =IF(D27=0,"",D27/$N27) -> 0.6989229 | E28: =IF(E27=0,"",E27/$N27) | F28: =IF(F27=0,"",F27/$N27) -> 0.095672718 | G28: =IF(G27=0,"",G27/$N27) -> 0.019673545 | H28: =IF(H27=0,"",H27/$N27) -> 0.003503508 | I28: =IF(I27=0,"",I27/$N27) -> 0.0026950062 | J28: =IF(J27=0,"",J27/$N27) -> 0.82046767 | K28: =IF(K27=0,"",K27/$N27) -> 0.17831957 | ... N28: =IF(N27=0,"",N27/$N27) -> 1
A29: 주) 전기비용은 턴키장비의 공통비용으로서 총 전기비용을 단위장비별 기계금액의 비율에 따라 배분함
N30: =IF('원가항목별(집계)'!I42='단위공사별(집계)'!N27,"","DATA오류입니다!")

Sheet 전기
B1: □ 전기부문: | C1: 전기부문(공통) | I1: (첨부)
A2: 구분 | C2: 품 명 | D2: 규격 | E2: 단위 | F2: 수량 | G2: 단가(원) | H2: 금액(원) | I2: 原MAKER
A3: 자 재 비 | B3: 철자재 | C3: 제작품 | D3: 콘트롤박스등 | E3: 식 | F3: 1 | G3: 8000000 | H3: =IF(F3=0,G3,G3*F3) -> 8000000
H4: =IF(F4=0,G4,G4*F4) -> 0
H5: =IF(F5=0,G5,G5*F5) -> 0
H6: =IF(F6=0,G6,G6*F6) -> 0
H7: =IF(F7=0,G7,G7*F7) -> 0
H8: =IF(F8=0,G8,G8*F8) -> 0
H9: =SUM(H3:H8) -> 8000000
B10: 설치/해체/ | H10: =IF(F10=0,G10,G10*F10) -> 0
B11: 시운전 공사 | H11: =IF(F11=0,G11,G11*F11) -> 0
B12: 자재 | H12: =IF(F12=0,G12,G12*F12) -> 0
H13: =IF(F13=0,G13,G13*F13) -> 0
H14: =IF(F14=0,G14,G14*F14) -> 0
H15: =IF(F15=0,G15,G15*F15) -> 0
H16: =SUM(H10:H15) -> 0
B17: 전기자재 | C17: ■PLC구매품 | D17: PLC등 | E17: 식 | F17: 1 | G17: 100000000 | H17: =IF(F17=0,G17,G17*F17) -> 100000000
H18: =IF(F18=0,G18,G18*F18) -> 0
C19: ■PC구매품 | D19: PC등 | E19: 식 | F19: 1 | G19: 15000000 | H19: =IF(F19=0,G19,G19*F19) -> 15000000
C20: ■PC P/G | E20: 식 | F20: 1 | G20: 20000000 | H20: =IF(F20=0,G20,G20*F20) -> 20000000
H21: =IF(F21=0,G21,G21*F21) -> 0
H22: =IF(F22=0,G22,G22*F22) -> 0
H23: =IF(F23=0,G23,G23*F23) -> 0
H24: =IF(F24=0,G24,G24*F24) -> 0
H25: =IF(F25=0,G25,G25*F25) -> 0
H26: =IF(F26=0,G26,G26*F26) -> 0
H27: =IF(F27=0,G27,G27*F27) -> 0
H28: =IF(F28=0,G28,G28*F28) -> 0
H29: =IF(F29=0,G29,G29*F29) -> 0
H30: =IF(F30=0,G30,G30*F30) -> 0
H31: =IF(F31=0,G31,G31*F31) -> 0
H32: =IF(F32=0,G32,G32*F32) -> 0
C33: 기타 잡자재 | E33: 식 | F33: 1 | G33: 2000000 | H33: =IF(F33=0,G33,G33*F33) -> 2000000
H34: =SUM(H17:H33) -> 137000000
B35: 자재비 소계 | H35: =SUM(H34,H9,H16) -> 145000000
A36: 노 무 비 | B36: 기존설비 철거 | E36: M/D | F36: 10 | G36: 250000 | H36: =F36*G36 -> 2500000
B37: 전기 설계/프로그램 | E37: M/D | F37: 50 | G37: 300000 | H37: =F37*G37 -> 15000000
B38: 전기 제작 | E38: M/D | F38: 30 | G38: 250000 | H38: =F38*G38 -> 7500000
B39: 전기 조립 | E39: M/D | F39: 30 | G39: 250000 | H39: =F39*G39 -> 7500000
B40: 전기 설치 | E40: M/D | F40: 20 | G40: 300000 | H40: =F40*G40 -> 6000000
...

Sheet #10
B1: □ 단위공사명(전기제외): | C1: OB 비젼검사/그리스 주입 | I1: (첨부)
A2: 구분 | C2: 품 명 | D2: 규격 | E2: 단위 | F2: 수량 | G2: 단가(원) | H2: 금액(원) | I2: 原MAKER
A3: 자 재 비 | B3: 철자재 | C3: ■BASE | D3: 제관,가공 | E3: 식 | F3: 1 | G3: 2000000 | H3: =IF(F3=0,G3,G3*F3) -> 2000000
C4: ■FRAME | D4: 제관,가공 | E4: 식 | F4: 1 | G4: 1500000 | H4: =IF(F4=0,G4,G4*F4) -> 1500000
C5: ■상측 COVER | D5: 제관,가공 | E5: 식 | F5: 1 | G5: 1500000 | H5: =IF(F5=0,G5,G5*F5) -> 1500000
C6: ■OP POST | E6: 식 | F6: 1 | G6: 600000 | H6: =IF(F6=0,G6,G6*F6) -> 600000
C7: ■비젼시스템 | E7: 식 | F7: 1 | G7: 1000000 | H7: =IF(F7=0,G7,G7*F7) -> 1000000
C8: ■상하1축 | E8: 식 | F8: 1 | G8: 2000000 | H8: =IF(F8=0,G8,G8*F8) -> 2000000
C9: ■WORK CLAMP | E9: 식 | F9: 1 | G9: 700000 | H9: =IF(F9=0,G9,G9*F9) -> 700000
C10: ■WORK 회전 | E10: 식 | F10: 1 | G10: 700000 | H10: =IF(F10=0,G10,G10*F10) -> 700000
C11: ■상하1축 | E11: 식 | F11: 1 | G11: 2000000 | H11: =IF(F11=0,G11,G11*F11) -> 2000000
C12: ■보관함 | E12: 식 | F12: 1 | G12: 1000000 | H12: =IF(F12=0,G12,G12*F12) -> 1000000
C13: ■LIFTER UNIT | E13: 식 | F13: 1 | G13: 1300000 | H13: =IF(F13=0,G13,G13*F13) -> 1300000
H14: =IF(F14=0,G14,G14*F14) -> 0
H15: =IF(F15=0,G15,G15*F15) -> 0
H16: =IF(F16=0,G16,G16*F16) -> 0
H17: =IF(F17=0,G17,G17*F17) -> 0
H18: =IF(F18=0,G18,G18*F18) -> 0
H19: =IF(F19=0,G19,G19*F19) -> 0
C20: 기타 | E20: 식 | F20: 1 | G20: 300000 | H20: =IF(F20=0,G20,G20*F20) -> 300000
H21: =SUM(H3:H20) -> 14600000
B22: 설치/해체/시운전 | H22: =IF(F22=0,G22,G22*F22) -> 0
B23: 공사 관련 자재 | H23: =IF(F23=0,G23,G23*F23) -> 0
H24: =IF(F24=0,G24,G24*F24) -> 0
H25: =IF(F25=0,G25,G25*F25) -> 0
H26: =IF(F26=0,G26,G26*F26) -> 0
H27: =SUM(H22:H26) -> 0
B28: 구매품 | C28: ■비젼시스템 | D28: 1600 X 1400 컬러 | E28: 식 | F28: 1 | G28: 20000000 | H28: =IF(F28=0,G28,G28*F28) -> 20000000
B29: (유공압품외) | C29: ■상하1축 | D29: 서보 | E29: 식 | F29: 1 | G29: 3600000 | H29: =IF(F29=0,G29,G29*F29) -> 3600000
C30: ■WORK CLAMP | D30: CLAMP 실린더 | E30: 식 | F30: 1 | G30: 1200000 | H30: =IF(F30=0,G30,G30*F30) -> 1200000
C31: ■WORK 회전 | D31: 회전 실린더 | E31: 식 | F31: 1 | G31: 600000 | H31: =IF(F31=0,G31,G31*F31) -> 600000
C32: ■PROXIMITY SENSOR | E32: EA | F32: 1 | G32: 40000 | H32: =IF(F32=0,G32,G32*F32) -> 40000
C33: ■소재 감지 센스 | E33: EA | F33: 1 | G33: 100000 | H33: =IF(F33=0,G33,G33*F33) -> 100000
C34: ■상하1축 | D34: 서보1축 | E34: 식 | F34: 1 | G34: 2800000 | H34: =IF(F34=0,G34,G34*F34) -> 2800000
C35: ■정량변 | D35: GRACO | E35: 식 | F35: 1 | G35: 7000000 | H35: =IF(F35=0,G35,G35*F35) -> 7000000
C36: ■고속카운트 | E36: 식 | F36: 1 | G36: 500000 | H36: =IF(F36=0,G36,G36*F36) -> 500000
C37: ■LIFTER UNIT | E37: 식 | F37: 1 | G37: 600000 | H37: =IF(F37=0,G37,G37*F37) -> 600000
H38: =IF(F38=0,G38,G38*F38) -> 0
C39: ■일반 자재류 | H39: =IF(F39=0,G39,G39*F39) -> 0
C40: F.R.L Unit | D40: AV4000 | E40: 식 | F40: 1 | G40: 350000 | H40: =IF(F40=0,G40,G40*F40) -> 350000
...

Sheet #20
B1: □ 단위공사명(전기제외): | C1: BOOT조립기 | I1: (첨부)
A2: 구분 | C2: 품 명 | D2: 규격 | E2: 단위 | F2: 수량 | G2: 단가(원) | H2: 금액(원) | I2: 原MAKER
A3: 자 재 비 | B3: 철자재 | C3: ■FRAME PART
C4: M/C BED | E4: 식 | F4: 1 | G4: 10000000 | H4: =F4*G4 -> 10000000
C5: FRAME | E5: 식 | F5: 1 | G5: 4000000 | H5: =F5*G5 -> 4000000
C6: OP POST | E6: 식 | F6: 1 | G6: 600000 | H6: =F6*G6 -> 600000
C7: SAFTY COVER | E7: 식 | F7: 1 | G7: 1500000 | H7: =F7*G7 -> 1500000
C8: ■LIFTER UNIT | E8: 식 | F8: 1 | G8: 1300000 | H8: =F8*G8 -> 1300000
C9: ■SHAFT공급부 | H9: =F9*G9 -> 0
C10: 폭조절장치 | E10: 식 | F10: 1 | G10: 1000000 | H10: =F10*G10 -> 1000000
C11: 틸팅부 | E11: 식 | F11: 1 | G11: 1000000 | H11: =F11*G11 -> 1000000
C12: 틸팅부 가변장치 | E12: 식 | F12: 1 | G12: 1000000 | H12: =F12*G12 -> 1000000
C13: 오일팬 | E13: 식 | F13: 1 | G13: 350000 | H13: =F13*G13 -> 350000
C14: ■길이측정부 | H14: =F14*G14 -> 0
C15: LVDT | E15: 식 | F15: 1 | G15: 500000 | H15: =F15*G15 -> 500000
C16: 서보1축(전후) | E16: 식 | F16: 1 | G16: 1500000 | H16: =F16*G16 -> 1500000
C17: 보조실린더1축(전후) | E17: 식 | F17: 1 | G17: 800000 | H17: =F17*G17 -> 800000
C18: ■ROBOT | H18: =F18*G18 -> 0
C19: 직교 로봇고정PART | E19: 식 | F19: 1 | G19: 1000000 | H19: =F19*G19 -> 1000000
C20: 그리퍼실린더 | E20: 식 | F20: 1 | G20: 800000 | H20: =F20*G20 -> 800000
C21: ■댐퍼 삽입부 | H21: =F21*G21 -> 0
C22: 삽입 PART | E22: 식 | F22: 1 | G22: 1000000 | H22: =F22*G22 -> 1000000
C23: ■댐퍼 이송부 | H23: =F23*G23 -> 0
C24: 서보1축(전후) | E24: 식 | F24: 1 | G24: 1500000 | H24: =F24*G24 -> 1500000
C25: 실린더1축(상하) | E25: 식 | F25: 1 | G25: 800000 | H25: =F25*G25 -> 800000
C26: 소재장착부 | E26: 식 | F26: 1 | G26: 500000 | H26: =F26*G26 -> 500000
C27: 차종변경 | E27: 식 | F27: 10 | G27: 150000 | H27: =F27*G27 -> 1500000
C28: ■댐퍼 CLAMP부 | H28: =F28*G28 -> 0
C29: CLAMP 실린더 고정PART | E29: 식 | F29: 1 | G29: 800000 | H29: =F29*G29 -> 800000
C30: 소재 감지 센스 | E30: 식 | F30: 1 | G30: 200000 | H30: =F30*G30 -> 200000
C31: 차종변경 | E31: 식 | F31: 10 | G31: 150000 | H31: =F31*G31 -> 1500000
C32: ■SHAFT+댐퍼 이송부 | H32: =F32*G32 -> 0
C33: 서보1축(전후) | E33: 식 | F33: 1 | G33: 1500000 | H33: =F33*G33 -> 1500000
C34: 실린더1축(상하) | E34: 식 | F34: 1 | G34: 1500000 | H34: =F34*G34 -> 1500000
C35: ■부트조립부 | H35: =F35*G35 -> 0
C36: 서보1축(전후) | E36: 식 | F36: 2 | G36: 1500000 | H36: =F36*G36 -> 3000000
C37: 보조실린더1축(전후) | E37: 식 | F37: 2 | G37: 1500000 | H37: =F37*G37 -> 3000000
C38: ■CIRCLIP조립부 | H38: =F38*G38 -> 0
C39: 압입부 | E39: 식 | F39: 1 | G39: 1000000 | H39: =F39*G39 -> 1000000
C40: ■구리스 도포부 | H40: =F40*G40 -> 0
...

Sheet #30
B1: □ 단위공사명(전기제외): | C1: D/SHAFT 가조립 | I1: (첨부)
A2: 구분 | C2: 품 명 | D2: 규격 | E2: 단위 | F2: 수량 | G2: 단가(원) | H2: 금액(원) | I2: 原MAKER
A3: 자 재 비 | B3: 철자재 | C3: ■BASE | D3: 제관,가공 | E3: 식 | F3: 1 | G3: 2000000 | H3: =IF(F3=0,G3,G3*F3) -> 2000000
C4: ■FRAME | D4: 제관,가공 | E4: 식 | F4: 1 | G4: 1500000 | H4: =IF(F4=0,G4,G4*F4) -> 1500000
C5: ■상측 COVER | D5: 제관,가공 | E5: 식 | F5: 1 | G5: 1500000 | H5: =IF(F5=0,G5,G5*F5) -> 1500000
C6: ■OP POST | E6: 식 | F6: 1 | G6: 600000 | H6: =IF(F6=0,G6,G6*F6) -> 600000
C7: ■가조립 UNIT | E7: 식 | F7: 1 | G7: 1500000 | H7: =IF(F7=0,G7,G7*F7) -> 1500000
C8: ■바코드리딩 | E8: 식 | F8: 1 | G8: 1000000 | H8: =IF(F8=0,G8,G8*F8) -> 1000000
C9: ■LIFTER UNIT | E9: 식 | F9: 1 | G9: 1300000 | H9: =IF(F9=0,G9,G9*F9) -> 1300000
H10: =IF(F10=0,G10,G10*F10) -> 0
H11: =IF(F11=0,G11,G11*F11) -> 0
H12: =IF(F12=0,G12,G12*F12) -> 0
H13: =IF(F13=0,G13,G13*F13) -> 0
H14: =IF(F14=0,G14,G14*F14) -> 0
C15: 기타 가공물 | E15: 식 | F15: 1 | G15: 200000 | H15: 0
H16: =SUM(H3:H15) -> 9400000
B17: 설치/해체/시운전 | H17: =IF(F17=0,G17,G17*F17) -> 0
B18: 공사 관련 자재 | H18: =IF(F18=0,G18,G18*F18) -> 0
H19: =IF(F19=0,G19,G19*F19) -> 0
H20: =IF(F20=0,G20,G20*F20) -> 0
H21: =IF(F21=0,G21,G21*F21) -> 0
H22: =SUM(H17:H21) -> 0
B23: 구매품 | C23: ■부품적재랙 | D23: BJ대경밴드,SPIDER | E23: 식 | F23: 1 | G23: 300000 | H23: =IF(F23=0,G23,G23*F23) -> 300000
B24: (유공압품외) | C24: ■가조립 UNIT | D24: SPIDER | E24: 식 | F24: 1 | G24: 500000 | H24: =IF(F24=0,G24,G24*F24) -> 500000
C25: ■가조립 UNIT | D25: SPIDER | E25: 식 | F25: 1 | H25: =IF(F25=0,G25,G25*F25) -> 0
C26: ■바코드리더 | E26: 식 | H26: =IF(F26=0,G26,G26*F26) -> 0
C27: 바코드리더 | D27: 코그넥스 | E27: 식 | F27: 1 | G27: 5000000 | H27: =IF(F27=0,G27,G27*F27) -> 5000000
C28: 전후1축 | D28: CYL'등 | E28: 식 | F28: 1 | G28: 500000 | H28: =IF(F28=0,G28,G28*F28) -> 500000
C29: 기타 | E29: 식 | F29: 1 | G29: 500000 | H29: =IF(F29=0,G29,G29*F29) -> 500000
H30: =IF(F30=0,G30,G30*F30) -> 0
C31: ■LIFTER UNIT | E31: 식 | F31: 1 | G31: 600000 | H31: =IF(F31=0,G31,G31*F31) -> 600000
H32: =IF(F32=0,G32,G32*F32) -> 0
H33: =IF(F33=0,G33,G33*F33) -> 0
H34: =IF(F34=0,G34,G34*F34) -> 0
H35: =IF(F35=0,G35,G35*F35) -> 0
H36: =IF(F36=0,G36,G36*F36) -> 0
H37: =IF(F37=0,G37,G37*F37) -> 0
C38: 기타잡자재 | E38: 식 | F38: 1 | G38: 1000000 | H38: 0
H39: =SUM(H23:H38) -> 7400000
B40: 외주제작품 | H40: =IF(F40=0,G40,G40*F40) -> 0
...

Sheet #40
B1: □ 단위공사명(전기제외): | C1: D/SHAFT 압입 | I1: (첨부)
A2: 구분 | C2: 품 명 | D2: 규격 | E2: 단위 | F2: 수량 | G2: 단가(원) | H2: 금액(원) | I2: 原MAKER
A3: 자 재 비 | B3: 철자재 | C3: ■BASE | D3: 제관,가공 | E3: 식 | F3: 1 | G3: 2000000 | H3: =IF(F3=0,G3,G3*F3) -> 2000000
C4: ■FRAME | D4: 제관,가공 | E4: 식 | F4: 1 | G4: 1500000 | H4: =IF(F4=0,G4,G4*F4) -> 1500000
C5: ■상측 COVER | D5: 제관,가공 | E5: 식 | F5: 1 | G5: 1500000 | H5: =IF(F5=0,G5,G5*F5) -> 1500000
C6: ■OP POST | E6: 식 | F6: 1 | G6: 600000 | H6: =IF(F6=0,G6,G6*F6) -> 600000
C7: ■서보프레스 | E7: 식 | F7: 1 | G7: 1500000 | H7: =IF(F7=0,G7,G7*F7) -> 1500000
C8: ■압입UNIT | D8: 서보1축 | E8: 식 | F8: 1 | G8: 2500000 | H8: =IF(F8=0,G8,G8*F8) -> 2500000
H9: =IF(F9=0,G9,G9*F9) -> 0
C10: ■LIFTER UNIT | E10: 식 | F10: 1 | G10: 1300000 | H10: =IF(F10=0,G10,G10*F10) -> 1300000
H11: =IF(F11=0,G11,G11*F11) -> 0
H12: =IF(F12=0,G12,G12*F12) -> 0
C13: 기타 | E13: 식 | F13: 1 | G13: 200000 | H13: 0
H14: =SUM(H3:H13) -> 10900000
B15: 설치/해체/시운전 | H15: =IF(F15=0,G15,G15*F15) -> 0
B16: 공사 관련 자재 | H16: =IF(F16=0,G16,G16*F16) -> 0
H17: =IF(F17=0,G17,G17*F17) -> 0
H18: =IF(F18=0,G18,G18*F18) -> 0
C19: 기타자재 | H19: =IF(F19=0,G19,G19*F19) -> 0
H20: =SUM(H15:H19) -> 0
B21: 구매품 | C21: ■서보프레스 | D21: 3t | E21: 식 | F21: 1 | G21: 18000000 | H21: =IF(F21=0,G21,G21*F21) -> 18000000
B22: (유공압품외) | C22: ■압입UNIT | D22: 서보1축 | E22: 식 | F22: 1 | G22: 4500000 | H22: =IF(F22=0,G22,G22*F22) -> 4500000
H23: =IF(F23=0,G23,G23*F23) -> 0
H24: =IF(F24=0,G24,G24*F24) -> 0
H25: =IF(F25=0,G25,G25*F25) -> 0
C26: ■LIFTER UNIT | E26: 식 | F26: 1 | G26: 600000 | H26: =IF(F26=0,G26,G26*F26) -> 600000
H27: =IF(F27=0,G27,G27*F27) -> 0
C28: ■일반 자재류 | H28: =IF(F28=0,G28,G28*F28) -> 0
C29: F.R.L Unit | D29: AV4000 | E29: 식 | F29: 1 | G29: 350000 | H29: =IF(F29=0,G29,G29*F29) -> 350000
C30: SOL V/V | D30: VQC4201 | E30: 식 | F30: 10 | G30: 75000 | H30: =IF(F30=0,G30,G30*F30) -> 750000
C31: Manifold | D31: VV5QC41 | E31: 식 | F31: 2 | G31: 850000 | H31: =IF(F31=0,G31,G31*F31) -> 1700000
C32: Speed Con | E32: 식 | F32: 10 | G32: 7000 | H32: =IF(F32=0,G32,G32*F32) -> 70000
C33: 배관자재 | E33: 식 | F33: 1 | G33: 100000 | H33: =IF(F33=0,G33,G33*F33) -> 100000
C34: 잡자재 | E34: 식 | F34: 1 | G34: 100000 | H34: =IF(F34=0,G34,G34*F34) -> 100000
H35: =IF(F35=0,G35,G35*F35) -> 0
H36: =IF(F36=0,G36,G36*F36) -> 0
H37: =IF(F37=0,G37,G37*F37) -> 0
H38: =IF(F38=0,G38,G38*F38) -> 0
C39: 기타자재 | E39: 식 | F39: 1 | G39: 1000000 | H39: 0
H40: =SUM(H21:H39) -> 26170000
...

Sheet #50
B1: □ 단위공사명(전기제외): | C1: I/B 가조립 | I1: (첨부)
A2: 구분 | C2: 품 명 | D2: 규격 | E2: 단위 | F2: 수량 | G2: 단가(원) | H2: 금액(원) | I2: 原MAKER
A3: 자 재 비 | B3: 철자재 | C3: ■BASE | D3: 제관,가공 | E3: 식 | F3: 1 | G3: 2000000 | H3: =IF(F3=0,G3,G3*F3) -> 2000000
C4: ■FRAME | D4: 제관,가공 | E4: 식 | F4: 1 | G4: 1500000 | H4: =IF(F4=0,G4,G4*F4) -> 1500000
C5: ■상측 COVER | D5: 제관,가공 | E5: 식 | F5: 1 | G5: 1500000 | H5: =IF(F5=0,G5,G5*F5) -> 1500000
C6: ■OP POST | E6: 식 | F6: 1 | G6: 600000 | H6: =IF(F6=0,G6,G6*F6) -> 600000
C7: ■가조립 UNIT | E7: 식 | F7: 1 | G7: 1500000 | H7: =IF(F7=0,G7,G7*F7) -> 1500000
C8: ■바코드리딩 | E8: 식 | F8: 1 | G8: 1000000 | H8: =IF(F8=0,G8,G8*F8) -> 1000000
C9: ■LIFTER UNIT | E9: 식 | F9: 1 | G9: 1300000 | H9: =IF(F9=0,G9,G9*F9) -> 1300000
H10: =IF(F10=0,G10,G10*F10) -> 0
C11: 기타 | E11: 식 | F11: 1 | G11: 500000 | H11: 0
H12: =SUM(H3:H11) -> 9400000
B13: 설치/해체/시운전 | H13: =IF(F13=0,G13,G13*F13) -> 0
B14: 공사 관련 자재 | H14: =IF(F14=0,G14,G14*F14) -> 0
H15: =IF(F15=0,G15,G15*F15) -> 0
H16: =IF(F16=0,G16,G16*F16) -> 0
C17: 기타자재 | H17: =IF(F17=0,G17,G17*F17) -> 0
H18: =SUM(H13:H17) -> 0
B19: 구매품 | C19: ■부품적재랙 | D19: BJ대경밴드,SPIDER | E19: 식 | F19: 1 | G19: 300000 | H19: =IF(F19=0,G19,G19*F19) -> 300000
B20: (유공압품외) | C20: ■가조립 UNIT | D20: SPIDER | E20: 식 | F20: 1 | G20: 500000 | H20: =IF(F20=0,G20,G20*F20) -> 500000
C21: ■바코드리더 | E21: 식 | H21: =IF(F21=0,G21,G21*F21) -> 0
C22: 바코드리더 | D22: 코그넥스 | E22: 식 | F22: 1 | G22: 5000000 | H22: =IF(F22=0,G22,G22*F22) -> 5000000
C23: 전후1축 | D23: CYL'등 | E23: 식 | F23: 1 | G23: 500000 | H23: =IF(F23=0,G23,G23*F23) -> 500000
C24: 기타 | E24: 식 | F24: 1 | G24: 500000 | H24: =IF(F24=0,G24,G24*F24) -> 500000
C25: ■LIFTER UNIT | E25: 식 | F25: 1 | G25: 600000 | H25: =IF(F25=0,G25,G25*F25) -> 600000
H26: =IF(F26=0,G26,G26*F26) -> 0
H27: =IF(F27=0,G27,G27*F27) -> 0
H28: =IF(F28=0,G28,G28*F28) -> 0
H29: =IF(F29=0,G29,G29*F29) -> 0
H30: =IF(F30=0,G30,G30*F30) -> 0
C31: 기타자재 | E31: 식 | F31: 1 | G31: 1000000 | H31: 0
H32: =SUM(H19:H31) -> 7400000
B33: 외주제작품 | H33: =IF(F33=0,G33,G33*F33) -> 0
H34: =IF(F34=0,G34,G34*F34) -> 0
H35: =IF(F35=0,G35,G35*F35) -> 0
H36: =IF(F36=0,G36,G36*F36) -> 0
H37: =IF(F37=0,G37,G37*F37) -> 0
H38: =IF(F38=0,G38,G38*F38) -> 0
C39: 기타자재 | H39: =IF(F39=0,G39,G39*F39) -> 0
H40: =SUM(H33:H39) -> 0
...

Sheet #60
B1: □ 단위공사명(전기제외): | C1: I/B 압입 | I1: (첨부)
A2: 구분 | C2: 품 명 | D2: 규격 | E2: 단위 | F2: 수량 | G2: 단가(원) | H2: 금액(원) | I2: 原MAKER
A3: 자 재 비 | B3: 철자재 | C3: ■BASE | D3: 제관,가공 | E3: 식 | F3: 1 | G3: 2000000 | H3: =IF(F3=0,G3,G3*F3) -> 2000000
C4: ■FRAME | D4: 제관,가공 | E4: 식 | F4: 1 | G4: 1500000 | H4: =IF(F4=0,G4,G4*F4) -> 1500000
C5: ■상측 COVER | D5: 제관,가공 | E5: 식 | F5: 1 | G5: 1500000 | H5: =IF(F5=0,G5,G5*F5) -> 1500000
C6: ■OP POST | E6: 식 | F6: 1 | G6: 600000 | H6: =IF(F6=0,G6,G6*F6) -> 600000
C7: ■서보프레스 | E7: 식 | F7: 1 | G7: 1500000 | H7: =IF(F7=0,G7,G7*F7) -> 1500000
C8: ■압입UNIT | D8: 서보1축 | E8: 식 | F8: 1 | G8: 2500000 | H8: =IF(F8=0,G8,G8*F8) -> 2500000
C9: ■LIFTER UNIT | E9: 식 | F9: 1 | G9: 1300000 | H9: =IF(F9=0,G9,G9*F9) -> 1300000
H10: =IF(F10=0,G10,G10*F10) -> 0
H11: =IF(F11=0,G11,G11*F11) -> 0
H12: =IF(F12=0,G12,G12*F12) -> 0
H13: =IF(F13=0,G13,G13*F13) -> 0
C14: 기타 가공물 | E14: 식 | F14: 1 | G14: 500000 | H14: 0
H15: =SUM(H3:H14) -> 10900000
B16: 설치/해체/시운전 | H16: =IF(F16=0,G16,G16*F16) -> 0
B17: 공사 관련 자재 | H17: =IF(F17=0,G17,G17*F17) -> 0
H18: =IF(F18=0,G18,G18*F18) -> 0
H19: =IF(F19=0,G19,G19*F19) -> 0
C20: 기타자재 | H20: =IF(F20=0,G20,G20*F20) -> 0
H21: =SUM(H16:H20) -> 0
B22: 구매품 | C22: ■서보프레스 | D22: 3t | E22: 식 | F22: 1 | G22: 18000000 | H22: =IF(F22=0,G22,G22*F22) -> 18000000
B23: (유공압품외) | C23: ■압입UNIT | D23: 서보1축 | E23: 식 | F23: 1 | G23: 3600000 | H23: =IF(F23=0,G23,G23*F23) -> 3600000
C24: ■LIFTER UNIT | E24: 식 | F24: 1 | G24: 600000 | H24: =IF(F24=0,G24,G24*F24) -> 600000
H25: =IF(F25=0,G25,G25*F25) -> 0
C26: ■일반 자재류 | H26: =IF(F26=0,G26,G26*F26) -> 0
C27: F.R.L Unit | D27: AV4000 | E27: 식 | F27: 1 | G27: 350000 | H27: =IF(F27=0,G27,G27*F27) -> 350000
C28: SOL V/V | D28: VQC4201 | E28: 식 | F28: 20 | G28: 75000 | H28: =IF(F28=0,G28,G28*F28) -> 1500000
C29: Manifold | D29: VV5QC41 | E29: 식 | F29: 2 | G29: 850000 | H29: =IF(F29=0,G29,G29*F29) -> 1700000
C30: Speed Con | E30: 식 | F30: 20 | G30: 7000 | H30: =IF(F30=0,G30,G30*F30) -> 140000
C31: 배관자재 | E31: 식 | F31: 1 | G31: 100000 | H31: =IF(F31=0,G31,G31*F31) -> 100000
C32: 잡자재 | E32: 식 | F32: 1 | G32: 100000 | H32: =IF(F32=0,G32,G32*F32) -> 100000
H33: =IF(F33=0,G33,G33*F33) -> 0
H34: =IF(F34=0,G34,G34*F34) -> 0
H35: =IF(F35=0,G35,G35*F35) -> 0
H36: =IF(F36=0,G36,G36*F36) -> 0
H37: =IF(F37=0,G37,G37*F37) -> 0
H38: =IF(F38=0,G38,G38*F38) -> 0
H39: =IF(F39=0,G39,G39*F39) -> 0
H40: =IF(F40=0,G40,G40*F40) -> 0
...

Sheet #70
B1: □ 단위공사명(전기제외): | C1: 대경 밴드체결 | I1: (첨부)
A2: 구분 | C2: 품 명 | D2: 규격 | E2: 단위 | F2: 수량 | G2: 단가(원) | H2: 금액(원) | I2: 原MAKER
A3: 자 재 비 | B3: 철자재 | C3: ■BASE | D3: 제관,가공 | E3: 식 | F3: 1 | G3: 2000000 | H3: =IF(F3=0,G3,G3*F3) -> 2000000
C4: ■FRAME | D4: 제관,가공 | E4: 식 | F4: 1 | G4: 1500000 | H4: =IF(F4=0,G4,G4*F4) -> 1500000
C5: ■상측 COVER | D5: 제관,가공 | E5: 식 | F5: 1 | G5: 1500000 | H5: =IF(F5=0,G5,G5*F5) -> 1500000
C6: ■OP POST | E6: 식 | F6: 1 | G6: 600000 | H6: =IF(F6=0,G6,G6*F6) -> 600000
C7: ■밴드체결UNIT | E7: 식 | F7: 1 | G7: 4000000 | H7: =IF(F7=0,G7,G7*F7) -> 4000000
H8: =IF(F8=0,G8,G8*F8) -> 0
C9: ■LIFTER UNIT | E9: 식 | F9: 1 | G9: 1300000 | H9: =IF(F9=0,G9,G9*F9) -> 1300000
H10: =IF(F10=0,G10,G10*F10) -> 0
H11: =IF(F11=0,G11,G11*F11) -> 0
C12: 기타 가공물 | E12: 식 | F12: 1 | G12: 500000 | H12: 0
H13: =SUM(H3:H12) -> 10900000
B14: 설치/해체/시운전 | H14: =IF(F14=0,G14,G14*F14) -> 0
B15: 공사 관련 자재 | H15: =IF(F15=0,G15,G15*F15) -> 0
H16: =IF(F16=0,G16,G16*F16) -> 0
H17: =IF(F17=0,G17,G17*F17) -> 0
C18: 기타자재 | H18: =IF(F18=0,G18,G18*F18) -> 0
H19: =SUM(H14:H18) -> 0
B20: 구매품 | C20: ■밴드체결툴 | E20: 식 | F20: 2 | G20: 1000000 | H20: =IF(F20=0,G20,G20*F20) -> 2000000
B21: (유공압품외) | C21: ■공압클램프 | E21: 식 | F21: 2 | G21: 500000 | H21: =IF(F21=0,G21,G21*F21) -> 1000000
C22: ■리시버탱크 | E22: 식 | F22: 1 | G22: 2000000 | H22: =IF(F22=0,G22,G22*F22) -> 2000000
C23: ■LM류 | E23: 식 | F23: 1 | G23: 1000000 | H23: =IF(F23=0,G23,G23*F23) -> 1000000
C24: ■공압 CYL | E24: 식 | F24: 1 | G24: 500000 | H24: =IF(F24=0,G24,G24*F24) -> 500000
H25: =IF(F25=0,G25,G25*F25) -> 0
C26: ■LIFTER UNIT | E26: 식 | F26: 2 | G26: 600000 | H26: =IF(F26=0,G26,G26*F26) -> 1200000
H27: =IF(F27=0,G27,G27*F27) -> 0
C28: ■일반 자재류 | H28: =IF(F28=0,G28,G28*F28) -> 0
C29: F.R.L Unit | D29: AV4000 | E29: 식 | F29: 3 | G29: 350000 | H29: =IF(F29=0,G29,G29*F29) -> 1050000
C30: SOL V/V | D30: VQC4201 | E30: 식 | F30: 20 | G30: 75000 | H30: =IF(F30=0,G30,G30*F30) -> 1500000
C31: Manifold | D31: VV5QC41 | E31: 식 | F31: 2 | G31: 850000 | H31: =IF(F31=0,G31,G31*F31) -> 1700000
C32: Speed Con | E32: 식 | F32: 20 | G32: 7000 | H32: =IF(F32=0,G32,G32*F32) -> 140000
C33: 배관자재 | E33: 식 | F33: 2 | G33: 100000 | H33: =IF(F33=0,G33,G33*F33) -> 200000
C34: 잡자재 | E34: 식 | F34: 2 | G34: 100000 | H34: =IF(F34=0,G34,G34*F34) -> 200000
H35: =IF(F35=0,G35,G35*F35) -> 0
H36: =IF(F36=0,G36,G36*F36) -> 0
H37: =IF(F37=0,G37,G37*F37) -> 0
H38: =IF(F38=0,G38,G38*F38) -> 0
H39: =IF(F39=0,G39,G39*F39) -> 0
H40: =IF(F40=0,G40,G40*F40) -> 0
...

Sheet #80
B1: □ 단위공사명(전기제외): | C1: 완성비젼 | I1: (첨부)
A2: 구분 | C2: 품 명 | D2: 규격 | E2: 단위 | F2: 수량 | G2: 단가(원) | H2: 금액(원) | I2: 原MAKER
A3: 자 재 비 | B3: 철자재 | C3: ■BASE | D3: 제관,가공 | E3: 식 | F3: 1 | G3: 2000000 | H3: =IF(F3=0,G3,G3*F3) -> 2000000
C4: ■FRAME | D4: 제관,가공 | E4: 식 | F4: 1 | G4: 1500000 | H4: =IF(F4=0,G4,G4*F4) -> 1500000
C5: ■상측 COVER | D5: 제관,가공 | E5: 식 | F5: 1 | G5: 1500000 | H5: =IF(F5=0,G5,G5*F5) -> 1500000
C6: ■OP POST | E6: 식 | F6: 1 | G6: 600000 | H6: =IF(F6=0,G6,G6*F6) -> 600000
C7: ■비젼 UNIT | D7: 암실등 | E7: 식 | F7: 1 | G7: 4000000 | H7: =IF(F7=0,G7,G7*F7) -> 4000000
H8: =IF(F8=0,G8,G8*F8) -> 0
C9: ■LIFTER UNIT | E9: 식 | F9: 1 | G9: 1300000 | H9: =IF(F9=0,G9,G9*F9) -> 1300000
H10: =IF(F10=0,G10,G10*F10) -> 0
C11: 기타자재 | E11: 식 | F11: 1 | G11: 500000 | H11: 0
H12: =SUM(H3:H11) -> 10900000
B13: 설치/해체/시운전 | H13: =IF(F13=0,G13,G13*F13) -> 0
B14: 공사 관련 자재 | H14: =IF(F14=0,G14,G14*F14) -> 0
H15: =IF(F15=0,G15,G15*F15) -> 0
H16: =IF(F16=0,G16,G16*F16) -> 0
C17: 기타자재 | H17: =IF(F17=0,G17,G17*F17) -> 0
H18: =SUM(H13:H17) -> 0
B19: 구매품 | C19: ■비젼 | H19: =IF(F19=0,G19,G19*F19) -> 0
B20: (유공압품외) | C20: 비젼시스템 | D20: XG-HL04M,XG-X2800 | E20: 식 | F20: 1 | G20: 30000000 | H20: =IF(F20=0,G20,G20*F20) -> 30000000
C21: 직교 robot | D21: 1축 | E21: 식 | F21: 1 | G21: 10000000 | H21: =IF(F21=0,G21,G21*F21) -> 10000000
C22: 기타(압쇼버/케이블베어등) | E22: 식 | F22: 1 | G22: 300000 | H22: =IF(F22=0,G22,G22*F22) -> 300000
C23: ■공압 CYL | E23: 식 | F23: 1 | G23: 500000 | H23: =IF(F23=0,G23,G23*F23) -> 500000
H24: =IF(F24=0,G24,G24*F24) -> 0
C25: ■LIFTER UNIT | E25: 식 | F25: 1 | G25: 600000 | H25: =IF(F25=0,G25,G25*F25) -> 600000
H26: =IF(F26=0,G26,G26*F26) -> 0
C27: ■일반 자재류 | H27: =IF(F27=0,G27,G27*F27) -> 0
C28: F.R.L Unit | D28: AV4000 | E28: 식 | F28: 1 | G28: 350000 | H28: =IF(F28=0,G28,G28*F28) -> 350000
C29: SOL V/V | D29: VQC4201 | E29: 식 | F29: 10 | G29: 75000 | H29: =IF(F29=0,G29,G29*F29) -> 750000
C30: Manifold | D30: VV5QC41 | E30: 식 | F30: 1 | G30: 850000 | H30: =IF(F30=0,G30,G30*F30) -> 850000
C31: Speed Con | E31: 식 | F31: 10 | G31: 7000 | H31: =IF(F31=0,G31,G31*F31) -> 70000
C32: 배관자재 | E32: 식 | F32: 1 | G32: 100000 | H32: =IF(F32=0,G32,G32*F32) -> 100000
C33: 잡자재 | E33: 식 | F33: 1 | G33: 100000 | H33: =IF(F33=0,G33,G33*F33) -> 100000
H34: =IF(F34=0,G34,G34*F34) -> 0
H35: =IF(F35=0,G35,G35*F35) -> 0
H36: =IF(F36=0,G36,G36*F36) -> 0
H37: =IF(F37=0,G37,G37*F37) -> 0
H38: =IF(F38=0,G38,G38*F38) -> 0
H39: =IF(F39=0,G39,G39*F39) -> 0
H40: =IF(F40=0,G40,G40*F40) -> 0
...

Sheet #90
B1: □ 단위공사명(전기제외): | C1: UN-LOADING 배출 및 적재 | I1: (첨부)
A2: 구분 | C2: 품 명 | D2: 규격 | E2: 단위 | F2: 수량 | G2: 단가(원) | H2: 금액(원) | I2: 原MAKER
A3: 자 재 비 | B3: 철자재 | C3: ■BASE | D3: 제관,가공 | E3: 식 | F3: 1 | G3: 2000000 | H3: =IF(F3=0,G3,G3*F3) -> 2000000
C4: ■FRAME | D4: 제관,가공 | E4: 식 | F4: 1 | G4: 1500000 | H4: =IF(F4=0,G4,G4*F4) -> 1500000
C5: ■상측 COVER | D5: 제관,가공 | E5: 식 | F5: 1 | G5: 1500000 | H5: =IF(F5=0,G5,G5*F5) -> 1500000
C6: ■OP POST | E6: 식 | F6: 1 | G6: 600000 | H6: =IF(F6=0,G6,G6*F6) -> 600000
C7: ■다축로봇 | D7: 제관,가공 | E7: 식 | F7: 1 | G7: 4500000 | H7: =IF(F7=0,G7,G7*F7) -> 4500000
D8: 안전펜스 | E8: 식 | F8: 1 | G8: 4500000 | H8: =IF(F8=0,G8,G8*F8) -> 4500000
C9: ■I팔레트 공급 | D9: 파레타이징 | E9: 식 | F9: 1 | G9: 19500000 | H9: =IF(F9=0,G9,G9*F9) -> 19500000
C10: ■LIFTER UNIT | E10: 식 | F10: 1 | G10: 1300000 | H10: =IF(F10=0,G10,G10*F10) -> 1300000
H11: =IF(F11=0,G11,G11*F11) -> 0
H12: =IF(F12=0,G12,G12*F12) -> 0
H13: =IF(F13=0,G13,G13*F13) -> 0
H14: =IF(F14=0,G14,G14*F14) -> 0
H15: =IF(F15=0,G15,G15*F15) -> 0
C16: 기타자재 | E16: 식 | F16: 1 | G16: 500000 | H16: 0
H17: =SUM(H3:H16) -> 35400000
B18: 설치/해체/시운전 | H18: =IF(F18=0,G18,G18*F18) -> 0
B19: 공사 관련 자재 | H19: =IF(F19=0,G19,G19*F19) -> 0
H20: =IF(F20=0,G20,G20*F20) -> 0
H21: =IF(F21=0,G21,G21*F21) -> 0
C22: 기타자재 | H22: =IF(F22=0,G22,G22*F22) -> 0
H23: =SUM(H18:H22) -> 0
B24: 구매품 | C24: ■다축로봇 | H24: =IF(F24=0,G24,G24*F24) -> 0
B25: (유공압품외) | C25: 6축로봇 | D25: 가와사키 200Kg | E25: 식 | F25: 1 | G25: 52000000 | H25: 0 | I25: 위아 사급
C26: 그리퍼 | E26: 식 | F26: 1 | G26: 2500000 | H26: =IF(F26=0,G26,G26*F26) -> 2500000
C27: ■팔레트 공급 | H27: =IF(F27=0,G27,G27*F27) -> 0
C28: 팔레트 투입/이송 | D28: 공압 CYL'류 | E28: 식 | F28: 2 | G28: 3400000 | H28: =IF(F28=0,G28,G28*F28) -> 6800000
D29: 센스류 | E29: 식 | F29: 2 | G29: 800000 | H29: =IF(F29=0,G29,G29*F29) -> 1600000
D30: 기타(LM,압쇼버등) | E30: 식 | F30: 2 | G30: 1500000 | H30: =IF(F30=0,G30,G30*F30) -> 3000000
C31: 팔레트 로딩 | D31: 공압 CYL'류 | E31: 식 | F31: 2 | G31: 3800000 | H31: =IF(F31=0,G31,G31*F31) -> 7600000
D32: 센스류 | E32: 식 | F32: 2 | G32: 1000000 | H32: =IF(F32=0,G32,G32*F32) -> 2000000
C33: 엘리베이트 | D33: 서보실린더 | E33: 식 | F33: 2 | G33: 2500000 | H33: =IF(F33=0,G33,G33*F33) -> 5000000
D34: 서버모타 ASS'Y | E34: 식 | F34: 2 | G34: 3000000 | H34: =IF(F34=0,G34,G34*F34) -> 6000000
D35: 감속기 | E35: 식 | F35: 2 | G35: 600000 | H35: =IF(F35=0,G35,G35*F35) -> 1200000
D36: 기타(LM,압쇼버등) | E36: 식 | F36: 2 | G36: 1800000 | H36: =IF(F36=0,G36,G36*F36) -> 3600000
C37: 배출 | D37: 서버모타 ASS'Y | E37: 식 | F37: 2 | G37: 3000000 | H37: =IF(F37=0,G37,G37*F37) -> 6000000
D38: 감속기 | E38: 식 | F38: 2 | G38: 600000 | H38: =IF(F38=0,G38,G38*F38) -> 1200000
D39: 기타(LM,압쇼버등) | E39: 식 | F39: 2 | G39: 200000 | H39: =IF(F39=0,G39,G39*F39) -> 400000
H40: =IF(F40=0,G40,G40*F40) -> 0
...

Sheet #100
B1: □ 단위공사명(전기제외): | C1: MAIN CONVEYOR | I1: (첨부)
A2: 구분 | C2: 품 명 | D2: 규격 | E2: 단위 | F2: 수량 | G2: 단가(원) | H2: 금액(원) | I2: 原MAKER
A3: 자 재 비 | B3: 철자재 | H3: =IF(F3=0,G3,G3*F3) -> 0
H4: =IF(F4=0,G4,G4*F4) -> 0
C5: ■기타 | H5: =IF(F5=0,G5,G5*F5) -> 0
C6: DUCT | E6: M | F6: 30 | G6: 150000 | H6: =IF(F6=0,G6,G6*F6) -> 4500000
C7: 계단 | E7: 식 | F7: 1 | G7: 1500000 | H7: =IF(F7=0,G7,G7*F7) -> 1500000
C8: 배관40APIPE | E8: M | F8: 30 | G8: 120000 | H8: =IF(F8=0,G8,G8*F8) -> 3600000
C9: T/B BKT | E9: 식 | F9: 1 | G9: 800000 | H9: =IF(F9=0,G9,G9*F9) -> 800000
C10: NAME PLATE | E10: 식 | F10: 1 | G10: 400000 | H10: =IF(F10=0,G10,G10*F10) -> 400000
H11: =IF(F11=0,G11,G11*F11) -> 0
H12: =IF(F12=0,G12,G12*F12) -> 0
H13: =IF(F13=0,G13,G13*F13) -> 0
H14: =IF(F14=0,G14,G14*F14) -> 0
H15: =IF(F15=0,G15,G15*F15) -> 0
C16: 기타자재 | E16: 식 | F16: 1 | G16: 1000000 | H16: 0
H17: =SUM(H3:H16) -> 10800000
B18: 설치/해체/시운전 | H18: =IF(F18=0,G18,G18*F18) -> 0
B19: 공사 관련 자재 | H19: =IF(F19=0,G19,G19*F19) -> 0
H20: =IF(F20=0,G20,G20*F20) -> 0
H21: =IF(F21=0,G21,G21*F21) -> 0
C22: 기타자재 | H22: =IF(F22=0,G22,G22*F22) -> 0
H23: =SUM(H18:H22) -> 0
B24: 구매품 | H24: =IF(F24=0,G24,G24*F24) -> 0
B25: (유공압품외) | H25: =IF(F25=0,G25,G25*F25) -> 0
H26: =IF(F26=0,G26,G26*F26) -> 0
H27: =IF(F27=0,G27,G27*F27) -> 0
C28: ■일반 자재류 | H28: =IF(F28=0,G28,G28*F28) -> 0
C29: F.R.L Unit | D29: AV4000 | E29: 식 | F29: 2 | G29: 350000 | H29: =IF(F29=0,G29,G29*F29) -> 700000
C30: SOL V/V | D30: VQC4201 | E30: 식 | F30: 30 | G30: 75000 | H30: =IF(F30=0,G30,G30*F30) -> 2250000
C31: Manifold | D31: VV5QC41 | E31: 식 | F31: 3 | G31: 850000 | H31: =IF(F31=0,G31,G31*F31) -> 2550000
C32: Speed Con | E32: 식 | F32: 60 | G32: 7000 | H32: =IF(F32=0,G32,G32*F32) -> 420000
C33: 배관자재 | E33: 식 | F33: 1 | G33: 3000000 | H33: =IF(F33=0,G33,G33*F33) -> 3000000
C34: 잡자재 | E34: 식 | F34: 1 | G34: 2000000 | H34: =IF(F34=0,G34,G34*F34) -> 2000000
H35: =IF(F35=0,G35,G35*F35) -> 0
H36: =IF(F36=0,G36,G36*F36) -> 0
H37: =IF(F37=0,G37,G37*F37) -> 0
H38: =IF(F38=0,G38,G38*F38) -> 0
H39: =IF(F39=0,G39,G39*F39) -> 0
H40: =IF(F40=0,G40,G40*F40) -> 0
...

Sheet #110
C1: □ 단위공사명(전기제외): | D1: PALLETS | J1: (첨부)
B2: 구분 | D2: 품 명 | E2: 규격 | F2: 단위 | G2: 수량 | H2: 단가(원) | I2: 금액(원) | J2: 原MAKER
C3: 철자재 | D3: ■PALLET | F3: 식 | G3: 25 | H3: 3000000 | I3: =IF(G3=0,H3,H3*G3) -> 75000000
I4: =IF(G4=0,H4,H4*G4) -> 0
I5: =IF(G5=0,H5,H5*G5) -> 0
I6: =IF(G6=0,H6,H6*G6) -> 0
I7: =IF(G7=0,H7,H7*G7) -> 0
I8: =IF(G8=0,H8,H8*G8) -> 0
I9: =IF(G9=0,H9,H9*G9) -> 0
I10: =IF(G10=0,H10,H10*G10) -> 0
I11: =IF(G11=0,H11,H11*G11) -> 0
I12: =IF(G12=0,H12,H12*G12) -> 0
I13: =IF(G13=0,H13,H13*G13) -> 0
I14: =IF(G14=0,H14,H14*G14) -> 0
I15: =IF(G15=0,H15,H15*G15) -> 0
... I44: =IF(G44=0,H44,H44*G44) -> 0
D46: 기타자재 | F46: 식 | I46: =IF(G46=0,H46,H46*G46) -> 0
I47: =SUM(I3:I46) -> 75000000
C48: 설치/해체/시운전 | I48: =IF(G48=0,H48,H48*G48) -> 0
C49: 공사 관련 자재 | I49: =IF(G49=0,H49,H49*G49) -> 0
D50: 기타자재 | I50: =IF(G50=0,H50,H50*G50) -> 0
I51: =SUM(I48:I50) -> 0
C52: 구매품 | D52: ■PALLET | I52: =IF(G52=0,H52,H52*G52) -> 0
C53: (유공압품외) | I53: =IF(G53=0,H53,H53*G53) -> 0
D54: 그리퍼 | F54: 식 | G54: 25 | H54: 800000 | I54: =IF(G54=0,H54,H54*G54) -> 20000000
I55: =IF(G55=0,H55,H55*G55) -> 0
I56: =IF(G56=0,H56,H56*G56) -> 0
I57: =IF(G57=0,H57,H57*G57) -> 0
I58: =IF(G58=0,H58,H58*G58) -> 0
I59: =IF(G59=0,H59,H59*G59) -> 0
I60: =IF(G60=0,H60,H60*G60) -> 0
I61: =IF(G61=0,H61,H61*G61) -> 0
I62: =IF(G62=0,H62,H62*G62) -> 0
I63: =IF(G63=0,H63,H63*G63) -> 0
I64: =IF(G64=0,H64,H64*G64) -> 0
I65: =IF(G65=0,H65,H65*G65) -> 0
I66: =IF(G66=0,H66,H66*G66) -> 0
... I101: =IF(G101=0,H101,H101*G101) -> 0
D102: 기타자재 | F102: 식 | I102: =IF(G102=0,H102,H102*G102) -> 0
I103: =SUM(I52:I102) -> 20000000
...

Sheet #120
B1: □ 단위공사명(전기제외): | C1: GREASE PUMP SYSTEM | I1: (첨부)
A2: 구분 | C2: 품 명 | D2: 규격 | E2: 단위 | F2: 수량 | G2: 단가(원) | H2: 금액(원) | I2: 原MAKER
A3: 자 재 비 | B3: 철자재 | H3: =F3*G3 -> 0
H4: =F4*G4 -> 0
H5: =F5*G5 -> 0
H6: =IF(F6=0,G6,G6*F6) -> 0
H7: =IF(F7=0,G7,G7*F7) -> 0
H8: =IF(F8=0,G8,G8*F8) -> 0
H9: =IF(F9=0,G9,G9*F9) -> 0
H10: =IF(F10=0,G10,G10*F10) -> 0
H11: =IF(F11=0,G11,G11*F11) -> 0
H12: =IF(F12=0,G12,G12*F12) -> 0
H13: =IF(F13=0,G13,G13*F13) -> 0
H14: =IF(F14=0,G14,G14*F14) -> 0
H15: =IF(F15=0,G15,G15*F15) -> 0
H16: =IF(F16=0,G16,G16*F16) -> 0
H17: =IF(F17=0,G17,G17*F17) -> 0
C18: 기타 가공물 | E18: 식 | H18: =IF(F18=0,G18,G18*F18) -> 0
H19: =SUM(H3:H18) -> 0
B20: 설치/해체/시운전 | H20: =IF(F20=0,G20,G20*F20) -> 0
B21: 공사 관련 자재 | H21: =IF(F21=0,G21,G21*F21) -> 0
H22: =IF(F22=0,G22,G22*F22) -> 0
H23: =IF(F23=0,G23,G23*F23) -> 0
C24: 기타자재 | H24: =IF(F24=0,G24,G24*F24) -> 0
H25: =SUM(H20:H24) -> 0
B26: 구매품 | H26: =IF(F26=0,G26,G26*F26) -> 0
B27: (유공압품외) | C27: 구리스 펌프 | E27: 식 | F27: 1 | G27: 43000000 | H27: =IF(F27=0,G27,G27*F27) -> 43000000
H28: =IF(F28=0,G28,G28*F28) -> 0
H29: =IF(F29=0,G29,G29*F29) -> 0
H30: =IF(F30=0,G30,G30*F30) -> 0
H31: =IF(F31=0,G31,G31*F31) -> 0
H32: =IF(F32=0,G32,G32*F32) -> 0
H33: =IF(F33=0,G33,G33*F33) -> 0
H34: =IF(F34=0,G34,G34*F34) -> 0
H35: =IF(F35=0,G35,G35*F35) -> 0
H36: =IF(F36=0,G36,G36*F36) -> 0
H37: =IF(F37=0,G37,G37*F37) -> 0
H38: =IF(F38=0,G38,G38*F38) -> 0
H39: =IF(F39=0,G39,G39*F39) -> 0
... H44: =IF(F44=0,G44,G44*F44) -> 0
...

Sheet #130
B1: □ 단위공사명(전기제외): | C1: LMS SYSTEM | I1: (첨부)
A2: 구분 | C2: 품 명 | D2: 규격 | E2: 단위 | F2: 수량 | G2: 단가(원) | H2: 금액(원) | I2: 原MAKER
A3: 자 재 비 | B3: 철자재 | H3: =F3*G3 -> 0
H4: =F4*G4 -> 0
H5: =F5*G5 -> 0
H6: =IF(F6=0,G6,G6*F6) -> 0
H7: =IF(F7=0,G7,G7*F7) -> 0
H8: =IF(F8=0,G8,G8*F8) -> 0
H9: =IF(F9=0,G9,G9*F9) -> 0
H10: =IF(F10=0,G10,G10*F10) -> 0
H11: =IF(F11=0,G11,G11*F11) -> 0
H12: =IF(F12=0,G12,G12*F12) -> 0
H13: =IF(F13=0,G13,G13*F13) -> 0
H14: =IF(F14=0,G14,G14*F14) -> 0
H15: =IF(F15=0,G15,G15*F15) -> 0
H16: =IF(F16=0,G16,G16*F16) -> 0
H17: =IF(F17=0,G17,G17*F17) -> 0
C18: 기타 가공물 | E18: 식 | H18: =IF(F18=0,G18,G18*F18) -> 0
H19: =SUM(H3:H18) -> 0
B20: 설치/해체/시운전 | H20: =IF(F20=0,G20,G20*F20) -> 0
B21: 공사 관련 자재 | H21: =IF(F21=0,G21,G21*F21) -> 0
H22: =IF(F22=0,G22,G22*F22) -> 0
H23: =IF(F23=0,G23,G23*F23) -> 0
C24: 기타자재 | H24: =IF(F24=0,G24,G24*F24) -> 0
H25: =SUM(H20:H24) -> 0
B26: 구매품 | H26: =IF(F26=0,G26,G26*F26) -> 0
B27: (유공압품외) | C27: LMS SYSTEM | E27: 식 | F27: 1 | G27: 30000000 | H27: =IF(F27=0,G27,G27*F27) -> 30000000
H28: =IF(F28=0,G28,G28*F28) -> 0
H29: =IF(F29=0,G29,G29*F29) -> 0
H30: =IF(F30=0,G30,G30*F30) -> 0
H31: =IF(F31=0,G31,G31*F31) -> 0
H32: =IF(F32=0,G32,G32*F32) -> 0
H33: =IF(F33=0,G33,G33*F33) -> 0
H34: =IF(F34=0,G34,G34*F34) -> 0
H35: =IF(F35=0,G35,G35*F35) -> 0
H36: =IF(F36=0,G36,G36*F36) -> 0
H37: =IF(F37=0,G37,G37*F37) -> 0
H38: =IF(F38=0,G38,G38*F38) -> 0
H39: =IF(F39=0,G39,G39*F39) -> 0
... H44: =IF(F44=0,G44,G44*F44) -> 0
...

Sheet #140
B1: □ 단위공사명(전기제외): | C1: RFID | I1: (첨부)
A2: 구분 | C2: 품 명 | D2: 규격 | E2: 단위 | F2: 수량 | G2: 단가(원) | H2: 금액(원) | I2: 原MAKER
A3: 자 재 비 | B3: 철자재 | H3: =F3*G3 -> 0
H4: =F4*G4 -> 0
H5: =F5*G5 -> 0
H6: =IF(F6=0,G6,G6*F6) -> 0
H7: =IF(F7=0,G7,G7*F7) -> 0
H8: =IF(F8=0,G8,G8*F8) -> 0
H9: =IF(F9=0,G9,G9*F9) -> 0
H10: =IF(F10=0,G10,G10*F10) -> 0
H11: =IF(F11=0,G11,G11*F11) -> 0
H12: =IF(F12=0,G12,G12*F12) -> 0
H13: =IF(F13=0,G13,G13*F13) -> 0
H14: =IF(F14=0,G14,G14*F14) -> 0
H15: =IF(F15=0,G15,G15*F15) -> 0
H16: =IF(F16=0,G16,G16*F16) -> 0
H17: =IF(F17=0,G17,G17*F17) -> 0
H18: =IF(F18=0,G18,G18*F18) -> 0
C19: 기타 가공물 | E19: 식 | H19: =IF(F19=0,G19,G19*F19) -> 0
H20: =SUM(H3:H19) -> 0
B21: 설치/해체/시운전 | H21: =IF(F21=0,G21,G21*F21) -> 0
B22: 공사 관련 자재 | H22: =IF(F22=0,G22,G22*F22) -> 0
H23: =IF(F23=0,G23,G23*F23) -> 0
H24: =IF(F24=0,G24,G24*F24) -> 0
C25: 기타자재 | H25: =IF(F25=0,G25,G25*F25) -> 0
H26: =SUM(H21:H25) -> 0
B27: 구매품 | H27: =IF(F27=0,G27,G27*F27) -> 0
B28: (유공압품외) | C28: RFID | E28: 식 | F28: 1 | G28: 16000000 | H28: =IF(F28=0,G28,G28*F28) -> 16000000
H29: =IF(F29=0,G29,G29*F29) -> 0
H30: =IF(F30=0,G30,G30*F30) -> 0
H31: =IF(F31=0,G31,G31*F31) -> 0
H32: =IF(F32=0,G32,G32*F32) -> 0
H33: =IF(F33=0,G33,G33*F33) -> 0
H34: =IF(F34=0,G34,G34*F34) -> 0
H35: =IF(F35=0,G35,G35*F35) -> 0
H36: =IF(F36=0,G36,G36*F36) -> 0
H37: =IF(F37=0,G37,G37*F37) -> 0
H38: =IF(F38=0,G38,G38*F38) -> 0
H39: =IF(F39=0,G39,G39*F39) -> 0
H40: =IF(F40=0,G40,G40*F40) -> 0
...

Sheet #150
B1: □ 단위공사명(전기제외): | I1: (첨부)
A2: 구분 | C2: 품 명 | D2: 규격 | E2: 단위 | F2: 수량 | G2: 단가(원) | H2: 금액(원) | I2: 原MAKER
A3: 자 재 비 | B3: 철자재 | H3: =F3*G3 -> 0
H4: =F4*G4 -> 0
H5: =F5*G5 -> 0
H6: =IF(F6=0,G6,G6*F6) -> 0
H7: =IF(F7=0,G7,G7*F7) -> 0
H8: =IF(F8=0,G8,G8*F8) -> 0
H9: =IF(F9=0,G9,G9*F9) -> 0
H10: =IF(F10=0,G10,G10*F10) -> 0
H11: =IF(F11=0,G11,G11*F11) -> 0
H12: =IF(F12=0,G12,G12*F12) -> 0
H13: =IF(F13=0,G13,G13*F13) -> 0
H14: =IF(F14=0,G14,G14*F14) -> 0
H15: =IF(F15=0,G15,G15*F15) -> 0
H16: =IF(F16=0,G16,G16*F16) -> 0
H17: =IF(F17=0,G17,G17*F17) -> 0
H18: =IF(F18=0,G18,G18*F18) -> 0
C19: 기타 가공물 | E19: 식 | H19: =IF(F19=0,G19,G19*F19) -> 0
H20: =SUM(H3:H19) -> 0
B21: 설치/해체/시운전 | H21: =IF(F21=0,G21,G21*F21) -> 0
B22: 공사 관련 자재 | H22: =IF(F22=0,G22,G22*F22) -> 0
H23: =IF(F23=0,G23,G23*F23) -> 0
H24: =IF(F24=0,G24,G24*F24) -> 0
C25: 기타자재 | H25: =IF(F25=0,G25,G25*F25) -> 0
H26: =SUM(H21:H25) -> 0
B27: 구매품 | H27: =IF(F27=0,0,G27*F27) -> 0
B28: (유공압품외) | H28: =IF(F28=0,0,G28*F28) -> 0
H29: =IF(F29=0,0,G29*F29) -> 0
H30: =IF(F30=0,0,G30*F30) -> 0
