Workbook

Sheet 갑지
B1: (현대/기아차 설비협력업체 견적통일양식)
B2: 見 積 書
B4: 현대 위아 貴下 | G4: ㈜지이엠
B5: 견적일자 | D5: 43787 | G5: 대표 : 송 칠 영 (인)
B6: 견적번호 | D6: GD1_191118-002 | G6: 주소 : 경남 창원시 성산구
B7: 납기 | C7: 입하 | G7: 성산패총로24번길 1
C8: 최종검수 | G8: 전화: 055-282-9488
B9: 견적유효기간 | D9: 견적일로부터30일 | G9: Fax: 055-282-9484 / 9490
B10: 인도장소 | D10: 현대위아 공장 | G10: 견적담당: | H10: 정대헌부장
B11: 지불조건 | D11: 현대위아 기준 | G11: 연 락 처 : | H11: 010-3452-0737
B13: 견적금액: 一金일십사억팔천구백만원整(\1,489,000,000 )
B15: 번호 | C15: 상세품목내역 | E15: 견적금액 (천원) | I15: 비 고
E16: 기계부분 | F16: 전기부문 | G16: 관리/이윤 (안전관리비포함) | H16: 합 계
B17: 1 | C17: =IF('단위공사별(집계)'!N7>0,'단위공사별(집계)'!B7,"") -> I/R선별,적재,공급 | E17: =IF('단위공사별(집계)'!N7>1,('단위공사별(집계)'!D7+'단위공사별(집계)'!E7+'단위공사별(집계)'!F7+'단위공사별(집계)'!G7+'단위공사별(집계)'!H7+'단위공사별(집계)'!I7)/1000," ") -> 157793.71 | F17: =IF('단위공사별(집계)'!N7>0,'단위공사별(집계)'!K37/1000,"") -> 254100 | G17: =IF('단위공사별(집계)'!N7>0,('단위공사별(집계)'!L7+'단위공사별(집계)'!M7)/1000,"") -> 276.5259 | H17: =IF('단위공사별(집계)'!N7>0,'단위공사별(집계)'!N7/1000,"") -> 190570.34
B18: 2 | C18: =IF('단위공사별(집계)'!N8>0,'단위공사별(집계)'!B8,"") -> I/B선별기 | E18: =IF('단위공사별(집계)'!N8>1,('단위공사별(집계)'!D8+'단위공사별(집계)'!E8+'단위공사별(집계)'!F8+'단위공사별(집계)'!G8+'단위공사별(집계)'!H8+'단위공사별(집계)'!I8)/1000," ") -> 74821.945 | G18: =IF('단위공사별(집계)'!N8>0,('단위공사별(집계)'!L8+'단위공사별(집계)'!M8)/1000,"") -> 131.12187 | H18: =IF('단위공사별(집계)'!N8>0,'단위공사별(집계)'!N8/1000,"") -> 90363.828
B19: 3 | C19: =IF('단위공사별(집계)'!N9>0,'단위공사별(집계)'!B9,"") -> I/B CLIP조립 | E19: =IF('단위공사별(집계)'!N9>1,('단위공사별(집계)'!D9+'단위공사별(집계)'!E9+'단위공사별(집계)'!F9+'단위공사별(집계)'!G9+'단위공사별(집계)'!H9+'단위공사별(집계)'!I9)/1000," ") -> 32769.686 | G19: =IF('단위공사별(집계)'!N9>0,('단위공사별(집계)'!L9+'단위공사별(집계)'!M9)/1000,"") -> 57.427302 | H19: =IF('단위공사별(집계)'!N9>0,'단위공사별(집계)'!N9/1000,"") -> 39576.548
B20: 4 | C20: =IF('단위공사별(집계)'!N10>0,'단위공사별(집계)'!B10,"") -> GRV정렬 | E20: =IF('단위공사별(집계)'!N10>1,('단위공사별(집계)'!D10+'단위공사별(집계)'!E10+'단위공사별(집계)'!F10+'단위공사별(집계)'!G10+'단위공사별(집계)'!H10+'단위공사별(집계)'!I10)/1000," ") -> 24198.845 | G20: =IF('단위공사별(집계)'!N10>0,('단위공사별(집계)'!L10+'단위공사별(집계)'!M10)/1000,"") -> 42.407313 | H20: =IF('단위공사별(집계)'!N10>0,'단위공사별(집계)'!N10/1000,"") -> 29225.386
B21: 5 | C21: =IF('단위공사별(집계)'!N11>0,'단위공사별(집계)'!B11,"") -> I/B선별 | E21: =IF('단위공사별(집계)'!N11>1,('단위공사별(집계)'!D11+'단위공사별(집계)'!E11+'단위공사별(집계)'!F11+'단위공사별(집계)'!G11+'단위공사별(집계)'!H11+'단위공사별(집계)'!I11)/1000," ") -> 44317.768 | G21: =IF('단위공사별(집계)'!N11>0,('단위공사별(집계)'!L11+'단위공사별(집계)'!M11)/1000,"") -> 77.66476 | H21: =IF('단위공사별(집계)'!N11>0,'단위공사별(집계)'!N11/1000,"") -> 53523.377
B22: 6 | C22: =IF('단위공사별(집계)'!N12>0,'단위공사별(집계)'!B12,"") -> 마킹 | E22: =IF('단위공사별(집계)'!N12>1,('단위공사별(집계)'!D12+'단위공사별(집계)'!E12+'단위공사별(집계)'!F12+'단위공사별(집계)'!G12+'단위공사별(집계)'!H12+'단위공사별(집계)'!I12)/1000," ") -> 84445.347 | G22: =IF('단위공사별(집계)'!N12>0,('단위공사별(집계)'!L12+'단위공사별(집계)'!M12)/1000,"") -> 147.98641 | H22: =IF('단위공사별(집계)'!N12>0,'단위공사별(집계)'!N12/1000,"") -> 101986.19
B23: 7 | C23: =IF('단위공사별(집계)'!N13>0,'단위공사별(집계)'!B13,"") -> I/B D/COVER압입 | E23: =IF('단위공사별(집계)'!N13>1,('단위공사별(집계)'!D13+'단위공사별(집계)'!E13+'단위공사별(집계)'!F13+'단위공사별(집계)'!G13+'단위공사별(집계)'!H13+'단위공사별(집계)'!I13)/1000," ") -> 71333.462 | G23: =IF('단위공사별(집계)'!N13>0,('단위공사별(집계)'!L13+'단위공사별(집계)'!M13)/1000,"") -> 125.00847 | H23: =IF('단위공사별(집계)'!N13>0,'단위공사별(집계)'!N13/1000,"") -> 86150.724
B24: 8 | C24: =IF('단위공사별(집계)'!N14>0,'단위공사별(집계)'!B14,"") -> 반전및 B/P압입 | E24: =IF('단위공사별(집계)'!N14>1,('단위공사별(집계)'!D14+'단위공사별(집계)'!E14+'단위공사별(집계)'!F14+'단위공사별(집계)'!G14+'단위공사별(집계)'!H14+'단위공사별(집계)'!I14)/1000," ") -> 84665.883 | G24: =IF('단위공사별(집계)'!N14>0,('단위공사별(집계)'!L14+'단위공사별(집계)'!M14)/1000,"") -> 148.37289 | H24: =IF('단위공사별(집계)'!N14>0,'단위공사별(집계)'!N14/1000,"") -> 102252.53
B25: 9 | C25: =IF('단위공사별(집계)'!N15>0,'단위공사별(집계)'!B15,"") -> I/R공급 및 방향정렬 | E25: =IF('단위공사별(집계)'!N15>1,('단위공사별(집계)'!D15+'단위공사별(집계)'!E15+'단위공사별(집계)'!F15+'단위공사별(집계)'!G15+'단위공사별(집계)'!H15+'단위공사별(집계)'!I15)/1000," ") -> 58412.041 | G25: =IF('단위공사별(집계)'!N15>0,('단위공사별(집계)'!L15+'단위공사별(집계)'!M15)/1000,"") -> 102.3643 | H25: =IF('단위공사별(집계)'!N15>0,'단위공사별(집계)'!N15/1000,"") -> 70545.288
B26: 10 | C26: =IF('단위공사별(집계)'!N16>0,'단위공사별(집계)'!B16,"") -> I/B볼 자동 공급 | E26: =IF('단위공사별(집계)'!N16>1,('단위공사별(집계)'!D16+'단위공사별(집계)'!E16+'단위공사별(집계)'!F16+'단위공사별(집계)'!G16+'단위공사별(집계)'!H16+'단위공사별(집계)'!I16)/1000," ") -> 48638.274 | G26: =IF('단위공사별(집계)'!N16>0,('단위공사별(집계)'!L16+'단위공사별(집계)'!M16)/1000,"") -> 85.23624 | H26: =IF('단위공사별(집계)'!N16>0,'단위공사별(집계)'!N16/1000,"") -> 58741.331
B27: 11 | C27: =IF('단위공사별(집계)'!N17>0,'단위공사별(집계)'!B17,"") -> I/B SUB 자동 조립 | E27: =IF('단위공사별(집계)'!N17>1,('단위공사별(집계)'!D17+'단위공사별(집계)'!E17+'단위공사별(집계)'!F17+'단위공사별(집계)'!G17+'단위공사별(집계)'!H17+'단위공사별(집계)'!I17)/1000," ") -> 51836.05 | G27: =IF('단위공사별(집계)'!N17>0,('단위공사별(집계)'!L17+'단위공사별(집계)'!M17)/1000,"") -> 90.840189 | H27: =IF('단위공사별(집계)'!N17>0,'단위공사별(집계)'!N17/1000,"") -> 62603.344
B28: 12 | C28: =IF('단위공사별(집계)'!N18>0,'단위공사별(집계)'!B18,"") -> I/B 스토퍼링 조립 | E28: =IF('단위공사별(집계)'!N18>1,('단위공사별(집계)'!D18+'단위공사별(집계)'!E18+'단위공사별(집계)'!F18+'단위공사별(집계)'!G18+'단위공사별(집계)'!H18+'단위공사별(집계)'!I18)/1000," ") -> 60316.673 | G28: =IF('단위공사별(집계)'!N18>0,('단위공사별(집계)'!L18+'단위공사별(집계)'!M18)/1000,"") -> 105.70207 | H28: =IF('단위공사별(집계)'!N18>0,'단위공사별(집계)'!N18/1000,"") -> 72845.546
B29: 13 | C29: =IF('단위공사별(집계)'!N19>0,'단위공사별(집계)'!B19,"") -> I/B 로더테스트 | E29: =IF('단위공사별(집계)'!N19>1,('단위공사별(집계)'!D19+'단위공사별(집계)'!E19+'단위공사별(집계)'!F19+'단위공사별(집계)'!G19+'단위공사별(집계)'!H19+'단위공사별(집계)'!I19)/1000," ") -> 47856.373 | G29: =IF('단위공사별(집계)'!N19>0,('단위공사별(집계)'!L19+'단위공사별(집계)'!M19)/1000,"") -> 83.865995 | H29: =IF('단위공사별(집계)'!N19>0,'단위공사별(집계)'!N19/1000,"") -> 57797.015
... B46: 30 | C46: =IF('단위공사별(집계)'!N36>0,'단위공사별(집계)'!B36,"") | E46: =IF('단위공사별(집계)'!N36>1,('단위공사별(집계)'!D36+'단위공사별(집계)'!E36+'단위공사별(집계)'!F36+'단위공사별(집계)'!G36+'단위공사별(집계)'!H36+'단위공사별(집계)'!I36)/1000," ") | G46: =IF('단위공사별(집계)'!N36>0,('단위공사별(집계)'!L36+'단위공사별(집계)'!M36)/1000,"") | H46: =IF('단위공사별(집계)'!N36>0,'단위공사별(집계)'!N36/1000,"")
B47: 견적 합계 | E47: =SUM(E17:E46) -> 1233700 | F47: =SUM(F17:F46) -> 254100 | G47: =SUM(G17:G46) -> 2162 | H47: =ROUNDDOWN(SUM(H17:H46),-3) -> 1489000
F49: 공개입찰가 (견적時 공란) | H49: 1489000
B51: 특기사항 | C51: 1. VAT 제외 | F51: 외주계획 업체명 (자작時 공란)
C52: 2. 기본 유틸리티공사 제외 | F52: 설계외주
C53: ='원가항목별(집계)'!I39 -> 2162000 | F53: 제작외주
F54: 전기외주
F55: 설치외주

Sheet 원가항목별(집계)
C2: A. 원가항목별 견적가 종합(상세견적 첨부)
B4: □ 현대/기아 요구사양과 견적조건 일치여부 CHECK: 1.일치함 2.일부상이(상이내역 첨부참조)
B6: 순번 | C6: 원가구분 | F6: 단위 | G6: 수량 | H6: 단가 | I6: 금 액(원) | J6: 비 고
B7: 1 | C7: 기계 부문 | D7: 자재비 | E7: 철자재(SS.SUS등) | F7: kg | G7: ='#10'!F22+'#20'!F22+'#30'!F20+'#40'!F18+'#50'!F20+'#60'!F19+'#70'!F20+'#80'!F22+'#90'!F19+'#100'!F18+'#110'!F26+'#120'!F19+'#130'!F18+'#140'!F18+'#150'!F17+'#160'!F22+'#170'!F19+'#180'!F26+'#190'!F19+'#200'!F18+'#210'!G18+'#220'!F17+'#230'!F22+'#240'!F19+'#250'!F18+'#260'!F18+'#270'!F18+'#280'!F18+'#290'!F18+'#300'!F18 -> 0 | I7: ='#10'!H19+'#20'!H18+'#30'!H14+'#40'!H12+'#50'!H14+'#60'!H13+'#70'!H14+'#80'!H16+'#90'!H13+'#100'!H12+'#110'!H20+'#120'!H13+'#130'!H12+'#140'!H12+'#150'!H11+'#160'!H16+'#170'!H13+'#180'!H20+'#190'!H13+'#200'!H12+'#210'!H12+'#220'!H11+'#230'!H16+'#240'!H13+'#250'!H12+'#260'!H12+'#270'!H12+'#280'!H12+'#290'!H12+'#300'!H12 -> 259950000 | J7: 加工必要資材
E8: 일반구매품 | F8: 식 | G8: 1 | I8: ='#10'!H68+'#20'!H40+'#30'!H43+'#40'!H40+'#50'!H40+'#60'!H38+'#70'!H48+'#80'!H57+'#90'!H43+'#100'!H40+'#110'!H48+'#120'!H42+'#130'!H40+'#140'!H34+'#150'!H34+'#160'!H40+'#170'!H45+'#180'!H48+'#190'!H42+'#200'!H40+'#210'!H34+'#220'!H34+'#230'!H40+'#240'!H45+'#250'!H32+'#260'!H40+'#270'!H40+'#280'!H40+'#290'!H40+'#300'!H40 -> 508700000 | J8: 加工不要資材
E9: 외주제작품 | F9: 식 | G9: 1 | I9: ='#10'!H72+'#20'!H48+'#30'!H48+'#40'!H48+'#50'!H43+'#60'!H46+'#70'!H56+'#80'!H65+'#90'!H51+'#100'!H48+'#110'!H56+'#120'!H50+'#130'!H48+'#140'!H39+'#150'!H42+'#160'!H48+'#170'!H53+'#180'!H56+'#190'!H50+'#200'!H48+'#210'!H42+'#220'!H42+'#230'!H48+'#240'!H53+'#250'!H40+'#260'!H48+'#270'!H48+'#280'!H48+'#290'!H48+'#300'!H48 -> 85000000 | J9: 旣加工SUB資材
E10: 설치/해체 공사 자재 | F10: 식 | G10: 1 | I10: ='#10'!H22+'#20'!H22+'#30'!H20+'#40'!H18+'#50'!H20+'#60'!H19+'#70'!H20+'#80'!H22+'#90'!H19+'#100'!H18+'#110'!H26+'#120'!H19+'#130'!H18+'#140'!H18+'#150'!H17+'#160'!H22+'#170'!H19+'#180'!H26+'#190'!H19+'#200'!H18+'#210'!H18+'#220'!H17+'#230'!H22+'#240'!H19+'#250'!H18+'#260'!H18+'#270'!H18+'#280'!H18+'#290'!H18+'#300'!H18 -> 0 | J10: 시운전 자재 포함
E11: 소계 | I11: =SUM(I7:I10) -> 853650000
D12: 노무비 | E12: 기존설비 철거 | F12: M/D | G12: ='#10'!F74+'#20'!F50+'#30'!F50+'#40'!F50+'#50'!F45+'#60'!F48+'#70'!F58+'#80'!F67+'#90'!F53+'#100'!F50+'#110'!F58+'#120'!F52+'#130'!F50+'#140'!F41+'#150'!F44+'#160'!F50+'#170'!F55+'#180'!F58+'#190'!F52+'#200'!F50+'#210'!F44+'#220'!F44+'#230'!F50+'#240'!F55+'#250'!F42+'#260'!F50+'#270'!F50+'#280'!F50+'#290'!F50+'#300'!F50 -> 0 | H12: =IF('#10'!G74>0,'#10'!G74,"") -> 250000 | I12: ='#10'!H74+'#20'!H50+'#30'!H50+'#40'!H50+'#50'!H45+'#60'!H48+'#70'!H58+'#80'!H67+'#90'!H53+'#100'!H50+'#110'!H58+'#120'!H52+'#130'!H50+'#140'!H41+'#150'!H44+'#160'!H50+'#170'!H55+'#180'!H58+'#190'!H52+'#200'!H50 -> 0 | J12: 개조공사時
E13: 설계 | F13: M/D | G13: ='#10'!F75+'#20'!F51+'#30'!F51+'#40'!F51+'#50'!F46+'#60'!F49+'#70'!F59+'#80'!F68+'#90'!F54+'#100'!F51+'#110'!F59+'#120'!F53+'#130'!F51+'#140'!F42+'#150'!F45+'#160'!F51+'#170'!F56+'#180'!F59+'#190'!F53+'#200'!F51+'#210'!F45+'#220'!F45+'#230'!F51+'#240'!F56+'#250'!F43+'#260'!F51+'#270'!F51+'#280'!F51+'#290'!F51+'#300'!F51 -> 455 | H13: =IF('#10'!G75>0,'#10'!G75,"") -> 300000 | I13: ='#10'!H75+'#20'!H51+'#30'!H51+'#40'!H51+'#50'!H46+'#60'!H49+'#70'!H59+'#80'!H68+'#90'!H54+'#100'!H51+'#110'!H59+'#120'!H53+'#130'!H51+'#140'!H42+'#150'!H45+'#160'!H51+'#170'!H56+'#180'!H59+'#190'!H53+'#200'!H51+'#210'!H45+'#220'!H45+'#230'!H51+'#240'!H56+'#250'!H43+'#260'!H51+'#270'!H51+'#280'!H51+'#290'!H51+'#300'!H51 -> 136500000
E14: 제작(제관,가공) | F14: M/D | G14: ='#10'!F76+'#20'!F52+'#30'!F52+'#40'!F52+'#50'!F47+'#60'!F50+'#70'!F60+'#80'!F69+'#90'!F55+'#100'!F52+'#110'!F60+'#120'!F54+'#130'!F52+'#140'!F43+'#150'!F46+'#160'!F52+'#170'!F57+'#180'!F60+'#190'!F54+'#200'!F52+'#210'!F46+'#220'!F46+'#230'!F52+'#240'!F57+'#250'!F44+'#260'!F52+'#270'!F52+'#280'!F52+'#290'!F52+'#300'!F52 -> 140 | H14: =IF('#10'!G76>0,'#10'!G76,"") -> 250000 | I14: ='#10'!H76+'#20'!H52+'#30'!H52+'#40'!H52+'#50'!H47+'#60'!H50+'#70'!H60+'#80'!H69+'#90'!H55+'#100'!H52+'#110'!H60+'#120'!H54+'#130'!H52+'#140'!H43+'#150'!H46+'#160'!H52+'#170'!H57+'#180'!H60+'#190'!H54+'#200'!H52+'#210'!H46+'#220'!H46+'#230'!H52+'#240'!H57+'#250'!H44+'#260'!H52+'#270'!H52+'#280'!H52+'#290'!H52+'#300'!H52 -> 35000000
E15: 조립 | F15: M/D | G15: ='#10'!F77+'#20'!F53+'#30'!F53+'#40'!F53+'#50'!F48+'#60'!F51+'#70'!F61+'#80'!F70+'#90'!F56+'#100'!F53+'#110'!F61+'#120'!F55+'#130'!F53+'#140'!F44+'#150'!F47+'#160'!F53+'#170'!F58+'#180'!F61+'#190'!F55+'#200'!F53+'#210'!F47+'#220'!F47+'#230'!F53+'#240'!F58+'#250'!F45+'#260'!F53+'#270'!F53+'#280'!F53+'#290'!F53+'#300'!F53 -> 520 | H15: =IF('#10'!G77>0,'#10'!G77,"") -> 250000 | I15: ='#10'!H77+'#20'!H53+'#30'!H53+'#40'!H53+'#50'!H48+'#60'!H51+'#70'!H61+'#80'!H70+'#90'!H56+'#100'!H53+'#110'!H61+'#120'!H55+'#130'!H53+'#140'!H44+'#150'!H47+'#160'!H53+'#170'!H58+'#180'!H61+'#190'!H55+'#200'!H53+'#210'!H47+'#220'!H47+'#230'!H53+'#240'!H58+'#250'!H45+'#260'!H53+'#270'!H53+'#280'!H53+'#290'!H53+'#300'!H53 -> 130000000 | J15: 정도검사포함
E16: 설치 | F16: M/D | G16: ='#10'!F78+'#20'!F54+'#30'!F54+'#40'!F54+'#50'!F49+'#60'!F52+'#70'!F62+'#80'!F71+'#90'!F57+'#100'!F54+'#110'!F62+'#120'!F56+'#130'!F54+'#140'!F45+'#150'!F48+'#160'!F54+'#170'!F59+'#180'!F62+'#190'!F56+'#200'!F54+'#210'!F48+'#220'!F48+'#230'!F54+'#240'!F59+'#250'!F46+'#260'!F54+'#270'!F54+'#280'!F54+'#290'!F54+'#300'!F54 -> 54 | H16: =IF('#10'!G78>0,'#10'!G78,"") -> 300000 | I16: ='#10'!H78+'#20'!H54+'#30'!H54+'#40'!H54+'#50'!H49+'#60'!H52+'#70'!H62+'#80'!H71+'#90'!H57+'#100'!H54+'#110'!H62+'#120'!H56+'#130'!H54+'#140'!H45+'#150'!H48+'#160'!H54+'#170'!H59+'#180'!H62+'#190'!H56+'#200'!H54+'#210'!H48+'#220'!H48+'#230'!H54+'#240'!H59+'#250'!H46+'#260'!H54+'#270'!H54+'#280'!H54+'#290'!H54+'#300'!H54 -> 16200000
E17: 시운전 | F17: M/D | G17: ='#10'!F79+'#20'!F55+'#30'!F55+'#40'!F55+'#50'!F50+'#60'!F53+'#70'!F63+'#80'!F72+'#90'!F58+'#100'!F55+'#110'!F63+'#120'!F57+'#130'!F55+'#140'!F46+'#150'!F49+'#160'!F55+'#170'!F60+'#180'!F63+'#190'!F57+'#200'!F55+'#210'!F49+'#220'!F49+'#230'!F55+'#240'!F60+'#250'!F47+'#260'!F55+'#270'!F55+'#280'!F55+'#290'!F55+'#300'!F55 -> 82 | H17: =IF('#10'!G79>0,'#10'!G79,"") -> 300000 | I17: ='#10'!H79+'#20'!H55+'#30'!H55+'#40'!H55+'#50'!H50+'#60'!H53+'#70'!H63+'#80'!H72+'#90'!H58+'#100'!H55+'#110'!H63+'#120'!H57+'#130'!H55+'#140'!H46+'#150'!H49+'#160'!H55+'#170'!H60+'#180'!H63+'#190'!H57+'#200'!H55+'#210'!H49+'#220'!H49+'#230'!H55+'#240'!H60+'#250'!H47+'#260'!H55+'#270'!H55+'#280'!H55+'#290'!H55+'#300'!H55 -> 24600000
E18: 양산대응 | F18: M/D | G18: ='#10'!F80+'#20'!F56+'#30'!F56+'#40'!F56+'#50'!F51+'#60'!F54+'#70'!F64+'#80'!F73+'#90'!F59+'#100'!F56+'#110'!F64+'#120'!F58+'#130'!F56+'#140'!F47+'#150'!F50+'#160'!F56+'#170'!F61+'#180'!F64+'#190'!F58+'#200'!F56+'#210'!F50+'#220'!F50+'#230'!F56+'#240'!F61+'#250'!F48+'#260'!F56+'#270'!F56+'#280'!F56+'#290'!F56+'#300'!F56 -> 30 | H18: =IF('#10'!G80>0,'#10'!G80,"") -> 300000 | I18: ='#10'!H80+'#20'!H56+'#30'!H56+'#40'!H56+'#50'!H51+'#60'!H54+'#70'!H64+'#80'!H73+'#90'!H59+'#100'!H56+'#110'!H64+'#120'!H58+'#130'!H56+'#140'!H47+'#150'!H50+'#160'!H56+'#170'!H61+'#180'!H64+'#190'!H58+'#200'!H56+'#210'!H50+'#220'!H50+'#230'!H56+'#240'!H61+'#250'!H48+'#260'!H56+'#270'!H56+'#280'!H56+'#290'!H56+'#300'!H56 -> 9000000
E19: 도장 | F19: M/D | G19: ='#10'!F81+'#20'!F57+'#30'!F57+'#40'!F57+'#50'!F52+'#60'!F55+'#70'!F65+'#80'!F74+'#90'!F60+'#100'!F57+'#110'!F65+'#120'!F59+'#130'!F57+'#140'!F48+'#150'!F51+'#160'!F57+'#170'!F62+'#180'!F65+'#190'!F59+'#200'!F57+'#210'!F51+'#220'!F51+'#230'!F57+'#240'!F62+'#250'!F49+'#260'!F57+'#270'!F57+'#280'!F57+'#290'!F57+'#300'!F57 -> 103 | H19: =IF('#10'!G81>0,'#10'!G81,"") -> 250000 | I19: ='#10'!H81+'#20'!H57+'#30'!H57+'#40'!H57+'#50'!H52+'#60'!H55+'#70'!H65+'#80'!H74+'#90'!H60+'#100'!H57+'#110'!H65+'#120'!H59+'#130'!H57+'#140'!H48+'#150'!H51+'#160'!H57+'#170'!H62+'#180'!H65+'#190'!H59+'#200'!H57+'#210'!H51+'#220'!H51+'#230'!H57+'#240'!H62+'#250'!H49+'#260'!H57+'#270'!H57+'#280'!H57+'#290'!H57+'#300'!H57 -> 25750000
E20: 소계 | I20: =SUM(I12:I19) -> 377050000
D21: 일반관리 및 이윤 | I21: ='#10'!H84+'#10'!H85+'#20'!H60+'#20'!H61+'#30'!H60+'#30'!H61+'#40'!H60+'#40'!H61+'#50'!H55+'#50'!H56+'#60'!H58+'#60'!H59+'#70'!H68+'#70'!H69+'#80'!H77+'#80'!H78+'#90'!H63+'#90'!H64+'#100'!H60+'#100'!H61+'#110'!H68+'#110'!H69+'#120'!H62+'#120'!H63+'#130'!H60+'#130'!H61+'#140'!H51+'#140'!H52+'#150'!H54+'#150'!H55+'#160'!H60+'#160'!H61+'#170'!H65+'#170'!H66+'#180'!H68+'#180'!H69+'#190'!H62+'#190'!H63+'#200'!H60+'#200'!H61+'#210'!H54+'#210'!H55+'#220'!H54+'#220'!H55+'#230'!H60+'#230'!H61+'#240'!H65+'#240'!H66+'#250'!H52+'#250'!H53+'#260'!H60+'#260'!H61+'#270'!H60+'#270'!H61+'#280'!H60+'#280'!H61+'#290'!H60+'#290'!H61+'#300'!H60+'#300'!H61 -> 0
E22: 기계 소계 | I22: =I20+I11+I21 -> 1230700000
B23: 2 | C23: 전기 부문 | D23: 자재비 | E23: 기계/전기자재 | F23: 식 | G23: 1 | I23: =전기!H27-I24 -> 166300000
E24: 설치/해체 공사 자재 | F24: 식 | G24: 1 | I24: =전기!H16 -> 0 | J24: 시운전 자재 포함
D25: 노무비 | E25: 철거(개조시) | F25: M/D | G25: =전기!F28 -> 10 | H25: =IF(전기!G28>0,전기!G28,"") -> 250000 | I25: =전기!H28 -> 2500000
E26: 설계,프로그램 | F26: M/D | G26: =전기!F29 -> 80 | H26: =IF(전기!G29>0,전기!G29,"") -> 300000 | I26: =전기!H29 -> 24000000
E27: 제작 | F27: M/D | G27: =전기!F30 -> 80 | H27: =IF(전기!G30>0,전기!G30,"") -> 250000 | I27: =전기!H30 -> 20000000
E28: 조립 | F28: M/D | G28: =전기!F31 -> 80 | H28: =IF(전기!G31>0,전기!G31,"") -> 250000 | I28: =전기!H31 -> 20000000
E29: 설치 | F29: M/D | G29: =전기!F32 -> 20 | H29: =IF(전기!G32>0,전기!G32,"") -> 300000 | I29: =전기!H32 -> 6000000
E30: 시운전 | F30: M/D | G30: =전기!F33 -> 30 | H30: =IF(전기!G33>0,전기!G33,"") -> 300000 | I30: =전기!H33 -> 9000000
E31: 양산대응 | F31: M/D | G31: =전기!F34 -> 21 | H31: =IF(전기!G34>0,전기!G34,"") -> 300000 | I31: =전기!H34 -> 6300000
E32: 소계 | I32: =SUM(I25:I31) -> 87800000
D33: 일반관리 및 이윤 | I33: =전기!H37+전기!H38 -> 0
E34: 전기 소계 | I34: =I32+I23+I33+I24 -> 254100000
B35: 3 | C35: 자재비 합계 | I35: =I23+I11+I24 -> 1019950000
C36: 노무비 합계 | I36: =I32+I20 -> 464850000
C37: 중간 합계 | I37: =I36+I35 -> 1484800000
B38: 4 | C38: 포장,운송 및 중장비 사용료 | I38: 3000000
B39: 5 | C39: 표준안전관리비 | F39: 설치/철거/수리금액 기준 | I39: =CEILING(MIN(I47:I48),1000) -> 2162000 | J39: =I30+I29+I25+I24+I17+I16+I12+I10 -> 58300000
B40: 6 | C40: 일반관리비 | I40: =전기!H37+'#10'!H84+'#20'!H60+'#30'!H60+'#40'!H60+'#50'!H55+'#60'!H58+'#70'!H68+'#80'!H77+'#90'!H63+'#100'!H60+'#110'!H68+'#120'!H62+'#130'!H60+'#140'!H51+'#150'!H54+'#160'!H60+'#170'!H65+'#180'!H68+'#190'!H62+'#200'!H60+'#210'!H54+'#220'!H54+'#230'!H60+'#240'!H65+'#250'!H52+'#260'!H60+'#270'!H60+'#280'!H60+'#290'!H60+'#300'!H60 -> 0
B41: 7 | C41: 이 윤 | I41: =전기!H38+'#10'!H85+'#20'!H61+'#30'!H61+'#40'!H61+'#50'!H56+'#60'!H59+'#70'!H69+'#80'!H78+'#90'!H64+'#100'!H61+'#110'!H69+'#120'!H63+'#130'!H61+'#140'!H52+'#150'!H55+'#160'!H61+'#170'!H66+'#180'!H69+'#190'!H63+'#200'!H61+'#210'!H55+'#220'!H55+'#230'!H61+'#240'!H66+'#250'!H53+'#260'!H61+'#270'!H61+'#280'!H61+'#290'!H61+'#300'!H61 -> 0
C42: 합 계 | F42: 3~7항 합계 | I42: =I22+I34+I38+I39 -> 1489962000
B43: 주1. 표준안전관리비:(설치/철거/시운전 공사 관련 금액)의 ⓐ2.66%,ⓑ1.95%+기초액,ⓒ2.02%(50억 이상일경우)
...

Sheet 단위공사별(집계)
A2: B. 단위장비별 견적가 종합(상세견적 첨부)
N3: 단위:원
I5: 포장/운송 | L5: 표준안전 | M5: 일반관리비
A6: 순번 | B6: 단위장비명 | C6: 수량 | D6: 자재비 | E6: 철거 | F6: 제작 | G6: 설치/시운전 | H6: 양산대응 | I6: 중장비사용 | J6: 기계소계 | K6: 전기소계 | L6: 관리비 | M6: 이윤 | N6: 합 계 | O6: 비 고
A7: =IF(B7>0,1,"") -> 1 | B7: ='#10'!C$1 -> I/R선별,적재,공급 | C7: 1식 | D7: ='#10'!H73 -> 113410000 | E7: ='#10'!H74 -> 0 | F7: ='#10'!H75+'#10'!H76+'#10'!H77+'#10'!H81 -> 35000000 | G7: ='#10'!H78+'#10'!H79 -> 7500000 | H7: ='#10'!H80 -> 1500000 | I7: =IF($B7>0,'원가항목별(집계)'!I$38*$P7/$P$37,0) -> 383708.46 | J7: =SUM(D7:I7) -> 1.5779371e+08 | K7: =IF(B7>0,'원가항목별(집계)'!I$34*P7/P$37,0) -> 32500106 | L7: =IF($B7>0,'원가항목별(집계)'!I$39*$P7/$P$37,0) -> 276525.9 | M7: ='#10'!H84+'#10'!H85 -> 0 | N7: =SUM(J7:M7) -> 1.9057034e+08 | P7: =D7+E7+F7+G7+H7+M7 -> 157410000
A8: =IF(B8>0,A7+1,"") -> 2 | B8: ='#20'!C$1 -> I/B선별기 | C8: 1식 | D8: ='#20'!H49 -> 57790000 | E8: ='#20'!H50 -> 0 | F8: ='#20'!H51+'#20'!H52+'#20'!H53+'#20'!H57 -> 14750000 | G8: ='#20'!H54+'#20'!H55 -> 1800000 | H8: ='#20'!H56 -> 300000 | I8: =IF($B8>0,'원가항목별(집계)'!I$38*$P8/$P$37,0) -> 181945.23 | J8: =SUM(D8:I8) -> 74821945 | K8: =IF(B8>0,'원가항목별(집계)'!I$34*P8/P$37,0) -> 15410761 | L8: =IF($B8>0,'원가항목별(집계)'!I$39*$P8/$P$37,0) -> 131121.87 | M8: ='#20'!H60+'#20'!H61 -> 0 | N8: =SUM(J8:M8) -> 90363828 | P8: =D8+E8+F8+G8+H8+M8 -> 74640000
A9: =IF(B9>0,A8+1,"") -> 3 | B9: ='#30'!C$1 -> I/B CLIP조립 | C9: 1식 | D9: ='#30'!H49 -> 14590000 | E9: ='#30'!H50 -> 0 | F9: ='#30'!H51+'#30'!H52+'#30'!H53+'#30'!H57 -> 16000000 | G9: ='#30'!H54+'#30'!H55 -> 1800000 | H9: ='#30'!H56 -> 300000 | I9: =IF($B9>0,'원가항목별(집계)'!I$38*$P9/$P$37,0) -> 79686.357 | J9: =SUM(D9:I9) -> 32769686 | K9: =IF(B9>0,'원가항목별(집계)'!I$34*P9/P$37,0) -> 6749434.5 | L9: =IF($B9>0,'원가항목별(집계)'!I$39*$P9/$P$37,0) -> 57427.302 | M9: ='#30'!H60+'#30'!H61 -> 0 | N9: =SUM(J9:M9) -> 39576548 | P9: =D9+E9+F9+G9+H9+M9 -> 32690000
A10: =IF(B10>0,A9+1,"") -> 4 | B10: ='#40'!C$1 -> GRV정렬 | C10: 1식 | D10: ='#40'!H49 -> 7290000 | E10: ='#40'!H50 -> 0 | F10: ='#40'!H51+'#40'!H52+'#40'!H53+'#40'!H57 -> 14750000 | G10: ='#40'!H54+'#40'!H55 -> 1800000 | H10: ='#40'!H56 -> 300000 | I10: =IF($B10>0,'원가항목별(집계)'!I$38*$P10/$P$37,0) -> 58844.56 | J10: =SUM(D10:I10) -> 24198845 | K10: =IF(B10>0,'원가항목별(집계)'!I$34*P10/P$37,0) -> 4984134.2 | L10: =IF($B10>0,'원가항목별(집계)'!I$39*$P10/$P$37,0) -> 42407.313 | M10: ='#40'!H60+'#40'!H61 -> 0 | N10: =SUM(J10:M10) -> 29225386 | P10: =D10+E10+F10+G10+H10+M10 -> 24140000
A11: =IF(B11>0,A10+1,"") -> 5 | B11: ='#50'!C$1 -> I/B선별 | C11: 1식 | D11: ='#50'!H44 -> 19710000 | E11: ='#50'!H45 -> 0 | F11: ='#50'!H46+'#50'!H47+'#50'!H48+'#50'!H52 -> 21500000 | G11: ='#50'!H49+'#50'!H50 -> 2700000 | H11: ='#50'!H51 -> 300000 | I11: =IF($B11>0,'원가항목별(집계)'!I$38*$P11/$P$37,0) -> 107767.94 | J11: =SUM(D11:I11) -> 44317768 | K11: =IF(B11>0,'원가항목별(집계)'!I$34*P11/P$37,0) -> 9127944.3 | L11: =IF($B11>0,'원가항목별(집계)'!I$39*$P11/$P$37,0) -> 77664.76 | M11: ='#50'!H55+'#50'!H56 -> 0 | N11: =SUM(J11:M11) -> 53523377 | P11: =D11+E11+F11+G11+H11+M11 -> 44210000
A12: =IF(B12>0,A11+1,"") -> 6 | B12: ='#60'!C$1 -> 마킹 | C12: 1식 | D12: ='#60'!H47 -> 67090000 | E12: ='#60'!H48 -> 0 | F12: ='#60'!H49+'#60'!H50+'#60'!H51+'#60'!H55 -> 14750000 | G12: ='#60'!H52+'#60'!H53 -> 1800000 | H12: ='#60'!H54 -> 600000 | I12: =IF($B12>0,'원가항목별(집계)'!I$38*$P12/$P$37,0) -> 205346.55 | J12: =SUM(D12:I12) -> 84445347 | K12: =IF(B12>0,'원가항목별(집계)'!I$34*P12/P$37,0) -> 17392853 | L12: =IF($B12>0,'원가항목별(집계)'!I$39*$P12/$P$37,0) -> 147986.41 | M12: ='#60'!H58+'#60'!H59 -> 0 | N12: =SUM(J12:M12) -> 1.0198619e+08 | P12: =D12+E12+F12+G12+H12+M12 -> 84240000
A13: =IF(B13>0,A12+1,"") -> 7 | B13: ='#70'!C$1 -> I/B D/COVER압입 | C13: 1식 | D13: ='#70'!H57 -> 51560000 | E13: ='#70'!H58 -> 0 | F13: ='#70'!H59+'#70'!H60+'#70'!H61+'#70'!H65 -> 17500000 | G13: ='#70'!H62+'#70'!H63 -> 1800000 | H13: ='#70'!H64 -> 300000 | I13: =IF($B13>0,'원가항목별(집계)'!I$38*$P13/$P$37,0) -> 173462.26 | J13: =SUM(D13:I13) -> 71333462 | K13: =IF(B13>0,'원가항목별(집계)'!I$34*P13/P$37,0) -> 14692253 | L13: =IF($B13>0,'원가항목별(집계)'!I$39*$P13/$P$37,0) -> 125008.47 | M13: ='#70'!H68+'#70'!H69 -> 0 | N13: =SUM(J13:M13) -> 86150724 | P13: =D13+E13+F13+G13+H13+M13 -> 71160000
A14: =IF(B14>0,A13+1,"") -> 8 | B14: ='#80'!C$1 -> 반전및 B/P압입 | C14: 1식 | D14: ='#80'!H66 -> 64860000 | E14: ='#80'!H67 -> 0 | F14: ='#80'!H68+'#80'!H69+'#80'!H70+'#80'!H74 -> 17500000 | G14: ='#80'!H71+'#80'!H72 -> 1800000 | H14: ='#80'!H73 -> 300000 | I14: =IF($B14>0,'원가항목별(집계)'!I$38*$P14/$P$37,0) -> 205882.83 | J14: =SUM(D14:I14) -> 84665883 | K14: =IF(B14>0,'원가항목별(집계)'!I$34*P14/P$37,0) -> 17438276 | L14: =IF($B14>0,'원가항목별(집계)'!I$39*$P14/$P$37,0) -> 148372.89 | M14: ='#80'!H77+'#80'!H78 -> 0 | N14: =SUM(J14:M14) -> 1.0225253e+08 | P14: =D14+E14+F14+G14+H14+M14 -> 84460000
A15: =IF(B15>0,A14+1,"") -> 9 | B15: ='#90'!C$1 -> I/R공급 및 방향정렬 | C15: 1식 | D15: ='#90'!H52 -> 38670000 | E15: ='#90'!H53 -> 0 | F15: ='#90'!H54+'#90'!H55+'#90'!H56+'#90'!H60 -> 17500000 | G15: ='#90'!H57+'#90'!H58 -> 1800000 | H15: ='#90'!H59 -> 300000 | I15: =IF($B15>0,'원가항목별(집계)'!I$38*$P15/$P$37,0) -> 142041.11 | J15: =SUM(D15:I15) -> 58412041 | K15: =IF(B15>0,'원가항목별(집계)'!I$34*P15/P$37,0) -> 12030882 | L15: =IF($B15>0,'원가항목별(집계)'!I$39*$P15/$P$37,0) -> 102364.3 | M15: ='#90'!H63+'#90'!H64 -> 0 | N15: =SUM(J15:M15) -> 70545288 | P15: =D15+E15+F15+G15+H15+M15 -> 58270000
A16: =IF(B16>0,A15+1,"") -> 10 | B16: ='#100'!C$1 -> I/B볼 자동 공급 | C16: 1식 | D16: ='#100'!H49 -> 29870000 | E16: ='#100'!H50 -> 0 | F16: ='#100'!H51+'#100'!H52+'#100'!H53+'#100'!H57 -> 16250000 | G16: ='#100'!H54+'#100'!H55 -> 1800000 | H16: ='#100'!H56 -> 600000 | I16: =IF($B16>0,'원가항목별(집계)'!I$38*$P16/$P$37,0) -> 118274.15 | J16: =SUM(D16:I16) -> 48638274 | K16: =IF(B16>0,'원가항목별(집계)'!I$34*P16/P$37,0) -> 10017821 | L16: =IF($B16>0,'원가항목별(집계)'!I$39*$P16/$P$37,0) -> 85236.24 | M16: ='#100'!H60+'#100'!H61 -> 0 | N16: =SUM(J16:M16) -> 58741331 | P16: =D16+E16+F16+G16+H16+M16 -> 48520000
A17: =IF(B17>0,A16+1,"") -> 11 | B17: ='#110'!C$1 -> I/B SUB 자동 조립 | C17: 1식 | D17: ='#110'!H57 -> 25010000 | E17: ='#110'!H58 -> 0 | F17: ='#110'!H59+'#110'!H60+'#110'!H61+'#110'!H65 -> 22500000 | G17: ='#110'!H62+'#110'!H63 -> 3000000 | H17: ='#110'!H64 -> 1200000 | I17: =IF($B17>0,'원가항목별(집계)'!I$38*$P17/$P$37,0) -> 126050.22 | J17: =SUM(D17:I17) -> 51836050 | K17: =IF(B17>0,'원가항목별(집계)'!I$34*P17/P$37,0) -> 10676453 | L17: =IF($B17>0,'원가항목별(집계)'!I$39*$P17/$P$37,0) -> 90840.189 | M17: ='#110'!H68+'#110'!H69 -> 0 | N17: =SUM(J17:M17) -> 62603344 | P17: =D17+E17+F17+G17+H17+M17 -> 51710000
A18: =IF(B18>0,A17+1,"") -> 12 | B18: ='#120'!C$1 -> I/B 스토퍼링 조립 | C18: 1식 | D18: ='#120'!H51 -> 42720000 | E18: ='#120'!H52 -> 0 | F18: ='#120'!H53+'#120'!H54+'#120'!H55+'#120'!H59 -> 14750000 | G18: ='#120'!H56+'#120'!H57 -> 1800000 | H18: ='#120'!H58 -> 900000 | I18: =IF($B18>0,'원가항목별(집계)'!I$38*$P18/$P$37,0) -> 146672.63 | J18: =SUM(D18:I18) -> 60316673 | K18: =IF(B18>0,'원가항목별(집계)'!I$34*P18/P$37,0) -> 12423171 | L18: =IF($B18>0,'원가항목별(집계)'!I$39*$P18/$P$37,0) -> 105702.07 | M18: ='#120'!H62+'#120'!H63 -> 0 | N18: =SUM(J18:M18) -> 72845546 | P18: =D18+E18+F18+G18+H18+M18 -> 60170000
A19: =IF(B19>0,A18+1,"") -> 13 | B19: ='#130'!C$1 -> I/B 로더테스트 | C19: 1식 | D19: ='#130'!H49 -> 22890000 | E19: ='#130'!H50 -> 0 | F19: ='#130'!H51+'#130'!H52+'#130'!H53+'#130'!H57 -> 22750000 | G19: ='#130'!H54+'#130'!H55 -> 1800000 | H19: ='#130'!H56 -> 300000 | I19: =IF($B19>0,'원가항목별(집계)'!I$38*$P19/$P$37,0) -> 116372.8 | J19: =SUM(D19:I19) -> 47856373 | K19: =IF(B19>0,'원가항목별(집계)'!I$34*P19/P$37,0) -> 9856775.8 | L19: =IF($B19>0,'원가항목별(집계)'!I$39*$P19/$P$37,0) -> 83865.995 | M19: ='#130'!H60+'#130'!H61 -> 0 | N19: =SUM(J19:M19) -> 57797015 | P19: =D19+E19+F19+G19+H19+M19 -> 47740000
A20: =IF(B20>0,A19+1,"") -> 14 | B20: ='#140'!C$1 -> I/B 그리스 주입 | C20: 1식 | D20: ='#140'!H40 -> 44040000 | E20: ='#140'!H41 -> 0 | F20: ='#140'!H42+'#140'!H43+'#140'!H44+'#140'!H48 -> 17500000 | G20: ='#140'!H45+'#140'!H46 -> 1800000 | H20: ='#140'!H47 -> 300000 | I20: =IF($B20>0,'원가항목별(집계)'!I$38*$P20/$P$37,0) -> 155131.23 | J20: =SUM(D20:I20) -> 63795131 | K20: =IF(B20>0,'원가항목별(집계)'!I$34*P20/P$37,0) -> 13139615 | L20: =IF($B20>0,'원가항목별(집계)'!I$39*$P20/$P$37,0) -> 111797.9 | M20: ='#140'!H51+'#140'!H52 -> 0 | N20: =SUM(J20:M20) -> 77046544 | P20: =D20+E20+F20+G20+H20+M20 -> 63640000
A21: =IF(B21>0,A20+1,"") -> 15 | B21: ='#150'!C$1 -> I/B 그리스주입(스플라인) | C21: 1식 | D21: ='#150'!H43 -> 19120000 | E21: ='#150'!H44 -> 0 | F21: ='#150'!H45+'#150'!H46+'#150'!H47+'#150'!H51 -> 17500000 | G21: ='#150'!H48+'#150'!H49 -> 1800000 | H21: ='#150'!H50 -> 300000 | I21: =IF($B21>0,'원가항목별(집계)'!I$38*$P21/$P$37,0) -> 94385.309 | J21: =SUM(D21:I21) -> 38814385 | K21: =IF(B21>0,'원가항목별(집계)'!I$34*P21/P$37,0) -> 7994435.7 | L21: =IF($B21>0,'원가항목별(집계)'!I$39*$P21/$P$37,0) -> 68020.346 | M21: ='#150'!H54+'#150'!H55 -> 0 | N21: =SUM(J21:M21) -> 46876841 | P21: =D21+E21+F21+G21+H21+M21 -> 38720000
A22: =IF(B22>0,A21+1,"") -> 16 | B22: ='#160'!C$1 -> 비젼검사 | C22: 1식 | D22: ='#160'!H49 -> 40730000 | E22: ='#160'!H50 -> 0 | F22: ='#160'!H51+'#160'!H52+'#160'!H53+'#160'!H57 -> 16250000 | G22: ='#160'!H54+'#160'!H55 -> 1800000 | H22: ='#160'!H56 -> 900000 | I22: =IF($B22>0,'원가항목별(집계)'!I$38*$P22/$P$37,0) -> 145478.18 | J22: =SUM(D22:I22) -> 59825478 | K22: =IF(B22>0,'원가항목별(집계)'!I$34*P22/P$37,0) -> 12322002 | L22: =IF($B22>0,'원가항목별(집계)'!I$39*$P22/$P$37,0) -> 104841.28 | M22: ='#160'!H60+'#160'!H61 -> 0 | N22: =SUM(J22:M22) -> 72252322 | P22: =D22+E22+F22+G22+H22+M22 -> 59680000
A23: =IF(B23>0,A22+1,"") -> 17 | B23: ='#170'!C$1 -> 배출/반전 | C23: 1식 | D23: ='#170'!H54 -> 60970000 | E23: ='#170'!H55 -> 0 | F23: ='#170'!H56+'#170'!H57+'#170'!H58+'#170'!H62 -> 17250000 | G23: ='#170'!H59+'#170'!H60 -> 1800000 | H23: ='#170'!H61 -> 300000 | I23: =IF($B23>0,'원가항목별(집계)'!I$38*$P23/$P$37,0) -> 195791.01 | J23: =SUM(D23:I23) -> 80515791 | K23: =IF(B23>0,'원가항목별(집계)'!I$34*P23/P$37,0) -> 16583499 | L23: =IF($B23>0,'원가항목별(집계)'!I$39*$P23/$P$37,0) -> 141100.06 | M23: ='#170'!H65+'#170'!H66 -> 0 | N23: =SUM(J23:M23) -> 97240390 | P23: =D23+E23+F23+G23+H23+M23 -> 80320000
A24: =IF(B24>0,A23+1,"") -> 18 | B24: ='#180'!C$1 -> MAIN CONVEYOR | C24: 1식 | D24: ='#180'!H57 -> 62530000 | E24: ='#180'!H58 -> 0 | F24: ='#180'!H59+'#180'!H60+'#180'!H61+'#180'!H65 -> 8000000 | G24: ='#180'!H62+'#180'!H63 -> 1500000 | H24: ='#180'!H64 -> 0 | I24: =IF($B24>0,'원가항목별(집계)'!I$38*$P24/$P$37,0) -> 175583 | J24: =SUM(D24:I24) -> 72205583 | K24: =IF(B24>0,'원가항목별(집계)'!I$34*P24/P$37,0) -> 14871880 | L24: =IF($B24>0,'원가항목별(집계)'!I$39*$P24/$P$37,0) -> 126536.82 | M24: ='#180'!H68+'#180'!H69 -> 0 | N24: =SUM(J24:M24) -> 87204000 | P24: =D24+E24+F24+G24+H24+M24 -> 72030000
A25: =IF(B25>0,A24+1,"") -> 19 | B25: ='#190'!C$1 -> PALLETS | C25: 1식 | D25: ='#190'!H51 -> 28800000 | E25: ='#190'!H52 -> 0 | F25: ='#190'!H53+'#190'!H54+'#190'!H55+'#190'!H59 -> 5250000 | G25: ='#190'!H56+'#190'!H57 -> 900000 | H25: ='#190'!H58 -> 0 | I25: =IF($B25>0,'원가항목별(집계)'!I$38*$P25/$P$37,0) -> 85195.417 | J25: =SUM(D25:I25) -> 35035195 | K25: =IF(B25>0,'원가항목별(집계)'!I$34*P25/P$37,0) -> 7216051.8 | L25: =IF($B25>0,'원가항목별(집계)'!I$39*$P25/$P$37,0) -> 61397.497 | M25: ='#190'!H62+'#190'!H63 -> 0 | N25: =SUM(J25:M25) -> 42312645 | P25: =D25+E25+F25+G25+H25+M25 -> 34950000
A26: =IF(B26>0,A25+1,"") -> 20 | B26: ='#200'!C$1 -> LMS SYSTEM | C26: 1식 | D26: ='#200'!H49 -> 30000000 | E26: ='#200'!H50 -> 0 | F26: ='#200'!H51+'#200'!H52+'#200'!H53+'#200'!H57 -> 0 | G26: ='#200'!H54+'#200'!H55 -> 0 | H26: ='#200'!H56 -> 0 | I26: =IF($B26>0,'원가항목별(집계)'!I$38*$P26/$P$37,0) -> 73129.114 | J26: =SUM(D26:I26) -> 30073129 | K26: =IF(B26>0,'원가항목별(집계)'!I$34*P26/P$37,0) -> 6194035.9 | L26: =IF($B26>0,'원가항목별(집계)'!I$39*$P26/$P$37,0) -> 52701.714 | M26: ='#200'!H60+'#200'!H61 -> 0 | N26: =SUM(J26:M26) -> 36319867 | P26: =D26+E26+F26+G26+H26+M26 -> 30000000
A27: =IF(B27>0,A26+1,"") -> 21 | B27: ='#210'!C$1 -> RFID | C27: 1식 | D27: ='#210'!H43 -> 12000000 | E27: ='#210'!H44 -> 0 | F27: ='#210'!H45+'#210'!H46+'#210'!H47+'#210'!H51 -> 0 | G27: ='#210'!H48+'#210'!H49 -> 0 | H27: ='#210'!H50 -> 0 | I27: =IF($B27>0,'원가항목별(집계)'!I$38*$P27/$P$37,0) -> 29251.645 | J27: =SUM(D27:I27) -> 12029252 | K27: =IF(B27>0,'원가항목별(집계)'!I$34*P27/P$37,0) -> 2477614.4 | L27: =IF($B27>0,'원가항목별(집계)'!I$39*$P27/$P$37,0) -> 21080.686 | M27: ='#210'!H54+'#210'!H55 -> 0 | N27: =SUM(J27:M27) -> 14527947 | P27: =D27+E27+F27+G27+H27+M27 -> 12000000
A28: =IF(B28>0,A27+1,"") | B28: ='#220'!C$1 -> 0 | C28: 1식 | D28: ='#220'!H43 -> 0 | E28: ='#220'!H44 -> 0 | F28: ='#220'!H45+'#220'!H46+'#220'!H47+'#220'!H51 -> 0 | G28: ='#220'!H48+'#220'!H49 -> 0 | H28: ='#220'!H50 -> 0 | I28: =IF($B28>0,'원가항목별(집계)'!I$38*$P28/$P$37,0) -> 0 | J28: =SUM(D28:I28) -> 0 | K28: =IF(B28>0,'원가항목별(집계)'!I$34*P28/P$37,0) -> 0 | L28: =IF($B28>0,'원가항목별(집계)'!I$39*$P28/$P$37,0) -> 0 | M28: ='#220'!H54+'#220'!H55 -> 0 | N28: =SUM(J28:M28) -> 0 | P28: =D28+E28+F28+G28+H28+M28 -> 0
A29: =IF(B29>0,A28+1,"") | B29: ='#230'!C$1 -> 0 | C29: 1식 | D29: ='#230'!H49 -> 0 | E29: ='#230'!H50 -> 0 | F29: ='#230'!H51+'#230'!H52+'#230'!H53+'#230'!H57 -> 0 | G29: ='#230'!H54+'#230'!H55 -> 0 | H29: ='#230'!H56 -> 0 | I29: =IF($B29>0,'원가항목별(집계)'!I$38*$P29/$P$37,0) -> 0 | J29: =SUM(D29:I29) -> 0 | K29: =IF(B29>0,'원가항목별(집계)'!I$34*P29/P$37,0) -> 0 | L29: =IF($B29>0,'원가항목별(집계)'!I$39*$P29/$P$37,0) -> 0 | M29: ='#230'!H60+'#230'!H61 -> 0 | N29: =SUM(J29:M29) -> 0 | P29: =D29+E29+F29+G29+H29+M29 -> 0
A30: =IF(B30>0,A29+1,"") | B30: ='#240'!C$1 -> 0 | C30: 1식 | D30: ='#240'!H54 -> 0 | E30: ='#240'!H55 -> 0 | F30: ='#240'!H56+'#240'!H57+'#240'!H58+'#240'!H62 -> 0 | G30: ='#240'!H59+'#240'!H60 -> 0 | H30: ='#240'!H61 -> 0 | I30: =IF($B30>0,'원가항목별(집계)'!I$38*$P30/$P$37,0) -> 0 | J30: =SUM(D30:I30) -> 0 | K30: =IF(B30>0,'원가항목별(집계)'!I$34*P30/P$37,0) -> 0 | L30: =IF($B30>0,'원가항목별(집계)'!I$39*$P30/$P$37,0) -> 0 | M30: ='#240'!H65+'#240'!H66 -> 0 | N30: =SUM(J30:M30) -> 0 | P30: =D30+E30+F30+G30+H30+M30 -> 0
A31: =IF(B31>0,A30+1,"") | B31: ='#250'!C$1 -> 0 | C31: 1식 | D31: ='#250'!H41 -> 0 | E31: ='#250'!H42 -> 0 | F31: ='#250'!H43+'#250'!H44+'#250'!H45+'#250'!H49 -> 0 | G31: ='#250'!H46+'#250'!H47 -> 0 | H31: ='#250'!H48 -> 0 | I31: =IF($B31>0,'원가항목별(집계)'!I$38*$P31/$P$37,0) -> 0 | J31: =SUM(D31:I31) -> 0 | K31: =IF(B31>0,'원가항목별(집계)'!I$34*P31/P$37,0) -> 0 | L31: =IF($B31>0,'원가항목별(집계)'!I$39*$P31/$P$37,0) -> 0 | M31: ='#250'!H52+'#250'!H53 -> 0 | N31: =SUM(J31:M31) -> 0 | P31: =D31+E31+F31+G31+H31+M31 -> 0
A32: =IF(B32>0,A31+1,"") | B32: ='#260'!C$1 -> 0 | C32: 1식 | D32: ='#260'!H49 -> 0 | E32: ='#260'!H50 -> 0 | F32: ='#260'!H51+'#260'!H52+'#260'!H53+'#260'!H57 -> 0 | G32: ='#260'!H54+'#260'!H55 -> 0 | H32: ='#260'!H56 -> 0 | I32: =IF($B32>0,'원가항목별(집계)'!I$38*$P32/$P$37,0) -> 0 | J32: =SUM(D32:I32) -> 0 | K32: =IF(B32>0,'원가항목별(집계)'!I$34*P32/P$37,0) -> 0 | L32: =IF($B32>0,'원가항목별(집계)'!I$39*$P32/$P$37,0) -> 0 | M32: ='#260'!H60+'#260'!H61 -> 0 | N32: =SUM(J32:M32) -> 0 | P32: =D32+E32+F32+G32+H32+M32 -> 0
A33: =IF(B33>0,A32+1,"") | B33: ='#270'!C$1 -> 0 | C33: 1식 | D33: ='#270'!H49 -> 0 | E33: ='#270'!H50 -> 0 | F33: ='#270'!H51+'#270'!H52+'#270'!H53+'#270'!H57 -> 0 | G33: ='#270'!H54+'#270'!H55 -> 0 | H33: ='#270'!H56 -> 0 | I33: =IF($B33>0,'원가항목별(집계)'!I$38*$P33/$P$37,0) -> 0 | J33: =SUM(D33:I33) -> 0 | K33: =IF(B33>0,'원가항목별(집계)'!I$34*P33/P$37,0) -> 0 | L33: =IF($B33>0,'원가항목별(집계)'!I$39*$P33/$P$37,0) -> 0 | M33: ='#270'!H60+'#270'!H61 -> 0 | N33: =SUM(J33:M33) -> 0 | P33: =D33+E33+F33+G33+H33+M33 -> 0
A34: =IF(B34>0,A33+1,"") | B34: ='#280'!C$1 -> 0 | C34: 1식 | D34: ='#280'!H49 -> 0 | E34: ='#280'!H50 -> 0 | F34: ='#280'!H51+'#280'!H52+'#280'!H53+'#280'!H57 -> 0 | G34: ='#280'!H54+'#280'!H55 -> 0 | H34: ='#280'!H56 -> 0 | I34: =IF($B34>0,'원가항목별(집계)'!I$38*$P34/$P$37,0) -> 0 | J34: =SUM(D34:I34) -> 0 | K34: =IF(B34>0,'원가항목별(집계)'!I$34*P34/P$37,0) -> 0 | L34: =IF($B34>0,'원가항목별(집계)'!I$39*$P34/$P$37,0) -> 0 | M34: ='#280'!H60+'#280'!H61 -> 0 | N34: =SUM(J34:M34) -> 0 | P34: =D34+E34+F34+G34+H34+M34 -> 0
A35: =IF(B35>0,A34+1,"") | B35: ='#290'!C$1 -> 0 | C35: 1식 | D35: ='#290'!H49 -> 0 | E35: ='#290'!H50 -> 0 | F35: ='#290'!H51+'#290'!H52+'#290'!H53+'#290'!H57 -> 0 | G35: ='#290'!H54+'#290'!H55 -> 0 | H35: ='#290'!H56 -> 0 | I35: =IF($B35>0,'원가항목별(집계)'!I$38*$P35/$P$37,0) -> 0 | J35: =SUM(D35:I35) -> 0 | K35: =IF(B35>0,'원가항목별(집계)'!I$34*P35/P$37,0) -> 0 | L35: =IF($B35>0,'원가항목별(집계)'!I$39*$P35/$P$37,0) -> 0 | M35: ='#290'!H60+'#290'!H61 -> 0 | N35: =SUM(J35:M35) -> 0 | P35: =D35+E35+F35+G35+H35+M35 -> 0
A36: =IF(B36>0,A35+1,"") | B36: ='#300'!C$1 -> 0 | C36: 1식 | D36: ='#300'!H49 -> 0 | E36: ='#300'!H50 -> 0 | F36: ='#300'!H51+'#300'!H52+'#300'!H53+'#300'!H57 -> 0 | G36: ='#300'!H54+'#300'!H55 -> 0 | H36: ='#300'!H56 -> 0 | I36: =IF($B36>0,'원가항목별(집계)'!I$38*$P36/$P$37,0) -> 0 | J36: =SUM(D36:I36) -> 0 | K36: =IF(B36>0,'원가항목별(집계)'!I$34*P36/P$37,0) -> 0 | L36: =IF($B36>0,'원가항목별(집계)'!I$39*$P36/$P$37,0) -> 0 | M36: ='#300'!H60+'#300'!H61 -> 0 | N36: =SUM(J36:M36) -> 0 | P36: =D36+E36+F36+G36+H36+M36 -> 0
A37: 합 계 | D37: =SUM(D7:D36) -> 853650000 | E37: =SUM(E7:E36) -> 0 | F37: =SUM(F7:F36) -> 327250000 | G37: =SUM(G7:G36) -> 40800000 | H37: =SUM(H7:H36) -> 9000000 | I37: =SUM(I7:I36) -> 3000000 | J37: =SUM(D37:I37) -> 1233700000 | K37: =SUM(K7:K36) -> 254100000 | L37: =SUM(L7:L36) -> 2162000 | M37: =SUM(M7:M36) -> 0 | N37: =SUM(N7:N36) -> 1.489962e+09 | P37: =SUM(P7:P36) -> 1230700000
D38: =IF(D37=0,"",D37/$N37) -> 0.57293407 | E38: =IF(E37=0,"",E37/$N37) | F38: =IF(F37=0,"",F37/$N37) -> 0.21963647 | G38: =IF(G37=0,"",G37/$N37) -> 0.027383249 | H38: =IF(H37=0,"",H37/$N37) -> 0.0060404225 | I38: =IF(I37=0,"",I37/$N37) -> 0.0020134742 | J38: =SUM(D38:I38) -> 0.82800769 | K38: =IF(K37=0,"",K37/$N37) -> 0.17054126 | L38: =IF(L37=0,"",L37/$N37) -> 0.0014510437 | M38: =IF(M37=0,"",M37/$N37) | N38: =IF(N37=0,"",N37/$N37) -> 1
A39: 주) 전기비용은 턴키장비의 공통비용으로서 총 전기비용을 단위장비별 기계금액의 비율에 따라 배분함
N40: =IF('원가항목별(집계)'!I42='단위공사별(집계)'!N37,"","DATA오류입니다!")

Sheet 전기
B1: □ 전기부문: | C1: 전기부문(공통) | I1: (첨부)
A2: 구분 | C2: 품 명 | D2: 규격 | E2: 단위 | F2: 수량 | G2: 단가(원) | H2: 금액(원) | I2: 原MAKER
A3: 자 재 비 | B3: 철자재 | C3: 제작품 | D3: 콘트롤박스등 | E3: 식 | F3: 1 | G3: 6300000 | H3: =IF(F3=0,G3,G3*F3) -> 6300000
H4: =IF(F4=0,G4,G4*F4) -> 0
H5: =IF(F5=0,G5,G5*F5) -> 0
H6: =IF(F6=0,G6,G6*F6) -> 0
H7: =IF(F7=0,G7,G7*F7) -> 0
H8: =IF(F8=0,G8,G8*F8) -> 0
H9: =SUM(H3:H8) -> 6300000
B10: 설치/해체/ | H10: =IF(F10=0,G10,G10*F10) -> 0
B11: 시운전 공사 | H11: =IF(F11=0,G11,G11*F11) -> 0
B12: 자재 | H12: =IF(F12=0,G12,G12*F12) -> 0
H13: =IF(F13=0,G13,G13*F13) -> 0
H14: =IF(F14=0,G14,G14*F14) -> 0
H15: =IF(F15=0,G15,G15*F15) -> 0
H16: =SUM(H10:H15) -> 0
B17: 전기자재 | C17: ■PLC구매품 | D17: PLC등 | E17: 식 | F17: 1 | G17: 98000000 | H17: =IF(F17=0,G17,G17*F17) -> 98000000
H18: =IF(F18=0,G18,G18*F18) -> 0
C19: ■PC구매품 | D19: PC등 | E19: 식 | F19: 1 | G19: 20000000 | H19: =IF(F19=0,G19,G19*F19) -> 20000000
C20: ■PC P/G | E20: 식 | F20: 1 | G20: 40000000 | H20: =IF(F20=0,G20,G20*F20) -> 40000000
H21: =IF(F21=0,G21,G21*F21) -> 0
H23: =IF(F23=0,G23,G23*F23) -> 0
H24: =IF(F24=0,G24,G24*F24) -> 0
C25: 기타 잡자재 | E25: 식 | F25: 1 | G25: 2000000 | H25: =IF(F25=0,G25,G25*F25) -> 2000000
H26: =SUM(H17:H25) -> 160000000
B27: 자재비 소계 | H27: =SUM(H26,H9,H16) -> 166300000
A28: 노 무 비 | B28: 기존설비 철거 | E28: M/D | F28: 10 | G28: 250000 | H28: =F28*G28 -> 2500000
B29: 전기 설계/프로그램 | E29: M/D | F29: 80 | G29: 300000 | H29: =F29*G29 -> 24000000
B30: 전기 제작 | E30: M/D | F30: 80 | G30: 250000 | H30: =F30*G30 -> 20000000
B31: 전기 조립 | E31: M/D | F31: 80 | G31: 250000 | H31: =F31*G31 -> 20000000
B32: 전기 설치 | E32: M/D | F32: 20 | G32: 300000 | H32: =F32*G32 -> 6000000
B33: 전기 시운전 | E33: M/D | F33: 30 | G33: 300000 | H33: =F33*G33 -> 9000000
B34: 전기 양산대응 | E34: M/D | F34: 21 | G34: 300000 | H34: =F34*G34 -> 6300000
B35: 노무비 소계 | H35: =SUM(H28:H34) -> 87800000
B36: 운반및중장비사용,표준안전관리비 | G36: * 기계부문에 포함시킴 | H36: 0
B37: 일반관리비 | H37: 0
B38: 이 윤 | H38: 0
B39: 합 계 | H39: =H27+H35+H36+H37+H38 -> 254100000

Sheet #10
B1: □ 단위공사명(전기제외): | C1: I/R선별,적재,공급 | I1: (첨부)
A2: 구분 | C2: 품 명 | D2: 규격 | E2: 단위 | F2: 수량 | G2: 단가(원) | H2: 금액(원) | I2: 原MAKER
A3: 자 재 비 | B3: 철자재 | C3: ■BASE | D3: 제관,가공 | E3: 식 | F3: 1 | G3: 2000000 | H3: =IF(F3=0,G3,G3*F3) -> 2000000
C4: ■FRAME | D4: 제관,가공 | E4: 식 | F4: 1 | G4: 1000000 | H4: =IF(F4=0,G4,G4*F4) -> 1000000
C5: ■상측 COVER | D5: 제관,가공 | E5: 식 | F5: 1 | G5: 1000000 | H5: =IF(F5=0,G5,G5*F5) -> 1000000
C6: ■OP POST | E6: 식 | F6: 1 | G6: 600000 | H6: =IF(F6=0,G6,G6*F6) -> 600000
C7: ■I/R선별 | E7: 식 | F7: 2 | G7: 5000000 | H7: =IF(F7=0,G7,G7*F7) -> 10000000
C8: ■I/R적재랙 | E8: 식 | F8: 2 | G8: 2000000 | H8: =IF(F8=0,G8,G8*F8) -> 4000000
C9: ■I/R공급 | D9: 파레타이징 | E9: 식 | F9: 2 | G9: 19500000 | H9: 0
C10: ■CAGE공급 | D10: 자재랙 | E10: 식 | F10: 2 | G10: 1000000 | H10: =IF(F10=0,G10,G10*F10) -> 2000000
E11: 식 | H11: =IF(F11=0,G11,G11*F11) -> 0
E12: 식 | H12: =IF(F12=0,G12,G12*F12) -> 0
E13: 식 | H13: =IF(F13=0,G13,G13*F13) -> 0
E14: 식 | H14: =IF(F14=0,G14,G14*F14) -> 0
E15: 식 | H15: =IF(F15=0,G15,G15*F15) -> 0
E16: 식 | H16: =IF(F16=0,G16,G16*F16) -> 0
E17: 식 | H17: =IF(F17=0,G17,G17*F17) -> 0
C18: 기타 | E18: 식 | F18: 2 | G18: 500000 | H18: 0
H19: =SUM(H3:H18) -> 20600000
B20: 설치/해체/시운전 | H20: =IF(F20=0,G20,G20*F20) -> 0
B21: 공사 관련 자재 | H21: =IF(F21=0,G21,G21*F21) -> 0
H22: =SUM(H20:H21) -> 0
B23: 구매품 | C23: ■I/R선별(2대) | H23: =IF(F23=0,G23,G23*F23) -> 0
B24: (유공압품외) | C24: LVDT | E24: EA | F24: 12 | G24: 1800000 | H24: =IF(F24=0,G24,G24*F24) -> 21600000
C25: CYL'(측정부) | D25: 공압 | E25: EA | F25: 12 | G25: 100000 | H25: =IF(F25=0,G25,G25*F25) -> 1200000
C26: LM GUIDE(측정부) | D26: THK | E26: EA | F26: 24 | G26: 100000 | H26: =IF(F26=0,G26,G26*F26) -> 2400000
C27: 상측상하 1축 | D27: LM2EA,CYL',압쇼버,센스,케이블베어등 | E27: 식 | F27: 2 | G27: 2000000 | H27: =IF(F27=0,G27,G27*F27) -> 4000000
C28: 하측상하 1축 | D28: LM3EA,CYL',압쇼버,센스,케이블베어등 | E28: 식 | F28: 2 | G28: 2000000 | H28: =IF(F28=0,G28,G28*F28) -> 4000000
C29: 하측회전 | D29: 서보1식 | E29: 식 | F29: 2 | G29: 3500000 | H29: =IF(F29=0,G29,G29*F29) -> 7000000
C30: PROXIMITY SENSOR | E30: EA | F30: 32 | G30: 40000 | H30: =IF(F30=0,G30,G30*F30) -> 1280000
C31: 소재 감지 센스 | E31: EA | F31: 2 | G31: 100000 | H31: =IF(F31=0,G31,G31*F31) -> 200000
C32: 일반구입물 | E32: 식 | F32: 2 | G32: 300000 | H32: =IF(F32=0,G32,G32*F32) -> 600000
C33: 라이트커튼 | E33: 식 | F33: 2 | G33: 1000000 | H33: =IF(F33=0,G33,G33*F33) -> 2000000
C34: 기타 | E34: 식 | F34: 2 | G34: 1500000 | H34: =IF(F34=0,G34,G34*F34) -> 3000000
C35: ■I/R적재랙 | D35: A~F등급 | H35: =IF(F35=0,G35,G35*F35) -> 0
C36: SHUTTER CYL' | D36: 공압 | E36: EA | F36: 12 | G36: 150000 | H36: =IF(F36=0,G36,G36*F36) -> 1800000
C37: PROXIMITY SENSOR | E37: EA | F37: 24 | G37: 40000 | H37: =IF(F37=0,G37,G37*F37) -> 960000
C38: 소재 감지 센스 | E38: EA | F38: 36 | G38: 100000 | H38: =IF(F38=0,G38,G38*F38) -> 3600000
C39: 기타 | E39: 식 | F39: 2 | G39: 1600000 | H39: =IF(F39=0,G39,G39*F39) -> 3200000
C40: ■I/R공급 | H40: =IF(F40=0,G40,G40*F40) -> 0
...

Sheet #20
B1: □ 단위공사명(전기제외): | C1: I/B선별기 | I1: (첨부)
A2: 구분 | C2: 품 명 | D2: 규격 | E2: 단위 | F2: 수량 | G2: 단가(원) | H2: 금액(원) | I2: 原MAKER
A3: 자 재 비 | B3: 철자재 | C3: ■BASE | D3: 제관,가공 | E3: 식 | F3: 1 | G3: 2000000 | H3: =IF(F3=0,G3,G3*F3) -> 2000000
C4: ■FRAME | D4: 제관,가공 | E4: 식 | F4: 1 | G4: 1500000 | H4: =IF(F4=0,G4,G4*F4) -> 1500000
C5: ■상측 COVER | D5: 제관,가공 | E5: 식 | F5: 1 | G5: 1500000 | H5: =IF(F5=0,G5,G5*F5) -> 1500000
C6: ■OP POST | E6: 식 | F6: 1 | G6: 600000 | H6: =IF(F6=0,G6,G6*F6) -> 600000
C7: ■공급 인스토커(I/B) | E7: 식 | F7: 1 | G7: 10000000 | H7: =IF(F7=0,G7,G7*F7) -> 10000000
C8: ■트랜스퍼이송장치 | H8: =IF(F8=0,G8,G8*F8) -> 0
C9: 상하이송unit | E9: 식 | F9: 1 | G9: 2000000 | H9: =IF(F9=0,G9,G9*F9) -> 2000000
C10: 전후이송unit | E10: 식 | F10: 1 | G10: 2000000 | H10: =IF(F10=0,G10,G10*F10) -> 2000000
C11: 좌우이송unit | E11: 식 | F11: 1 | G11: 2000000 | H11: =IF(F11=0,G11,G11*F11) -> 2000000
C12: 그리퍼unit | E12: 식 | F12: 1 | G12: 2000000 | H12: =IF(F12=0,G12,G12*F12) -> 2000000
C13: ■LIFTER UNIT | E13: 식 | F13: 1 | G13: 1300000 | H13: =IF(F13=0,G13,G13*F13) -> 1300000
H14: =IF(F14=0,G14,G14*F14) -> 0
H15: =IF(F15=0,G15,G15*F15) -> 0
H16: =IF(F16=0,G16,G16*F16) -> 0
C17: 기타 | E17: 식 | F17: 1 | G17: 1000000 | H17: 0
H18: =SUM(H3:H17) -> 24900000
B19: 설치/해체/시운전 | H19: =IF(F19=0,G19,G19*F19) -> 0
B20: 공사 관련 자재 | H20: =IF(F20=0,G20,G20*F20) -> 0
H21: =IF(F21=0,G21,G21*F21) -> 0
H22: =SUM(H19:H20) -> 0
B23: 구매품 | C23: ■공급 인스토커(I/B) | D23: CHINE,MOTOR등 | E23: 식 | F23: 1 | G23: 12000000 | H23: =IF(F23=0,G23,G23*F23) -> 12000000
B24: (유공압품외) | C24: ■트랜스퍼이송장치 | E24: 식 | F24: 1 | G24: 2700000 | H24: =IF(F24=0,G24,G24*F24) -> 2700000
C25: 상하이송unit | E25: 식 | F25: 1 | G25: 2450000 | H25: =IF(F25=0,G25,G25*F25) -> 2450000
C26: 전후이송unit | E26: 식 | F26: 1 | G26: 2450000 | H26: =IF(F26=0,G26,G26*F26) -> 2450000
C27: 좌우이송unit | E27: 식 | F27: 1 | G27: 2800000 | H27: =IF(F27=0,G27,G27*F27) -> 2800000
C28: 그리퍼unit | E28: 식 | F28: 5 | G28: 1200000 | H28: =IF(F28=0,G28,G28*F28) -> 6000000
C29: ■LIFTER UNIT | E29: 식 | F29: 1 | G29: 600000 | H29: =IF(F29=0,G29,G29*F29) -> 600000
H30: =IF(F30=0,G30,G30*F30) -> 0
C31: ■일반 자재류 | H31: =IF(F31=0,G31,G31*F31) -> 0
C32: F.R.L Unit | D32: AV4000 | E32: 식 | F32: 1 | G32: 350000 | H32: =IF(F32=0,G32,G32*F32) -> 350000
C33: SOL V/V | D33: VQC4201 | E33: 식 | F33: 20 | G33: 75000 | H33: =IF(F33=0,G33,G33*F33) -> 1500000
C34: Manifold | D34: VV5QC41 | E34: 식 | F34: 2 | G34: 850000 | H34: =IF(F34=0,G34,G34*F34) -> 1700000
C35: Speed Con | E35: 식 | F35: 20 | G35: 7000 | H35: =IF(F35=0,G35,G35*F35) -> 140000
C36: 배관자재 | E36: 식 | F36: 1 | G36: 100000 | H36: =IF(F36=0,G36,G36*F36) -> 100000
C37: 잡자재 | E37: 식 | F37: 1 | G37: 100000 | H37: =IF(F37=0,G37,G37*F37) -> 100000
H38: =IF(F38=0,G38,G38*F38) -> 0
C39: 기타자재 | E39: 식 | F39: 1 | G39: 500000 | H39: 0
H40: =SUM(H23:H39) -> 32890000
...

Sheet #30
B1: □ 단위공사명(전기제외): | C1: I/B CLIP조립 | I1: (첨부)
A2: 구분 | C2: 품 명 | D2: 규격 | E2: 단위 | F2: 수량 | G2: 단가(원) | H2: 금액(원) | I2: 原MAKER
A3: 자 재 비 | B3: 철자재 | C3: ■소재 공급 | E3: 식 | F3: 1 | G3: 1800000 | H3: =IF(F3=0,G3,G3*F3) -> 1800000
C4: ■클램프 UNIT | E4: 식 | F4: 1 | G4: 1000000 | H4: =IF(F4=0,G4,G4*F4) -> 1000000
C5: ■소재삽입 | E5: 식 | F5: 1 | G5: 2000000 | H5: =IF(F5=0,G5,G5*F5) -> 2000000
H6: =IF(F6=0,G6,G6*F6) -> 0
H7: =IF(F7=0,G7,G7*F7) -> 0
H8: =IF(F8=0,G8,G8*F8) -> 0
H9: =IF(F9=0,G9,G9*F9) -> 0
H10: =IF(F10=0,G10,G10*F10) -> 0
H11: =IF(F11=0,G11,G11*F11) -> 0
H12: =IF(F12=0,G12,G12*F12) -> 0
C13: 기타 가공물 | E13: 식 | F13: 1 | G13: 500000 | H13: 0
H14: =SUM(H3:H13) -> 4800000
B15: 설치/해체/시운전 | H15: =IF(F15=0,G15,G15*F15) -> 0
B16: 공사 관련 자재 | H16: =IF(F16=0,G16,G16*F16) -> 0
H17: =IF(F17=0,G17,G17*F17) -> 0
H18: =IF(F18=0,G18,G18*F18) -> 0
H19: =IF(F19=0,G19,G19*F19) -> 0
H20: =SUM(H15:H19) -> 0
B21: 구매품 | C21: ■소재 공급 | H21: =IF(F21=0,G21,G21*F21) -> 0
B22: (유공압품외) | C22: 전후이송 | D22: 실린더1축 | E22: 식 | F22: 1 | G22: 1000000 | H22: =IF(F22=0,G22,G22*F22) -> 1000000
C23: PROXIMITY SENSOR | E23: 식 | F23: 2 | G23: 40000 | H23: =IF(F23=0,G23,G23*F23) -> 80000
C24: ■클램프 UNIT | H24: =IF(F24=0,G24,G24*F24) -> 0
C25: 상하이송 | D25: 실린더1축 | E25: 식 | F25: 1 | G25: 500000 | H25: =IF(F25=0,G25,G25*F25) -> 500000
C26: 그리퍼 | E26: 식 | F26: 1 | G26: 800000 | H26: =IF(F26=0,G26,G26*F26) -> 800000
C27: PROXIMITY SENSOR | E27: 식 | F27: 4 | G27: 40000 | H27: =IF(F27=0,G27,G27*F27) -> 160000
C28: ■소재 삽입 | E28: EA | F28: 3 | G28: 40000 | H28: =IF(F28=0,G28,G28*F28) -> 120000
C29: 상하이송 | D29: 서보1축 | E29: 식 | F29: 1 | G29: 3600000 | H29: =IF(F29=0,G29,G29*F29) -> 3600000
C30: 보조상하이송 | D30: 시린더1축 | E30: 식 | F30: 1 | G30: 500000 | H30: =IF(F30=0,G30,G30*F30) -> 500000
C31: PROXIMITY SENSOR | E31: 식 | F31: 6 | G31: 40000 | H31: =IF(F31=0,G31,G31*F31) -> 240000
C32: 기타 | E32: 식 | F32: 1 | G32: 500000 | H32: =IF(F32=0,G32,G32*F32) -> 500000
H33: =IF(F33=0,G33,G33*F33) -> 0
C34: ■일반 자재류 | H34: =IF(F34=0,G34,G34*F34) -> 0
C35: F.R.L Unit | D35: AV4000 | E35: 식 | F35: 1 | G35: 350000 | H35: =IF(F35=0,G35,G35*F35) -> 350000
C36: SOL V/V | D36: VQC4201 | E36: 식 | F36: 10 | G36: 75000 | H36: =IF(F36=0,G36,G36*F36) -> 750000
C37: Manifold | D37: VV5QC41 | E37: 식 | F37: 1 | G37: 850000 | H37: =IF(F37=0,G37,G37*F37) -> 850000
C38: Speed Con | E38: 식 | F38: 20 | G38: 7000 | H38: =IF(F38=0,G38,G38*F38) -> 140000
C39: 배관자재 | E39: 식 | F39: 1 | G39: 100000 | H39: =IF(F39=0,G39,G39*F39) -> 100000
C40: 잡자재 | E40: 식 | F40: 1 | G40: 100000 | H40: =IF(F40=0,G40,G40*F40) -> 100000
...

Sheet #40
B1: □ 단위공사명(전기제외): | C1: GRV정렬 | I1: (첨부)
A2: 구분 | C2: 품 명 | D2: 규격 | E2: 단위 | F2: 수량 | G2: 단가(원) | H2: 금액(원) | I2: 原MAKER
A3: 자 재 비 | B3: 철자재 | C3: ■GRV정렬 | E3: 식 | F3: 1 | G3: 2500000 | H3: =IF(F3=0,G3,G3*F3) -> 2500000
H4: =IF(F4=0,G4,G4*F4) -> 0
H5: =IF(F5=0,G5,G5*F5) -> 0
H6: =IF(F6=0,G6,G6*F6) -> 0
H7: =IF(F7=0,G7,G7*F7) -> 0
H8: =IF(F8=0,G8,G8*F8) -> 0
H9: =IF(F9=0,G9,G9*F9) -> 0
H10: =IF(F10=0,G10,G10*F10) -> 0
C11: 기타 가공물 | E11: 식 | F11: 1 | G11: 500000 | H11: 0
H12: =SUM(H3:H11) -> 2500000
B13: 설치/해체/시운전 | H13: =IF(F13=0,G13,G13*F13) -> 0
B14: 공사 관련 자재 | H14: =IF(F14=0,G14,G14*F14) -> 0
H15: =IF(F15=0,G15,G15*F15) -> 0
H16: =IF(F16=0,G16,G16*F16) -> 0
C17: 기타자재 | H17: =IF(F17=0,G17,G17*F17) -> 0
H18: =SUM(H13:H17) -> 0
B19: 구매품 | C19: ■GRV정렬 | H19: =IF(F19=0,G19,G19*F19) -> 0
B20: (유공압품외) | C20: 상측상하1축 | E20: 식 | F20: 1 | G20: 1000000 | H20: =IF(F20=0,G20,G20*F20) -> 1000000
C21: 하측상하1축 | E21: 식 | F21: 1 | G21: 1000000 | H21: =IF(F21=0,G21,G21*F21) -> 1000000
C22: 기타 | E22: 식 | F22: 1 | G22: 500000 | H22: =IF(F22=0,G22,G22*F22) -> 500000
H23: =IF(F23=0,G23,G23*F23) -> 0
H24: =IF(F24=0,G24,G24*F24) -> 0
H25: =IF(F25=0,G25,G25*F25) -> 0
H26: =IF(F26=0,G26,G26*F26) -> 0
H27: =IF(F27=0,G27,G27*F27) -> 0
H28: =IF(F28=0,G28,G28*F28) -> 0
H29: =IF(F29=0,G29,G29*F29) -> 0
H30: =IF(F30=0,G30,G30*F30) -> 0
C31: ■일반 자재류 | H31: =IF(F31=0,G31,G31*F31) -> 0
C32: F.R.L Unit | D32: AV4000 | E32: 식 | F32: 1 | G32: 350000 | H32: =IF(F32=0,G32,G32*F32) -> 350000
C33: SOL V/V | D33: VQC4201 | E33: 식 | F33: 10 | G33: 75000 | H33: =IF(F33=0,G33,G33*F33) -> 750000
C34: Manifold | D34: VV5QC41 | E34: 식 | F34: 1 | G34: 850000 | H34: =IF(F34=0,G34,G34*F34) -> 850000
C35: Speed Con | E35: 식 | F35: 20 | G35: 7000 | H35: =IF(F35=0,G35,G35*F35) -> 140000
C36: 배관자재 | E36: 식 | F36: 1 | G36: 100000 | H36: =IF(F36=0,G36,G36*F36) -> 100000
C37: 잡자재 | E37: 식 | F37: 1 | G37: 100000 | H37: =IF(F37=0,G37,G37*F37) -> 100000
H38: =IF(F38=0,G38,G38*F38) -> 0
C39: 기타자재 | E39: 식 | F39: 1 | G39: 500000 | H39: 0
H40: =SUM(H19:H39) -> 4790000
...

Sheet #50
B1: □ 단위공사명(전기제외): | C1: I/B선별 | I1: (첨부)
A2: 구분 | C2: 품 명 | D2: 규격 | E2: 단위 | F2: 수량 | G2: 단가(원) | H2: 금액(원) | I2: 原MAKER
A3: 자 재 비 | B3: 철자재 | C3: ■O/R선별 | E3: 식 | F3: 1 | G3: 2500000 | H3: =IF(F3=0,G3,G3*F3) -> 2500000
H4: =IF(F4=0,G4,G4*F4) -> 0
H5: =IF(F5=0,G5,G5*F5) -> 0
H6: =IF(F6=0,G6,G6*F6) -> 0
H7: =IF(F7=0,G7,G7*F7) -> 0
H8: =IF(F8=0,G8,G8*F8) -> 0
H9: =IF(F9=0,G9,G9*F9) -> 0
H10: =IF(F10=0,G10,G10*F10) -> 0
H11: =IF(F11=0,G11,G11*F11) -> 0
H12: =IF(F12=0,G12,G12*F12) -> 0
C13: 기타자재 | E13: 식 | F13: 1 | G13: 500000 | H13: 0
H14: =SUM(H3:H13) -> 2500000
B15: 설치/해체/시운전 | H15: =IF(F15=0,G15,G15*F15) -> 0
B16: 공사 관련 자재 | H16: =IF(F16=0,G16,G16*F16) -> 0
H17: =IF(F17=0,G17,G17*F17) -> 0
H18: =IF(F18=0,G18,G18*F18) -> 0
C19: 기타자재 | H19: =IF(F19=0,G19,G19*F19) -> 0
H20: =SUM(H15:H19) -> 0
B21: 구매품 | C21: ■O/RACE등급선별(2대) | H21: =IF(F21=0,G21,G21*F21) -> 0
B22: (유공압품외) | C22: LVDT | E22: EA | F22: 6 | G22: 1800000 | H22: =IF(F22=0,G22,G22*F22) -> 10800000
C23: CYL'(측정부) | D23: 공압 | E23: EA | F23: 6 | G23: 60000 | H23: =IF(F23=0,G23,G23*F23) -> 360000
C24: LM GUIDE(측정부) | D24: THK | E24: EA | F24: 12 | G24: 60000 | H24: =IF(F24=0,G24,G24*F24) -> 720000
C25: 상측상하 1축 | D25: LM2EA,CYL',압쇼버,센스,케이블베어등 | E25: 식 | F25: 1 | G25: 1000000 | H25: =IF(F25=0,G25,G25*F25) -> 1000000
C26: 하측상하 1축 | D26: LM3EA,CYL',압쇼버,센스,케이블베어등 | E26: 식 | F26: 1 | G26: 1000000 | H26: =IF(F26=0,G26,G26*F26) -> 1000000
C27: PROXIMITY SENSOR | E27: EA | F27: 16 | G27: 40000 | H27: =IF(F27=0,G27,G27*F27) -> 640000
C28: 소재 감지 센스 | E28: EA | F28: 1 | G28: 100000 | H28: =IF(F28=0,G28,G28*F28) -> 100000
C29: 일반구입물 | E29: 식 | F29: 1 | G29: 300000 | H29: =IF(F29=0,G29,G29*F29) -> 300000
H30: =IF(F30=0,G30,G30*F30) -> 0
C31: ■일반 자재류 | H31: =IF(F31=0,G31,G31*F31) -> 0
C32: F.R.L Unit | D32: AV4000 | E32: 식 | F32: 1 | G32: 350000 | H32: =IF(F32=0,G32,G32*F32) -> 350000
C33: SOL V/V | D33: VQC4201 | E33: 식 | F33: 10 | G33: 75000 | H33: =IF(F33=0,G33,G33*F33) -> 750000
C34: Manifold | D34: VV5QC41 | E34: 식 | F34: 1 | G34: 850000 | H34: =IF(F34=0,G34,G34*F34) -> 850000
C35: Speed Con | E35: 식 | F35: 20 | G35: 7000 | H35: =IF(F35=0,G35,G35*F35) -> 140000
C36: 배관자재 | E36: 식 | F36: 1 | G36: 100000 | H36: =IF(F36=0,G36,G36*F36) -> 100000
C37: 잡자재 | E37: 식 | F37: 1 | G37: 100000 | H37: =IF(F37=0,G37,G37*F37) -> 100000
H38: =IF(F38=0,G38,G38*F38) -> 0
C39: 기타자재 | E39: 식 | F39: 1 | G39: 500000 | H39: 0
H40: =SUM(H21:H39) -> 17210000
...

Sheet #60
B1: □ 단위공사명(전기제외): | C1: 마킹 | I1: (첨부)
A2: 구분 | C2: 품 명 | D2: 규격 | E2: 단위 | F2: 수량 | G2: 단가(원) | H2: 금액(원) | I2: 原MAKER
A3: 자 재 비 | B3: 철자재 | C3: ■상측 COVER | D3: 제관,가공 | E3: 식 | F3: 1 | G3: 1500000 | H3: =IF(F3=0,G3,G3*F3) -> 1500000
C4: ■상하1축 | E4: 식 | F4: 1 | G4: 2500000 | H4: =IF(F4=0,G4,G4*F4) -> 2500000
C5: ■직교로봇 | E5: 식 | F5: 1 | G5: 2000000 | H5: =IF(F5=0,G5,G5*F5) -> 2000000
C6: ■그리퍼 | E6: 식 | F6: 1 | G6: 1000000 | H6: =IF(F6=0,G6,G6*F6) -> 1000000
H7: =IF(F7=0,G7,G7*F7) -> 0
H8: =IF(F8=0,G8,G8*F8) -> 0
H9: =IF(F9=0,G9,G9*F9) -> 0
H10: =IF(F10=0,G10,G10*F10) -> 0
H11: =IF(F11=0,G11,G11*F11) -> 0
C12: 기타자재 | E12: 식 | F12: 1 | G12: 500000 | H12: 0
H13: =SUM(H3:H12) -> 7000000
B14: 설치/해체/시운전 | H14: =IF(F14=0,G14,G14*F14) -> 0
B15: 공사 관련 자재 | H15: =IF(F15=0,G15,G15*F15) -> 0
H16: =IF(F16=0,G16,G16*F16) -> 0
H17: =IF(F17=0,G17,G17*F17) -> 0
C18: 기타자재 | H18: =IF(F18=0,G18,G18*F18) -> 0
H19: =SUM(H14:H18) -> 0
B20: 구매품 | C20: ■마킹기 | D20: 20w | E20: 식 | F20: 1 | G20: 35500000 | H20: =IF(F20=0,G20,G20*F20) -> 35500000 | I20: KEYENCE
B21: (유공압품외) | C21: ■상하1축 | D21: 서보 | E21: 식 | F21: 1 | G21: 3600000 | H21: =IF(F21=0,G21,G21*F21) -> 3600000
C22: ■PROXIMITY SENSOR | E22: EA | F22: 3 | G22: 40000 | H22: =IF(F22=0,G22,G22*F22) -> 120000
C23: ■직교로봇 | D23: 2축 | E23: 식 | F23: 1 | G23: 12000000 | H23: =IF(F23=0,G23,G23*F23) -> 12000000
C24: ■그리퍼 | E24: 식 | F24: 1 | G24: 1500000 | H24: =IF(F24=0,G24,G24*F24) -> 1500000
C25: ■PROXIMITY SENSOR | E25: 식 | F25: 2 | G25: 40000 | H25: =IF(F25=0,G25,G25*F25) -> 80000
H26: =IF(F26=0,G26,G26*F26) -> 0
H27: =IF(F27=0,G27,G27*F27) -> 0
H28: =IF(F28=0,G28,G28*F28) -> 0
C29: ■일반 자재류 | H29: =IF(F29=0,G29,G29*F29) -> 0
C30: F.R.L Unit | D30: AV4000 | E30: 식 | F30: 1 | G30: 350000 | H30: =IF(F30=0,G30,G30*F30) -> 350000
C31: SOL V/V | D31: VQC4201 | E31: 식 | F31: 10 | G31: 75000 | H31: =IF(F31=0,G31,G31*F31) -> 750000
C32: Manifold | D32: VV5QC41 | E32: 식 | F32: 1 | G32: 850000 | H32: =IF(F32=0,G32,G32*F32) -> 850000
C33: Speed Con | E33: 식 | F33: 20 | G33: 7000 | H33: =IF(F33=0,G33,G33*F33) -> 140000
C34: 배관자재 | E34: 식 | F34: 1 | G34: 100000 | H34: =IF(F34=0,G34,G34*F34) -> 100000
C35: 잡자재 | E35: 식 | F35: 1 | G35: 100000 | H35: =IF(F35=0,G35,G35*F35) -> 100000
H36: =IF(F36=0,G36,G36*F36) -> 0
C37: 기타자재 | E37: 식 | F37: 1 | G37: 500000 | H37: 0
H38: =SUM(H20:H37) -> 55090000
B39: 외주제작품 | C39: 불량 배출 컨베어 | E39: 식 | F39: 1 | G39: 5000000 | H39: =IF(F39=0,G39,G39*F39) -> 5000000
H40: =IF(F40=0,G40,G40*F40) -> 0
...

Sheet #70
B1: □ 단위공사명(전기제외): | C1: I/B D/COVER압입 | I1: (첨부)
A2: 구분 | C2: 품 명 | D2: 규격 | E2: 단위 | F2: 수량 | G2: 단가(원) | H2: 금액(원) | I2: 原MAKER
A3: 자 재 비 | B3: 철자재 | C3: ■BASE | D3: 제관,가공 | E3: 식 | F3: 1 | G3: 2000000 | H3: =IF(F3=0,G3,G3*F3) -> 2000000
C4: ■FRAME | D4: 제관,가공 | E4: 식 | F4: 1 | G4: 1500000 | H4: =IF(F4=0,G4,G4*F4) -> 1500000
C5: ■상측 COVER | D5: 제관,가공 | E5: 식 | F5: 1 | G5: 1500000 | H5: =IF(F5=0,G5,G5*F5) -> 1500000
C6: ■OP POST | E6: 식 | F6: 1 | G6: 600000 | H6: =IF(F6=0,G6,G6*F6) -> 600000
C7: ■소재적재 | E7: 식 | F7: 1 | G7: 5000000 | H7: =IF(F7=0,G7,G7*F7) -> 5000000
C8: ■소재 공급 | D8: 2축 | E8: 식 | F8: 1 | G8: 3500000 | H8: =IF(F8=0,G8,G8*F8) -> 3500000
D9: 그리퍼 및 HEAD | E9: 식 | F9: 1 | G9: 1500000 | H9: =IF(F9=0,G9,G9*F9) -> 1500000
C10: ■압입 | E10: 식 | F10: 1 | G10: 2000000 | H10: =IF(F10=0,G10,G10*F10) -> 2000000
C11: ■LIFTER UNIT | E11: 식 | F11: 1 | G11: 1300000 | H11: =IF(F11=0,G11,G11*F11) -> 1300000
H12: =IF(F12=0,G12,G12*F12) -> 0
C13: 기타 가공물 | E13: 식 | F13: 1 | G13: 200000 | H13: 0
H14: =SUM(H3:H13) -> 18900000
B15: 설치/해체/시운전 | H15: =IF(F15=0,G15,G15*F15) -> 0
B16: 공사 관련 자재 | H16: =IF(F16=0,G16,G16*F16) -> 0
H17: =IF(F17=0,G17,G17*F17) -> 0
H18: =IF(F18=0,G18,G18*F18) -> 0
C19: 기타자재 | H19: =IF(F19=0,G19,G19*F19) -> 0
H20: =SUM(H15:H19) -> 0
B21: 구매품 | C21: ■소재적재 | H21: =IF(F21=0,G21,G21*F21) -> 0
B22: (유공압품외) | C22: 공압인덱스 | D22: HM280 | E22: EA | F22: 1 | G22: 3200000 | H22: =IF(F22=0,G22,G22*F22) -> 3200000
C23: 상하 이송 | D23: TM SCREW,LM등 | E23: 식 | F23: 1 | G23: 1000000 | H23: =IF(F23=0,G23,G23*F23) -> 1000000
C24: 소재 감지 센스 | E24: EA | F24: 1 | G24: 100000 | H24: =IF(F24=0,G24,G24*F24) -> 100000
C25: PROXIMITY SENSOR | E25: EA | F25: 5 | G25: 40000 | H25: =IF(F25=0,G25,G25*F25) -> 200000
H26: =IF(F26=0,G26,G26*F26) -> 0
C27: ■소재 공급 | H27: =IF(F27=0,G27,G27*F27) -> 0
C28: 전후이송 | D28: 실린더 | E28: 식 | F28: 1 | G28: 2500000 | H28: =IF(F28=0,G28,G28*F28) -> 2500000
C29: 상하이송 | D29: 실린더 | E29: 식 | F29: 1 | G29: 1000000 | H29: =IF(F29=0,G29,G29*F29) -> 1000000
C30: 그리퍼 CYL' | E30: EA | F30: 1 | G30: 800000 | H30: =IF(F30=0,G30,G30*F30) -> 800000
C31: PROXIMITY SENSOR | E31: EA | F31: 6 | G31: 40000 | H31: =IF(F31=0,G31,G31*F31) -> 240000
C32: 기타 | E32: 식 | F32: 1 | G32: 500000 | H32: =IF(F32=0,G32,G32*F32) -> 500000
C33: ■압입 | H33: =IF(F33=0,G33,G33*F33) -> 0
C34: 서보프레스 | D34: 3t | E34: EA | F34: 1 | G34: 18000000 | H34: =IF(F34=0,G34,G34*F34) -> 18000000
C35: AIR착자 | E35: EA | F35: 3 | G35: 600000 | H35: =IF(F35=0,G35,G35*F35) -> 1800000
C36: 기타 | E36: 식 | F36: 1 | G36: 500000 | H36: =IF(F36=0,G36,G36*F36) -> 500000
C37: ■LIFTER UNIT | E37: 식 | F37: 1 | G37: 600000 | H37: =IF(F37=0,G37,G37*F37) -> 600000
H38: =IF(F38=0,G38,G38*F38) -> 0
C39: ■일반 자재류 | H39: =IF(F39=0,G39,G39*F39) -> 0
C40: F.R.L Unit | D40: AV4000 | E40: 식 | F40: 1 | G40: 350000 | H40: =IF(F40=0,G40,G40*F40) -> 350000
...

Sheet #80
B1: □ 단위공사명(전기제외): | C1: 반전및 B/P압입 | I1: (첨부)
A2: 구분 | C2: 품 명 | D2: 규격 | E2: 단위 | F2: 수량 | G2: 단가(원) | H2: 금액(원) | I2: 原MAKER
A3: 자 재 비 | B3: 철자재 | C3: ■BASE | D3: 제관,가공 | E3: 식 | F3: 1 | G3: 2000000 | H3: =IF(F3=0,G3,G3*F3) -> 2000000
C4: ■FRAME | D4: 제관,가공 | E4: 식 | F4: 1 | G4: 1500000 | H4: =IF(F4=0,G4,G4*F4) -> 1500000
C5: ■상측 COVER | D5: 제관,가공 | E5: 식 | F5: 1 | G5: 1500000 | H5: =IF(F5=0,G5,G5*F5) -> 1500000
C6: ■OP POST | E6: 식 | F6: 1 | G6: 600000 | H6: =IF(F6=0,G6,G6*F6) -> 600000
C7: ■소재적재 | E7: 식 | F7: 1 | G7: 5000000 | H7: =IF(F7=0,G7,G7*F7) -> 5000000
C8: ■소재 공급 | D8: 2축 | E8: 식 | F8: 1 | G8: 3500000 | H8: =IF(F8=0,G8,G8*F8) -> 3500000
D9: 그리퍼 및 HEAD | E9: 식 | F9: 1 | G9: 1500000 | H9: =IF(F9=0,G9,G9*F9) -> 1500000
C10: ■압입 | E10: 식 | F10: 1 | G10: 2000000 | H10: =IF(F10=0,G10,G10*F10) -> 2000000
C11: ■LIFTER UNIT | E11: 식 | F11: 1 | G11: 1300000 | H11: =IF(F11=0,G11,G11*F11) -> 1300000
C12: ■반전장치 | E12: 식 | F12: 1 | G12: 2500000 | H12: =IF(F12=0,G12,G12*F12) -> 2500000
H13: =IF(F13=0,G13,G13*F13) -> 0
H14: =IF(F14=0,G14,G14*F14) -> 0
C15: 기타 가공물 | E15: 식 | F15: 1 | G15: 500000 | H15: 0
H16: =SUM(H3:H15) -> 21400000
B17: 설치/해체/시운전 | H17: =IF(F17=0,G17,G17*F17) -> 0
B18: 공사 관련 자재 | H18: =IF(F18=0,G18,G18*F18) -> 0
H19: =IF(F19=0,G19,G19*F19) -> 0
H20: =IF(F20=0,G20,G20*F20) -> 0
C21: 기타자재 | H21: =IF(F21=0,G21,G21*F21) -> 0
H22: =SUM(H17:H21) -> 0
B23: 구매품 | C23: ■소재적재 | H23: =IF(F23=0,G23,G23*F23) -> 0
B24: (유공압품외) | C24: 공압인덱스 | D24: HM280 | E24: EA | F24: 1 | G24: 3200000 | H24: =IF(F24=0,G24,G24*F24) -> 3200000
C25: 상하 이송 | D25: TM SCREW,LM등 | E25: 식 | F25: 1 | G25: 1000000 | H25: =IF(F25=0,G25,G25*F25) -> 1000000
C26: 소재 감지 센스 | E26: EA | F26: 1 | G26: 100000 | H26: =IF(F26=0,G26,G26*F26) -> 100000
C27: PROXIMITY SENSOR | E27: EA | F27: 5 | G27: 40000 | H27: =IF(F27=0,G27,G27*F27) -> 200000
H28: =IF(F28=0,G28,G28*F28) -> 0
C29: ■소재 공급 | H29: =IF(F29=0,G29,G29*F29) -> 0
C30: 전후이송 | D30: 실린더 | E30: 식 | F30: 1 | G30: 2500000 | H30: =IF(F30=0,G30,G30*F30) -> 2500000
C31: 상하이송 | D31: 실린더 | E31: 식 | F31: 1 | G31: 1000000 | H31: =IF(F31=0,G31,G31*F31) -> 1000000
C32: 그리퍼 CYL' | E32: EA | F32: 1 | G32: 800000 | H32: =IF(F32=0,G32,G32*F32) -> 800000
C33: PROXIMITY SENSOR | E33: EA | F33: 6 | G33: 40000 | H33: =IF(F33=0,G33,G33*F33) -> 240000
C34: 기타 | E34: 식 | F34: 1 | G34: 500000 | H34: =IF(F34=0,G34,G34*F34) -> 500000
C35: ■압입 | H35: =IF(F35=0,G35,G35*F35) -> 0
C36: 서보프레스 | D36: 3t | E36: EA | F36: 1 | G36: 18000000 | H36: =IF(F36=0,G36,G36*F36) -> 18000000
C37: AIR착자 | E37: EA | F37: 3 | G37: 600000 | H37: =IF(F37=0,G37,G37*F37) -> 1800000
C38: 기타 | E38: 식 | F38: 1 | G38: 500000 | H38: =IF(F38=0,G38,G38*F38) -> 500000
C39: ■LIFTER UNIT | E39: 식 | F39: 1 | G39: 600000 | H39: =IF(F39=0,G39,G39*F39) -> 600000
C40: ■반전장치 | H40: =IF(F40=0,G40,G40*F40) -> 0
...

Sheet #90
B1: □ 단위공사명(전기제외): | C1: I/R공급 및 방향정렬 | I1: (첨부)
A2: 구분 | C2: 품 명 | D2: 규격 | E2: 단위 | F2: 수량 | G2: 단가(원) | H2: 금액(원) | I2: 原MAKER
A3: 자 재 비 | B3: 철자재 | C3: ■BASE | D3: 제관,가공 | E3: 식 | F3: 1 | G3: 2000000 | H3: =IF(F3=0,G3,G3*F3) -> 2000000
C4: ■FRAME | D4: 제관,가공 | E4: 식 | F4: 1 | G4: 1000000 | H4: =IF(F4=0,G4,G4*F4) -> 1000000
C5: ■상측 COVER | D5: 제관,가공 | E5: 식 | F5: 1 | G5: 1000000 | H5: =IF(F5=0,G5,G5*F5) -> 1000000
C6: ■OP POST | E6: 식 | F6: 1 | G6: 600000 | H6: =IF(F6=0,G6,G6*F6) -> 600000
C7: ■GRV정렬 | E7: 식 | F7: 1 | G7: 2500000 | H7: =IF(F7=0,G7,G7*F7) -> 2500000
C8: ■LIFTER UNIT | E8: 식 | F8: 1 | G8: 1300000 | H8: =IF(F8=0,G8,G8*F8) -> 1300000
H9: =IF(F9=0,G9,G9*F9) -> 0
H11: =IF(F11=0,G11,G11*F11) -> 0
C12: 기타 가공물 | E12: 식 | F12: 1 | G12: 500000 | H12: 0
H13: =SUM(H3:H12) -> 8400000
B14: 설치/해체/시운전 | H14: =IF(F14=0,G14,G14*F14) -> 0
B15: 공사 관련 자재 | H15: =IF(F15=0,G15,G15*F15) -> 0
H16: =IF(F16=0,G16,G16*F16) -> 0
H17: =IF(F17=0,G17,G17*F17) -> 0
C18: 기타자재 | H18: =IF(F18=0,G18,G18*F18) -> 0
H19: =SUM(H14:H18) -> 0
B20: 구매품 | C20: ■뱡향정렬 | H20: =IF(F20=0,G20,G20*F20) -> 0
B21: (유공압품외) | C21: 상측상하 1축 | D21: LM2EA,CYL',압쇼버,센스,케이블베어등 | E21: 식 | F21: 1 | G21: 1000000 | H21: =IF(F21=0,G21,G21*F21) -> 1000000
C22: 하측상하 1축 | D22: 모타,CYL,LM BUSH등 | E22: 식 | F22: 1 | G22: 1000000 | H22: =IF(F22=0,G22,G22*F22) -> 1000000
C23: 정렬 회전 | D23: 모타,CYL,LM BUSH등 | E23: 식 | F23: 1 | G23: 3500000 | H23: =IF(F23=0,G23,G23*F23) -> 3500000
C24: 기타 | E24: 식 | F24: 1 | G24: 500000 | H24: =IF(F24=0,G24,G24*F24) -> 500000
C25: ■소재 공급 | H25: =IF(F25=0,G25,G25*F25) -> 0
C26: 직교 로봇 | D26: 3축(로보스타) | E26: 식 | F26: 1 | G26: 20000000 | H26: =IF(F26=0,G26,G26*F26) -> 20000000
C27: 그리퍼 CYL' | E27: EA | F27: 1 | G27: 800000 | H27: =IF(F27=0,G27,G27*F27) -> 800000
C28: PROXIMITY SENSOR | E28: EA | F28: 2 | G28: 40000 | H28: =IF(F28=0,G28,G28*F28) -> 80000
C29: 기타 | E29: 식 | F29: 1 | G29: 500000 | H29: =IF(F29=0,G29,G29*F29) -> 500000
C30: ■LIFTER UNIT | E30: 식 | F30: 1 | G30: 600000 | H30: =IF(F30=0,G30,G30*F30) -> 600000
H31: =IF(F31=0,G31,G31*F31) -> 0
