Workbook

Sheet 갑지
B1: (현대/기아차 설비협력업체 견적통일양식)
B2: 見 積 書
B4: 현대위아 貴下
B5: 견적일자 | D5: 45929 | G5: 대표 :김동학
B6: 견적번호 | D6: FTC-2530 | G6: 주소 : 경기도 시흥시 군자천로 219
B7: 납기 | C7: 입하 | D7: 발주후 90일
C8: 최종검수 | D8: 2026년 | G8: 전화: 031)314-0803
B9: 견적유효기간 | D9: 견적 제출 후 30일 | G9: Fax: 031)314-0805
B10: 인도장소 | D10: 귀사 지정장소 | G10: 견적담당: | H10: 김 동학
B11: 지불조건 | D11: 정기 지불조건 | G11: 연 락 처 : | H11: 010-8822-0803
B13: 공사명 : HVAC Assy Line SX3i
B14: 견적금액: 이십육억사천만원정
B16: 번호 | C16: 상세품목내역 | E16: 견적금액 (천원) | I16: 비 고
E17: 기계부문 | F17: 전기부문 | G17: 관리/이윤 (안전관리비포함) | H17: 합 계
B18: 1 | C18: =IF('단위공사별(집계)'!N7>0,'단위공사별(집계)'!B7,"") -> 서브 라인 | E18: =IF('단위공사별(집계)'!N7>1,('단위공사별(집계)'!D7+'단위공사별(집계)'!E7+'단위공사별(집계)'!F7+'단위공사별(집계)'!G7+'단위공사별(집계)'!H7+'단위공사별(집계)'!I7)/1000," ") -> 410421.07 | F18: =IF('단위공사별(집계)'!N7>0,'단위공사별(집계)'!K17/1000,"") -> 447119.08 | G18: =IF('단위공사별(집계)'!N7>0,('단위공사별(집계)'!L7+'단위공사별(집계)'!M7)/1000,"") -> 60988.828 | H18: =IF('단위공사별(집계)'!N7>0,'단위공사별(집계)'!N7/1000,"") -> 567515.79
B19: 2 | C19: =IF('단위공사별(집계)'!N8>0,'단위공사별(집계)'!B8,"") -> HVAC 조립 LINE | E19: =IF('단위공사별(집계)'!N8>1,('단위공사별(집계)'!D8+'단위공사별(집계)'!E8+'단위공사별(집계)'!F8+'단위공사별(집계)'!G8+'단위공사별(집계)'!H8+'단위공사별(집계)'!I8)/1000," ") -> 1384098.7 | G19: =IF('단위공사별(집계)'!N8>0,('단위공사별(집계)'!L8+'단위공사별(집계)'!M8)/1000,"") -> 205677.93 | H19: =IF('단위공사별(집계)'!N8>0,'단위공사별(집계)'!N8/1000,"") -> 1913882.9
B20: 3 | C20: =IF('단위공사별(집계)'!N9>0,'단위공사별(집계)'!B9,"") -> OTHER COST | E20: =IF('단위공사별(집계)'!N9>1,('단위공사별(집계)'!D9+'단위공사별(집계)'!E9+'단위공사별(집계)'!F9+'단위공사별(집계)'!G9+'단위공사별(집계)'!H9+'단위공사별(집계)'!I9)/1000," ") -> 114906.24 | G20: =IF('단위공사별(집계)'!N9>0,('단위공사별(집계)'!L9+'단위공사별(집계)'!M9)/1000,"") -> 17075.14 | H20: =IF('단위공사별(집계)'!N9>0,'단위공사별(집계)'!N9/1000,"") -> 158888.31
B21: 4 | C21: =IF('단위공사별(집계)'!N10>0,'단위공사별(집계)'!B10,"") | E21: =IF('단위공사별(집계)'!N10>1,('단위공사별(집계)'!D10+'단위공사별(집계)'!E10+'단위공사별(집계)'!F10+'단위공사별(집계)'!G10+'단위공사별(집계)'!H10+'단위공사별(집계)'!I10)/1000," ") | G21: =IF('단위공사별(집계)'!N10>0,('단위공사별(집계)'!L10+'단위공사별(집계)'!M10)/1000,"") | H21: =IF('단위공사별(집계)'!N10>0,'단위공사별(집계)'!N10/1000,"")
B22: 5 | C22: =IF('단위공사별(집계)'!N11>0,'단위공사별(집계)'!B11,"") | E22: =IF('단위공사별(집계)'!N11>1,('단위공사별(집계)'!D11+'단위공사별(집계)'!E11+'단위공사별(집계)'!F11+'단위공사별(집계)'!G11+'단위공사별(집계)'!H11+'단위공사별(집계)'!I11)/1000," ") | G22: =IF('단위공사별(집계)'!N11>0,('단위공사별(집계)'!L11+'단위공사별(집계)'!M11)/1000,"") | H22: =IF('단위공사별(집계)'!N11>0,'단위공사별(집계)'!N11/1000,"")
B23: 6 | C23: =IF('단위공사별(집계)'!N12>0,'단위공사별(집계)'!B12,"") | E23: =IF('단위공사별(집계)'!N12>1,('단위공사별(집계)'!D12+'단위공사별(집계)'!E12+'단위공사별(집계)'!F12+'단위공사별(집계)'!G12+'단위공사별(집계)'!H12+'단위공사별(집계)'!I12)/1000," ") | G23: =IF('단위공사별(집계)'!N12>0,('단위공사별(집계)'!L12+'단위공사별(집계)'!M12)/1000,"") | H23: =IF('단위공사별(집계)'!N12>0,'단위공사별(집계)'!N12/1000,"")
B24: 7 | C24: =IF('단위공사별(집계)'!N13>0,'단위공사별(집계)'!B13,"") | E24: =IF('단위공사별(집계)'!N13>1,('단위공사별(집계)'!D13+'단위공사별(집계)'!E13+'단위공사별(집계)'!F13+'단위공사별(집계)'!G13+'단위공사별(집계)'!H13+'단위공사별(집계)'!I13)/1000," ") | G24: =IF('단위공사별(집계)'!N13>0,('단위공사별(집계)'!L13+'단위공사별(집계)'!M13)/1000,"") | H24: =IF('단위공사별(집계)'!N13>0,'단위공사별(집계)'!N13/1000,"")
B25: 8 | C25: =IF('단위공사별(집계)'!N14>0,'단위공사별(집계)'!B14,"") | E25: =IF('단위공사별(집계)'!N14>1,('단위공사별(집계)'!D14+'단위공사별(집계)'!E14+'단위공사별(집계)'!F14+'단위공사별(집계)'!G14+'단위공사별(집계)'!H14+'단위공사별(집계)'!I14)/1000," ") | G25: =IF('단위공사별(집계)'!N14>0,('단위공사별(집계)'!L14+'단위공사별(집계)'!M14)/1000,"") | H25: =IF('단위공사별(집계)'!N14>0,'단위공사별(집계)'!N14/1000,"")
B26: 9 | C26: =IF('단위공사별(집계)'!N15>0,'단위공사별(집계)'!B15,"") | E26: =IF('단위공사별(집계)'!N15>1,('단위공사별(집계)'!D15+'단위공사별(집계)'!E15+'단위공사별(집계)'!F15+'단위공사별(집계)'!G15+'단위공사별(집계)'!H15+'단위공사별(집계)'!I15)/1000," ") | G26: =IF('단위공사별(집계)'!N15>0,('단위공사별(집계)'!L15+'단위공사별(집계)'!M15)/1000,"") | H26: =IF('단위공사별(집계)'!N15>0,'단위공사별(집계)'!N15/1000,"")
B27: 10 | C27: =IF('단위공사별(집계)'!N16>0,'단위공사별(집계)'!B16,"") | E27: =IF('단위공사별(집계)'!N16>1,('단위공사별(집계)'!D16+'단위공사별(집계)'!E16+'단위공사별(집계)'!F16+'단위공사별(집계)'!G16+'단위공사별(집계)'!H16+'단위공사별(집계)'!I16)/1000," ") | G27: =IF('단위공사별(집계)'!N16>0,('단위공사별(집계)'!L16+'단위공사별(집계)'!M16)/1000,"") | H27: =IF('단위공사별(집계)'!N16>0,'단위공사별(집계)'!N16/1000,"")
B28: 견적 합계 | E28: =SUM(E18:E24) -> 1909426 | F28: =SUM(F18:F24) -> 447119.08 | G28: =SUM(G18:G24) -> 283741.9 | H28: =SUM(H18:H24)-287 -> 2640000
F30: 공개입찰가 (견적時 공란)
B32: 특기사항 | C32: 1. VAT 제외 | F32: 외주계획 업체명 (자작時 공란)
C33: 2. 기본 유틸리티공사 제외 | F33: 설계외주
C34: ='원가항목별(집계)'!I38 -> 2578000 | F34: 제작외주
F35: 전기외주
F36: 설치외주

Sheet 원가항목별(집계)
C1: A. 원가항목별 견적가 종합(상세견적 첨부)
B3: □ 현대/기아 요구사양과 견적조건 일치여부 CHECK: 1.일치함 2.일부상이(상이내역 첨부참조)
B5: 순번 | C5: 원가구분 | F5: 단위 | G5: 수량 | H5: 단가 | I5: 금 액(원) | J5: 비 고
B6: 1 | C6: 기계 부문 | D6: 자재비 | E6: 철자재(SS.SUS등) | F6: kg | G6: =서브라인!F36+'HVAC조립 LINE'!F108+'OTHER COST'!F17+단위장비4!F28+단위장비5!F30+단위장비6!F30+단위장비7!F30+단위장비8!F30+단위장비9!F30+단위장비10!F30 -> 0 | I6: =서브라인!H30+'HVAC조립 LINE'!H102+'OTHER COST'!H11+단위장비4!H22+단위장비5!H24+단위장비6!H24+단위장비7!H24+단위장비8!H24+단위장비9!H24+단위장비10!H24 -> 166456000 | J6: 加工必要資材
E7: 일반구매품 | F7: 식 | G7: 1 | I7: =서브라인!H118+'HVAC조립 LINE'!H184+'OTHER COST'!H25+단위장비4!H45+단위장비5!H47+단위장비6!H47+단위장비7!H47+단위장비8!H47+단위장비9!H47+단위장비10!H47 -> 329520000 | J7: 加工不要資材
E8: 외주제작품 | F8: 식 | G8: 1 | I8: =서브라인!H126+'HVAC조립 LINE'!H205+'OTHER COST'!H41+단위장비4!H53+단위장비5!H55+단위장비6!H55+단위장비7!H55+단위장비8!H55+단위장비9!H55+단위장비10!H55 -> 1164250000 | J8: 旣加工SUB資材
E9: 설치/해체 공사 자재 | F9: 식 | G9: 1 | I9: =서브라인!H36+'HVAC조립 LINE'!H108+'OTHER COST'!H17+단위장비4!H28+단위장비5!H30+단위장비6!H30+단위장비7!H30+단위장비8!H30+단위장비9!H30+단위장비10!H30 -> 0 | J9: 시운전 자재 포함
E10: 소계 | I10: =SUM(I6:I9) -> 1660226000
D11: 노무비 | E11: 기존설비 철거 | F11: M/D | G11: =서브라인!F128+'HVAC조립 LINE'!F207+'OTHER COST'!F43+단위장비4!F55+단위장비5!F57+단위장비6!F57+단위장비7!F57+단위장비8!F57+단위장비9!F57+단위장비10!F57 -> 0 | H11: =IF(서브라인!G128>0,서브라인!G128,"") | I11: =서브라인!H128+'HVAC조립 LINE'!H207+'OTHER COST'!H43+단위장비4!H55+단위장비5!H57+단위장비6!H57+단위장비7!H57+단위장비8!H57+단위장비9!H57+단위장비10!H57 -> 0 | J11: 개조공사時
E12: 설계 | F12: M/D | G12: =서브라인!F129+'HVAC조립 LINE'!F208+'OTHER COST'!F44+단위장비4!F56+단위장비5!F58+단위장비6!F58+단위장비7!F58+단위장비8!F58+단위장비9!F58+단위장비10!F58 -> 87 | H12: =IF(서브라인!G129>0,서브라인!G129,"") -> 300000 | I12: =서브라인!H129+'HVAC조립 LINE'!H208+'OTHER COST'!H44+단위장비4!H56+단위장비5!H58+단위장비6!H58+단위장비7!H58+단위장비8!H58+단위장비9!H58+단위장비10!H58 -> 26100000
E13: 제작(제관,가공) | F13: M/D | G13: =서브라인!F130+'HVAC조립 LINE'!F209+'OTHER COST'!F45+단위장비4!F57+단위장비5!F59+단위장비6!F59+단위장비7!F59+단위장비8!F59+단위장비9!F59+단위장비10!F59 -> 150 | H13: =IF(서브라인!G130>0,서브라인!G130,"") -> 300000 | I13: =서브라인!H130+'HVAC조립 LINE'!H209+'OTHER COST'!H45+단위장비4!H57+단위장비5!H59+단위장비6!H59+단위장비7!H59+단위장비8!H59+단위장비9!H59+단위장비10!H59 -> 45000000
E14: 조립 | F14: M/D | G14: =서브라인!F131+'HVAC조립 LINE'!F210+'OTHER COST'!F46+단위장비4!F58+단위장비5!F60+단위장비6!F60+단위장비7!F60+단위장비8!F60+단위장비9!F60+단위장비10!F60 -> 140 | H14: =IF(서브라인!G131>0,서브라인!G131,"") -> 300000 | I14: =서브라인!H131+'HVAC조립 LINE'!H210+'OTHER COST'!H46+단위장비4!H58+단위장비5!H60+단위장비6!H60+단위장비7!H60+단위장비8!H60+단위장비9!H60+단위장비10!H60 -> 42000000 | J14: 정도검사포함
E15: 설치 | F15: M/D | G15: =서브라인!F132+'HVAC조립 LINE'!F211+'OTHER COST'!F47+단위장비4!F59+단위장비5!F61+단위장비6!F61+단위장비7!F61+단위장비8!F61+단위장비9!F61+단위장비10!F61 -> 30 | H15: =IF(서브라인!G132>0,서브라인!G132,"") -> 300000 | I15: =서브라인!H132+'HVAC조립 LINE'!H211+'OTHER COST'!H47+단위장비4!H59+단위장비5!H61+단위장비6!H61+단위장비7!H61+단위장비8!H61+단위장비9!H61+단위장비10!H61 -> 9000000
E16: 시운전 | F16: M/D | G16: =서브라인!F133+'HVAC조립 LINE'!F212+'OTHER COST'!F48+단위장비4!F60+단위장비5!F62+단위장비6!F62+단위장비7!F62+단위장비8!F62+단위장비9!F62+단위장비10!F62 -> 70 | H16: =IF(서브라인!G133>0,서브라인!G133,"") -> 300000 | I16: =서브라인!H133+'HVAC조립 LINE'!H212+'OTHER COST'!H48+단위장비4!H60+단위장비5!H62+단위장비6!H62+단위장비7!H62+단위장비8!H62+단위장비9!H62+단위장비10!H62 -> 23000000
E17: 양산대응 | F17: M/D | G17: =서브라인!F134+'HVAC조립 LINE'!F213+'OTHER COST'!F49+단위장비4!F61+단위장비5!F63+단위장비6!F63+단위장비7!F63+단위장비8!F63+단위장비9!F63+단위장비10!F63 -> 105 | H17: =IF(서브라인!G134>0,서브라인!G134,"") -> 500000 | I17: =서브라인!H134+'HVAC조립 LINE'!H213+'OTHER COST'!H49+단위장비4!H61+단위장비5!H63+단위장비6!H63+단위장비7!H63+단위장비8!H63+단위장비9!H63+단위장비10!H63 -> 52500000
E18: 도장 | F18: M/D | G18: =서브라인!F135+'HVAC조립 LINE'!F214+'OTHER COST'!F50+단위장비4!F62+단위장비5!F64+단위장비6!F64+단위장비7!F64+단위장비8!F64+단위장비9!F64+단위장비10!F64 -> 2 | H18: =IF(서브라인!G135>0,서브라인!G135,"") -> 8500000 | I18: =서브라인!H135+'HVAC조립 LINE'!H214+'OTHER COST'!H50+단위장비4!H62+단위장비5!H64+단위장비6!H64+단위장비7!H64+단위장비8!H64+단위장비9!H64+단위장비10!H64 -> 16600000
E19: 소계 | I19: =SUM(I11:I18) -> 214200000
D20: 일반관리 및 이윤 | I20: =서브라인!H138+서브라인!H139+'HVAC조립 LINE'!H217+'HVAC조립 LINE'!H218+'OTHER COST'!H53+'OTHER COST'!H54+단위장비4!H65+단위장비4!H66+단위장비5!H67+단위장비5!H68+단위장비6!H67+단위장비6!H68+단위장비7!H67+단위장비7!H68+단위장비8!H67+단위장비8!H68+단위장비9!H67+단위장비9!H68+단위장비10!H67+단위장비10!H68 -> 281163900
E21: 기계 소계 | I21: =I19+I10+I20 -> 2155589900
B22: 2 | C22: 전기 부문 | D22: 자재비 | E22: 기계/전기자재 | F22: 식 | G22: 1 | I22: =전기!H307-I23 -> 276299200
E23: 설치/해체 공사 자재 | F23: 식 | G23: 1 | I23: =전기!H35 -> 0 | J23: 시운전 자재 포함
D24: 노무비 | E24: 철거(개조시) | F24: M/D | G24: =전기!F308 -> 0 | H24: =IF(전기!G308>0,전기!G308,"") | I24: =전기!H308 -> 0
E25: 설계,프로그램 | F25: M/D | G25: =전기!F309 -> 100 | H25: =IF(전기!G309>0,전기!G309,"") -> 350000 | I25: =전기!H309 -> 35000000
E26: 제작 | F26: M/D | G26: =전기!F310 -> 50 | H26: =IF(전기!G310>0,전기!G310,"") -> 250000 | I26: =전기!H310 -> 12500000
E27: 조립 | F27: M/D | G27: =전기!F311 -> 40 | H27: =IF(전기!G311>0,전기!G311,"") -> 250000 | I27: =전기!H311 -> 10000000
E28: 설치 | F28: M/D | G28: =전기!F312 -> 80 | H28: =IF(전기!G312>0,전기!G312,"") -> 250000 | I28: =전기!H312 -> 20000000
E29: 시운전 | F29: M/D | G29: =전기!F313 -> 50 | H29: =IF(전기!G313>0,전기!G313,"") -> 350000 | I29: =전기!H313 -> 17500000
E30: 양산대응 | F30: M/D | G30: =전기!F314 -> 35 | H30: =IF(전기!G314>0,전기!G314,"") -> 500000 | I30: =전기!H314 -> 17500000
E31: 소계 | I31: =SUM(I24:I30) -> 112500000
D32: 일반관리 및 이윤 | I32: =전기!H317+전기!H318 -> 58319880
E33: 전기 소계 | I33: =I31+I22+I32+I23 -> 447119080
B34: 3 | C34: 자재비 합계 | I34: =I22+I10+I23 -> 1936525200
C35: 노무비 합계 | I35: =I31+I19 -> 326700000
C36: 중간 합계 | I36: =I35+I34 -> 2263225200
B37: 4 | C37: 포장,운송 및 중장비 사용료 | I37: 35000000
B38: 5 | C38: 표준안전관리비 | F38: 설치/철거/수리금액 기준 | I38: =CEILING(MIN(I46:I47),1000) -> 2578000 | J38: =I29+I28+I24+I23+I16+I15+I11+I9 -> 69500000
B39: 6 | C39: 일반관리비 | I39: =전기!H317+서브라인!H138+'HVAC조립 LINE'!H217+'OTHER COST'!H53+단위장비4!H65+단위장비5!H67+단위장비6!H67+단위장비7!H67+단위장비8!H67+단위장비9!H67+단위장비10!H67 -> 67896756
B40: 7 | C40: 이 윤 | I40: =전기!H318+서브라인!H139+'HVAC조립 LINE'!H218+'OTHER COST'!H54+단위장비4!H66+단위장비5!H68+단위장비6!H68+단위장비7!H68+단위장비8!H68+단위장비9!H68+단위장비10!H68 -> 271587024
C41: 합 계 | F41: 3~7항 합계 | I41: =(I21+I33+I37+I38)-286980 -> 2640000000
B42: 주1. 표준안전관리비:(설치/철거/시운전 공사 관련 금액)의 ⓐ2.66%,ⓑ1.95%+기초액,ⓒ2.02%(50억 이상일경우)
...

Sheet 단위공사별(집계)
A2: B. 단위장비별 견적가 종합(상세견적 첨부)
N3: 단위:원
I5: 포장/운송 | L5: 표준안전 | M5: 일반관리비
A6: 순번 | B6: 단위장비명 | C6: 수량 | D6: 자재비 | E6: 철거 | F6: 제작 | G6: 설치/시운전 | H6: 양산대응 | I6: 중장비사용 | J6: 기계소계 | K6: 전기소계 | L6: 관리비 | M6: 이윤 | N6: 합 계 | O6: 비 고
A7: =IF(B7>0,1,"") -> 1 | B7: =서브라인!C$1 -> 서브 라인 | C7: 1식 | D7: =서브라인!H127 -> 308398000 | E7: =서브라인!H128 -> 0 | F7: =서브라인!H129+서브라인!H130+서브라인!H131+서브라인!H135 -> 68500000 | G7: =서브라인!H132+서브라인!H133 -> 13500000 | H7: =서브라인!H134 -> 12500000 | I7: =IF($B7>0,'원가항목별(집계)'!I$37*$P7/$P$17,0) -> 7523065.7 | J7: =SUM(D7:I7) -> 4.1042107e+08 | K7: =IF(B7>0,'원가항목별(집계)'!I$33*P7/P$17,0) -> 96105892 | L7: =IF($B7>0,'원가항목별(집계)'!I$38*$P7/$P$17,0) -> 554127.53 | M7: =서브라인!H138+서브라인!H139 -> 60434700 | N7: =SUM(J7:M7) -> 5.6751579e+08 | P7: =D7+E7+F7+G7+H7+M7 -> 463332700
A8: =IF(B8>0,A7+1,"") -> 2 | B8: ='HVAC조립 LINE'!C$1 -> HVAC 조립 LINE | C8: 1식 | D8: ='HVAC조립 LINE'!H206 -> 1249028000 | E8: ='HVAC조립 LINE'!H207 -> 0 | F8: ='HVAC조립 LINE'!H208+'HVAC조립 LINE'!H209+'HVAC조립 LINE'!H210+'HVAC조립 LINE'!H214 -> 61200000 | G8: ='HVAC조립 LINE'!H211+'HVAC조립 LINE'!H212 -> 13500000 | H8: ='HVAC조립 LINE'!H213 -> 35000000 | I8: =IF($B8>0,'원가항목별(집계)'!I$37*$P8/$P$17,0) -> 25370689 | J8: =SUM(D8:I8) -> 1.3840987e+09 | K8: =IF(B8>0,'원가항목별(집계)'!I$33*P8/P$17,0) -> 3.2410627e+08 | L8: =IF($B8>0,'원가항목별(집계)'!I$38*$P8/$P$17,0) -> 1868732.5 | M8: ='HVAC조립 LINE'!H217+'HVAC조립 LINE'!H218 -> 203809200 | N8: =SUM(J8:M8) -> 1.9138829e+09 | P8: =D8+E8+F8+G8+H8+M8 -> 1562537200
A9: =IF(B9>0,A8+1,"") -> 3 | B9: ='OTHER COST'!C$1 -> OTHER COST | C9: 1식 | D9: ='OTHER COST'!H42 -> 102800000 | E9: ='OTHER COST'!H43 -> 0 | F9: ='OTHER COST'!H44+'OTHER COST'!H45+'OTHER COST'!H46+'OTHER COST'!H50 -> 0 | G9: ='OTHER COST'!H47+'OTHER COST'!H48 -> 5000000 | H9: ='OTHER COST'!H49 -> 5000000 | I9: =IF($B9>0,'원가항목별(집계)'!I$37*$P9/$P$17,0) -> 2106244.8 | J9: =SUM(D9:I9) -> 1.1490624e+08 | K9: =IF(B9>0,'원가항목별(집계)'!I$33*P9/P$17,0) -> 26906921 | L9: =IF($B9>0,'원가항목별(집계)'!I$38*$P9/$P$17,0) -> 155139.97 | M9: ='OTHER COST'!H53+'OTHER COST'!H54 -> 16920000 | N9: =SUM(J9:M9) -> 1.5888831e+08 | P9: =D9+E9+F9+G9+H9+M9 -> 129720000
A10: =IF(B10>0,A9+1,"") | B10: =단위장비4!C$1 -> 0 | C10: 1식 | D10: =단위장비4!H54 -> 0 | E10: =단위장비4!H55 -> 0 | F10: =단위장비4!H56+단위장비4!H57+단위장비4!H58+단위장비4!H62 -> 0 | G10: =단위장비4!H59+단위장비4!H60 -> 0 | H10: =단위장비4!H61 -> 0 | I10: =IF($B10>0,'원가항목별(집계)'!I$37*$P10/$P$17,0) -> 0 | J10: =SUM(D10:I10) -> 0 | K10: =IF(B10>0,'원가항목별(집계)'!I$33*P10/P$17,0) -> 0 | L10: =IF($B10>0,'원가항목별(집계)'!I$38*$P10/$P$17,0) -> 0 | M10: =단위장비4!H65+단위장비4!H66 -> 0 | N10: =SUM(J10:M10) -> 0 | P10: =D10+E10+F10+G10+H10+M10 -> 0
A11: =IF(B11>0,A10+1,"") | B11: =단위장비5!C$1 -> 0 | C11: 1식 | D11: =단위장비5!H56 -> 0 | E11: =단위장비5!H57 -> 0 | F11: =단위장비5!H58+단위장비5!H59+단위장비5!H60+단위장비5!H64 -> 0 | G11: =단위장비5!H61+단위장비5!H62 -> 0 | H11: =단위장비5!H63 -> 0 | I11: =IF($B11>0,'원가항목별(집계)'!I$37*$P11/$P$17,0) -> 0 | J11: =SUM(D11:I11) -> 0 | K11: =IF(B11>0,'원가항목별(집계)'!I$33*P11/P$17,0) -> 0 | L11: =IF($B11>0,'원가항목별(집계)'!I$38*$P11/$P$17,0) -> 0 | M11: =단위장비5!H67+단위장비5!H68 -> 0 | N11: =SUM(J11:M11) -> 0 | P11: =D11+E11+F11+G11+H11+M11 -> 0
A12: =IF(B12>0,A11+1,"") | B12: =단위장비6!C$1 -> 0 | C12: 1식 | D12: =단위장비6!H56 -> 0 | E12: =단위장비6!H57 -> 0 | F12: =단위장비6!H58+단위장비6!H59+단위장비6!H60+단위장비6!H64 -> 0 | G12: =단위장비6!H61+단위장비6!H62 -> 0 | H12: =단위장비6!H63 -> 0 | I12: =IF($B12>0,'원가항목별(집계)'!I$37*$P12/$P$17,0) -> 0 | J12: =SUM(D12:I12) -> 0 | K12: =IF(B12>0,'원가항목별(집계)'!I$33*P12/P$17,0) -> 0 | L12: =IF($B12>0,'원가항목별(집계)'!I$38*$P12/$P$17,0) -> 0 | M12: =단위장비6!H67+단위장비6!H68 -> 0 | N12: =SUM(J12:M12) -> 0 | P12: =D12+E12+F12+G12+H12+M12 -> 0
A13: =IF(B13>0,A8+1,"") | B13: =단위장비7!C$1 -> 0 | C13: 1식 | D13: =단위장비7!H56 -> 0 | E13: =단위장비7!H57 -> 0 | F13: =단위장비7!H58+단위장비7!H59+단위장비7!H60+단위장비7!H64 -> 0 | G13: =단위장비7!H61+단위장비7!H62 -> 0 | H13: =단위장비7!H63 -> 0 | I13: =IF($B13>0,'원가항목별(집계)'!I$37*$P13/$P$17,0) -> 0 | J13: =SUM(D13:I13) -> 0 | K13: =IF(B13>0,'원가항목별(집계)'!I$33*P13/P$17,0) -> 0 | L13: =IF($B13>0,'원가항목별(집계)'!I$38*$P13/$P$17,0) -> 0 | M13: =단위장비7!H67+단위장비7!H68 -> 0 | N13: =SUM(J13:M13) -> 0 | P13: =D13+E13+F13+G13+H13+M13 -> 0
A14: =IF(B14>0,A13+1,"") | B14: =단위장비8!C$1 -> 0 | C14: 1식 | D14: =단위장비8!H56 -> 0 | E14: =단위장비8!H57 -> 0 | F14: =단위장비8!H58+단위장비8!H59+단위장비8!H60+단위장비8!H64 -> 0 | G14: =단위장비8!H61+단위장비8!H62 -> 0 | H14: =단위장비8!H63 -> 0 | I14: =IF($B14>0,'원가항목별(집계)'!I$37*$P14/$P$17,0) -> 0 | J14: =SUM(D14:I14) -> 0 | K14: =IF(B14>0,'원가항목별(집계)'!I$33*P14/P$17,0) -> 0 | L14: =IF($B14>0,'원가항목별(집계)'!I$38*$P14/$P$17,0) -> 0 | M14: =단위장비8!H67+단위장비8!H68 -> 0 | N14: =SUM(J14:M14) -> 0 | P14: =D14+E14+F14+G14+H14+M14 -> 0
A15: =IF(B15>0,A14+1,"") | B15: =단위장비9!C$1 -> 0 | C15: 1식 | D15: =단위장비9!H57 -> 0 | E15: =단위장비9!H58 -> 0 | F15: =단위장비9!H59+단위장비9!H60+단위장비9!H61+단위장비9!H65 -> 0 | G15: =단위장비9!H62+단위장비9!H63 -> 0 | H15: =단위장비9!H64 -> 0 | I15: =IF($B15>0,'원가항목별(집계)'!I$37*$P15/$P$17,0) -> 0 | J15: =SUM(D15:I15) -> 0 | K15: =IF(B15>0,'원가항목별(집계)'!I$33*P15/P$17,0) -> 0 | L15: =IF($B15>0,'원가항목별(집계)'!I$38*$P15/$P$17,0) -> 0 | M15: =단위장비9!H68+단위장비9!H69 -> 0 | N15: =SUM(J15:M15) -> 0 | P15: =D15+E15+F15+G15+H15+M15 -> 0
A16: =IF(B16>0,A15+1,"") | B16: =단위장비10!C$1 -> 0 | C16: 1식 | D16: =단위장비10!H58 -> 0 | E16: =단위장비10!H59 -> 0 | F16: =단위장비10!H60+단위장비10!H61+단위장비10!H62+단위장비10!H66 -> 0 | G16: =단위장비10!H63+단위장비10!H64 -> 0 | H16: =단위장비10!H65 -> 0 | I16: =IF($B16>0,'원가항목별(집계)'!I$37*$P16/$P$17,0) -> 0 | J16: =SUM(D16:I16) -> 0 | K16: =IF(B16>0,'원가항목별(집계)'!I$33*P16/P$17,0) -> 0 | L16: =IF($B16>0,'원가항목별(집계)'!I$38*$P16/$P$17,0) -> 0 | M16: =단위장비10!H69+단위장비10!H70 -> 0 | N16: =SUM(J16:M16) -> 0 | P16: =D16+E16+F16+G16+H16+M16 -> 0
A17: 합 계 | D17: =SUM(D7:D16) -> 1660226000 | E17: =SUM(E7:E16) -> 0 | F17: =SUM(F7:F16) -> 129700000 | G17: =SUM(G7:G16) -> 32000000 | H17: =SUM(H7:H16) -> 52500000 | I17: =SUM(I7:I16) -> 35000000 | J17: =SUM(D17:I17) -> 1909426000 | K17: =SUM(K7:K16) -> 447119080 | L17: =SUM(L7:L16) -> 2578000 | M17: =SUM(M7:M16) -> 281163900 | N17: =SUM(N7:N14) -> 2.640287e+09 | P17: =SUM(P7:P16) -> 2155589900
D18: =IF(D17=0,"",D17/$N17) -> 0.62880513 | E18: =IF(E17=0,"",E17/$N17) | F18: =IF(F17=0,"",F17/$N17) -> 0.049123448 | G18: =IF(G17=0,"",G17/$N17) -> 0.012119895 | H18: =IF(H17=0,"",H17/$N17) -> 0.019884202 | I18: =IF(I17=0,"",I17/$N17) -> 0.013256135 | J18: =IF(J17=0,"",J17/$N17) -> 0.72318881 | K18: =IF(K17=0,"",K17/$N17) -> 0.16934488 | ... N18: =IF(N17=0,"",N17/$N17) -> 1
A19: 주) 전기비용은 턴키장비의 공통비용으로서 총 전기비용을 단위장비별 기계금액의 비율에 따라 배분함
N20: =IF('원가항목별(집계)'!I41='단위공사별(집계)'!N17,"","DATA오류입니다!") -> DATA오류입니다!

Sheet 전기
B1: □ 전기부문: | C1: 전기부문(공통) | I1: (첨부)
A2: 구분 | C2: 품 명 | D2: 규격 | E2: 단위 | F2: 수량 | G2: 단가(원) | H2: 금액(원) | I2: 原MAKER
A3: 자 재 비 | B3: 철자재 | C3: 사출조립라인 PANEL | D3: 1000X800X300 | E3: EA | F3: 5 | G3: 800000 | H3: =IF(F3=0,G3,G3*F3) -> 4000000
C4: GOT BOX | D4: 400X400X250 | E4: EA | F4: 5 | G4: 200000 | H4: =IF(F4=0,G4,G4*F4) -> 1000000
C5: CC-LINK BOX | D5: 450X400 | E5: EA | F5: 6 | G5: 280000 | H5: =IF(F5=0,G5,G5*F5) -> 1680000
C6: NANE PLATE | D6: AL 명판 | E6: LOT | F6: 1 | G6: 100000 | H6: =IF(F6=0,G6,G6*F6) -> 100000
C7: NANE PLATE | D7: 꼬리표 | E7: LOT | F7: 1 | G7: 400000 | H7: =IF(F7=0,G7,G7*F7) -> 400000
C8: BLWR조립라인 PANEL | D8: 1000X800X300 | E8: EA | F8: 2 | G8: 800000 | H8: =IF(F8=0,G8,G8*F8) -> 1600000
C9: GOT BOX | D9: 400X400X250 | E9: EA | F9: 2 | G9: 200000 | H9: =IF(F9=0,G9,G9*F9) -> 400000
C10: CC-LINK BOX | D10: 450X400 | E10: EA | F10: 2 | G10: 280000 | H10: =IF(F10=0,G10,G10*F10) -> 560000
C11: NANE PLATE | D11: AL 명판 | E11: LOT | F11: 1 | G11: 100000 | H11: =IF(F11=0,G11,G11*F11) -> 100000
C12: NANE PLATE | D12: 꼬리표 | E12: LOT | F12: 1 | G12: 400000 | H12: =IF(F12=0,G12,G12*F12) -> 400000
C13: HTR조립라인 PANEL | D13: 1000X800X300 | E13: EA | F13: 4 | G13: 800000 | H13: =IF(F13=0,G13,G13*F13) -> 3200000
C14: GOT BOX | D14: 400X400X250 | E14: EA | F14: 4 | G14: 200000 | H14: =IF(F14=0,G14,G14*F14) -> 800000
C15: CC-LINK BOX | D15: 450X400 | E15: EA | F15: 4 | G15: 280000 | H15: =IF(F15=0,G15,G15*F15) -> 1120000
... C25: CC-LINK BOX | D25: 450X400 | E25: SET | F25: 6 | G25: 280000 | H25: =IF(F25=0,G25,G25*F25) -> 1680000
C26: NANE PLATE | E26: LOT | F26: 1 | G26: 200000 | H26: =IF(F26=0,G26,G26*F26) -> 200000
C27: NANE PLATE | D27: 꼬리표 | E27: LOT | F27: 1 | G27: 1000000 | H27: =IF(F27=0,G27,G27*F27) -> 1000000
H28: =SUM(H3:H27) -> 27930000
B29: 설치/해체/ | H29: =IF(F29=0,G29,G29*F29) -> 0
B30: 시운전 공사 | H30: =IF(F30=0,G30,G30*F30) -> 0
B31: 자재 | H31: =IF(F31=0,G31,G31*F31) -> 0
H32: =IF(F32=0,G32,G32*F32) -> 0
H33: =IF(F33=0,G33,G33*F33) -> 0
H34: =IF(F34=0,G34,G34*F34) -> 0
H35: =SUM(H29:H34) -> 0
B36: 전기자재 | C36: GOT2000 | D36: GT2712-STBA | E36: EA | F36: 5 | G36: 1650000 | H36: =IF(F36=0,G36,G36*F36) -> 8250000 | I36: 미쯔비시
B37: 사출조립라인 | C37: PLC CPU | D37: Q13UDVCPU | E37: EA | F37: 5 | G37: 1840000 | H37: =IF(F37=0,G37,G37*F37) -> 9200000 | I37: 미쯔비시
C38: PLC POWER | D38: Q62P | E38: EA | F38: 5 | G38: 145000 | H38: =IF(F38=0,G38,G38*F38) -> 725000 | I38: 미쯔비시
C39: PLC BASE | D39: Q312B | E39: EA | F39: 5 | G39: 240000 | H39: =IF(F39=0,G39,G39*F39) -> 1200000 | I39: 미쯔비시
C40: PLC CCLINK | D40: QJ61BT11N | E40: EA | F40: 5 | G40: 221000 | H40: =IF(F40=0,G40,G40*F40) -> 1105000 | I40: 미쯔비시
C41: PLC ETHERNET UINT | D41: QJ1E71-100 | E41: EA | F41: 10 | G41: 932000 | H41: =IF(F41=0,G41,G41*F41) -> 9320000 | I41: 미쯔비시
C42: PLC 통신카드 | D42: QJ71C24N | E42: EA | F42: 2 | G42: 500000 | H42: =IF(F42=0,G42,G42*F42) -> 1000000 | I42: 미쯔비시
C43: CC-LINK | D43: AJ65SBT1-32D | E43: EA | F43: 12 | G43: 210000 | H43: =IF(F43=0,G43,G43*F43) -> 2520000 | I43: 미쯔비시
D44: AJ65SBT1-32T | E44: EA | F44: 6 | G44: 210000 | H44: =IF(F44=0,G44,G44*F44) -> 1260000 | I44: 미쯔비시
D45: AJ65SBT1-32DT | E45: EA | F45: 8 | G45: 210000 | H45: =IF(F45=0,G45,G45*F45) -> 1680000 | I45: 미쯔비시
C46: NFB | D46: ABS32/15A | E46: EA | F46: 20 | G46: 25600 | H46: =IF(F46=0,G46,G46*F46) -> 512000
D47: N-40c | E47: EA | F47: 5 | G47: 17600 | H47: =IF(F47=0,G47,G47*F47) -> 88000
C48: CP | D48: GCP32/7 | E48: EA | F48: 60 | G48: 24200 | H48: =IF(F48=0,G48,G48*F48) -> 1452000
C49: CONSENT | D49: AC220V 2구 | E49: EA | F49: 6 | G49: 2500 | H49: =IF(F49=0,G49,G49*F49) -> 15000
...

Sheet 서브라인
B1: □ 단위공사명(전기제외): | C1: 서브 라인 | I1: (첨부)
A2: 구분 | C2: 품 명 | D2: 규격 | E2: 단위 | F2: 수량 | G2: 단가(원) | H2: 금액(원) | I2: 原MAKER
A3: 자 재 비 | B3: 철자재 | C3: MAIN FRAME | D3: PROFILE 40*80 | E3: SET | F3: 6 | G3: 2500000 | H3: =IF(F3=0,G3,G3*F3) -> 15000000
B4: 사출조립라인 | C4: BASE PLATE | D4: SS400*4.5T,상하 | E4: EA | F4: 12 | G4: 150000 | H4: =IF(F4=0,G4,G4*F4) -> 1800000
C5: PARTS BOX SHELF | E5: EA | F5: 6 | G5: 120000 | H5: =IF(F5=0,G5,G5*F5) -> 720000
C6: ASS'Y JIG | E6: SET | F6: 8 | G6: 2500000 | H6: =IF(F6=0,G6,G6*F6) -> 20000000
C7: GREASE JIG | E7: SET | F7: 3 | G7: 3500000 | H7: =IF(F7=0,G7,G7*F7) -> 10500000
C8: SHUTE | D8: ROLLER TRACK | E8: SET | F8: 4 | G8: 600000 | H8: =IF(F8=0,G8,G8*F8) -> 2400000
B9: BLWR 조립라인 | C9: MAIN FRAME | D9: PROFILE 40*80 | E9: SET | F9: 2 | G9: 2500000 | H9: =IF(F9=0,G9,G9*F9) -> 5000000
C10: BASE PLATE | D10: SS400*4.5T,상하 | E10: EA | F10: 4 | G10: 150000 | H10: =IF(F10=0,G10,G10*F10) -> 600000
C11: PARTS BOX SHELF | E11: EA | F11: 2 | G11: 120000 | H11: =IF(F11=0,G11,G11*F11) -> 240000
C12: ASS'Y JIG | E12: SET | F12: 2 | G12: 2500000 | H12: =IF(F12=0,G12,G12*F12) -> 5000000
C13: SHUTE | D13: ROLLER TRACK | E13: SET | F13: 2 | G13: 600000 | H13: =IF(F13=0,G13,G13*F13) -> 1200000
B14: HTR 조립라인 | C14: MAIN FRAME | D14: PROFILE 40*80 | E14: SET | F14: 4 | G14: 2500000 | H14: =IF(F14=0,G14,G14*F14) -> 10000000
C15: BASE PLATE | D15: SS400*4.5T,상하 | E15: EA | F15: 8 | G15: 150000 | H15: =IF(F15=0,G15,G15*F15) -> 1200000
C16: PARTS BOX SHELF | E16: EA | F16: 4 | G16: 120000 | H16: =IF(F16=0,G16,G16*F16) -> 480000
C17: ASS'Y JIG | E17: SET | F17: 4 | G17: 2500000 | H17: =IF(F17=0,G17,G17*F17) -> 10000000
C18: SAFETY ROOM | D18: PC,PROFILE | E18: EA | F18: 1 | G18: 1500000 | H18: =IF(F18=0,G18,G18*F18) -> 1500000
C19: ROBOT BASE | D19: SQ PIPE 100*50*3.3T | E19: EA | F19: 1 | G19: 800000 | H19: =IF(F19=0,G19,G19*F19) -> 800000
C20: JIG | E20: EA | F20: 1 | G20: 2500000 | H20: =IF(F20=0,G20,G20*F20) -> 2500000
C21: MOVING BASE | D21: 15T | E21: SET | F21: 1 | G21: 300000 | H21: =IF(F21=0,G21,G21*F21) -> 300000
C22: LM BASE | D22: AL30T | E22: EA | F22: 2 | G22: 150000 | H22: =IF(F22=0,G22,G22*F22) -> 300000
C23: SHUTE | D23: ROLLER TRACK | E23: SET | F23: 4 | G23: 600000 | H23: =IF(F23=0,G23,G23*F23) -> 2400000
B24: 열교환기및기타서브 | C24: MAIN FRAME | D24: PROFILE 40*80 | E24: SET | F24: 5 | G24: 2500000 | H24: =IF(F24=0,G24,G24*F24) -> 12500000
C25: BASE PLATE | D25: SS400*4.5T,상하 | E25: EA | F25: 10 | G25: 150000 | H25: =IF(F25=0,G25,G25*F25) -> 1500000
C26: PARTS BOX SHELF | E26: EA | F26: 5 | G26: 120000 | H26: =IF(F26=0,G26,G26*F26) -> 600000
C27: ASS'Y JIG | E27: SET | F27: 4 | G27: 2500000 | H27: =IF(F27=0,G27,G27*F27) -> 10000000
C28: SHUTE | D28: ROLLER TRACK | E28: SET | F28: 3 | G28: 600000 | H28: =IF(F28=0,G28,G28*F28) -> 1800000
H29: =IF(F29=0,G29,G29*F29) -> 0
H30: =SUM(H3:H29) -> 118340000
B31: 설치/해체/시운전 | H31: =IF(F31=0,G31,G31*F31) -> 0
B32: 공사 관련 자재 | H32: =IF(F32=0,G32,G32*F32) -> 0
H33: =IF(F33=0,G33,G33*F33) -> 0
H34: =IF(F34=0,G34,G34*F34) -> 0
H35: =IF(F35=0,G35,G35*F35) -> 0
H36: =SUM(H31:H35) -> 0
B37: 구매품 | C37: AIR SERVICE UNIT | E37: SET | F37: 6 | G37: 150000 | H37: =IF(F37=0,G37,G37*F37) -> 900000 | I37: SMC
B38: (유공압품외) | C38: 작업지시 MONITOR | D38: 24",거치대,USB | E38: SET | F38: 6 | G38: 350000 | H38: =IF(F38=0,G38,G38*F38) -> 2100000 | I38: LG
B39: 사출조립라인 | C39: AIR HOSE,FITTING | E39: SET | F39: 6 | G39: 150000 | H39: =IF(F39=0,G39,G39*F39) -> 900000
C40: LOCKING CYLINDER | D40: MKB20-30 | E40: SET | F40: 8 | G40: 150000 | H40: =IF(F40=0,G40,G40*F40) -> 1200000 | I40: SMC
...

Sheet HVAC조립 LINE
B1: □ 단위공사명(전기제외): | C1: HVAC 조립 LINE | I1: (첨부)
A2: 구분 | C2: 품 명 | D2: 규격 | E2: 단위 | F2: 수량 | G2: 단가(원) | H2: 금액(원) | I2: 原MAKER
A3: 자 재 비 | B3: 철자재 | C3: DRIVE/TAIL FRAME | D3: 9T | E3: SET | F3: 4 | G3: 260000 | H3: =IF(F3=0,G3,G3*F3) -> 1040000
B4: MAIN CONVEYOR | C4: LEG FRAME | D4: 9T | E4: SET | F4: 20 | G4: 70000 | H4: =IF(F4=0,G4,G4*F4) -> 1400000
C5: ADJUST UNIT | D5: 12T, M16 | E5: SET | F5: 60 | G5: 10000 | H5: =IF(F5=0,G5,G5*F5) -> 600000
C6: MOTOR BASE | D6: 12T | E6: EA | F6: 2 | G6: 45000 | H6: =IF(F6=0,G6,G6*F6) -> 90000
C7: MOTOR CHAIN COVER | D7: 2.3T | E7: EA | F7: 2 | G7: 30000 | H7: =IF(F7=0,G7,G7*F7) -> 60000
C8: DRIVE SPROCKET | D8: #60*25T/25T | E8: SET | F8: 2 | G8: 45000 | H8: =IF(F8=0,G8,G8*F8) -> 90000
C9: DRIVE SHAFT | D9: Ø60 | E9: EA | F9: 2 | G9: 60000 | H9: =IF(F9=0,G9,G9*F9) -> 120000
C10: STAY BAR | D10: SQ PIPE 50*30 | E10: EA | F10: 20 | G10: 15000 | H10: =IF(F10=0,G10,G10*F10) -> 300000
C11: SENSOR BRACKET | E11: LOT | F11: 2 | G11: 200000 | H11: =IF(F11=0,G11,G11*F11) -> 400000
C12: CENTER COVER | D12: SS400*1.5T | E12: M | F12: 40 | G12: 20000 | H12: =IF(F12=0,G12,G12*F12) -> 800000
C13: LAMP POST | E13: SET | F13: 6 | G13: 500000 | H13: =IF(F13=0,G13,G13*F13) -> 3000000
C14: PARTS TABLE | D14: 3.2T | E14: EA | F14: 6 | G14: 100000 | H14: =IF(F14=0,G14,G14*F14) -> 600000
C15: MAIN DUCT | D15: AL 100*100 | E15: M | F15: 40 | G15: 30000 | H15: =IF(F15=0,G15,G15*F15) -> 1200000
C16: SIGNAL DUCT | D16: AL 100*100 | E16: M | F16: 40 | G16: 30000 | H16: =IF(F16=0,G16,G16*F16) -> 1200000
C17: MAIN FRAME | D17: DY1031N | E17: M | F17: 80 | G17: 44000 | H17: =IF(F17=0,G17,G17*F17) -> 3520000 | I17: DYC
B18: CONNECT CONV | C18: DRIVE/TAIL FRAME | D18: 9T | E18: SET | F18: 4 | G18: 260000 | H18: =IF(F18=0,G18,G18*F18) -> 1040000
C19: ADJUST UNIT | D19: 12T, M16 | E19: SET | F19: 16 | G19: 10000 | H19: =IF(F19=0,G19,G19*F19) -> 160000
C20: MAIN SPROCKET | D20: VRP 2060*11NT | E20: EA | F20: 2 | G20: 60000 | H20: =IF(F20=0,G20,G20*F20) -> 120000
C21: MOTOR BASE | D21: 12T | E21: EA | F21: 2 | G21: 45000 | H21: =IF(F21=0,G21,G21*F21) -> 90000
C22: MOTOR CHAIN COVER | D22: 2.3T | E22: EA | F22: 2 | G22: 30000 | H22: =IF(F22=0,G22,G22*F22) -> 60000
C23: DRIVE SPROCKET | D23: #60*19T/25T | E23: SET | F23: 2 | G23: 45000 | H23: =IF(F23=0,G23,G23*F23) -> 90000
C24: DRIVE SHAFT | D24: Ø60 | E24: EA | F24: 2 | G24: 60000 | H24: =IF(F24=0,G24,G24*F24) -> 120000
C25: STAY BAR | D25: SQ PIPE 50*30 | E25: EA | F25: 4 | G25: 15000 | H25: =IF(F25=0,G25,G25*F25) -> 60000
C26: SENSOR BRACKET | E26: LOT | F26: 2 | G26: 50000 | H26: =IF(F26=0,G26,G26*F26) -> 100000
C27: MAIN DUCT | D27: AL 100*100 | E27: M | F27: 4 | G27: 45000 | H27: =IF(F27=0,G27,G27*F27) -> 180000
C28: SIGNAL DUCT | D28: AL 100*100 | E28: M | F28: 4 | G28: 45000 | H28: =IF(F28=0,G28,G28*F28) -> 180000
C29: MAIN FRAME | D29: DY1031N | E29: M | F29: 8 | G29: 44000 | H29: =IF(F29=0,G29,G29*F29) -> 352000 | I29: DYC
B30: STOPPER | C30: MAIN BASE | D30: 150W*4.5T | E30: EA | F30: 30 | G30: 60000 | H30: =IF(F30=0,G30,G30*F30) -> 1800000
B31: (30SET) | C31: SPACER | D31: 15T | E31: EA | F31: 60 | G31: 10000 | H31: =IF(F31=0,G31,G31*F31) -> 600000
C32: SENSOR BRACKET | D32: 3.2T | E32: EA | F32: 30 | G32: 5000 | H32: =IF(F32=0,G32,G32*F32) -> 150000
B33: DIVERTER | C33: MAIN BASE | D33: 12T | E33: EA | F33: 4 | G33: 150000 | H33: =IF(F33=0,G33,G33*F33) -> 600000
B34: (4SET) | C34: UP/DOWN BASE | D34: 12T | E34: EA | F34: 4 | G34: 60000 | H34: =IF(F34=0,G34,G34*F34) -> 240000
C35: BASE SUPPORT | D35: 12T | E35: EA | F35: 8 | G35: 50000 | H35: =IF(F35=0,G35,G35*F35) -> 400000
C36: CYL' FLANGE | D36: Ø120 | E36: EA | F36: 4 | G36: 40000 | H36: =IF(F36=0,G36,G36*F36) -> 160000
C37: DRIVE SHAFT | D37: Ø30 | E37: EA | F37: 4 | G37: 45000 | H37: =IF(F37=0,G37,G37*F37) -> 180000
C38: DRIVE/TAIL ROLLER | D38: Ø100 | E38: EA | F38: 16 | G38: 80000 | H38: =IF(F38=0,G38,G38*F38) -> 1280000
C39: IDLE ROLLER | D39: Ø60 | E39: EA | F39: 16 | G39: 50000 | H39: =IF(F39=0,G39,G39*F39) -> 800000
C40: ROLLER BRAKET | D40: 4.5T | E40: EA | F40: 8 | G40: 30000 | H40: =IF(F40=0,G40,G40*F40) -> 240000
...

Sheet OTHER COST
B1: □ 단위공사명(전기제외): | C1: OTHER COST | I1: (첨부)
A2: 구분 | C2: 품 명 | D2: 규격 | E2: 단위 | F2: 수량 | G2: 단가(원) | H2: 금액(원) | I2: 原MAKER
A3: 자 재 비 | B3: 철자재 | H3: =IF(F3=0,G3,G3*F3) -> 0
H4: =IF(F4=0,G4,G4*F4) -> 0
H5: =IF(F5=0,G5,G5*F5) -> 0
H6: =IF(F6=0,G6,G6*F6) -> 0
H7: =IF(F7=0,G7,G7*F7) -> 0
H8: =IF(F8=0,G8,G8*F8) -> 0
H9: =IF(F9=0,G9,G9*F9) -> 0
H10: =IF(F10=0,G10,G10*F10) -> 0
H11: =SUM(H3:H10) -> 0
B12: 설치/해체/시운전 | H12: =IF(F12=0,G12,G12*F12) -> 0
B13: 공사 관련 자재 | H13: =IF(F13=0,G13,G13*F13) -> 0
H14: =IF(F14=0,G14,G14*F14) -> 0
H15: =IF(F15=0,G15,G15*F15) -> 0
H16: =IF(F16=0,G16,G16*F16) -> 0
H17: =SUM(H12:H16) -> 0
B18: 구매품 | H18: =IF(F18=0,G18,G18*F18) -> 0
B19: (유공압품외) | H19: =IF(F19=0,G19,G19*F19) -> 0
H20: =IF(F20=0,G20,G20*F20) -> 0
H21: =IF(F21=0,G21,G21*F21) -> 0
H22: =IF(F22=0,G22,G22*F22) -> 0
H23: =IF(F23=0,G23,G23*F23) -> 0
H24: =IF(F24=0,G24,G24*F24) -> 0
H25: =SUM(H18:H24) -> 0
B26: 외주제작품 | C26: 항공비(설치) | D26: 기계2,전기2,로봇1 | E26: M | F26: 5 | G26: 1500000 | H26: =IF(F26=0,G26,G26*F26) -> 7500000
C27: 항공비(P1) | D27: PM1,기계1,전기1,로봇1 | E27: M | F27: 4 | G27: 1500000 | H27: =IF(F27=0,G27,G27*F27) -> 6000000
C28: 항공비(P2) | D28: PM1,기계1,전기1 | E28: M | F28: 3 | G28: 1500000 | H28: =IF(F28=0,G28,G28*F28) -> 4500000
C29: 항공비(양산대응) | D29: PM1,기계1,전기1,로봇1 | E29: M | F29: 4 | G29: 1500000 | H29: =IF(F29=0,G29,G29*F29) -> 6000000
C30: 체류비(설치) | D30: 5인*2주,1인*10일 | E30: M/D | F30: 80 | G30: 300000 | H30: =IF(F30=0,G30,G30*F30) -> 24000000
C31: 체류비(P1) | D31: 3인*2주,1인*5일 | E31: M/D | F31: 47 | G31: 300000 | H31: =IF(F31=0,G31,G31*F31) -> 14100000
C32: 체류비(P2) | D32: 3인*2주 | E32: M/D | F32: 42 | G32: 300000 | H32: =IF(F32=0,G32,G32*F32) -> 12600000
C33: 체류비(양산대응) | D33: 3인*2주,1인*5일 | E33: M/D | F33: 47 | G33: 300000 | H33: =IF(F33=0,G33,G33*F33) -> 14100000
C34: CEPA 인증비 | E34: LOT | F34: 1 | G34: 8000000 | H34: =IF(F34=0,G34,G34*F34) -> 8000000
C35: 공장 임대료 | E35: LOT | F35: 1 | G35: 6000000 | H35: =IF(F35=0,G35,G35*F35) -> 6000000
H36: =IF(F36=0,G36,G36*F36) -> 0
H37: =IF(F37=0,G37,G37*F37) -> 0
H38: =IF(F38=0,G38,G38*F38) -> 0
H39: =IF(F39=0,G39,G39*F39) -> 0
H40: =IF(F40=0,G40,G40*F40) -> 0
...

Sheet 단위장비4
B1: □ 단위공사명(전기제외): | I1: (첨부)
A2: 구분 | C2: 품 명 | D2: 규격 | E2: 단위 | F2: 수량 | G2: 단가(원) | H2: 금액(원) | I2: 原MAKER
A3: 자 재 비 | B3: 철자재 | H3: =IF(F3=0,G3,G3*F3) -> 0
H4: =IF(F4=0,G4,G4*F4) -> 0
H5: =IF(F5=0,G5,G5*F5) -> 0
H6: =IF(F6=0,G6,G6*F6) -> 0
H7: =IF(F7=0,G7,G7*F7) -> 0
H8: =IF(F8=0,G8,G8*F8) -> 0
H9: =IF(F9=0,G9,G9*F9) -> 0
H10: =IF(F10=0,G10,G10*F10) -> 0
H11: =IF(F11=0,G11,G11*F11) -> 0
H12: =IF(F12=0,G12,G12*F12) -> 0
H13: =IF(F13=0,G13,G13*F13) -> 0
H14: =IF(F14=0,G14,G14*F14) -> 0
H15: =IF(F15=0,G15,G15*F15) -> 0
... H21: =IF(F21=0,G21,G21*F21) -> 0
H22: =SUM(H3:H21) -> 0
B23: 설치/해체/시운전 | H23: =IF(F23=0,G23,G23*F23) -> 0
B24: 공사 관련 자재 | H24: =IF(F24=0,G24,G24*F24) -> 0
H25: =IF(F25=0,G25,G25*F25) -> 0
H26: =IF(F26=0,G26,G26*F26) -> 0
H27: =IF(F27=0,G27,G27*F27) -> 0
H28: =SUM(H23:H27) -> 0
B29: 구매품 | H29: =IF(F29=0,G29,G29*F29) -> 0
B30: (유공압품외) | H30: =IF(F30=0,G30,G30*F30) -> 0
H31: =IF(F31=0,G31,G31*F31) -> 0
H32: =IF(F32=0,G32,G32*F32) -> 0
H33: =IF(F33=0,G33,G33*F33) -> 0
H34: =IF(F34=0,G34,G34*F34) -> 0
H35: =IF(F35=0,G35,G35*F35) -> 0
H36: =IF(F36=0,G36,G36*F36) -> 0
H37: =IF(F37=0,G37,G37*F37) -> 0
H38: =IF(F38=0,G38,G38*F38) -> 0
H39: =IF(F39=0,G39,G39*F39) -> 0
H40: =IF(F40=0,G40,G40*F40) -> 0
H41: =IF(F41=0,G41,G41*F41) -> 0
H42: =IF(F42=0,G42,G42*F42) -> 0
... H44: =IF(F44=0,G44,G44*F44) -> 0
H45: =SUM(H29:H44) -> 0
B46: 외주제작품 | H46: =IF(F46=0,G46,G46*F46) -> 0
...

Sheet 단위장비5
B1: □ 단위공사명(전기제외): | I1: (첨부)
A2: 구분 | C2: 품 명 | D2: 규격 | E2: 단위 | F2: 수량 | G2: 단가(원) | H2: 금액(원) | I2: 原MAKER
A3: 자 재 비 | B3: 철자재 | H3: =IF(F3=0,G3,G3*F3) -> 0
H4: =IF(F4=0,G4,G4*F4) -> 0
H5: =IF(F5=0,G5,G5*F5) -> 0
H6: =IF(F6=0,G6,G6*F6) -> 0
H7: =IF(F7=0,G7,G7*F7) -> 0
H8: =IF(F8=0,G8,G8*F8) -> 0
H9: =IF(F9=0,G9,G9*F9) -> 0
H10: =IF(F10=0,G10,G10*F10) -> 0
H11: =IF(F11=0,G11,G11*F11) -> 0
H12: =IF(F12=0,G12,G12*F12) -> 0
H13: =IF(F13=0,G13,G13*F13) -> 0
H14: =IF(F14=0,G14,G14*F14) -> 0
H15: =IF(F15=0,G15,G15*F15) -> 0
... H23: =IF(F23=0,G23,G23*F23) -> 0
H24: =SUM(H3:H23) -> 0
B25: 설치/해체/시운전 | H25: =IF(F25=0,G25,G25*F25) -> 0
B26: 공사 관련 자재 | H26: =IF(F26=0,G26,G26*F26) -> 0
H27: =IF(F27=0,G27,G27*F27) -> 0
H28: =IF(F28=0,G28,G28*F28) -> 0
H29: =IF(F29=0,G29,G29*F29) -> 0
H30: =SUM(H25:H29) -> 0
B31: 구매품 | H31: =IF(F31=0,G31,G31*F31) -> 0
B32: (유공압품외) | H32: =IF(F32=0,G32,G32*F32) -> 0
H33: =IF(F33=0,G33,G33*F33) -> 0
H34: =IF(F34=0,G34,G34*F34) -> 0
H35: =IF(F35=0,G35,G35*F35) -> 0
H36: =IF(F36=0,G36,G36*F36) -> 0
H37: =IF(F37=0,G37,G37*F37) -> 0
H38: =IF(F38=0,G38,G38*F38) -> 0
H39: =IF(F39=0,G39,G39*F39) -> 0
H40: =IF(F40=0,G40,G40*F40) -> 0
H41: =IF(F41=0,G41,G41*F41) -> 0
H42: =IF(F42=0,G42,G42*F42) -> 0
H43: =IF(F43=0,G43,G43*F43) -> 0
H44: =IF(F44=0,G44,G44*F44) -> 0
... H46: =IF(F46=0,G46,G46*F46) -> 0
H47: =SUM(H31:H46) -> 0
B48: 외주제작품 | H48: =IF(F48=0,G48,G48*F48) -> 0
...

Sheet 단위장비6
B1: □ 단위공사명(전기제외): | I1: (첨부)
A2: 구분 | C2: 품 명 | D2: 규격 | E2: 단위 | F2: 수량 | G2: 단가(원) | H2: 금액(원) | I2: 原MAKER
A3: 자 재 비 | B3: 철자재 | H3: =IF(F3=0,G3,G3*F3) -> 0
H4: =IF(F4=0,G4,G4*F4) -> 0
H5: =IF(F5=0,G5,G5*F5) -> 0
H6: =IF(F6=0,G6,G6*F6) -> 0
H7: =IF(F7=0,G7,G7*F7) -> 0
H8: =IF(F8=0,G8,G8*F8) -> 0
H9: =IF(F9=0,G9,G9*F9) -> 0
H10: =IF(F10=0,G10,G10*F10) -> 0
H11: =IF(F11=0,G11,G11*F11) -> 0
H12: =IF(F12=0,G12,G12*F12) -> 0
H13: =IF(F13=0,G13,G13*F13) -> 0
H14: =IF(F14=0,G14,G14*F14) -> 0
H15: =IF(F15=0,G15,G15*F15) -> 0
... H23: =IF(F23=0,G23,G23*F23) -> 0
H24: =SUM(H3:H23) -> 0
B25: 설치/해체/시운전 | H25: =IF(F25=0,G25,G25*F25) -> 0
B26: 공사 관련 자재 | H26: =IF(F26=0,G26,G26*F26) -> 0
H27: =IF(F27=0,G27,G27*F27) -> 0
H28: =IF(F28=0,G28,G28*F28) -> 0
H29: =IF(F29=0,G29,G29*F29) -> 0
H30: =SUM(H25:H29) -> 0
B31: 구매품 | H31: =IF(F31=0,G31,G31*F31) -> 0
B32: (유공압품외) | H32: =IF(F32=0,G32,G32*F32) -> 0
H33: =IF(F33=0,G33,G33*F33) -> 0
H34: =IF(F34=0,G34,G34*F34) -> 0
H35: =IF(F35=0,G35,G35*F35) -> 0
H36: =IF(F36=0,G36,G36*F36) -> 0
H37: =IF(F37=0,G37,G37*F37) -> 0
H38: =IF(F38=0,G38,G38*F38) -> 0
H39: =IF(F39=0,G39,G39*F39) -> 0
H40: =IF(F40=0,G40,G40*F40) -> 0
H41: =IF(F41=0,G41,G41*F41) -> 0
H42: =IF(F42=0,G42,G42*F42) -> 0
H43: =IF(F43=0,G43,G43*F43) -> 0
H44: =IF(F44=0,G44,G44*F44) -> 0
... H46: =IF(F46=0,G46,G46*F46) -> 0
H47: =SUM(H31:H46) -> 0
B48: 외주제작품 | H48: =IF(F48=0,G48,G48*F48) -> 0
...

Sheet 단위장비7
B1: □ 단위공사명(전기제외): | I1: (첨부)
A2: 구분 | C2: 품 명 | D2: 규격 | E2: 단위 | F2: 수량 | G2: 단가(원) | H2: 금액(원) | I2: 原MAKER
A3: 자 재 비 | B3: 철자재 | H3: =IF(F3=0,G3,G3*F3) -> 0
H4: =IF(F4=0,G4,G4*F4) -> 0
H5: =IF(F5=0,G5,G5*F5) -> 0
H6: =IF(F6=0,G6,G6*F6) -> 0
H7: =IF(F7=0,G7,G7*F7) -> 0
H8: =IF(F8=0,G8,G8*F8) -> 0
H9: =IF(F9=0,G9,G9*F9) -> 0
H10: =IF(F10=0,G10,G10*F10) -> 0
H11: =IF(F11=0,G11,G11*F11) -> 0
H12: =IF(F12=0,G12,G12*F12) -> 0
H13: =IF(F13=0,G13,G13*F13) -> 0
H14: =IF(F14=0,G14,G14*F14) -> 0
H15: =IF(F15=0,G15,G15*F15) -> 0
... H23: =IF(F23=0,G23,G23*F23) -> 0
H24: =SUM(H3:H23) -> 0
B25: 설치/해체/시운전 | H25: =IF(F25=0,G25,G25*F25) -> 0
B26: 공사 관련 자재 | H26: =IF(F26=0,G26,G26*F26) -> 0
H27: =IF(F27=0,G27,G27*F27) -> 0
H28: =IF(F28=0,G28,G28*F28) -> 0
H29: =IF(F29=0,G29,G29*F29) -> 0
H30: =SUM(H25:H29) -> 0
B31: 구매품 | H31: =IF(F31=0,G31,G31*F31) -> 0
B32: (유공압품외) | H32: =IF(F32=0,G32,G32*F32) -> 0
H33: =IF(F33=0,G33,G33*F33) -> 0
H34: =IF(F34=0,G34,G34*F34) -> 0
H35: =IF(F35=0,G35,G35*F35) -> 0
H36: =IF(F36=0,G36,G36*F36) -> 0
H37: =IF(F37=0,G37,G37*F37) -> 0
H38: =IF(F38=0,G38,G38*F38) -> 0
H39: =IF(F39=0,G39,G39*F39) -> 0
H40: =IF(F40=0,G40,G40*F40) -> 0
H41: =IF(F41=0,G41,G41*F41) -> 0
H42: =IF(F42=0,G42,G42*F42) -> 0
H43: =IF(F43=0,G43,G43*F43) -> 0
H44: =IF(F44=0,G44,G44*F44) -> 0
... H46: =IF(F46=0,G46,G46*F46) -> 0
H47: =SUM(H31:H46) -> 0
B48: 외주제작품 | H48: =IF(F48=0,G48,G48*F48) -> 0
...

Sheet 단위장비8
B1: □ 단위공사명(전기제외): | I1: (첨부)
A2: 구분 | C2: 품 명 | D2: 규격 | E2: 단위 | F2: 수량 | G2: 단가(원) | H2: 금액(원) | I2: 原MAKER
A3: 자 재 비 | B3: 철자재 | H3: =IF(F3=0,G3,G3*F3) -> 0
H4: =IF(F4=0,G4,G4*F4) -> 0
H5: =IF(F5=0,G5,G5*F5) -> 0
H6: =IF(F6=0,G6,G6*F6) -> 0
H7: =IF(F7=0,G7,G7*F7) -> 0
H8: =IF(F8=0,G8,G8*F8) -> 0
H9: =IF(F9=0,G9,G9*F9) -> 0
H10: =IF(F10=0,G10,G10*F10) -> 0
H11: =IF(F11=0,G11,G11*F11) -> 0
H12: =IF(F12=0,G12,G12*F12) -> 0
H13: =IF(F13=0,G13,G13*F13) -> 0
H14: =IF(F14=0,G14,G14*F14) -> 0
H15: =IF(F15=0,G15,G15*F15) -> 0
... H22: =IF(F22=0,G22,G22*F22) -> 0
C23: 기타자재 | H23: =IF(F23=0,G23,G23*F23) -> 0
H24: =SUM(H3:H23) -> 0
B25: 설치/해체/시운전 | H25: =IF(F25=0,G25,G25*F25) -> 0
B26: 공사 관련 자재 | H26: =IF(F26=0,G26,G26*F26) -> 0
H27: =IF(F27=0,G27,G27*F27) -> 0
H28: =IF(F28=0,G28,G28*F28) -> 0
C29: 기타자재 | H29: =IF(F29=0,G29,G29*F29) -> 0
H30: =SUM(H25:H29) -> 0
B31: 구매품 | H31: =IF(F31=0,G31,G31*F31) -> 0
B32: (유공압품외) | H32: =IF(F32=0,G32,G32*F32) -> 0
H33: =IF(F33=0,G33,G33*F33) -> 0
H34: =IF(F34=0,G34,G34*F34) -> 0
H35: =IF(F35=0,G35,G35*F35) -> 0
H36: =IF(F36=0,G36,G36*F36) -> 0
H37: =IF(F37=0,G37,G37*F37) -> 0
H38: =IF(F38=0,G38,G38*F38) -> 0
H39: =IF(F39=0,G39,G39*F39) -> 0
H40: =IF(F40=0,G40,G40*F40) -> 0
H41: =IF(F41=0,G41,G41*F41) -> 0
H42: =IF(F42=0,G42,G42*F42) -> 0
H43: =IF(F43=0,G43,G43*F43) -> 0
H44: =IF(F44=0,G44,G44*F44) -> 0
H45: =IF(F45=0,G45,G45*F45) -> 0
C46: 기타자재 | H46: =IF(F46=0,G46,G46*F46) -> 0
...

Sheet 단위장비9
B1: □ 단위공사명(전기제외): | I1: (첨부)
A2: 구분 | C2: 품 명 | D2: 규격 | E2: 단위 | F2: 수량 | G2: 단가(원) | H2: 금액(원) | I2: 原MAKER
A3: 자 재 비 | B3: 철자재 | H3: =IF(F3=0,G3,G3*F3) -> 0
H4: =IF(F4=0,G4,G4*F4) -> 0
H5: =IF(F5=0,G5,G5*F5) -> 0
H6: =IF(F6=0,G6,G6*F6) -> 0
H7: =IF(F7=0,G7,G7*F7) -> 0
H8: =IF(F8=0,G8,G8*F8) -> 0
H9: =IF(F9=0,G9,G9*F9) -> 0
H10: =IF(F10=0,G10,G10*F10) -> 0
H11: =IF(F11=0,G11,G11*F11) -> 0
H12: =IF(F12=0,G12,G12*F12) -> 0
H13: =IF(F13=0,G13,G13*F13) -> 0
H14: =IF(F14=0,G14,G14*F14) -> 0
H15: =IF(F15=0,G15,G15*F15) -> 0
... H22: =IF(F22=0,G22,G22*F22) -> 0
C23: 기타자재 | H23: =IF(F23=0,G23,G23*F23) -> 0
H24: =SUM(H3:H23) -> 0
B25: 설치/해체/시운전 | H25: =IF(F25=0,G25,G25*F25) -> 0
B26: 공사 관련 자재 | H26: =IF(F26=0,G26,G26*F26) -> 0
H27: =IF(F27=0,G27,G27*F27) -> 0
H28: =IF(F28=0,G28,G28*F28) -> 0
C29: 기타자재 | H29: =IF(F29=0,G29,G29*F29) -> 0
H30: =SUM(H25:H29) -> 0
B31: 구매품 | H31: =IF(F31=0,G31,G31*F31) -> 0
B32: (유공압품외) | H32: =IF(F32=0,G32,G32*F32) -> 0
H33: =IF(F33=0,G33,G33*F33) -> 0
H34: =IF(F34=0,G34,G34*F34) -> 0
H35: =IF(F35=0,G35,G35*F35) -> 0
H36: =IF(F36=0,G36,G36*F36) -> 0
H37: =IF(F37=0,G37,G37*F37) -> 0
H38: =IF(F38=0,G38,G38*F38) -> 0
H39: =IF(F39=0,G39,G39*F39) -> 0
H40: =IF(F40=0,G40,G40*F40) -> 0
H41: =IF(F41=0,G41,G41*F41) -> 0
H42: =IF(F42=0,G42,G42*F42) -> 0
H43: =IF(F43=0,G43,G43*F43) -> 0
H44: =IF(F44=0,G44,G44*F44) -> 0
H45: =IF(F45=0,G45,G45*F45) -> 0
C46: 기타자재 | H46: =IF(F46=0,G46,G46*F46) -> 0
...

Sheet 단위장비10
B1: □ 단위공사명(전기제외): | I1: (첨부)
A2: 구분 | C2: 품 명 | D2: 규격 | E2: 단위 | F2: 수량 | G2: 단가(원) | H2: 금액(원) | I2: 原MAKER
A3: 자 재 비 | B3: 철자재 | H3: =IF(F3=0,G3,G3*F3) -> 0
H4: =IF(F4=0,G4,G4*F4) -> 0
H5: =IF(F5=0,G5,G5*F5) -> 0
H6: =IF(F6=0,G6,G6*F6) -> 0
H7: =IF(F7=0,G7,G7*F7) -> 0
H8: =IF(F8=0,G8,G8*F8) -> 0
H9: =IF(F9=0,G9,G9*F9) -> 0
H10: =IF(F10=0,G10,G10*F10) -> 0
H11: =IF(F11=0,G11,G11*F11) -> 0
H12: =IF(F12=0,G12,G12*F12) -> 0
H13: =IF(F13=0,G13,G13*F13) -> 0
H14: =IF(F14=0,G14,G14*F14) -> 0
H15: =IF(F15=0,G15,G15*F15) -> 0
... H22: =IF(F22=0,G22,G22*F22) -> 0
C23: 기타자재 | H23: =IF(F23=0,G23,G23*F23) -> 0
H24: =SUM(H3:H23) -> 0
B25: 설치/해체/시운전 | H25: =IF(F25=0,G25,G25*F25) -> 0
B26: 공사 관련 자재 | H26: =IF(F26=0,G26,G26*F26) -> 0
H27: =IF(F27=0,G27,G27*F27) -> 0
H28: =IF(F28=0,G28,G28*F28) -> 0
C29: 기타자재 | H29: =IF(F29=0,G29,G29*F29) -> 0
H30: =SUM(H25:H29) -> 0
B31: 구매품 | H31: =IF(F31=0,G31,G31*F31) -> 0
B32: (유공압품외) | H32: =IF(F32=0,G32,G32*F32) -> 0
H33: =IF(F33=0,G33,G33*F33) -> 0
H34: =IF(F34=0,G34,G34*F34) -> 0
H35: =IF(F35=0,G35,G35*F35) -> 0
H36: =IF(F36=0,G36,G36*F36) -> 0
H37: =IF(F37=0,G37,G37*F37) -> 0
H38: =IF(F38=0,G38,G38*F38) -> 0
H39: =IF(F39=0,G39,G39*F39) -> 0
H40: =IF(F40=0,G40,G40*F40) -> 0
H41: =IF(F41=0,G41,G41*F41) -> 0
H42: =IF(F42=0,G42,G42*F42) -> 0
H43: =IF(F43=0,G43,G43*F43) -> 0
H44: =IF(F44=0,G44,G44*F44) -> 0
H45: =IF(F45=0,G45,G45*F45) -> 0
C46: 기타자재 | H46: =IF(F46=0,G46,G46*F46) -> 0
...

Sheet 첨부(견적조건차이내역)
A1: ※ 현대/기아차의 요구사양과 업체견적사양이 다른경우만 작성
D2: (첨부)
A3: 현대/기아차 요구사양대비 견적조건 상이내역
A5: 항 목 | B5: 현대/기아차 요구사양 | C5: 업체 견적기준 사양 | D5: 비 고
