Workbook

Sheet 견적서
D3: 현대자동차주식회사
B4: 見 積 書
C6: 현대위아 | G6: 귀중 | L6: 견적서NO :
L7: 제 출 일 : | M7: 2025-04-21
D9: 귀팀 | F9: 요청에 의하여 아래와 같이 견적서를 제출하오니 선처바랍니다.
C11: 견적금액 : | F11: =NUMBERSTRING(L28*1000,1)&TEXT(L28*1000,"원 정 (\#,###")&")" -> 삼십사억삼천만원 정 (₩3,430,000,000)
C12: 납 기 : | F12: 8개월 | H12: 포장 : | I12: 폐사표준 | K12: 운임 : | L12: 견적가에 포함
C13: 납품장소 : | F13: 귀팀공장 | G13: 시운전도 | H13: (단, 하차및 설치 제외) | K13: 견적유효기간 : | L13: 1개월
C15: 지불조건 : | F15: 계약금 0% 1차 중도금 0% 2차 중도금 0% 잔금 0%
C16: 프로젝트 : | F16: 멕시코 엔진공장 감마2T/T-HEV+누우A/S 기종추가
C17: 공정번호 :
C18: 장 비 명 : | F18: 메인조립라인 개조
C19: 소 재 명 :
M20: [단위:천원]
C21: NO. | E21: 품명 | J21: 수량 | K21: 견적단가 | L21: 견적금액
C23: 1 | E23: 메인조립라인 개조 | J23: 1 | K23: ='상세 견적_메인조립기'!K52 -> 3430000 | L23: =J23*K23 -> 3430000
E27: * 세부 견적내역은 첨부참조
E28: TOTAL | L28: =L23 -> 3430000
C31: 메카트로닉스기술실장 | J31: 상무 정 종 주

Sheet 상세 견적_메인조립기
C2: 세부견적내역 | K2: Page 1
C3: 공정NO : | G3: 장비명 : | K3: 단위:천원
D4: 품명 | I4: 수량 | J4: 견적금액
B6: 1 | C6: 메인조립기 (OP 010~140) | I6: 1 | K6: =SUM(I7:I20) -> 1807470
D7: MNG00-010 | E7: BLOCK Input | I7: 46500
D8: MNG00-010 | E8: LADDER FRAME Separate M/C | I8: 267400
D9: MNG00-030 | E9: MAIN BEARING Assy M/C | I9: 147620
D10: MNG00-040 | E10: CRANK SHAFT Input | I10: 0
D11: MNG00-040 | E11: CPS WHEEL Assy M/C | I11: 10000
D12: MNG00-060 | E12: PIstON Sub assy M/C | I12: 6300
D13: MNG00-070 | E13: PIstON Assy M/C | I13: 43600
D14: MNG00-090 | E14: L/FRAME & REAR OIL SEAL Assy M/C | I14: 28500
D15: MNG00-100 | E15: CYLINDER HEAD Assy M/C | I15: 38000
D16: MNG00-110 | E16: MLA & HLA assy M/C | I16: 128250
D17: MNG00-120 | E17: TIMING CHAIN COVER Assy M/C | I17: 80700
D18: MNG00-130 | E18: OIL PAN Assy M/C | I18: 38200
D19: MNG00-140 | E19: C/HEAD COVER Assy M/C | I19: 83700
E20: 공통노무비 | I20: =공통!H50/1000 -> 888700
B21: 2 | C21: 비전시스템 | I21: 1 | K21: =비전!H50/1000 -> 632047.5
B22: 3 | C22: 실런트시스템 | I22: 1 | K22: =실런트!H29/1000 -> 39397.8
B23: 4 | C23: 툴네비게이트 | I23: 1 | K23: =툴네비게이트!H38/1000 -> 62504
C24: HMC
B25: 5 | C25: 기계_설계 (국내) | I25: 120 | J25: M/D | K25: 80767
B26: 6 | C26: 기계_승인협의 및 현지 설비 확인 | I26: 14 | J26: M/D | K26: 12223
B27: 7 | C27: 기계_T/O | I27: 120 | J27: M/D | K27: 104767
B28: 8 | C28: 기계_시운전 | I28: 42 | J28: M/D | K28: 36668
B29: 9 | C29: 기계_양산 1차 | I29: 28 | J29: M/D | K29: 24446
B30: 10 | C30: 기계_양산 2차 | I30: 7 | J30: M/D | K30: 6111
B31: 11 | C31: 기계_이벤트 대응 1 | I31: 7 | J31: M/D | K31: 6111
B32: 12 | C32: 기계_이벤트 대응 2 | I32: 7 | J32: M/D | K32: 6111
B33: 13 | C33: 기계_양산 3차 | I33: 7 | J33: M/D | K33: 6111
B34: 14 | C34: 전기_설계 (국내) | I34: 60 | J34: M/D | K34: 40383
B35: 15 | C35: 전기_승인협의 및 현지 설비 확인 | I35: 7 | J35: M/D | K35: 6111
B36: 16 | C36: 전기_T/O | I36: 60 | J36: M/D | K36: 52383
... B42: 22 | C42: 전기_양산 3차 | I42: 7 | J42: M/D | K42: 6111
C43: 기타
B44: 23 | C44: 포장/국내운송/FOB | I44: 1 | K44: 50000
C47: 소 계 | K47: =SUM(K6:K46) -> 3028612.3
B48: 24 | C48: 안전관리비 및 기업이윤/일반관리비 | I48: 0.1 | K48: =K47*0.1 -> 302861.23
B49: 25 | C49: 출장비 | I49: 1 | K49: 100000
...

Sheet 10-1
C1: 10-1 BLOCK Input
B2: 구분 | C2: 장치 구분 | E2: 견적가 | I2: 비고
C3: 장치 | D3: 내 용 | E3: 단위 | F3: 수량 | G3: 단가(원) | H3: 견적(원)
B4: 기계 | C4: HOIST JIG | E4: SET | F4: 1 | G4: 800000 | H4: =F4*G4 -> 800000
C5: SHUTTLE JIG RTL. | E5: SET | F5: 2 | G5: 1000000 | H5: =F5*G5 -> 2000000
C6: BLOCK ROBOT GRIPPER RTL. | E6: SET | F6: 2 | G6: 2500000 | H6: =F6*G6 -> 5000000
C7: C/CASE ROBOT GRIPPER RTL. | E7: SET | F7: 2 | G7: 600000 | H7: =F7*G7 -> 1200000
C8: ROBOT TEACHING/PROGRAM | E8: SET | F8: 3 | G8: 10000000 | H8: =F8*G8 -> 30000000
C9: FRAME/SUPPORT | E9: SET | F9: 1 | G9: 2000000 | H9: =F9*G9 -> 2000000
C10: POST CHANGER | E10: SET | F10: 1 | G10: 2500000 | H10: =F10*G10 -> 2500000
C11: SAFETY EQUIPMENTS | E11: SET | F11: 1 | G11: 3000000 | H11: =F11*G11 -> 3000000
B12: 전기
B13: 기계 노무비
B15: 전기 노무비
B17: 기타
B20: 소계 | H20: =SUM(H4:H19) -> 46500000
B21: GRAND TOTAL | H21: =H20 -> 46500000

Sheet 10-2
C1: 10-2 LADDER FRAME Separate M/C
B2: 구분 | C2: 장치 구분 | E2: 견적가 | I2: 비고
C3: 장치 | D3: 내 용 | E3: 단위 | F3: 수량 | G3: 단가(원) | H3: 견적(원)
B4: 기계 | C4: BUSH PRESS | D4: BED EQUIPMENT | E4: SET | F4: 1 | G4: 6000000 | H4: =F4*G4 -> 6000000
D5: FRAME/SUPPORT | E5: SET | F5: 1 | G5: 6000000 | H5: =F5*G5 -> 6000000
D6: PART FEEDER | E6: SET | F6: 1 | G6: 15000000 | H6: =F6*G6 -> 15000000
D7: BUSH DISTRIBUTOR | E7: SET | F7: 1 | G7: 5000000 | H7: =F7*G7 -> 5000000
D8: SUPPLY CHUTE | E8: SET | F8: 1 | G8: 1500000 | H8: =F8*G8 -> 1500000
D9: ESCAPER/CATCHER | E9: SET | F9: 1 | G9: 1500000 | H9: =F9*G9 -> 1500000
D10: PRESS UNIT | E10: SET | F10: 1 | G10: 4000000 | H10: =F10*G10 -> 4000000
D11: BACKUP UNIT | E11: SET | F11: 1 | G11: 2500000 | H11: =F11*G11 -> 2500000
D12: SERVO PRESS SUPERVISING | E12: SET | F12: 1 | G12: 5000000 | H12: =F12*G12 -> 5000000
D13: SAFETY EQUIPMENTS | E13: SET | F13: 1 | G13: 3000000 | H13: =F13*G13 -> 3000000
D14: C/CASE ROBOT GRIPPER RTL. | E14: SET | F14: 2 | G14: 600000 | H14: =F14*G14 -> 1200000
D15: ROBOT TEACHING/PROGRAM | E15: SET | F15: 2 | G15: 10000000 | H15: =F15*G15 -> 20000000
C16: S/CAP PRESS | D16: FRAME/SUPPORT | E16: SET | F16: 1 | G16: 6000000 | H16: =F16*G16 -> 6000000
D17: BUSH DISTRIBUTOR | E17: SET | F17: 1 | G17: 5000000 | H17: =F17*G17 -> 5000000
D18: SUPPLY CHUTE | E18: SET | F18: 2 | G18: 1500000 | H18: =F18*G18 -> 3000000
D19: ESCAPER/CATCHER | E19: SET | F19: 2 | G19: 1500000 | H19: =F19*G19 -> 3000000
D20: PRESS UNIT | E20: SET | F20: 2 | G20: 4000000 | H20: =F20*G20 -> 8000000
D21: BACKUP UNIT | E21: SET | F21: 2 | G21: 2500000 | H21: =F21*G21 -> 5000000
D22: SERVO PRESS SUPERVISING | E22: SET | F22: 1 | G22: 5000000 | H22: =F22*G22 -> 5000000
D23: ROBOT TEACHING/PROGRAM | E23: SET | F23: 1 | G23: 10000000 | H23: =F23*G23 -> 10000000
D24: SAFETY EQUIPMENTS | E24: SET | F24: 1 | G24: 3000000 | H24: =F24*G24 -> 3000000
C25: SEALANT SPRAY | D25: BED EQUIPMENT | E25: SET | F25: 1 | G25: 2500000 | H25: =F25*G25 -> 2500000
D26: FRAME/SUPPORT | E26: SET | F26: 1 | G26: 2500000 | H26: =F26*G26 -> 2500000
D27: SPRAY UNIT | E27: SET | F27: 1 | G27: 4000000 | H27: =F27*G27 -> 4000000
D28: 3AXIS ROBOT | E28: SET | F28: 1 | G28: 11000000 | H28: =F28*G28 -> 11000000
D29: 3AXIS ROBOT SUPERVISING | E29: SET | F29: 1 | G29: 4000000 | H29: =F29*G29 -> 4000000
D30: SEALANT SYSTEM | E30: SET | F30: 1 | G30: 9500000 | H30: =F30*G30 -> 9500000
D31: VISION SYSTEM | E31: SET | F31: 1 | G31: 20000000 | H31: =F31*G31 -> 20000000
D32: ROBOT TEACHING/PROGRAM | E32: SET | F32: 1 | G32: 10000000 | H32: =F32*G32 -> 10000000
D33: SAFETY EQUIPMENTS | E33: SET | F33: 1 | G33: 3000000 | H33: =F33*G33 -> 3000000
C34: S/CAP PRESS | D34: BED EQUIPMENT | E34: SET | F34: 1 | G34: 6000000 | H34: =F34*G34 -> 6000000
C35: (NU, G1) | D35: FRAME/SUPPORT | E35: SET | F35: 1 | G35: 6000000 | H35: =F35*G35 -> 6000000
D36: SUPPLY CHUTE | E36: SET | F36: 2 | G36: 1500000 | H36: =F36*G36 -> 3000000
D37: ESCAPER/CATCHER | E37: SET | F37: 2 | G37: 1500000 | H37: =F37*G37 -> 3000000
D38: PRESS UNIT | E38: SET | F38: 2 | G38: 4000000 | H38: =F38*G38 -> 8000000
D39: PRESS UNIT SHIFTING | E39: SET | F39: 2 | G39: 2000000 | H39: =F39*G39 -> 4000000
D40: BACKUP UNIT | E40: SET | F40: 2 | G40: 2500000 | H40: =F40*G40 -> 5000000
...

Sheet 30
C1: 30 MAIN BEARING Assy M/C
B2: 구분 | C2: 장치 구분 | E2: 견적가 | I2: 비고
C3: 장치 | D3: 내 용 | E3: 단위 | F3: 수량 | G3: 단가(원) | H3: 견적(원)
B4: 기계 | C4: MBC ASS'Y | D4: OIL JET VISION UNIT | E4: SET | F4: 1 | G4: 1500000 | H4: =F4*G4 -> 1500000
D5: 1AXIS ROBOT SUPERVISING | E5: SET | F5: 1 | G5: 4000000 | H5: =F5*G5 -> 4000000
D6: ROBOT TEACHING/PROGRAM | E6: SET | F6: 1 | G6: 20000000 | H6: =F6*G6 -> 20000000
D7: CRK. GRIPPER RTL. | E7: SET | F7: 1 | G7: 500000 | H7: =F7*G7 -> 500000
D8: C/CASE INDEX JIG RTL. | E8: SET | F8: 2 | G8: 600000 | H8: =F8*G8 -> 1200000
D9: TILTING UNIT GRIPPER RTL. | E9: SET | F9: 1 | G9: 1500000 | H9: =F9*G9 -> 1500000
D10: C/CASE ROBOT GRIPPER RTL. | E10: SET | F10: 1 | G10: 600000 | H10: =F10*G10 -> 600000
D11: ROBOT TEACHING/PROGRAM | E11: SET | F11: 1 | G11: 10000000 | H11: =F11*G11 -> 10000000
D12: SEALING MASTER | E12: SET | F12: 1 | G12: 600000 | H12: =F12*G12 -> 600000
C13: BOLT CHECK | D13: BED EQUIPMENT | E13: SET | F13: 1 | G13: 6000000 | H13: =F13*G13 -> 6000000
D14: FRAME/SUPPORT | E14: SET | F14: 1 | G14: 6000000 | H14: =F14*G14 -> 6000000
D15: A/P CLAMP | E15: SET | F15: 1 | G15: 5000000 | H15: =F15*G15 -> 5000000
D16: CHECK UNIT | E16: SET | F16: 1 | G16: 4000000 | H16: =F16*G16 -> 4000000
D17: UNIT UP/DOWN | E17: SET | F17: 1 | G17: 2000000 | H17: =F17*G17 -> 2000000
D18: PIN DIVERTER RTL. | E18: SET | F18: 1 | G18: 1500000 | H18: =F18*G18 -> 1500000
D19: SAFETY EQUIPMENTS | E19: SET | F19: 1 | G19: 3000000 | H19: =F19*G19 -> 3000000
C20: CAP N/R | D20: BED EQUIPMENT | E20: SET | F20: 1 | G20: 6000000 | H20: =F20*G20 -> 6000000
D21: FRAME/SUPPORT | E21: SET | F21: 1 | G21: 6000000 | H21: =F21*G21 -> 6000000
D22: A/P CLAMP | E22: SET | F22: 1 | G22: 5000000 | H22: =F22*G22 -> 5000000
D23: N/R HEAD | E23: SET | F23: 1 | G23: 2500000 | H23: =F23*G23 -> 2500000
D24: N/R SHIFTING | E24: SET | F24: 1 | G24: 2500000 | H24: =F24*G24 -> 2500000
D25: N/R SHIFTING | E25: SET | F25: 2 | G25: 2500000 | H25: =F25*G25 -> 5000000
D26: N/R HEAD UP/DOWN | E26: SET | F26: 1 | G26: 4000000 | H26: =F26*G26 -> 4000000
D27: N/R HEAD MOVING | E27: SET | F27: 1 | G27: 2500000 | H27: =F27*G27 -> 2500000
D28: 1AXIS ROBOT | E28: SET | F28: 1 | G28: 4000000 | H28: =F28*G28 -> 4000000
D29: 1AXIS ROBOT SUPERVISING | E29: SET | F29: 1 | G29: 4000000 | H29: =F29*G29 -> 4000000
D30: N/R SPINDLE | E30: SET | F30: 4 | G30: 850000 | H30: =F30*G30 -> 3400000
D31: N/R SOCKET | E31: SET | F31: 8 | G31: 40000 | H31: =F31*G31 -> 320000
D32: N/R PROGRAM | E32: SET | F32: 1 | G32: 2500000 | H32: =F32*G32 -> 2500000
... D35: SAFETY EQUIPMENTS | E35: SET | F35: 1 | G35: 3000000 | H35: =F35*G35 -> 3000000
C36: CAP REMOVE | D36: BED EQUIPMENT | E36: SET | F36: 1 | G36: 6000000 | H36: =F36*G36 -> 6000000
D37: FRAME/SUPPORT | E37: SET | F37: 1 | G37: 6000000 | H37: =F37*G37 -> 6000000
D38: A/P CLAMP | E38: SET | F38: 1 | G38: 5000000 | H38: =F38*G38 -> 5000000
D39: CAP REMOVE HEAD | E39: SET | F39: 1 | G39: 3500000 | H39: =F39*G39 -> 3500000
D40: HEAD UP/DOWN | E40: SET | F40: 1 | G40: 4000000 | H40: =F40*G40 -> 4000000
D41: SAFETY EQUIPMENTS | E41: SET | F41: 1 | G41: 3000000 | H41: =F41*G41 -> 3000000
B42: 전기
...

Sheet 40-1
C1: 40-1 CRANK SHAFT Input
B2: 구분 | C2: 장치 구분 | E2: 견적가 | I2: 비고
C3: 장치 | D3: 내 용 | E3: 단위 | F3: 수량 | G3: 단가(원) | H3: 견적(원)
B4: 기계
B5: 전기
B6: 기계 노무비
B8: 전기 노무비
B10: 기타
B13: 소계 | H13: =SUM(H4:H12) -> 0
B14: GRAND TOTAL | H14: =H13 -> 0

Sheet 40-2
C1: 40-2 CPS WHEEL Assy M/C
B2: 구분 | C2: 장치 구분 | E2: 견적가 | I2: 비고
C3: 장치 | D3: 내 용 | E3: 단위 | F3: 수량 | G3: 단가(원) | H3: 견적(원)
B4: 기계 | C4: CRK. JIG FIXTURE | E4: SET | F4: 1 | G4: 2000000 | H4: =F4*G4 -> 2000000
C5: JIG SHUTTLE UNIT | E5: SET | F5: 1 | G5: 3000000 | H5: =F5*G5 -> 3000000
C6: SERVO PRESS SUPERVISING | E6: SET | F6: 1 | G6: 5000000 | H6: =F6*G6 -> 5000000
B7: 전기
B8: 기계 노무비
B10: 전기 노무비
B12: 기타
B15: 소계 | H15: =SUM(H4:H14) -> 10000000
B16: GRAND TOTAL | H16: =H15 -> 10000000

Sheet 60
C1: 60
B2: 구분 | C2: 장치 구분 | E2: 견적가 | I2: 비고
C3: 장치 | D3: 내 용 | E3: 단위 | F3: 수량 | G3: 단가(원) | H3: 견적(원)
B4: 기계 | C4: PISTON JIG FIXTURE | E4: SET | F4: 1 | G4: 1500000 | H4: =F4*G4 -> 1500000
C5: SNAP RING CHECKER | E5: SET | F5: 1 | G5: 1500000 | H5: =F5*G5 -> 1500000
C6: S/RING ASS'Y JIG | E6: SET | F6: 1 | G6: 800000 | H6: =F6*G6 -> 800000
C7: S/RING SUPPLY RTL. | E7: SET | F7: 1 | G7: 2000000 | H7: =F7*G7 -> 2000000
C8: S/RING PUSHER RTL. | E8: SET | F8: 1 | G8: 500000 | H8: =F8*G8 -> 500000
B9: 전기
B10: 기계 노무비
B12: 전기 노무비
B14: 기타
B17: 소계 | H17: =SUM(H4:H16) -> 6300000
B18: GRAND TOTAL | H18: =H17 -> 6300000

Sheet 70
C1: 70
B2: 구분 | C2: 장치 구분 | E2: 견적가 | I2: 비고
C3: 장치 | D3: 내 용 | E3: 단위 | F3: 수량 | G3: 단가(원) | H3: 견적(원)
C4: PISTON ASS'Y | D4: ROBOT TEACHING/PROGRAM | E4: SET | F4: 1 | G4: 10000000 | H4: =F4*G4 -> 10000000
D5: INSERT GUIDE | E5: SET | F5: 2 | G5: 4000000 | H5: =F5*G5 -> 8000000
D6: INSERT FORK | E6: SET | F6: 1 | G6: 800000 | H6: =F6*G6 -> 800000
D7: JIG INTERLOCK BOX | E7: SET | F7: 1 | G7: 1000000 | H7: =F7*G7 -> 1000000
D8: CRK. ROTATOR | E8: SET | F8: 1 | G8: 800000 | H8: =F8*G8 -> 800000
C9: CAP CHECK | D9: CHECK UNIT RTL. | E9: SET | F9: 1 | G9: 1500000 | H9: =F9*G9 -> 1500000
D10: 1AXIS ROBOT SUPERVISING | E10: SET | F10: 1 | G10: 4000000 | H10: =F10*G10 -> 4000000
D11: LIGHT SHIELD ROOM | E11: SET | F11: 1 | G11: 2000000 | H11: =F11*G11 -> 2000000
D12: SAFETY EQUIPMENTS | E12: SET | F12: 1 | G12: 3000000 | H12: =F12*G12 -> 3000000
C13: CAP N/R | D13: N/R PROGRAM | E13: SET | F13: 1 | G13: 2500000 | H13: =F13*G13 -> 2500000
D14: ROBOT TEACHING/PROGRAM | E14: SET | F14: 1 | G14: 10000000 | H14: =F14*G14 -> 10000000
B15: 전기
B16: 기계 노무비
B18: 전기 노무비
B20: 기타
B23: 소계 | H23: =SUM(H4:H22) -> 43600000
B24: GRAND TOTAL | H24: =H23 -> 43600000

Sheet 90
C1: 90
B2: 구분 | C2: 장치 구분 | E2: 견적가 | I2: 비고
C3: 장치 | D3: 내 용 | E3: 단위 | F3: 수량 | G3: 단가(원) | H3: 견적(원)
C4: LADDER ASS'Y | D4: BACKUP UNIT RTL. | E4: SET | F4: 1 | G4: 1500000 | H4: =F4*G4 -> 1500000
D5: SERVO PRESS SUPERVISING | E5: SET | F5: 1 | G5: 5000000 | H5: =F5*G5 -> 5000000
C6: LEAK | D6: BACKUP UNIT RTL. | E6: SET | F6: 1 | G6: 1500000 | H6: =F6*G6 -> 1500000
D7: TEST GAUGE PROGRAM | E7: SET | F7: 1 | G7: 1000000 | H7: =F7*G7 -> 1000000
C8: D/PIN PRESS | D8: ROBOT TEACHING/PROGRAM | E8: SET | F8: 1 | G8: 10000000 | H8: =F8*G8 -> 10000000
D9: JIG FIXTURE | E9: SET | F9: 1 | G9: 1500000 | H9: =F9*G9 -> 1500000
D10: BACKUP UNIT RTL. | E10: SET | F10: 2 | G10: 1500000 | H10: =F10*G10 -> 3000000
D11: SERVO PRESS SUPERVISING | E11: SET | F11: 1 | G11: 5000000 | H11: =F11*G11 -> 5000000
B12: 전기
B13: 기계 노무비
B15: 전기 노무비
B17: 기타
B20: 소계 | H20: =SUM(H4:H19) -> 28500000
B21: GRAND TOTAL | H21: =H20 -> 28500000

Sheet 100
C1: 100
B2: 구분 | C2: 장치 구분 | E2: 견적가 | I2: 비고
C3: 장치 | D3: 내 용 | E3: 단위 | F3: 수량 | G3: 단가(원) | H3: 견적(원)
B4: 기계 | C4: GASKET RACK | E4: SET | F4: 1 | G4: 4000000 | H4: =F4*G4 -> 4000000
C5: 3AXIS ROBOT SUPERVISING | E5: SET | F5: 1 | G5: 4000000 | H5: =F5*G5 -> 4000000
C6: HEAD ROBOT GRIPPER RTL. | E6: SET | F6: 1 | G6: 2500000 | H6: =F6*G6 -> 2500000
C7: ROBOT TEACHING/PROGRAM | E7: SET | F7: 1 | G7: 10000000 | H7: =F7*G7 -> 10000000
C8: N/R PROGRAM | E8: SET | F8: 1 | G8: 2500000 | H8: =F8*G8 -> 2500000
C9: C/CAP, CARRIER ROBOT GRIPPER RTL. | E9: SET | F9: 2 | G9: 2500000 | H9: =F9*G9 -> 5000000
C10: ROBOT TEACHING/PROGRAM | E10: SET | F10: 1 | G10: 10000000 | H10: =F10*G10 -> 10000000
B11: 전기
B12: 기계 노무비
B14: 전기 노무비
B16: 기타
B19: 소계 | H19: =SUM(H4:H18) -> 38000000
B20: GRAND TOTAL | H20: =H19 -> 38000000

Sheet 110
C1: 10-2 LADDER FRAME Separate M/C
B2: 구분 | C2: 장치 구분 | E2: 견적가 | I2: 비고
C3: 장치 | D3: 내 용 | E3: 단위 | F3: 수량 | G3: 단가(원) | H3: 견적(원)
B4: 기계 | C4: MLA/HLA ASS'Y | D4: CAM SHAFT CLAMP | E4: SET | F4: 2 | G4: 800000 | H4: =F4*G4 -> 1600000
D5: MODEL CHECKER | E5: SET | F5: 2 | G5: 1500000 | H5: =F5*G5 -> 3000000
C6: CVVT N/R | D6: INDEX TABLE | E6: SET | F6: 1 | G6: 2000000 | H6: =F6*G6 -> 2000000
D7: JIG FIXTURE | E7: SET | F7: 2 | G7: 1200000 | H7: =F7*G7 -> 2400000
D8: CLAMP UNIT | E8: SET | F8: 2 | G8: 1500000 | H8: =F8*G8 -> 3000000
D9: CVVD JIG FIXTURE | E9: SET | F9: 1 | G9: 1200000 | H9: =F9*G9 -> 1200000
D10: CLAMP UNIT | E10: SET | F10: 1 | G10: 1500000 | H10: =F10*G10 -> 1500000
D11: N/R HEAD | E11: SET | F11: 1 | G11: 1200000 | H11: =F11*G11 -> 1200000
D12: N/R SPINDLE | E12: SET | F12: 1 | G12: 850000 | H12: =F12*G12 -> 850000
D13: N/R PROGRAM | E13: SET | F13: 1 | G13: 2500000 | H13: =F13*G13 -> 2500000
D14: SOCKET | E14: SET | F14: 1 | G14: 40000 | H14: =F14*G14 -> 40000
D15: SOCKET INTERLOCK BOX | E15: SET | F15: 1 | G15: 500000 | H15: =F15*G15 -> 500000
D16: OIL SPRAY UNIT RTL. | E16: SET | F16: 1 | G16: 300000 | H16: =F16*G16 -> 300000
D17: AIR BLOW UNIT | E17: SET | F17: 1 | G17: 300000 | H17: =F17*G17 -> 300000
C18: CARRIER SEALING | D18: 3AXIS ROBOT SUPERVISING | E18: SET | F18: 1 | G18: 4000000 | H18: =F18*G18 -> 4000000
D19: SEALING MASTER | E19: SET | F19: 1 | G19: 600000 | H19: =F19*G19 -> 600000
D20: CVVD OIL SPRAY UNIT | E20: SET | F20: 1 | G20: 2500000 | H20: =F20*G20 -> 2500000
D21: MOVING OIL PAN | E21: SET | F21: 1 | G21: 900000 | H21: =F21*G21 -> 900000
D22: OIL SUPPLY RTL. | E22: SET | F22: 1 | G22: 600000 | H22: =F22*G22 -> 600000
C23: SWING ARM | D23: VISION UNIT RTL. | E23: SET | F23: 1 | G23: 1500000 | H23: =F23*G23 -> 1500000
D24: 3AXIS ROBOT SUPERVISING | E24: SET | F24: 1 | G24: 4000000 | H24: =F24*G24 -> 4000000
C25: C/CAP N/R | D25: ROBOT TEACHING/PROGRAM | E25: SET | F25: 3 | G25: 10000000 | H25: =F25*G25 -> 30000000
D26: SAFETY FENCE RTL. | E26: SET | F26: 1 | G26: 3000000 | H26: =F26*G26 -> 3000000
C27: CVVD N/R | D27: BED EQUIPMENT | E27: SET | F27: 1 | G27: 6000000 | H27: =F27*G27 -> 6000000
D28: FRAME/SUPPORT | E28: SET | F28: 1 | G28: 6000000 | H28: =F28*G28 -> 6000000
D29: A/P CLAMP | E29: SET | F29: 1 | G29: 5000000 | H29: =F29*G29 -> 5000000
D30: N/R HEAD | E30: SET | F30: 4 | G30: 1000000 | H30: =F30*G30 -> 4000000
D31: N/R SHIFTING | E31: SET | F31: 4 | G31: 6300000 | H31: =F31*G31 -> 25200000
D32: N/R HEAD UP/DOWN | E32: SET | F32: 1 | G32: 4000000 | H32: =F32*G32 -> 4000000
D33: N/R SPINDLE | E33: SET | F33: 4 | G33: 850000 | H33: =F33*G33 -> 3400000
D34: N/R SOCKET | E34: SET | F34: 4 | G34: 40000 | H34: =F34*G34 -> 160000
D35: N/R PROGRAM | E35: SET | F35: 1 | G35: 2500000 | H35: =F35*G35 -> 2500000
D36: SAFETY EQUIPMENTS | E36: SET | F36: 1 | G36: 3000000 | H36: =F36*G36 -> 3000000
D37: BACKUP STATION RTL. | E37: SET | F37: 1 | G37: 1500000 | H37: =F37*G37 -> 1500000
B38: 전기
B39: 기계 노무비
B41: 전기 노무비
...

Sheet 120
C1: 120
B2: 구분 | C2: 장치 구분 | E2: 견적가 | I2: 비고
C3: 장치 | D3: 내 용 | E3: 단위 | F3: 수량 | G3: 단가(원) | H3: 견적(원)
C4: C/COVER ASS'Y | D4: ROBOT TEACHING/PROGRAM | E4: SET | F4: 1 | G4: 10000000 | H4: =F4*G4 -> 10000000
C5: SEALANT SPRAY | D5: 3AXIS ROBOT SUPERVISING | E5: SET | F5: 1 | G5: 4000000 | H5: =F5*G5 -> 4000000
D6: JIG FIXTURE | E6: SET | F6: 4 | G6: 1500000 | H6: =F6*G6 -> 6000000
D7: SEALING MASTER | E7: SET | F7: 2 | G7: 600000 | H7: =F7*G7 -> 1200000
C8: A/P TILTING | D8: BED EQUIPMENT | E8: SET | F8: 1 | G8: 6000000 | H8: =F8*G8 -> 6000000
D9: FRAME/SUPPORT | E9: SET | F9: 1 | G9: 4000000 | H9: =F9*G9 -> 4000000
D10: LONG STROKE LIFTER | E10: SET | F10: 1 | G10: 4000000 | H10: =F10*G10 -> 4000000
D11: A/P CLAMP UNIT | E11: SET | F11: 1 | G11: 5000000 | H11: =F11*G11 -> 5000000
D12: CLAMP TILTING | E12: SET | F12: 1 | G12: 5000000 | H12: =F12*G12 -> 5000000
D13: SAFETY EQUIPMENTS | E13: SET | F13: 1 | G13: 3000000 | H13: =F13*G13 -> 3000000
C14: C/COVER N/R | D14: N/R PROGRAM | E14: SET | F14: 1 | G14: 2500000 | H14: =F14*G14 -> 2500000
D15: ROBOT TEACHING/PROGRAM | E15: SET | F15: 3 | G15: 10000000 | H15: =F15*G15 -> 30000000
B16: 전기
B17: 기계 노무비
B19: 전기 노무비
B21: 기타
B24: 소계 | H24: =SUM(H4:H23) -> 80700000
B25: GRAND TOTAL | H25: =H24 -> 80700000

Sheet 130
C1: 130
B2: 구분 | C2: 장치 구분 | E2: 견적가 | I2: 비고
C3: 장치 | D3: 내 용 | E3: 단위 | F3: 수량 | G3: 단가(원) | H3: 견적(원)
C4: ROBOT TEACHING/PROGRAM | E4: SET | F4: 1 | G4: 10000000 | H4: =F4*G4 -> 10000000
C5: SEALING MASTER | E5: SET | F5: 2 | G5: 600000 | H5: =F5*G5 -> 1200000
C6: FRAME/SUPPORT | E6: SET | F6: 1 | G6: 2000000 | H6: =F6*G6 -> 2000000
C7: O/PAN CHECKER | E7: SET | F7: 1 | G7: 2000000 | H7: =F7*G7 -> 2000000
C8: ROBOT TEACHING/PROGRAM | E8: SET | F8: 2 | G8: 10000000 | H8: =F8*G8 -> 20000000
C9: SAFETY FENCE RTL. | E9: SET | F9: 1 | G9: 3000000 | H9: =F9*G9 -> 3000000
B10: 전기
B11: 기계 노무비
B13: 전기 노무비
B15: 기타
B18: 소계 | H18: =SUM(H4:H17) -> 38200000
B19: GRAND TOTAL | H19: =H18 -> 38200000

Sheet 140
C1: 140
B2: 구분 | C2: 장치 구분 | E2: 견적가 | I2: 비고
C3: 장치 | D3: 내 용 | E3: 단위 | F3: 수량 | G3: 단가(원) | H3: 견적(원)
B4: 기계 | C4: H/COVER ASS'Y | D4: BED EQUIPMENT | E4: SET | F4: 1 | G4: 6000000 | H4: =F4*G4 -> 6000000
D5: FRAME/SUPPORT | E5: SET | F5: 1 | G5: 6000000 | H5: =F5*G5 -> 6000000
D6: A/P CLAMP | E6: SET | F6: 1 | G6: 5000000 | H6: =F6*G6 -> 5000000
D7: CHECK VISION UNIT | E7: SET | F7: 1 | G7: 1500000 | H7: =F7*G7 -> 1500000
D8: LIGHT SHIELD ROOM | E8: SET | F8: 1 | G8: 2000000 | H8: =F8*G8 -> 2000000
D9: SAFETY EQUIPMENTS | E9: SET | F9: 1 | G9: 3000000 | H9: =F9*G9 -> 3000000
D10: BARCODE PRINTER PROGRAM | E10: SET | F10: 1 | G10: 2500000 | H10: =F10*G10 -> 2500000
D11: N/R PROGRAM | E11: SET | F11: 1 | G11: 2500000 | H11: =F11*G11 -> 2500000
D12: ROBOT TEACHING/PROGRAM | E12: SET | F12: 2 | G12: 10000000 | H12: =F12*G12 -> 20000000
D13: S/P JIG/INTERLOCK | E13: SET | F13: 9 | G13: 800000 | H13: =F13*G13 -> 7200000
C14: F/PUMP N/R | D14: N/R HEAD UP/DOWN RTL. | E14: SET | F14: 1 | G14: 4000000 | H14: =F14*G14 -> 4000000
D15: 2AXIS ROBOT SUPERVISING | E15: SET | F15: 1 | G15: 4000000 | H15: =F15*G15 -> 4000000
D16: N/R PROGRAM | E16: SET | F16: 1 | G16: 2500000 | H16: =F16*G16 -> 2500000
D17: TAPET CHECK | E17: SET | F17: 1 | G17: 1500000 | H17: =F17*G17 -> 1500000
D18: BACKUP RTL. | E18: SET | F18: 1 | G18: 500000 | H18: =F18*G18 -> 500000
D19: INJECTOR PUSHER RTL. | E19: SET | F19: 1 | G19: 1500000 | H19: =F19*G19 -> 1500000
C20: INJECTOR N/R | D20: N/R PROGRAM | E20: SET | F20: 1 | G20: 2500000 | H20: =F20*G20 -> 2500000
D21: SOCKET CHANGER | E21: SET | F21: 1 | G21: 1500000 | H21: =F21*G21 -> 1500000
D22: ROBOT TEACHING/PROGRAM | E22: SET | F22: 1 | G22: 10000000 | H22: =F22*G22 -> 10000000
B23: 전기
B24: 기계 노무비
B26: 전기 노무비
B28: 기타
B31: 소계 | H31: =SUM(H4:H30) -> 83700000
B32: GRAND TOTAL | H32: =H31 -> 83700000

Sheet 공통
C1: 140
B2: 구분 | C2: 장치 구분 | E2: 견적가 | I2: 비고
C3: 장치 | D3: 내 용 | E3: 단위 | F3: 수량 | G3: 단가(원) | H3: 견적(원)
B4: 기계 | C4: 표준 UNIT | D4: STOPPER & BRK'T | E4: SET | F4: 6 | G4: 600000 | H4: =F4*G4 -> 3600000
D5: WORK 도착,통과단 | E5: SET | F5: 6 | G5: 100000 | H5: =F5*G5 -> 600000
D6: LIFT UNIT | E6: SET | F6: 6 | G6: 3000000 | H6: =F6*G6 -> 18000000
C7: 전장부분 | D7: DUCT | E7: M | F7: 10 | G7: 200000 | H7: =F7*G7 -> 2000000
D8: POLE | E8: SET | F8: 8 | G8: 1000000 | H8: =F8*G8 -> 8000000
D9: BOX BRACKET | E9: SET | F9: 24 | G9: 150000 | H9: =F9*G9 -> 3600000
D10: ID CONTROLLER BOX | E10: SET | F10: 4 | G10: 800000 | H10: =F10*G10 -> 3200000
D11: SOL V/V BRACKET | E11: SET | F11: 16 | G11: 500000 | H11: =F11*G11 -> 8000000
D12: TERMINAL BOX | E12: SET | F12: 13 | G12: 600000 | H12: =F12*G12 -> 7800000
C13: PIP'G | D13: 공압 회로관련 부품 | E13: SET | F13: 1 | G13: 12000000 | H13: =F13*G13 -> 12000000
D14: LUB 회로관련 부품 | E14: SET | F14: 13 | G14: 500000 | H14: =F14*G14 -> 6500000
D15: 통신 밸브 | E15: SET | F15: 16 | G15: 1600000 | H15: =F15*G15 -> 25600000
D16: 배관공사 | E16: MD | F16: 32 | G16: 350000 | H16: =F16*G16 -> 11200000
B17: 전기 | C17: 제어반 | D17: 주 제어반 | E17: SET | F17: 8 | G17: 3000000 | H17: =F17*G17 -> 24000000
C18: 조작반 | D18: 부조작반 | E18: SET | F18: 11 | G18: 4000000 | H18: =F18*G18 -> 44000000
C19: PLC | D19: 추가 통신카드 | E19: EA | F19: 22 | G19: 1350000 | H19: =F19*G19 -> 29700000
D20: 입출력 카드 | E20: EA | F20: 26 | G20: 1050000 | H20: =F20*G20 -> 27300000
C21: ID | D21: ID ANT. | E21: SET | F21: 4 | G21: 600000 | H21: =F21*G21 -> 2400000
D22: ID CONTROLLER | E22: SET | F22: 4 | G22: 2500000 | H22: =F22*G22 -> 10000000
C23: HMI | D23: 주, 부조작반용 | E23: EA | F23: 11 | G23: 2500000 | H23: =F23*G23 -> 27500000
C24: 박스류 | D24: 리모트박스 | E24: EA | F24: 11 | G24: 3000000 | H24: =F24*G24 -> 33000000
D25: 터미날박스 | E25: EA | F25: 13 | G25: 900000 | H25: =F25*G25 -> 11700000
C26: 배선자재 | D26: CABLE, 단자대, 명판 등 | E26: SET | F26: 1 | G26: 5000000 | H26: =F26*G26 -> 5000000
B27: 기계 노무비 | C27: 설계 | D27: 메뉴얼작성 포함 | E27: M/D | F27: 90 | G27: 350000 | H27: =F27*G27 -> 31500000
C28: 조립 (국내) | D28: 조립 , 셋팅 | E28: M/D | F28: 40 | G28: 350000 | H28: =F28*G28 -> 14000000
C29: 시운전(국내) | D29: 단동&연동 무부하 | E29: M/D | F29: 20 | G29: 350000 | H29: =F29*G29 -> 7000000
C30: 기존라인 분해 (현지) | D30: 현지 해체 | E30: M/D | F30: 30 | G30: 350000 | H30: =F30*G30 -> 10500000
C31: 설치 (현지) | D31: 해체,입고,레이아웃 설치 | E31: M/D | F31: 150 | G31: 350000 | H31: =F31*G31 -> 52500000
C32: 시운전(현지) | D32: 셋팅&단동,연동 | E32: M/D | F32: 150 | G32: 350000 | H32: =F32*G32 -> 52500000
C33: 이벤트대응 | D33: P1(15일) ,P2 (15일) 기준 | E33: M/D | F33: 30 | G33: 350000 | H33: =F33*G33 -> 10500000
C34: 양산대응 | E34: M/D | F34: 30 | G34: 350000 | H34: =F34*G34 -> 10500000
C35: 교육 | D35: 통역포함 | E35: M/D | F35: 10 | H35: 9000000
B36: 전기 노무비 | C36: 설계 | D36: 메뉴얼작성 포함 | E36: M/D | F36: 90 | G36: 350000 | H36: =F36*G36 -> 31500000
C37: 판넬제작&외선 | E37: M/D | F37: 40 | G37: 350000 | H37: =F37*G37 -> 14000000
C38: 시운전(국내) | D38: 단동&연동 무부하 | E38: M/D | F38: 40 | G38: 350000 | H38: =F38*G38 -> 14000000
C39: 기존라인 분해 (현지) | E39: M/D | F39: 30 | G39: 350000 | H39: =F39*G39 -> 10500000
C40: 재배선 (현지) | E40: M/D | F40: 90 | G40: 350000 | H40: =F40*G40 -> 31500000
...

Sheet 비전
C1: 비전시스템
B2: 구분 | C2: 장치 구분 | E2: 견적가 | I2: 비고
C3: 장치 | D3: 내 용 | E3: 단위 | F3: 수량 | G3: 단가(원) | H3: 견적(원)
B4: 기계 | C4: 비전시스템 | D4: 제어컴퓨터 | E4: SET | F4: 10 | G4: 4370000 | H4: =F4*G4 -> 43700000
D5: 모니터 | E5: EA | F5: 12 | G5: 402500 | H5: =F5*G5 -> 4830000
D6: 기가랜카드 | E6: EA | F6: 12 | G6: 460000 | H6: =F6*G6 -> 5520000
D7: 라이센스키 | E7: EA | F7: 12 | G7: 5750000 | H7: =F7*G7 -> 69000000
D8: 검사프로그램 | E8: 식 | F8: 10 | G8: 9200000 | H8: =F8*G8 -> 92000000
D9: 교육 및 매뉴얼 | E9: 식 | F9: 12 | G9: 2300000 | H9: =F9*G9 -> 27600000
D10: 백업지원 | E10: 식 | F10: 16 | G10: 1150000 | H10: =F10*G10 -> 18400000
D11: PoE HUB | E11: EA | F11: 3 | G11: 690000 | H11: =F11*G11 -> 2070000
D12: 카메라 | E12: EA | F12: 8 | G12: 1380000 | H12: =F12*G12 -> 11040000
D13: 렌즈 | E13: EA | F13: 8 | G13: 345000 | H13: =F13*G13 -> 2760000
D14: 카메라 전원케이블 | E14: EA | F14: 8 | G14: 690000 | H14: =F14*G14 -> 5520000
D15: 카메라 영상케이블 | E15: SET | F15: 8 | G15: 805000 | H15: =F15*G15 -> 6440000
D16: 카메라 고정 브라켓 | E16: SET | F16: 5 | G16: 460000 | H16: =F16*G16 -> 2300000
... D35: 검사프로그램 | E35: 식 | F35: 2 | G35: 13800000 | H35: =F35*G35 -> 27600000
B36: 노무비 | C36: 설치 (국내) | E36: M/D | F36: 30 | G36: 500000 | H36: =F36*G36 -> 15000000
C37: 시운전 (국내) | E37: M/D | F37: 20 | G37: 500000 | H37: =F37*G37 -> 10000000
C38: 분해 | E38: M/D | F38: 6 | G38: 500000 | H38: =F38*G38 -> 3000000
C39: 설치 (현지) | E39: M/D | F39: 70 | G39: 700000 | H39: =F39*G39 -> 49000000
C40: 시운전 (현지) | E40: M/D | F40: 30 | G40: 700000 | H40: =F40*G40 -> 21000000
C41: 이벤트대응1 | E41: M/D | F41: 30 | G41: 700000 | H41: =F41*G41 -> 21000000
C42: 이벤트대응2 | E42: M/D | F42: 15 | G42: 700000 | H42: =F42*G42 -> 10500000
C43: 이벤트대응3 | E43: M/D | F43: 15 | G43: 700000 | H43: =F43*G43 -> 10500000
C44: 이벤트대응4 | E44: M/D | F44: 15 | G44: 700000 | H44: =F44*G44 -> 10500000
B46: 기타 | C46: 출장비 | E46: SET | F46: 1 | G46: 30000000 | H46: =G46*F46 -> 30000000
B49: 소계 | H49: =SUM(H4:H48) -> 632047500
B50: GRAND TOTAL | H50: =H49 -> 632047500

Sheet 실런트
C1: 실런트
B2: 구분 | C2: 장치 구분 | E2: 견적가 | I2: 비고
C3: 장치 | D3: 내 용 | E3: 단위 | F3: 수량 | G3: 단가(원) | H3: 견적(원)
B4: 기계 | C4: 실런트 유공압품 外 | D4: Regulator(A.O.P.R) | E4: SET | F4: 1 | G4: 3949900 | H4: =F4*G4 -> 3949900
D5: Heted Teflon Hose | E5: SET | F5: 1 | G5: 2400000 | H5: =F5*G5 -> 2400000
D6: Heted Teflon Hose | E6: SET | F6: 1 | G6: 2000000 | H6: =F6*G6 -> 2000000
D7: Heted Teflon Hose | E7: SET | F7: 1 | G7: 1600000 | H7: =F7*G7 -> 1600000
D8: H.P Teflon Hose | E8: SET | F8: 2 | G8: 400000 | H8: =F8*G8 -> 800000
D9: Manual Regulator | E9: SET | F9: 1 | G9: 1422900 | H9: =F9*G9 -> 1422900
D10: Nozzle Adapter | E10: SET | F10: 5 | G10: 37000 | H10: =F10*G10 -> 185000
D11: Nozzle | E11: SET | F11: 20 | G11: 2000 | H11: =F11*G11 -> 40000
D12: Pressure Senser & Cable | E12: SET | F12: 1 | G12: 1800000 | H12: =F12*G12 -> 1800000
D13: Regulator | E13: SET | F13: 1 | G13: 2200000 | H13: =F13*G13 -> 2200000
D14: Stator | E14: SET | F14: 1 | G14: 1850000 | H14: =F14*G14 -> 1850000
D15: Cartridge | E15: SET | F15: 1 | G15: 1500000 | H15: =F15*G15 -> 1500000
D16: Wave absorber | E16: SET | F16: 1 | G16: 1500000 | H16: =F16*G16 -> 1500000
... D22: 기타자재 | E22: SET | F22: 1 | G22: 100000 | H22: =F22*G22 -> 100000
B23: 기계 노무비 | C23: 시운전(현지) | E23: M/D | F23: 5 | G23: 500000 | H23: =F23*G23 -> 2500000
B25: 기타 | C25: 출장비 | E25: SET | F25: 1 | G25: 7500000 | H25: =G25*F25 -> 7500000
B28: 소계 | H28: =SUM(H4:H27) -> 39397800
B29: GRAND TOTAL | H29: =H28 -> 39397800

Sheet 툴네비게이트
C1: 툴네비게이트
B2: 구분 | C2: 장치 구분 | E2: 견적가 | I2: 비고
C3: 장치 | D3: 내 용 | E3: 단위 | F3: 수량 | G3: 단가(원) | H3: 견적(원)
B4: 기계 | C4: 실런트 유공압품 外 | D4: LPS Ultrasonic-Receiver CMS10-9-WL | E4: SET | F4: 2 | G4: 7430000 | H4: =F4*G4 -> 14860000
D5: Mounting plate Receiver | E5: SET | F5: 2 | G5: 80000 | H5: =F5*G5 -> 160000
D6: Mechanical accessories | E6: SET | F6: 2 | G6: 90000 | H6: =F6*G6 -> 180000
D7: Temperatur-Sensor | E7: SET | F7: 2 | G7: 500000 | H7: =F7*G7 -> 1000000
D8: TeGa Patchcable 15 m (ISO/IEC) | E8: SET | F8: 2 | G8: 80000 | H8: =F8*G8 -> 160000
D9: Industrial Gigabit PoE Switch 4+4 port | E9: SET | F9: 1 | G9: 660000 | H9: =F9*G9 -> 660000
D10: TeGa Patchcable 2,0 m (ISO/IEC) | E10: SET | F10: 2 | G10: 22000 | H10: =F10*G10 -> 44000
D11: Tool transmitter Wireless positioning Smart | E11: SET | F11: 3 | G11: 2510000 | H11: =F11*G11 -> 7530000
D12: Adapter plate Smart Wireless Triplet | E12: SET | F12: 3 | G12: 130000 | H12: =F12*G12 -> 390000
D13: Mounting set for wireless tags | E13: SET | F13: 3 | G13: 600000 | H13: =F13*G13 -> 1800000
D14: 2 port USB charger Anker | E14: SET | F14: 1 | G14: 60000 | H14: =F14*G14 -> 60000
D15: Charging / programming cable | E15: SET | F15: 3 | G15: 40000 | H15: =F15*G15 -> 120000
D16: Industrial-Box-PC VL2 BPC 7000 SAR 01 | E16: SET | F16: 1 | G16: 5500000 | H16: =F16*G16 -> 5500000
... D31: PC Rack | E31: SET | F31: 1 | G31: 950000 | H31: =F31*G31 -> 950000
B32: 기계 노무비 | C32: 시운전(현지) | E32: M/D | F32: 12 | G32: 500000 | H32: =F32*G32 -> 6000000
B34: 기타 | C34: 출장비 | E34: SET | F34: 1 | G34: 3000000 | H34: =G34*F34 -> 3000000
B37: 소계 | H37: =SUM(H4:H36) -> 62504000
B38: GRAND TOTAL | H38: =H37 -> 62504000

Sheet Sheet1
