Workbook

Sheet 갑지
B1: (현대/기아차 설비협력업체 견적통일양식)
B2: 見 積 書
B4: 현대 위아 貴下 | G4: 한로기술(주)
B5: 견적일자 | D5: 45976 | G5: 대표 : 장헌기
B6: 견적번호 | D6: HR251115-01 | G6: 주소 : 경기도 시흥시 달월길 78
B7: 납기 | C7: 입하 | D7: 2026 년 12월 일
C8: 최종검수 | D8: 2027 년 2 월 일 | G8: 전화: 031-498-6154
B9: 견적유효기간 | D9: 제출후 30 일 | G9: Fax: 031-498-6175
B10: 인도장소 | D10: 귀사 지정장소 | G10: 견적담당: | H10: 임종철 부사장
B11: 지불조건 | D11: 협의사항(FOB) | G11: 연 락 처 : | H11: 010-5316-1313
B13: 공사명 : | D13: 인도법인 푸네 CVJ 시험기(백래쉬, 비틀림내구, 비틀림파단, 회전내구)
B14: 견적금액 | D14: ="一金"&NUMBERSTRING(H14,1)&"원整" -> 一金이십사억일천구백팔십사만사천오백원整 | G14: 整(\ | H14: =H28*1000 -> 2419844500 | I14: )
B16: 번호 | C16: 상세품목내역 | E16: 견적금액 (천원) | I16: 비 고
E17: 기계부문 | F17: 전기부문 | G17: 관리/이윤 (안전관리비포함) | H17: 합 계
B18: 1 | C18: =단위장비1!C1 -> 백래쉬시험기 | E18: =IF('단위공사별(집계)'!N7>1,('단위공사별(집계)'!D7+'단위공사별(집계)'!E7+'단위공사별(집계)'!F7+'단위공사별(집계)'!G7+'단위공사별(집계)'!H7+'단위공사별(집계)'!I7)/1000," ") -> 206132.86 | F18: =IF('단위공사별(집계)'!N7>0,'단위공사별(집계)'!K17/1000,"") -> 423045 | G18: =IF('단위공사별(집계)'!N7>0,('단위공사별(집계)'!L7+'단위공사별(집계)'!M7)/1000,"") -> 10293.42 | H18: =IF('단위공사별(집계)'!N7>0,'단위공사별(집계)'!N7/1000,"") -> 262278.68
B19: 2 | C19: =단위장비2!C1 -> 비틀림내구시험기 | E19: =IF('단위공사별(집계)'!N8>1,('단위공사별(집계)'!D8+'단위공사별(집계)'!E8+'단위공사별(집계)'!F8+'단위공사별(집계)'!G8+'단위공사별(집계)'!H8+'단위공사별(집계)'!I8)/1000," ") -> 426177.49 | G19: =IF('단위공사별(집계)'!N8>0,('단위공사별(집계)'!L8+'단위공사별(집계)'!M8)/1000,"") -> 21281.536 | H19: =IF('단위공사별(집계)'!N8>0,'단위공사별(집계)'!N8/1000,"") -> 542258.38
B20: 3 | C20: =단위장비3!C1 -> 비틀림 파단시험기 | E20: =IF('단위공사별(집계)'!N9>1,('단위공사별(집계)'!D9+'단위공사별(집계)'!E9+'단위공사별(집계)'!F9+'단위공사별(집계)'!G9+'단위공사별(집계)'!H9+'단위공사별(집계)'!I9)/1000," ") -> 529285.79 | G20: =IF('단위공사별(집계)'!N9>0,('단위공사별(집계)'!L9+'단위공사별(집계)'!M9)/1000,"") -> 26430.337 | H20: =IF('단위공사별(집계)'!N9>0,'단위공사별(집계)'!N9/1000,"") -> 673451
B21: 4 | C21: =단위장비4!C1 -> 회전 내구 시험기 | E21: =IF('단위공사별(집계)'!N10>1,('단위공사별(집계)'!D10+'단위공사별(집계)'!E10+'단위공사별(집계)'!F10+'단위공사별(집계)'!G10+'단위공사별(집계)'!H10+'단위공사별(집계)'!I10)/1000," ") -> 740233.86 | G21: =IF('단위공사별(집계)'!N10>0,('단위공사별(집계)'!L10+'단위공사별(집계)'!M10)/1000,"") -> 36964.208 | H21: =IF('단위공사별(집계)'!N10>0,'단위공사별(집계)'!N10/1000,"") -> 941856.44
B22: 5 | C22: =단위장비5!C1 -> 0 | E22: =IF('단위공사별(집계)'!N11>1,('단위공사별(집계)'!D11+'단위공사별(집계)'!E11+'단위공사별(집계)'!F11+'단위공사별(집계)'!G11+'단위공사별(집계)'!H11+'단위공사별(집계)'!I11)/1000," ") | G22: =IF('단위공사별(집계)'!N11>0,('단위공사별(집계)'!L11+'단위공사별(집계)'!M11)/1000,"") | H22: =IF('단위공사별(집계)'!N11>0,'단위공사별(집계)'!N11/1000,"")
B23: 6 | C23: =단위장비6!C1 -> 0 | E23: =IF('단위공사별(집계)'!N12>1,('단위공사별(집계)'!D12+'단위공사별(집계)'!E12+'단위공사별(집계)'!F12+'단위공사별(집계)'!G12+'단위공사별(집계)'!H12+'단위공사별(집계)'!I12)/1000," ") | G23: =IF('단위공사별(집계)'!N12>0,('단위공사별(집계)'!L12+'단위공사별(집계)'!M12)/1000,"") | H23: =IF('단위공사별(집계)'!N12>0,'단위공사별(집계)'!N12/1000,"")
B24: 7 | C24: =단위장비7!C1 -> 0 | E24: =IF('단위공사별(집계)'!N13>1,('단위공사별(집계)'!D13+'단위공사별(집계)'!E13+'단위공사별(집계)'!F13+'단위공사별(집계)'!G13+'단위공사별(집계)'!H13+'단위공사별(집계)'!I13)/1000," ") | G24: =IF('단위공사별(집계)'!N13>0,('단위공사별(집계)'!L13+'단위공사별(집계)'!M13)/1000,"") | H24: =IF('단위공사별(집계)'!N13>0,'단위공사별(집계)'!N13/1000,"")
B25: 8 | C25: =단위장비8!C1 -> 0 | E25: =IF('단위공사별(집계)'!N14>1,('단위공사별(집계)'!D14+'단위공사별(집계)'!E14+'단위공사별(집계)'!F14+'단위공사별(집계)'!G14+'단위공사별(집계)'!H14+'단위공사별(집계)'!I14)/1000," ") | G25: =IF('단위공사별(집계)'!N14>0,('단위공사별(집계)'!L14+'단위공사별(집계)'!M14)/1000,"") | H25: =IF('단위공사별(집계)'!N14>0,'단위공사별(집계)'!N14/1000,"")
B26: 9 | C26: =단위장비9!C1 -> 0 | E26: =IF('단위공사별(집계)'!N15>1,('단위공사별(집계)'!D15+'단위공사별(집계)'!E15+'단위공사별(집계)'!F15+'단위공사별(집계)'!G15+'단위공사별(집계)'!H15+'단위공사별(집계)'!I15)/1000," ") | G26: =IF('단위공사별(집계)'!N15>0,('단위공사별(집계)'!L15+'단위공사별(집계)'!M15)/1000,"") | H26: =IF('단위공사별(집계)'!N15>0,'단위공사별(집계)'!N15/1000,"")
B27: 10 | C27: =단위장비10!C1 -> 0 | E27: =IF('단위공사별(집계)'!N16>1,('단위공사별(집계)'!D16+'단위공사별(집계)'!E16+'단위공사별(집계)'!F16+'단위공사별(집계)'!G16+'단위공사별(집계)'!H16+'단위공사별(집계)'!I16)/1000," ") | G27: =IF('단위공사별(집계)'!N16>0,('단위공사별(집계)'!L16+'단위공사별(집계)'!M16)/1000,"") | H27: =IF('단위공사별(집계)'!N16>0,'단위공사별(집계)'!N16/1000,"")
B28: 견적 합계 | E28: =SUM(E18:E27) -> 1901830 | F28: =SUM(F18) -> 423045 | G28: =SUM(G18:G27) -> 94969.5 | H28: =SUM(H18:H27) -> 2419844.5
F30: 공개입찰가 (견적時 공란) | H30: 2120000
B32: 특기사항 | C32: 1. VAT 제외 | F32: 외주계획 업체명 (자작時 공란)
C33: 2. 기본 유틸리티공사 제외 | F33: 설계외주
C34: ='원가항목별(집계)'!I39 -> 4128000 | F34: 제작외주
F35: 전기외주
F36: 설치외주

Sheet 원가항목별(집계)
C2: A. 원가항목별 견적가 종합(상세견적 첨부)
B4: □ 현대/기아 요구사양과 견적조건 일치여부 CHECK: 1.일치함 2.일부상이(상이내역 첨부참조)
B6: 순번 | C6: 원가구분 | F6: 단위 | G6: 수량 | H6: 단가 | I6: 금 액(원) | J6: 비 고
B7: 1 | C7: 기계 부문 | D7: 자재비 | E7: 철자재(SS.SUS등) | F7: kg | G7: =단위장비1!F34+단위장비2!F34+단위장비3!F35+단위장비5!F34+단위장비4!F35+단위장비6!F35+단위장비7!F35+단위장비8!F35+단위장비9!F35+단위장비10!F35 -> 0 | I7: =단위장비1!H23+단위장비2!H23+단위장비3!H24+단위장비5!H23+단위장비4!H24+단위장비6!H24+단위장비7!H24+단위장비8!H24+단위장비9!H24+단위장비10!H24 -> 558050000 | J7: 加工必要資材
E8: 일반구매품 | F8: 식 | G8: 1 | I8: =단위장비1!H61+단위장비2!H60+단위장비3!H56+단위장비5!H55+단위장비4!H60+단위장비6!H56+단위장비7!H56+단위장비8!H56+단위장비9!H56+단위장비10!H56 -> 771150000 | J8: 加工不要資材
E9: 외주제작품 | F9: 식 | G9: 1 | I9: =단위장비1!H82+단위장비2!H81+단위장비3!H77+단위장비5!H76+단위장비4!H81+단위장비6!H77+단위장비7!H77+단위장비8!H77+단위장비9!H77+단위장비10!H77 -> 338430000 | J9: 旣加工SUB資材
E10: 설치/해체 공사 자재 | F10: 식 | G10: 1 | I10: =단위장비1!H34+단위장비2!H34+단위장비3!H35+단위장비5!H34+단위장비4!H35+단위장비6!H35+단위장비7!H35+단위장비8!H35+단위장비9!H35+단위장비10!H35 -> 0 | J10: 시운전 자재 포함
E11: 소계 | I11: =SUM(I7:I10) -> 1667630000
D12: 노무비 | E12: 기존설비 철거 | F12: M/D | G12: =단위장비1!F84+단위장비2!F83+단위장비3!F79+단위장비5!F78+단위장비4!F83+단위장비6!F79+단위장비7!F79+단위장비8!F79+단위장비9!F79+단위장비10!F79 -> 0 | H12: =IF(단위장비1!G84>0,단위장비1!G84,"") | I12: =단위장비1!H84+단위장비2!H83+단위장비3!H79+단위장비5!H78+단위장비4!H83+단위장비6!H79+단위장비7!H79+단위장비8!H79+단위장비9!H79+단위장비10!H79 -> 0 | J12: 개조공사時
E13: 설계 | F13: M/D | G13: =단위장비1!F85+단위장비2!F84+단위장비3!F80+단위장비5!F79+단위장비4!F84+단위장비6!F80+단위장비7!F80+단위장비8!F80+단위장비9!F80+단위장비10!F80 -> 40 | H13: =IF(단위장비1!G85>0,단위장비1!G85,"") -> 500000 | I13: =단위장비1!H85+단위장비2!H84+단위장비3!H80+단위장비5!H79+단위장비4!H84+단위장비6!H80+단위장비7!H80+단위장비8!H80+단위장비9!H80+단위장비10!H80 -> 20000000
E14: 제작(제관,가공) | F14: M/D | G14: =단위장비1!F86+단위장비2!F85+단위장비3!F81+단위장비5!F80+단위장비4!F85+단위장비6!F81+단위장비7!F81+단위장비8!F81+단위장비9!F81+단위장비10!F81 -> 0 | H14: =IF(단위장비1!G86>0,단위장비1!G86,"") | I14: =단위장비1!H86+단위장비2!H85+단위장비3!H81+단위장비5!H80+단위장비4!H85+단위장비6!H81+단위장비7!H81+단위장비8!H81+단위장비9!H81+단위장비10!H81 -> 0
E15: 조립 | F15: M/D | G15: =단위장비1!F87+단위장비2!F86+단위장비3!F82+단위장비5!F81+단위장비4!F86+단위장비6!F82+단위장비7!F82+단위장비8!F82+단위장비9!F82+단위장비10!F82 -> 40 | H15: =IF(단위장비1!G87>0,단위장비1!G87,"") -> 500000 | I15: =단위장비1!H87+단위장비2!H86+단위장비3!H82+단위장비5!H81+단위장비4!H86+단위장비6!H82+단위장비7!H82+단위장비8!H82+단위장비9!H82+단위장비10!H82 -> 20000000 | J15: 정도검사포함
E16: 설치 | F16: M/D | G16: =단위장비1!F88+단위장비2!F87+단위장비3!F83+단위장비5!F82+단위장비4!F87+단위장비6!F83+단위장비7!F83+단위장비8!F83+단위장비9!F83+단위장비10!F83 -> 168 | H16: =IF(단위장비1!G88>0,단위장비1!G88,"") -> 650000 | I16: =단위장비1!H88+단위장비2!H87+단위장비3!H83+단위장비5!H82+단위장비4!H87+단위장비6!H83+단위장비7!H83+단위장비8!H83+단위장비9!H83+단위장비10!H83 -> 109200000
E17: 시운전 | F17: M/D | G17: =단위장비1!F89+단위장비2!F88+단위장비3!F84+단위장비5!F83+단위장비4!F88+단위장비6!F84+단위장비7!F84+단위장비8!F84+단위장비9!F84+단위장비10!F84 -> 0 | H17: =IF(단위장비1!G89>0,단위장비1!G89,"") | I17: =단위장비1!H89+단위장비2!H88+단위장비3!H84+단위장비5!H83+단위장비4!H88+단위장비6!H84+단위장비7!H84+단위장비8!H84+단위장비9!H84+단위장비10!H84 -> 0
E18: 양산대응 | F18: M/D | G18: =단위장비1!F90+단위장비2!F89+단위장비3!F85+단위장비5!F84+단위장비4!F89+단위장비6!F85+단위장비7!F85+단위장비8!F85+단위장비9!F85+단위장비10!F85 -> 0 | H18: =IF(단위장비1!G90>0,단위장비1!G90,"") | I18: =단위장비1!H90+단위장비2!H89+단위장비3!H85+단위장비5!H84+단위장비4!H89+단위장비6!H85+단위장비7!H85+단위장비8!H85+단위장비9!H85+단위장비10!H85 -> 0
E19: 도장 | F19: M/D | G19: =단위장비1!F91+단위장비2!F90+단위장비3!F86+단위장비5!F85+단위장비4!F90+단위장비6!F86+단위장비7!F86+단위장비8!F86+단위장비9!F86+단위장비10!F86 -> 0 | H19: =IF(단위장비1!G91>0,단위장비1!G91,"") | I19: =단위장비1!H91+단위장비2!H90+단위장비3!H86+단위장비5!H85+단위장비4!H90+단위장비6!H86+단위장비7!H86+단위장비8!H86+단위장비9!H86+단위장비10!H86 -> 0
E20: 소계 | I20: =SUM(I12:I19) -> 149200000
D21: 일반관리 및 이윤 | I21: =단위장비1!H94+단위장비1!H95+단위장비2!H93+단위장비2!H94+단위장비3!H89+단위장비3!H90+단위장비5!H88+단위장비5!H89+단위장비4!H93+단위장비4!H94+단위장비6!H89+단위장비6!H90+단위장비7!H89+단위장비7!H90+단위장비8!H89+단위장비8!H90+단위장비9!H89+단위장비9!H90+단위장비10!H89+단위장비10!H90 -> 90841500
E22: 기계 소계 | I22: =I20+I11+I21 -> 1907671500
B23: 2 | C23: 전기 부문 | D23: 자재비 | E23: 기계/전기자재 | F23: 식 | G23: 1 | I23: =전기!H80-I24 -> 373700000
E24: 설치/해체 공사 자재 | F24: 식 | G24: 1 | I24: =전기!H10 -> 0 | J24: 시운전 자재 포함
D25: 노무비 | E25: 철거(개조시) | F25: M/D | G25: =전기!F81 -> 0 | H25: =IF(전기!G81>0,전기!G81,"") | I25: =전기!H81 -> 0
E26: 설계,프로그램 | F26: M/D | G26: =전기!F82 -> 0 | H26: =IF(전기!G82>0,전기!G82,"") | I26: =전기!H82 -> 0
E27: 제작 | F27: M/D | G27: =전기!F83 -> 0 | H27: =IF(전기!G83>0,전기!G83,"") | I27: =전기!H83 -> 0
E28: 조립 | F28: M/D | G28: =전기!F84 -> 0 | H28: =IF(전기!G84>0,전기!G84,"") | I28: =전기!H84 -> 0
E29: 설치 | F29: M/D | G29: =전기!F85 -> 0 | H29: =IF(전기!G85>0,전기!G85,"") | I29: =전기!H85 -> 0
E30: 시운전 | F30: M/D | G30: =전기!F86 -> 0 | H30: =IF(전기!G86>0,전기!G86,"") | I30: =전기!H86 -> 0
E31: 양산대응 | F31: M/D | G31: =전기!F89 -> 150 | H31: =IF(전기!G89>0,전기!G89,"") -> 188000 | I31: =전기!H89 -> 28200000
E32: 소계 | I32: =SUM(I25:I31) -> 28200000
D33: 일반관리 및 이윤 | I33: =전기!H92+전기!H93 -> 21145000
E34: 전기 소계 | I34: =I32+I23+I33+I24 -> 423045000
B35: 3 | C35: 자재비 합계 | I35: =I23+I11+I24 -> 2041330000
C36: 노무비 합계 | I36: =I32+I20 -> 177400000
C37: 중간 합계 | I37: =I36+I35 -> 2218730000
B38: 4 | C38: 포장,운송 및 중장비 사용료 | I38: 85000000
B39: 5 | C39: 표준안전관리비 | F39: 설치/철거/수리금액 기준 | I39: =CEILING(MIN(I48:I49),1000) -> 4128000 | J39: =I30+I29+I25+I24+I17+I16+I12+I10 -> 109200000
B40: 6 | C40: 일반관리비 | I40: =전기!H92+단위장비1!H94+단위장비2!H93+단위장비3!H89+단위장비5!H88+단위장비4!H93+단위장비6!H89+단위장비7!H89+단위장비8!H89+단위장비9!H89+단위장비10!H89 -> 48865900
B41: 7 | C41: 이 윤 | I41: =전기!H93+단위장비1!H95+단위장비2!H94+단위장비3!H90+단위장비5!H89+단위장비4!H94+단위장비6!H90+단위장비7!H90+단위장비8!H90+단위장비9!H90+단위장비10!H90 -> 63120600
C42: 합 계 | F42: 3~7항 합계 | I42: =I22+I34+I38+I39 -> 2419844500
B43: 주1. 표준안전관리비:(설치/철거/시운전 공사 관련 금액)의
...

Sheet 단위공사별(집계)
A2: B. 단위장비별 견적가 종합(상세견적 첨부)
N3: 단위:원
I5: 포장/운송 | L5: 표준안전 | M5: 일반관리비 | R5: 한로기술 | T5: 에이포웰
A6: 순번 | B6: 단위장비명 | C6: 수량 | D6: 자재비 | E6: 철거 | F6: 제작 | G6: 설치/시운전 | H6: 양산대응 | I6: 중장비사용 | J6: 기계소계 | K6: 전기소계 | L6: 관리비 | M6: 이윤 | N6: 합 계 | O6: 비 고 | R6: 실적가
A7: =IF(B7>0,1,"") -> 1 | B7: =단위장비1!C$1 -> 백래쉬시험기 | C7: 1식 | D7: =단위장비1!H83 -> 171320000 | E7: =단위장비1!H84 -> 0 | F7: =단위장비1!H85+단위장비1!H86+단위장비1!H87+단위장비1!H91 -> 10000000 | G7: =단위장비1!H88+단위장비1!H89 -> 15600000 | H7: =단위장비1!H90 -> 0 | I7: =IF($B7>0,'원가항목별(집계)'!I$38*$P7/$P$17,0) -> 9212859.8 | J7: =SUM(D7:I7) -> 2.0613286e+08 | K7: =IF(B7>0,'원가항목별(집계)'!I$34*P7/P$17,0) -> 45852403 | L7: =IF($B7>0,'원가항목별(집계)'!I$39*$P7/$P$17,0) -> 447419.82 | M7: =단위장비1!H94+단위장비1!H95 -> 9846000 | N7: =SUM(J7:M7) -> 2.6227868e+08 | P7: =D7+E7+F7+G7+H7+M7 -> 206766000 | R7: 192609000 | S7: 유럽법인 CVJ 볼보 GPA 대응 PJT 백래쉬 측정기 (2023년)
A8: =IF(B8>0,A7+1,"") -> 2 | B8: =단위장비2!C$1 -> 비틀림내구시험기 | C8: 1식 | D8: =단위장비2!H82 -> 365930000 | E8: =단위장비2!H83 -> 0 | F8: =단위장비2!H84+단위장비2!H85+단위장비2!H86+단위장비2!H90 -> 10000000 | G8: =단위장비2!H87+단위장비2!H88 -> 31200000 | H8: =단위장비2!H89 -> 0 | I8: =IF($B8>0,'원가항목별(집계)'!I$38*$P8/$P$17,0) -> 19047489 | J8: =SUM(D8:I8) -> 4.2617749e+08 | K8: =IF(B8>0,'원가항목별(집계)'!I$34*P8/P$17,0) -> 94799354 | L8: =IF($B8>0,'원가항목별(집계)'!I$39*$P8/$P$17,0) -> 925035.72 | M8: =단위장비2!H93+단위장비2!H94 -> 20356500 | N8: =SUM(J8:M8) -> 5.4225838e+08 | P8: =D8+E8+F8+G8+H8+M8 -> 427486500 | S8: 인도 첸나이 (2023년)
A9: =IF(B9>0,A8+1,"") -> 3 | B9: =단위장비3!C$1 -> 비틀림 파단시험기 | C9: 1식 | D9: =단위장비3!H78 -> 464430000 | E9: =단위장비3!H79 -> 0 | F9: =단위장비3!H80+단위장비3!H81+단위장비3!H82+단위장비3!H86 -> 10000000 | G9: =단위장비3!H83+단위장비3!H84 -> 31200000 | H9: =단위장비3!H85 -> 0 | I9: =IF($B9>0,'원가항목별(집계)'!I$38*$P9/$P$17,0) -> 23655791 | J9: =SUM(D9:I9) -> 5.2928579e+08 | K9: =IF(B9>0,'원가항목별(집계)'!I$34*P9/P$17,0) -> 1.1773487e+08 | L9: =IF($B9>0,'원가항목별(집계)'!I$39*$P9/$P$17,0) -> 1148836.5 | M9: =단위장비3!H89+단위장비3!H90 -> 25281500 | N9: =SUM(J9:M9) -> 6.73451e+08 | P9: =D9+E9+F9+G9+H9+M9 -> 530911500 | T9: 548000000 | U9: 유럽법인 CVJ 볼보 GPA 대응 PJT 파단 시험기(2023년)
A10: =IF(B10>0,A9+1,"") -> 4 | B10: =단위장비4!C1 -> 회전 내구 시험기 | C10: 1식 | D10: =단위장비4!H82 -> 665950000 | E10: =단위장비4!H83 -> 0 | F10: =단위장비4!H84+단위장비4!H85+단위장비4!H86+단위장비4!H90 -> 10000000 | G10: =단위장비4!H87+단위장비4!H88 -> 31200000 | H10: =단위장비4!H89 -> 0 | I10: =IF($B10>0,'원가항목별(집계)'!I$38*$P10/$P$17,0) -> 33083860 | J10: =SUM(D10:I10) -> 7.4023386e+08 | K10: =IF(B10>0,'원가항목별(집계)'!I$34*P10/P$17,0) -> 1.6465837e+08 | L10: =IF($B10>0,'원가항목별(집계)'!I$39*$P10/$P$17,0) -> 1606707.9 | M10: =단위장비4!H93+단위장비4!H94 -> 35357500 | N10: =SUM(J10:M10) -> 9.4185644e+08 | P10: =D10+E10+F10+G10+H10+M10 -> 742507500 | S10: 인도 첸나이 (2023년) | V10: 강건화 요청 추가
A11: =IF(B11>0,A10+1,"") | B11: =단위장비5!C1 -> 0 | C11: 1식 | D11: =단위장비5!H77 -> 0 | E11: =단위장비5!H78 -> 0 | F11: =단위장비5!H79+단위장비5!H80+단위장비5!H81+단위장비5!H85 -> 0 | G11: =단위장비5!H82+단위장비5!H83 -> 0 | H11: =단위장비5!H84 -> 0 | I11: =IF($B11>0,'원가항목별(집계)'!I$38*$P11/$P$17,0) -> 0 | J11: =SUM(D11:I11) -> 0 | K11: =IF(B11>0,'원가항목별(집계)'!I$34*P11/P$17,0) -> 0 | L11: =IF($B11>0,'원가항목별(집계)'!I$39*$P11/$P$17,0) -> 0 | M11: =단위장비5!H88+단위장비5!H89 -> 0 | N11: =SUM(J11:M11) -> 0 | P11: =D11+E11+F11+G11+H11+M11 -> 0
A12: =IF(B12>0,A11+1,"") | B12: =단위장비6!C$1 -> 0 | C12: 1식 | D12: =단위장비6!H78 -> 0 | E12: =단위장비6!H79 -> 0 | F12: =단위장비6!H80+단위장비6!H81+단위장비6!H82+단위장비6!H86 -> 0 | G12: =단위장비6!H83+단위장비6!H84 -> 0 | H12: =단위장비6!H85 -> 0 | I12: =IF($B12>0,'원가항목별(집계)'!I$38*$P12/$P$17,0) -> 0 | J12: =SUM(D12:I12) -> 0 | K12: =IF(B12>0,'원가항목별(집계)'!I$34*P12/P$17,0) -> 0 | L12: =IF($B12>0,'원가항목별(집계)'!I$39*$P12/$P$17,0) -> 0 | M12: =단위장비6!H89+단위장비6!H90 -> 0 | N12: =SUM(J12:M12) -> 0 | P12: =D12+E12+F12+G12+H12+M12 -> 0
A13: =IF(B13>0,A12+1,"") | B13: =단위장비7!C$1 -> 0 | C13: 1식 | D13: =단위장비7!H78 -> 0 | E13: =단위장비7!H79 -> 0 | F13: =단위장비7!H80+단위장비7!H81+단위장비7!H82+단위장비7!H86 -> 0 | G13: =단위장비7!H83+단위장비7!H84 -> 0 | H13: =단위장비7!H85 -> 0 | I13: =IF($B13>0,'원가항목별(집계)'!I$38*$P13/$P$17,0) -> 0 | J13: =SUM(D13:I13) -> 0 | K13: =IF(B13>0,'원가항목별(집계)'!I$34*P13/P$17,0) -> 0 | L13: =IF($B13>0,'원가항목별(집계)'!I$39*$P13/$P$17,0) -> 0 | M13: =단위장비7!H89+단위장비7!H90 -> 0 | N13: =SUM(J13:M13) -> 0 | P13: =D13+E13+F13+G13+H13+M13 -> 0
A14: =IF(B14>0,A13+1,"") | B14: =단위장비8!C$1 -> 0 | C14: 1식 | D14: =단위장비8!H78 -> 0 | E14: =단위장비8!H79 -> 0 | F14: =단위장비8!H80+단위장비8!H81+단위장비8!H82+단위장비8!H86 -> 0 | G14: =단위장비8!H83+단위장비8!H84 -> 0 | H14: =단위장비8!H85 -> 0 | I14: =IF($B14>0,'원가항목별(집계)'!I$38*$P14/$P$17,0) -> 0 | J14: =SUM(D14:I14) -> 0 | K14: =IF(B14>0,'원가항목별(집계)'!I$34*P14/P$17,0) -> 0 | L14: =IF($B14>0,'원가항목별(집계)'!I$39*$P14/$P$17,0) -> 0 | M14: =단위장비8!H89+단위장비8!H90 -> 0 | N14: =SUM(J14:M14) -> 0 | P14: =D14+E14+F14+G14+H14+M14 -> 0
A15: =IF(B15>0,A14+1,"") | B15: =단위장비9!C$1 -> 0 | C15: 1식 | D15: =단위장비9!H79 -> 0 | E15: =단위장비9!H80 -> 0 | F15: =단위장비9!H81+단위장비9!H82+단위장비9!H83+단위장비9!H87 -> 0 | G15: =단위장비9!H84+단위장비9!H85 -> 0 | H15: =단위장비9!H86 -> 0 | I15: =IF($B15>0,'원가항목별(집계)'!I$38*$P15/$P$17,0) -> 0 | J15: =SUM(D15:I15) -> 0 | K15: =IF(B15>0,'원가항목별(집계)'!I$34*P15/P$17,0) -> 0 | L15: =IF($B15>0,'원가항목별(집계)'!I$39*$P15/$P$17,0) -> 0 | M15: =단위장비9!H90+단위장비9!H91 -> 0 | N15: =SUM(J15:M15) -> 0 | P15: =D15+E15+F15+G15+H15+M15 -> 0
A16: =IF(B16>0,A15+1,"") | B16: =단위장비10!C$1 -> 0 | C16: 1식 | D16: =단위장비10!H80 -> 0 | E16: =단위장비10!H81 -> 0 | F16: =단위장비10!H82+단위장비10!H83+단위장비10!H84+단위장비10!H88 -> 0 | G16: =단위장비10!H85+단위장비10!H86 -> 0 | H16: =단위장비10!H87 -> 0 | I16: =IF($B16>0,'원가항목별(집계)'!I$38*$P16/$P$17,0) -> 0 | J16: =SUM(D16:I16) -> 0 | K16: =IF(B16>0,'원가항목별(집계)'!I$34*P16/P$17,0) -> 0 | L16: =IF($B16>0,'원가항목별(집계)'!I$39*$P16/$P$17,0) -> 0 | M16: =단위장비10!H91+단위장비10!H92 -> 0 | N16: =SUM(J16:M16) -> 0 | P16: =D16+E16+F16+G16+H16+M16 -> 0
A17: 합 계 | D17: =SUM(D7:D16) -> 1667630000 | E17: =SUM(E7:E16) -> 0 | F17: =SUM(F7:F16) -> 40000000 | G17: =SUM(G7:G16) -> 109200000 | H17: =SUM(H7:H16) -> 0 | I17: =SUM(I7:I16) -> 85000000 | J17: =SUM(D17:I17) -> 1901830000 | K17: =SUM(K7:K16) -> 423045000 | L17: =SUM(L7:L16) -> 4128000 | M17: =SUM(M7:M16) -> 90841500 | N17: =SUM(N7:N14) -> 2419844500 | P17: =SUM(P7:P16) -> 1907671500
D18: =IF(D17=0,"",D17/$N17) -> 0.68914759 | E18: =IF(E17=0,"",E17/$N17) | F18: =IF(F17=0,"",F17/$N17) -> 0.016529988 | G18: =IF(G17=0,"",G17/$N17) -> 0.045126867 | H18: =IF(H17=0,"",H17/$N17) | I18: =IF(I17=0,"",I17/$N17) -> 0.035126224 | J18: =IF(J17=0,"",J17/$N17) -> 0.78593067 | K18: =IF(K17=0,"",K17/$N17) -> 0.17482322 | ... N18: =IF(N17=0,"",N17/$N17) -> 1
A19: 주) 전기비용은 턴키장비의 공통비용으로서 총 전기비용을 단위장비별 기계금액의 비율에 따라 배분함
N20: =IF('원가항목별(집계)'!I42='단위공사별(집계)'!N17,"","DATA오류입니다!")

Sheet 전기
B1: □ 전기부문: | C1: 전기장치 | I1: (첨부)
A2: 구분 | C2: 품 명 | D2: 규격 | E2: 단위 | F2: 수량 | G2: 단가(원) | H2: 금액(원) | I2: 原MAKER
A3: 자 재 비 | B3: 철자재 | H3: =IF(F3=0,G3,G3*F3) -> 0
H4: =IF(F4=0,G4,G4*F4) -> 0
H5: =IF(F5=0,G5,G5*F5) -> 0
H6: =SUM(H3:H5) -> 0
B7: 설치/해체/ | H7: =IF(F7=0,G7,G7*F7) -> 0
B8: 시운전 공사 | H8: =IF(F8=0,G8,G8*F8) -> 0
H9: =IF(F9=0,G9,G9*F9) -> 0
H10: =SUM(H7:H9) -> 0
B11: 백래쉬 시험기 | C11: CONTROL RACK | D11: 표준형 19" | E11: EA | F11: 1 | G11: 2800000 | H11: =IF(F11=0,G11,G11*F11) -> 2800000 | I11: 신우엔텍
C12: CONTROL TORQUE & ANGLE AMP. | E12: EA | F12: 1 | G12: 9000000 | H12: =IF(F12=0,G12,G12*F12) -> 9000000 | I12: 조이콘트롤
C13: PLC SYSTEM | E13: SET | F13: 1 | G13: 7000000 | H13: =IF(F13=0,G13,G13*F13) -> 7000000 | I13: 형제
C14: CONNECTION REMOTE CONTROL/WIRING | E14: SET | F14: 1 | G14: 6000000 | H14: =IF(F14=0,G14,G14*F14) -> 6000000 | I14: 형제
C15: INDICATOR | E15: SET | F15: 1 | G15: 3000000 | H15: =IF(F15=0,G15,G15*F15) -> 3000000 | I15: 조이콘트롤
C16: MOVING CONTROL | E16: SET | F16: 1 | G16: 2000000 | H16: =IF(F16=0,G16,G16*F16) -> 2000000 | I16: 조이콘트롤
C17: 부자재 | E17: SET | F17: 1 | G17: 1500000 | H17: =IF(F17=0,G17,G17*F17) -> 1500000
C18: AVR(UPS) | D18: KSP-9100A | E18: SYS | F18: 1 | G18: 9000000 | H18: =IF(F18=0,G18,G18*F18) -> 9000000 | I18: 삼풍
C19: 제어용 COMPUTER | D19: 모니터, MS OFFICE | E19: SET | F19: 2 | G19: 4500000 | H19: =IF(F19=0,G19,G19*F19) -> 9000000 | I19: ADVENTEC
C20: 7) UPS(2.0KVA) | D20: HAP-920 | E20: SET | F20: 2 | G20: 1000000 | H20: =IF(F20=0,G20,G20*F20) -> 2000000 | I20: 삼풍
H21: =IF(F21=0,G21,G21*F21) -> 0
C22: ***주기*** | H22: =IF(F22=0,G22,G22*F22) -> 0
C23: 1) 1차 전원공사 및 냉각수, 에어공사-현대위아에서 | H23: =IF(F23=0,G23,G23*F23) -> 0
C24: 2) 설비(LAYOUT) 위치이동-현대위아에서 | H24: =IF(F24=0,G24,G24*F24) -> 0
H25: =IF(F25=0,G25,G25*F25) -> 0
B26: 비틀림 내구 | C26: CONTROL SYSTEM | H26: =IF(F26=0,G26,G26*F26) -> 0
B27: 시험기 | C27: 1. 19" RACK | E27: EA | F27: 1 | G27: 2800000 | H27: =IF(F27=0,G27,G27*F27) -> 2800000 | I27: 신우엔텍
C28: 2. DIGITAL AMP. | E28: SET | F28: 1 | G28: 25000000 | H28: =IF(F28=0,G28,G28*F28) -> 25000000 | I28: HANRO
C29: 1) ANGLE AMP/CPU AMP | H29: =IF(F29=0,G29,G29*F29) -> 0
C30: 2) DIGITAL I/O 12CH | H30: =IF(F30=0,G30,G30*F30) -> 0
C31: 3) DIGITAL D/O 32CH | H31: =IF(F31=0,G31,G31*F31) -> 0
C32: 3. ELECTRIC PARTS(MAIN BODY,UPPER&LOWER) | E32: SYS | F32: 1 | G32: 12000000 | H32: =IF(F32=0,G32,G32*F32) -> 12000000 | I32: 형제
C33: 4. PLC CONTROL & CABLE WIRING | E33: SYS | F33: 1 | G33: 8000000 | H33: =IF(F33=0,G33,G33*F33) -> 8000000 | I33: 조이콘트롤
C34: 5. PANEL | D34: 2300x1500x800 | E34: SYS | F34: 2 | G34: 8000000 | H34: =IF(F34=0,G34,G34*F34) -> 16000000 | I34: 화신
C35: 6. PLC & PROGRAM | E35: SYS | F35: 1 | G35: 4000000 | H35: =IF(F35=0,G35,G35*F35) -> 4000000 | I35: 조이콘트롤
C36: 7. REMOTE CONTROL | D36: 유선 | E36: SET | F36: 1 | G36: 2000000 | H36: =IF(F36=0,G36,G36*F36) -> 2000000 | I36: 형제
C37: 8. 부자재 | E37: 식 | F37: 1 | G37: 2000000 | H37: =IF(F37=0,G37,G37*F37) -> 2000000 | I37: 형제
C38: 9.AVR(UPS) | E38: SYS | F38: 1 | G38: 25000000 | H38: =IF(F38=0,G38,G38*F38) -> 25000000 | I38: 삼풍
H39: =IF(F39=0,G39,G39*F39) -> 0
C40: ***주기*** | H40: =IF(F40=0,G40,G40*F40) -> 0
...

Sheet 단위장비1
B1: □ 단위공사명(전기제외): | C1: 백래쉬시험기 | I1: (첨부)
A2: 구분 | C2: 품 명 | D2: 규격 | E2: 단위 | F2: 수량 | G2: 단가(원) | H2: 금액(원) | I2: 原MAKER
A3: 자 재 비 | B3: 철자재 | C3: MAIN BODY | D3: 600x2000x1200 | E3: EA | F3: 1 | G3: 32000000 | H3: =IF(F3=0,G3,G3*F3) -> 32000000 | I3: NSP
C4: MOVING SYSTEM | E4: SYS | F4: 1 | G4: 9000000 | H4: =F4*G4 -> 9000000 | I4: 동광테크
C5: SLIDE & AIR CLAMP TYPE | D5: 유압 UNIT | E5: SET | F5: 2 | G5: 8000000 | H5: =F5*G5 -> 16000000 | I5: KCC
C6: ANGLE 검출 SYSTEM | E6: SYS | F6: 3 | G6: 2350000 | H6: =F6*G6 -> 7050000 | I6: 동광테크
C7: COLLUE CHUCK PART | E7: SYS | F7: 2 | G7: 2500000 | H7: =F7*G7 -> 5000000 | I7: 아성정밀
C8: ROAD PART | E8: SYS | F8: 1 | G8: 2000000 | H8: =IF(F8=0,G8,G8*F8) -> 2000000 | I8: 아성정밀
C9: 부자재 | E9: 식 | F9: 1 | G9: 1500000 | H9: =IF(F9=0,G9,G9*F9) -> 1500000
H10: =F10*G10 -> 0
H11: =F11*G11 -> 0
H12: =IF(F12=0,G12,G12*F12) -> 0
H13: 0
H14: =F14*G14 -> 0
H15: =F15*G15 -> 0
H16: =IF(F16=0,G16,G16*F16) -> 0
H17: 0
H18: =F18*G18 -> 0
H19: =F19*G19 -> 0
H20: =IF(F20=0,G20,G20*F20) -> 0
H21: =IF(F21=0,G21,G21*F21) -> 0
H22: =IF(F22=0,G22,G22*F22) -> 0
H23: =SUM(H3:H22) -> 72550000
B24: 설치/해체/시운전 | H24: =IF(F24=0,G24,G24*F24) -> 0
B25: 공사 관련 자재 | H25: =IF(F25=0,G25,G25*F25) -> 0
H26: =IF(F26=0,G26,G26*F26) -> 0
H27: =IF(F27=0,G27,G27*F27) -> 0
H28: =IF(F28=0,G28,G28*F28) -> 0
H29: =IF(F29=0,G29,G29*F29) -> 0
H30: =IF(F30=0,G30,G30*F30) -> 0
H31: =IF(F31=0,G31,G31*F31) -> 0
H32: =IF(F32=0,G32,G32*F32) -> 0
H33: =IF(F33=0,G33,G33*F33) -> 0
H34: =SUM(H24:H33) -> 0
B35: 구매품 | C35: SERVO MOTOR&DRIVE | D35: ±20kgf.m | E35: SET | F35: 1 | G35: 7000000 | H35: =IF(F35=0,G35,G35*F35) -> 7000000 | I35: MITSUBISHI
B36: (유공압품외) | C36: TORQUE CELL | D36: 500KN | E36: EA | F36: 1 | G36: 9500000 | H36: =IF(F36=0,G36,G36*F36) -> 9500000 | I36: NTS
C37: ANGLE SENSOR | D37: ±360˚, 360,000P | E37: EA | F37: 1 | G37: 8500000 | H37: =IF(F37=0,G37,G37*F37) -> 8500000 | I37: GURLEY
C38: 이송모터 & 감속기 | E38: SET | F38: 1 | G38: 3000000 | H38: =IF(F38=0,G38,G38*F38) -> 3000000 | I38: SPG/LS
C39: MAGNETIC SCALE | E39: SET | F39: 3 | G39: 1500000 | H39: =IF(F39=0,G39,G39*F39) -> 4500000 | I39: KEYENCE
C40: TEMPERATURE SENSOR | D40: 비접촉 0~200 | E40: SET | F40: 2 | G40: 2000000 | H40: =IF(F40=0,G40,G40*F40) -> 4000000 | I40: KEYENCE
...

Sheet 단위장비2
B1: □ 단위공사명(전기제외): | C1: 비틀림내구시험기 | I1: (첨부)
A2: 구분 | C2: 품 명 | D2: 규격 | E2: 단위 | F2: 수량 | G2: 단가(원) | H2: 금액(원) | I2: 原MAKER
A3: 자 재 비 | B3: 철자재 | C3: MACANICAL UNIT
C4: 1. MAIN BASE (주물100T) | D4: L4000xW1500xH17500mm | E4: SYS | F4: 1 | G4: 70000000 | H4: =F4*G4 -> 70000000 | I4: NSP
C5: 2. 기계장치 | D5: 200~1400/0~600/±100 | E5: SET | F5: 4 | G5: 9000000 | H5: =F5*G5 -> 36000000 | I5: 동광테크
D6: 0~60˚ | H6: =F6*G6 -> 0
C7: 3. 이송모터 & 감속기 | D7: 4 PLACE | E7: SET | F7: 4 | G7: 3750000 | H7: =F7*G7 -> 15000000 | I7: DKM
C8: 4. 부속품 및 기타 | E8: SYS | F8: 1 | G8: 2000000 | H8: =F8*G8 -> 2000000 | I8: HT/SPG
C9: 5. 안전커버 | E9: SYS | F9: 1 | G9: 8000000 | H9: =F9*G9 -> 8000000 | I9: 동광테크
H10: =F10*G10 -> 0
H11: =F11*G11 -> 0
H12: =F12*G12 -> 0
H13: =F13*G13 -> 0
H14: =F14*G14 -> 0
H15: =F15*G15 -> 0
H16: =F16*G16 -> 0
H17: =F17*G17 -> 0
H18: =F18*G18 -> 0
H19: =F19*G19 -> 0
H20: =IF(F20=0,G20,G20*F20) -> 0
H21: =IF(F21=0,G21,G21*F21) -> 0
H22: =IF(F22=0,G22,G22*F22) -> 0
H23: =SUM(H3:H22) -> 131000000
B24: 설치/해체/시운전 | H24: =IF(F24=0,G24,G24*F24) -> 0
B25: 공사 관련 자재 | H25: =IF(F25=0,G25,G25*F25) -> 0
H26: =IF(F26=0,G26,G26*F26) -> 0
H27: =IF(F27=0,G27,G27*F27) -> 0
H28: =IF(F28=0,G28,G28*F28) -> 0
H29: =IF(F29=0,G29,G29*F29) -> 0
H30: =IF(F30=0,G30,G30*F30) -> 0
H31: =IF(F31=0,G31,G31*F31) -> 0
H32: =IF(F32=0,G32,G32*F32) -> 0
H33: =IF(F33=0,G33,G33*F33) -> 0
H34: =SUM(H24:H33) -> 0
B35: 구매품 | C35: 구동 UNIT
B36: (유공압품외) | C36: 1. TORQUE MOTOR | D36: 110KW, 7000N.m | E36: EA | F36: 1 | G36: 95000000 | H36: =IF(F36=0,G36,G36*F36) -> 95000000 | I36: SIEMENS
C37: 2. MOTOR DRIVE | D37: 5000Nm | E37: EA | F37: 1 | G37: 15000000 | H37: =IF(F37=0,G37,G37*F37) -> 15000000 | I37: SIEMENS
C38: 3. WATER COOLING(CHILLER) | D38: 7000Kcal/h | E38: EA | F38: 1 | G38: 12000000 | H38: =IF(F38=0,G38,G38*F38) -> 12000000 | I38: 포스텍
C39: 4. TORQUE METER | D39: 10000Nm | E39: EA | F39: 1 | G39: 30000000 | H39: =IF(F39=0,G39,G39*F39) -> 30000000 | I39: HBM
C40: - MAGNETIC SCALE-1300/300 | H40: =IF(F40=0,G40,G40*F40) -> 0 | I40: JENIX
...

Sheet 단위장비3
B1: □ 단위공사명(전기제외): | C1: 비틀림 파단시험기 | I1: (첨부)
A2: 구분 | C2: 품 명 | D2: 규격 | E2: 단위 | F2: 수량 | G2: 단가(원) | H2: 금액(원) | I2: 原MAKER
A3: 자 재 비 | B3: 철자재 | C3: 1. MAIN BED | D3: 5000x2700x200mm | E3: SYS | F3: 1 | G3: 95000000 | H3: =IF(F3=0,G3,G3*F3) -> 95000000 | I3: NSP
C4: (주물 100T이상) | D4: SYSTEM 장착 가공 | H4: =F4*G4 -> 0
C5: 2. TORQUE측 MOVING | D5: 65˚/500mm | E5: SET | F5: 1 | G5: 30000000 | H5: =F5*G5 -> 30000000 | I5: SPG
C6: /SPECIMEN FIXING LENGTH 200~1200mm MOVING | H6: =F6*G6 -> 0
C7: 3. 부자재 | F7: 1 | G7: 3500000 | H7: =F7*G7 -> 3500000
H8: =IF(F8=0,G8,G8*F8) -> 0
H9: =IF(F9=0,G9,G9*F9) -> 0
H10: =IF(F10=0,G10,G10*F10) -> 0
H11: =IF(F11=0,G11,G11*F11) -> 0
H12: =IF(F12=0,G12,G12*F12) -> 0
H13: =IF(F13=0,G13,G13*F13) -> 0
H14: =IF(F14=0,G14,G14*F14) -> 0
H15: =IF(F15=0,G15,G15*F15) -> 0
H16: =IF(F16=0,G16,G16*F16) -> 0
H17: =IF(F17=0,G17,G17*F17) -> 0
H18: =IF(F18=0,G18,G18*F18) -> 0
H19: =IF(F19=0,G19,G19*F19) -> 0
... H23: =IF(F23=0,G23,G23*F23) -> 0
H24: =SUM(H3:H23) -> 128500000
B25: 설치/해체/시운전 | H25: =IF(F25=0,G25,G25*F25) -> 0
B26: 공사 관련 자재 | H26: =IF(F26=0,G26,G26*F26) -> 0
H27: =IF(F27=0,G27,G27*F27) -> 0
H28: =IF(F28=0,G28,G28*F28) -> 0
H29: =IF(F29=0,G29,G29*F29) -> 0
H30: =IF(F30=0,G30,G30*F30) -> 0
H31: =IF(F31=0,G31,G31*F31) -> 0
H32: =IF(F32=0,G32,G32*F32) -> 0
H33: =IF(F33=0,G33,G33*F33) -> 0
H34: =IF(F34=0,G34,G34*F34) -> 0
H35: =SUM(H25:H34) -> 0
B36: 구매품 | C36: 1. MOTOR | E36: SET | F36: 2 | G36: 45000000 | H36: =IF(F36=0,G36,G36*F36) -> 90000000 | I36: SIEMENS
B37: (유공압품외) | C37: /MAX. TORQUE ±20kN.m
C38: 2. 감속기 | E38: SET | F38: 2 | G38: 30000000 | H38: =IF(F38=0,G38,G38*F38) -> 60000000 | I38: BREVINI
C39: 3. TORQUE TRANSDUCER | E39: SET | F39: 2 | G39: 33000000 | H39: =IF(F39=0,G39,G39*F39) -> 66000000 | I39: HBM
C40: 4. ANGLE SENSOR | E40: SET | F40: 2 | G40: 1500000 | H40: =IF(F40=0,G40,G40*F40) -> 3000000 | I40: OMRON
C41: 5. MAGNETIC SCALE | E41: SET | F41: 3 | G41: 1500000 | H41: =IF(F41=0,G41,G41*F41) -> 4500000 | I41: 동광
C42: 6.TEMPERATURE SENSOR | D42: 비접촉 0~200 | E42: SET | F42: 4 | G42: 2000000 | H42: =IF(F42=0,G42,G42*F42) -> 8000000 | I42: KEYENCE
C43: DATA ACQUISITION | H43: =IF(F43=0,G43,G43*F43) -> 0
...

Sheet 단위장비4
B1: □ 단위공사명(전기제외): | C1: 회전 내구 시험기 | I1: (첨부)
A2: 구분 | C2: 품 명 | D2: 규격 | E2: 단위 | F2: 수량 | G2: 단가(원) | H2: 금액(원) | I2: 原MAKER
A3: 자 재 비 | B3: 철자재 | C3: MACANICAL UNIT
C4: 1. MAIN BED(해석포함) | D4: L6300xW2100xH2800mm | E4: SYS | F4: 1 | G4: 150000000 | H4: =F4*G4 -> 150000000 | I4: NSP
C5: 2. 기계장치 구조물 | D5: Motor&Torque Bed | E5: SET | F5: 3 | G5: 10000000 | H5: =F5*G5 -> 30000000 | I5: 동광테크
D6: LM, 부자재 | H6: =F6*G6 -> 0
C7: 3. 베이스 이송 유닛 | D7: Jounce, 기어박스 | E7: SET | F7: 2 | G7: 10000000 | H7: =F7*G7 -> 20000000 | I7: LS
C8: 4. 안전커버 | E8: SET | F8: 1 | G8: 10000000 | H8: =F8*G8 -> 10000000 | I8: 동광테크
C9: 6. AIR BLOWER PART | E9: SET | F9: 8 | G9: 2000000 | H9: =F9*G9 -> 16000000 | I9: 아성정밀
H10: =IF(F10=0,G10,G10*F10) -> 0
H11: =IF(F11=0,G11,G11*F11) -> 0
H12: =IF(F12=0,G12,G12*F12) -> 0
H13: =IF(F13=0,G13,G13*F13) -> 0
H14: =IF(F14=0,G14,G14*F14) -> 0
H15: =IF(F15=0,G15,G15*F15) -> 0
H16: =IF(F16=0,G16,G16*F16) -> 0
H17: =IF(F17=0,G17,G17*F17) -> 0
H18: =IF(F18=0,G18,G18*F18) -> 0
H19: =IF(F19=0,G19,G19*F19) -> 0
H20: =IF(F20=0,G20,G20*F20) -> 0
H21: =IF(F21=0,G21,G21*F21) -> 0
... H23: =IF(F23=0,G23,G23*F23) -> 0
H24: =SUM(H3:H23) -> 226000000
B25: 설치/해체/시운전 | H25: =IF(F25=0,G25,G25*F25) -> 0
B26: 공사 관련 자재 | H26: =IF(F26=0,G26,G26*F26) -> 0
H27: =IF(F27=0,G27,G27*F27) -> 0
H28: =IF(F28=0,G28,G28*F28) -> 0
H29: =IF(F29=0,G29,G29*F29) -> 0
H30: =IF(F30=0,G30,G30*F30) -> 0
H31: =IF(F31=0,G31,G31*F31) -> 0
H32: =IF(F32=0,G32,G32*F32) -> 0
H33: =IF(F33=0,G33,G33*F33) -> 0
H34: =IF(F34=0,G34,G34*F34) -> 0
H35: =SUM(H25:H34) -> 0
B36: 구매품 | C36: 구동장치 및 부하장치
B37: (유공압품외) | C37: 1. 구동MOTOR 및 케이블류 | D37: 3000RPM | E37: SYS | F37: 1 | G37: 85000000 | H37: =IF(F37=0,G37,G37*F37) -> 85000000 | I37: SIEMENS
C38: 2. 토크MOTOR 및 케이블류 | D38: 5000Nm | E38: SYS | F38: 1 | G38: 12000000 | H38: =IF(F38=0,G38,G38*F38) -> 12000000 | I38: SIEMENS
C39: 3. LOAD HAMONIC | E39: SET | F39: 1 | G39: 15000000 | H39: =IF(F39=0,G39,G39*F39) -> 15000000 | I39: HDS
C40: 냉각장치
C41: 1. GEAR BOX COOLING PART | E41: SET | F41: 2 | G41: 5000000 | H41: =IF(F41=0,G41,G41*F41) -> 10000000 | I41: FLOWFORCE
...

Sheet 단위장비5
B1: □ 단위공사명(전기제외): | I1: (첨부)
A2: 구분 | C2: 품 명 | D2: 규격 | E2: 단위 | F2: 수량 | G2: 단가(원) | H2: 금액(원) | I2: 原MAKER
A3: 자 재 비 | B3: 철자재 | H3: =IF(F3=0,G3,G3*F3) -> 0
H4: =IF(F4=0,G4,G4*F4) -> 0
H5: =IF(F5=0,G5,G5*F5) -> 0
H6: =IF(F6=0,G6,G6*F6) -> 0
H7: =IF(F7=0,G7,G7*F7) -> 0
H8: =IF(F8=0,G8,G8*F8) -> 0
H9: =IF(F9=0,G9,G9*F9) -> 0
H10: =IF(F10=0,G10,G10*F10) -> 0
H11: =IF(F11=0,G11,G11*F11) -> 0
H12: =IF(F12=0,G12,G12*F12) -> 0
H13: =IF(F13=0,G13,G13*F13) -> 0
H14: =IF(F14=0,G14,G14*F14) -> 0
H15: =IF(F15=0,G15,G15*F15) -> 0
... H22: =IF(F22=0,G22,G22*F22) -> 0
H23: =SUM(H3:H22) -> 0
B24: 설치/해체/시운전 | H24: =IF(F24=0,G24,G24*F24) -> 0
B25: 공사 관련 자재 | H25: =IF(F25=0,G25,G25*F25) -> 0
H26: =IF(F26=0,G26,G26*F26) -> 0
H27: =IF(F27=0,G27,G27*F27) -> 0
H28: =IF(F28=0,G28,G28*F28) -> 0
H29: =IF(F29=0,G29,G29*F29) -> 0
H30: =IF(F30=0,G30,G30*F30) -> 0
H31: =IF(F31=0,G31,G31*F31) -> 0
H32: =IF(F32=0,G32,G32*F32) -> 0
H33: =IF(F33=0,G33,G33*F33) -> 0
H34: =SUM(H24:H33) -> 0
B35: 구매품 | H35: =IF(F35=0,G35,G35*F35) -> 0
B36: (유공압품외) | H36: =IF(F36=0,G36,G36*F36) -> 0
H37: =IF(F37=0,G37,G37*F37) -> 0
H38: =IF(F38=0,G38,G38*F38) -> 0
H39: =IF(F39=0,G39,G39*F39) -> 0
H40: =IF(F40=0,G40,G40*F40) -> 0
H41: =IF(F41=0,G41,G41*F41) -> 0
H42: =IF(F42=0,G42,G42*F42) -> 0
H43: =IF(F43=0,G43,G43*F43) -> 0
H44: =IF(F44=0,G44,G44*F44) -> 0
H45: =IF(F45=0,G45,G45*F45) -> 0
H46: =IF(F46=0,G46,G46*F46) -> 0
...

Sheet 단위장비6
B1: □ 단위공사명(전기제외): | I1: (첨부)
A2: 구분 | C2: 품 명 | D2: 규격 | E2: 단위 | F2: 수량 | G2: 단가(원) | H2: 금액(원) | I2: 原MAKER
A3: 자 재 비 | B3: 철자재 | H3: =IF(F3=0,G3,G3*F3) -> 0
H4: =IF(F4=0,G4,G4*F4) -> 0
H5: =IF(F5=0,G5,G5*F5) -> 0
H6: =IF(F6=0,G6,G6*F6) -> 0
H7: =IF(F7=0,G7,G7*F7) -> 0
H8: =IF(F8=0,G8,G8*F8) -> 0
H9: =IF(F9=0,G9,G9*F9) -> 0
H10: =IF(F10=0,G10,G10*F10) -> 0
H11: =IF(F11=0,G11,G11*F11) -> 0
H12: =IF(F12=0,G12,G12*F12) -> 0
H13: =IF(F13=0,G13,G13*F13) -> 0
H14: =IF(F14=0,G14,G14*F14) -> 0
H15: =IF(F15=0,G15,G15*F15) -> 0
... H22: =IF(F22=0,G22,G22*F22) -> 0
C23: 기타자재 | H23: =IF(F23=0,G23,G23*F23) -> 0
H24: =SUM(H3:H23) -> 0
B25: 설치/해체/시운전 | H25: =IF(F25=0,G25,G25*F25) -> 0
B26: 공사 관련 자재 | H26: =IF(F26=0,G26,G26*F26) -> 0
H27: =IF(F27=0,G27,G27*F27) -> 0
H28: =IF(F28=0,G28,G28*F28) -> 0
H29: =IF(F29=0,G29,G29*F29) -> 0
H30: =IF(F30=0,G30,G30*F30) -> 0
H31: =IF(F31=0,G31,G31*F31) -> 0
H32: =IF(F32=0,G32,G32*F32) -> 0
H33: =IF(F33=0,G33,G33*F33) -> 0
C34: 기타자재 | H34: =IF(F34=0,G34,G34*F34) -> 0
H35: =SUM(H25:H34) -> 0
B36: 구매품 | H36: =IF(F36=0,G36,G36*F36) -> 0
B37: (유공압품외) | H37: =IF(F37=0,G37,G37*F37) -> 0
H38: =IF(F38=0,G38,G38*F38) -> 0
H39: =IF(F39=0,G39,G39*F39) -> 0
H40: =IF(F40=0,G40,G40*F40) -> 0
H41: =IF(F41=0,G41,G41*F41) -> 0
H42: =IF(F42=0,G42,G42*F42) -> 0
H43: =IF(F43=0,G43,G43*F43) -> 0
H44: =IF(F44=0,G44,G44*F44) -> 0
H45: =IF(F45=0,G45,G45*F45) -> 0
H46: =IF(F46=0,G46,G46*F46) -> 0
...

Sheet 단위장비7
B1: □ 단위공사명(전기제외): | I1: (첨부)
A2: 구분 | C2: 품 명 | D2: 규격 | E2: 단위 | F2: 수량 | G2: 단가(원) | H2: 금액(원) | I2: 原MAKER
A3: 자 재 비 | B3: 철자재 | H3: =IF(F3=0,G3,G3*F3) -> 0
H4: =IF(F4=0,G4,G4*F4) -> 0
H5: =IF(F5=0,G5,G5*F5) -> 0
H6: =IF(F6=0,G6,G6*F6) -> 0
H7: =IF(F7=0,G7,G7*F7) -> 0
H8: =IF(F8=0,G8,G8*F8) -> 0
H9: =IF(F9=0,G9,G9*F9) -> 0
H10: =IF(F10=0,G10,G10*F10) -> 0
H11: =IF(F11=0,G11,G11*F11) -> 0
H12: =IF(F12=0,G12,G12*F12) -> 0
H13: =IF(F13=0,G13,G13*F13) -> 0
H14: =IF(F14=0,G14,G14*F14) -> 0
H15: =IF(F15=0,G15,G15*F15) -> 0
... H22: =IF(F22=0,G22,G22*F22) -> 0
C23: 기타자재 | E23: ST | H23: =IF(F23=0,G23,G23*F23) -> 0
H24: =SUM(H3:H23) -> 0
B25: 설치/해체/시운전 | H25: =IF(F25=0,G25,G25*F25) -> 0
B26: 공사 관련 자재 | H26: =IF(F26=0,G26,G26*F26) -> 0
H27: =IF(F27=0,G27,G27*F27) -> 0
H28: =IF(F28=0,G28,G28*F28) -> 0
H29: =IF(F29=0,G29,G29*F29) -> 0
H30: =IF(F30=0,G30,G30*F30) -> 0
H31: =IF(F31=0,G31,G31*F31) -> 0
H32: =IF(F32=0,G32,G32*F32) -> 0
H33: =IF(F33=0,G33,G33*F33) -> 0
C34: 기타자재 | H34: =IF(F34=0,G34,G34*F34) -> 0
H35: =SUM(H25:H34) -> 0
B36: 구매품 | H36: =IF(F36=0,G36,G36*F36) -> 0
B37: (유공압품외) | H37: =IF(F37=0,G37,G37*F37) -> 0
H38: =IF(F38=0,G38,G38*F38) -> 0
H39: =IF(F39=0,G39,G39*F39) -> 0
H40: =IF(F40=0,G40,G40*F40) -> 0
H41: =IF(F41=0,G41,G41*F41) -> 0
H42: =IF(F42=0,G42,G42*F42) -> 0
H43: =IF(F43=0,G43,G43*F43) -> 0
H44: =IF(F44=0,G44,G44*F44) -> 0
H45: =IF(F45=0,G45,G45*F45) -> 0
H46: =IF(F46=0,G46,G46*F46) -> 0
...

Sheet 단위장비8
B1: □ 단위공사명(전기제외): | I1: (첨부)
A2: 구분 | C2: 품 명 | D2: 규격 | E2: 단위 | F2: 수량 | G2: 단가(원) | H2: 금액(원) | I2: 原MAKER
A3: 자 재 비 | B3: 철자재 | H3: =IF(F3=0,G3,G3*F3) -> 0
H4: =IF(F4=0,G4,G4*F4) -> 0
H5: =IF(F5=0,G5,G5*F5) -> 0
H6: =IF(F6=0,G6,G6*F6) -> 0
H7: =IF(F7=0,G7,G7*F7) -> 0
H8: =IF(F8=0,G8,G8*F8) -> 0
H9: =IF(F9=0,G9,G9*F9) -> 0
H10: =IF(F10=0,G10,G10*F10) -> 0
H11: =IF(F11=0,G11,G11*F11) -> 0
H12: =IF(F12=0,G12,G12*F12) -> 0
H13: =IF(F13=0,G13,G13*F13) -> 0
H14: =IF(F14=0,G14,G14*F14) -> 0
H15: =IF(F15=0,G15,G15*F15) -> 0
... H22: =IF(F22=0,G22,G22*F22) -> 0
C23: 기타자재 | H23: =IF(F23=0,G23,G23*F23) -> 0
H24: =SUM(H3:H23) -> 0
B25: 설치/해체/시운전 | H25: =IF(F25=0,G25,G25*F25) -> 0
B26: 공사 관련 자재 | H26: =IF(F26=0,G26,G26*F26) -> 0
H27: =IF(F27=0,G27,G27*F27) -> 0
H28: =IF(F28=0,G28,G28*F28) -> 0
H29: =IF(F29=0,G29,G29*F29) -> 0
H30: =IF(F30=0,G30,G30*F30) -> 0
H31: =IF(F31=0,G31,G31*F31) -> 0
H32: =IF(F32=0,G32,G32*F32) -> 0
H33: =IF(F33=0,G33,G33*F33) -> 0
C34: 기타자재 | H34: =IF(F34=0,G34,G34*F34) -> 0
H35: =SUM(H25:H34) -> 0
B36: 구매품 | H36: =IF(F36=0,G36,G36*F36) -> 0
B37: (유공압품외) | H37: =IF(F37=0,G37,G37*F37) -> 0
H38: =IF(F38=0,G38,G38*F38) -> 0
H39: =IF(F39=0,G39,G39*F39) -> 0
H40: =IF(F40=0,G40,G40*F40) -> 0
H41: =IF(F41=0,G41,G41*F41) -> 0
H42: =IF(F42=0,G42,G42*F42) -> 0
H43: =IF(F43=0,G43,G43*F43) -> 0
H44: =IF(F44=0,G44,G44*F44) -> 0
H45: =IF(F45=0,G45,G45*F45) -> 0
H46: =IF(F46=0,G46,G46*F46) -> 0
...

Sheet 단위장비9
B1: □ 단위공사명(전기제외): | I1: (첨부)
A2: 구분 | C2: 품 명 | D2: 규격 | E2: 단위 | F2: 수량 | G2: 단가(원) | H2: 금액(원) | I2: 原MAKER
A3: 자 재 비 | B3: 철자재 | H3: =IF(F3=0,G3,G3*F3) -> 0
H4: =IF(F4=0,G4,G4*F4) -> 0
H5: =IF(F5=0,G5,G5*F5) -> 0
H6: =IF(F6=0,G6,G6*F6) -> 0
H7: =IF(F7=0,G7,G7*F7) -> 0
H8: =IF(F8=0,G8,G8*F8) -> 0
H9: =IF(F9=0,G9,G9*F9) -> 0
H10: =IF(F10=0,G10,G10*F10) -> 0
H11: =IF(F11=0,G11,G11*F11) -> 0
H12: =IF(F12=0,G12,G12*F12) -> 0
H13: =IF(F13=0,G13,G13*F13) -> 0
H14: =IF(F14=0,G14,G14*F14) -> 0
H15: =IF(F15=0,G15,G15*F15) -> 0
... H22: =IF(F22=0,G22,G22*F22) -> 0
C23: 기타자재 | H23: =IF(F23=0,G23,G23*F23) -> 0
H24: =SUM(H3:H23) -> 0
B25: 설치/해체/시운전 | H25: =IF(F25=0,G25,G25*F25) -> 0
B26: 공사 관련 자재 | H26: =IF(F26=0,G26,G26*F26) -> 0
H27: =IF(F27=0,G27,G27*F27) -> 0
H28: =IF(F28=0,G28,G28*F28) -> 0
H29: =IF(F29=0,G29,G29*F29) -> 0
H30: =IF(F30=0,G30,G30*F30) -> 0
H31: =IF(F31=0,G31,G31*F31) -> 0
H32: =IF(F32=0,G32,G32*F32) -> 0
H33: =IF(F33=0,G33,G33*F33) -> 0
C34: 기타자재 | H34: =IF(F34=0,G34,G34*F34) -> 0
H35: =SUM(H25:H34) -> 0
B36: 구매품 | H36: =IF(F36=0,G36,G36*F36) -> 0
B37: (유공압품외) | H37: =IF(F37=0,G37,G37*F37) -> 0
H38: =IF(F38=0,G38,G38*F38) -> 0
H39: =IF(F39=0,G39,G39*F39) -> 0
H40: =IF(F40=0,G40,G40*F40) -> 0
H41: =IF(F41=0,G41,G41*F41) -> 0
H42: =IF(F42=0,G42,G42*F42) -> 0
H43: =IF(F43=0,G43,G43*F43) -> 0
H44: =IF(F44=0,G44,G44*F44) -> 0
H45: =IF(F45=0,G45,G45*F45) -> 0
H46: =IF(F46=0,G46,G46*F46) -> 0
...

Sheet 단위장비10
B1: □ 단위공사명(전기제외): | I1: (첨부)
A2: 구분 | C2: 품 명 | D2: 규격 | E2: 단위 | F2: 수량 | G2: 단가(원) | H2: 금액(원) | I2: 原MAKER
A3: 자 재 비 | B3: 철자재 | H3: =IF(F3=0,G3,G3*F3) -> 0
H4: =IF(F4=0,G4,G4*F4) -> 0
H5: =IF(F5=0,G5,G5*F5) -> 0
H6: =IF(F6=0,G6,G6*F6) -> 0
H7: =IF(F7=0,G7,G7*F7) -> 0
H8: =IF(F8=0,G8,G8*F8) -> 0
H9: =IF(F9=0,G9,G9*F9) -> 0
H10: =IF(F10=0,G10,G10*F10) -> 0
H11: =IF(F11=0,G11,G11*F11) -> 0
H12: =IF(F12=0,G12,G12*F12) -> 0
H13: =IF(F13=0,G13,G13*F13) -> 0
H14: =IF(F14=0,G14,G14*F14) -> 0
H15: =IF(F15=0,G15,G15*F15) -> 0
... H22: =IF(F22=0,G22,G22*F22) -> 0
C23: 기타자재 | H23: =IF(F23=0,G23,G23*F23) -> 0
H24: =SUM(H3:H23) -> 0
B25: 설치/해체/시운전 | H25: =IF(F25=0,G25,G25*F25) -> 0
B26: 공사 관련 자재 | H26: =IF(F26=0,G26,G26*F26) -> 0
H27: =IF(F27=0,G27,G27*F27) -> 0
H28: =IF(F28=0,G28,G28*F28) -> 0
H29: =IF(F29=0,G29,G29*F29) -> 0
H30: =IF(F30=0,G30,G30*F30) -> 0
H31: =IF(F31=0,G31,G31*F31) -> 0
H32: =IF(F32=0,G32,G32*F32) -> 0
H33: =IF(F33=0,G33,G33*F33) -> 0
C34: 기타자재 | H34: =IF(F34=0,G34,G34*F34) -> 0
H35: =SUM(H25:H34) -> 0
B36: 구매품 | H36: =IF(F36=0,G36,G36*F36) -> 0
B37: (유공압품외) | H37: =IF(F37=0,G37,G37*F37) -> 0
H38: =IF(F38=0,G38,G38*F38) -> 0
H39: =IF(F39=0,G39,G39*F39) -> 0
H40: =IF(F40=0,G40,G40*F40) -> 0
H41: =IF(F41=0,G41,G41*F41) -> 0
H42: =IF(F42=0,G42,G42*F42) -> 0
H43: =IF(F43=0,G43,G43*F43) -> 0
H44: =IF(F44=0,G44,G44*F44) -> 0
H45: =IF(F45=0,G45,G45*F45) -> 0
H46: =IF(F46=0,G46,G46*F46) -> 0
...

Sheet 첨부(견적조건차이내역)
A1: ※ 현대/기아차의 요구사양과 업체견적사양이 다른경우만 작성
D2: (첨부)
A3: 현대/기아차 요구사양대비 견적조건 상이내역
A5: 항 목 | B5: 현대/기아차 요구사양 | C5: 업체 견적기준 사양 | D5: 비 고

Sheet Sheet1
