Workbook

Sheet 갑지
B1: (현대/기아차 설비협력업체 견적통일양식)
B2: 見 積 書
B4: 현대위아 貴下 | G4: 현대리바트
B5: 견적일자 | D5: 2021년07월26일 | G5: 대표 : 윤 기 철
B6: 견적번호 | D6: Q2021070012553 | G6: 주소 : 경기도 용인시 처인구 남사면
B7: 납기 | C7: 입하 | G7: 경기동로 316
C8: 최종검수 | G8: 전화 : 055-280-9806
B9: 견적유효기간 | D9: 견적일로부터 1개월 | G9: 메일 : 77158@hyundai-wia.com
B10: 인도장소 | D10: 현대위아 지정장소 | G10: 견적담당 : 김관희과장
B11: 지불조건 | D11: 현대위아 사규의거 | G11: 연 락 처 : 010-3231-5709
B13: 공 사 명 : 21년 대한산업안전협회 안전개선(등속공장)-CM861202107220012
B14: ="견적금액 : 一金 "& NUMBERSTRING(H29,1)& " 원整 ("&DOLLAR(H29,0)&")" -> 견적금액 : 一金 일억삼천팔백칠십오만 원整 (₩138,750,000)
B16: 번호 | C16: 상세품목내역 | E16: 견적금액 (원) | I16: 비 고
E17: 기계 | F17: 전기(공통) | G17: 관리비/이윤 | H17: 합 계
B18: 1 | C18: ='단위공사별(집계)'!B7 -> 등속 가공라인 | E18: ='단위공사별(집계)'!J7 -> 84600000 | F18: ='단위공사별(집계)'!M17 -> 0 | G18: ='단위공사별(집계)'!K7+'단위공사별(집계)'!L7 -> 9162071.9 | H18: =E18+F18+G18 -> 93762072
B19: 2 | C19: ='단위공사별(집계)'!B8 -> 등속 조립라인 | E19: ='단위공사별(집계)'!J8 -> 40600000 | G19: ='단위공사별(집계)'!K8+'단위공사별(집계)'!L8 -> 4396928.1 | H19: =E19+G19 -> 44996928
B20: 3 | C20: ='단위공사별(집계)'!B9 -> 0 | E20: ='단위공사별(집계)'!J9 -> 0 | G20: ='단위공사별(집계)'!K9+'단위공사별(집계)'!L9 -> 0 | H20: =E20+G20 -> 0
B21: 4 | C21: ='단위공사별(집계)'!B10 -> 0 | E21: ='단위공사별(집계)'!J10 -> 0 | G21: ='단위공사별(집계)'!K10+'단위공사별(집계)'!L10 -> 0 | H21: =E21+G21 -> 0
B22: 5 | C22: ='단위공사별(집계)'!B11 -> 0 | E22: ='단위공사별(집계)'!J11 -> 0 | G22: ='단위공사별(집계)'!K11+'단위공사별(집계)'!L11 -> 0 | H22: =E22+G22 -> 0
B23: 6 | C23: ='단위공사별(집계)'!B12 -> 0 | E23: ='단위공사별(집계)'!J12 -> 0 | G23: ='단위공사별(집계)'!K12+'단위공사별(집계)'!L12 -> 0 | H23: =E23+G23 -> 0
B24: 7 | C24: ='단위공사별(집계)'!B13 -> 0 | E24: ='단위공사별(집계)'!J13 -> 0 | G24: ='단위공사별(집계)'!K13+'단위공사별(집계)'!L13 -> 0 | H24: =E24+G24 -> 0
B25: 8 | C25: ='단위공사별(집계)'!B14 -> 0 | E25: ='단위공사별(집계)'!J14 -> 0 | G25: ='단위공사별(집계)'!K14+'단위공사별(집계)'!L14 -> 0 | H25: =E25+G25 -> 0
B26: 9 | C26: ='단위공사별(집계)'!B15 -> 0 | E26: ='단위공사별(집계)'!J15 -> 0 | G26: ='단위공사별(집계)'!K15+'단위공사별(집계)'!L15 -> 0 | H26: =E26+G26 -> 0
B27: 10 | C27: ='단위공사별(집계)'!B16 -> 0 | E27: ='단위공사별(집계)'!J16 -> 0 | G27: ='단위공사별(집계)'!K16+'단위공사별(집계)'!L16 -> 0 | H27: =E27+G27 -> 0
B28: 견적 합계 | E28: =SUM(E18:E27) -> 125200000 | F28: =F18 -> 0 | G28: =SUM(G18:G27) -> 13559000 | H28: =E28+F28+G28 -> 138759000
H29: =ROUNDDOWN(H28,-4) -> 138750000
F30: 공개입찰가 (견적時 공란)
B32: 특기사항 | C32: 1. VAT 제외 | F32: 외주계획 업체명 (자작時 공란)
C33: 2. 기본 유틸리티공사 제외 | F33: 설계외주
C34: ='원가항목별(집계)'!I39 -> 1039000 | F34: 제작외주
C35: 4. 천원단위 절사 | F35: 전기외주
F36: 설치외주

Sheet 원가항목별(집계)
C2: A. 원가항목별 견적가 종합(상세견적 첨부)
B4: □ 현대/기아 요구사양과 견적조건 일치여부 CHECK: 1.일치함 2.일부상이(상이내역 첨부참조)
B6: 순번 | C6: 원가구분 | F6: 단위 | G6: 수량 | H6: 단가 | I6: 금 액(원) | J6: 비 고
B7: 1 | C7: 기계 부문 | D7: 자재비 | E7: 철자재(SS.SUS등) | F7: kg | G7: =단위장비1!F30+단위장비2!F30+단위장비3!F30+단위장비4!F30+단위장비5!F30+단위장비6!F30+단위장비7!F30+단위장비8!F30+단위장비9!F30+단위장비10!F30 -> 0 | I7: =단위장비1!H24+단위장비2!H24+단위장비3!H24+단위장비4!H24+단위장비5!H24+단위장비6!H24+단위장비7!H24+단위장비8!H24+단위장비9!H24+단위장비10!H24 -> 26400000 | J7: 加工必要資材
E8: 일반구매품 | F8: 식 | G8: 1 | I8: =단위장비1!H47+단위장비2!H47+단위장비3!H47+단위장비4!H47+단위장비5!H47+단위장비6!H47+단위장비7!H47+단위장비8!H47+단위장비9!H47+단위장비10!H47 -> 21000000 | J8: 加工不要資材
E9: 외주제작품 | F9: 식 | G9: 1 | I9: =단위장비1!H55+단위장비2!H55+단위장비3!H55+단위장비4!H55+단위장비5!H55+단위장비6!H55+단위장비7!H55+단위장비8!H55+단위장비9!H55+단위장비10!H55 -> 18000000 | J9: 旣加工SUB資材
E10: 설치/해체 공사 자재 | F10: 식 | G10: 1 | I10: =단위장비1!H30+단위장비2!H30+단위장비3!H30+단위장비4!H30+단위장비5!H30+단위장비6!H30+단위장비7!H30+단위장비8!H30+단위장비9!H30+단위장비10!H30 -> 0 | J10: 시운전 자재 포함
E11: 소계 | I11: =SUM(I7:I10) -> 65400000
D12: 노무비 | E12: 기존설비 철거 | F12: M/D | G12: =단위장비1!F57+단위장비2!F57+단위장비3!F57+단위장비4!F57+단위장비5!F57+단위장비6!F57+단위장비7!F57+단위장비8!F57+단위장비9!F57+단위장비10!F57 -> 0 | H12: =IF(단위장비1!G57>0,단위장비1!G57,"") -> 200000 | I12: =단위장비1!H57+단위장비2!H57+단위장비3!H57+단위장비4!H57+단위장비5!H57+단위장비6!H57+단위장비7!H57+단위장비8!H57+단위장비9!H57+단위장비10!H57 -> 0 | J12: 개조공사時
E13: 설계 | F13: M/D | G13: =단위장비1!F58+단위장비2!F58+단위장비3!F58+단위장비4!F58+단위장비5!F58+단위장비6!F58+단위장비7!F58+단위장비8!F58+단위장비9!F58+단위장비10!F58 -> 39 | H13: =IF(단위장비1!G58>0,단위장비1!G58,"") -> 200000 | I13: =단위장비1!H58+단위장비2!H58+단위장비3!H58+단위장비4!H58+단위장비5!H58+단위장비6!H58+단위장비7!H58+단위장비8!H58+단위장비9!H58+단위장비10!H58 -> 7800000
E14: 제작(제관,가공) | F14: M/D | G14: =단위장비1!F59+단위장비2!F59+단위장비3!F59+단위장비4!F59+단위장비5!F59+단위장비6!F59+단위장비7!F59+단위장비8!F59+단위장비9!F59+단위장비10!F59 -> 60 | H14: =IF(단위장비1!G59>0,단위장비1!G59,"") -> 200000 | I14: =단위장비1!H59+단위장비2!H59+단위장비3!H59+단위장비4!H59+단위장비5!H59+단위장비6!H59+단위장비7!H59+단위장비8!H59+단위장비9!H59+단위장비10!H59 -> 12000000
E15: 조립 | F15: M/D | G15: =단위장비1!F60+단위장비2!F60+단위장비3!F60+단위장비4!F60+단위장비5!F60+단위장비6!F60+단위장비7!F60+단위장비8!F60+단위장비9!F60+단위장비10!F60 -> 60 | H15: =IF(단위장비1!G60>0,단위장비1!G60,"") -> 200000 | I15: =단위장비1!H60+단위장비2!H60+단위장비3!H60+단위장비4!H60+단위장비5!H60+단위장비6!H60+단위장비7!H60+단위장비8!H60+단위장비9!H60+단위장비10!H60 -> 12000000 | J15: 정도검사포함
E16: 설치 | F16: M/D | G16: =단위장비1!F61+단위장비2!F61+단위장비3!F61+단위장비4!F61+단위장비5!F61+단위장비6!F61+단위장비7!F61+단위장비8!F61+단위장비9!F61+단위장비10!F61 -> 140 | H16: =IF(단위장비1!G61>0,단위장비1!G61,"") -> 200000 | I16: =단위장비1!H61+단위장비2!H61+단위장비3!H61+단위장비4!H61+단위장비5!H61+단위장비6!H61+단위장비7!H61+단위장비8!H61+단위장비9!H61+단위장비10!H61 -> 28000000
E17: 시운전 | F17: M/D | G17: =단위장비1!F62+단위장비2!F62+단위장비3!F62+단위장비4!F62+단위장비5!F62+단위장비6!F62+단위장비7!F62+단위장비8!F62+단위장비9!F62+단위장비10!F62 -> 0 | H17: =IF(단위장비1!G62>0,단위장비1!G62,"") -> 200000 | I17: =단위장비1!H62+단위장비2!H62+단위장비3!H62+단위장비4!H62+단위장비5!H62+단위장비6!H62+단위장비7!H62+단위장비8!H62+단위장비9!H62+단위장비10!H62 -> 0
E18: 양산대응 | F18: M/D | G18: =단위장비1!F63+단위장비2!F63+단위장비3!F63+단위장비4!F63+단위장비5!F63+단위장비6!F63+단위장비7!F63+단위장비8!F63+단위장비9!F63+단위장비10!F63 -> 0 | H18: =IF(단위장비1!G63>0,단위장비1!G63,"") -> 200000 | I18: =단위장비1!H63+단위장비2!H63+단위장비3!H63+단위장비4!H63+단위장비5!H63+단위장비6!H63+단위장비7!H63+단위장비8!H63+단위장비9!H63+단위장비10!H63 -> 0
E19: 도장 | F19: M/D | G19: =단위장비1!F64+단위장비2!F64+단위장비3!F64+단위장비4!F64+단위장비5!F64+단위장비6!F64+단위장비7!F64+단위장비8!F64+단위장비9!F64+단위장비10!F64 -> 0 | H19: =IF(단위장비1!G64>0,단위장비1!G64,"") -> 200000 | I19: =단위장비1!H64+단위장비2!H64+단위장비3!H64+단위장비4!H64+단위장비5!H64+단위장비6!H64+단위장비7!H64+단위장비8!H64+단위장비9!H64+단위장비10!H64 -> 0
E20: 소계 | I20: =SUM(I12:I19) -> 59800000
D21: 일반관리 및 이윤 | I21: =단위장비1!H67+단위장비1!H68+단위장비2!H67+단위장비2!H68+단위장비3!H67+단위장비3!H68+단위장비4!H67+단위장비4!H68+단위장비5!H67+단위장비5!H68+단위장비6!H67+단위장비6!H68+단위장비7!H67+단위장비7!H68+단위장비8!H67+단위장비8!H68+단위장비9!H67+단위장비9!H68+단위장비10!H67+단위장비10!H68 -> 12520000
E22: 기계 소계 | I22: =I20+I11+I21 -> 137720000
B23: 2 | C23: 전기 부문 | D23: 자재비 | E23: 기계/전기자재 | F23: 식 | G23: 1 | I23: =전기!H55-I24 -> 0
E24: 설치/해체 공사 자재 | F24: 식 | G24: 1 | I24: =전기!H16 -> 0 | J24: 시운전 자재 포함
D25: 노무비 | E25: 철거(개조시) | F25: M/D | G25: =전기!F56 -> 0 | H25: =IF(전기!G56>0,전기!G56,"") -> 250000 | I25: =전기!H56 -> 0
E26: 설계,프로그램 | F26: M/D | G26: =전기!F57 -> 0 | H26: =IF(전기!G57>0,전기!G57,"") -> 250000 | I26: =전기!H57 -> 0
E27: 제작 | F27: M/D | G27: =전기!F58 -> 0 | H27: =IF(전기!G58>0,전기!G58,"") -> 250000 | I27: =전기!H58 -> 0
E28: 조립 | F28: M/D | G28: =전기!F59 -> 0 | H28: =IF(전기!G59>0,전기!G59,"") -> 250000 | I28: =전기!H59 -> 0
E29: 설치 | F29: M/D | G29: =전기!F60 -> 0 | H29: =IF(전기!G60>0,전기!G60,"") -> 250000 | I29: =전기!H60 -> 0
E30: 시운전 | F30: M/D | G30: =전기!F61 -> 0 | H30: =IF(전기!G61>0,전기!G61,"") -> 250000 | I30: =전기!H61 -> 0
E31: 양산대응 | F31: M/D | G31: =전기!F62 -> 0 | H31: =IF(전기!G62>0,전기!G62,"") -> 250000 | I31: =전기!H62 -> 0
E32: 소계 | I32: =SUM(I25:I31) -> 0
D33: 일반관리 및 이윤 | I33: =전기!H65+전기!H66 -> 0
E34: 전기 소계 | I34: =I32+I23+I33+I24 -> 0
B35: 3 | C35: 자재비 합계 | I35: =I23+I11+I24 -> 65400000
C36: 노무비 합계 | I36: =I32+I20 -> 59800000
C37: 중간 합계 | I37: =I36+I35 -> 125200000
B38: 4 | C38: 포장,운송 및 중장비 사용료
B39: 5 | C39: 표준안전관리비 | F39: 설치/철거/수리금액 기준 | I39: =CEILING(MIN(I47:I48),1000) -> 1039000 | J39: =I30+I29+I25+I24+I17+I16+I12+I10 -> 28000000
B40: 6 | C40: 일반관리비 | I40: =전기!H65+단위장비1!H67+단위장비2!H67+단위장비3!H67+단위장비4!H67+단위장비5!H67+단위장비6!H67+단위장비7!H67+단위장비8!H67+단위장비9!H67+단위장비10!H67 -> 6260000
B41: 7 | C41: 이 윤 | I41: =전기!H66+단위장비1!H68+단위장비2!H68+단위장비3!H68+단위장비4!H68+단위장비5!H68+단위장비6!H68+단위장비7!H68+단위장비8!H68+단위장비9!H68+단위장비10!H68 -> 6260000
C42: 합 계 | F42: 3~7항 합계 | I42: =I22+I34+I38+I39 -> 138759000
B43: 주1. 표준안전관리비:(설치/철거/시운전 공사 관련 금액)의 ⓐ2.66%,ⓑ1.95%+기초액,ⓒ2.02%(50억 이상일경우)
...

Sheet 단위공사별(집계)
A2: B. 단위장비별 견적가 종합(상세견적 첨부)
N3: 단위:원
M4: 전기소계 (공통,관리비,이윤포함) | N4: 합 계 | O4: 비 고
I5: 포장/운송 | K5: 표준안전 | L5: 일반관리비 및
A6: 순번 | B6: 단위장비명 | C6: 수량 | D6: 자재비 | E6: 철거 | F6: 제작 | G6: 설치/시운전 | H6: 양산대응 | I6: 중장비사용 | J6: 기계소계 | K6: 관리비 | L6: 이윤
A7: =IF(B7>0,1,"") -> 1 | B7: =단위장비1!C$1 -> 등속 가공라인 | C7: 1식 | D7: =단위장비1!H56 -> 43600000 | E7: =단위장비1!H57 -> 0 | F7: =단위장비1!H58+단위장비1!H59+단위장비1!H60+단위장비1!H64 -> 21000000 | G7: =단위장비1!H61+단위장비1!H62 -> 20000000 | H7: =단위장비1!H63 -> 0 | I7: =IF($B7>0,'원가항목별(집계)'!I$38*$P7/$P$17,0) -> 0 | J7: =SUM(D7:I7) -> 84600000 | K7: =IF($B7>0,'원가항목별(집계)'!I$39*$P7/$P$17,0) -> 702071.88 | L7: =단위장비1!H67+단위장비1!H68 -> 8460000 | N7: =SUM(J7:L7) -> 93762072 | P7: =D7+E7+F7+G7+H7+L7 -> 93060000
A8: =IF(B8>0,A7+1,"") -> 2 | B8: =단위장비2!C$1 -> 등속 조립라인 | C8: 1식 | D8: =단위장비2!H56 -> 21800000 | E8: =단위장비2!H57 -> 0 | F8: =단위장비2!H58+단위장비2!H59+단위장비2!H60+단위장비2!H64 -> 10800000 | G8: =단위장비2!H61+단위장비2!H62 -> 8000000 | H8: =단위장비2!H63 -> 0 | I8: =IF($B8>0,'원가항목별(집계)'!I$38*$P8/$P$17,0) -> 0 | J8: =SUM(D8:I8) -> 40600000 | K8: =IF($B8>0,'원가항목별(집계)'!I$39*$P8/$P$17,0) -> 336928.12 | L8: =단위장비2!H67+단위장비2!H68 -> 4060000 | N8: =SUM(J8:L8) -> 44996928 | P8: =D8+E8+F8+G8+H8+L8 -> 44660000
A9: =IF(B9>0,A8+1,"") | B9: =단위장비3!C$1 -> 0 | C9: 1식 | D9: =단위장비3!H56 -> 0 | E9: =단위장비3!H57 -> 0 | F9: =단위장비3!H58+단위장비3!H59+단위장비3!H60+단위장비3!H64 -> 0 | G9: =단위장비3!H61+단위장비3!H62 -> 0 | H9: =단위장비3!H63 -> 0 | I9: =IF($B9>0,'원가항목별(집계)'!I$38*$P9/$P$17,0) -> 0 | J9: =SUM(D9:I9) -> 0 | K9: =IF($B9>0,'원가항목별(집계)'!I$39*$P9/$P$17,0) -> 0 | L9: =단위장비3!H67+단위장비3!H68 -> 0 | N9: =SUM(J9:L9) -> 0 | P9: =D9+E9+F9+G9+H9+L9 -> 0
A10: =IF(B10>0,A9+1,"") | B10: =단위장비4!C$1 -> 0 | C10: 1식 | D10: =단위장비4!H56 -> 0 | E10: =단위장비4!H57 -> 0 | F10: =단위장비4!H58+단위장비4!H59+단위장비4!H60+단위장비4!H64 -> 0 | G10: =단위장비4!H61+단위장비4!H62 -> 0 | H10: =단위장비4!H63 -> 0 | I10: =IF($B10>0,'원가항목별(집계)'!I$38*$P10/$P$17,0) -> 0 | J10: =SUM(D10:I10) -> 0 | K10: =IF($B10>0,'원가항목별(집계)'!I$39*$P10/$P$17,0) -> 0 | L10: =단위장비4!H67+단위장비4!H68 -> 0 | N10: =SUM(J10:L10) -> 0 | P10: =D10+E10+F10+G10+H10+L10 -> 0
A11: =IF(B11>0,A10+1,"") | B11: =단위장비5!C$1 -> 0 | C11: 1식 | D11: =단위장비5!H56 -> 0 | E11: =단위장비5!H57 -> 0 | F11: =단위장비5!H58+단위장비5!H59+단위장비5!H60+단위장비5!H64 -> 0 | G11: =단위장비5!H61+단위장비5!H62 -> 0 | H11: =단위장비5!H63 -> 0 | I11: =IF($B11>0,'원가항목별(집계)'!I$38*$P11/$P$17,0) -> 0 | J11: =SUM(D11:I11) -> 0 | K11: =IF($B11>0,'원가항목별(집계)'!I$39*$P11/$P$17,0) -> 0 | L11: =단위장비5!H67+단위장비5!H68 -> 0 | N11: =SUM(J11:L11) -> 0 | P11: =D11+E11+F11+G11+H11+L11 -> 0
A12: =IF(B12>0,A11+1,"") | B12: =단위장비6!C$1 -> 0 | C12: 1식 | D12: =단위장비6!H56 -> 0 | E12: =단위장비6!H57 -> 0 | F12: =단위장비6!H58+단위장비6!H59+단위장비6!H60+단위장비6!H64 -> 0 | G12: =단위장비6!H61+단위장비6!H62 -> 0 | H12: =단위장비6!H63 -> 0 | I12: =IF($B12>0,'원가항목별(집계)'!I$38*$P12/$P$17,0) -> 0 | J12: =SUM(D12:I12) -> 0 | K12: =IF($B12>0,'원가항목별(집계)'!I$39*$P12/$P$17,0) -> 0 | L12: =단위장비6!H67+단위장비6!H68 -> 0 | N12: =SUM(J12:L12) -> 0 | P12: =D12+E12+F12+G12+H12+L12 -> 0
A13: =IF(B13>0,A12+1,"") | B13: =단위장비7!C$1 -> 0 | C13: 1식 | D13: =단위장비7!H56 -> 0 | E13: =단위장비7!H57 -> 0 | F13: =단위장비7!H58+단위장비7!H59+단위장비7!H60+단위장비7!H64 -> 0 | G13: =단위장비7!H61+단위장비7!H62 -> 0 | H13: =단위장비7!H63 -> 0 | I13: =IF($B13>0,'원가항목별(집계)'!I$38*$P13/$P$17,0) -> 0 | J13: =SUM(D13:I13) -> 0 | K13: =IF($B13>0,'원가항목별(집계)'!I$39*$P13/$P$17,0) -> 0 | L13: =단위장비7!H67+단위장비7!H68 -> 0 | N13: =SUM(J13:L13) -> 0 | P13: =D13+E13+F13+G13+H13+L13 -> 0
A14: =IF(B14>0,A13+1,"") | B14: =단위장비8!C$1 -> 0 | C14: 1식 | D14: =단위장비8!H56 -> 0 | E14: =단위장비8!H57 -> 0 | F14: =단위장비8!H58+단위장비8!H59+단위장비8!H60+단위장비8!H64 -> 0 | G14: =단위장비8!H61+단위장비8!H62 -> 0 | H14: =단위장비8!H63 -> 0 | I14: =IF($B14>0,'원가항목별(집계)'!I$38*$P14/$P$17,0) -> 0 | J14: =SUM(D14:I14) -> 0 | K14: =IF($B14>0,'원가항목별(집계)'!I$39*$P14/$P$17,0) -> 0 | L14: =단위장비8!H67+단위장비8!H68 -> 0 | N14: =SUM(J14:L14) -> 0 | P14: =D14+E14+F14+G14+H14+L14 -> 0
A15: 9 | B15: =단위장비9!C$1 -> 0 | C15: 1식 | D15: =단위장비9!H56 -> 0 | E15: =단위장비9!H57 -> 0 | F15: =단위장비9!H58+단위장비9!H59+단위장비9!H60+단위장비9!H64 -> 0 | G15: =단위장비9!H61+단위장비9!H62 -> 0 | H15: =단위장비9!H63 -> 0 | I15: =IF($B15>0,'원가항목별(집계)'!I$38*$P15/$P$17,0) -> 0 | J15: =SUM(D15:I15) -> 0 | K15: =IF($B15>0,'원가항목별(집계)'!I$39*$P15/$P$17,0) -> 0 | L15: =단위장비9!H67+단위장비9!H68 -> 0 | N15: =SUM(J15:L15) -> 0 | P15: =D15+E15+F15+G15+H15+L15 -> 0
A16: 10 | B16: =단위장비10!C$1 -> 0 | C16: 1식 | D16: =단위장비10!H56 -> 0 | E16: =단위장비10!H57 -> 0 | F16: =단위장비10!H58+단위장비10!H59+단위장비10!H60+단위장비10!H64 -> 0 | G16: =단위장비10!H61+단위장비10!H62 -> 0 | H16: =단위장비10!H63 -> 0 | I16: =IF($B16>0,'원가항목별(집계)'!I$38*$P16/$P$17,0) -> 0 | J16: =SUM(D16:I16) -> 0 | K16: =IF($B16>0,'원가항목별(집계)'!I$39*$P16/$P$17,0) -> 0 | L16: =단위장비10!H67+단위장비10!H68 -> 0 | N16: =SUM(J16:L16) -> 0 | P16: =D16+E16+F16+G16+H16+L16 -> 0
A17: 합 계 | D17: =SUM(D7:D16) -> 65400000 | E17: =SUM(E7:E16) -> 0 | F17: =SUM(F7:F16) -> 31800000 | G17: =SUM(G7:G16) -> 28000000 | H17: =SUM(H7:H16) -> 0 | I17: =SUM(I7:I16) -> 0 | J17: =SUM(D17:I17) -> 125200000 | K17: =SUM(K7:K16) -> 1039000 | L17: =SUM(L7:L16) -> 12520000 | M17: =전기!H67 -> 0 | N17: =J17+K17+L17+M17 -> 138759000 | O17: 전기소계포함 | P17: =SUM(P7:P16) -> 137720000
D18: =IF(D17=0,"",D17/$N17) -> 0.47132078 | E18: =IF(E17=0,"",E17/$N17) | F18: =IF(F17=0,"",F17/$N17) -> 0.22917432 | G18: =IF(G17=0,"",G17/$N17) -> 0.20178871 | H18: =IF(H17=0,"",H17/$N17) | I18: =IF(I17=0,"",I17/$N17) | J18: =IF(J17=0,"",J17/$N17) -> 0.90228382 | K18: =IF(K17=0,"",K17/$N17) -> 0.0074878026 | ... N18: =IF(N17=0,"",N17/$N17) -> 1
A19: 주) 전기비용은 턴키장비의 공통비용으로서 총 전기비용을 단위장비별 기계금액의 비율에 따라 배분함
N20: =IF('원가항목별(집계)'!I42='단위공사별(집계)'!N17,"","DATA오류입니다!")

Sheet 전기
B1: □ 전기부문: | C1: 전기부문(공통) | I1: (첨부)
A2: 구분 | C2: 품 명 | D2: 규격 | E2: 단위 | F2: 수량 | G2: 단가(원) | H2: 금액(원) | I2: 原MAKER
A3: 자 재 비 | B3: 철자재 | H3: =IF(F3=0,G3,G3*F3) -> 0
H4: =IF(F4=0,G4,G4*F4) -> 0
H5: =IF(F5=0,G5,G5*F5) -> 0
H6: =IF(F6=0,G6,G6*F6) -> 0
H7: =IF(F7=0,G7,G7*F7) -> 0
H8: =IF(F8=0,G8,G8*F8) -> 0
H9: =SUM(H3:H8) -> 0
B10: 설치/해체/ | H10: =IF(F10=0,G10,G10*F10) -> 0
B11: 시운전 공사 | H11: =IF(F11=0,G11,G11*F11) -> 0
B12: 자재 | H12: =IF(F12=0,G12,G12*F12) -> 0
H13: =IF(F13=0,G13,G13*F13) -> 0
H14: =IF(F14=0,G14,G14*F14) -> 0
H15: =IF(F15=0,G15,G15*F15) -> 0
H16: =SUM(H10:H15) -> 0
B17: 전기자재 | H17: =IF(F17=0,G17,G17*F17) -> 0
H18: =IF(F18=0,G18,G18*F18) -> 0
H19: =IF(F19=0,G19,G19*F19) -> 0
H20: =IF(F20=0,G20,G20*F20) -> 0
H21: =IF(F21=0,G21,G21*F21) -> 0
H22: =IF(F22=0,G22,G22*F22) -> 0
H23: =IF(F23=0,G23,G23*F23) -> 0
H24: =IF(F24=0,G24,G24*F24) -> 0
H25: =IF(F25=0,G25,G25*F25) -> 0
H26: =IF(F26=0,G26,G26*F26) -> 0
H27: =IF(F27=0,G27,G27*F27) -> 0
H28: =IF(F28=0,G28,G28*F28) -> 0
H29: =IF(F29=0,G29,G29*F29) -> 0
... H53: =IF(F53=0,G53,G53*F53) -> 0
H54: =SUM(H17:H53) -> 0
B55: 자재비 소계 | H55: =SUM(H54,H9,H16) -> 0
A56: 노 무 비 | B56: 기존설비 철거 | E56: M/D | G56: 250000 | H56: =F56*G56 -> 0
B57: 전기 설계/프로그램 | E57: M/D | G57: 250000 | H57: =F57*G57 -> 0
B58: 전기 제작 | E58: M/D | G58: 250000 | H58: =F58*G58 -> 0
B59: 전기 조립 | E59: M/D | G59: 250000 | H59: =F59*G59 -> 0
B60: 전기 설치 | E60: M/D | G60: 250000 | H60: =F60*G60 -> 0
B61: 전기 시운전 | E61: M/D | G61: 250000 | H61: =F61*G61 -> 0
B62: 전기 양산대응 | E62: M/D | G62: 250000 | H62: =F62*G62 -> 0
B63: 노무비 소계 | H63: =SUM(H56:H62) -> 0
...

Sheet 단위장비1
B1: □ 단위공사명(전기제외): | C1: 등속 가공라인 | I1: (첨부)
A2: 구분 | C2: 품 명 | D2: 규격 | E2: 단위 | F2: 수량 | G2: 단가(원) | H2: 금액(원) | I2: 原MAKER
A3: 자 재 비 | B3: 철자재 | C3: STEEL PLATE | D3: 1219x2438x1.6T | E3: SET | F3: 1 | G3: 4000000 | H3: =IF(F3=0,G3,G3*F3) -> 4000000
C4: STEEL PLATE | D4: 1219x2438x3.2T | E4: SET | F4: 1 | G4: 1000000 | H4: =IF(F4=0,G4,G4*F4) -> 1000000
C5: SQ PIPE | D5: 40x40x2.4T | E5: SET | F5: 1 | G5: 1600000 | H5: =IF(F5=0,G5,G5*F5) -> 1600000
C6: ROUND PIPE | D6: 25A,KS,BLACK | E6: SET | F6: 1 | G6: 1000000 | H6: =IF(F6=0,G6,G6*F6) -> 1000000
C7: FLAT BAR | D7: 50x3.0T | E7: SET | F7: 1 | G7: 400000 | H7: =IF(F7=0,G7,G7*F7) -> 400000
C8: EX-METAL | D8: SS-133 | E8: SET | F8: 1 | G8: 2000000 | H8: =IF(F8=0,G8,G8*F8) -> 2000000
C9: A/L PROFILE | D9: DNF4040 | E9: SET | F9: 1 | G9: 6000000 | H9: =IF(F9=0,G9,G9*F9) -> 6000000
H10: =IF(F10=0,G10,G10*F10) -> 0
H11: =IF(F11=0,G11,G11*F11) -> 0
H12: =IF(F12=0,G12,G12*F12) -> 0
H13: =IF(F13=0,G13,G13*F13) -> 0
H14: =IF(F14=0,G14,G14*F14) -> 0
H15: =IF(F15=0,G15,G15*F15) -> 0
H16: =IF(F16=0,G16,G16*F16) -> 0
H17: =IF(F17=0,G17,G17*F17) -> 0
H18: =IF(F18=0,G18,G18*F18) -> 0
H19: =IF(F19=0,G19,G19*F19) -> 0
H20: =IF(F20=0,G20,G20*F20) -> 0
H21: =IF(F21=0,G21,G21*F21) -> 0
H22: =IF(F22=0,G22,G22*F22) -> 0
C23: 기타 | D23: 보강자재 | E23: SET | F23: 1 | G23: 1600000 | H23: =IF(F23=0,G23,G23*F23) -> 1600000
H24: =SUM(H3:H23) -> 17600000
B25: 설치/해체/시운전 | H25: =IF(F25=0,G25,G25*F25) -> 0
B26: 공사 관련 자재 | H26: =IF(F26=0,G26,G26*F26) -> 0
H27: =IF(F27=0,G27,G27*F27) -> 0
H28: =IF(F28=0,G28,G28*F28) -> 0
H29: =IF(F29=0,G29,G29*F29) -> 0
H30: =SUM(H25:H29) -> 0
B31: 구매품 | C31: POLYCARBONATE | D31: 1219x2438x5.0T,CLEAR | E31: SET | F31: 1 | G31: 8000000 | H31: =IF(F31=0,G31,G31*F31) -> 8000000
B32: (유공압품외) | C32: HARDWARE | D32: 경첩,손잡이외 | E32: SET | F32: 1 | G32: 2000000 | H32: =IF(F32=0,G32,G32*F32) -> 2000000
C33: SUBSIDIARY MATERIALS | D33: 프로파일용 자재류 | E33: SET | F33: 1 | G33: 3000000 | H33: =IF(F33=0,G33,G33*F33) -> 3000000
H34: =IF(F34=0,G34,G34*F34) -> 0
H35: =IF(F35=0,G35,G35*F35) -> 0
H36: =IF(F36=0,G36,G36*F36) -> 0
H37: =IF(F37=0,G37,G37*F37) -> 0
H38: =IF(F38=0,G38,G38*F38) -> 0
H39: =IF(F39=0,G39,G39*F39) -> 0
H40: =IF(F40=0,G40,G40*F40) -> 0
...

Sheet 단위장비2
B1: □ 단위공사명(전기제외): | C1: 등속 조립라인 | I1: (첨부)
A2: 구분 | C2: 품 명 | D2: 규격 | E2: 단위 | F2: 수량 | G2: 단가(원) | H2: 금액(원) | I2: 原MAKER
A3: 자 재 비 | B3: 철자재 | C3: STEEL PLATE | D3: 1219x2438x1.6T | E3: SET | F3: 1 | G3: 2000000 | H3: =IF(F3=0,G3,G3*F3) -> 2000000
C4: STEEL PLATE | D4: 1219x2438x3.2T | E4: SET | F4: 1 | G4: 500000 | H4: =IF(F4=0,G4,G4*F4) -> 500000
C5: SQ PIPE | D5: 40x40x2.4T | E5: SET | F5: 1 | G5: 800000 | H5: =IF(F5=0,G5,G5*F5) -> 800000
C6: ROUND PIPE | D6: 25A,KS,BLACK | E6: SET | F6: 1 | G6: 500000 | H6: =IF(F6=0,G6,G6*F6) -> 500000
C7: FLAT BAR | D7: 50x3.0T | E7: SET | F7: 1 | G7: 200000 | H7: =IF(F7=0,G7,G7*F7) -> 200000
C8: EX-METAL | D8: SS-133 | E8: SET | F8: 1 | G8: 1000000 | H8: =IF(F8=0,G8,G8*F8) -> 1000000
C9: A/L PROFILE | D9: DNF4040 | E9: SET | F9: 1 | G9: 3000000 | H9: =IF(F9=0,G9,G9*F9) -> 3000000
H10: =IF(F10=0,G10,G10*F10) -> 0
H11: =IF(F11=0,G11,G11*F11) -> 0
H12: =IF(F12=0,G12,G12*F12) -> 0
H13: =IF(F13=0,G13,G13*F13) -> 0
H14: =IF(F14=0,G14,G14*F14) -> 0
H15: =IF(F15=0,G15,G15*F15) -> 0
H16: =IF(F16=0,G16,G16*F16) -> 0
H17: =IF(F17=0,G17,G17*F17) -> 0
H18: =IF(F18=0,G18,G18*F18) -> 0
H19: =IF(F19=0,G19,G19*F19) -> 0
H20: =IF(F20=0,G20,G20*F20) -> 0
H21: =IF(F21=0,G21,G21*F21) -> 0
H22: =IF(F22=0,G22,G22*F22) -> 0
C23: 기타 | D23: 보강자재 | E23: SET | F23: 1 | G23: 800000 | H23: =IF(F23=0,G23,G23*F23) -> 800000
H24: =SUM(H3:H23) -> 8800000
B25: 설치/해체/시운전 | H25: =IF(F25=0,G25,G25*F25) -> 0
B26: 공사 관련 자재 | H26: =IF(F26=0,G26,G26*F26) -> 0
H27: =IF(F27=0,G27,G27*F27) -> 0
H28: =IF(F28=0,G28,G28*F28) -> 0
H29: =IF(F29=0,G29,G29*F29) -> 0
H30: =SUM(H25:H29) -> 0
B31: 구매품 | C31: POLYCARBONATE | D31: 1219x2438x5.0T,CLEAR | E31: SET | F31: 1 | G31: 4000000 | H31: =IF(F31=0,G31,G31*F31) -> 4000000
B32: (유공압품외) | C32: HARDWARE | D32: 경첩,손잡이외 | E32: SET | F32: 1 | G32: 1000000 | H32: =IF(F32=0,G32,G32*F32) -> 1000000
C33: SUBSIDIARY MATERIALS | D33: 프로파일용 자재류 | E33: SET | F33: 1 | G33: 1500000 | H33: =IF(F33=0,G33,G33*F33) -> 1500000
H34: =IF(F34=0,G34,G34*F34) -> 0
H35: =IF(F35=0,G35,G35*F35) -> 0
H36: =IF(F36=0,G36,G36*F36) -> 0
H37: =IF(F37=0,G37,G37*F37) -> 0
H38: =IF(F38=0,G38,G38*F38) -> 0
H39: =IF(F39=0,G39,G39*F39) -> 0
H40: =IF(F40=0,G40,G40*F40) -> 0
...

Sheet 단위장비3
B1: □ 단위공사명(전기제외): | I1: (첨부)
A2: 구분 | C2: 품 명 | D2: 규격 | E2: 단위 | F2: 수량 | G2: 단가(원) | H2: 금액(원) | I2: 原MAKER
A3: 자 재 비 | B3: 철자재 | H3: =IF(F3=0,G3,G3*F3) -> 0
H4: =IF(F4=0,G4,G4*F4) -> 0
H5: =IF(F5=0,G5,G5*F5) -> 0
H6: =IF(F6=0,G6,G6*F6) -> 0
H7: =IF(F7=0,G7,G7*F7) -> 0
H8: =IF(F8=0,G8,G8*F8) -> 0
H9: =IF(F9=0,G9,G9*F9) -> 0
H10: =IF(F10=0,G10,G10*F10) -> 0
H11: =IF(F11=0,G11,G11*F11) -> 0
H12: =IF(F12=0,G12,G12*F12) -> 0
H13: =IF(F13=0,G13,G13*F13) -> 0
H14: =IF(F14=0,G14,G14*F14) -> 0
H15: =IF(F15=0,G15,G15*F15) -> 0
... H23: =IF(F23=0,G23,G23*F23) -> 0
H24: =SUM(H3:H23) -> 0
B25: 설치/해체/시운전 | H25: =IF(F25=0,G25,G25*F25) -> 0
B26: 공사 관련 자재 | H26: =IF(F26=0,G26,G26*F26) -> 0
H27: =IF(F27=0,G27,G27*F27) -> 0
H28: =IF(F28=0,G28,G28*F28) -> 0
H29: =IF(F29=0,G29,G29*F29) -> 0
H30: =SUM(H25:H29) -> 0
B31: 구매품 | H31: =IF(F31=0,G31,G31*F31) -> 0
B32: (유공압품외) | H32: =IF(F32=0,G32,G32*F32) -> 0
H33: =IF(F33=0,G33,G33*F33) -> 0
H34: =IF(F34=0,G34,G34*F34) -> 0
H35: =IF(F35=0,G35,G35*F35) -> 0
H36: =IF(F36=0,G36,G36*F36) -> 0
H37: =IF(F37=0,G37,G37*F37) -> 0
H38: =IF(F38=0,G38,G38*F38) -> 0
H39: =IF(F39=0,G39,G39*F39) -> 0
H40: =IF(F40=0,G40,G40*F40) -> 0
H41: =IF(F41=0,G41,G41*F41) -> 0
H42: =IF(F42=0,G42,G42*F42) -> 0
H43: =IF(F43=0,G43,G43*F43) -> 0
H44: =IF(F44=0,G44,G44*F44) -> 0
... H46: =IF(F46=0,G46,G46*F46) -> 0
H47: =SUM(H31:H46) -> 0
B48: 외주제작품 | H48: =IF(F48=0,G48,G48*F48) -> 0
...

Sheet 단위장비4
B1: □ 단위공사명(전기제외): | I1: (첨부)
A2: 구분 | C2: 품 명 | D2: 규격 | E2: 단위 | F2: 수량 | G2: 단가(원) | H2: 금액(원) | I2: 原MAKER
A3: 자 재 비 | B3: 철자재 | H3: =IF(F3=0,G3,G3*F3) -> 0
H4: =IF(F4=0,G4,G4*F4) -> 0
H5: =IF(F5=0,G5,G5*F5) -> 0
H6: =IF(F6=0,G6,G6*F6) -> 0
H7: =IF(F7=0,G7,G7*F7) -> 0
H8: =IF(F8=0,G8,G8*F8) -> 0
H9: =IF(F9=0,G9,G9*F9) -> 0
H10: =IF(F10=0,G10,G10*F10) -> 0
H11: =IF(F11=0,G11,G11*F11) -> 0
H12: =IF(F12=0,G12,G12*F12) -> 0
H13: =IF(F13=0,G13,G13*F13) -> 0
H14: =IF(F14=0,G14,G14*F14) -> 0
H15: =IF(F15=0,G15,G15*F15) -> 0
... H23: =IF(F23=0,G23,G23*F23) -> 0
H24: =SUM(H3:H23) -> 0
B25: 설치/해체/시운전 | H25: =IF(F25=0,G25,G25*F25) -> 0
B26: 공사 관련 자재 | H26: =IF(F26=0,G26,G26*F26) -> 0
H27: =IF(F27=0,G27,G27*F27) -> 0
H28: =IF(F28=0,G28,G28*F28) -> 0
H29: =IF(F29=0,G29,G29*F29) -> 0
H30: =SUM(H25:H29) -> 0
B31: 구매품 | H31: =IF(F31=0,G31,G31*F31) -> 0
B32: (유공압품외) | H32: =IF(F32=0,G32,G32*F32) -> 0
H33: =IF(F33=0,G33,G33*F33) -> 0
H34: =IF(F34=0,G34,G34*F34) -> 0
H35: =IF(F35=0,G35,G35*F35) -> 0
H36: =IF(F36=0,G36,G36*F36) -> 0
H37: =IF(F37=0,G37,G37*F37) -> 0
H38: =IF(F38=0,G38,G38*F38) -> 0
H39: =IF(F39=0,G39,G39*F39) -> 0
H40: =IF(F40=0,G40,G40*F40) -> 0
H41: =IF(F41=0,G41,G41*F41) -> 0
H42: =IF(F42=0,G42,G42*F42) -> 0
H43: =IF(F43=0,G43,G43*F43) -> 0
H44: =IF(F44=0,G44,G44*F44) -> 0
... H46: =IF(F46=0,G46,G46*F46) -> 0
H47: =SUM(H31:H46) -> 0
B48: 외주제작품 | H48: =IF(F48=0,G48,G48*F48) -> 0
...

Sheet 단위장비5
B1: □ 단위공사명(전기제외): | I1: (첨부)
A2: 구분 | C2: 품 명 | D2: 규격 | E2: 단위 | F2: 수량 | G2: 단가(원) | H2: 금액(원) | I2: 原MAKER
A3: 자 재 비 | B3: 철자재 | H3: =IF(F3=0,G3,G3*F3) -> 0
H4: =IF(F4=0,G4,G4*F4) -> 0
H5: =IF(F5=0,G5,G5*F5) -> 0
H6: =IF(F6=0,G6,G6*F6) -> 0
H7: =IF(F7=0,G7,G7*F7) -> 0
H8: =IF(F8=0,G8,G8*F8) -> 0
H9: =IF(F9=0,G9,G9*F9) -> 0
H10: =IF(F10=0,G10,G10*F10) -> 0
H11: =IF(F11=0,G11,G11*F11) -> 0
H12: =IF(F12=0,G12,G12*F12) -> 0
H13: =IF(F13=0,G13,G13*F13) -> 0
H14: =IF(F14=0,G14,G14*F14) -> 0
H15: =IF(F15=0,G15,G15*F15) -> 0
... H23: =IF(F23=0,G23,G23*F23) -> 0
H24: =SUM(H3:H23) -> 0
B25: 설치/해체/시운전 | H25: =IF(F25=0,G25,G25*F25) -> 0
B26: 공사 관련 자재 | H26: =IF(F26=0,G26,G26*F26) -> 0
H27: =IF(F27=0,G27,G27*F27) -> 0
H28: =IF(F28=0,G28,G28*F28) -> 0
H29: =IF(F29=0,G29,G29*F29) -> 0
H30: =SUM(H25:H29) -> 0
B31: 구매품 | H31: =IF(F31=0,G31,G31*F31) -> 0
B32: (유공압품외) | H32: =IF(F32=0,G32,G32*F32) -> 0
H33: =IF(F33=0,G33,G33*F33) -> 0
H34: =IF(F34=0,G34,G34*F34) -> 0
H35: =IF(F35=0,G35,G35*F35) -> 0
H36: =IF(F36=0,G36,G36*F36) -> 0
H37: =IF(F37=0,G37,G37*F37) -> 0
H38: =IF(F38=0,G38,G38*F38) -> 0
H39: =IF(F39=0,G39,G39*F39) -> 0
H40: =IF(F40=0,G40,G40*F40) -> 0
H41: =IF(F41=0,G41,G41*F41) -> 0
H42: =IF(F42=0,G42,G42*F42) -> 0
H43: =IF(F43=0,G43,G43*F43) -> 0
H44: =IF(F44=0,G44,G44*F44) -> 0
... H46: =IF(F46=0,G46,G46*F46) -> 0
H47: =SUM(H31:H46) -> 0
B48: 외주제작품 | H48: =IF(F48=0,G48,G48*F48) -> 0
...

Sheet 단위장비6
B1: □ 단위공사명(전기제외): | I1: (첨부)
A2: 구분 | C2: 품 명 | D2: 규격 | E2: 단위 | F2: 수량 | G2: 단가(원) | H2: 금액(원) | I2: 原MAKER
A3: 자 재 비 | B3: 철자재 | H3: =IF(F3=0,G3,G3*F3) -> 0
H4: =IF(F4=0,G4,G4*F4) -> 0
H5: =IF(F5=0,G5,G5*F5) -> 0
H6: =IF(F6=0,G6,G6*F6) -> 0
H7: =IF(F7=0,G7,G7*F7) -> 0
H8: =IF(F8=0,G8,G8*F8) -> 0
H9: =IF(F9=0,G9,G9*F9) -> 0
H10: =IF(F10=0,G10,G10*F10) -> 0
H11: =IF(F11=0,G11,G11*F11) -> 0
H12: =IF(F12=0,G12,G12*F12) -> 0
H13: =IF(F13=0,G13,G13*F13) -> 0
H14: =IF(F14=0,G14,G14*F14) -> 0
H15: =IF(F15=0,G15,G15*F15) -> 0
... H23: =IF(F23=0,G23,G23*F23) -> 0
H24: =SUM(H3:H23) -> 0
B25: 설치/해체/시운전 | H25: =IF(F25=0,G25,G25*F25) -> 0
B26: 공사 관련 자재 | H26: =IF(F26=0,G26,G26*F26) -> 0
H27: =IF(F27=0,G27,G27*F27) -> 0
H28: =IF(F28=0,G28,G28*F28) -> 0
H29: =IF(F29=0,G29,G29*F29) -> 0
H30: =SUM(H25:H29) -> 0
B31: 구매품 | H31: =IF(F31=0,G31,G31*F31) -> 0
B32: (유공압품외) | H32: =IF(F32=0,G32,G32*F32) -> 0
H33: =IF(F33=0,G33,G33*F33) -> 0
H34: =IF(F34=0,G34,G34*F34) -> 0
H35: =IF(F35=0,G35,G35*F35) -> 0
H36: =IF(F36=0,G36,G36*F36) -> 0
H37: =IF(F37=0,G37,G37*F37) -> 0
H38: =IF(F38=0,G38,G38*F38) -> 0
H39: =IF(F39=0,G39,G39*F39) -> 0
H40: =IF(F40=0,G40,G40*F40) -> 0
H41: =IF(F41=0,G41,G41*F41) -> 0
H42: =IF(F42=0,G42,G42*F42) -> 0
H43: =IF(F43=0,G43,G43*F43) -> 0
H44: =IF(F44=0,G44,G44*F44) -> 0
... H46: =IF(F46=0,G46,G46*F46) -> 0
H47: =SUM(H31:H46) -> 0
B48: 외주제작품 | H48: =IF(F48=0,G48,G48*F48) -> 0
...

Sheet 단위장비7
B1: □ 단위공사명(전기제외): | I1: (첨부)
A2: 구분 | C2: 품 명 | D2: 규격 | E2: 단위 | F2: 수량 | G2: 단가(원) | H2: 금액(원) | I2: 原MAKER
A3: 자 재 비 | B3: 철자재 | H3: =IF(F3=0,G3,G3*F3) -> 0
H4: =IF(F4=0,G4,G4*F4) -> 0
H5: =IF(F5=0,G5,G5*F5) -> 0
H6: =IF(F6=0,G6,G6*F6) -> 0
H7: =IF(F7=0,G7,G7*F7) -> 0
H8: =IF(F8=0,G8,G8*F8) -> 0
H9: =IF(F9=0,G9,G9*F9) -> 0
H10: =IF(F10=0,G10,G10*F10) -> 0
H11: =IF(F11=0,G11,G11*F11) -> 0
H12: =IF(F12=0,G12,G12*F12) -> 0
H13: =IF(F13=0,G13,G13*F13) -> 0
H14: =IF(F14=0,G14,G14*F14) -> 0
H15: =IF(F15=0,G15,G15*F15) -> 0
... H23: =IF(F23=0,G23,G23*F23) -> 0
H24: =SUM(H3:H23) -> 0
B25: 설치/해체/시운전 | H25: =IF(F25=0,G25,G25*F25) -> 0
B26: 공사 관련 자재 | H26: =IF(F26=0,G26,G26*F26) -> 0
H27: =IF(F27=0,G27,G27*F27) -> 0
H28: =IF(F28=0,G28,G28*F28) -> 0
H29: =IF(F29=0,G29,G29*F29) -> 0
H30: =SUM(H25:H29) -> 0
B31: 구매품 | H31: =IF(F31=0,G31,G31*F31) -> 0
B32: (유공압품외) | H32: =IF(F32=0,G32,G32*F32) -> 0
H33: =IF(F33=0,G33,G33*F33) -> 0
H34: =IF(F34=0,G34,G34*F34) -> 0
H35: =IF(F35=0,G35,G35*F35) -> 0
H36: =IF(F36=0,G36,G36*F36) -> 0
H37: =IF(F37=0,G37,G37*F37) -> 0
H38: =IF(F38=0,G38,G38*F38) -> 0
H39: =IF(F39=0,G39,G39*F39) -> 0
H40: =IF(F40=0,G40,G40*F40) -> 0
H41: =IF(F41=0,G41,G41*F41) -> 0
H42: =IF(F42=0,G42,G42*F42) -> 0
H43: =IF(F43=0,G43,G43*F43) -> 0
H44: =IF(F44=0,G44,G44*F44) -> 0
... H46: =IF(F46=0,G46,G46*F46) -> 0
H47: =SUM(H31:H46) -> 0
B48: 외주제작품 | H48: =IF(F48=0,G48,G48*F48) -> 0
...

Sheet 단위장비8
B1: □ 단위공사명(전기제외): | I1: (첨부)
A2: 구분 | C2: 품 명 | D2: 규격 | E2: 단위 | F2: 수량 | G2: 단가(원) | H2: 금액(원) | I2: 原MAKER
A3: 자 재 비 | B3: 철자재 | H3: =IF(F3=0,G3,G3*F3) -> 0
H4: =IF(F4=0,G4,G4*F4) -> 0
H5: =IF(F5=0,G5,G5*F5) -> 0
H6: =IF(F6=0,G6,G6*F6) -> 0
H7: =IF(F7=0,G7,G7*F7) -> 0
H8: =IF(F8=0,G8,G8*F8) -> 0
H9: =IF(F9=0,G9,G9*F9) -> 0
H10: =IF(F10=0,G10,G10*F10) -> 0
H11: =IF(F11=0,G11,G11*F11) -> 0
H12: =IF(F12=0,G12,G12*F12) -> 0
H13: =IF(F13=0,G13,G13*F13) -> 0
H14: =IF(F14=0,G14,G14*F14) -> 0
H15: =IF(F15=0,G15,G15*F15) -> 0
... H23: =IF(F23=0,G23,G23*F23) -> 0
H24: =SUM(H3:H23) -> 0
B25: 설치/해체/시운전 | H25: =IF(F25=0,G25,G25*F25) -> 0
B26: 공사 관련 자재 | H26: =IF(F26=0,G26,G26*F26) -> 0
H27: =IF(F27=0,G27,G27*F27) -> 0
H28: =IF(F28=0,G28,G28*F28) -> 0
H29: =IF(F29=0,G29,G29*F29) -> 0
H30: =SUM(H25:H29) -> 0
B31: 구매품 | H31: =IF(F31=0,G31,G31*F31) -> 0
B32: (유공압품외) | H32: =IF(F32=0,G32,G32*F32) -> 0
H33: =IF(F33=0,G33,G33*F33) -> 0
H34: =IF(F34=0,G34,G34*F34) -> 0
H35: =IF(F35=0,G35,G35*F35) -> 0
H36: =IF(F36=0,G36,G36*F36) -> 0
H37: =IF(F37=0,G37,G37*F37) -> 0
H38: =IF(F38=0,G38,G38*F38) -> 0
H39: =IF(F39=0,G39,G39*F39) -> 0
H40: =IF(F40=0,G40,G40*F40) -> 0
H41: =IF(F41=0,G41,G41*F41) -> 0
H42: =IF(F42=0,G42,G42*F42) -> 0
H43: =IF(F43=0,G43,G43*F43) -> 0
H44: =IF(F44=0,G44,G44*F44) -> 0
... H46: =IF(F46=0,G46,G46*F46) -> 0
H47: =SUM(H31:H46) -> 0
B48: 외주제작품 | H48: =IF(F48=0,G48,G48*F48) -> 0
...

Sheet 단위장비9
B1: □ 단위공사명(전기제외): | I1: (첨부)
A2: 구분 | C2: 품 명 | D2: 규격 | E2: 단위 | F2: 수량 | G2: 단가(원) | H2: 금액(원) | I2: 原MAKER
A3: 자 재 비 | B3: 철자재 | H3: =IF(F3=0,G3,G3*F3) -> 0
H4: =IF(F4=0,G4,G4*F4) -> 0
H5: =IF(F5=0,G5,G5*F5) -> 0
H6: =IF(F6=0,G6,G6*F6) -> 0
H7: =IF(F7=0,G7,G7*F7) -> 0
H8: =IF(F8=0,G8,G8*F8) -> 0
H9: =IF(F9=0,G9,G9*F9) -> 0
H10: =IF(F10=0,G10,G10*F10) -> 0
H11: =IF(F11=0,G11,G11*F11) -> 0
H12: =IF(F12=0,G12,G12*F12) -> 0
H13: =IF(F13=0,G13,G13*F13) -> 0
H14: =IF(F14=0,G14,G14*F14) -> 0
H15: =IF(F15=0,G15,G15*F15) -> 0
... H23: =IF(F23=0,G23,G23*F23) -> 0
H24: =SUM(H3:H23) -> 0
B25: 설치/해체/시운전 | H25: =IF(F25=0,G25,G25*F25) -> 0
B26: 공사 관련 자재 | H26: =IF(F26=0,G26,G26*F26) -> 0
H27: =IF(F27=0,G27,G27*F27) -> 0
H28: =IF(F28=0,G28,G28*F28) -> 0
H29: =IF(F29=0,G29,G29*F29) -> 0
H30: =SUM(H25:H29) -> 0
B31: 구매품 | H31: =IF(F31=0,G31,G31*F31) -> 0
B32: (유공압품외) | H32: =IF(F32=0,G32,G32*F32) -> 0
H33: =IF(F33=0,G33,G33*F33) -> 0
H34: =IF(F34=0,G34,G34*F34) -> 0
H35: =IF(F35=0,G35,G35*F35) -> 0
H36: =IF(F36=0,G36,G36*F36) -> 0
H37: =IF(F37=0,G37,G37*F37) -> 0
H38: =IF(F38=0,G38,G38*F38) -> 0
H39: =IF(F39=0,G39,G39*F39) -> 0
H40: =IF(F40=0,G40,G40*F40) -> 0
H41: =IF(F41=0,G41,G41*F41) -> 0
H42: =IF(F42=0,G42,G42*F42) -> 0
H43: =IF(F43=0,G43,G43*F43) -> 0
H44: =IF(F44=0,G44,G44*F44) -> 0
... H46: =IF(F46=0,G46,G46*F46) -> 0
H47: =SUM(H31:H46) -> 0
B48: 외주제작품 | H48: =IF(F48=0,G48,G48*F48) -> 0
...

Sheet 단위장비10
B1: □ 단위공사명(전기제외): | I1: (첨부)
A2: 구분 | C2: 품 명 | D2: 규격 | E2: 단위 | F2: 수량 | G2: 단가(원) | H2: 금액(원) | I2: 原MAKER
A3: 자 재 비 | B3: 철자재 | H3: =IF(F3=0,G3,G3*F3) -> 0
H4: =IF(F4=0,G4,G4*F4) -> 0
H5: =IF(F5=0,G5,G5*F5) -> 0
H6: =IF(F6=0,G6,G6*F6) -> 0
H7: =IF(F7=0,G7,G7*F7) -> 0
H8: =IF(F8=0,G8,G8*F8) -> 0
H9: =IF(F9=0,G9,G9*F9) -> 0
H10: =IF(F10=0,G10,G10*F10) -> 0
H11: =IF(F11=0,G11,G11*F11) -> 0
H12: =IF(F12=0,G12,G12*F12) -> 0
H13: =IF(F13=0,G13,G13*F13) -> 0
H14: =IF(F14=0,G14,G14*F14) -> 0
H15: =IF(F15=0,G15,G15*F15) -> 0
... H23: =IF(F23=0,G23,G23*F23) -> 0
H24: =SUM(H3:H23) -> 0
B25: 설치/해체/시운전 | H25: =IF(F25=0,G25,G25*F25) -> 0
B26: 공사 관련 자재 | H26: =IF(F26=0,G26,G26*F26) -> 0
H27: =IF(F27=0,G27,G27*F27) -> 0
H28: =IF(F28=0,G28,G28*F28) -> 0
H29: =IF(F29=0,G29,G29*F29) -> 0
H30: =SUM(H25:H29) -> 0
B31: 구매품 | H31: =IF(F31=0,G31,G31*F31) -> 0
B32: (유공압품외) | H32: =IF(F32=0,G32,G32*F32) -> 0
H33: =IF(F33=0,G33,G33*F33) -> 0
H34: =IF(F34=0,G34,G34*F34) -> 0
H35: =IF(F35=0,G35,G35*F35) -> 0
H36: =IF(F36=0,G36,G36*F36) -> 0
H37: =IF(F37=0,G37,G37*F37) -> 0
H38: =IF(F38=0,G38,G38*F38) -> 0
H39: =IF(F39=0,G39,G39*F39) -> 0
H40: =IF(F40=0,G40,G40*F40) -> 0
H41: =IF(F41=0,G41,G41*F41) -> 0
H42: =IF(F42=0,G42,G42*F42) -> 0
H43: =IF(F43=0,G43,G43*F43) -> 0
H44: =IF(F44=0,G44,G44*F44) -> 0
... H46: =IF(F46=0,G46,G46*F46) -> 0
H47: =SUM(H31:H46) -> 0
B48: 외주제작품 | H48: =IF(F48=0,G48,G48*F48) -> 0
...

Sheet 첨부(견적조건차이내역)
A1: ※ 현대/기아차의 요구사양과 업체견적사양이 다른경우만 작성
D2: (첨부)
A3: 현대/기아차 요구사양대비 견적조건 상이내역
A5: 항 목 | B5: 현대/기아차 요구사양 | C5: 업체 견적기준 사양 | D5: 비 고
