Workbook

Sheet 갑지
B1: (현대/기아차 설비협력업체 견적통일양식)
B2: 見 積 書
B4: 현대위아(주) 貴下 | G4: ㈜에스엠티
B5: 견적일자 | D5: 44655 | G5: 대표 : 박 현 (인)
B6: 견적번호 | D6: TPL220404-01-03 | G6: 주소 : 창원시 마산회원구 봉암공단 10길41-1
B7: 납기 | C7: 공사완료 | D7: 44780 | G7: 전화: 82-55-294-8847
C8: 최종검수 | D8: 44804 | G8: Fax : 82-55-294-8850
B9: 견적유효기간 | D9: 견적일로부터30일 | G9: E-mail : hyeon@so-ul.co.kr
B10: 대금지급조건 | D10: 계약후 20%, FAC완료후 80% | G10: 견적담당 : 박 현 대표
B11: 담 당 자 | D11: 구매팀 / 이주헌 님 | G11: 연 락 처 : 82-55-294-8847
B13: 공 사 명: | D13: 창원3공장 등속조립라인 R/RING 공정개선
B14: 최종견적금액: | D14: ="一金"&NUMBERSTRING(H19,1)&"원整 ("&TEXT(H19,"\#,#)") -> 一金일억일천사백만원整 (₩114,000,000)
B16: 번호 | C16: 상세품목내역 | E16: 견적금액 (원) | I16: 비 고
E17: 기계부문 | F17: 전기부문 | G17: 관리/이윤 (안전관리비포함) | H17: 합 계
B18: 1 | C18: =IF('단위공사별(집계)'!N7>0,'단위공사별(집계)'!B7,"") -> R/RING공정개선(112,203,204,205) | E18: =IF('단위공사별(집계)'!N7>1,('단위공사별(집계)'!D7+'단위공사별(집계)'!E7+'단위공사별(집계)'!F7+'단위공사별(집계)'!G7+'단위공사별(집계)'!H7+'단위공사별(집계)'!I7)," ") -> 71230000 | F18: =IF('단위공사별(집계)'!N7>0,'단위공사별(집계)'!K8,"") -> 31495500 | G18: =IF('단위공사별(집계)'!N7>0,('단위공사별(집계)'!L7+'단위공사별(집계)'!M7),"") -> 11274500 | H18: =IF('단위공사별(집계)'!N7>0,'단위공사별(집계)'!N7,"") -> 114000000
B19: 견적 합계 | E19: =SUM(E18:E18) -> 71230000 | F19: =SUM(F18:F18) -> 31495500 | G19: =SUM(G18:G18) -> 11274500 | H19: =SUM(H18:H18) -> 114000000
F21: 공개입찰가 (견적時 공란)
B23: 특기사항 | C23: 1. VAT 제외 | F23: 외주계획 업체명 (자작時 공란)
C24: 2. 기본 유틸리티공사 제외 | F24: 설계외주
C25: 3. 사급(서보프레스SET,PLC부품,인디게이터 류, 등) | F25: 제작외주
F26: 전기외주
F27: 설치외주

Sheet 원가항목별(집계)
C2: A. 원가항목별 견적가 종합(상세견적 첨부)
B4: □ 현대/기아 요구사양과 견적조건 일치여부 CHECK: 1.일치함 2.일부상이(상이내역 첨부참조)
B6: 순번 | C6: 원가구분 | F6: 단위 | G6: 수량 | H6: 단가 | I6: 금 액(원) | J6: 비 고
B7: 1 | C7: 기계 부문 | D7: 자재비 | E7: 철자재(SS.SUS등) | F7: kg | G7: 1 | I7: =SUM(단위장비1!H9) -> 370000 | J7: 加工必要資材
E8: 일반구매품 | F8: 식 | G8: 1 | I8: =SUM(단위장비1!H38) -> 1000000 | J8: 加工不要資材
E9: 외주제작품 | F9: 식 | G9: 1 | I9: =SUM(단위장비1!H55) -> 53260000 | J9: 旣加工SUB資材
E10: 설치/해체 공사 자재 | F10: 식 | G10: 1 | I10: =SUM(단위장비1!H15) -> 0 | J10: 시운전 자재 포함
E11: 소계 | I11: =SUM(I7:I10) -> 54630000
D12: 노무비 | E12: 기존설비 철거 | F12: M/D | G12: =SUM(단위장비1!F57) -> 0 | H12: =IF(단위장비1!G57>0,단위장비1!G57,"") -> 300000 | I12: =SUM(단위장비1!H57) -> 0 | J12: 개조공사時
E13: 설계 | F13: M/D | G13: =SUM(단위장비1!F58) -> 8 | H13: =IF(단위장비1!G58>0,단위장비1!G58,"") -> 350000 | I13: =SUM(단위장비1!H58) -> 2800000
E14: 제작(제관,가공) | F14: M/D | G14: =SUM(단위장비1!F59) -> 0 | H14: =IF(단위장비1!G59>0,단위장비1!G59,"") -> 300000 | I14: =SUM(단위장비1!H59) -> 0
E15: 조립 | F15: M/D | G15: =SUM(단위장비1!F60) -> 8 | H15: =IF(단위장비1!G60>0,단위장비1!G60,"") -> 300000 | I15: =SUM(단위장비1!H60) -> 2400000 | J15: 정도검사포함
E16: 설치 | F16: M/D | G16: =SUM(단위장비1!F61) -> 16 | H16: =IF(단위장비1!G61>0,단위장비1!G61,"") -> 300000 | I16: =SUM(단위장비1!H61) -> 4800000
E17: 시운전 | F17: M/D | G17: =SUM(단위장비1!F62) -> 10 | H17: =IF(단위장비1!G62>0,단위장비1!G62,"") -> 300000 | I17: =SUM(단위장비1!H62) -> 3000000
E18: 양산대응 | F18: M/D | G18: =SUM(단위장비1!F63) -> 12 | H18: =IF(단위장비1!G63>0,단위장비1!G63,"") -> 300000 | I18: =SUM(단위장비1!H63) -> 3600000
E19: 도장 | F19: M/D | G19: =SUM(단위장비1!F64) -> 0 | H19: =IF(단위장비1!G64>0,단위장비1!G64,"") -> 300000 | I19: =SUM(단위장비1!H64) -> 0
E20: 소계 | I20: =SUM(I12:I19) -> 16600000
D21: 일반관리 및 이윤 | I21: =(SUM(단위장비1!H67))+(SUM(단위장비1!H68)) -> 10417952
E22: 기계 소계 | I22: =I20+I11+I21 -> 81647952
B23: 2 | C23: 전기 부문 | D23: 자재비 | E23: 기계/전기자재 | F23: 식 | G23: 1 | I23: =전기!H57-I24 -> 1840000
E24: 설치/해체 공사 자재 | F24: 식 | G24: 1 | I24: =전기!H14 -> 0 | J24: 시운전 자재 포함
D25: 노무비 | E25: 철거(개조시) | F25: M/D | G25: =전기!F58 -> 0 | H25: =IF(전기!G58>0,전기!G58,"") | I25: =전기!H58 -> 0
E26: 설계,프로그램 | F26: M/D | G26: =전기!F59 -> 25 | H26: =IF(전기!G59>0,전기!G59,"") -> 350000 | I26: =전기!H59 -> 8750000
E27: 제작 | F27: M/D | G27: =전기!F60 -> 5 | H27: =IF(전기!G60>0,전기!G60,"") -> 300000 | I27: =전기!H60 -> 1500000
E28: 조립 | F28: M/D | G28: =전기!F61 -> 12 | H28: =IF(전기!G61>0,전기!G61,"") -> 300000 | I28: =전기!H61 -> 3600000
E29: 설치 | F29: M/D | G29: =전기!F62 -> 12 | H29: =IF(전기!G62>0,전기!G62,"") -> 300000 | I29: =전기!H62 -> 3600000
E30: 시운전 | F30: M/D | G30: =전기!F63 -> 15 | H30: =IF(전기!G63>0,전기!G63,"") -> 300000 | I30: =전기!H63 -> 4500000
E31: 양산대응 | F31: M/D | G31: =전기!F64 -> 12 | H31: =IF(전기!G64>0,전기!G64,"") -> 300000 | I31: =전기!H64 -> 3600000
E32: 소계 | I32: =SUM(I25:I31) -> 25550000
D33: 일반관리 및 이윤 | I33: =전기!H67+전기!H68 -> 4105500
E34: 전기 소계 | I34: =I32+I23+I33+I24 -> 31495500
B35: 3 | C35: 자재비 합계 | I35: =I23+I11+I24 -> 56470000
C36: 노무비 합계 | I36: =I32+I20 -> 42150000
C37: 중간 합계 | I37: =I36+I35 -> 98620000
B38: 4 | C38: 포장,운송 및 중장비 사용료
B39: 5 | C39: 표준안전관리비 | F39: 설치/철거/수리금액 기준 | I39: =I48 -> 856548 | J39: =I30+I29+I25+I24+I17+I16+I12+I10 -> 15900000
B40: 6 | C40: 일반관리비 | I40: =전기!H67+(SUM(단위장비1!H67)) -> 4931000
B41: 7 | C41: 이 윤 | I41: =전기!H68+(SUM(단위장비1!H68)) -> 9592452
C42: 합 계 | F42: 3~7항 합계 | I42: =I22+I34+I38+I39 -> 114000000
B43: 주1. 표준안전관리비:(설치/철거/시운전 공사 관련 금액)의 ⓐ2.66%,ⓑ1.95%+기초액,ⓒ2.02%(50억 이상일경우)
...

Sheet 단위공사별(집계)
A2: B. 단위장비별 견적가 종합(상세견적 첨부)
N3: 단위:원
I5: 포장/운송 | L5: 표준안전 | M5: 일반관리비
A6: 순번 | B6: 단위장비명 | C6: 수량 | D6: 자재비 | E6: 철거 | F6: 제작 | G6: 설치/시운전 | H6: 양산대응 | I6: 중장비사용 | J6: 기계소계 | K6: 전기소계 | L6: 관리비 | M6: 이윤 | N6: 합 계 | O6: 비 고
A7: =IF(B7>0,1,"") -> 1 | B7: =단위장비1!C$1 -> R/RING공정개선(112,203,204,205) | C7: 1식 | D7: =단위장비1!H56 -> 54630000 | E7: =단위장비1!H57 -> 0 | F7: =단위장비1!$H$58+단위장비1!$H$59+단위장비1!$H$60+단위장비1!$H$64 -> 5200000 | G7: =단위장비1!$H$61+단위장비1!$H$62 -> 7800000 | H7: =단위장비1!H63 -> 3600000 | I7: =IF($B7>0,'원가항목별(집계)'!I$38*$P7/$P$8,0) -> 0 | J7: =SUM(D7:I7) -> 71230000 | K7: =IF(B7>0,'원가항목별(집계)'!I$34*P7/P$8,0) -> 31495500 | L7: =IF($B7>0,'원가항목별(집계)'!I$39*$P7/$P$8,0) -> 856548 | M7: =단위장비1!$H$67+단위장비1!$H$68 -> 10417952 | N7: =SUM(J7:M7) -> 114000000 | P7: =D7+E7+F7+G7+H7+M7 -> 81647952
A8: 합 계 | D8: =SUM(D7:D7) -> 54630000 | E8: =SUM(E7:E7) -> 0 | F8: =SUM(F7:F7) -> 5200000 | G8: =SUM(G7:G7) -> 7800000 | H8: =SUM(H7:H7) -> 3600000 | I8: =SUM(I7:I7) -> 0 | J8: =SUM(D8:I8) -> 71230000 | K8: =SUM(K7:K7) -> 31495500 | L8: =SUM(L7:L7) -> 856548 | M8: =SUM(M7:M7) -> 10417952 | N8: =SUM(N7:N7) -> 114000000 | P8: =SUM(P7:P7) -> 81647952
D9: =IF(D8=0,"",D8/$N8) -> 0.47921053 | E9: =IF(E8=0,"",E8/$N8) | F9: =IF(F8=0,"",F8/$N8) -> 0.045614035 | G9: =IF(G8=0,"",G8/$N8) -> 0.068421053 | H9: =IF(H8=0,"",H8/$N8) -> 0.031578947 | I9: =IF(I8=0,"",I8/$N8) | J9: =IF(J8=0,"",J8/$N8) -> 0.62482456 | K9: =IF(K8=0,"",K8/$N8) -> 0.27627632 | ... N9: =IF(N8=0,"",N8/$N8) -> 1
A10: 주) 전기비용은 턴키장비의 공통비용으로서 총 전기비용을 단위장비별 기계금액의 비율에 따라 배분함
N11: =IF('원가항목별(집계)'!I42='단위공사별(집계)'!N8,"","DATA오류입니다!")

Sheet 전기
B1: □ 전기부문: | C1: 전기부문(공통) | I1: (첨부)
A2: 구분 | C2: 품 명 | D2: 규격 | E2: 단위 | F2: 수량 | G2: 단가(원) | H2: 금액(원) | I2: 原MAKER
A3: 자 재 비 | B3: 철자재 | H3: =IF(F3=0,G3,G3*F3) -> 0
H4: =IF(F4=0,G4,G4*F4) -> 0
H5: =IF(F5=0,G5,G5*F5) -> 0
H6: =IF(F6=0,G6,G6*F6) -> 0
H7: =SUM(H3:H6) -> 0
B8: 설치/해체/ | H8: =IF(F8=0,G8,G8*F8) -> 0
B9: 시운전 공사 | H9: =IF(F9=0,G9,G9*F9) -> 0
B10: 자재 | H10: =IF(F10=0,G10,G10*F10) -> 0
H11: =IF(F11=0,G11,G11*F11) -> 0
H12: =IF(F12=0,G12,G12*F12) -> 0
H13: =IF(F13=0,G13,G13*F13) -> 0
H14: =SUM(H8:H13) -> 0
B15: 전기자재 | C15: HMI | E15: EA | F15: 0 | G15: 1450000 | H15: =G15*F15 -> 0
C16: PLC BASE | E16: 식 | F16: 0 | G16: 255000 | H16: =G16*F16 -> 0
C17: PLC CPU | E17: 식 | F17: 0 | G17: 1550000 | H17: =G17*F17 -> 0
C18: PLC COMMUNICATON CARD | D18: E-NET | E18: 식 | F18: 0 | G18: 420000 | H18: =G18*F18 -> 0
C19: PLC COMMUNICATON CARD | D19: CC-LINK | E19: 식 | F19: 4 | G19: 195000 | H19: 0 | I19: 사급
C20: PLC COMMUNICATON CARD | D20: RS232C | E20: 식 | F20: 4 | G20: 450000 | H20: 0 | I20: 사급
C21: PLC COMMUNICATON CARD | D21: COUNT | E21: 식 | F21: 0 | G21: 450000 | H21: =G21*F21 -> 0
C22: PLC 위치결정 CARD | D22: SERVO | E22: 식 | F22: 0 | G22: 1250000 | H22: =G22*F22 -> 0
C23: PLC POWER | E23: 식 | F23: 0 | G23: 215000 | H23: =G23*F23 -> 0
C24: IN PUT I/O CARD | E24: 식 | F24: 0 | G24: 205000 | H24: =G24*F24 -> 0
C25: OUT PUT I/O CARD | E25: 식 | F25: 0 | G25: 205000 | H25: =G25*F25 -> 0
C26: REMOTE I/O CARD | E26: 식 | F26: 4 | G26: 155000 | H26: 0 | I26: 사급
C27: CIRCUIT PROTECTER | E27: 식 | F27: 0 | G27: 35000 | H27: =G27*F27 -> 0
C28: HUB | E28: 식 | F28: 0 | G28: 500000 | H28: =G28*F28 -> 0
C29: POWER SUPPLY | E29: 식 | F29: 4 | G29: 350000 | H29: 0 | I29: 사급
C30: SWITCH | E30: 식 | F30: 0 | G30: 100000 | H30: =G30*F30 -> 0
C31: AIR CON | E31: 식 | F31: 0 | G31: 1550000 | H31: =G31*F31 -> 0
C32: 조작반 자재류 | E32: 식 | F32: 0 | G32: 200000 | H32: =G32*F32 -> 0
C33: 제어반 자재류 | E33: 식 | F33: 0 | G33: 200000 | H33: =G33*F33 -> 0
C34: CABLE 류 | E34: 식 | F34: 0 | G34: 700000 | H34: =G34*F34 -> 0
C35: 전장반 및 조작반 외함 | E35: 식 | F35: 1 | G35: 1500000 | H35: =G35*F35 -> 1500000
C36: 기타 구매품 | E36: 식 | F36: 1 | G36: 340000 | H36: =G36*F36 -> 340000
H37: =G37*F37 -> 0
H38: =G38*F38 -> 0
H39: =G39*F39 -> 0
B40: 외주제작품 | H40: =G40*F40 -> 0
...

Sheet 단위장비1
B1: □ 단위공사명(전기제외): | C1: R/RING공정개선(112,203,204,205) | I1: (첨부)
A2: 구분 | C2: 품 명 | D2: 규격 | E2: 단위 | F2: 수량 | G2: 단가(원) | H2: 금액(원) | I2: 原MAKER
A3: 자 재 비 | B3: 철자재 | C3: FRAME 류 | D3: SS400 | E3: KG | F3: 150 | G3: 1200 | H3: =IF(F3=0,G3,G3*F3) -> 180000
C4: PLATE 류 | D4: SS400 | E4: KG | F4: 100 | G4: 1200 | H4: =IF(F4=0,G4,G4*F4) -> 120000
C5: BLOCK 류 | D5: SS400 | E5: KG | F5: 50 | G5: 1200 | H5: =IF(F5=0,G5,G5*F5) -> 60000
H6: =IF(F6=0,G6,G6*F6) -> 0
H7: =IF(F7=0,G7,G7*F7) -> 0
C8: 기타자재 | E8: 식 | F8: 1 | G8: 10000 | H8: =IF(F8=0,G8,G8*F8) -> 10000
H9: =SUM(H3:H8) -> 370000
B10: 설치/해체/시운전 | H10: =IF(F10=0,G10,G10*F10) -> 0
B11: 공사 관련 자재 | H11: =IF(F11=0,G11,G11*F11) -> 0
H12: =IF(F12=0,G12,G12*F12) -> 0
H13: =IF(F13=0,G13,G13*F13) -> 0
C14: 기타자재 | H14: =IF(F14=0,G14,G14*F14) -> 0
H15: =SUM(H10:H14) -> 0
B16: 구매품 | C16: AIR CYL' 류 | E16: 식 | F16: 0 | G16: 900000 | H16: =G16*F16 -> 0
B17: (유공압품외) | C17: CLAMP CYL' 류 | E17: 식 | F17: 0 | G17: 420000 | H17: =G17*F17 -> 0
C18: 직선운동 류 ( LM GUIDE / BALL BUSH ) | E18: 식 | F18: 0 | G18: 1350000 | H18: =G18*F18 -> 0
C19: 회전운동 류 ( BEARING / SPROCKET ) | E19: 식 | F19: 0 | G19: 300000 | H19: =G19*F19 -> 0
C20: PRX' SENSOR | E20: 식 | F20: 0 | G20: 35000 | H20: =G20*F20 -> 0
C21: SENSOR CABLE | E21: 식 | F21: 0 | G21: 10000 | H21: =G21*F21 -> 0
C22: PHOTO' SENSOR | E22: 식 | F22: 0 | G22: 95000 | H22: =G22*F22 -> 0
C23: SENSOR CABLE | E23: 식 | F23: 0 | G23: 10000 | H23: =G23*F23 -> 0
C24: DOOR SENSOR | E24: 식 | F24: 0 | G24: 255000 | H24: =G24*F24 -> 0
C25: AREA SENSOR | E25: 식 | F25: 0 | G25: 1750000 | H25: =G25*F25 -> 0
C26: SOL VELVE 류 | E26: 식 | F26: 0 | G26: 1150000 | H26: =G26*F26 -> 0
C27: F,R,L UNIT | E27: 식 | F27: 0 | G27: 285000 | H27: =G27*F27 -> 0
C28: 기타 구매품 | E28: 식 | F28: 1 | G28: 1000000 | H28: =G28*F28 -> 1000000
H29: =G29*F29 -> 0
C30: 서보 프레스 SET | D30: 0.5 Ton | H30: =G30*F30 -> 0 | I30: 사급
C31: 로드셀 및 인디게이터 SET | H31: =G31*F31 -> 0 | I31: 사급
H32: =G32*F32 -> 0
H33: =G33*F33 -> 0
H34: =G34*F34 -> 0
H35: =G35*F35 -> 0
H36: =IF(F36=0,G36,G36*F36) -> 0
H37: =IF(F37=0,G37,G37*F37) -> 0
H38: =SUM(H16:H37) -> 1000000
B39: 외주제작품 | C39: SLIDE BASE UNIT | E39: 식 | F39: 4 | G39: 1000000 | H39: =IF(F39=0,G39,G39*F39) -> 4000000
C40: RING SUPPLY UNIT | E40: 식 | F40: 4 | G40: 1200000 | H40: =IF(F40=0,G40,G40*F40) -> 4800000
...
