Workbook

Sheet 갑지
B1: (현대/기아차 설비협력업체 견적통일양식)
B2: 見 積 書
B4: 현대 위아 貴下 | G4: 협력사명
B5: 견적일자 | D5: 45922 | G5: 대표 : 김 현 태
B6: 견적번호 | D6: STEM2508-016/17/18/19 | G6: 주소 : 전라남도 장성군 나노산단2로 76
B7: 납기 | C7: 입하 | D7: 협의사항
C8: 최종검수 | D8: 협의사항 | G8: 전화: 062-951-7713
B9: 견적유효기간 | D9: 제출후 30 일 | G9: Fax: 062-971-7713
B10: 인도장소 | D10: 귀사 지정장소 | G10: 견적담당: | H10: 조 귀 현
B11: 지불조건 | D11: 협의사항 | G11: 연 락 처 : | H11: 010-4602-9549
B13: 견적금액 | D13: ="一金"&NUMBERSTRING(H27,1)&"원整" -> 一金이백팔십일만원整 | G13: =H27 -> 2810000.2 | I13: )
B15: 번호 | C15: 상세품목내역 | E15: 견적금액 (천원) | I15: 비 고
E16: 기계부문 | F16: 전기부문 | G16: 관리/이윤 (안전관리비포함) | H16: 합 계 | K16: 기계부문 | L16: 전기부문 | M16: 관리/이윤 | N16: 소계
B17: 1 | C17: COND. CORE BUILDER | E17: 443984 | F17: 608293.4 | G17: 45918.4 | H17: 606999.6 | K17: 443984 | L17: 117097.2 | M17: 45918.4 | N17: 606999.6
B18: 2 | C18: RAD. CORE BUUILDER | E18: 784950.8 | G18: 78495.08 | H18: 1073000.3 | K18: 784950.8 | L18: 209554.4 | M18: 78495.08 | N18: 1073000.3
B19: 3 | C19: EVAP. CORE BUILDER | E19: 411002 | G19: 41100.2 | H19: 593000.1 | K19: 411002 | L19: 140897.9 | M19: 41100.2 | N19: 593000.1
B20: 4 | C20: HTR. CORE BUILDER | E20: 360233 | G20: 36023.3 | H20: 537000.2 | K20: 360233 | L20: 140743.9 | M20: 36023.3 | N20: 537000.2
B21: 5
B22: 6
B23: 7
B24: 8
B25: 9
B26: 10
B27: 견적 합계 | E27: =SUM(E17:E26) -> 2000169.8 | F27: =SUM(F17) -> 608293.4 | G27: =SUM(G17:G26) -> 201536.98 | H27: =SUM(H17:H26) -> 2810000.2 | N27: =SUM(N17:N26) -> 2810000.2
F29: 공개입찰가 (견적時 공란)
B31: 특기사항 | C31: 1. VAT 제외 | F31: 외주계획 업체명 (자작時 공란)
C32: 2. 기본 유틸리티공사 제외 | F32: 설계외주
C33: ='원가항목별(집계)'!I39 -> 0 | F33: 제작외주
F34: 전기외주
F35: 설치외주
K44: =#REF!+#REF!+#REF!+#REF!+#REF!+#REF!+#REF!+#REF!+#REF!+#REF!+#REF! -> #REF!

Sheet 원가항목별(집계)
C2: A. 원가항목별 견적가 종합(상세견적 첨부)
B4: □ 현대/기아 요구사양과 견적조건 일치여부 CHECK: 1.일치함 2.일부상이(상이내역 첨부참조)
B6: 순번 | C6: 원가구분 | F6: 단위 | G6: 수량 | H6: 단가 | I6: 금 액(원) | J6: 비 고 | Q6: COND | R6: RAD | S6: EVAP | T6: HTR
B7: 1 | C7: 기계 부문 | D7: 자재비 | E7: 철자재(SS.SUS등) | F7: kg | G7: 1식 | I7: =SUM(Q7:T7) -> 138200000 | J7: 加工必要資材 | Q7: 20500000 | R7: 49000000 | S7: 32100000 | T7: 36600000
E8: 일반구매품 | F8: 식 | G8: 1 | I8: =SUM(Q8:T8) -> 468474800 | J8: 加工不要資材 | Q8: 101984000 | R8: 200320800 | S8: 110152000 | T8: 56018000
E9: 외주제작품 | F9: 식 | G9: 1 | I9: =SUM(Q9:T9) -> 1025177000 | J9: 旣加工SUB資材 | Q9: 256782000 | R9: 444730000 | S9: 176850000 | T9: 146815000
E10: 설치/해체 공사 자재 | F10: 식 | G10: 1 | I10: 0 | J10: 시운전 자재 포함
E11: 소계 | I11: =SUM(I7:I10) -> 1631851800 | Q11: 379266000 | R11: 694050800 | S11: 319102000 | T11: 239433000
D12: 노무비 | E12: 기존설비 철거 | F12: M/D | G12: 0 | H12: 0 | I12: 0 | J12: 개조공사時
E13: 설계 | F13: M/D | G13: =SUM(U13:X13) -> 60 | H13: 200000 | I13: =H13*G13 -> 12000000 | Q13: 2200000 | R13: 2200000 | S13: 4200000 | T13: 3400000 | U13: 11 | V13: 11 | W13: 21 | X13: 17
E14: 제작(제관,가공) | F14: M/D | G14: 0 | H14: 0 | I14: 0
E15: 조립 | F15: M/D | G15: =SUM(U15:X15) -> 131 | H15: 200000 | I15: =H15*G15 -> 26200000 | J15: 정도검사포함 | Q15: 4200000 | R15: 8400000 | S15: 7400000 | T15: 6200000 | U15: 21 | V15: 42 | W15: 37 | X15: 31
E16: 설치 | F16: M/D | G16: =SUM(U16:X16) -> 174 | H16: 600000 | I16: =H16*G16 -> 104400000 | Q16: 18000000 | R16: 25200000 | S16: 25200000 | T16: 36000000 | U16: 30 | V16: 42 | W16: 42 | X16: 60
E17: 시운전 | F17: M/D | G17: =SUM(U17:X17) -> 16 | H17: 600000 | I17: =H17*G17 -> 9600000 | Q17: 2400000 | R17: 2400000 | S17: 2400000 | T17: 2400000 | U17: 4 | V17: 4 | W17: 4 | X17: 4
E18: 양산대응 | F18: M/D | G18: =SUM(U18:X18) -> 175 | H18: 600000 | I18: =H18*G18 -> 105000000 | J18: 전기 포함 | Q18: 16800000 | R18: 25200000 | S18: 25200000 | T18: 37800000 | U18: 28 | V18: 42 | W18: 42 | X18: 63
E19: 항공료 | F19: M/D | G19: =SUM(U19:X19) -> 45 | H19: 2500000 | I19: =H19*G19 -> 112500000 | Q19: 22500000 | R19: 27500000 | S19: 27500000 | T19: 35000000 | U19: 9 | V19: 11 | W19: 11 | X19: 14
E20: 소계 | I20: =SUM(I12:I19) -> 369700000 | Q20: 66100000 | R20: 90900000 | S20: 91900000 | T20: 120800000
D21: 일반관리 및 이윤 | I21: =SUM(Q21:T21) -> 200155180 | Q21: 44536600 | R21: 78495080 | S21: 41100200 | T21: 36023300
E22: 기계 소계 | I22: =I20+I11+I21 -> 2201706980 | Q22: 489902600 | R22: 863445880 | S22: 452102200 | T22: 396256300
B23: 2 | C23: 전기 부문 | D23: 자재비 | E23: 기계/전기자재 | F23: 식 | G23: 1 | I23: =SUM(Q23:T23) -> 295794000 | Q23: 59852000 | R23: 119704000 | S23: 59489000 | T23: 56749000
E24: 설치/해체 공사 자재 | F24: 식 | G24: 1 | I24: 0 | J24: 시운전 자재 포함
D25: 노무비 | E25: 철거(개조시) | F25: M/D | G25: 0 | H25: 0 | I25: 0
E26: 설계,프로그램 | F26: M/D | G26: =SUM(U26:X26) -> 100 | H26: 200000 | I26: =H26*G26 -> 20000000 | Q26: 4000000 | R26: 6000000 | S26: 6000000 | T26: 4000000 | U26: 20 | V26: 30 | W26: 30 | X26: 20
E27: 제작 | F27: M/D | G27: =SUM(U27:X27) -> 160 | H27: 200000 | I27: =H27*G27 -> 32000000 | Q27: 6000000 | R27: 12000000 | S27: 8000000 | T27: 6000000 | U27: 30 | V27: 60 | W27: 40 | X27: 30
E28: 조립 | F28: M/D | G28: 0 | H28: 200000 | I28: 0
E29: 설치 | F29: M/D | G29: =SUM(U29:X29) -> 151 | H29: 600000 | I29: =H29*G29 -> 90600000 | Q29: 17400000 | R29: 25200000 | S29: 27000000 | T29: 21000000 | U29: 29 | V29: 42 | W29: 45 | X29: 35
E30: 시운전 | F30: M/D | G30: =SUM(U30:X30) -> 16 | H30: 600000 | I30: =H30*G30 -> 9600000 | Q30: 2400000 | R30: 2400000 | S30: 2400000 | T30: 2400000 | U30: 4 | V30: 4 | W30: 4 | X30: 4
E31: 양산대응 | F31: M/D | G31: =SUM(U31:X31) -> 175 | H31: 600000 | I31: =H31*G31 -> 105000000 | Q31: 16800000 | R31: 25200000 | S31: 25200000 | T31: 37800000 | U31: 28 | V31: 42 | W31: 42 | X31: 63
E32: 소계 | I32: =SUM(I25:I31) -> 257200000 | Q32: 46600000 | R32: 70800000 | S32: 68600000 | T32: 71200000
D33: 일반관리 및 이윤 | I33: =SUM(Q33:T33) -> 55299400 | Q33: 10645200 | R33: 19050400 | S33: 12808900 | T33: 12794900
E34: 전기 소계 | I34: =I32+I23+I33+I24 -> 608293400 | Q34: 117097200 | R34: 209554400 | S34: 140897900 | T34: 140743900
B35: 3 | C35: 자재비 합계 | I35: =I23+I11+I24 -> 1927645800 | Q35: 439118000 | R35: 813754800 | S35: 378591000 | T35: 296182000
C36: 노무비 합계 | I36: =I32+I20 -> 626900000 | Q36: 112700000 | R36: 161700000 | S36: 160500000 | T36: 192000000
C37: 중간 합계 | I37: =I36+I35 -> 2554545800 | Q37: 551818000 | R37: 975454800 | S37: 539091000 | T37: 488182000
B38: 4 | C38: 포장,운송 및 중장비 사용료
B39: 5 | C39: 표준안전관리비 | F39: 설치/철거/수리금액 기준 | J39: =I30+I29+I25+I24+I17+I16+I12+I10 -> 214200000
B40: 6 | C40: 일반관리비 | I40: =SUM(Q40:T40) -> 127727290 | Q40: 27590900 | R40: 48772740 | S40: 26954550 | T40: 24409100
B41: 7 | C41: 이 윤 | I41: =SUM(Q41:T41) -> 127727290 | Q41: 27590900 | R41: 48772740 | S41: 26954550 | T41: 24409100
C42: 합 계 | F42: 3~7항 합계 | I42: =I22+I34+I38+I39 -> 2810000380 | Q42: 606999800 | R42: 1073000280 | S42: 593000100 | T42: 537000200
B43: 주1. 표준안전관리비:(설치/철거/시운전 공사 관련 금액)의
...

Sheet 단위공사별(집계)
A2: B. 단위장비별 견적가 종합(상세견적 첨부)
N3: 단위:원
I5: 포장/운송 | L5: 표준안전 | M5: 일반관리비
A6: 순번 | B6: 단위장비명 | C6: 수량 | D6: 자재비 | E6: 철거 | F6: 제작 | G6: 설치/시운전 | H6: 양산대응 | I6: 중장비사용 | J6: 기계소계 | K6: 전기소계 | L6: 관리비 | M6: 이윤 | N6: 합 계 | O6: 비 고
A7: =IF(B7>0,1,"") -> 1 | B7: =갑지!C17 -> COND. CORE BUILDER | C7: 1식 | D7: 379266000 | E7: 0 | F7: 6400000 | G7: 32900000 | H7: 26800000 | I7: 0 | J7: 445366000 | K7: 1.170972e+08 | L7: 0 | M7: 44536600 | N7: =SUM(J7:M7) -> 606999800 | P7: =D7+E7+F7+G7+H7+M7 -> 489902600
A8: =IF(B8>0,A7+1,"") -> 2 | B8: =갑지!C18 -> RAD. CORE BUUILDER | C8: 1식 | D8: 694050800 | E8: 0 | F8: 10600000 | G8: 40100000 | H8: 40200000 | I8: 0 | J8: 784950800 | K8: 2.095544e+08 | L8: 0 | M8: 78495080 | N8: =SUM(J8:M8) -> 1073000280 | P8: =D8+E8+F8+G8+H8+M8 -> 863445880
A9: =IF(B9>0,A8+1,"") -> 3 | B9: =갑지!C19 -> EVAP. CORE BUILDER | C9: 1식 | D9: 319102000 | E9: 0 | F9: 11600000 | G9: 40100000 | H9: 40200000 | I9: 0 | J9: 411002000 | K9: 140897900 | L9: 0 | M9: 41100200 | N9: =SUM(J9:M9) -> 593000100 | P9: =D9+E9+F9+G9+H9+M9 -> 452102200
A10: =IF(B10>0,A9+1,"") -> 4 | B10: =갑지!C20 -> HTR. CORE BUILDER | C10: 1식 | D10: 239433000 | E10: 0 | F10: 9600000 | G10: 50900000 | H10: 60300000 | I10: 0 | J10: 360233000 | K10: 1.407439e+08 | L10: 0 | M10: 36023300 | N10: =SUM(J10:M10) -> 537000200 | P10: =D10+E10+F10+G10+H10+M10 -> 396256300
P11: =D11+E11+F11+G11+H11+M11 -> 0
P12: =D12+E12+F12+G12+H12+M12 -> 0
P13: =D13+E13+F13+G13+H13+M13 -> 0
P14: =D14+E14+F14+G14+H14+M14 -> 0
P15: =D15+E15+F15+G15+H15+M15 -> 0
P16: =D16+E16+F16+G16+H16+M16 -> 0
A17: 합 계 | D17: =SUM(D7:D16) -> 1631851800 | E17: =SUM(E7:E16) -> 0 | F17: =SUM(F7:F16) -> 38200000 | G17: =SUM(G7:G16) -> 164000000 | H17: =SUM(H7:H16) -> 167500000 | I17: =SUM(I7:I16) -> 0 | J17: =SUM(D17:I17) -> 2001551800 | K17: =SUM(K7:K16) -> 608293400 | L17: =SUM(L7:L16) -> 0 | M17: =SUM(M7:M16) -> 200155180 | N17: =SUM(N7:N14) -> 2810000380 | P17: =SUM(P7:P16) -> 2201706980
D18: =IF(D17=0,"",D17/$N17) -> 0.5807301 | E18: =IF(E17=0,"",E17/$N17) | F18: =IF(F17=0,"",F17/$N17) -> 0.013594304 | G18: =IF(G17=0,"",G17/$N17) -> 0.058362981 | H18: =IF(H17=0,"",H17/$N17) -> 0.059608533 | I18: =IF(I17=0,"",I17/$N17) | J18: =IF(J17=0,"",J17/$N17) -> 0.71229592 | K18: =IF(K17=0,"",K17/$N17) -> 0.21647449 | ... N18: =IF(N17=0,"",N17/$N17) -> 1
A19: 주) 전기비용은 턴키장비의 공통비용으로서 총 전기비용을 단위장비별 기계금액의 비율에 따라 배분함
N20: =IF('원가항목별(집계)'!I42='단위공사별(집계)'!N17,"","DATA오류입니다!")
H22: =SUM(G17:H17) -> 331500000 | J22: =SUM(J17,M17) -> 2201706980

Sheet Sheet1
