Workbook

Sheet 갑지
B1: (현대/기아차 설비협력업체 견적통일양식)
B2: 見 積 書
B4: 현대 위아 貴下 | G4: ㈜부남테크
B5: 견적일자 | D5: =TODAY() -> 46210 | G5: 대표 : 김기효
B6: 견적번호 | D6: DM250313-001 | G6: 주소 : 경기도 안산시 상록구 담원안길 25
B7: 납기 | C7: 입하 | D7: 2025 년 월 일
C8: 최종검수 | D8: 2025 년 월 일 | G8: 전화: 031-409-5421
B9: 견적유효기간 | D9: 제출후 30 일 | G9: Fax: 031-409-5420
B10: 인도장소 | D10: 귀사 지정장소 | G10: 견적담당: | H10: 지정도
B11: 지불조건 | D11: 협의사항 | G11: 연 락 처 : | H11: 010-3624-2351
B13: 견적금액 | D13: ="一金"&NUMBERSTRING(H27,1)&"천원整" -> 一金일백칠십삼만오천이백구천원整 | G13: =H27 -> 1735209 | I13: )
B15: 번호 | C15: 상세품목내역 | E15: 견적금액 (천원) | I15: 비 고
E16: 설치/시운전 | G16: 관리/이윤 (안전관리비포함) | H16: 합 계
B17: 1 | C17: ='공사(라인)1'!C1 -> KMX SVM 차종설치 시운전 | E17: =IF('단위공사별(집계)'!P7>1,('단위공사별(집계)'!D7+'단위공사별(집계)'!E7+'단위공사별(집계)'!F7+'단위공사별(집계)'!G7+'단위공사별(집계)'!I7+'단위공사별(집계)'!K7)/1000," ") -> 1466073 | G17: =IF('단위공사별(집계)'!P7>0,('단위공사별(집계)'!M7+'단위공사별(집계)'!N7+'단위공사별(집계)'!O7)/1000,"") -> 66486 | H17: =IF('단위공사별(집계)'!P7>0,'단위공사별(집계)'!P7/1000,"") -> 1735209
B18: 2 | C18: ='공사(라인)2'!C1 -> 0 | E18: =IF('단위공사별(집계)'!P8>1,('단위공사별(집계)'!D8+'단위공사별(집계)'!E8+'단위공사별(집계)'!F8+'단위공사별(집계)'!G8+'단위공사별(집계)'!I8+'단위공사별(집계)'!K8)/1000," ") | G18: =IF('단위공사별(집계)'!P8>0,('단위공사별(집계)'!M8+'단위공사별(집계)'!N8+'단위공사별(집계)'!O8)/1000,"") | H18: =IF('단위공사별(집계)'!P8>0,'단위공사별(집계)'!P8/1000,"")
B19: 3 | C19: ='공사(라인)3'!C1 -> 0 | E19: =IF('단위공사별(집계)'!P9>1,('단위공사별(집계)'!D9+'단위공사별(집계)'!E9+'단위공사별(집계)'!F9+'단위공사별(집계)'!G9+'단위공사별(집계)'!I9+'단위공사별(집계)'!K9)/1000," ") | G19: =IF('단위공사별(집계)'!P9>0,('단위공사별(집계)'!M9+'단위공사별(집계)'!N9+'단위공사별(집계)'!O9)/1000,"") | H19: =IF('단위공사별(집계)'!P9>0,'단위공사별(집계)'!P9/1000,"")
B20: 4 | C20: ='공사(라인)4'!C1 -> 0 | E20: =IF('단위공사별(집계)'!P10>1,('단위공사별(집계)'!D10+'단위공사별(집계)'!E10+'단위공사별(집계)'!F10+'단위공사별(집계)'!G10+'단위공사별(집계)'!I10+'단위공사별(집계)'!K10)/1000," ") | G20: =IF('단위공사별(집계)'!P10>0,('단위공사별(집계)'!M10+'단위공사별(집계)'!N10+'단위공사별(집계)'!O10)/1000,"") | H20: =IF('단위공사별(집계)'!P10>0,'단위공사별(집계)'!P10/1000,"")
B21: 5 | C21: ='공사(라인)5'!C1 -> 0 | E21: =IF('단위공사별(집계)'!P11>1,('단위공사별(집계)'!D11+'단위공사별(집계)'!E11+'단위공사별(집계)'!F11+'단위공사별(집계)'!G11+'단위공사별(집계)'!I11+'단위공사별(집계)'!K11)/1000," ") | G21: =IF('단위공사별(집계)'!P11>0,('단위공사별(집계)'!M11+'단위공사별(집계)'!N11+'단위공사별(집계)'!O11)/1000,"") | H21: =IF('단위공사별(집계)'!P11>0,'단위공사별(집계)'!P11/1000,"")
B22: 6 | C22: ='공사(라인)6'!C1 -> 0 | E22: =IF('단위공사별(집계)'!P12>1,('단위공사별(집계)'!D12+'단위공사별(집계)'!E12+'단위공사별(집계)'!F12+'단위공사별(집계)'!G12+'단위공사별(집계)'!I12+'단위공사별(집계)'!K12)/1000," ") | G22: =IF('단위공사별(집계)'!P12>0,('단위공사별(집계)'!M12+'단위공사별(집계)'!N12+'단위공사별(집계)'!O12)/1000,"") | H22: =IF('단위공사별(집계)'!P12>0,'단위공사별(집계)'!P12/1000,"")
B23: 7 | C23: ='공사(라인)7'!C1 -> 0 | E23: =IF('단위공사별(집계)'!P13>1,('단위공사별(집계)'!D13+'단위공사별(집계)'!E13+'단위공사별(집계)'!F13+'단위공사별(집계)'!G13+'단위공사별(집계)'!I13+'단위공사별(집계)'!K13)/1000," ") | G23: =IF('단위공사별(집계)'!P13>0,('단위공사별(집계)'!M13+'단위공사별(집계)'!N13+'단위공사별(집계)'!O13)/1000,"") | H23: =IF('단위공사별(집계)'!P13>0,'단위공사별(집계)'!P13/1000,"")
B24: 8 | C24: ='공사(라인)8'!C1 -> 0 | E24: =IF('단위공사별(집계)'!P14>1,('단위공사별(집계)'!D14+'단위공사별(집계)'!E14+'단위공사별(집계)'!F14+'단위공사별(집계)'!G14+'단위공사별(집계)'!I14+'단위공사별(집계)'!K14)/1000," ") | G24: =IF('단위공사별(집계)'!P14>0,('단위공사별(집계)'!M14+'단위공사별(집계)'!N14+'단위공사별(집계)'!O14)/1000,"") | H24: =IF('단위공사별(집계)'!P14>0,'단위공사별(집계)'!P14/1000,"")
B25: 9 | C25: ='공사(라인)9'!C1 -> 0 | E25: =IF('단위공사별(집계)'!P15>1,('단위공사별(집계)'!D15+'단위공사별(집계)'!E15+'단위공사별(집계)'!F15+'단위공사별(집계)'!G15+'단위공사별(집계)'!I15+'단위공사별(집계)'!K15)/1000," ") | G25: =IF('단위공사별(집계)'!P15>0,('단위공사별(집계)'!M15+'단위공사별(집계)'!N15+'단위공사별(집계)'!O15)/1000,"") | H25: =IF('단위공사별(집계)'!P15>0,'단위공사별(집계)'!P15/1000,"")
B26: 10 | C26: ='공사(라인)10'!C1 -> 0 | E26: =IF('단위공사별(집계)'!P16>1,('단위공사별(집계)'!D16+'단위공사별(집계)'!E16+'단위공사별(집계)'!F16+'단위공사별(집계)'!G16+'단위공사별(집계)'!I16+'단위공사별(집계)'!K16)/1000," ") | G26: =IF('단위공사별(집계)'!P16>0,('단위공사별(집계)'!M16+'단위공사별(집계)'!N16+'단위공사별(집계)'!O16)/1000,"") | H26: =IF('단위공사별(집계)'!P16>0,'단위공사별(집계)'!P16/1000,"")
B27: 견적 합계 | E27: =SUM(E17:F26) -> 1466073 | G27: =SUM(G17:G26) -> 66486 | H27: =SUM(H17:H26) -> 1735209
F29: 공개입찰가 (견적時 공란) | H29: 1712850
B31: 특기사항 | C31: 1. VAT 제외 | F31: 외주계획 업체명 (자작時 공란)
C32: 2. 기본 유틸리티공사 제외 | F32: 설계외주
C33: ='원가항목별(집계)'!I18 -> 0 | F33: 제작외주
F34: 공사외주
F35: 시운전외주
K44: =#REF!+#REF!+#REF!+#REF!+#REF!+#REF!+#REF!+#REF!+#REF!+#REF!+#REF! -> #REF!

Sheet 원가항목별(집계)
C2: A. 원가항목별 견적가 종합(상세견적 첨부)
B4: □ 현대/기아 요구사양과 견적조건 일치여부 CHECK: 1.일치함 2.일부상이(상이내역 첨부참조)
B6: 순번 | C6: 원가구분 | F6: 단위 | G6: 수량 | H6: 단가 | I6: 금 액(원) | J6: 비 고
B7: 1 | C7: 직접비 | D7: 자재비 | E7: 설치자재비 | F7: 식 | G7: 1 | H7: ='단위공사별(집계)'!D17 -> 6573000 | I7: =SUM(G7*H7) -> 6573000
E8: 일반구매품 | F8: 식 | G8: 1 | H8: ='단위공사별(집계)'!E17 -> 0 | I8: =SUM(G8*H8) -> 0
E9: 외주제작품 | F9: 식 | G9: 1 | H9: ='단위공사별(집계)'!F17 -> 0 | I9: =SUM(G9*H9) -> 0
E10: 소계 | I10: =SUM(I7:I9) -> 6573000
D11: 노무비 | E11: 설치 | F11: 식 | G11: 1 | H11: ='단위공사별(집계)'!G17 -> 58200000 | I11: =SUM(G11*H11) -> 58200000
E12: 티칭/시운전 | F12: 식 | G12: 1 | H12: ='단위공사별(집계)'!H17 -> 181400000 | I12: =SUM(G12*H12) -> 181400000
E13: 품확/이벤트/생산대응 | F13: 식 | G13: 1 | H13: ='단위공사별(집계)'!I17 -> 714000000 | I13: =SUM(G13*H13) -> 714000000
E14: 추가공사 및 기타 | F14: 식 | G14: 1 | H14: ='단위공사별(집계)'!J17 -> 21250000 | I14: =SUM(G14*H14) -> 21250000
E15: 소계 | I15: =SUM(I11:I14) -> 974850000
D16: 경비 | F16: 식 | G16: 1 | H16: ='단위공사별(집계)'!K17 -> 687300000 | I16: =SUM(G16*H16) -> 687300000
E17: 소 계 | I17: =SUM(I16) -> 687300000
B18: 2 | C18: 표준안전관리비 | F18: 설치/철거/수리금액 기준 | I18: ='단위공사별(집계)'!M17 -> 0
B19: 3 | C19: 일반관리비 | I19: ='단위공사별(집계)'!N17 -> 0
B20: 4 | C20: 이 윤 | I20: ='단위공사별(집계)'!O17 -> 66486000
C21: 합 계 | F21: 1~4항 합계 | I21: =SUM(I10,I15,I17,I18,I19,I20) -> 1735209000
B22: 주1. 표준안전관리비:(설치/철거/시운전 공사 관련 금액)의
B23: ⓐ3.15%(5억원미만),ⓑ2.53%+기초액(5억원 이상 ~ 50억원 미만),ⓒ2.60%(50억 이상일경우)
B24: 주2. 제작을 전량 외주할경우 자재비중 [외주제작품] 항목은 삭제함

Sheet 단위공사별(집계)
A2: B. 단위장비별 견적가 종합(상세견적 첨부)
P3: 단위:원
D5: 재료비 | G5: 노무비 | K5: 경비
A6: 순번 | B6: 단위장비명 | C6: 수량 | D6: 설치자재비 | E6: 일반구매품 | F6: 외주제작품 | G6: 설치 | H6: 티칭/시운전 | I6: 품확/이벤트/생산대응 | J6: 추가공사 및 기타 | K6: 경비 | L6: 소계 | M6: 표준안전관리비 | N6: 일반관리비 | O6: 이윤 | P6: 합 계 | Q6: 비 고
A7: =IF(B7>0,1,"") -> 1 | B7: ='공사(라인)1'!C$1 -> KMX SVM 차종설치 시운전 | C7: 1식 | D7: ='공사(라인)1'!I25 -> 6573000 | E7: ='공사(라인)1'!I28 -> 0 | F7: ='공사(라인)1'!I31 -> 0 | G7: ='공사(라인)1'!I59 -> 58200000 | H7: ='공사(라인)1'!I72 -> 181400000 | I7: ='공사(라인)1'!I77 -> 714000000 | J7: ='공사(라인)1'!I89 -> 21250000 | K7: ='공사(라인)1'!I96 -> 687300000 | L7: =SUM(D7:K7) -> 1668723000 | M7: ='공사(라인)1'!I98 -> 0 | N7: ='공사(라인)1'!I99 -> 0 | O7: ='공사(라인)1'!I100 -> 66486000 | P7: =SUM(L7:O7) -> 1735209000
A8: =IF(B8>0,1,"") | B8: ='공사(라인)2'!C1 -> 0 | C8: 1식 | D8: ='공사(라인)2'!I5 -> 0 | E8: ='공사(라인)2'!I8 -> 0 | F8: ='공사(라인)2'!I11 -> 0 | G8: ='공사(라인)2'!I48 -> 0 | H8: ='공사(라인)2'!I61 -> 0 | I8: ='공사(라인)2'!I66 -> 0 | J8: ='공사(라인)2'!I78 -> 0 | K8: ='공사(라인)2'!I82 -> 0 | L8: =SUM(D8:K8) -> 0 | M8: ='공사(라인)2'!I84 -> 0 | N8: ='공사(라인)2'!I85 -> 0 | O8: ='공사(라인)2'!I86 -> 0 | P8: =SUM(L8:O8) -> 0
A9: =IF(B9>0,1,"") | B9: ='공사(라인)3'!C$1 -> 0 | C9: 1식 | D9: ='공사(라인)3'!I5 -> 0 | E9: ='공사(라인)3'!I8 -> 0 | F9: ='공사(라인)3'!I11 -> 0 | G9: ='공사(라인)3'!I48 -> 0 | H9: ='공사(라인)3'!I61 -> 0 | I9: ='공사(라인)3'!I66 -> 0 | J9: ='공사(라인)3'!I78 -> 0 | K9: ='공사(라인)3'!I82 -> 0 | L9: =SUM(D9:K9) -> 0 | M9: ='공사(라인)3'!I84 -> 0 | N9: ='공사(라인)3'!I85 -> 0 | O9: ='공사(라인)3'!I86 -> 0 | P9: =SUM(L9:O9) -> 0
A10: =IF(B10>0,1,"") | B10: ='공사(라인)4'!C$1 -> 0 | C10: 1식 | D10: ='공사(라인)4'!I5 -> 0 | E10: ='공사(라인)4'!I8 -> 0 | F10: ='공사(라인)4'!I11 -> 0 | G10: ='공사(라인)4'!I48 -> 0 | H10: ='공사(라인)4'!I61 -> 0 | I10: ='공사(라인)4'!I66 -> 0 | J10: ='공사(라인)4'!I78 -> 0 | K10: ='공사(라인)4'!I82 -> 0 | L10: =SUM(D10:K10) -> 0 | M10: ='공사(라인)4'!I84 -> 0 | N10: ='공사(라인)4'!I85 -> 0 | O10: ='공사(라인)4'!I86 -> 0 | P10: =SUM(L10:O10) -> 0
A11: =IF(B11>0,1,"") | B11: ='공사(라인)5'!C$1 -> 0 | C11: 1식 | D11: ='공사(라인)5'!I5 -> 0 | E11: ='공사(라인)5'!I8 -> 0 | F11: ='공사(라인)5'!I11 -> 0 | G11: ='공사(라인)5'!I48 -> 0 | H11: ='공사(라인)5'!I61 -> 0 | I11: ='공사(라인)5'!I66 -> 0 | J11: ='공사(라인)5'!I78 -> 0 | K11: ='공사(라인)5'!I82 -> 0 | L11: =SUM(D11:K11) -> 0 | M11: ='공사(라인)5'!I84 -> 0 | N11: ='공사(라인)5'!I85 -> 0 | O11: ='공사(라인)5'!I86 -> 0 | P11: =SUM(L11:O11) -> 0
A12: =IF(B12>0,1,"") | B12: ='공사(라인)6'!C$1 -> 0 | C12: 1식 | D12: ='공사(라인)6'!I5 -> 0 | E12: ='공사(라인)6'!I8 -> 0 | F12: ='공사(라인)6'!I11 -> 0 | G12: ='공사(라인)6'!I48 -> 0 | H12: ='공사(라인)6'!I61 -> 0 | I12: ='공사(라인)6'!I66 -> 0 | J12: ='공사(라인)6'!I78 -> 0 | K12: ='공사(라인)6'!I82 -> 0 | L12: =SUM(D12:K12) -> 0 | M12: ='공사(라인)6'!I84 -> 0 | N12: ='공사(라인)6'!I85 -> 0 | O12: ='공사(라인)6'!I86 -> 0 | P12: =SUM(L12:O12) -> 0
A13: =IF(B13>0,1,"") | B13: ='공사(라인)7'!C$1 -> 0 | C13: 1식 | D13: ='공사(라인)7'!I5 -> 0 | E13: ='공사(라인)7'!I8 -> 0 | F13: ='공사(라인)7'!I11 -> 0 | G13: ='공사(라인)7'!I48 -> 0 | H13: ='공사(라인)7'!I61 -> 0 | I13: ='공사(라인)7'!I66 -> 0 | J13: ='공사(라인)7'!I78 -> 0 | K13: ='공사(라인)7'!I82 -> 0 | L13: =SUM(D13:K13) -> 0 | M13: ='공사(라인)7'!I84 -> 0 | N13: ='공사(라인)7'!I85 -> 0 | O13: ='공사(라인)7'!I86 -> 0 | P13: =SUM(L13:O13) -> 0
A14: =IF(B14>0,1,"") | B14: ='공사(라인)8'!C$1 -> 0 | C14: 1식 | D14: ='공사(라인)8'!I5 -> 0 | E14: ='공사(라인)8'!I8 -> 0 | F14: ='공사(라인)8'!I11 -> 0 | G14: ='공사(라인)8'!I48 -> 0 | H14: ='공사(라인)8'!I61 -> 0 | I14: ='공사(라인)8'!I66 -> 0 | J14: ='공사(라인)8'!I78 -> 0 | K14: ='공사(라인)8'!I82 -> 0 | L14: =SUM(D14:K14) -> 0 | M14: ='공사(라인)8'!I84 -> 0 | N14: ='공사(라인)8'!I85 -> 0 | O14: ='공사(라인)8'!I86 -> 0 | P14: =SUM(L14:O14) -> 0
A15: =IF(B15>0,1,"") | B15: ='공사(라인)9'!C$1 -> 0 | C15: 1식 | D15: ='공사(라인)9'!I5 -> 0 | E15: ='공사(라인)9'!I8 -> 0 | F15: ='공사(라인)9'!I11 -> 0 | G15: ='공사(라인)9'!I48 -> 0 | H15: ='공사(라인)9'!I61 -> 0 | I15: ='공사(라인)9'!I66 -> 0 | J15: ='공사(라인)9'!I78 -> 0 | K15: ='공사(라인)9'!I82 -> 0 | L15: =SUM(D15:K15) -> 0 | M15: ='공사(라인)9'!I84 -> 0 | N15: ='공사(라인)9'!I85 -> 0 | O15: ='공사(라인)9'!I86 -> 0 | P15: =SUM(L15:O15) -> 0
A16: =IF(B16>0,1,"") | B16: ='공사(라인)10'!C$1 -> 0 | C16: 1식 | D16: ='공사(라인)10'!I5 -> 0 | E16: ='공사(라인)10'!I8 -> 0 | F16: ='공사(라인)10'!I11 -> 0 | G16: ='공사(라인)10'!I48 -> 0 | H16: ='공사(라인)10'!I61 -> 0 | I16: ='공사(라인)10'!I66 -> 0 | J16: ='공사(라인)10'!I78 -> 0 | K16: ='공사(라인)10'!I82 -> 0 | L16: =SUM(D16:K16) -> 0 | M16: ='공사(라인)10'!I84 -> 0 | N16: ='공사(라인)10'!I85 -> 0 | O16: ='공사(라인)10'!I86 -> 0 | P16: =SUM(L16:O16) -> 0
A17: 합 계 | D17: =SUM(D7:D16) -> 6573000 | E17: =SUM(E7:E16) -> 0 | F17: =SUM(F7:F16) -> 0 | G17: =SUM(G7:G16) -> 58200000 | H17: =SUM(H7:H16) -> 181400000 | I17: =SUM(I7:I16) -> 714000000 | J17: =SUM(J7:J16) -> 21250000 | K17: =SUM(K7:K16) -> 687300000 | ... P17: =SUM(P7:P16) -> 1735209000
D18: =IF(D17=0,"",D17/$P17) -> 0.0037880163 | E18: =IF(E17=0,"",E17/$P17) | F18: =IF(F17=0,"",F17/$P17) | G18: =IF(G17=0,"",G17/$P17) -> 0.033540628 | H18: =IF(H17=0,"",H17/$P17) -> 0.10454072 | I18: =IF(I17=0,"",I17/$P17) -> 0.41147781 | J18: =IF(J17=0,"",J17/$P17) -> 0.012246363 | K18: =IF(K17=0,"",K17/$P17) -> 0.39609062 | ... P18: =IF(P17=0,"",P17/$P17) -> 1
P20: =IF('원가항목별(집계)'!I21='단위공사별(집계)'!P17,"","DATA오류입니다!")

Sheet 공사(라인)1
B1: □ 단위공사명: | C1: KMX SVM 차종설치 시운전 | J1: (첨부)
A2: 구분 | C2: 품 명 | E2: 규격 | F2: 단위 | G2: 수량 | H2: 단가(원) | I2: 금액(원) | J2: 原MAKER
B3: 설치자재비 | C3: 냉각수 호수 | D3: Coolant Hose | E3: 19Ø(적색) | F3: M | G3: 50 | H3: 5100 | I3: =IF(G3=0,H3,H3*G3) -> 255000 | J3: 야성
C4: 냉각수 호수 | D4: Coolant Hose | E4: 19Ø(녹색) | F4: M | G4: 25 | H4: 5100 | I4: =IF(G4=0,H4,H4*G4) -> 127500 | J4: 야성
C5: 에어호수 | D5: Coolant Hose | E5: 12Ø(흑색) | F5: M | G5: 100 | H5: 2410 | I5: =IF(G5=0,H5,H5*G5) -> 241000 | J5: 야성
C6: 냉각수 호수 | D6: CNU | E6: 16x12(녹색) | F6: M | G6: 50 | H6: 3000 | I6: =IF(G6=0,H6,H6*G6) -> 150000 | J6: NITTA
C7: 냉각수 호수 | D7: CNU | E7: 12*8(적색) | F7: M | G7: 200 | H7: 3000 | I7: =IF(G7=0,H7,H7*G7) -> 600000 | J7: NITTA
C8: 냉각수 호수 | D8: CNU | E8: 12*8(적색) | F8: M | G8: 200 | H8: 3000 | I8: =IF(G8=0,H8,H8*G8) -> 600000 | J8: NITTA
C9: 에어 호수 | D9: U2 | E9: 12*8(흑색) | F9: M | G9: 100 | H9: 1400 | I9: =IF(G9=0,H9,H9*G9) -> 140000 | J9: NITTA
C10: 용접케이블 (무빙용) | D10: ROEEU | E10: 1G25(노랑) | F10: M | G10: 50 | H10: 9000 | I10: =IF(G10=0,H10,H10*G10) -> 450000 | J10: 경신
C11: 용접케이블 (무빙용) | D11: ROEEU | E11: 1G25(녹) | F11: M | G11: 25 | H11: 9000 | I11: =IF(G11=0,H11,H11*G11) -> 225000 | J11: 경신
C12: 통신케이블 (고정형) | D12: Profibus L2 indoor | E12: 1X2X0.64 | F12: M | G12: 200 | H12: 2300 | I12: =IF(G12=0,H12,H12*G12) -> 460000 | J12: HELU
C13: 통신케이블 (무빙형) | D13: Profibus L2 Torsion | E13: 1X2X0.8 | F13: M | G13: 30 | H13: 8800 | I13: =IF(G13=0,H13,H13*G13) -> 264000 | J13: HELU
C14: 신호 케이블 (고정용) | D14: PCVV | E14: 4G 0.75 | F14: M | G14: 50 | H14: 900 | I14: =IF(G14=0,H14,H14*G14) -> 45000 | J14: 경신
C15: 신호 케이블 (무빙용) | D15: ROEEU | E15: 4G 1 | F15: M | G15: 50 | H15: 3500 | I15: =IF(G15=0,H15,H15*G15) -> 175000 | J15: 경신
... C23: 용접케이블 (고정용) | D23: H07RNF | E23: 3G 25 | F23: M | G23: 30 | H23: 30000 | I23: =IF(G23=0,H23,H23*G23) -> 900000 | J23: 경신
C24: 기계 | F24: SET | G24: 2 | H24: 300000 | I24: 600000
I25: =SUM(I3:I24) -> 6573000
B26: 일반구매품 | I26: =IF(G26=0,H26,H26*G26) -> 0
B27: (유공압품 등) | I27: =IF(G27=0,H27,H27*G27) -> 0
I28: =SUM(I26:I27) -> 0
B29: 외주제작품 | F29: SET | I29: =IF(G29=0,H29,H29*G29) -> 0
I30: =IF(G30=0,H30,H30*G30) -> 0
I31: =SUM(I29:I30) -> 0
B32: 자재비 소계 | I32: =SUM(I31,I28,I25) -> 6573000
A33: 노 무 비 | B33: 설치 | C33: 로봇 설치(철거/설치 포함) | D33: 100kg급 이상 | F33: 식 | G33: 2 | H33: 4500000 | I33: =G33*H33 -> 9000000 | J33: 중장비 포함
D34: 30 ~ 100kg급 미만 | F34: 식 | I34: =G34*H34 -> 0
D35: 30kg급 미만 | F35: 식 | I35: =G35*H35 -> 0
C36: 로봇 설치(가설 미포함) | D36: 100kg급 이상 | F36: 식 | I36: =G36*H36 -> 0
D37: 30 ~ 100kg급 미만 | F37: 식 | I37: =G37*H37 -> 0
D38: 30kg급 미만 | F38: 식 | I38: =G38*H38 -> 0
C39: 로봇 철거 | D39: 100kg급 이상 | F39: 식 | I39: =G39*H39 -> 0
D40: 30 ~ 100kg급 미만 | F40: 식 | I40: =G40*H40 -> 0
D41: 30kg급 미만 | F41: 식 | I41: =G41*H41 -> 0
C42: 배관/배선(가설 포함) | D42: SPOT용접 | F42: 식 | I42: =G42*H42 -> 0
D43: HANDLING/SEALING | F43: 식 | I43: =G43*H43 -> 0
D44: ARC용접 | F44: 식 | I44: =G44*H44 -> 0
C45: 배관/배선(가설 미포함) | D45: SPOT용접 | F45: 식 | G45: 2 | H45: 3500000 | I45: =G45*H45 -> 7000000
D46: HANDLING/SEALING | F46: 식 | I46: =G46*H46 -> 0
D47: ARC용접 | F47: 식 | I47: =G47*H47 -> 0
...

Sheet 공사(라인)2
B1: □ 단위공사명: | J1: (첨부)
A2: 구분 | C2: 품 명 | E2: 규격 | F2: 단위 | G2: 수량 | H2: 단가(원) | I2: 금액(원) | J2: 原MAKER
A3: 자 재 비 | B3: 설치자재비 | C3: 볼트 | D3: MAIN PANEL | E3: W600*H2000*D500 | F3: 1 | G3: 500 | I3: =IF(G3=0,H3,H3*G3) -> 0 | J3: RITTAL | K3: ← 예시
C4: 앙카
I5: =SUM(I3:I4) -> 0
B6: 일반구매품 | I6: =IF(G6=0,H6,H6*G6) -> 0
B7: (유공압품 등) | I7: =IF(G7=0,H7,H7*G7) -> 0
I8: =SUM(I6:I7) -> 0
B9: 외주제작품 | I9: =IF(G9=0,H9,H9*G9) -> 0
I10: =IF(G10=0,H10,H10*G10) -> 0
I11: =SUM(I9:I10) -> 0
B12: 자재비 소계 | I12: =SUM(I11,I8,I5) -> 0
A13: 노 무 비 | B13: 설치 | C13: 로봇 설치(철거/설치 포함) | D13: 100kg급 이상 | E13: (0명 x 0일) | F13: M/D | I13: =G13*H13 -> 0
D14: 30 ~ 100kg급 미만 | E14: (0명 x 0일) | F14: M/D | I14: =G14*H14 -> 0
D15: 30kg급 미만 | E15: (0명 x 0일) | F15: M/D | I15: =G15*H15 -> 0
C16: 로봇 설치(가설 미포함) | D16: 100kg급 이상 | E16: (0명 x 0일) | F16: M/D | I16: =G16*H16 -> 0
D17: 30 ~ 100kg급 미만 | E17: (0명 x 0일) | F17: M/D | I17: =G17*H17 -> 0
D18: 30kg급 미만 | E18: (0명 x 0일) | F18: M/D | I18: =G18*H18 -> 0
C19: 로봇 철거 | D19: 100kg급 이상 | E19: (0명 x 0일) | F19: M/D | I19: =G19*H19 -> 0
D20: 30 ~ 100kg급 미만 | E20: (0명 x 0일) | F20: M/D | I20: =G20*H20 -> 0
D21: 30kg급 미만 | E21: (0명 x 0일) | F21: M/D | I21: =G21*H21 -> 0
C22: 배관/배선(가설 포함) | D22: SPOT용접 | E22: (0명 x 0일) | F22: M/D | I22: =G22*H22 -> 0
D23: HANDLING/SEALING | E23: (0명 x 0일) | F23: M/D | I23: =G23*H23 -> 0
D24: ARC용접 | E24: (0명 x 0일) | F24: M/D | I24: =G24*H24 -> 0
C25: 배관/배선(가설 미포함) | D25: SPOT용접 | E25: (0명 x 0일) | F25: M/D | I25: =G25*H25 -> 0
D26: HANDLING/SEALING | E26: (0명 x 0일) | F26: M/D | I26: =G26*H26 -> 0
D27: ARC용접 | E27: (0명 x 0일) | F27: M/D | I27: =G27*H27 -> 0
C28: 안전펜스 철거/개조/설치 | D28: 20 M 미만 | E28: (0명 x 0일) | F28: M/D | I28: =G28*H28 -> 0
D29: 20 ~ 50 M 미만 | E29: (0명 x 0일) | F29: M/D | I29: =G29*H29 -> 0
D30: 50 M 이상 | E30: (0명 x 0일) | F30: M/D | I30: =G30*H30 -> 0
C31: GUN 신작 | E31: (0명 x 0일) | F31: M/D | I31: =G31*H31 -> 0
C32: 캐리지 설치 | D32: 기계부설치 | E32: (0명 x 0일) | F32: M/D | I32: =G32*H32 -> 0
C33: 행거 신작 | D33: 설치/배선/배관 | E33: (0명 x 0일) | F33: M/D | I33: =G33*H33 -> 0
C34: 작업발판&안전팬스 | E34: (0명 x 0일) | F34: M/D | I34: =G34*H34 -> 0
C35: ATD 신규 | D35: 배선/배관 | E35: (0명 x 0일) | F35: M/D | I35: =G35*H35 -> 0
C36: T/C 신규 | D36: 배선/배관 | E36: (0명 x 0일) | F36: M/D | I36: =G36*H36 -> 0
C37: ESS 이설 | D37: 배선/배관 정리포함 | E37: (0명 x 0일) | F37: M/D | I37: =G37*H37 -> 0
C38: 제어반 이동 | E38: (0명 x 0일) | F38: M/D | I38: =G38*H38 -> 0
C39: 변위센서 제품교체 | D39: 제품교체(보전사급) | E39: (0명 x 0일) | F39: M/D | I39: =G39*H39 -> 0
C40: 주행하네스 V3교체 | D40: 가와사키 케이블교체 | E40: (0명 x 0일) | F40: M/D | I40: =G40*H40 -> 0
...

Sheet 공사(라인)3
B1: □ 단위공사명: | J1: (첨부)
A2: 구분 | C2: 품 명 | E2: 규격 | F2: 단위 | G2: 수량 | H2: 단가(원) | I2: 금액(원) | J2: 原MAKER
A3: 자 재 비 | B3: 설치자재비 | C3: 볼트 | D3: MAIN PANEL | E3: W600*H2000*D500 | F3: 1 | G3: 1 | I3: =IF(G3=0,H3,H3*G3) -> 0 | J3: RITTAL | K3: ← 예시
C4: 앙카
I5: =SUM(I3:I4) -> 0
B6: 일반구매품 | I6: =IF(G6=0,H6,H6*G6) -> 0
B7: (유공압품 등) | I7: =IF(G7=0,H7,H7*G7) -> 0
I8: =SUM(I6:I7) -> 0
B9: 외주제작품 | I9: =IF(G9=0,H9,H9*G9) -> 0
I10: =IF(G10=0,H10,H10*G10) -> 0
I11: =SUM(I9:I10) -> 0
B12: 자재비 소계 | I12: =SUM(I11,I8,I5) -> 0
A13: 노 무 비 | B13: 설치 | C13: 로봇 설치(철거/설치 포함) | D13: 100kg급 이상 | E13: (0명 x 0일) | F13: M/D | I13: =G13*H13 -> 0
D14: 30 ~ 100kg급 미만 | E14: (0명 x 0일) | F14: M/D | I14: =G14*H14 -> 0
D15: 30kg급 미만 | E15: (0명 x 0일) | F15: M/D | I15: =G15*H15 -> 0
C16: 로봇 설치(가설 미포함) | D16: 100kg급 이상 | E16: (0명 x 0일) | F16: M/D | I16: =G16*H16 -> 0
D17: 30 ~ 100kg급 미만 | E17: (0명 x 0일) | F17: M/D | I17: =G17*H17 -> 0
D18: 30kg급 미만 | E18: (0명 x 0일) | F18: M/D | I18: =G18*H18 -> 0
C19: 로봇 철거 | D19: 100kg급 이상 | E19: (0명 x 0일) | F19: M/D | I19: =G19*H19 -> 0
D20: 30 ~ 100kg급 미만 | E20: (0명 x 0일) | F20: M/D | I20: =G20*H20 -> 0
D21: 30kg급 미만 | E21: (0명 x 0일) | F21: M/D | I21: =G21*H21 -> 0
C22: 배관/배선(가설 포함) | D22: SPOT용접 | E22: (0명 x 0일) | F22: M/D | I22: =G22*H22 -> 0
D23: HANDLING/SEALING | E23: (0명 x 0일) | F23: M/D | I23: =G23*H23 -> 0
D24: ARC용접 | E24: (0명 x 0일) | F24: M/D | I24: =G24*H24 -> 0
C25: 배관/배선(가설 미포함) | D25: SPOT용접 | E25: (0명 x 0일) | F25: M/D | I25: =G25*H25 -> 0
D26: HANDLING/SEALING | E26: (0명 x 0일) | F26: M/D | I26: =G26*H26 -> 0
D27: ARC용접 | E27: (0명 x 0일) | F27: M/D | I27: =G27*H27 -> 0
C28: 안전펜스 철거/개조/설치 | D28: 20 M 미만 | E28: (0명 x 0일) | F28: M/D | I28: =G28*H28 -> 0
D29: 20 ~ 50 M 미만 | E29: (0명 x 0일) | F29: M/D | I29: =G29*H29 -> 0
D30: 50 M 이상 | E30: (0명 x 0일) | F30: M/D | I30: =G30*H30 -> 0
C31: GUN 신작 | E31: (0명 x 0일) | F31: M/D | I31: =G31*H31 -> 0
C32: 캐리지 설치 | D32: 기계부설치 | E32: (0명 x 0일) | F32: M/D | I32: =G32*H32 -> 0
C33: 행거 신작 | D33: 설치/배선/배관 | E33: (0명 x 0일) | F33: M/D | I33: =G33*H33 -> 0
C34: 작업발판&안전팬스 | E34: (0명 x 0일) | F34: M/D | I34: =G34*H34 -> 0
C35: ATD 신규 | D35: 배선/배관 | E35: (0명 x 0일) | F35: M/D | I35: =G35*H35 -> 0
C36: T/C 신규 | D36: 배선/배관 | E36: (0명 x 0일) | F36: M/D | I36: =G36*H36 -> 0
C37: ESS 이설 | D37: 배선/배관 정리포함 | E37: (0명 x 0일) | F37: M/D | I37: =G37*H37 -> 0
C38: 제어반 이동 | E38: (0명 x 0일) | F38: M/D | I38: =G38*H38 -> 0
C39: 변위센서 제품교체 | D39: 제품교체(보전사급) | E39: (0명 x 0일) | F39: M/D | I39: =G39*H39 -> 0
C40: 주행하네스 V3교체 | D40: 가와사키 케이블교체 | E40: (0명 x 0일) | F40: M/D | I40: =G40*H40 -> 0
...

Sheet 공사(라인)4
B1: □ 단위공사명: | J1: (첨부)
A2: 구분 | C2: 품 명 | E2: 규격 | F2: 단위 | G2: 수량 | H2: 단가(원) | I2: 금액(원) | J2: 原MAKER
A3: 자 재 비 | B3: 설치자재비 | C3: 볼트 | D3: MAIN PANEL | E3: W600*H2000*D500 | F3: 1 | G3: 1 | I3: =IF(G3=0,H3,H3*G3) -> 0 | J3: RITTAL | K3: ← 예시
C4: 앙카
I5: =SUM(I3:I4) -> 0
B6: 일반구매품 | I6: =IF(G6=0,H6,H6*G6) -> 0
B7: (유공압품 등) | I7: =IF(G7=0,H7,H7*G7) -> 0
I8: =SUM(I6:I7) -> 0
B9: 외주제작품 | I9: =IF(G9=0,H9,H9*G9) -> 0
I10: =IF(G10=0,H10,H10*G10) -> 0
I11: =SUM(I9:I10) -> 0
B12: 자재비 소계 | I12: =SUM(I11,I8,I5) -> 0
A13: 노 무 비 | B13: 설치 | C13: 로봇 설치(철거/설치 포함) | D13: 100kg급 이상 | E13: (0명 x 0일) | F13: M/D | I13: =G13*H13 -> 0
D14: 30 ~ 100kg급 미만 | E14: (0명 x 0일) | F14: M/D | I14: =G14*H14 -> 0
D15: 30kg급 미만 | E15: (0명 x 0일) | F15: M/D | I15: =G15*H15 -> 0
C16: 로봇 설치(가설 미포함) | D16: 100kg급 이상 | E16: (0명 x 0일) | F16: M/D | I16: =G16*H16 -> 0
D17: 30 ~ 100kg급 미만 | E17: (0명 x 0일) | F17: M/D | I17: =G17*H17 -> 0
D18: 30kg급 미만 | E18: (0명 x 0일) | F18: M/D | I18: =G18*H18 -> 0
C19: 로봇 철거 | D19: 100kg급 이상 | E19: (0명 x 0일) | F19: M/D | I19: =G19*H19 -> 0
D20: 30 ~ 100kg급 미만 | E20: (0명 x 0일) | F20: M/D | I20: =G20*H20 -> 0
D21: 30kg급 미만 | E21: (0명 x 0일) | F21: M/D | I21: =G21*H21 -> 0
C22: 배관/배선(가설 포함) | D22: SPOT용접 | E22: (0명 x 0일) | F22: M/D | I22: =G22*H22 -> 0
D23: HANDLING/SEALING | E23: (0명 x 0일) | F23: M/D | I23: =G23*H23 -> 0
D24: ARC용접 | E24: (0명 x 0일) | F24: M/D | I24: =G24*H24 -> 0
C25: 배관/배선(가설 미포함) | D25: SPOT용접 | E25: (0명 x 0일) | F25: M/D | I25: =G25*H25 -> 0
D26: HANDLING/SEALING | E26: (0명 x 0일) | F26: M/D | I26: =G26*H26 -> 0
D27: ARC용접 | E27: (0명 x 0일) | F27: M/D | I27: =G27*H27 -> 0
C28: 안전펜스 철거/개조/설치 | D28: 20 M 미만 | E28: (0명 x 0일) | F28: M/D | I28: =G28*H28 -> 0
D29: 20 ~ 50 M 미만 | E29: (0명 x 0일) | F29: M/D | I29: =G29*H29 -> 0
D30: 50 M 이상 | E30: (0명 x 0일) | F30: M/D | I30: =G30*H30 -> 0
C31: GUN 신작 | E31: (0명 x 0일) | F31: M/D | I31: =G31*H31 -> 0
C32: 캐리지 설치 | D32: 기계부설치 | E32: (0명 x 0일) | F32: M/D | I32: =G32*H32 -> 0
C33: 행거 신작 | D33: 설치/배선/배관 | E33: (0명 x 0일) | F33: M/D | I33: =G33*H33 -> 0
C34: 작업발판&안전팬스 | E34: (0명 x 0일) | F34: M/D | I34: =G34*H34 -> 0
C35: ATD 신규 | D35: 배선/배관 | E35: (0명 x 0일) | F35: M/D | I35: =G35*H35 -> 0
C36: T/C 신규 | D36: 배선/배관 | E36: (0명 x 0일) | F36: M/D | I36: =G36*H36 -> 0
C37: ESS 이설 | D37: 배선/배관 정리포함 | E37: (0명 x 0일) | F37: M/D | I37: =G37*H37 -> 0
C38: 제어반 이동 | E38: (0명 x 0일) | F38: M/D | I38: =G38*H38 -> 0
C39: 변위센서 제품교체 | D39: 제품교체(보전사급) | E39: (0명 x 0일) | F39: M/D | I39: =G39*H39 -> 0
C40: 주행하네스 V3교체 | D40: 가와사키 케이블교체 | E40: (0명 x 0일) | F40: M/D | I40: =G40*H40 -> 0
...

Sheet 공사(라인)5
B1: □ 단위공사명: | J1: (첨부)
A2: 구분 | C2: 품 명 | E2: 규격 | F2: 단위 | G2: 수량 | H2: 단가(원) | I2: 금액(원) | J2: 原MAKER
A3: 자 재 비 | B3: 설치자재비 | C3: 볼트 | D3: MAIN PANEL | E3: W600*H2000*D500 | F3: 1 | G3: 1 | I3: =IF(G3=0,H3,H3*G3) -> 0 | J3: RITTAL | K3: ← 예시
C4: 앙카
I5: =SUM(I3:I4) -> 0
B6: 일반구매품 | I6: =IF(G6=0,H6,H6*G6) -> 0
B7: (유공압품 등) | I7: =IF(G7=0,H7,H7*G7) -> 0
I8: =SUM(I6:I7) -> 0
B9: 외주제작품 | I9: =IF(G9=0,H9,H9*G9) -> 0
I10: =IF(G10=0,H10,H10*G10) -> 0
I11: =SUM(I9:I10) -> 0
B12: 자재비 소계 | I12: =SUM(I11,I8,I5) -> 0
A13: 노 무 비 | B13: 설치 | C13: 로봇 설치(철거/설치 포함) | D13: 100kg급 이상 | E13: (0명 x 0일) | F13: M/D | I13: =G13*H13 -> 0
D14: 30 ~ 100kg급 미만 | E14: (0명 x 0일) | F14: M/D | I14: =G14*H14 -> 0
D15: 30kg급 미만 | E15: (0명 x 0일) | F15: M/D | I15: =G15*H15 -> 0
C16: 로봇 설치(가설 미포함) | D16: 100kg급 이상 | E16: (0명 x 0일) | F16: M/D | I16: =G16*H16 -> 0
D17: 30 ~ 100kg급 미만 | E17: (0명 x 0일) | F17: M/D | I17: =G17*H17 -> 0
D18: 30kg급 미만 | E18: (0명 x 0일) | F18: M/D | I18: =G18*H18 -> 0
C19: 로봇 철거 | D19: 100kg급 이상 | E19: (0명 x 0일) | F19: M/D | I19: =G19*H19 -> 0
D20: 30 ~ 100kg급 미만 | E20: (0명 x 0일) | F20: M/D | I20: =G20*H20 -> 0
D21: 30kg급 미만 | E21: (0명 x 0일) | F21: M/D | I21: =G21*H21 -> 0
C22: 배관/배선(가설 포함) | D22: SPOT용접 | E22: (0명 x 0일) | F22: M/D | I22: =G22*H22 -> 0
D23: HANDLING/SEALING | E23: (0명 x 0일) | F23: M/D | I23: =G23*H23 -> 0
D24: ARC용접 | E24: (0명 x 0일) | F24: M/D | I24: =G24*H24 -> 0
C25: 배관/배선(가설 미포함) | D25: SPOT용접 | E25: (0명 x 0일) | F25: M/D | I25: =G25*H25 -> 0
D26: HANDLING/SEALING | E26: (0명 x 0일) | F26: M/D | I26: =G26*H26 -> 0
D27: ARC용접 | E27: (0명 x 0일) | F27: M/D | I27: =G27*H27 -> 0
C28: 안전펜스 철거/개조/설치 | D28: 20 M 미만 | E28: (0명 x 0일) | F28: M/D | I28: =G28*H28 -> 0
D29: 20 ~ 50 M 미만 | E29: (0명 x 0일) | F29: M/D | I29: =G29*H29 -> 0
D30: 50 M 이상 | E30: (0명 x 0일) | F30: M/D | I30: =G30*H30 -> 0
C31: GUN 신작 | E31: (0명 x 0일) | F31: M/D | I31: =G31*H31 -> 0
C32: 캐리지 설치 | D32: 기계부설치 | E32: (0명 x 0일) | F32: M/D | I32: =G32*H32 -> 0
C33: 행거 신작 | D33: 설치/배선/배관 | E33: (0명 x 0일) | F33: M/D | I33: =G33*H33 -> 0
C34: 작업발판&안전팬스 | E34: (0명 x 0일) | F34: M/D | I34: =G34*H34 -> 0
C35: ATD 신규 | D35: 배선/배관 | E35: (0명 x 0일) | F35: M/D | I35: =G35*H35 -> 0
C36: T/C 신규 | D36: 배선/배관 | E36: (0명 x 0일) | F36: M/D | I36: =G36*H36 -> 0
C37: ESS 이설 | D37: 배선/배관 정리포함 | E37: (0명 x 0일) | F37: M/D | I37: =G37*H37 -> 0
C38: 제어반 이동 | E38: (0명 x 0일) | F38: M/D | I38: =G38*H38 -> 0
C39: 변위센서 제품교체 | D39: 제품교체(보전사급) | E39: (0명 x 0일) | F39: M/D | I39: =G39*H39 -> 0
C40: 주행하네스 V3교체 | D40: 가와사키 케이블교체 | E40: (0명 x 0일) | F40: M/D | I40: =G40*H40 -> 0
...

Sheet 공사(라인)6
B1: □ 단위공사명: | J1: (첨부)
A2: 구분 | C2: 품 명 | E2: 규격 | F2: 단위 | G2: 수량 | H2: 단가(원) | I2: 금액(원) | J2: 原MAKER
A3: 자 재 비 | B3: 설치자재비 | C3: 볼트 | D3: MAIN PANEL | E3: W600*H2000*D500 | F3: 1 | G3: 1 | I3: =IF(G3=0,H3,H3*G3) -> 0 | J3: RITTAL | K3: ← 예시
C4: 앙카
I5: =SUM(I3:I4) -> 0
B6: 일반구매품 | I6: =IF(G6=0,H6,H6*G6) -> 0
B7: (유공압품 등) | I7: =IF(G7=0,H7,H7*G7) -> 0
I8: =SUM(I6:I7) -> 0
B9: 외주제작품 | I9: =IF(G9=0,H9,H9*G9) -> 0
I10: =IF(G10=0,H10,H10*G10) -> 0
I11: =SUM(I9:I10) -> 0
B12: 자재비 소계 | I12: =SUM(I11,I8,I5) -> 0
A13: 노 무 비 | B13: 설치 | C13: 로봇 설치(철거/설치 포함) | D13: 100kg급 이상 | E13: (0명 x 0일) | F13: M/D | I13: =G13*H13 -> 0
D14: 30 ~ 100kg급 미만 | E14: (0명 x 0일) | F14: M/D | I14: =G14*H14 -> 0
D15: 30kg급 미만 | E15: (0명 x 0일) | F15: M/D | I15: =G15*H15 -> 0
C16: 로봇 설치(가설 미포함) | D16: 100kg급 이상 | E16: (0명 x 0일) | F16: M/D | I16: =G16*H16 -> 0
D17: 30 ~ 100kg급 미만 | E17: (0명 x 0일) | F17: M/D | I17: =G17*H17 -> 0
D18: 30kg급 미만 | E18: (0명 x 0일) | F18: M/D | I18: =G18*H18 -> 0
C19: 로봇 철거 | D19: 100kg급 이상 | E19: (0명 x 0일) | F19: M/D | I19: =G19*H19 -> 0
D20: 30 ~ 100kg급 미만 | E20: (0명 x 0일) | F20: M/D | I20: =G20*H20 -> 0
D21: 30kg급 미만 | E21: (0명 x 0일) | F21: M/D | I21: =G21*H21 -> 0
C22: 배관/배선(가설 포함) | D22: SPOT용접 | E22: (0명 x 0일) | F22: M/D | I22: =G22*H22 -> 0
D23: HANDLING/SEALING | E23: (0명 x 0일) | F23: M/D | I23: =G23*H23 -> 0
D24: ARC용접 | E24: (0명 x 0일) | F24: M/D | I24: =G24*H24 -> 0
C25: 배관/배선(가설 미포함) | D25: SPOT용접 | E25: (0명 x 0일) | F25: M/D | I25: =G25*H25 -> 0
D26: HANDLING/SEALING | E26: (0명 x 0일) | F26: M/D | I26: =G26*H26 -> 0
D27: ARC용접 | E27: (0명 x 0일) | F27: M/D | I27: =G27*H27 -> 0
C28: 안전펜스 철거/개조/설치 | D28: 20 M 미만 | E28: (0명 x 0일) | F28: M/D | I28: =G28*H28 -> 0
D29: 20 ~ 50 M 미만 | E29: (0명 x 0일) | F29: M/D | I29: =G29*H29 -> 0
D30: 50 M 이상 | E30: (0명 x 0일) | F30: M/D | I30: =G30*H30 -> 0
C31: GUN 신작 | E31: (0명 x 0일) | F31: M/D | I31: =G31*H31 -> 0
C32: 캐리지 설치 | D32: 기계부설치 | E32: (0명 x 0일) | F32: M/D | I32: =G32*H32 -> 0
C33: 행거 신작 | D33: 설치/배선/배관 | E33: (0명 x 0일) | F33: M/D | I33: =G33*H33 -> 0
C34: 작업발판&안전팬스 | E34: (0명 x 0일) | F34: M/D | I34: =G34*H34 -> 0
C35: ATD 신규 | D35: 배선/배관 | E35: (0명 x 0일) | F35: M/D | I35: =G35*H35 -> 0
C36: T/C 신규 | D36: 배선/배관 | E36: (0명 x 0일) | F36: M/D | I36: =G36*H36 -> 0
C37: ESS 이설 | D37: 배선/배관 정리포함 | E37: (0명 x 0일) | F37: M/D | I37: =G37*H37 -> 0
C38: 제어반 이동 | E38: (0명 x 0일) | F38: M/D | I38: =G38*H38 -> 0
C39: 변위센서 제품교체 | D39: 제품교체(보전사급) | E39: (0명 x 0일) | F39: M/D | I39: =G39*H39 -> 0
C40: 주행하네스 V3교체 | D40: 가와사키 케이블교체 | E40: (0명 x 0일) | F40: M/D | I40: =G40*H40 -> 0
...

Sheet 공사(라인)7
B1: □ 단위공사명: | J1: (첨부)
A2: 구분 | C2: 품 명 | E2: 규격 | F2: 단위 | G2: 수량 | H2: 단가(원) | I2: 금액(원) | J2: 原MAKER
A3: 자 재 비 | B3: 설치자재비 | C3: 볼트 | D3: MAIN PANEL | E3: W600*H2000*D500 | F3: 1 | G3: 1 | I3: =IF(G3=0,H3,H3*G3) -> 0 | J3: RITTAL | K3: ← 예시
C4: 앙카
I5: =SUM(I3:I4) -> 0
B6: 일반구매품 | I6: =IF(G6=0,H6,H6*G6) -> 0
B7: (유공압품 등) | I7: =IF(G7=0,H7,H7*G7) -> 0
I8: =SUM(I6:I7) -> 0
B9: 외주제작품 | I9: =IF(G9=0,H9,H9*G9) -> 0
I10: =IF(G10=0,H10,H10*G10) -> 0
I11: =SUM(I9:I10) -> 0
B12: 자재비 소계 | I12: =SUM(I11,I8,I5) -> 0
A13: 노 무 비 | B13: 설치 | C13: 로봇 설치(철거/설치 포함) | D13: 100kg급 이상 | E13: (0명 x 0일) | F13: M/D | I13: =G13*H13 -> 0
D14: 30 ~ 100kg급 미만 | E14: (0명 x 0일) | F14: M/D | I14: =G14*H14 -> 0
D15: 30kg급 미만 | E15: (0명 x 0일) | F15: M/D | I15: =G15*H15 -> 0
C16: 로봇 설치(가설 미포함) | D16: 100kg급 이상 | E16: (0명 x 0일) | F16: M/D | I16: =G16*H16 -> 0
D17: 30 ~ 100kg급 미만 | E17: (0명 x 0일) | F17: M/D | I17: =G17*H17 -> 0
D18: 30kg급 미만 | E18: (0명 x 0일) | F18: M/D | I18: =G18*H18 -> 0
C19: 로봇 철거 | D19: 100kg급 이상 | E19: (0명 x 0일) | F19: M/D | I19: =G19*H19 -> 0
D20: 30 ~ 100kg급 미만 | E20: (0명 x 0일) | F20: M/D | I20: =G20*H20 -> 0
D21: 30kg급 미만 | E21: (0명 x 0일) | F21: M/D | I21: =G21*H21 -> 0
C22: 배관/배선(가설 포함) | D22: SPOT용접 | E22: (0명 x 0일) | F22: M/D | I22: =G22*H22 -> 0
D23: HANDLING/SEALING | E23: (0명 x 0일) | F23: M/D | I23: =G23*H23 -> 0
D24: ARC용접 | E24: (0명 x 0일) | F24: M/D | I24: =G24*H24 -> 0
C25: 배관/배선(가설 미포함) | D25: SPOT용접 | E25: (0명 x 0일) | F25: M/D | I25: =G25*H25 -> 0
D26: HANDLING/SEALING | E26: (0명 x 0일) | F26: M/D | I26: =G26*H26 -> 0
D27: ARC용접 | E27: (0명 x 0일) | F27: M/D | I27: =G27*H27 -> 0
C28: 안전펜스 철거/개조/설치 | D28: 20 M 미만 | E28: (0명 x 0일) | F28: M/D | I28: =G28*H28 -> 0
D29: 20 ~ 50 M 미만 | E29: (0명 x 0일) | F29: M/D | I29: =G29*H29 -> 0
D30: 50 M 이상 | E30: (0명 x 0일) | F30: M/D | I30: =G30*H30 -> 0
C31: GUN 신작 | E31: (0명 x 0일) | F31: M/D | I31: =G31*H31 -> 0
C32: 캐리지 설치 | D32: 기계부설치 | E32: (0명 x 0일) | F32: M/D | I32: =G32*H32 -> 0
C33: 행거 신작 | D33: 설치/배선/배관 | E33: (0명 x 0일) | F33: M/D | I33: =G33*H33 -> 0
C34: 작업발판&안전팬스 | E34: (0명 x 0일) | F34: M/D | I34: =G34*H34 -> 0
C35: ATD 신규 | D35: 배선/배관 | E35: (0명 x 0일) | F35: M/D | I35: =G35*H35 -> 0
C36: T/C 신규 | D36: 배선/배관 | E36: (0명 x 0일) | F36: M/D | I36: =G36*H36 -> 0
C37: ESS 이설 | D37: 배선/배관 정리포함 | E37: (0명 x 0일) | F37: M/D | I37: =G37*H37 -> 0
C38: 제어반 이동 | E38: (0명 x 0일) | F38: M/D | I38: =G38*H38 -> 0
C39: 변위센서 제품교체 | D39: 제품교체(보전사급) | E39: (0명 x 0일) | F39: M/D | I39: =G39*H39 -> 0
C40: 주행하네스 V3교체 | D40: 가와사키 케이블교체 | E40: (0명 x 0일) | F40: M/D | I40: =G40*H40 -> 0
...

Sheet 공사(라인)8
B1: □ 단위공사명: | J1: (첨부)
A2: 구분 | C2: 품 명 | E2: 규격 | F2: 단위 | G2: 수량 | H2: 단가(원) | I2: 금액(원) | J2: 原MAKER
A3: 자 재 비 | B3: 설치자재비 | C3: 볼트 | D3: MAIN PANEL | E3: W600*H2000*D500 | F3: 1 | G3: 1 | I3: =IF(G3=0,H3,H3*G3) -> 0 | J3: RITTAL | K3: ← 예시
C4: 앙카
I5: =SUM(I3:I4) -> 0
B6: 일반구매품 | I6: =IF(G6=0,H6,H6*G6) -> 0
B7: (유공압품 등) | I7: =IF(G7=0,H7,H7*G7) -> 0
I8: =SUM(I6:I7) -> 0
B9: 외주제작품 | I9: =IF(G9=0,H9,H9*G9) -> 0
I10: =IF(G10=0,H10,H10*G10) -> 0
I11: =SUM(I9:I10) -> 0
B12: 자재비 소계 | I12: =SUM(I11,I8,I5) -> 0
A13: 노 무 비 | B13: 설치 | C13: 로봇 설치(철거/설치 포함) | D13: 100kg급 이상 | E13: (0명 x 0일) | F13: M/D | I13: =G13*H13 -> 0
D14: 30 ~ 100kg급 미만 | E14: (0명 x 0일) | F14: M/D | I14: =G14*H14 -> 0
D15: 30kg급 미만 | E15: (0명 x 0일) | F15: M/D | I15: =G15*H15 -> 0
C16: 로봇 설치(가설 미포함) | D16: 100kg급 이상 | E16: (0명 x 0일) | F16: M/D | I16: =G16*H16 -> 0
D17: 30 ~ 100kg급 미만 | E17: (0명 x 0일) | F17: M/D | I17: =G17*H17 -> 0
D18: 30kg급 미만 | E18: (0명 x 0일) | F18: M/D | I18: =G18*H18 -> 0
C19: 로봇 철거 | D19: 100kg급 이상 | E19: (0명 x 0일) | F19: M/D | I19: =G19*H19 -> 0
D20: 30 ~ 100kg급 미만 | E20: (0명 x 0일) | F20: M/D | I20: =G20*H20 -> 0
D21: 30kg급 미만 | E21: (0명 x 0일) | F21: M/D | I21: =G21*H21 -> 0
C22: 배관/배선(가설 포함) | D22: SPOT용접 | E22: (0명 x 0일) | F22: M/D | I22: =G22*H22 -> 0
D23: HANDLING/SEALING | E23: (0명 x 0일) | F23: M/D | I23: =G23*H23 -> 0
D24: ARC용접 | E24: (0명 x 0일) | F24: M/D | I24: =G24*H24 -> 0
C25: 배관/배선(가설 미포함) | D25: SPOT용접 | E25: (0명 x 0일) | F25: M/D | I25: =G25*H25 -> 0
D26: HANDLING/SEALING | E26: (0명 x 0일) | F26: M/D | I26: =G26*H26 -> 0
D27: ARC용접 | E27: (0명 x 0일) | F27: M/D | I27: =G27*H27 -> 0
C28: 안전펜스 철거/개조/설치 | D28: 20 M 미만 | E28: (0명 x 0일) | F28: M/D | I28: =G28*H28 -> 0
D29: 20 ~ 50 M 미만 | E29: (0명 x 0일) | F29: M/D | I29: =G29*H29 -> 0
D30: 50 M 이상 | E30: (0명 x 0일) | F30: M/D | I30: =G30*H30 -> 0
C31: GUN 신작 | E31: (0명 x 0일) | F31: M/D | I31: =G31*H31 -> 0
C32: 캐리지 설치 | D32: 기계부설치 | E32: (0명 x 0일) | F32: M/D | I32: =G32*H32 -> 0
C33: 행거 신작 | D33: 설치/배선/배관 | E33: (0명 x 0일) | F33: M/D | I33: =G33*H33 -> 0
C34: 작업발판&안전팬스 | E34: (0명 x 0일) | F34: M/D | I34: =G34*H34 -> 0
C35: ATD 신규 | D35: 배선/배관 | E35: (0명 x 0일) | F35: M/D | I35: =G35*H35 -> 0
C36: T/C 신규 | D36: 배선/배관 | E36: (0명 x 0일) | F36: M/D | I36: =G36*H36 -> 0
C37: ESS 이설 | D37: 배선/배관 정리포함 | E37: (0명 x 0일) | F37: M/D | I37: =G37*H37 -> 0
C38: 제어반 이동 | E38: (0명 x 0일) | F38: M/D | I38: =G38*H38 -> 0
C39: 변위센서 제품교체 | D39: 제품교체(보전사급) | E39: (0명 x 0일) | F39: M/D | I39: =G39*H39 -> 0
C40: 주행하네스 V3교체 | D40: 가와사키 케이블교체 | E40: (0명 x 0일) | F40: M/D | I40: =G40*H40 -> 0
...

Sheet 공사(라인)9
B1: □ 단위공사명: | J1: (첨부)
A2: 구분 | C2: 품 명 | E2: 규격 | F2: 단위 | G2: 수량 | H2: 단가(원) | I2: 금액(원) | J2: 原MAKER
A3: 자 재 비 | B3: 설치자재비 | C3: 볼트 | D3: MAIN PANEL | E3: W600*H2000*D500 | F3: 1 | G3: 1 | I3: =IF(G3=0,H3,H3*G3) -> 0 | J3: RITTAL | K3: ← 예시
C4: 앙카
I5: =SUM(I3:I4) -> 0
B6: 일반구매품 | I6: =IF(G6=0,H6,H6*G6) -> 0
B7: (유공압품 등) | I7: =IF(G7=0,H7,H7*G7) -> 0
I8: =SUM(I6:I7) -> 0
B9: 외주제작품 | I9: =IF(G9=0,H9,H9*G9) -> 0
I10: =IF(G10=0,H10,H10*G10) -> 0
I11: =SUM(I9:I10) -> 0
B12: 자재비 소계 | I12: =SUM(I11,I8,I5) -> 0
A13: 노 무 비 | B13: 설치 | C13: 로봇 설치(철거/설치 포함) | D13: 100kg급 이상 | E13: (0명 x 0일) | F13: M/D | I13: =G13*H13 -> 0
D14: 30 ~ 100kg급 미만 | E14: (0명 x 0일) | F14: M/D | I14: =G14*H14 -> 0
D15: 30kg급 미만 | E15: (0명 x 0일) | F15: M/D | I15: =G15*H15 -> 0
C16: 로봇 설치(가설 미포함) | D16: 100kg급 이상 | E16: (0명 x 0일) | F16: M/D | I16: =G16*H16 -> 0
D17: 30 ~ 100kg급 미만 | E17: (0명 x 0일) | F17: M/D | I17: =G17*H17 -> 0
D18: 30kg급 미만 | E18: (0명 x 0일) | F18: M/D | I18: =G18*H18 -> 0
C19: 로봇 철거 | D19: 100kg급 이상 | E19: (0명 x 0일) | F19: M/D | I19: =G19*H19 -> 0
D20: 30 ~ 100kg급 미만 | E20: (0명 x 0일) | F20: M/D | I20: =G20*H20 -> 0
D21: 30kg급 미만 | E21: (0명 x 0일) | F21: M/D | I21: =G21*H21 -> 0
C22: 배관/배선(가설 포함) | D22: SPOT용접 | E22: (0명 x 0일) | F22: M/D | I22: =G22*H22 -> 0
D23: HANDLING/SEALING | E23: (0명 x 0일) | F23: M/D | I23: =G23*H23 -> 0
D24: ARC용접 | E24: (0명 x 0일) | F24: M/D | I24: =G24*H24 -> 0
C25: 배관/배선(가설 미포함) | D25: SPOT용접 | E25: (0명 x 0일) | F25: M/D | I25: =G25*H25 -> 0
D26: HANDLING/SEALING | E26: (0명 x 0일) | F26: M/D | I26: =G26*H26 -> 0
D27: ARC용접 | E27: (0명 x 0일) | F27: M/D | I27: =G27*H27 -> 0
C28: 안전펜스 철거/개조/설치 | D28: 20 M 미만 | E28: (0명 x 0일) | F28: M/D | I28: =G28*H28 -> 0
D29: 20 ~ 50 M 미만 | E29: (0명 x 0일) | F29: M/D | I29: =G29*H29 -> 0
D30: 50 M 이상 | E30: (0명 x 0일) | F30: M/D | I30: =G30*H30 -> 0
C31: GUN 신작 | E31: (0명 x 0일) | F31: M/D | I31: =G31*H31 -> 0
C32: 캐리지 설치 | D32: 기계부설치 | E32: (0명 x 0일) | F32: M/D | I32: =G32*H32 -> 0
C33: 행거 신작 | D33: 설치/배선/배관 | E33: (0명 x 0일) | F33: M/D | I33: =G33*H33 -> 0
C34: 작업발판&안전팬스 | E34: (0명 x 0일) | F34: M/D | I34: =G34*H34 -> 0
C35: ATD 신규 | D35: 배선/배관 | E35: (0명 x 0일) | F35: M/D | I35: =G35*H35 -> 0
C36: T/C 신규 | D36: 배선/배관 | E36: (0명 x 0일) | F36: M/D | I36: =G36*H36 -> 0
C37: ESS 이설 | D37: 배선/배관 정리포함 | E37: (0명 x 0일) | F37: M/D | I37: =G37*H37 -> 0
C38: 제어반 이동 | E38: (0명 x 0일) | F38: M/D | I38: =G38*H38 -> 0
C39: 변위센서 제품교체 | D39: 제품교체(보전사급) | E39: (0명 x 0일) | F39: M/D | I39: =G39*H39 -> 0
C40: 주행하네스 V3교체 | D40: 가와사키 케이블교체 | E40: (0명 x 0일) | F40: M/D | I40: =G40*H40 -> 0
...

Sheet 공사(라인)10
B1: □ 단위공사명: | J1: (첨부)
A2: 구분 | C2: 품 명 | E2: 규격 | F2: 단위 | G2: 수량 | H2: 단가(원) | I2: 금액(원) | J2: 原MAKER
A3: 자 재 비 | B3: 설치자재비 | C3: 볼트 | D3: MAIN PANEL | E3: W600*H2000*D500 | F3: 1 | G3: 1 | I3: =IF(G3=0,H3,H3*G3) -> 0 | J3: RITTAL | K3: ← 예시
C4: 앙카
I5: =SUM(I3:I4) -> 0
B6: 일반구매품 | I6: =IF(G6=0,H6,H6*G6) -> 0
B7: (유공압품 등) | I7: =IF(G7=0,H7,H7*G7) -> 0
I8: =SUM(I6:I7) -> 0
B9: 외주제작품 | I9: =IF(G9=0,H9,H9*G9) -> 0
I10: =IF(G10=0,H10,H10*G10) -> 0
I11: =SUM(I9:I10) -> 0
B12: 자재비 소계 | I12: =SUM(I11,I8,I5) -> 0
A13: 노 무 비 | B13: 설치 | C13: 로봇 설치(철거/설치 포함) | D13: 100kg급 이상 | E13: (0명 x 0일) | F13: M/D | I13: =G13*H13 -> 0
D14: 30 ~ 100kg급 미만 | E14: (0명 x 0일) | F14: M/D | I14: =G14*H14 -> 0
D15: 30kg급 미만 | E15: (0명 x 0일) | F15: M/D | I15: =G15*H15 -> 0
C16: 로봇 설치(가설 미포함) | D16: 100kg급 이상 | E16: (0명 x 0일) | F16: M/D | I16: =G16*H16 -> 0
D17: 30 ~ 100kg급 미만 | E17: (0명 x 0일) | F17: M/D | I17: =G17*H17 -> 0
D18: 30kg급 미만 | E18: (0명 x 0일) | F18: M/D | I18: =G18*H18 -> 0
C19: 로봇 철거 | D19: 100kg급 이상 | E19: (0명 x 0일) | F19: M/D | I19: =G19*H19 -> 0
D20: 30 ~ 100kg급 미만 | E20: (0명 x 0일) | F20: M/D | I20: =G20*H20 -> 0
D21: 30kg급 미만 | E21: (0명 x 0일) | F21: M/D | I21: =G21*H21 -> 0
C22: 배관/배선(가설 포함) | D22: SPOT용접 | E22: (0명 x 0일) | F22: M/D | I22: =G22*H22 -> 0
D23: HANDLING/SEALING | E23: (0명 x 0일) | F23: M/D | I23: =G23*H23 -> 0
D24: ARC용접 | E24: (0명 x 0일) | F24: M/D | I24: =G24*H24 -> 0
C25: 배관/배선(가설 미포함) | D25: SPOT용접 | E25: (0명 x 0일) | F25: M/D | I25: =G25*H25 -> 0
D26: HANDLING/SEALING | E26: (0명 x 0일) | F26: M/D | I26: =G26*H26 -> 0
D27: ARC용접 | E27: (0명 x 0일) | F27: M/D | I27: =G27*H27 -> 0
C28: 안전펜스 철거/개조/설치 | D28: 20 M 미만 | E28: (0명 x 0일) | F28: M/D | I28: =G28*H28 -> 0
D29: 20 ~ 50 M 미만 | E29: (0명 x 0일) | F29: M/D | I29: =G29*H29 -> 0
D30: 50 M 이상 | E30: (0명 x 0일) | F30: M/D | I30: =G30*H30 -> 0
C31: GUN 신작 | E31: (0명 x 0일) | F31: M/D | I31: =G31*H31 -> 0
C32: 캐리지 설치 | D32: 기계부설치 | E32: (0명 x 0일) | F32: M/D | I32: =G32*H32 -> 0
C33: 행거 신작 | D33: 설치/배선/배관 | E33: (0명 x 0일) | F33: M/D | I33: =G33*H33 -> 0
C34: 작업발판&안전팬스 | E34: (0명 x 0일) | F34: M/D | I34: =G34*H34 -> 0
C35: ATD 신규 | D35: 배선/배관 | E35: (0명 x 0일) | F35: M/D | I35: =G35*H35 -> 0
C36: T/C 신규 | D36: 배선/배관 | E36: (0명 x 0일) | F36: M/D | I36: =G36*H36 -> 0
C37: ESS 이설 | D37: 배선/배관 정리포함 | E37: (0명 x 0일) | F37: M/D | I37: =G37*H37 -> 0
C38: 제어반 이동 | E38: (0명 x 0일) | F38: M/D | I38: =G38*H38 -> 0
C39: 변위센서 제품교체 | D39: 제품교체(보전사급) | E39: (0명 x 0일) | F39: M/D | I39: =G39*H39 -> 0
C40: 주행하네스 V3교체 | D40: 가와사키 케이블교체 | E40: (0명 x 0일) | F40: M/D | I40: =G40*H40 -> 0
...

Sheet 첨부(견적조건차이내역)
A1: ※ 현대/기아차의 요구사양과 업체견적사양이 다른경우만 작성
D2: (첨부)
A3: 현대/기아차 요구사양대비 견적조건 상이내역
A5: 항 목 | B5: 현대/기아차 요구사양 | C5: 업체 견적기준 사양 | D5: 비 고

Sheet Sheet1
