Workbook

Sheet 갑지
B1: (현대/기아차 설비협력업체 견적통일양식)
B2: 見 積 書
B4: 현대위아 貴下
B5: 견적일자 | D5: 45929 | G5: 대표 :김동학
B6: 견적번호 | D6: FTC-2531 | G6: 주소 : 경기도 시흥시 군자천로 219
B7: 납기 | C7: 입하 | D7: 발주후 90일
C8: 최종검수 | D8: 2026년 | G8: 전화: 031)314-0803
B9: 견적유효기간 | D9: 견적 제출 후 30일 | G9: Fax: 031)314-0805
B10: 인도장소 | D10: 귀사 지정장소 | G10: 견적담당: | H10: 김 동학
B11: 지불조건 | D11: 정기 지불조건 | G11: 연 락 처 : | H11: 010-8822-0803
B13: 공사명 : C Moudle Assy Table Line SX3i
B14: 견적금액:오억육천만원정
B16: 번호 | C16: 상세품목내역 | E16: 견적금액 (천원) | I16: 비 고
E17: 기계부문 | F17: 전기부문 | G17: 관리/이윤 (안전관리비포함) | H17: 합 계
B18: 1 | C18: =IF('단위공사별(집계)'!N7>0,'단위공사별(집계)'!B7,"") -> ASS'Y TABLE | E18: =IF('단위공사별(집계)'!N7>1,('단위공사별(집계)'!D7+'단위공사별(집계)'!E7+'단위공사별(집계)'!F7+'단위공사별(집계)'!G7+'단위공사별(집계)'!H7+'단위공사별(집계)'!I7)/1000," ") -> 167014.86 | F18: =IF('단위공사별(집계)'!N7>0,'단위공사별(집계)'!K17/1000,"") -> 117375.21 | G18: =IF('단위공사별(집계)'!N7>0,('단위공사별(집계)'!L7+'단위공사별(집계)'!M7)/1000,"") -> 25165.094 | H18: =IF('단위공사별(집계)'!N7>0,'단위공사별(집계)'!N7/1000,"") -> 243132.16
B19: 2 | C19: =IF('단위공사별(집계)'!N8>0,'단위공사별(집계)'!B8,"") -> VISION/BAECODE/DB | E19: =IF('단위공사별(집계)'!N8>1,('단위공사별(집계)'!D8+'단위공사별(집계)'!E8+'단위공사별(집계)'!F8+'단위공사별(집계)'!G8+'단위공사별(집계)'!H8+'단위공사별(집계)'!I8)/1000," ") -> 175784.86 | G19: =IF('단위공사별(집계)'!N8>0,('단위공사별(집계)'!L8+'단위공사별(집계)'!M8)/1000,"") -> 26486.521 | H19: =IF('단위공사별(집계)'!N8>0,'단위공사별(집계)'!N8/1000,"") -> 255899.11
B20: 3 | C20: =IF('단위공사별(집계)'!N9>0,'단위공사별(집계)'!B9,"") -> OTHER COST | E20: =IF('단위공사별(집계)'!N9>1,('단위공사별(집계)'!D9+'단위공사별(집계)'!E9+'단위공사별(집계)'!F9+'단위공사별(집계)'!G9+'단위공사별(집계)'!H9+'단위공사별(집계)'!I9)/1000," ") -> 41941.28 | G20: =IF('단위공사별(집계)'!N9>0,('단위공사별(집계)'!L9+'단위공사별(집계)'!M9)/1000,"") -> 6319.535 | H20: =IF('단위공사별(집계)'!N9>0,'단위공사별(집계)'!N9/1000,"") -> 61056.089
B21: 4 | C21: =IF('단위공사별(집계)'!N10>0,'단위공사별(집계)'!B10,"") | E21: =IF('단위공사별(집계)'!N10>1,('단위공사별(집계)'!D10+'단위공사별(집계)'!E10+'단위공사별(집계)'!F10+'단위공사별(집계)'!G10+'단위공사별(집계)'!H10+'단위공사별(집계)'!I10)/1000," ") | G21: =IF('단위공사별(집계)'!N10>0,('단위공사별(집계)'!L10+'단위공사별(집계)'!M10)/1000,"") | H21: =IF('단위공사별(집계)'!N10>0,'단위공사별(집계)'!N10/1000,"")
B22: 5 | C22: =IF('단위공사별(집계)'!N11>0,'단위공사별(집계)'!B11,"") | E22: =IF('단위공사별(집계)'!N11>1,('단위공사별(집계)'!D11+'단위공사별(집계)'!E11+'단위공사별(집계)'!F11+'단위공사별(집계)'!G11+'단위공사별(집계)'!H11+'단위공사별(집계)'!I11)/1000," ") | G22: =IF('단위공사별(집계)'!N11>0,('단위공사별(집계)'!L11+'단위공사별(집계)'!M11)/1000,"") | H22: =IF('단위공사별(집계)'!N11>0,'단위공사별(집계)'!N11/1000,"")
B23: 6 | C23: =IF('단위공사별(집계)'!N12>0,'단위공사별(집계)'!B12,"") | E23: =IF('단위공사별(집계)'!N12>1,('단위공사별(집계)'!D12+'단위공사별(집계)'!E12+'단위공사별(집계)'!F12+'단위공사별(집계)'!G12+'단위공사별(집계)'!H12+'단위공사별(집계)'!I12)/1000," ") | G23: =IF('단위공사별(집계)'!N12>0,('단위공사별(집계)'!L12+'단위공사별(집계)'!M12)/1000,"") | H23: =IF('단위공사별(집계)'!N12>0,'단위공사별(집계)'!N12/1000,"")
B24: 7 | C24: =IF('단위공사별(집계)'!N13>0,'단위공사별(집계)'!B13,"") | E24: =IF('단위공사별(집계)'!N13>1,('단위공사별(집계)'!D13+'단위공사별(집계)'!E13+'단위공사별(집계)'!F13+'단위공사별(집계)'!G13+'단위공사별(집계)'!H13+'단위공사별(집계)'!I13)/1000," ") | G24: =IF('단위공사별(집계)'!N13>0,('단위공사별(집계)'!L13+'단위공사별(집계)'!M13)/1000,"") | H24: =IF('단위공사별(집계)'!N13>0,'단위공사별(집계)'!N13/1000,"")
B25: 8 | C25: =IF('단위공사별(집계)'!N14>0,'단위공사별(집계)'!B14,"") | E25: =IF('단위공사별(집계)'!N14>1,('단위공사별(집계)'!D14+'단위공사별(집계)'!E14+'단위공사별(집계)'!F14+'단위공사별(집계)'!G14+'단위공사별(집계)'!H14+'단위공사별(집계)'!I14)/1000," ") | G25: =IF('단위공사별(집계)'!N14>0,('단위공사별(집계)'!L14+'단위공사별(집계)'!M14)/1000,"") | H25: =IF('단위공사별(집계)'!N14>0,'단위공사별(집계)'!N14/1000,"")
B26: 9 | C26: =IF('단위공사별(집계)'!N15>0,'단위공사별(집계)'!B15,"") | E26: =IF('단위공사별(집계)'!N15>1,('단위공사별(집계)'!D15+'단위공사별(집계)'!E15+'단위공사별(집계)'!F15+'단위공사별(집계)'!G15+'단위공사별(집계)'!H15+'단위공사별(집계)'!I15)/1000," ") | G26: =IF('단위공사별(집계)'!N15>0,('단위공사별(집계)'!L15+'단위공사별(집계)'!M15)/1000,"") | H26: =IF('단위공사별(집계)'!N15>0,'단위공사별(집계)'!N15/1000,"")
B27: 10 | C27: =IF('단위공사별(집계)'!N16>0,'단위공사별(집계)'!B16,"") | E27: =IF('단위공사별(집계)'!N16>1,('단위공사별(집계)'!D16+'단위공사별(집계)'!E16+'단위공사별(집계)'!F16+'단위공사별(집계)'!G16+'단위공사별(집계)'!H16+'단위공사별(집계)'!I16)/1000," ") | G27: =IF('단위공사별(집계)'!N16>0,('단위공사별(집계)'!L16+'단위공사별(집계)'!M16)/1000,"") | H27: =IF('단위공사별(집계)'!N16>0,'단위공사별(집계)'!N16/1000,"")
B28: 견적 합계 | E28: =SUM(E18:E24) -> 384741 | F28: =SUM(F18:F24) -> 117375.21 | G28: =SUM(G18:G24) -> 57971.15 | H28: =SUM(H18:H24)-87 -> 560000.36
F30: 공개입찰가 (견적時 공란)
B32: 특기사항 | C32: 1. VAT 제외 | F32: 외주계획 업체명 (자작時 공란)
C33: 2. 기본 유틸리티공사 제외 | F33: 설계외주
C34: ='원가항목별(집계)'!I38 -> 1280000 | F34: 제작외주
F35: 전기외주
F36: 설치외주

Sheet 원가항목별(집계)
C1: A. 원가항목별 견적가 종합(상세견적 첨부)
B3: □ 현대/기아 요구사양과 견적조건 일치여부 CHECK: 1.일치함 2.일부상이(상이내역 첨부참조)
B5: 순번 | C5: 원가구분 | F5: 단위 | G5: 수량 | H5: 단가 | I5: 금 액(원) | J5: 비 고
B6: 1 | C6: 기계 부문 | D6: 자재비 | E6: 철자재(SS.SUS등) | F6: kg | G6: ='ASSY TABLE '!F36+'VISION BAECODE DB'!F32+'OTHER COST'!F17+단위장비4!F28+단위장비5!F30+단위장비6!F30+단위장비7!F30+단위장비8!F30+단위장비9!F30+단위장비10!F30 -> 0 | I6: ='ASSY TABLE '!H30+'VISION BAECODE DB'!H26+'OTHER COST'!H11+단위장비4!H22+단위장비5!H24+단위장비6!H24+단위장비7!H24+단위장비8!H24+단위장비9!H24+단위장비10!H24 -> 56880000 | J6: 加工必要資材
E7: 일반구매품 | F7: 식 | G7: 1 | I7: ='ASSY TABLE '!H81+'VISION BAECODE DB'!H58+'OTHER COST'!H25+단위장비4!H45+단위장비5!H47+단위장비6!H47+단위장비7!H47+단위장비8!H47+단위장비9!H47+단위장비10!H47 -> 117061000 | J7: 加工不要資材
E8: 외주제작품 | F8: 식 | G8: 1 | I8: ='ASSY TABLE '!H89+'VISION BAECODE DB'!H66+'OTHER COST'!H39+단위장비4!H53+단위장비5!H55+단위장비6!H55+단위장비7!H55+단위장비8!H55+단위장비9!H55+단위장비10!H55 -> 89000000 | J8: 旣加工SUB資材
E9: 설치/해체 공사 자재 | F9: 식 | G9: 1 | I9: ='ASSY TABLE '!H36+'VISION BAECODE DB'!H32+'OTHER COST'!H17+단위장비4!H28+단위장비5!H30+단위장비6!H30+단위장비7!H30+단위장비8!H30+단위장비9!H30+단위장비10!H30 -> 0 | J9: 시운전 자재 포함
E10: 소계 | I10: =SUM(I6:I9) -> 262941000
D11: 노무비 | E11: 기존설비 철거 | F11: M/D | G11: ='ASSY TABLE '!F91+'VISION BAECODE DB'!F68+'OTHER COST'!F41+단위장비4!F55+단위장비5!F57+단위장비6!F57+단위장비7!F57+단위장비8!F57+단위장비9!F57+단위장비10!F57 -> 0 | H11: =IF('ASSY TABLE '!G91>0,'ASSY TABLE '!G91,"") | I11: ='ASSY TABLE '!H91+'VISION BAECODE DB'!H68+'OTHER COST'!H41+단위장비4!H55+단위장비5!H57+단위장비6!H57+단위장비7!H57+단위장비8!H57+단위장비9!H57+단위장비10!H57 -> 0 | J11: 개조공사時
E12: 설계 | F12: M/D | G12: ='ASSY TABLE '!F92+'VISION BAECODE DB'!F69+'OTHER COST'!F42+단위장비4!F56+단위장비5!F58+단위장비6!F58+단위장비7!F58+단위장비8!F58+단위장비9!F58+단위장비10!F58 -> 60 | H12: =IF('ASSY TABLE '!G92>0,'ASSY TABLE '!G92,"") -> 300000 | I12: ='ASSY TABLE '!H92+'VISION BAECODE DB'!H69+'OTHER COST'!H42+단위장비4!H56+단위장비5!H58+단위장비6!H58+단위장비7!H58+단위장비8!H58+단위장비9!H58+단위장비10!H58 -> 21000000
E13: 제작(제관,가공) | F13: M/D | G13: ='ASSY TABLE '!F93+'VISION BAECODE DB'!F70+'OTHER COST'!F43+단위장비4!F57+단위장비5!F59+단위장비6!F59+단위장비7!F59+단위장비8!F59+단위장비9!F59+단위장비10!F59 -> 45 | H13: =IF('ASSY TABLE '!G93>0,'ASSY TABLE '!G93,"") -> 300000 | I13: ='ASSY TABLE '!H93+'VISION BAECODE DB'!H70+'OTHER COST'!H43+단위장비4!H57+단위장비5!H59+단위장비6!H59+단위장비7!H59+단위장비8!H59+단위장비9!H59+단위장비10!H59 -> 15000000
E14: 조립 | F14: M/D | G14: ='ASSY TABLE '!F94+'VISION BAECODE DB'!F71+'OTHER COST'!F44+단위장비4!F58+단위장비5!F60+단위장비6!F60+단위장비7!F60+단위장비8!F60+단위장비9!F60+단위장비10!F60 -> 35 | H14: =IF('ASSY TABLE '!G94>0,'ASSY TABLE '!G94,"") -> 300000 | I14: ='ASSY TABLE '!H94+'VISION BAECODE DB'!H71+'OTHER COST'!H44+단위장비4!H58+단위장비5!H60+단위장비6!H60+단위장비7!H60+단위장비8!H60+단위장비9!H60+단위장비10!H60 -> 12000000 | J14: 정도검사포함
E15: 설치 | F15: M/D | G15: ='ASSY TABLE '!F95+'VISION BAECODE DB'!F72+'OTHER COST'!F45+단위장비4!F59+단위장비5!F61+단위장비6!F61+단위장비7!F61+단위장비8!F61+단위장비9!F61+단위장비10!F61 -> 25 | H15: =IF('ASSY TABLE '!G95>0,'ASSY TABLE '!G95,"") -> 300000 | I15: ='ASSY TABLE '!H95+'VISION BAECODE DB'!H72+'OTHER COST'!H45+단위장비4!H59+단위장비5!H61+단위장비6!H61+단위장비7!H61+단위장비8!H61+단위장비9!H61+단위장비10!H61 -> 9000000
E16: 시운전 | F16: M/D | G16: ='ASSY TABLE '!F96+'VISION BAECODE DB'!F73+'OTHER COST'!F46+단위장비4!F60+단위장비5!F62+단위장비6!F62+단위장비7!F62+단위장비8!F62+단위장비9!F62+단위장비10!F62 -> 55 | H16: =IF('ASSY TABLE '!G96>0,'ASSY TABLE '!G96,"") -> 300000 | I16: ='ASSY TABLE '!H96+'VISION BAECODE DB'!H73+'OTHER COST'!H46+단위장비4!H60+단위장비5!H62+단위장비6!H62+단위장비7!H62+단위장비8!H62+단위장비9!H62+단위장비10!H62 -> 19500000
E17: 양산대응 | F17: M/D | G17: ='ASSY TABLE '!F97+'VISION BAECODE DB'!F74+'OTHER COST'!F47+단위장비4!F61+단위장비5!F63+단위장비6!F63+단위장비7!F63+단위장비8!F63+단위장비9!F63+단위장비10!F63 -> 69 | H17: =IF('ASSY TABLE '!G97>0,'ASSY TABLE '!G97,"") -> 500000 | I17: ='ASSY TABLE '!H97+'VISION BAECODE DB'!H74+'OTHER COST'!H47+단위장비4!H61+단위장비5!H63+단위장비6!H63+단위장비7!H63+단위장비8!H63+단위장비9!H63+단위장비10!H63 -> 34500000
E18: 도장 | F18: M/D | G18: ='ASSY TABLE '!F98+'VISION BAECODE DB'!F75+'OTHER COST'!F48+단위장비4!F62+단위장비5!F64+단위장비6!F64+단위장비7!F64+단위장비8!F64+단위장비9!F64+단위장비10!F64 -> 1 | H18: =IF('ASSY TABLE '!G98>0,'ASSY TABLE '!G98,"") -> 4000000 | I18: ='ASSY TABLE '!H98+'VISION BAECODE DB'!H75+'OTHER COST'!H48+단위장비4!H62+단위장비5!H64+단위장비6!H64+단위장비7!H64+단위장비8!H64+단위장비9!H64+단위장비10!H64 -> 4000000
E19: 소계 | I19: =SUM(I11:I18) -> 115000000
D20: 일반관리 및 이윤 | I20: ='ASSY TABLE '!H101+'ASSY TABLE '!H102+'VISION BAECODE DB'!H78+'VISION BAECODE DB'!H79+'OTHER COST'!H51+'OTHER COST'!H52+단위장비4!H65+단위장비4!H66+단위장비5!H67+단위장비5!H68+단위장비6!H67+단위장비6!H68+단위장비7!H67+단위장비7!H68+단위장비8!H67+단위장비8!H68+단위장비9!H67+단위장비9!H68+단위장비10!H67+단위장비10!H68 -> 56691150
E21: 기계 소계 | I21: =I19+I10+I20 -> 434632150
B22: 2 | C22: 전기 부문 | D22: 자재비 | E22: 기계/전기자재 | F22: 식 | G22: 1 | I22: =전기!H69-I23 -> 61065400
E23: 설치/해체 공사 자재 | F23: 식 | G23: 1 | I23: =전기!H17 -> 0 | J23: 시운전 자재 포함
D24: 노무비 | E24: 철거(개조시) | F24: M/D | G24: =전기!F70 -> 0 | H24: =IF(전기!G70>0,전기!G70,"") | I24: =전기!H70 -> 0
E25: 설계,프로그램 | F25: M/D | G25: =전기!F71 -> 30 | H25: =IF(전기!G71>0,전기!G71,"") -> 300000 | I25: =전기!H71 -> 9000000
E26: 제작 | F26: M/D | G26: =전기!F72 -> 10 | H26: =IF(전기!G72>0,전기!G72,"") -> 250000 | I26: =전기!H72 -> 2500000
E27: 조립 | F27: M/D | G27: =전기!F73 -> 10 | H27: =IF(전기!G73>0,전기!G73,"") -> 250000 | I27: =전기!H73 -> 2500000
E28: 설치 | F28: M/D | G28: =전기!F74 -> 10 | H28: =IF(전기!G74>0,전기!G74,"") -> 250000 | I28: =전기!H74 -> 2500000
E29: 시운전 | F29: M/D | G29: =전기!F75 -> 10 | H29: =IF(전기!G75>0,전기!G75,"") -> 350000 | I29: =전기!H75 -> 3500000
E30: 양산대응 | F30: M/D | G30: =전기!F76 -> 42 | H30: =IF(전기!G76>0,전기!G76,"") -> 500000 | I30: =전기!H76 -> 21000000
E31: 소계 | I31: =SUM(I24:I30) -> 41000000
D32: 일반관리 및 이윤 | I32: =전기!H79+전기!H80 -> 15309810
E33: 전기 소계 | I33: =I31+I22+I32+I23 -> 117375210
B34: 3 | C34: 자재비 합계 | I34: =I22+I10+I23 -> 324006400
C35: 노무비 합계 | I35: =I31+I19 -> 156000000
C36: 중간 합계 | I36: =I35+I34 -> 480006400
B37: 4 | C37: 포장,운송 및 중장비 사용료 | I37: 6800000
B38: 5 | C38: 표준안전관리비 | F38: 설치/철거/수리금액 기준 | I38: =CEILING(MIN(I46:I47),1000) -> 1280000 | J38: =I29+I28+I24+I23+I16+I15+I11+I9 -> 34500000
B39: 6 | C39: 일반관리비 | I39: =전기!H79+'ASSY TABLE '!H101+'VISION BAECODE DB'!H78+'OTHER COST'!H51+단위장비4!H65+단위장비5!H67+단위장비6!H67+단위장비7!H67+단위장비8!H67+단위장비9!H67+단위장비10!H67 -> 14400192
B40: 7 | C40: 이 윤 | I40: =전기!H80+'ASSY TABLE '!H102+'VISION BAECODE DB'!H79+'OTHER COST'!H52+단위장비4!H66+단위장비5!H68+단위장비6!H68+단위장비7!H68+단위장비8!H68+단위장비9!H68+단위장비10!H68 -> 57600768
C41: 합 계 | F41: 3~7항 합계 | I41: =(I21+I33+I37+I38)-87360 -> 560000000
B42: 주1. 표준안전관리비:(설치/철거/시운전 공사 관련 금액)의 ⓐ2.66%,ⓑ1.95%+기초액,ⓒ2.02%(50억 이상일경우)
...

Sheet 단위공사별(집계)
A2: B. 단위장비별 견적가 종합(상세견적 첨부)
N3: 단위:원
I5: 포장/운송 | L5: 표준안전 | M5: 일반관리비
A6: 순번 | B6: 단위장비명 | C6: 수량 | D6: 자재비 | E6: 철거 | F6: 제작 | G6: 설치/시운전 | H6: 양산대응 | I6: 중장비사용 | J6: 기계소계 | K6: 전기소계 | L6: 관리비 | M6: 이윤 | N6: 합 계 | O6: 비 고
A7: =IF(B7>0,1,"") -> 1 | B7: ='ASSY TABLE '!C$1 -> ASS'Y TABLE | C7: 1식 | D7: ='ASSY TABLE '!H90 -> 98563000 | E7: ='ASSY TABLE '!H91 -> 0 | F7: ='ASSY TABLE '!H92+'ASSY TABLE '!H93+'ASSY TABLE '!H94+'ASSY TABLE '!H98 -> 28000000 | G7: ='ASSY TABLE '!H95+'ASSY TABLE '!H96 -> 10500000 | H7: ='ASSY TABLE '!H97 -> 27000000 | I7: =IF($B7>0,'원가항목별(집계)'!I$37*$P7/$P$17,0) -> 2951858.6 | J7: =SUM(D7:I7) -> 1.6701486e+08 | K7: =IF(B7>0,'원가항목별(집계)'!I$33*P7/P$17,0) -> 50952210 | L7: =IF($B7>0,'원가항목별(집계)'!I$38*$P7/$P$17,0) -> 555643.98 | M7: ='ASSY TABLE '!H101+'ASSY TABLE '!H102 -> 24609450 | N7: =SUM(J7:M7) -> 2.4313216e+08 | P7: =D7+E7+F7+G7+H7+M7 -> 188672450
A8: =IF(B8>0,A7+1,"") -> 2 | B8: ='VISION BAECODE DB'!C$1 -> VISION/BAECODE/DB | C8: 1식 | D8: ='VISION BAECODE DB'!H67 -> 123178000 | E8: ='VISION BAECODE DB'!H68 -> 0 | F8: ='VISION BAECODE DB'!H69+'VISION BAECODE DB'!H70+'VISION BAECODE DB'!H71+'VISION BAECODE DB'!H75 -> 24000000 | G8: ='VISION BAECODE DB'!H72+'VISION BAECODE DB'!H73 -> 18000000 | H8: ='VISION BAECODE DB'!H74 -> 7500000 | I8: =IF($B8>0,'원가항목별(집계)'!I$37*$P8/$P$17,0) -> 3106861.7 | J8: =SUM(D8:I8) -> 1.7578486e+08 | K8: =IF(B8>0,'원가항목별(집계)'!I$33*P8/P$17,0) -> 53627726 | L8: =IF($B8>0,'원가항목별(집계)'!I$38*$P8/$P$17,0) -> 584821.02 | M8: ='VISION BAECODE DB'!H78+'VISION BAECODE DB'!H79 -> 25901700 | N8: =SUM(J8:M8) -> 2.5589911e+08 | P8: =D8+E8+F8+G8+H8+M8 -> 198579700
A9: =IF(B9>0,A8+1,"") -> 3 | B9: ='OTHER COST'!C$1 -> OTHER COST | C9: 1식 | D9: ='OTHER COST'!H40 -> 41200000 | E9: ='OTHER COST'!H41 -> 0 | F9: ='OTHER COST'!H42+'OTHER COST'!H43+'OTHER COST'!H44+'OTHER COST'!H48 -> 0 | G9: ='OTHER COST'!H45+'OTHER COST'!H46 -> 0 | H9: ='OTHER COST'!H47 -> 0 | I9: =IF($B9>0,'원가항목별(집계)'!I$37*$P9/$P$17,0) -> 741279.72 | J9: =SUM(D9:I9) -> 41941280 | K9: =IF(B9>0,'원가항목별(집계)'!I$33*P9/P$17,0) -> 12795274 | L9: =IF($B9>0,'원가항목별(집계)'!I$38*$P9/$P$17,0) -> 139535.01 | M9: ='OTHER COST'!H51+'OTHER COST'!H52 -> 6180000 | N9: =SUM(J9:M9) -> 61056089 | P9: =D9+E9+F9+G9+H9+M9 -> 47380000
A10: =IF(B10>0,A9+1,"") | B10: =단위장비4!C$1 -> 0 | C10: 1식 | D10: =단위장비4!H54 -> 0 | E10: =단위장비4!H55 -> 0 | F10: =단위장비4!H56+단위장비4!H57+단위장비4!H58+단위장비4!H62 -> 0 | G10: =단위장비4!H59+단위장비4!H60 -> 0 | H10: =단위장비4!H61 -> 0 | I10: =IF($B10>0,'원가항목별(집계)'!I$37*$P10/$P$17,0) -> 0 | J10: =SUM(D10:I10) -> 0 | K10: =IF(B10>0,'원가항목별(집계)'!I$33*P10/P$17,0) -> 0 | L10: =IF($B10>0,'원가항목별(집계)'!I$38*$P10/$P$17,0) -> 0 | M10: =단위장비4!H65+단위장비4!H66 -> 0 | N10: =SUM(J10:M10) -> 0 | P10: =D10+E10+F10+G10+H10+M10 -> 0
A11: =IF(B11>0,A10+1,"") | B11: =단위장비5!C$1 -> 0 | C11: 1식 | D11: =단위장비5!H56 -> 0 | E11: =단위장비5!H57 -> 0 | F11: =단위장비5!H58+단위장비5!H59+단위장비5!H60+단위장비5!H64 -> 0 | G11: =단위장비5!H61+단위장비5!H62 -> 0 | H11: =단위장비5!H63 -> 0 | I11: =IF($B11>0,'원가항목별(집계)'!I$37*$P11/$P$17,0) -> 0 | J11: =SUM(D11:I11) -> 0 | K11: =IF(B11>0,'원가항목별(집계)'!I$33*P11/P$17,0) -> 0 | L11: =IF($B11>0,'원가항목별(집계)'!I$38*$P11/$P$17,0) -> 0 | M11: =단위장비5!H67+단위장비5!H68 -> 0 | N11: =SUM(J11:M11) -> 0 | P11: =D11+E11+F11+G11+H11+M11 -> 0
A12: =IF(B12>0,A11+1,"") | B12: =단위장비6!C$1 -> 0 | C12: 1식 | D12: =단위장비6!H56 -> 0 | E12: =단위장비6!H57 -> 0 | F12: =단위장비6!H58+단위장비6!H59+단위장비6!H60+단위장비6!H64 -> 0 | G12: =단위장비6!H61+단위장비6!H62 -> 0 | H12: =단위장비6!H63 -> 0 | I12: =IF($B12>0,'원가항목별(집계)'!I$37*$P12/$P$17,0) -> 0 | J12: =SUM(D12:I12) -> 0 | K12: =IF(B12>0,'원가항목별(집계)'!I$33*P12/P$17,0) -> 0 | L12: =IF($B12>0,'원가항목별(집계)'!I$38*$P12/$P$17,0) -> 0 | M12: =단위장비6!H67+단위장비6!H68 -> 0 | N12: =SUM(J12:M12) -> 0 | P12: =D12+E12+F12+G12+H12+M12 -> 0
A13: =IF(B13>0,A8+1,"") | B13: =단위장비7!C$1 -> 0 | C13: 1식 | D13: =단위장비7!H56 -> 0 | E13: =단위장비7!H57 -> 0 | F13: =단위장비7!H58+단위장비7!H59+단위장비7!H60+단위장비7!H64 -> 0 | G13: =단위장비7!H61+단위장비7!H62 -> 0 | H13: =단위장비7!H63 -> 0 | I13: =IF($B13>0,'원가항목별(집계)'!I$37*$P13/$P$17,0) -> 0 | J13: =SUM(D13:I13) -> 0 | K13: =IF(B13>0,'원가항목별(집계)'!I$33*P13/P$17,0) -> 0 | L13: =IF($B13>0,'원가항목별(집계)'!I$38*$P13/$P$17,0) -> 0 | M13: =단위장비7!H67+단위장비7!H68 -> 0 | N13: =SUM(J13:M13) -> 0 | P13: =D13+E13+F13+G13+H13+M13 -> 0
A14: =IF(B14>0,A13+1,"") | B14: =단위장비8!C$1 -> 0 | C14: 1식 | D14: =단위장비8!H56 -> 0 | E14: =단위장비8!H57 -> 0 | F14: =단위장비8!H58+단위장비8!H59+단위장비8!H60+단위장비8!H64 -> 0 | G14: =단위장비8!H61+단위장비8!H62 -> 0 | H14: =단위장비8!H63 -> 0 | I14: =IF($B14>0,'원가항목별(집계)'!I$37*$P14/$P$17,0) -> 0 | J14: =SUM(D14:I14) -> 0 | K14: =IF(B14>0,'원가항목별(집계)'!I$33*P14/P$17,0) -> 0 | L14: =IF($B14>0,'원가항목별(집계)'!I$38*$P14/$P$17,0) -> 0 | M14: =단위장비8!H67+단위장비8!H68 -> 0 | N14: =SUM(J14:M14) -> 0 | P14: =D14+E14+F14+G14+H14+M14 -> 0
A15: =IF(B15>0,A14+1,"") | B15: =단위장비9!C$1 -> 0 | C15: 1식 | D15: =단위장비9!H57 -> 0 | E15: =단위장비9!H58 -> 0 | F15: =단위장비9!H59+단위장비9!H60+단위장비9!H61+단위장비9!H65 -> 0 | G15: =단위장비9!H62+단위장비9!H63 -> 0 | H15: =단위장비9!H64 -> 0 | I15: =IF($B15>0,'원가항목별(집계)'!I$37*$P15/$P$17,0) -> 0 | J15: =SUM(D15:I15) -> 0 | K15: =IF(B15>0,'원가항목별(집계)'!I$33*P15/P$17,0) -> 0 | L15: =IF($B15>0,'원가항목별(집계)'!I$38*$P15/$P$17,0) -> 0 | M15: =단위장비9!H68+단위장비9!H69 -> 0 | N15: =SUM(J15:M15) -> 0 | P15: =D15+E15+F15+G15+H15+M15 -> 0
A16: =IF(B16>0,A15+1,"") | B16: =단위장비10!C$1 -> 0 | C16: 1식 | D16: =단위장비10!H58 -> 0 | E16: =단위장비10!H59 -> 0 | F16: =단위장비10!H60+단위장비10!H61+단위장비10!H62+단위장비10!H66 -> 0 | G16: =단위장비10!H63+단위장비10!H64 -> 0 | H16: =단위장비10!H65 -> 0 | I16: =IF($B16>0,'원가항목별(집계)'!I$37*$P16/$P$17,0) -> 0 | J16: =SUM(D16:I16) -> 0 | K16: =IF(B16>0,'원가항목별(집계)'!I$33*P16/P$17,0) -> 0 | L16: =IF($B16>0,'원가항목별(집계)'!I$38*$P16/$P$17,0) -> 0 | M16: =단위장비10!H69+단위장비10!H70 -> 0 | N16: =SUM(J16:M16) -> 0 | P16: =D16+E16+F16+G16+H16+M16 -> 0
A17: 합 계 | D17: =SUM(D7:D16) -> 262941000 | E17: =SUM(E7:E16) -> 0 | F17: =SUM(F7:F16) -> 52000000 | G17: =SUM(G7:G16) -> 28500000 | H17: =SUM(H7:H16) -> 34500000 | I17: =SUM(I7:I16) -> 6800000 | J17: =SUM(D17:I17) -> 384741000 | K17: =SUM(K7:K16) -> 117375210 | L17: =SUM(L7:L16) -> 1280000 | M17: =SUM(M7:M16) -> 56691150 | N17: =SUM(N7:N14) -> 560087360 | P17: =SUM(P7:P16) -> 434632150
D18: =IF(D17=0,"",D17/$N17) -> 0.46946426 | E18: =IF(E17=0,"",E17/$N17) | F18: =IF(F17=0,"",F17/$N17) -> 0.092842659 | G18: =IF(G17=0,"",G17/$N17) -> 0.050884919 | H18: =IF(H17=0,"",H17/$N17) -> 0.061597534 | I18: =IF(I17=0,"",I17/$N17) -> 0.012140963 | J18: =IF(J17=0,"",J17/$N17) -> 0.68693034 | K18: =IF(K17=0,"",K17/$N17) -> 0.2095659 | ... N18: =IF(N17=0,"",N17/$N17) -> 1
A19: 주) 전기비용은 턴키장비의 공통비용으로서 총 전기비용을 단위장비별 기계금액의 비율에 따라 배분함
N20: =IF('원가항목별(집계)'!I41='단위공사별(집계)'!N17,"","DATA오류입니다!") -> DATA오류입니다!

Sheet 전기
B1: □ 전기부문: | C1: 전기부문(공통) | I1: (첨부)
A2: 구분 | C2: 품 명 | D2: 규격 | E2: 단위 | F2: 수량 | G2: 단가(원) | H2: 금액(원) | I2: 原MAKER
A3: 자 재 비 | B3: 철자재 | C3: PANEL | D3: 800X800X600 | E3: EA | F3: 5 | G3: 800000 | H3: =IF(F3=0,G3,G3*F3) -> 4000000
C4: NANE PLATE | E4: LOT | F4: 1 | G4: 200000 | H4: =IF(F4=0,G4,G4*F4) -> 200000
C5: GOT BOX | D5: 400X400X250 | E5: SET | F5: 5 | G5: 200000 | H5: =IF(F5=0,G5,G5*F5) -> 1000000
C6: NANE PLATE | D6: AL 꼬리표 | E6: LOT | F6: 1 | G6: 500000 | H6: =IF(F6=0,G6,G6*F6) -> 500000
H7: =IF(F7=0,G7,G7*F7) -> 0
H8: =IF(F8=0,G8,G8*F8) -> 0
H9: =IF(F9=0,G9,G9*F9) -> 0
H10: =SUM(H3:H9) -> 5700000
B11: 설치/해체/ | H11: =IF(F11=0,G11,G11*F11) -> 0
B12: 시운전 공사 | H12: =IF(F12=0,G12,G12*F12) -> 0
B13: 자재 | H13: =IF(F13=0,G13,G13*F13) -> 0
H14: =IF(F14=0,G14,G14*F14) -> 0
H15: =IF(F15=0,G15,G15*F15) -> 0
H16: =IF(F16=0,G16,G16*F16) -> 0
H17: =SUM(H11:H16) -> 0
B18: 전기자재 | C18: GOT2000 | D18: GT2712-STBA | E18: EA | F18: 5 | G18: 1650000 | H18: =IF(F18=0,G18,G18*F18) -> 8250000 | I18: MITSUBISHI
C19: PLC CPU | D19: Q13UDVCPU | E19: EA | F19: 5 | G19: 1840000 | H19: =IF(F19=0,G19,G19*F19) -> 9200000 | I19: MITSUBISHI
C20: PLC POWER | D20: Q62P | E20: EA | F20: 5 | G20: 145000 | H20: =IF(F20=0,G20,G20*F20) -> 725000 | I20: MITSUBISHI
C21: PLC BASE | D21: Q312B | E21: EA | F21: 5 | G21: 240000 | H21: =IF(F21=0,G21,G21*F21) -> 1200000 | I21: MITSUBISHI
C22: PLC CCLINK | D22: QJ61BT11N | E22: EA | F22: 5 | G22: 221000 | H22: =IF(F22=0,G22,G22*F22) -> 1105000 | I22: MITSUBISHI
C23: PLC ETHERNET UINT | D23: QJ1E71-100 | E23: EA | F23: 5 | G23: 932000 | H23: =IF(F23=0,G23,G23*F23) -> 4660000 | I23: MITSUBISHI
C24: PLC 통신카드 | D24: QJ71C24N | E24: EA | F24: 6 | G24: 500000 | H24: =IF(F24=0,G24,G24*F24) -> 3000000 | I24: MITSUBISHI
C25: CC-LINK | D25: AJ65SBT1-32D | E25: EA | F25: 18 | G25: 210000 | H25: =IF(F25=0,G25,G25*F25) -> 3780000 | I25: MITSUBISHI
D26: AJ65SBT1-32T | E26: EA | F26: 6 | G26: 210000 | H26: =IF(F26=0,G26,G26*F26) -> 1260000 | I26: MITSUBISHI
D27: AJ65SBT1-32DT | E27: EA | F27: 6 | G27: 210000 | H27: =IF(F27=0,G27,G27*F27) -> 1260000 | I27: MITSUBISHI
C28: NFB | D28: ABS32/15A | E28: EA | F28: 15 | G28: 25600 | H28: =IF(F28=0,G28,G28*F28) -> 384000
D29: N-40c | E29: EA | F29: 5 | G29: 17600 | H29: =IF(F29=0,G29,G29*F29) -> 88000
C30: NFB | D30: GV2ME | E30: EA | F30: 10 | G30: 46600 | H30: =IF(F30=0,G30,G30*F30) -> 466000
D31: GVAE11 | E31: EA | F31: 10 | G31: 7150 | H31: =IF(F31=0,G31,G31*F31) -> 71500
C32: ` | D32: GCP32/7 | E32: EA | F32: 30 | G32: 24200 | H32: =IF(F32=0,G32,G32*F32) -> 726000
C33: CONSENT | D33: AC220V 2구 | E33: EA | F33: 5 | G33: 2500 | H33: =IF(F33=0,G33,G33*F33) -> 12500
C34: COOLING FAN | E34: SET | F34: 5 | G34: 185000 | H34: =IF(F34=0,G34,G34*F34) -> 925000
C35: PANEL LIGHT | E35: EA | F35: 5 | G35: 50000 | H35: =IF(F35=0,G35,G35*F35) -> 250000
C36: RELAY | D36: 47BND | E36: EA | F36: 8 | G36: 40000 | H36: =IF(F36=0,G36,G36*F36) -> 320000
C37: RELAY | D37: LY2N | E37: EA | F37: 20 | G37: 5500 | H37: =IF(F37=0,G37,G37*F37) -> 110000
C38: MC | D38: LC1D09BD | E38: EA | F38: 12 | G38: 27700 | H38: =IF(F38=0,G38,G38*F38) -> 332400
C39: NOISE FILTER | D39: 10A | E39: EA | F39: 5 | G39: 32200 | H39: =IF(F39=0,G39,G39*F39) -> 161000
C40: DC POWER SPULLY | D40: S8VS-24024A | E40: EA | F40: 5 | G40: 268200 | H40: =IF(F40=0,G40,G40*F40) -> 1341000
...

Sheet ASSY TABLE 
B1: □ 단위공사명(전기제외): | C1: ASS'Y TABLE | I1: (첨부)
A2: 구분 | C2: 품 명 | D2: 규격 | E2: 단위 | F2: 수량 | G2: 단가(원) | H2: 금액(원) | I2: 原MAKER
A3: 자 재 비 | B3: 철자재 | C3: FRAME | D3: PROFILE 40*40 | E3: SET | F3: 1 | G3: 2500000 | H3: =IF(F3=0,G3,G3*F3) -> 2500000
B4: ASS'Y TABLE | C4: BASE PLATE | D4: SS400*4.5T,상하 | E4: EA | F4: 2 | G4: 150000 | H4: =IF(F4=0,G4,G4*F4) -> 300000
B5: (OP10) | C5: PARTS BOX SHELF | E5: EA | F5: 1 | G5: 120000 | H5: =IF(F5=0,G5,G5*F5) -> 120000
C6: BUFFER TABLE | D6: PROFILE 40*40 | E6: SET | F6: 1 | G6: 800000 | H6: =IF(F6=0,G6,G6*F6) -> 800000
C7: JIG MAIN BASE | D7: AL*15T | E7: SET | F7: 1 | G7: 300000 | H7: =IF(F7=0,G7,G7*F7) -> 300000
C8: ASS'Y JIG | D8: AL*15T,LOCK'G UNIT | E8: SET | F8: 5 | G8: 800000 | H8: =IF(F8=0,G8,G8*F8) -> 4000000
B9: ASS'Y TABLE | C9: FRAME | D9: PROFILE 40*40 | E9: SET | F9: 2 | G9: 2500000 | H9: =IF(F9=0,G9,G9*F9) -> 5000000
B10: (OP20,30) | C10: BASE PLATE | D10: SS400*4.5T,상하 | E10: EA | F10: 4 | G10: 150000 | H10: =IF(F10=0,G10,G10*F10) -> 600000
C11: PARTS BOX SHELF | E11: EA | F11: 2 | G11: 120000 | H11: =IF(F11=0,G11,G11*F11) -> 240000
C12: JIG MAIN BASE | D12: AL*15T | E12: SET | F12: 2 | G12: 300000 | H12: =IF(F12=0,G12,G12*F12) -> 600000
C13: ASS'Y JIG | D13: AL*15T,LOCK'G UNIT | E13: SET | F13: 10 | G13: 800000 | H13: =IF(F13=0,G13,G13*F13) -> 8000000
C14: BUFFER TABLE | E14: SET | F14: 2 | G14: 800000 | H14: =IF(F14=0,G14,G14*F14) -> 1600000
B15: AIR LEAK TABLE | C15: FRAME | D15: PROFILE 40*40 | E15: SET | F15: 2 | G15: 3500000 | H15: =IF(F15=0,G15,G15*F15) -> 7000000
B16: (OP40) | C16: BASE PLATE | D16: SS400*4.5T,상하 | E16: EA | F16: 4 | G16: 150000 | H16: =IF(F16=0,G16,G16*F16) -> 600000
C17: LEAK TESTER 거치대 | D17: SS400*4.5T | E17: SET | F17: 2 | G17: 250000 | H17: =IF(F17=0,G17,G17*F17) -> 500000
C18: JIG MAIN BASE | D18: AL*15T | E18: SET | F18: 2 | G18: 300000 | H18: =IF(F18=0,G18,G18*F18) -> 600000
C19: LEAK JIG | D19: AL*15T,LOCK'G UNIT | E19: SET | F19: 10 | G19: 800000 | H19: =IF(F19=0,G19,G19*F19) -> 8000000
C20: SEALING COUPLER | D20: RAD/LTR/COND | E20: EA | F20: 20 | G20: 300000 | H20: =IF(F20=0,G20,G20*F20) -> 6000000
C21: BUFFER TABLE | E21: SET | F21: 1 | G21: 800000 | H21: =IF(F21=0,G21,G21*F21) -> 800000
B22: FINAL CHECK TABLE | C22: FRAME | D22: PROFILE 40*40 | E22: SET | F22: 1 | G22: 3500000 | H22: =IF(F22=0,G22,G22*F22) -> 3500000
B23: (OP50) | C23: BASE PLATE | D23: SS400*4.5T,상하 | E23: EA | F23: 2 | G23: 150000 | H23: =IF(F23=0,G23,G23*F23) -> 300000
C24: PARTS BOX SHELF | E24: EA | F24: 1 | G24: 120000 | H24: =IF(F24=0,G24,G24*F24) -> 120000
H25: =IF(F25=0,G25,G25*F25) -> 0
H26: =IF(F26=0,G26,G26*F26) -> 0
H27: =IF(F27=0,G27,G27*F27) -> 0
H28: =IF(F28=0,G28,G28*F28) -> 0
H29: =IF(F29=0,G29,G29*F29) -> 0
H30: =SUM(H3:H29) -> 51480000
B31: 설치/해체/시운전 | H31: =IF(F31=0,G31,G31*F31) -> 0
B32: 공사 관련 자재 | H32: =IF(F32=0,G32,G32*F32) -> 0
H33: =IF(F33=0,G33,G33*F33) -> 0
H34: =IF(F34=0,G34,G34*F34) -> 0
H35: =IF(F35=0,G35,G35*F35) -> 0
H36: =SUM(H31:H35) -> 0
B37: 구매품 | C37: AIR SERVICE UNIT | E37: SET | F37: 1 | G37: 250000 | H37: =IF(F37=0,G37,G37*F37) -> 250000 | I37: SMC
B38: (유공압품외) | C38: 작업 표준 MONITOR | D38: 24",거치대 | E38: SET | F38: 1 | G38: 350000 | H38: =IF(F38=0,G38,G38*F38) -> 350000 | I38: LG
B39: ASS'Y TABLE (OP10) | C39: TORQUE TOOL(사급) | D39: ETD SL21 | E39: SET | F39: 1 | H39: =IF(F39=0,G39,G39*F39) -> 0 | I39: ATLAS
C40: TORQUE ARM | E40: SET | F40: 1 | G40: 1500000 | H40: =IF(F40=0,G40,G40*F40) -> 1500000
...

Sheet VISION BAECODE DB
B1: □ 단위공사명(전기제외): | C1: VISION/BAECODE/DB | I1: (첨부)
A2: 구분 | C2: 품 명 | D2: 규격 | E2: 단위 | F2: 수량 | G2: 단가(원) | H2: 금액(원) | I2: 原MAKER
A3: 자 재 비 | B3: 철자재 | C3: PC 랙 | E3: EA | F3: 1 | G3: 4200000 | H3: =IF(F3=0,G3,G3*F3) -> 4200000
C4: 마운트 블록 | E4: EA | F4: 6 | G4: 200000 | H4: =IF(F4=0,G4,G4*F4) -> 1200000
H5: =IF(F5=0,G5,G5*F5) -> 0
H6: =IF(F6=0,G6,G6*F6) -> 0
H7: =IF(F7=0,G7,G7*F7) -> 0
H8: =IF(F8=0,G8,G8*F8) -> 0
H9: =IF(F9=0,G9,G9*F9) -> 0
H10: =IF(F10=0,G10,G10*F10) -> 0
H11: =IF(F11=0,G11,G11*F11) -> 0
H12: =IF(F12=0,G12,G12*F12) -> 0
H13: =IF(F13=0,G13,G13*F13) -> 0
H14: =IF(F14=0,G14,G14*F14) -> 0
H15: =IF(F15=0,G15,G15*F15) -> 0
H16: =IF(F16=0,G16,G16*F16) -> 0
... H25: =IF(F25=0,G25,G25*F25) -> 0
H26: =SUM(H3:H25) -> 5400000
B27: 설치/해체/시운전 | H27: =IF(F27=0,G27,G27*F27) -> 0
B28: 공사 관련 자재 | H28: =IF(F28=0,G28,G28*F28) -> 0
H29: =IF(F29=0,G29,G29*F29) -> 0
H30: =IF(F30=0,G30,G30*F30) -> 0
H31: =IF(F31=0,G31,G31*F31) -> 0
H32: =SUM(H27:H31) -> 0
B33: 구매품 | C33: 스마트 비전 | D33: IV3-G500CA | E33: EA | F33: 6 | G33: 4800000 | H33: =IF(F33=0,G33,G33*F33) -> 28800000 | I33: KEYENCE
B34: (유공압품외) | C34: GigE 케이블 | E34: EA | F34: 6 | G34: 110000 | H34: =IF(F34=0,G34,G34*F34) -> 660000
C35: GigE 케이블 커플러 | E35: EA | F35: 6 | G35: 30000 | H35: =IF(F35=0,G35,G35*F35) -> 180000
C36: 산업용 PC | D36: 비젼 | E36: EA | F36: 1 | G36: 3300000 | H36: =IF(F36=0,G36,G36*F36) -> 3300000 | I36: ADVANTECH
C37: 무선랜 카드 | E37: EA | F37: 1 | G37: 50000 | H37: =IF(F37=0,G37,G37*F37) -> 50000
C38: UPS | E38: EA | F38: 1 | G38: 600000 | H38: =IF(F38=0,G38,G38*F38) -> 600000 | I38: APC
C39: Ethernet 허브 | E39: EA | F39: 1 | G39: 380000 | H39: =IF(F39=0,G39,G39*F39) -> 380000
C40: 파워 서플라이 | E40: EA | F40: 1 | G40: 150000 | H40: =IF(F40=0,G40,G40*F40) -> 150000
C41: 모니터 | E41: EA | F41: 1 | G41: 230000 | H41: =IF(F41=0,G41,G41*F41) -> 230000
C42: 마운트 블록 | E42: EA | F42: 6 | G42: 200000 | H42: =IF(F42=0,G42,G42*F42) -> 1200000
C43: 기타 자재 | E43: LOT | F43: 1 | G43: 1988000 | H43: =IF(F43=0,G43,G43*F43) -> 1988000
C44: SQL | E44: EA | F44: 1 | G44: 4100000 | H44: =IF(F44=0,G44,G44*F44) -> 4100000
C45: PC 랙 | E45: EA | F45: 1 | G45: 4200000 | H45: =IF(F45=0,G45,G45*F45) -> 4200000
C46: 산업용 PC | D46: 바코드 | E46: EA | F46: 1 | G46: 4200000 | H46: =IF(F46=0,G46,G46*F46) -> 4200000 | I46: ADVANTECH
C47: 무선랜 카드 | E47: EA | F47: 1 | G47: 50000 | H47: =IF(F47=0,G47,G47*F47) -> 50000
C48: 모니터 | E48: EA | F48: 1 | G48: 230000 | H48: =IF(F48=0,G48,G48*F48) -> 230000
...

Sheet OTHER COST
B1: □ 단위공사명(전기제외): | C1: OTHER COST | I1: (첨부)
A2: 구분 | C2: 품 명 | D2: 규격 | E2: 단위 | F2: 수량 | G2: 단가(원) | H2: 금액(원) | I2: 原MAKER
A3: 자 재 비 | B3: 철자재 | H3: =IF(F3=0,G3,G3*F3) -> 0
H4: =IF(F4=0,G4,G4*F4) -> 0
H5: =IF(F5=0,G5,G5*F5) -> 0
H6: =IF(F6=0,G6,G6*F6) -> 0
H7: =IF(F7=0,G7,G7*F7) -> 0
H8: =IF(F8=0,G8,G8*F8) -> 0
H9: =IF(F9=0,G9,G9*F9) -> 0
H10: =IF(F10=0,G10,G10*F10) -> 0
H11: =SUM(H3:H10) -> 0
B12: 설치/해체/시운전 | H12: =IF(F12=0,G12,G12*F12) -> 0
B13: 공사 관련 자재 | H13: =IF(F13=0,G13,G13*F13) -> 0
H14: =IF(F14=0,G14,G14*F14) -> 0
H15: =IF(F15=0,G15,G15*F15) -> 0
H16: =IF(F16=0,G16,G16*F16) -> 0
H17: =SUM(H12:H16) -> 0
B18: 구매품 | H18: =IF(F18=0,G18,G18*F18) -> 0
B19: (유공압품외) | H19: =IF(F19=0,G19,G19*F19) -> 0
H20: =IF(F20=0,G20,G20*F20) -> 0
H21: =IF(F21=0,G21,G21*F21) -> 0
H22: =IF(F22=0,G22,G22*F22) -> 0
H23: =IF(F23=0,G23,G23*F23) -> 0
H24: =IF(F24=0,G24,G24*F24) -> 0
H25: =SUM(H18:H24) -> 0
B26: 외주제작품 | C26: 국내 양산대응 | E26: LOT | F26: 1 | G26: 2000000 | H26: =IF(F26=0,G26,G26*F26) -> 2000000
C27: 항공비 | D27: 2인*3회(기계,전기) | E27: M | F27: 6 | G27: 1500000 | H27: =IF(F27=0,G27,G27*F27) -> 9000000
C28: 체류비 | D28: 설치,PI,P2 (2인*2주*2회) | E28: M/D | F28: 84 | G28: 300000 | H28: =IF(F28=0,G28,G28*F28) -> 25200000
C29: CEPA 인증비 | E29: LOT | F29: 1 | G29: 3000000 | H29: =IF(F29=0,G29,G29*F29) -> 3000000
C30: 공장 임대료 | E30: LOT | F30: 1 | G30: 2000000 | H30: =IF(F30=0,G30,G30*F30) -> 2000000
H31: =IF(F31=0,G31,G31*F31) -> 0
H32: =IF(F32=0,G32,G32*F32) -> 0
H33: =IF(F33=0,G33,G33*F33) -> 0
H34: =IF(F34=0,G34,G34*F34) -> 0
H35: =IF(F35=0,G35,G35*F35) -> 0
H36: =IF(F36=0,G36,G36*F36) -> 0
H37: =IF(F37=0,G37,G37*F37) -> 0
H38: =IF(F38=0,G38,G38*F38) -> 0
H39: =SUM(H26:H38) -> 41200000
B40: 자재비 소계 | H40: =SUM(H39,H25,H17,H11) -> 41200000
...

Sheet 단위장비4
B1: □ 단위공사명(전기제외): | I1: (첨부)
A2: 구분 | C2: 품 명 | D2: 규격 | E2: 단위 | F2: 수량 | G2: 단가(원) | H2: 금액(원) | I2: 原MAKER
A3: 자 재 비 | B3: 철자재 | H3: =IF(F3=0,G3,G3*F3) -> 0
H4: =IF(F4=0,G4,G4*F4) -> 0
H5: =IF(F5=0,G5,G5*F5) -> 0
H6: =IF(F6=0,G6,G6*F6) -> 0
H7: =IF(F7=0,G7,G7*F7) -> 0
H8: =IF(F8=0,G8,G8*F8) -> 0
H9: =IF(F9=0,G9,G9*F9) -> 0
H10: =IF(F10=0,G10,G10*F10) -> 0
H11: =IF(F11=0,G11,G11*F11) -> 0
H12: =IF(F12=0,G12,G12*F12) -> 0
H13: =IF(F13=0,G13,G13*F13) -> 0
H14: =IF(F14=0,G14,G14*F14) -> 0
H15: =IF(F15=0,G15,G15*F15) -> 0
... H21: =IF(F21=0,G21,G21*F21) -> 0
H22: =SUM(H3:H21) -> 0
B23: 설치/해체/시운전 | H23: =IF(F23=0,G23,G23*F23) -> 0
B24: 공사 관련 자재 | H24: =IF(F24=0,G24,G24*F24) -> 0
H25: =IF(F25=0,G25,G25*F25) -> 0
H26: =IF(F26=0,G26,G26*F26) -> 0
H27: =IF(F27=0,G27,G27*F27) -> 0
H28: =SUM(H23:H27) -> 0
B29: 구매품 | H29: =IF(F29=0,G29,G29*F29) -> 0
B30: (유공압품외) | H30: =IF(F30=0,G30,G30*F30) -> 0
H31: =IF(F31=0,G31,G31*F31) -> 0
H32: =IF(F32=0,G32,G32*F32) -> 0
H33: =IF(F33=0,G33,G33*F33) -> 0
H34: =IF(F34=0,G34,G34*F34) -> 0
H35: =IF(F35=0,G35,G35*F35) -> 0
H36: =IF(F36=0,G36,G36*F36) -> 0
H37: =IF(F37=0,G37,G37*F37) -> 0
H38: =IF(F38=0,G38,G38*F38) -> 0
H39: =IF(F39=0,G39,G39*F39) -> 0
H40: =IF(F40=0,G40,G40*F40) -> 0
H41: =IF(F41=0,G41,G41*F41) -> 0
H42: =IF(F42=0,G42,G42*F42) -> 0
... H44: =IF(F44=0,G44,G44*F44) -> 0
H45: =SUM(H29:H44) -> 0
B46: 외주제작품 | H46: =IF(F46=0,G46,G46*F46) -> 0
...

Sheet 단위장비5
B1: □ 단위공사명(전기제외): | I1: (첨부)
A2: 구분 | C2: 품 명 | D2: 규격 | E2: 단위 | F2: 수량 | G2: 단가(원) | H2: 금액(원) | I2: 原MAKER
A3: 자 재 비 | B3: 철자재 | H3: =IF(F3=0,G3,G3*F3) -> 0
H4: =IF(F4=0,G4,G4*F4) -> 0
H5: =IF(F5=0,G5,G5*F5) -> 0
H6: =IF(F6=0,G6,G6*F6) -> 0
H7: =IF(F7=0,G7,G7*F7) -> 0
H8: =IF(F8=0,G8,G8*F8) -> 0
H9: =IF(F9=0,G9,G9*F9) -> 0
H10: =IF(F10=0,G10,G10*F10) -> 0
H11: =IF(F11=0,G11,G11*F11) -> 0
H12: =IF(F12=0,G12,G12*F12) -> 0
H13: =IF(F13=0,G13,G13*F13) -> 0
H14: =IF(F14=0,G14,G14*F14) -> 0
H15: =IF(F15=0,G15,G15*F15) -> 0
... H23: =IF(F23=0,G23,G23*F23) -> 0
H24: =SUM(H3:H23) -> 0
B25: 설치/해체/시운전 | H25: =IF(F25=0,G25,G25*F25) -> 0
B26: 공사 관련 자재 | H26: =IF(F26=0,G26,G26*F26) -> 0
H27: =IF(F27=0,G27,G27*F27) -> 0
H28: =IF(F28=0,G28,G28*F28) -> 0
H29: =IF(F29=0,G29,G29*F29) -> 0
H30: =SUM(H25:H29) -> 0
B31: 구매품 | H31: =IF(F31=0,G31,G31*F31) -> 0
B32: (유공압품외) | H32: =IF(F32=0,G32,G32*F32) -> 0
H33: =IF(F33=0,G33,G33*F33) -> 0
H34: =IF(F34=0,G34,G34*F34) -> 0
H35: =IF(F35=0,G35,G35*F35) -> 0
H36: =IF(F36=0,G36,G36*F36) -> 0
H37: =IF(F37=0,G37,G37*F37) -> 0
H38: =IF(F38=0,G38,G38*F38) -> 0
H39: =IF(F39=0,G39,G39*F39) -> 0
H40: =IF(F40=0,G40,G40*F40) -> 0
H41: =IF(F41=0,G41,G41*F41) -> 0
H42: =IF(F42=0,G42,G42*F42) -> 0
H43: =IF(F43=0,G43,G43*F43) -> 0
H44: =IF(F44=0,G44,G44*F44) -> 0
... H46: =IF(F46=0,G46,G46*F46) -> 0
H47: =SUM(H31:H46) -> 0
B48: 외주제작품 | H48: =IF(F48=0,G48,G48*F48) -> 0
...

Sheet 단위장비6
B1: □ 단위공사명(전기제외): | I1: (첨부)
A2: 구분 | C2: 품 명 | D2: 규격 | E2: 단위 | F2: 수량 | G2: 단가(원) | H2: 금액(원) | I2: 原MAKER
A3: 자 재 비 | B3: 철자재 | H3: =IF(F3=0,G3,G3*F3) -> 0
H4: =IF(F4=0,G4,G4*F4) -> 0
H5: =IF(F5=0,G5,G5*F5) -> 0
H6: =IF(F6=0,G6,G6*F6) -> 0
H7: =IF(F7=0,G7,G7*F7) -> 0
H8: =IF(F8=0,G8,G8*F8) -> 0
H9: =IF(F9=0,G9,G9*F9) -> 0
H10: =IF(F10=0,G10,G10*F10) -> 0
H11: =IF(F11=0,G11,G11*F11) -> 0
H12: =IF(F12=0,G12,G12*F12) -> 0
H13: =IF(F13=0,G13,G13*F13) -> 0
H14: =IF(F14=0,G14,G14*F14) -> 0
H15: =IF(F15=0,G15,G15*F15) -> 0
... H23: =IF(F23=0,G23,G23*F23) -> 0
H24: =SUM(H3:H23) -> 0
B25: 설치/해체/시운전 | H25: =IF(F25=0,G25,G25*F25) -> 0
B26: 공사 관련 자재 | H26: =IF(F26=0,G26,G26*F26) -> 0
H27: =IF(F27=0,G27,G27*F27) -> 0
H28: =IF(F28=0,G28,G28*F28) -> 0
H29: =IF(F29=0,G29,G29*F29) -> 0
H30: =SUM(H25:H29) -> 0
B31: 구매품 | H31: =IF(F31=0,G31,G31*F31) -> 0
B32: (유공압품외) | H32: =IF(F32=0,G32,G32*F32) -> 0
H33: =IF(F33=0,G33,G33*F33) -> 0
H34: =IF(F34=0,G34,G34*F34) -> 0
H35: =IF(F35=0,G35,G35*F35) -> 0
H36: =IF(F36=0,G36,G36*F36) -> 0
H37: =IF(F37=0,G37,G37*F37) -> 0
H38: =IF(F38=0,G38,G38*F38) -> 0
H39: =IF(F39=0,G39,G39*F39) -> 0
H40: =IF(F40=0,G40,G40*F40) -> 0
H41: =IF(F41=0,G41,G41*F41) -> 0
H42: =IF(F42=0,G42,G42*F42) -> 0
H43: =IF(F43=0,G43,G43*F43) -> 0
H44: =IF(F44=0,G44,G44*F44) -> 0
... H46: =IF(F46=0,G46,G46*F46) -> 0
H47: =SUM(H31:H46) -> 0
B48: 외주제작품 | H48: =IF(F48=0,G48,G48*F48) -> 0
...

Sheet 단위장비7
B1: □ 단위공사명(전기제외): | I1: (첨부)
A2: 구분 | C2: 품 명 | D2: 규격 | E2: 단위 | F2: 수량 | G2: 단가(원) | H2: 금액(원) | I2: 原MAKER
A3: 자 재 비 | B3: 철자재 | H3: =IF(F3=0,G3,G3*F3) -> 0
H4: =IF(F4=0,G4,G4*F4) -> 0
H5: =IF(F5=0,G5,G5*F5) -> 0
H6: =IF(F6=0,G6,G6*F6) -> 0
H7: =IF(F7=0,G7,G7*F7) -> 0
H8: =IF(F8=0,G8,G8*F8) -> 0
H9: =IF(F9=0,G9,G9*F9) -> 0
H10: =IF(F10=0,G10,G10*F10) -> 0
H11: =IF(F11=0,G11,G11*F11) -> 0
H12: =IF(F12=0,G12,G12*F12) -> 0
H13: =IF(F13=0,G13,G13*F13) -> 0
H14: =IF(F14=0,G14,G14*F14) -> 0
H15: =IF(F15=0,G15,G15*F15) -> 0
... H23: =IF(F23=0,G23,G23*F23) -> 0
H24: =SUM(H3:H23) -> 0
B25: 설치/해체/시운전 | H25: =IF(F25=0,G25,G25*F25) -> 0
B26: 공사 관련 자재 | H26: =IF(F26=0,G26,G26*F26) -> 0
H27: =IF(F27=0,G27,G27*F27) -> 0
H28: =IF(F28=0,G28,G28*F28) -> 0
H29: =IF(F29=0,G29,G29*F29) -> 0
H30: =SUM(H25:H29) -> 0
B31: 구매품 | H31: =IF(F31=0,G31,G31*F31) -> 0
B32: (유공압품외) | H32: =IF(F32=0,G32,G32*F32) -> 0
H33: =IF(F33=0,G33,G33*F33) -> 0
H34: =IF(F34=0,G34,G34*F34) -> 0
H35: =IF(F35=0,G35,G35*F35) -> 0
H36: =IF(F36=0,G36,G36*F36) -> 0
H37: =IF(F37=0,G37,G37*F37) -> 0
H38: =IF(F38=0,G38,G38*F38) -> 0
H39: =IF(F39=0,G39,G39*F39) -> 0
H40: =IF(F40=0,G40,G40*F40) -> 0
H41: =IF(F41=0,G41,G41*F41) -> 0
H42: =IF(F42=0,G42,G42*F42) -> 0
H43: =IF(F43=0,G43,G43*F43) -> 0
H44: =IF(F44=0,G44,G44*F44) -> 0
... H46: =IF(F46=0,G46,G46*F46) -> 0
H47: =SUM(H31:H46) -> 0
B48: 외주제작품 | H48: =IF(F48=0,G48,G48*F48) -> 0
...

Sheet 단위장비8
B1: □ 단위공사명(전기제외): | I1: (첨부)
A2: 구분 | C2: 품 명 | D2: 규격 | E2: 단위 | F2: 수량 | G2: 단가(원) | H2: 금액(원) | I2: 原MAKER
A3: 자 재 비 | B3: 철자재 | H3: =IF(F3=0,G3,G3*F3) -> 0
H4: =IF(F4=0,G4,G4*F4) -> 0
H5: =IF(F5=0,G5,G5*F5) -> 0
H6: =IF(F6=0,G6,G6*F6) -> 0
H7: =IF(F7=0,G7,G7*F7) -> 0
H8: =IF(F8=0,G8,G8*F8) -> 0
H9: =IF(F9=0,G9,G9*F9) -> 0
H10: =IF(F10=0,G10,G10*F10) -> 0
H11: =IF(F11=0,G11,G11*F11) -> 0
H12: =IF(F12=0,G12,G12*F12) -> 0
H13: =IF(F13=0,G13,G13*F13) -> 0
H14: =IF(F14=0,G14,G14*F14) -> 0
H15: =IF(F15=0,G15,G15*F15) -> 0
... H22: =IF(F22=0,G22,G22*F22) -> 0
C23: 기타자재 | H23: =IF(F23=0,G23,G23*F23) -> 0
H24: =SUM(H3:H23) -> 0
B25: 설치/해체/시운전 | H25: =IF(F25=0,G25,G25*F25) -> 0
B26: 공사 관련 자재 | H26: =IF(F26=0,G26,G26*F26) -> 0
H27: =IF(F27=0,G27,G27*F27) -> 0
H28: =IF(F28=0,G28,G28*F28) -> 0
C29: 기타자재 | H29: =IF(F29=0,G29,G29*F29) -> 0
H30: =SUM(H25:H29) -> 0
B31: 구매품 | H31: =IF(F31=0,G31,G31*F31) -> 0
B32: (유공압품외) | H32: =IF(F32=0,G32,G32*F32) -> 0
H33: =IF(F33=0,G33,G33*F33) -> 0
H34: =IF(F34=0,G34,G34*F34) -> 0
H35: =IF(F35=0,G35,G35*F35) -> 0
H36: =IF(F36=0,G36,G36*F36) -> 0
H37: =IF(F37=0,G37,G37*F37) -> 0
H38: =IF(F38=0,G38,G38*F38) -> 0
H39: =IF(F39=0,G39,G39*F39) -> 0
H40: =IF(F40=0,G40,G40*F40) -> 0
H41: =IF(F41=0,G41,G41*F41) -> 0
H42: =IF(F42=0,G42,G42*F42) -> 0
H43: =IF(F43=0,G43,G43*F43) -> 0
H44: =IF(F44=0,G44,G44*F44) -> 0
H45: =IF(F45=0,G45,G45*F45) -> 0
C46: 기타자재 | H46: =IF(F46=0,G46,G46*F46) -> 0
...

Sheet 단위장비9
B1: □ 단위공사명(전기제외): | I1: (첨부)
A2: 구분 | C2: 품 명 | D2: 규격 | E2: 단위 | F2: 수량 | G2: 단가(원) | H2: 금액(원) | I2: 原MAKER
A3: 자 재 비 | B3: 철자재 | H3: =IF(F3=0,G3,G3*F3) -> 0
H4: =IF(F4=0,G4,G4*F4) -> 0
H5: =IF(F5=0,G5,G5*F5) -> 0
H6: =IF(F6=0,G6,G6*F6) -> 0
H7: =IF(F7=0,G7,G7*F7) -> 0
H8: =IF(F8=0,G8,G8*F8) -> 0
H9: =IF(F9=0,G9,G9*F9) -> 0
H10: =IF(F10=0,G10,G10*F10) -> 0
H11: =IF(F11=0,G11,G11*F11) -> 0
H12: =IF(F12=0,G12,G12*F12) -> 0
H13: =IF(F13=0,G13,G13*F13) -> 0
H14: =IF(F14=0,G14,G14*F14) -> 0
H15: =IF(F15=0,G15,G15*F15) -> 0
... H22: =IF(F22=0,G22,G22*F22) -> 0
C23: 기타자재 | H23: =IF(F23=0,G23,G23*F23) -> 0
H24: =SUM(H3:H23) -> 0
B25: 설치/해체/시운전 | H25: =IF(F25=0,G25,G25*F25) -> 0
B26: 공사 관련 자재 | H26: =IF(F26=0,G26,G26*F26) -> 0
H27: =IF(F27=0,G27,G27*F27) -> 0
H28: =IF(F28=0,G28,G28*F28) -> 0
C29: 기타자재 | H29: =IF(F29=0,G29,G29*F29) -> 0
H30: =SUM(H25:H29) -> 0
B31: 구매품 | H31: =IF(F31=0,G31,G31*F31) -> 0
B32: (유공압품외) | H32: =IF(F32=0,G32,G32*F32) -> 0
H33: =IF(F33=0,G33,G33*F33) -> 0
H34: =IF(F34=0,G34,G34*F34) -> 0
H35: =IF(F35=0,G35,G35*F35) -> 0
H36: =IF(F36=0,G36,G36*F36) -> 0
H37: =IF(F37=0,G37,G37*F37) -> 0
H38: =IF(F38=0,G38,G38*F38) -> 0
H39: =IF(F39=0,G39,G39*F39) -> 0
H40: =IF(F40=0,G40,G40*F40) -> 0
H41: =IF(F41=0,G41,G41*F41) -> 0
H42: =IF(F42=0,G42,G42*F42) -> 0
H43: =IF(F43=0,G43,G43*F43) -> 0
H44: =IF(F44=0,G44,G44*F44) -> 0
H45: =IF(F45=0,G45,G45*F45) -> 0
C46: 기타자재 | H46: =IF(F46=0,G46,G46*F46) -> 0
...

Sheet 단위장비10
B1: □ 단위공사명(전기제외): | I1: (첨부)
A2: 구분 | C2: 품 명 | D2: 규격 | E2: 단위 | F2: 수량 | G2: 단가(원) | H2: 금액(원) | I2: 原MAKER
A3: 자 재 비 | B3: 철자재 | H3: =IF(F3=0,G3,G3*F3) -> 0
H4: =IF(F4=0,G4,G4*F4) -> 0
H5: =IF(F5=0,G5,G5*F5) -> 0
H6: =IF(F6=0,G6,G6*F6) -> 0
H7: =IF(F7=0,G7,G7*F7) -> 0
H8: =IF(F8=0,G8,G8*F8) -> 0
H9: =IF(F9=0,G9,G9*F9) -> 0
H10: =IF(F10=0,G10,G10*F10) -> 0
H11: =IF(F11=0,G11,G11*F11) -> 0
H12: =IF(F12=0,G12,G12*F12) -> 0
H13: =IF(F13=0,G13,G13*F13) -> 0
H14: =IF(F14=0,G14,G14*F14) -> 0
H15: =IF(F15=0,G15,G15*F15) -> 0
... H22: =IF(F22=0,G22,G22*F22) -> 0
C23: 기타자재 | H23: =IF(F23=0,G23,G23*F23) -> 0
H24: =SUM(H3:H23) -> 0
B25: 설치/해체/시운전 | H25: =IF(F25=0,G25,G25*F25) -> 0
B26: 공사 관련 자재 | H26: =IF(F26=0,G26,G26*F26) -> 0
H27: =IF(F27=0,G27,G27*F27) -> 0
H28: =IF(F28=0,G28,G28*F28) -> 0
C29: 기타자재 | H29: =IF(F29=0,G29,G29*F29) -> 0
H30: =SUM(H25:H29) -> 0
B31: 구매품 | H31: =IF(F31=0,G31,G31*F31) -> 0
B32: (유공압품외) | H32: =IF(F32=0,G32,G32*F32) -> 0
H33: =IF(F33=0,G33,G33*F33) -> 0
H34: =IF(F34=0,G34,G34*F34) -> 0
H35: =IF(F35=0,G35,G35*F35) -> 0
H36: =IF(F36=0,G36,G36*F36) -> 0
H37: =IF(F37=0,G37,G37*F37) -> 0
H38: =IF(F38=0,G38,G38*F38) -> 0
H39: =IF(F39=0,G39,G39*F39) -> 0
H40: =IF(F40=0,G40,G40*F40) -> 0
H41: =IF(F41=0,G41,G41*F41) -> 0
H42: =IF(F42=0,G42,G42*F42) -> 0
H43: =IF(F43=0,G43,G43*F43) -> 0
H44: =IF(F44=0,G44,G44*F44) -> 0
H45: =IF(F45=0,G45,G45*F45) -> 0
C46: 기타자재 | H46: =IF(F46=0,G46,G46*F46) -> 0
...

Sheet 첨부(견적조건차이내역)
A1: ※ 현대/기아차의 요구사양과 업체견적사양이 다른경우만 작성
D2: (첨부)
A3: 현대/기아차 요구사양대비 견적조건 상이내역
A5: 항 목 | B5: 현대/기아차 요구사양 | C5: 업체 견적기준 사양 | D5: 비 고
