Workbook

Sheet 갑지
B1: (현대/기아차 설비협력업체 견적통일양식)
B2: 見 積 書
B4: 현대 위아 貴下 | G4: ㈜ 영산테크노
B5: 견적일자 | D5: 45950 | G5: 대표 : 김영근, 김민섭
B6: 견적번호 | D6: YS-25-P-124 | G6: 주소 : 경기도 군포시 군포첨단산업2로 102
B7: 납기 | C7: 입하 | D7: 협의사항
C8: 최종검수 | D8: 협의사항 | G8: 전화: (031) 355 - 1150
B9: 견적유효기간 | D9: 제출후 30 일 | G9: Fax: (031) 355 - 1154
B10: 인도장소 | D10: 귀사 지정장소 | G10: 견적담당: | H10: 조보형
B11: 지불조건 | D11: 협의사항 | G11: 연 락 처 : | H11: 010-4811-2196
B13: 견적금액 | D13: ="一金"&NUMBERSTRING(H27,1)&"원整" -> 一金이백칠십오만원整 | G13: =H27 -> 2750000 | I13: )
B15: 번호 | C15: 상세품목내역 | E15: 견적금액 (천원) | I15: 비 고
E16: 기계부문 | F16: 전기부문 | G16: 관리/이윤 (안전관리비포함) | H16: 합 계
B17: 1 | C17: =단위장비1!C1 -> 친수 코팅 라인 | E17: =IF('단위공사별(집계)'!N7>1,('단위공사별(집계)'!D7+'단위공사별(집계)'!E7+'단위공사별(집계)'!F7+'단위공사별(집계)'!G7+'단위공사별(집계)'!H7+'단위공사별(집계)'!I7)/1000," ") -> 1445590 | F17: =IF('단위공사별(집계)'!N7>0,'단위공사별(집계)'!K17/1000,"") -> 394625 | G17: =IF('단위공사별(집계)'!N7>0,('단위공사별(집계)'!L7+'단위공사별(집계)'!M7)/1000,"") -> 43179.986 | H17: =IF('단위공사별(집계)'!N7>0,'단위공사별(집계)'!N7/1000,"") -> 1738202
B18: 2 | C18: =단위장비2!C1 -> 바이오 코팅 라인 | E18: =IF('단위공사별(집계)'!N8>1,('단위공사별(집계)'!D8+'단위공사별(집계)'!E8+'단위공사별(집계)'!F8+'단위공사별(집계)'!G8+'단위공사별(집계)'!H8+'단위공사별(집계)'!I8)/1000," ") -> 595410 | G18: =IF('단위공사별(집계)'!N8>0,('단위공사별(집계)'!L8+'단위공사별(집계)'!M8)/1000,"") -> 18505.078 | H18: =IF('단위공사별(집계)'!N8>0,'단위공사별(집계)'!N8/1000,"") -> 716771.84
B19: 3 | C19: =단위장비3!C1 -> 현지설치 및 시운전 | E19: =IF('단위공사별(집계)'!N9>1,('단위공사별(집계)'!D9+'단위공사별(집계)'!E9+'단위공사별(집계)'!F9+'단위공사별(집계)'!G9+'단위공사별(집계)'!H9+'단위공사별(집계)'!I9)/1000," ") -> 112000 | G19: =IF('단위공사별(집계)'!N9>0,('단위공사별(집계)'!L9+'단위공사별(집계)'!M9)/1000,"") -> 664.30264 | H19: =IF('단위공사별(집계)'!N9>0,'단위공사별(집계)'!N9/1000,"") -> 131540.34
B20: 4 | C20: =단위장비4!C1 -> P1 대응비 | E20: =IF('단위공사별(집계)'!N10>1,('단위공사별(집계)'!D10+'단위공사별(집계)'!E10+'단위공사별(집계)'!F10+'단위공사별(집계)'!G10+'단위공사별(집계)'!H10+'단위공사별(집계)'!I10)/1000," ") -> 19200 | G20: =IF('단위공사별(집계)'!N10>0,('단위공사별(집계)'!L10+'단위공사별(집계)'!M10)/1000,"") -> 113.88045 | H20: =IF('단위공사별(집계)'!N10>0,'단위공사별(집계)'!N10/1000,"") -> 22549.773
B21: 5 | C21: =단위장비5!C1 -> P2 대응비 | E21: =IF('단위공사별(집계)'!N11>1,('단위공사별(집계)'!D11+'단위공사별(집계)'!E11+'단위공사별(집계)'!F11+'단위공사별(집계)'!G11+'단위공사별(집계)'!H11+'단위공사별(집계)'!I11)/1000," ") -> 19200 | G21: =IF('단위공사별(집계)'!N11>0,('단위공사별(집계)'!L11+'단위공사별(집계)'!M11)/1000,"") -> 113.88045 | H21: =IF('단위공사별(집계)'!N11>0,'단위공사별(집계)'!N11/1000,"") -> 22549.773
B22: 6 | C22: =단위장비6!C1 -> 양산 대응비 | E22: =IF('단위공사별(집계)'!N12>1,('단위공사별(집계)'!D12+'단위공사별(집계)'!E12+'단위공사별(집계)'!F12+'단위공사별(집계)'!G12+'단위공사별(집계)'!H12+'단위공사별(집계)'!I12)/1000," ") -> 30400 | G22: =IF('단위공사별(집계)'!N12>0,('단위공사별(집계)'!L12+'단위공사별(집계)'!M12)/1000,"") -> 180.31072 | H22: =IF('단위공사별(집계)'!N12>0,'단위공사별(집계)'!N12/1000,"") -> 35703.807
B23: 7 | C23: =단위장비7!C1 -> 출장경비 | E23: =IF('단위공사별(집계)'!N13>1,('단위공사별(집계)'!D13+'단위공사별(집계)'!E13+'단위공사별(집계)'!F13+'단위공사별(집계)'!G13+'단위공사별(집계)'!H13+'단위공사별(집계)'!I13)/1000," ") -> 70400 | G23: =IF('단위공사별(집계)'!N13>0,('단위공사별(집계)'!L13+'단위공사별(집계)'!M13)/1000,"") -> 417.56166 | H23: =IF('단위공사별(집계)'!N13>0,'단위공사별(집계)'!N13/1000,"") -> 82682.5
B24: 8 | C24: =[1]단위장비8!C1 -> 0 | E24: =IF('단위공사별(집계)'!N14>1,('단위공사별(집계)'!D14+'단위공사별(집계)'!E14+'단위공사별(집계)'!F14+'단위공사별(집계)'!G14+'단위공사별(집계)'!H14+'단위공사별(집계)'!I14)/1000," ") | G24: =IF('단위공사별(집계)'!N14>0,('단위공사별(집계)'!L14+'단위공사별(집계)'!M14)/1000,"") | H24: =IF('단위공사별(집계)'!N14>0,'단위공사별(집계)'!N14/1000,"")
B25: 9 | C25: =[1]단위장비9!C1 -> 0 | E25: =IF('단위공사별(집계)'!N15>1,('단위공사별(집계)'!D15+'단위공사별(집계)'!E15+'단위공사별(집계)'!F15+'단위공사별(집계)'!G15+'단위공사별(집계)'!H15+'단위공사별(집계)'!I15)/1000," ") | G25: =IF('단위공사별(집계)'!N15>0,('단위공사별(집계)'!L15+'단위공사별(집계)'!M15)/1000,"") | H25: =IF('단위공사별(집계)'!N15>0,'단위공사별(집계)'!N15/1000,"")
B26: 10 | C26: =[1]단위장비10!C1 -> 0 | E26: =IF('단위공사별(집계)'!N16>1,('단위공사별(집계)'!D16+'단위공사별(집계)'!E16+'단위공사별(집계)'!F16+'단위공사별(집계)'!G16+'단위공사별(집계)'!H16+'단위공사별(집계)'!I16)/1000," ") | G26: =IF('단위공사별(집계)'!N16>0,('단위공사별(집계)'!L16+'단위공사별(집계)'!M16)/1000,"") | H26: =IF('단위공사별(집계)'!N16>0,'단위공사별(집계)'!N16/1000,"")
B27: 견적 합계 | E27: =SUM(E17:E26) -> 2292200 | F27: =SUM(F17) -> 394625 | G27: =SUM(G17:G26) -> 63175 | H27: =SUM(H17:H26) -> 2750000
F29: 공개입찰가 (견적時 공란)
B31: 특기사항 | C31: 1. VAT 제외 | F31: 외주계획 업체명 (자작時 공란)
C32: 2. 기본 유틸리티공사 제외 | F32: 설계외주
F33: 제작외주
F34: 전기외주
F35: 설치외주
K44: =전기!H67+단위장비1!H295+단위장비2!H172+단위장비3!H69+단위장비5!H68+단위장비4!H69+단위장비6!H69+단위장비7!H69+[1]단위장비8!H69+[1]단위장비9!H69+[1]단위장비10!H69 -> 2736112000

Sheet 원가항목별(집계)
C2: A. 원가항목별 견적가 종합(상세견적 첨부)
B4: □ 현대/기아 요구사양과 견적조건 일치여부 CHECK: 1.일치함 2.일부상이(상이내역 첨부참조)
B6: 순번 | C6: 원가구분 | F6: 단위 | G6: 수량 | H6: 단가 | I6: 금 액(원) | J6: 비 고
B7: 1 | C7: 기계 부문 | D7: 자재비 | E7: 철자재(SS.SUS등) | F7: kg | G7: =단위장비1!F145+단위장비2!F62+단위장비3!F30+단위장비5!F29+단위장비4!F30+단위장비6!F30+단위장비7!F30+[1]단위장비8!F30+[1]단위장비9!F30+[1]단위장비10!F30 -> 0 | I7: =단위장비1!H139+단위장비2!H56+단위장비3!H24+단위장비5!H23+단위장비4!H24+단위장비6!H24+단위장비7!H24+[1]단위장비8!H24+[1]단위장비9!H24+[1]단위장비10!H24 -> 658540000 | J7: 加工必要資材
E8: 일반구매품 | F8: 식 | G8: 1 | I8: =단위장비1!H273+단위장비2!H150+단위장비3!H47+단위장비5!H46+단위장비4!H47+단위장비6!H47+단위장비7!H47+[1]단위장비8!H47+[1]단위장비9!H47+[1]단위장비10!H47 -> 668860000 | J8: 加工不要資材
E9: 외주제작품 | F9: 식 | G9: 1 | I9: =단위장비1!H281+단위장비2!H158+단위장비3!H55+단위장비5!H54+단위장비4!H55+단위장비6!H55+단위장비7!H55+[1]단위장비8!H55+[1]단위장비9!H55+[1]단위장비10!H55 -> 329000000 | J9: 旣加工SUB資材
E10: 설치/해체 공사 자재 | F10: 식 | G10: 1 | I10: =단위장비1!H145+단위장비2!H62+단위장비3!H30+단위장비5!H29+단위장비4!H30+단위장비6!H30+단위장비7!H30+[1]단위장비8!H30+[1]단위장비9!H30+[1]단위장비10!H30 -> 0 | J10: 시운전 자재 포함
E11: 소계 | I11: =SUM(I7:I10) -> 1656400000
D12: 노무비 | E12: 기존설비 철거 | F12: M/D | G12: =단위장비1!F283+단위장비2!F160+단위장비3!F57+단위장비5!F56+단위장비4!F57+단위장비6!F57+단위장비7!F57+[1]단위장비8!F57+[1]단위장비9!F57+[1]단위장비10!F57 -> 0 | H12: =IF(단위장비1!G283>0,단위장비1!G283,"") | I12: =단위장비1!H283+단위장비2!H160+단위장비3!H57+단위장비5!H56+단위장비4!H57+단위장비6!H57+단위장비7!H57+[1]단위장비8!H57+[1]단위장비9!H57+[1]단위장비10!H57 -> 0 | J12: 개조공사時
E13: 설계 | F13: M/D | G13: =단위장비1!F284+단위장비2!F161+단위장비3!F58+단위장비5!F57+단위장비4!F58+단위장비6!F58+단위장비7!F58+[1]단위장비8!F58+[1]단위장비9!F58+[1]단위장비10!F58 -> 0 | H13: =IF(단위장비1!G284>0,단위장비1!G284,"") | I13: =단위장비1!H284+단위장비2!H161+단위장비3!H58+단위장비5!H57+단위장비4!H58+단위장비6!H58+단위장비7!H58+[1]단위장비8!H58+[1]단위장비9!H58+[1]단위장비10!H58 -> 0
E14: 제작(제관,가공) | F14: M/D | G14: =단위장비1!F285+단위장비2!F162+단위장비3!F59+단위장비5!F58+단위장비4!F59+단위장비6!F59+단위장비7!F59+[1]단위장비8!F59+[1]단위장비9!F59+[1]단위장비10!F59 -> 1170 | H14: =IF(단위장비1!G285>0,단위장비1!G285,"") -> 300000 | I14: =단위장비1!H285+단위장비2!H162+단위장비3!H59+단위장비5!H58+단위장비4!H59+단위장비6!H59+단위장비7!H59+[1]단위장비8!H59+[1]단위장비9!H59+[1]단위장비10!H59 -> 351000000
E15: 조립 | F15: M/D | G15: =단위장비1!F286+단위장비2!F163+단위장비3!F60+단위장비5!F59+단위장비4!F60+단위장비6!F60+단위장비7!F60+[1]단위장비8!F60+[1]단위장비9!F60+[1]단위장비10!F60 -> 0 | H15: =IF(단위장비1!G286>0,단위장비1!G286,"") | I15: =단위장비1!H286+단위장비2!H163+단위장비3!H60+단위장비5!H59+단위장비4!H60+단위장비6!H60+단위장비7!H60+[1]단위장비8!H60+[1]단위장비9!H60+[1]단위장비10!H60 -> 0 | J15: 정도검사포함
E16: 설치 | F16: M/D | G16: =단위장비1!F287+단위장비2!F164+단위장비3!F61+단위장비5!F60+단위장비4!F61+단위장비6!F61+단위장비7!F61+[1]단위장비8!F61+[1]단위장비9!F61+[1]단위장비10!F61 -> 520 | H16: =IF(단위장비1!G287>0,단위장비1!G287,"") -> 300000 | I16: =단위장비1!H287+단위장비2!H164+단위장비3!H61+단위장비5!H60+단위장비4!H61+단위장비6!H61+단위장비7!H61+[1]단위장비8!H61+[1]단위장비9!H61+[1]단위장비10!H61 -> 172000000
E17: 시운전 | F17: M/D | G17: =단위장비1!F288+단위장비2!F165+단위장비3!F62+단위장비5!F61+단위장비4!F62+단위장비6!F62+단위장비7!F62+[1]단위장비8!F62+[1]단위장비9!F62+[1]단위장비10!F62 -> 256 | H17: =IF(단위장비1!G288>0,단위장비1!G288,"") -> 300000 | I17: =단위장비1!H288+단위장비2!H165+단위장비3!H62+단위장비5!H61+단위장비4!H62+단위장비6!H62+단위장비7!H62+[1]단위장비8!H62+[1]단위장비9!H62+[1]단위장비10!H62 -> 90400000
E18: 양산대응 | F18: M/D | G18: =단위장비1!F289+단위장비2!F166+단위장비3!F63+단위장비5!F62+단위장비4!F63+단위장비6!F63+단위장비7!F63+[1]단위장비8!F63+[1]단위장비9!F63+[1]단위장비10!F63 -> 56 | H18: =IF(단위장비1!G289>0,단위장비1!G289,"") | I18: =단위장비1!H289+단위장비2!H166+단위장비3!H63+단위장비5!H62+단위장비4!H63+단위장비6!H63+단위장비7!H63+[1]단위장비8!H63+[1]단위장비9!H63+[1]단위장비10!H63 -> 22400000
E19: 도장 | F19: M/D | G19: =단위장비1!F290+단위장비2!F167+단위장비3!F64+단위장비5!F63+단위장비4!F64+단위장비6!F64+단위장비7!F64+[1]단위장비8!F64+[1]단위장비9!F64+[1]단위장비10!F64 -> 0 | H19: =IF(단위장비1!G290>0,단위장비1!G290,"") | I19: =단위장비1!H290+단위장비2!H167+단위장비3!H64+단위장비5!H63+단위장비4!H64+단위장비6!H64+단위장비7!H64+[1]단위장비8!H64+[1]단위장비9!H64+[1]단위장비10!H64 -> 0
E20: 소계 | I20: =SUM(I12:I19) -> 635800000
D21: 일반관리 및 이윤 | I21: =단위장비1!H293+단위장비1!H294+단위장비2!H170+단위장비2!H171+단위장비3!H67+단위장비3!H68+단위장비5!H66+단위장비5!H67+단위장비4!H67+단위장비4!H68+단위장비6!H67+단위장비6!H68+단위장비7!H67+단위장비7!H68+[1]단위장비8!H67+[1]단위장비8!H68+[1]단위장비9!H67+[1]단위장비9!H68+[1]단위장비10!H67+[1]단위장비10!H68 -> 49287000
E22: 기계 소계 | I22: =I20+I11+I21 -> 2341487000
B23: 2 | C23: 전기 부문 | D23: 자재비 | E23: 기계/전기자재 | F23: 식 | G23: 1 | I23: =전기!H55-I24 -> 260000000
E24: 설치/해체 공사 자재 | F24: 식 | G24: 1 | I24: =전기!H16 -> 0 | J24: 시운전 자재 포함
D25: 노무비 | E25: 철거(개조시) | F25: M/D | G25: =전기!F56 -> 0 | H25: =IF(전기!G56>0,전기!G56,"") | I25: =전기!H56 -> 0
E26: 설계,프로그램 | F26: M/D | G26: =전기!F57 -> 40 | H26: =IF(전기!G57>0,전기!G57,"") -> 500000 | I26: =전기!H57 -> 20000000
E27: 제작 | F27: M/D | G27: =전기!F58 -> 0 | H27: =IF(전기!G58>0,전기!G58,"") | I27: =전기!H58 -> 0
E28: 조립 | F28: M/D | G28: =전기!F59 -> 0 | H28: =IF(전기!G59>0,전기!G59,"") | I28: =전기!H59 -> 0
E29: 설치 | F29: M/D | G29: =전기!F60 -> 350 | H29: =IF(전기!G60>0,전기!G60,"") -> 300000 | I29: =전기!H60 -> 105000000
E30: 시운전 | F30: M/D | G30: =전기!F61 -> 0 | H30: =IF(전기!G61>0,전기!G61,"") | I30: =전기!H61 -> 0
E31: 양산대응 | F31: M/D | G31: =전기!F62 -> 0 | H31: =IF(전기!G62>0,전기!G62,"") | I31: =전기!H62 -> 0
E32: 소계 | I32: =SUM(I25:I31) -> 125000000
D33: 일반관리 및 이윤 | I33: =전기!H65+전기!H66 -> 9625000
E34: 전기 소계 | I34: =I32+I23+I33+I24 -> 394625000
B35: 3 | C35: 자재비 합계 | I35: =I23+I11+I24 -> 1916400000
C36: 노무비 합계 | I36: =I32+I20 -> 760800000
C37: 중간 합계 | I37: =I36+I35 -> 2677200000
B38: 4 | C38: 포장,운송 및 중장비 사용료
B39: 5 | C39: 표준안전관리비 | F39: 설치/철거/수리금액 기준 | I39: =CEILING(MIN(I48:I49),1000) -> 13888000 | J39: =I30+I29+I25+I24+I17+I16+I12+I10 -> 367400000
B40: 6 | C40: 일반관리비 | I40: =전기!H65+단위장비1!H293+단위장비2!H170+단위장비3!H67+단위장비5!H66+단위장비4!H67+단위장비6!H67+단위장비7!H67+[1]단위장비8!H67+[1]단위장비9!H67+[1]단위장비10!H67 -> 0
B41: 7 | C41: 이 윤 | I41: =전기!H66+단위장비1!H294+단위장비2!H171+단위장비3!H68+단위장비5!H67+단위장비4!H68+단위장비6!H68+단위장비7!H68+[1]단위장비8!H68+[1]단위장비9!H68+[1]단위장비10!H68 -> 58912000
C42: 합 계 | F42: 3~7항 합계 | I42: =I22+I34+I38+I39 -> 2750000000
B43: 주1. 표준안전관리비:(설치/철거/시운전 공사 관련 금액)의
...

Sheet 단위공사별(집계)
A2: B. 단위장비별 견적가 종합(상세견적 첨부)
N3: 단위:원
I5: 포장/운송 | L5: 표준안전 | M5: 일반관리비
A6: 순번 | B6: 단위장비명 | C6: 수량 | D6: 자재비 | E6: 철거 | F6: 제작 | G6: 설치/시운전 | H6: 양산대응 | I6: 중장비사용 | J6: 기계소계 | K6: 전기소계 | L6: 관리비 | M6: 이윤 | N6: 합 계 | O6: 비 고
A7: =IF(B7>0,1,"") -> 1 | B7: =단위장비1!C$1 -> 친수 코팅 라인 | C7: 1식 | D7: =단위장비1!H282 -> 1088590000 | E7: =단위장비1!H283 -> 0 | F7: =단위장비1!H284+단위장비1!H285+단위장비1!H286+단위장비1!H290 -> 246000000 | G7: =단위장비1!H287+단위장비1!H288 -> 111000000 | H7: =단위장비1!H289 -> 0 | I7: =IF($B7>0,'원가항목별(집계)'!I$38*$P7/$P$17,0) -> 0 | J7: =SUM(D7:I7) -> 1445590000 | K7: =IF(B7>0,'원가항목별(집계)'!I$34*P7/P$17,0) -> 2.4943198e+08 | L7: =IF($B7>0,'원가항목별(집계)'!I$39*$P7/$P$17,0) -> 8778236 | M7: =단위장비1!H293+단위장비1!H294 -> 34401750 | N7: =SUM(J7:M7) -> 1.738202e+09 | P7: =D7+E7+F7+G7+H7+M7 -> 1479991750
A8: =IF(B8>0,A7+1,"") -> 2 | B8: =단위장비2!C$1 -> 바이오 코팅 라인 | C8: 1식 | D8: =단위장비2!H159 -> 457410000 | E8: =단위장비2!H160 -> 0 | F8: =단위장비2!H161+단위장비2!H162+단위장비2!H163+단위장비2!H167 -> 105000000 | G8: =단위장비2!H164+단위장비2!H165 -> 33000000 | H8: =단위장비2!H166 -> 0 | I8: =IF($B8>0,'원가항목별(집계)'!I$38*$P8/$P$17,0) -> 0 | J8: =SUM(D8:I8) -> 595410000 | K8: =IF(B8>0,'원가항목별(집계)'!I$34*P8/P$17,0) -> 1.0285676e+08 | L8: =IF($B8>0,'원가항목별(집계)'!I$39*$P8/$P$17,0) -> 3619828.1 | M8: =단위장비2!H170+단위장비2!H171 -> 14885250 | N8: =SUM(J8:M8) -> 7.1677184e+08 | P8: =D8+E8+F8+G8+H8+M8 -> 610295250
A9: =IF(B9>0,A8+1,"") -> 3 | B9: =단위장비3!C$1 -> 현지설치 및 시운전 | C9: 1식 | D9: =단위장비3!H56 -> 16000000 | E9: =단위장비3!H57 -> 0 | F9: =단위장비3!H58+단위장비3!H59+단위장비3!H60+단위장비3!H64 -> 0 | G9: =단위장비3!H61+단위장비3!H62 -> 96000000 | H9: =단위장비3!H63 -> 0 | I9: =IF($B9>0,'원가항목별(집계)'!I$38*$P9/$P$17,0) -> 0 | J9: =SUM(D9:I9) -> 112000000 | K9: =IF(B9>0,'원가항목별(집계)'!I$34*P9/P$17,0) -> 18876039 | L9: =IF($B9>0,'원가항목별(집계)'!I$39*$P9/$P$17,0) -> 664302.64 | M9: =단위장비3!H67+단위장비3!H68 -> 0 | N9: =SUM(J9:M9) -> 1.3154034e+08 | P9: =D9+E9+F9+G9+H9+M9 -> 112000000
A10: =IF(B10>0,A9+1,"") -> 4 | B10: =단위장비4!C1 -> P1 대응비 | C10: 1식 | D10: =단위장비4!H56 -> 8000000 | E10: =단위장비4!H57 -> 0 | F10: =단위장비4!H58+단위장비4!H59+단위장비4!H60+단위장비4!H64 -> 0 | G10: =단위장비4!H61+단위장비4!H62 -> 11200000 | H10: =단위장비4!H63 -> 0 | I10: =IF($B10>0,'원가항목별(집계)'!I$38*$P10/$P$17,0) -> 0 | J10: =SUM(D10:I10) -> 19200000 | K10: =IF(B10>0,'원가항목별(집계)'!I$34*P10/P$17,0) -> 3235892.4 | L10: =IF($B10>0,'원가항목별(집계)'!I$39*$P10/$P$17,0) -> 113880.45 | M10: =단위장비4!H67+단위장비4!H68 -> 0 | N10: =SUM(J10:M10) -> 22549773 | P10: =D10+E10+F10+G10+H10+M10 -> 19200000
A11: =IF(B11>0,A10+1,"") -> 5 | B11: =단위장비5!C1 -> P2 대응비 | C11: 1식 | D11: =단위장비5!H55 -> 8000000 | E11: =단위장비5!H56 -> 0 | F11: =단위장비5!H57+단위장비5!H58+단위장비5!H59+단위장비5!H63 -> 0 | G11: =단위장비5!H60+단위장비5!H61 -> 11200000 | H11: =단위장비5!H62 -> 0 | I11: =IF($B11>0,'원가항목별(집계)'!I$38*$P11/$P$17,0) -> 0 | J11: =SUM(D11:I11) -> 19200000 | K11: =IF(B11>0,'원가항목별(집계)'!I$34*P11/P$17,0) -> 3235892.4 | L11: =IF($B11>0,'원가항목별(집계)'!I$39*$P11/$P$17,0) -> 113880.45 | M11: =단위장비5!H66+단위장비5!H67 -> 0 | N11: =SUM(J11:M11) -> 22549773 | P11: =D11+E11+F11+G11+H11+M11 -> 19200000
A12: =IF(B12>0,A11+1,"") -> 6 | B12: =단위장비6!C$1 -> 양산 대응비 | C12: 1식 | D12: =단위장비6!H56 -> 8000000 | E12: =단위장비6!H57 -> 0 | F12: =단위장비6!H58+단위장비6!H59+단위장비6!H60+단위장비6!H64 -> 0 | G12: =단위장비6!H61+단위장비6!H62 -> 0 | H12: =단위장비6!H63 -> 22400000 | I12: =IF($B12>0,'원가항목별(집계)'!I$38*$P12/$P$17,0) -> 0 | J12: =SUM(D12:I12) -> 30400000 | K12: =IF(B12>0,'원가항목별(집계)'!I$34*P12/P$17,0) -> 5123496.3 | L12: =IF($B12>0,'원가항목별(집계)'!I$39*$P12/$P$17,0) -> 180310.72 | M12: =단위장비6!H67+단위장비6!H68 -> 0 | N12: =SUM(J12:M12) -> 35703807 | P12: =D12+E12+F12+G12+H12+M12 -> 30400000
A13: =IF(B13>0,A12+1,"") -> 7 | B13: =단위장비7!C$1 -> 출장경비 | C13: 1식 | D13: =단위장비7!H56 -> 70400000 | E13: =단위장비7!H57 -> 0 | F13: =단위장비7!H58+단위장비7!H59+단위장비7!H60+단위장비7!H64 -> 0 | G13: =단위장비7!H61+단위장비7!H62 -> 0 | H13: =단위장비7!H63 -> 0 | I13: =IF($B13>0,'원가항목별(집계)'!I$38*$P13/$P$17,0) -> 0 | J13: =SUM(D13:I13) -> 70400000 | K13: =IF(B13>0,'원가항목별(집계)'!I$34*P13/P$17,0) -> 11864939 | L13: =IF($B13>0,'원가항목별(집계)'!I$39*$P13/$P$17,0) -> 417561.66 | M13: =단위장비7!H67+단위장비7!H68 -> 0 | N13: =SUM(J13:M13) -> 82682500 | P13: =D13+E13+F13+G13+H13+M13 -> 70400000
A14: =IF(B14>0,A13+1,"") | B14: =[1]단위장비8!C$1 -> 0 | C14: 1식 | D14: =[1]단위장비8!H56 -> 0 | E14: =[1]단위장비8!H57 -> 0 | F14: =[1]단위장비8!H58+[1]단위장비8!H59+[1]단위장비8!H60+[1]단위장비8!H64 -> 0 | G14: =[1]단위장비8!H61+[1]단위장비8!H62 -> 0 | H14: =[1]단위장비8!H63 -> 0 | I14: =IF($B14>0,'원가항목별(집계)'!I$38*$P14/$P$17,0) -> 0 | J14: =SUM(D14:I14) -> 0 | K14: =IF(B14>0,'원가항목별(집계)'!I$34*P14/P$17,0) -> 0 | L14: =IF($B14>0,'원가항목별(집계)'!I$39*$P14/$P$17,0) -> 0 | M14: =[1]단위장비8!H67+[1]단위장비8!H68 -> 0 | N14: =SUM(J14:M14) -> 0 | P14: =D14+E14+F14+G14+H14+M14 -> 0
A15: =IF(B15>0,A14+1,"") | B15: =[1]단위장비9!C$1 -> 0 | C15: 1식 | D15: =[1]단위장비9!H57 -> 0 | E15: =[1]단위장비9!H58 -> 0 | F15: =[1]단위장비9!H59+[1]단위장비9!H60+[1]단위장비9!H61+[1]단위장비9!H65 -> 0 | G15: =[1]단위장비9!H62+[1]단위장비9!H63 -> 0 | H15: =[1]단위장비9!H64 -> 0 | I15: =IF($B15>0,'원가항목별(집계)'!I$38*$P15/$P$17,0) -> 0 | J15: =SUM(D15:I15) -> 0 | K15: =IF(B15>0,'원가항목별(집계)'!I$34*P15/P$17,0) -> 0 | L15: =IF($B15>0,'원가항목별(집계)'!I$39*$P15/$P$17,0) -> 0 | M15: =[1]단위장비9!H68+[1]단위장비9!H69 -> 0 | N15: =SUM(J15:M15) -> 0 | P15: =D15+E15+F15+G15+H15+M15 -> 0
A16: =IF(B16>0,A15+1,"") | B16: =[1]단위장비10!C$1 -> 0 | C16: 1식 | D16: =[1]단위장비10!H58 -> 0 | E16: =[1]단위장비10!H59 -> 0 | F16: =[1]단위장비10!H60+[1]단위장비10!H61+[1]단위장비10!H62+[1]단위장비10!H66 -> 0 | G16: =[1]단위장비10!H63+[1]단위장비10!H64 -> 0 | H16: =[1]단위장비10!H65 -> 0 | I16: =IF($B16>0,'원가항목별(집계)'!I$38*$P16/$P$17,0) -> 0 | J16: =SUM(D16:I16) -> 0 | K16: =IF(B16>0,'원가항목별(집계)'!I$34*P16/P$17,0) -> 0 | L16: =IF($B16>0,'원가항목별(집계)'!I$39*$P16/$P$17,0) -> 0 | M16: =[1]단위장비10!H69+[1]단위장비10!H70 -> 0 | N16: =SUM(J16:M16) -> 0 | P16: =D16+E16+F16+G16+H16+M16 -> 0
A17: 합 계 | D17: =SUM(D7:D16) -> 1656400000 | E17: =SUM(E7:E16) -> 0 | F17: =SUM(F7:F16) -> 351000000 | G17: =SUM(G7:G16) -> 262400000 | H17: =SUM(H7:H16) -> 22400000 | I17: =SUM(I7:I16) -> 0 | J17: =SUM(D17:I17) -> 2292200000 | K17: =SUM(K7:K16) -> 3.94625e+08 | L17: =SUM(L7:L16) -> 13888000 | M17: =SUM(M7:M16) -> 49287000 | N17: =SUM(N7:N14) -> 2.75e+09 | P17: =SUM(P7:P16) -> 2341487000
D18: =IF(D17=0,"",D17/$N17) -> 0.60232727 | E18: =IF(E17=0,"",E17/$N17) | F18: =IF(F17=0,"",F17/$N17) -> 0.12763636 | G18: =IF(G17=0,"",G17/$N17) -> 0.095418182 | H18: =IF(H17=0,"",H17/$N17) -> 0.0081454545 | I18: =IF(I17=0,"",I17/$N17) | J18: =IF(J17=0,"",J17/$N17) -> 0.83352727 | K18: =IF(K17=0,"",K17/$N17) -> 0.1435 | ... N18: =IF(N17=0,"",N17/$N17) -> 1
A19: 주) 전기비용은 턴키장비의 공통비용으로서 총 전기비용을 단위장비별 기계금액의 비율에 따라 배분함
N20: =IF('원가항목별(집계)'!I42='단위공사별(집계)'!N17,"","DATA오류입니다!")

Sheet 전기
B1: □ 전기부문: | I1: (첨부)
A2: 구분 | C2: 품 명 | D2: 규격 | E2: 단위 | F2: 수량 | G2: 단가(원) | H2: 금액(원) | I2: 原MAKER
A3: 자 재 비 | B3: 철자재 | H3: =IF(F3=0,G3,G3*F3) -> 0
H4: =IF(F4=0,G4,G4*F4) -> 0
H5: =IF(F5=0,G5,G5*F5) -> 0
H6: =IF(F6=0,G6,G6*F6) -> 0
H7: =IF(F7=0,G7,G7*F7) -> 0
H8: =IF(F8=0,G8,G8*F8) -> 0
H9: =SUM(H3:H8) -> 0
B10: 설치/해체/ | H10: =IF(F10=0,G10,G10*F10) -> 0
B11: 시운전 공사 | H11: =IF(F11=0,G11,G11*F11) -> 0
B12: 자재 | H12: =IF(F12=0,G12,G12*F12) -> 0
H13: =IF(F13=0,G13,G13*F13) -> 0
H14: =IF(F14=0,G14,G14*F14) -> 0
C15: 기타자재 | E15: ST | H15: =IF(F15=0,G15,G15*F15) -> 0
H16: =SUM(H10:H15) -> 0
B17: 전기자재 | C17: 판넬 자재 & 제작비 | D17: Q PLC (미쓰비시) | E17: LOT | F17: 1 | G17: =96500000+60000000 -> 156500000 | H17: =IF(F17=0,G17,G17*F17) -> 156500000
C18: 2차 공사 자재비 | E18: LOT | F18: 1 | G18: =83500000+20000000 -> 103500000 | H18: =IF(F18=0,G18,G18*F18) -> 103500000
H19: =IF(F19=0,G19,G19*F19) -> 0
H20: =IF(F20=0,G20,G20*F20) -> 0
H21: =IF(F21=0,G21,G21*F21) -> 0
H22: =IF(F22=0,G22,G22*F22) -> 0
H23: =IF(F23=0,G23,G23*F23) -> 0
H24: =IF(F24=0,G24,G24*F24) -> 0
H25: =IF(F25=0,G25,G25*F25) -> 0
H26: =IF(F26=0,G26,G26*F26) -> 0
H27: =IF(F27=0,G27,G27*F27) -> 0
H28: =IF(F28=0,G28,G28*F28) -> 0
H29: =IF(F29=0,G29,G29*F29) -> 0
H30: =IF(F30=0,G30,G30*F30) -> 0
... H53: =IF(F53=0,G53,G53*F53) -> 0
H54: =SUM(H17:H53) -> 260000000
B55: 자재비 소계 | H55: =SUM(H54,H9,H16) -> 260000000
A56: 노 무 비 | B56: 기존설비 철거 | E56: M/D | H56: =F56*G56 -> 0
B57: 작화. PROGRAM 비 | E57: M/D | F57: =20+20 -> 40 | G57: 500000 | H57: =F57*G57 -> 20000000
B58: 전기 제작 | E58: M/D | H58: =F58*G58 -> 0
B59: 전기 조립 | E59: M/D | H59: =F59*G59 -> 0
B60: 전기 설치 | E60: M/D | F60: 350 | G60: 300000 | H60: =F60*G60 -> 105000000
B61: 전기 시운전 | E61: M/D | H61: =F61*G61 -> 0
B62: 전기 양산대응 | E62: M/D | H62: =F62*G62 -> 0
...

Sheet 단위장비1
B1: □ 단위공사명(전기제외): | C1: 친수 코팅 라인 | I1: (첨부)
A2: 구분 | C2: 품 명 | D2: 규격 | E2: 단위 | F2: 수량 | G2: 단가(원) | H2: 금액(원) | I2: 原MAKER
A3: 자 재 비 | B3: 철자재 | C3: 1. FRAME & BASE
C4: H-BEAM | D4: H - 200 x 200 | E4: LOT | F4: 1 | G4: 21000000 | H4: =IF(F4=0,G4,G4*F4) -> 21000000
C5: H-BEAM | D5: H - 200 x 100 | E5: LOT | F5: 1 | G5: 5290000 | H5: =F5*G5 -> 5290000
C6: I-BEAM | D6: I-250x125 | E6: LOT | F6: 1 | G6: 5040000 | H6: =F6*G6 -> 5040000
C7: CHANNEL | D7: ㄷ - 200 x 80 | E7: LOT | F7: 1 | G7: 3640000 | H7: =F7*G7 -> 3640000
C8: CHANNEL | D8: ㄷ - 125 x 65 | E8: LOT | F8: 1 | G8: 4410000 | H8: =F8*G8 -> 4410000
C9: CHANNEL | D9: ㄷ - 100 x 50 | E9: LOT | F9: 1 | G9: 2210000 | H9: =F9*G9 -> 2210000
C10: STEEL PLATE | D10: SS - 20Tx4'x8'외 | E10: LOT | F10: 1 | G10: 4640000 | H10: =F10*G10 -> 4640000
C11: ANGLE | D11: SS L - 65 x 6T | E11: LOT | F11: 1 | G11: 2730000 | H11: =F11*G11 -> 2730000
C12: ANGLE | D12: SS L - 50 x 6T | E12: LOT | F12: 1 | G12: 1160000 | H12: =F12*G12 -> 1160000
C13: CHECK PLATE | D13: SS - 4'x8'x 4.5T | E13: LOT | F13: 1 | G13: 5510000 | H13: =F13*G13 -> 5510000
C14: PIPE | D14: 25A외 | E14: LOT | F14: 1 | G14: 2100000 | H14: =F14*G14 -> 2100000
C15: C형강 | D15: 150x65x3.2T | E15: LOT | F15: 1 | G15: 840000 | H15: =F15*G15 -> 840000
C16: 소모자재 및 잡자재 | E16: LOT | F16: 1 | G16: 1580000 | H16: =F16*G16 -> 1580000
C18: 2. PROCESS TANK
C19: 수세조 #1 | D19: SUS304 1650x1650x1100 | E19: LOT | F19: 1 | G19: 16800000 | H19: =F19*G19 -> 16800000
C20: 화성조 | D20: SUS316 1650x1650x1100/보온 | E20: LOT | F20: 1 | G20: 33600000 | H20: =F20*G20 -> 33600000
C21: 2단 수세조 #2,3 | D21: SUS304 1650x3430x1100 | E21: LOT | F21: 1 | G21: 28350000 | H21: =IF(F21=0,G21,G21*F21) -> 28350000
C22: 친수조 | D22: SUS304 1650x1650x1100 | E22: LOT | F22: 1 | G22: 16800000 | H22: =F22*G22 -> 16800000
C23: 화성보조조 | D23: PP15T 900x1350x1000 | E23: LOT | F23: 1 | G23: 6300000 | H23: =F23*G23 -> 6300000
C24: 친수보조조 | D24: PP15T 900x1350x1000 | E24: LOT | F24: 1 | G24: 6300000 | H24: =F24*G24 -> 6300000
C25: 약품저장조 | D25: PP15T 940x 690x 985 | E25: LOT | F25: 2 | G25: 5250000 | H25: =F25*G25 -> 10500000
C27: 3. AUTOMATIC O/H CARRIER-2SET
C28: CHANNEL | D28: SS41 ㄷ-150x75외 | E28: LOT | F28: 2 | G28: 880000 | H28: =F28*G28 -> 1760000
C29: SQ-PIPE | D29: SS41 ㅁ-100x50 | E29: LOT | F29: 2 | G29: 330000 | H29: =F29*G29 -> 660000
C30: STEEL PLATE | D30: SS41 16T외 | E30: LOT | F30: 2 | G30: 1320000 | H30: =F30*G30 -> 2640000
C31: STEEL PLATE | D31: SUS304 1.5T외 | E31: LOT | F31: 2 | G31: 840000 | H31: =F31*G31 -> 1680000
C32: 기타잡자재 | E32: LOT | F32: 2 | G32: 530000 | H32: =F32*G32 -> 1060000
C34: 4. 자동 약품관리 SYSTEM
C35: 형강류 | D35: C-CHANNEL, STEEL PLATE | E35: LOT | F35: 1 | G35: 1950000 | H35: =F35*G35 -> 1950000
C37: 5. LIFTER UNIT-2SET
C38: SQ-PIPE | D38: SS ㅁ-100x100 | E38: LOT | F38: 2 | G38: 1760000 | H38: =F38*G38 -> 3520000
C39: CHANNEL | D39: SS ㄷ-100x50외 | E39: LOT | F39: 2 | G39: 660000 | H39: =F39*G39 -> 1320000
C40: ELEVATOR RAIL | E40: LOT | F40: 2 | G40: 420000 | H40: =F40*G40 -> 840000
C41: STEEL PLATE | D41: SS 9T외 | E41: LOT | F41: 2 | G41: 1100000 | H41: =F41*G41 -> 2200000
C42: 안전망,핸드레일 | E42: LOT | F42: 2 | G42: 630000 | H42: =F42*G42 -> 1260000
C43: 기타잡자재 | E43: LOT | F43: 2 | G43: 320000 | H43: =F43*G43 -> 640000
C45: 6. LOADING CONVEYOR
...

Sheet 단위장비2
B1: □ 단위공사명(전기제외): | C1: 바이오 코팅 라인 | I1: (첨부)
A2: 구분 | C2: 품 명 | D2: 규격 | E2: 단위 | F2: 수량 | G2: 단가(원) | H2: 금액(원) | I2: 原MAKER
A3: 자 재 비 | B3: 철자재 | C3: 1. LOADING/UNLOADING CONVEYOR
C4: FRAME | D4: FAL6030, FAC11847 | E4: LOT | F4: 7 | G4: 2770000 | H4: =F4*G4 -> 19390000
C5: PLATE | D5: SS400 20t 외 | E5: LOT | F5: 7 | G5: 760000 | H5: =F5*G5 -> 5320000
C6: 잡자재 | D6: 볼트 외 | E6: LOT | F6: 7 | G6: 250000 | H6: =F6*G6 -> 1750000
C8: 2. LOADING/UNLOADING LOADER
C9: SQ-PIPE | D9: SS ㅁ- 100x100x3.2T외 | E9: LOT | F9: 2 | G9: 1210000 | H9: =IF(F9=0,G9,G9*F9) -> 2420000
C10: AL PLATE | D10: AL 20T외 | E10: LOT | F10: 2 | G10: 970000 | H10: =IF(F10=0,G10,G10*F10) -> 1940000
C11: 기타잡자재 | E11: LOT | F11: 2 | G11: 420000 | H11: =IF(F11=0,G11,G11*F11) -> 840000
C13: 3. SPRAY SYSTEM & BOOTH
C14: FRAME | D14: S.Q PIPE 80x40x3.2t | E14: LOT | F14: 1 | G14: 4160000
C15: PLATE | D15: STS304 3t 외 | E15: LOT | F15: 1 | G15: 8660000 | H15: =IF(F15=0,G15,G15*F15) -> 8660000
C16: 잡자재 | D16: 볼트 외 | E16: LOT | F16: 1 | G16: 1680000 | H16: =IF(F16=0,G16,G16*F16) -> 1680000
C18: 4. 건조로 투입 TRANSFER
C19: FRAME | D19: S.Q PIPE 100x100x3.2t | E19: LOT | F19: 1 | G19: 1010000 | H19: =IF(F19=0,G19,G19*F19) -> 1010000
C20: PLATE | D20: SS400 20t 외 | E20: LOT | F20: 1 | G20: 760000 | H20: =F20*G20 -> 760000
C21: 잡자재 | D21: 볼트 외 | E21: LOT | F21: 1 | G21: 380000 | H21: =F21*G21 -> 380000
C23: 5. 건조로 CONVEYOR
C24: FRAME | D24: ㄷ100x50 외 | E24: LOT | F24: 3 | G24: 3000000 | H24: =IF(F24=0,G24,G24*F24) -> 9000000
C25: CHAIN & SPROCKET | D25: RS60 | E25: LOT | F25: 3 | G25: 1030000 | H25: =IF(F25=0,G25,G25*F25) -> 3090000
C26: 피치 이송 UNIT | D26: AL6061 12t 외 | E26: LOT | F26: 6 | G26: 740000 | H26: =IF(F26=0,G26,G26*F26) -> 4440000
C27: 잡자재 | D27: 볼트 외 | E27: LOT | F27: 3 | G27: 400000 | H27: =IF(F27=0,G27,G27*F27) -> 1200000
C29: 6. 건조로 본체
C30: FRAME | D30: S.Q PIPE 100x100x3.2t | E30: LOT | F30: 1 | G30: 12500000 | H30: =IF(F30=0,G30,G30*F30) -> 12500000
C31: PLATE | D31: SS400 9t 외 | E31: LOT | F31: 1 | G31: 16700000 | H31: =IF(F31=0,G31,G31*F31) -> 16700000
C32: 점검 도어 | D32: SS FRAME & PC 점검창 | E32: LOT | F32: 1 | G32: 12700000 | H32: =IF(F32=0,G32,G32*F32) -> 12700000
C33: 본체 INSULATION | D33: 50t | E33: LOT | F33: 1 | G33: 4000000 | H33: =IF(F33=0,G33,G33*F33) -> 4000000
C34: 덕트 INSULATION | D34: 50t | E34: LOT | F34: 1 | G34: 7500000 | H34: =IF(F34=0,G34,G34*F34) -> 7500000
C35: 잡자재 | D35: 볼트 외 | E35: LOT | F35: 1 | G35: 4200000 | H35: =IF(F35=0,G35,G35*F35) -> 4200000
C37: 7. 건조로 이송 셔틀
C38: FRAME | D38: S.Q PIPE 100x100x3.2t | E38: LOT | F38: 2 | G38: 1010000 | H38: =F38*G38 -> 2020000
C39: PLATE | D39: SS400 20t 외 | E39: LOT | F39: 2 | G39: 760000 | H39: =F39*G39 -> 1520000
C40: 잡자재 | D40: 볼트 외 | E40: LOT | F40: 2 | G40: 380000 | H40: =IF(F40=0,G40,G40*F40) -> 760000
C42: 8. 기타
C43: 배관공사 | E43: LOT | F43: 1 | G43: 30000000 | H43: =IF(F43=0,G43,G43*F43) -> 30000000
C44: 안전 휀스 제작 & 설치 | E44: LOT | F44: 1 | G44: 15000000 | H44: =IF(F44=0,G44,G44*F44) -> 15000000
C45: 압력용기 인증비 | D45: BIO, 세척액 탱크 | E45: LOT | F45: 1 | G45: 31600000 | H45: =IF(F45=0,G45,G45*F45) -> 31600000
H46: =IF(F46=0,G46,G46*F46) -> 0
H47: =IF(F47=0,G47,G47*F47) -> 0
...

Sheet 단위장비3
B1: □ 단위공사명(전기제외): | C1: 현지설치 및 시운전 | I1: (첨부)
A2: 구분 | C2: 품 명 | D2: 규격 | E2: 단위 | F2: 수량 | G2: 단가(원) | H2: 금액(원) | I2: 原MAKER
A3: 자 재 비 | B3: 철자재 | I3: Manifold
H4: =IF(F4=0,G4,G4*F4) -> 0
H5: =IF(F5=0,G5,G5*F5) -> 0
H6: =IF(F6=0,G6,G6*F6) -> 0
H7: =IF(F7=0,G7,G7*F7) -> 0
H8: =IF(F8=0,G8,G8*F8) -> 0
H9: =IF(F9=0,G9,G9*F9) -> 0
H10: =IF(F10=0,G10,G10*F10) -> 0
H11: =IF(F11=0,G11,G11*F11) -> 0
H12: =IF(F12=0,G12,G12*F12) -> 0
H13: =IF(F13=0,G13,G13*F13) -> 0
H14: =IF(F14=0,G14,G14*F14) -> 0
H15: =IF(F15=0,G15,G15*F15) -> 0
... H23: =IF(F23=0,G23,G23*F23) -> 0
H24: =SUM(H3:H23) -> 0
B25: 설치/해체/시운전 | H25: =IF(F25=0,G25,G25*F25) -> 0
B26: 공사 관련 자재 | H26: =IF(F26=0,G26,G26*F26) -> 0
H27: =IF(F27=0,G27,G27*F27) -> 0
H28: =IF(F28=0,G28,G28*F28) -> 0
H29: =IF(F29=0,G29,G29*F29) -> 0
H30: =SUM(H25:H29) -> 0
B31: 구매품 | C31: 항공료(왕복) | E31: LOT | F31: 8 | G31: 2000000 | H31: =IF(F31=0,G31,G31*F31) -> 16000000
B32: (유공압품외) | H32: =IF(F32=0,G32,G32*F32) -> 0
H33: =IF(F33=0,G33,G33*F33) -> 0
H34: =IF(F34=0,G34,G34*F34) -> 0
H35: =IF(F35=0,G35,G35*F35) -> 0
H36: =IF(F36=0,G36,G36*F36) -> 0
H37: =IF(F37=0,G37,G37*F37) -> 0
H38: =IF(F38=0,G38,G38*F38) -> 0
H39: =IF(F39=0,G39,G39*F39) -> 0
H40: =IF(F40=0,G40,G40*F40) -> 0
H41: =IF(F41=0,G41,G41*F41) -> 0
H42: =IF(F42=0,G42,G42*F42) -> 0
H43: =IF(F43=0,G43,G43*F43) -> 0
H44: =IF(F44=0,G44,G44*F44) -> 0
... H46: =IF(F46=0,G46,G46*F46) -> 0
H47: =SUM(H31:H46) -> 16000000
B48: 외주제작품 | H48: =IF(F48=0,G48,G48*F48) -> 0
...

Sheet 단위장비4
B1: □ 단위공사명(전기제외): | C1: P1 대응비 | I1: (첨부)
A2: 구분 | C2: 품 명 | D2: 규격 | E2: 단위 | F2: 수량 | G2: 단가(원) | H2: 금액(원) | I2: 原MAKER
A3: 자 재 비 | B3: 철자재 | H3: =IF(F3=0,G3,G3*F3) -> 0
H4: =IF(F4=0,G4,G4*F4) -> 0
H5: =IF(F5=0,G5,G5*F5) -> 0
H6: =IF(F6=0,G6,G6*F6) -> 0
H7: =IF(F7=0,G7,G7*F7) -> 0
H8: =IF(F8=0,G8,G8*F8) -> 0
H9: =IF(F9=0,G9,G9*F9) -> 0
H10: =IF(F10=0,G10,G10*F10) -> 0
H11: =IF(F11=0,G11,G11*F11) -> 0
H12: =IF(F12=0,G12,G12*F12) -> 0
H13: =IF(F13=0,G13,G13*F13) -> 0
H14: =IF(F14=0,G14,G14*F14) -> 0
H15: =IF(F15=0,G15,G15*F15) -> 0
... H23: =IF(F23=0,G23,G23*F23) -> 0
H24: =SUM(H3:H23) -> 0
B25: 설치/해체/시운전 | H25: =IF(F25=0,G25,G25*F25) -> 0
B26: 공사 관련 자재 | H26: =IF(F26=0,G26,G26*F26) -> 0
H27: =IF(F27=0,G27,G27*F27) -> 0
H28: =IF(F28=0,G28,G28*F28) -> 0
H29: =IF(F29=0,G29,G29*F29) -> 0
H30: =SUM(H25:H29) -> 0
B31: 구매품 | C31: 항공료(왕복) | E31: LOT | F31: 4 | G31: 2000000 | H31: =IF(F31=0,G31,G31*F31) -> 8000000
B32: (유공압품외) | H32: =IF(F32=0,G32,G32*F32) -> 0
H33: =IF(F33=0,G33,G33*F33) -> 0
H34: =IF(F34=0,G34,G34*F34) -> 0
H35: =IF(F35=0,G35,G35*F35) -> 0
H36: =IF(F36=0,G36,G36*F36) -> 0
H37: =IF(F37=0,G37,G37*F37) -> 0
H38: =IF(F38=0,G38,G38*F38) -> 0
H39: =IF(F39=0,G39,G39*F39) -> 0
H40: =IF(F40=0,G40,G40*F40) -> 0
H41: =IF(F41=0,G41,G41*F41) -> 0
H42: =IF(F42=0,G42,G42*F42) -> 0
H43: =IF(F43=0,G43,G43*F43) -> 0
H44: =IF(F44=0,G44,G44*F44) -> 0
... H46: =IF(F46=0,G46,G46*F46) -> 0
H47: =SUM(H31:H46) -> 8000000
B48: 외주제작품 | H48: =IF(F48=0,G48,G48*F48) -> 0
...

Sheet 단위장비5
B1: □ 단위공사명(전기제외): | C1: P2 대응비 | I1: (첨부)
A2: 구분 | C2: 품 명 | D2: 규격 | E2: 단위 | F2: 수량 | G2: 단가(원) | H2: 금액(원) | I2: 原MAKER
A3: 자 재 비 | B3: 철자재 | H3: =IF(F3=0,G3,G3*F3) -> 0
H4: =IF(F4=0,G4,G4*F4) -> 0
H5: =IF(F5=0,G5,G5*F5) -> 0
H6: =IF(F6=0,G6,G6*F6) -> 0
H7: =IF(F7=0,G7,G7*F7) -> 0
H8: =IF(F8=0,G8,G8*F8) -> 0
H9: =IF(F9=0,G9,G9*F9) -> 0
H10: =IF(F10=0,G10,G10*F10) -> 0
H11: =IF(F11=0,G11,G11*F11) -> 0
H12: =IF(F12=0,G12,G12*F12) -> 0
H13: =IF(F13=0,G13,G13*F13) -> 0
H14: =IF(F14=0,G14,G14*F14) -> 0
H15: =IF(F15=0,G15,G15*F15) -> 0
... H22: =IF(F22=0,G22,G22*F22) -> 0
H23: =SUM(H3:H22) -> 0
B24: 설치/해체/시운전 | H24: =IF(F24=0,G24,G24*F24) -> 0
B25: 공사 관련 자재 | H25: =IF(F25=0,G25,G25*F25) -> 0
H26: =IF(F26=0,G26,G26*F26) -> 0
H27: =IF(F27=0,G27,G27*F27) -> 0
H28: =IF(F28=0,G28,G28*F28) -> 0
H29: =SUM(H24:H28) -> 0
B30: 구매품 | C30: 항공료(왕복) | E30: LOT | F30: 4 | G30: 2000000 | H30: =IF(F30=0,G30,G30*F30) -> 8000000
B31: (유공압품외) | H31: =IF(F31=0,G31,G31*F31) -> 0
H32: =IF(F32=0,G32,G32*F32) -> 0
H33: =IF(F33=0,G33,G33*F33) -> 0
H34: =IF(F34=0,G34,G34*F34) -> 0
H35: =IF(F35=0,G35,G35*F35) -> 0
H36: =IF(F36=0,G36,G36*F36) -> 0
H37: =IF(F37=0,G37,G37*F37) -> 0
H38: =IF(F38=0,G38,G38*F38) -> 0
H39: =IF(F39=0,G39,G39*F39) -> 0
H40: =IF(F40=0,G40,G40*F40) -> 0
H41: =IF(F41=0,G41,G41*F41) -> 0
H42: =IF(F42=0,G42,G42*F42) -> 0
H43: =IF(F43=0,G43,G43*F43) -> 0
... H45: =IF(F45=0,G45,G45*F45) -> 0
H46: =SUM(H30:H45) -> 8000000
B47: 외주제작품 | H47: =IF(F47=0,G47,G47*F47) -> 0
...

Sheet 단위장비6
B1: □ 단위공사명(전기제외): | C1: 양산 대응비 | I1: (첨부)
A2: 구분 | C2: 품 명 | D2: 규격 | E2: 단위 | F2: 수량 | G2: 단가(원) | H2: 금액(원) | I2: 原MAKER
A3: 자 재 비 | B3: 철자재 | H3: =IF(F3=0,G3,G3*F3) -> 0
H4: =IF(F4=0,G4,G4*F4) -> 0
H5: =IF(F5=0,G5,G5*F5) -> 0
H6: =IF(F6=0,G6,G6*F6) -> 0
H7: =IF(F7=0,G7,G7*F7) -> 0
H8: =IF(F8=0,G8,G8*F8) -> 0
H9: =IF(F9=0,G9,G9*F9) -> 0
H10: =IF(F10=0,G10,G10*F10) -> 0
H11: =IF(F11=0,G11,G11*F11) -> 0
H12: =IF(F12=0,G12,G12*F12) -> 0
H13: =IF(F13=0,G13,G13*F13) -> 0
H14: =IF(F14=0,G14,G14*F14) -> 0
H15: =IF(F15=0,G15,G15*F15) -> 0
... H22: =IF(F22=0,G22,G22*F22) -> 0
C23: 기타자재 | H23: =IF(F23=0,G23,G23*F23) -> 0
H24: =SUM(H3:H23) -> 0
B25: 설치/해체/시운전 | H25: =IF(F25=0,G25,G25*F25) -> 0
B26: 공사 관련 자재 | H26: =IF(F26=0,G26,G26*F26) -> 0
H27: =IF(F27=0,G27,G27*F27) -> 0
H28: =IF(F28=0,G28,G28*F28) -> 0
C29: 기타자재 | H29: =IF(F29=0,G29,G29*F29) -> 0
H30: =SUM(H25:H29) -> 0
B31: 구매품 | C31: 항공료(왕복) | E31: LOT | F31: 4 | G31: 2000000 | H31: =IF(F31=0,G31,G31*F31) -> 8000000
B32: (유공압품외) | H32: =IF(F32=0,G32,G32*F32) -> 0
H33: =IF(F33=0,G33,G33*F33) -> 0
H34: =IF(F34=0,G34,G34*F34) -> 0
H35: =IF(F35=0,G35,G35*F35) -> 0
H36: =IF(F36=0,G36,G36*F36) -> 0
H37: =IF(F37=0,G37,G37*F37) -> 0
H38: =IF(F38=0,G38,G38*F38) -> 0
H39: =IF(F39=0,G39,G39*F39) -> 0
H40: =IF(F40=0,G40,G40*F40) -> 0
H41: =IF(F41=0,G41,G41*F41) -> 0
H42: =IF(F42=0,G42,G42*F42) -> 0
H43: =IF(F43=0,G43,G43*F43) -> 0
H44: =IF(F44=0,G44,G44*F44) -> 0
H45: =IF(F45=0,G45,G45*F45) -> 0
C46: 기타자재 | E46: ST | H46: =IF(F46=0,G46,G46*F46) -> 0
...

Sheet 단위장비7
B1: □ 단위공사명(전기제외): | C1: 출장경비 | I1: (첨부)
A2: 구분 | C2: 품 명 | D2: 규격 | E2: 단위 | F2: 수량 | G2: 단가(원) | H2: 금액(원) | I2: 原MAKER
A3: 자 재 비 | B3: 철자재 | H3: =IF(F3=0,G3,G3*F3) -> 0
H4: =IF(F4=0,G4,G4*F4) -> 0
H5: =IF(F5=0,G5,G5*F5) -> 0
H6: =IF(F6=0,G6,G6*F6) -> 0
H7: =IF(F7=0,G7,G7*F7) -> 0
H8: =IF(F8=0,G8,G8*F8) -> 0
H9: =IF(F9=0,G9,G9*F9) -> 0
H10: =IF(F10=0,G10,G10*F10) -> 0
H11: =IF(F11=0,G11,G11*F11) -> 0
H12: =IF(F12=0,G12,G12*F12) -> 0
H13: =IF(F13=0,G13,G13*F13) -> 0
H14: =IF(F14=0,G14,G14*F14) -> 0
H15: =IF(F15=0,G15,G15*F15) -> 0
... H22: =IF(F22=0,G22,G22*F22) -> 0
C23: 기타자재 | E23: ST | H23: =IF(F23=0,G23,G23*F23) -> 0
H24: =SUM(H3:H23) -> 0
B25: 설치/해체/시운전 | H25: =IF(F25=0,G25,G25*F25) -> 0
B26: 공사 관련 자재 | H26: =IF(F26=0,G26,G26*F26) -> 0
H27: =IF(F27=0,G27,G27*F27) -> 0
H28: =IF(F28=0,G28,G28*F28) -> 0
C29: 기타자재 | H29: =IF(F29=0,G29,G29*F29) -> 0
H30: =SUM(H25:H29) -> 0
B31: 구매품 | C31: 출장경비 | D31: 호텔,식비 등 | E31: MD | F31: 352 | G31: 200000 | H31: =IF(F31=0,G31,G31*F31) -> 70400000
B32: (유공압품외) | H32: =IF(F32=0,G32,G32*F32) -> 0
H33: =IF(F33=0,G33,G33*F33) -> 0
H34: =IF(F34=0,G34,G34*F34) -> 0
H35: =IF(F35=0,G35,G35*F35) -> 0
H36: =IF(F36=0,G36,G36*F36) -> 0
H37: =IF(F37=0,G37,G37*F37) -> 0
H38: =IF(F38=0,G38,G38*F38) -> 0
H39: =IF(F39=0,G39,G39*F39) -> 0
H40: =IF(F40=0,G40,G40*F40) -> 0
H41: =IF(F41=0,G41,G41*F41) -> 0
H42: =IF(F42=0,G42,G42*F42) -> 0
H43: =IF(F43=0,G43,G43*F43) -> 0
H44: =IF(F44=0,G44,G44*F44) -> 0
H45: =IF(F45=0,G45,G45*F45) -> 0
C46: 기타자재 | E46: ST | H46: =IF(F46=0,G46,G46*F46) -> 0
...

Sheet Sheet1
