Workbook

Sheet 갑지
B1: (현대/기아차 설비협력업체 견적통일양식)
B2: 見 積 書
B4: 현대 위아 貴下 | G4: 협력사명
B5: 견적일자 | D5: 45905 | G5: 대표 : 김 상 조
B6: 견적번호 | D6: NKT25226-0902-C-08 | G6: 주소 : 경남 김해시 서김해산단로 81
B7: 납기 | C7: 입하 | D7: 2025 년 월 일
C8: 최종검수 | D8: 2025 년 월 일 | G8: 전화: 055-322-9420
B9: 견적유효기간 | D9: 제출후 30 일 | G9: Fax: 055-322-9427
B10: 인도장소 | D10: 귀사 지정장소 | G10: 견적담당: 박종훈
B11: 지불조건 | D11: 협의사항 | G11: 연 락 처 : 010-3937-3206
B13: 견적금액 | D13: ="一金"&NUMBERSTRING(H27,1)&"원整" -> 一金이백팔십만칠백이원整 | G13: =H27 -> 2800701.9 | I13: )
B15: 번호 | C15: 상세품목내역 | E15: 견적금액 (천원) | I15: 비 고
E16: 기계부문 | F16: 전기부문 | G16: 관리/이윤 (안전관리비포함) | H16: 합 계
B17: 1 | C17: ='포승 I-Pin 헤어핀 성형기'!C1 -> 포승 I-Pin 헤어핀 성형기 | E17: =IF('단위공사별(집계)'!N7>1,('단위공사별(집계)'!D7+'단위공사별(집계)'!E7+'단위공사별(집계)'!F7+'단위공사별(집계)'!G7+'단위공사별(집계)'!H7+'단위공사별(집계)'!I7)/1000," ") -> 297004.76 | F17: =IF('단위공사별(집계)'!N7>0,'단위공사별(집계)'!K17/1000,"") -> 0 | G17: =IF('단위공사별(집계)'!N7>0,('단위공사별(집계)'!L7+'단위공사별(집계)'!M7)/1000,"") -> 43383.96 | H17: =IF('단위공사별(집계)'!N7>0,'단위공사별(집계)'!N7/1000,"") -> 340388.72
B18: 2 | C18: ='U핀 가정열 설비'!C1 -> U핀 가정열 설비 | E18: =IF('단위공사별(집계)'!N8>1,('단위공사별(집계)'!D8+'단위공사별(집계)'!E8+'단위공사별(집계)'!F8+'단위공사별(집계)'!G8+'단위공사별(집계)'!H8+'단위공사별(집계)'!I8)/1000," ") -> 288140.86 | G18: =IF('단위공사별(집계)'!N8>0,('단위공사별(집계)'!L8+'단위공사별(집계)'!M8)/1000,"") -> 42089.196 | H18: =IF('단위공사별(집계)'!N8>0,'단위공사별(집계)'!N8/1000,"") -> 330230.06
B19: 3 | C19: ='I핀 가정열 설비'!C1 -> I핀 가정열 설비 | E19: =IF('단위공사별(집계)'!N9>1,('단위공사별(집계)'!D9+'단위공사별(집계)'!E9+'단위공사별(집계)'!F9+'단위공사별(집계)'!G9+'단위공사별(집계)'!H9+'단위공사별(집계)'!I9)/1000," ") -> 89182.02 | G19: =IF('단위공사별(집계)'!N9>0,('단위공사별(집계)'!L9+'단위공사별(집계)'!M9)/1000,"") -> 13026.96 | H19: =IF('단위공사별(집계)'!N9>0,'단위공사별(집계)'!N9/1000,"") -> 102208.98
B20: 4 | C20: ='코어 자동화 로딩기'!C1 -> 코어 자동화 로딩기 | E20: =IF('단위공사별(집계)'!N10>1,('단위공사별(집계)'!D10+'단위공사별(집계)'!E10+'단위공사별(집계)'!F10+'단위공사별(집계)'!G10+'단위공사별(집계)'!H10+'단위공사별(집계)'!I10)/1000," ") -> 627886.96 | G20: =IF('단위공사별(집계)'!N10>0,('단위공사별(집계)'!L10+'단위공사별(집계)'!M10)/1000,"") -> 91716.45 | H20: =IF('단위공사별(집계)'!N10>0,'단위공사별(집계)'!N10/1000,"") -> 719603.41
B21: 5 | C21: ='절연지 삽입'!C1 -> 절연지 삽입 | E21: =IF('단위공사별(집계)'!N11>1,('단위공사별(집계)'!D11+'단위공사별(집계)'!E11+'단위공사별(집계)'!F11+'단위공사별(집계)'!G11+'단위공사별(집계)'!H11+'단위공사별(집계)'!I11)/1000," ") -> 154132.22 | G21: =IF('단위공사별(집계)'!N11>0,('단위공사별(집계)'!L11+'단위공사별(집계)'!M11)/1000,"") -> 22514.34 | H21: =IF('단위공사별(집계)'!N11>0,'단위공사별(집계)'!N11/1000,"") -> 176646.56
B22: 6 | C22: =인서팅!C1 -> 인서팅 | E22: =IF('단위공사별(집계)'!N12>1,('단위공사별(집계)'!D12+'단위공사별(집계)'!E12+'단위공사별(집계)'!F12+'단위공사별(집계)'!G12+'단위공사별(집계)'!H12+'단위공사별(집계)'!I12)/1000," ") -> 150449.47 | G22: =IF('단위공사별(집계)'!N12>0,('단위공사별(집계)'!L12+'단위공사별(집계)'!M12)/1000,"") -> 21976.395 | H22: =IF('단위공사별(집계)'!N12>0,'단위공사별(집계)'!N12/1000,"") -> 172425.87
B23: 7 | C23: =확관!C1 -> 확관 | E23: =IF('단위공사별(집계)'!N13>1,('단위공사별(집계)'!D13+'단위공사별(집계)'!E13+'단위공사별(집계)'!F13+'단위공사별(집계)'!G13+'단위공사별(집계)'!H13+'단위공사별(집계)'!I13)/1000," ") -> 147762.38 | G23: =IF('단위공사별(집계)'!N13>0,('단위공사별(집계)'!L13+'단위공사별(집계)'!M13)/1000,"") -> 21583.887 | H23: =IF('단위공사별(집계)'!N13>0,'단위공사별(집계)'!N13/1000,"") -> 169346.27
B24: 8 | C24: =트위스팅!C1 -> 트위스팅 | E24: =IF('단위공사별(집계)'!N14>1,('단위공사별(집계)'!D14+'단위공사별(집계)'!E14+'단위공사별(집계)'!F14+'단위공사별(집계)'!G14+'단위공사별(집계)'!H14+'단위공사별(집계)'!I14)/1000," ") -> 287948.28 | G24: =IF('단위공사별(집계)'!N14>0,('단위공사별(집계)'!L14+'단위공사별(집계)'!M14)/1000,"") -> 42061.065 | H24: =IF('단위공사별(집계)'!N14>0,'단위공사별(집계)'!N14/1000,"") -> 330009.35
B25: 9 | C25: =하부컷팅!C1 -> 하부컷팅 | E25: =IF('단위공사별(집계)'!N15>1,('단위공사별(집계)'!D15+'단위공사별(집계)'!E15+'단위공사별(집계)'!F15+'단위공사별(집계)'!G15+'단위공사별(집계)'!H15+'단위공사별(집계)'!I15)/1000," ") -> 96041.053 | G25: =IF('단위공사별(집계)'!N15>0,('단위공사별(집계)'!L15+'단위공사별(집계)'!M15)/1000,"") -> 14028.87 | H25: =IF('단위공사별(집계)'!N15>0,'단위공사별(집계)'!N15/1000,"") -> 110069.92
B26: 10 | C26: ='납품, 현지설치 및 이벤트 양산대응'!C1 -> 납품, 현지설치 및 이벤트 양산대응 | E26: =IF('단위공사별(집계)'!N16>1,('단위공사별(집계)'!D16+'단위공사별(집계)'!E16+'단위공사별(집계)'!F16+'단위공사별(집계)'!G16+'단위공사별(집계)'!H16+'단위공사별(집계)'!I16)/1000," ") -> 7992.8032 | G26: =IF('단위공사별(집계)'!N16>0,('단위공사별(집계)'!L16+'단위공사별(집계)'!M16)/1000,"") -> 341780 | H26: =IF('단위공사별(집계)'!N16>0,'단위공사별(집계)'!N16/1000,"") -> 349772.8
B27: 견적 합계 | E27: =SUM(E17:E26) -> 2146540.8 | F27: =SUM(F17) -> 0 | G27: =SUM(G17:G26) -> 654161.12 | H27: =SUM(H17:H26) -> 2800701.9
F29: 공개입찰가 (견적時 공란)
B31: 특기사항 | C31: 1. VAT 제외 | F31: 외주계획 업체명 (자작時 공란)
C32: 2. 기본 유틸리티공사 제외 | F32: 설계외주
C33: ='원가항목별(집계)'!I39 -> 0 | F33: 제작외주
F34: 전기외주
F35: 설치외주

Sheet 원가항목별(집계)
C2: A. 원가항목별 견적가 종합(상세견적 첨부)
B4: □ 현대/기아 요구사양과 견적조건 일치여부 CHECK: 1.일치함 2.일부상이(상이내역 첨부참조)
B6: 순번 | C6: 원가구분 | F6: 단위 | G6: 수량 | H6: 단가 | I6: 금 액(원) | J6: 비 고
B7: 1 | C7: 기계 부문 | D7: 자재비 | E7: 철자재(SS.SUS등) | F7: kg | G7: ='포승 I-Pin 헤어핀 성형기'!F47+'U핀 가정열 설비'!F30+'I핀 가정열 설비'!F30+'절연지 삽입'!F42+'코어 자동화 로딩기'!F46+인서팅!F25+확관!F24+트위스팅!F40+하부컷팅!F20+'납품, 현지설치 및 이벤트 양산대응'!F36 -> 0 | I7: ='포승 I-Pin 헤어핀 성형기'!H41+'U핀 가정열 설비'!H24+'I핀 가정열 설비'!H24+'절연지 삽입'!H36+'코어 자동화 로딩기'!H40+인서팅!H19+확관!H18+트위스팅!H34+하부컷팅!H15+'납품, 현지설치 및 이벤트 양산대응'!H24 -> 1060772400 | J7: 加工必要資材
E8: 일반구매품 | F8: 식 | G8: 1 | I8: ='포승 I-Pin 헤어핀 성형기'!H114+'U핀 가정열 설비'!H63+'I핀 가정열 설비'!H58+'절연지 삽입'!H92+'코어 자동화 로딩기'!H107+인서팅!H66+확관!H63+트위스팅!H70+하부컷팅!H46+'납품, 현지설치 및 이벤트 양산대응'!H53 -> 868463420 | J8: 加工不要資材
E9: 외주제작품 | F9: 식 | G9: 1 | I9: ='포승 I-Pin 헤어핀 성형기'!H122+'U핀 가정열 설비'!H71+'I핀 가정열 설비'!H66+'절연지 삽입'!H100+'코어 자동화 로딩기'!H115+인서팅!H74+확관!H71+트위스팅!H78+하부컷팅!H54+'납품, 현지설치 및 이벤트 양산대응'!H61 -> 40000000 | J9: 旣加工SUB資材
E10: 설치/해체 공사 자재 | F10: 식 | G10: 1 | I10: ='포승 I-Pin 헤어핀 성형기'!H47+'U핀 가정열 설비'!H30+'I핀 가정열 설비'!H30+'절연지 삽입'!H42+'코어 자동화 로딩기'!H46+인서팅!H25+확관!H24+트위스팅!H40+하부컷팅!H20+'납품, 현지설치 및 이벤트 양산대응'!H36 -> 410505000 | J10: 시운전 자재 포함
E11: 소계 | I11: =SUM(I7:I10) -> 2379740820
D12: 노무비 | E12: 기존설비 철거 | F12: M/D | G12: ='포승 I-Pin 헤어핀 성형기'!F124+'U핀 가정열 설비'!F73+'I핀 가정열 설비'!F68+'절연지 삽입'!F102+'코어 자동화 로딩기'!F117+인서팅!F76+확관!F73+트위스팅!F80+하부컷팅!F56+'납품, 현지설치 및 이벤트 양산대응'!F63 -> 0 | H12: =IF('포승 I-Pin 헤어핀 성형기'!G124>0,'포승 I-Pin 헤어핀 성형기'!G124,"") | I12: ='포승 I-Pin 헤어핀 성형기'!H124+'U핀 가정열 설비'!H73+'I핀 가정열 설비'!H68+'절연지 삽입'!H102+'코어 자동화 로딩기'!H117+인서팅!H76+확관!H73+트위스팅!H80+하부컷팅!H56+'납품, 현지설치 및 이벤트 양산대응'!H63 -> 0 | J12: 개조공사時
E13: 설계 | F13: M/D | G13: ='포승 I-Pin 헤어핀 성형기'!F125+'U핀 가정열 설비'!F74+'I핀 가정열 설비'!F69+'절연지 삽입'!F103+'코어 자동화 로딩기'!F118+인서팅!F77+확관!F74+트위스팅!F81+하부컷팅!F57+'납품, 현지설치 및 이벤트 양산대응'!F64 -> 0 | H13: =IF('포승 I-Pin 헤어핀 성형기'!G125>0,'포승 I-Pin 헤어핀 성형기'!G125,"") | I13: ='포승 I-Pin 헤어핀 성형기'!H125+'U핀 가정열 설비'!H74+'I핀 가정열 설비'!H69+'절연지 삽입'!H103+'코어 자동화 로딩기'!H118+인서팅!H77+확관!H74+트위스팅!H81+하부컷팅!H57+'납품, 현지설치 및 이벤트 양산대응'!H64 -> 0
E14: 제작(제관,가공) | F14: M/D | G14: ='포승 I-Pin 헤어핀 성형기'!F126+'U핀 가정열 설비'!F75+'I핀 가정열 설비'!F70+'절연지 삽입'!F104+'코어 자동화 로딩기'!F119+인서팅!F78+확관!F75+트위스팅!F82+하부컷팅!F58+'납품, 현지설치 및 이벤트 양산대응'!F65 -> 0 | H14: =IF('포승 I-Pin 헤어핀 성형기'!G126>0,'포승 I-Pin 헤어핀 성형기'!G126,"") | I14: ='포승 I-Pin 헤어핀 성형기'!H126+'U핀 가정열 설비'!H75+'I핀 가정열 설비'!H70+'절연지 삽입'!H104+'코어 자동화 로딩기'!H119+인서팅!H78+확관!H75+트위스팅!H82+하부컷팅!H58+'납품, 현지설치 및 이벤트 양산대응'!H65 -> 0
E15: 조립 | F15: M/D | G15: ='포승 I-Pin 헤어핀 성형기'!F127+'U핀 가정열 설비'!F76+'I핀 가정열 설비'!F71+'절연지 삽입'!F105+'코어 자동화 로딩기'!F120+인서팅!F79+확관!F76+트위스팅!F83+하부컷팅!F59+'납품, 현지설치 및 이벤트 양산대응'!F66 -> 0 | H15: =IF('포승 I-Pin 헤어핀 성형기'!G127>0,'포승 I-Pin 헤어핀 성형기'!G127,"") | I15: ='포승 I-Pin 헤어핀 성형기'!H127+'U핀 가정열 설비'!H76+'I핀 가정열 설비'!H71+'절연지 삽입'!H105+'코어 자동화 로딩기'!H120+인서팅!H79+확관!H76+트위스팅!H83+하부컷팅!H59+'납품, 현지설치 및 이벤트 양산대응'!H66 -> 0 | J15: 정도검사포함
E16: 설치 | F16: M/D | G16: ='포승 I-Pin 헤어핀 성형기'!F128+'U핀 가정열 설비'!F77+'I핀 가정열 설비'!F72+'절연지 삽입'!F106+'코어 자동화 로딩기'!F121+인서팅!F80+확관!F77+트위스팅!F84+하부컷팅!F60+'납품, 현지설치 및 이벤트 양산대응'!F67 -> 0 | H16: =IF('포승 I-Pin 헤어핀 성형기'!G128>0,'포승 I-Pin 헤어핀 성형기'!G128,"") | I16: ='포승 I-Pin 헤어핀 성형기'!H128+'U핀 가정열 설비'!H77+'I핀 가정열 설비'!H72+'절연지 삽입'!H106+'코어 자동화 로딩기'!H121+인서팅!H80+확관!H77+트위스팅!H84+하부컷팅!H60+'납품, 현지설치 및 이벤트 양산대응'!H67 -> 0
E17: 시운전 | F17: M/D | G17: ='포승 I-Pin 헤어핀 성형기'!F129+'U핀 가정열 설비'!F78+'I핀 가정열 설비'!F73+'절연지 삽입'!F107+'코어 자동화 로딩기'!F122+인서팅!F81+확관!F78+트위스팅!F85+하부컷팅!F61+'납품, 현지설치 및 이벤트 양산대응'!F68 -> 0 | H17: =IF('포승 I-Pin 헤어핀 성형기'!G129>0,'포승 I-Pin 헤어핀 성형기'!G129,"") | I17: ='포승 I-Pin 헤어핀 성형기'!H129+'U핀 가정열 설비'!H78+'I핀 가정열 설비'!H73+'절연지 삽입'!H107+'코어 자동화 로딩기'!H122+인서팅!H81+확관!H78+트위스팅!H85+하부컷팅!H61+'납품, 현지설치 및 이벤트 양산대응'!H68 -> 0
E18: 양산대응 | F18: M/D | G18: ='포승 I-Pin 헤어핀 성형기'!F130+'U핀 가정열 설비'!F79+'I핀 가정열 설비'!F74+'절연지 삽입'!F108+'코어 자동화 로딩기'!F123+인서팅!F82+확관!F79+트위스팅!F86+하부컷팅!F62+'납품, 현지설치 및 이벤트 양산대응'!F69 -> 0 | H18: =IF('포승 I-Pin 헤어핀 성형기'!G130>0,'포승 I-Pin 헤어핀 성형기'!G130,"") | I18: ='포승 I-Pin 헤어핀 성형기'!H130+'U핀 가정열 설비'!H79+'I핀 가정열 설비'!H74+'절연지 삽입'!H108+'코어 자동화 로딩기'!H123+인서팅!H82+확관!H79+트위스팅!H86+하부컷팅!H62+'납품, 현지설치 및 이벤트 양산대응'!H69 -> 0
E19: 도장 | F19: M/D | G19: ='포승 I-Pin 헤어핀 성형기'!F131+'U핀 가정열 설비'!F80+'I핀 가정열 설비'!F75+'절연지 삽입'!F109+'코어 자동화 로딩기'!F124+인서팅!F83+확관!F80+트위스팅!F87+하부컷팅!F63+'납품, 현지설치 및 이벤트 양산대응'!F70 -> 0 | H19: =IF('포승 I-Pin 헤어핀 성형기'!G131>0,'포승 I-Pin 헤어핀 성형기'!G131,"") | I19: ='포승 I-Pin 헤어핀 성형기'!H131+'U핀 가정열 설비'!H80+'I핀 가정열 설비'!H75+'절연지 삽입'!H109+'코어 자동화 로딩기'!H124+인서팅!H83+확관!H80+트위스팅!H87+하부컷팅!H63+'납품, 현지설치 및 이벤트 양산대응'!H70 -> 0
E20: 소계 | I20: =SUM(I12:I19) -> 0
D21: 일반관리 및 이윤 | I21: ='포승 I-Pin 헤어핀 성형기'!H134+'포승 I-Pin 헤어핀 성형기'!H135+'U핀 가정열 설비'!H83+'U핀 가정열 설비'!H84+'I핀 가정열 설비'!H78+'I핀 가정열 설비'!H79+'절연지 삽입'!H112+'절연지 삽입'!H113+'코어 자동화 로딩기'!H127+'코어 자동화 로딩기'!H128+인서팅!H85+인서팅!H86+확관!H82+확관!H83+트위스팅!H90+트위스팅!H91+하부컷팅!H66+하부컷팅!H67+'납품, 현지설치 및 이벤트 양산대응'!H73+'납품, 현지설치 및 이벤트 양산대응'!H74 -> 356961123
E22: 기계 소계 | I22: =I20+I11+I21 -> 2736701943
B23: 2 | C23: 전기 부문 | D23: 자재비 | E23: 기계/전기자재 | F23: 식 | G23: 1 | I23: =전기!H55-I24 -> 0
E24: 설치/해체 공사 자재 | F24: 식 | G24: 1 | I24: =전기!H16 -> 0 | J24: 시운전 자재 포함
D25: 노무비 | E25: 철거(개조시) | F25: M/D | G25: =전기!F56 -> 0 | H25: =IF(전기!G56>0,전기!G56,"") | I25: =전기!H56 -> 0
E26: 설계,프로그램 | F26: M/D | G26: =전기!F57 -> 0 | H26: =IF(전기!G57>0,전기!G57,"") | I26: =전기!H57 -> 0
E27: 제작 | F27: M/D | G27: =전기!F58 -> 0 | H27: =IF(전기!G58>0,전기!G58,"") | I27: =전기!H58 -> 0
E28: 조립 | F28: M/D | G28: =전기!F59 -> 0 | H28: =IF(전기!G59>0,전기!G59,"") | I28: =전기!H59 -> 0
E29: 설치 | F29: M/D | G29: =전기!F60 -> 0 | H29: =IF(전기!G60>0,전기!G60,"") | I29: =전기!H60 -> 0
E30: 시운전 | F30: M/D | G30: =전기!F61 -> 0 | H30: =IF(전기!G61>0,전기!G61,"") | I30: =전기!H61 -> 0
E31: 양산대응 | F31: M/D | G31: =전기!F62 -> 0 | H31: =IF(전기!G62>0,전기!G62,"") | I31: =전기!H62 -> 0
E32: 소계 | I32: =SUM(I25:I31) -> 0
D33: 일반관리 및 이윤 | I33: =전기!H65+전기!H66 -> 0
E34: 전기 소계 | I34: =I32+I23+I33+I24 -> 0
B35: 3 | C35: 자재비 합계 | I35: =I23+I11+I24 -> 2379740820
C36: 노무비 합계 | I36: =I32+I20 -> 0
C37: 중간 합계 | I37: =I36+I35 -> 2379740820
B38: 4 | C38: 포장,운송 및 중장비 사용료 | I38: 64000000
B39: 5 | C39: 표준안전관리비 | F39: 설치/철거/수리금액 기준 | J39: =I30+I29+I25+I24+I17+I16+I12+I10 -> 410505000
B40: 6 | C40: 일반관리비 | I40: =전기!H65+'포승 I-Pin 헤어핀 성형기'!H134+'U핀 가정열 설비'!H83+'I핀 가정열 설비'!H78+'절연지 삽입'!H112+'코어 자동화 로딩기'!H127+인서팅!H85+확관!H82+트위스팅!H90+하부컷팅!H66+'납품, 현지설치 및 이벤트 양산대응'!H73 -> 118987041
B41: 7 | C41: 이 윤 | I41: =전기!H66+'포승 I-Pin 헤어핀 성형기'!H135+'U핀 가정열 설비'!H84+'I핀 가정열 설비'!H79+'절연지 삽입'!H113+'코어 자동화 로딩기'!H128+인서팅!H86+확관!H83+트위스팅!H91+하부컷팅!H67+'납품, 현지설치 및 이벤트 양산대응'!H74 -> 237974082
C42: 합 계 | F42: 3~7항 합계 | I42: =I22+I34+I38+I39 -> 2800701943
B43: 주1. 표준안전관리비:(설치/철거/시운전 공사 관련 금액)의
...

Sheet 단위공사별(집계)
A2: B. 단위장비별 견적가 종합(상세견적 첨부)
N3: 단위:원
I5: 포장/운송 | L5: 표준안전 | M5: 일반관리비
A6: 순번 | B6: 단위장비명 | C6: 수량 | D6: 자재비 | E6: 철거 | F6: 제작 | G6: 설치/시운전 | H6: 양산대응 | I6: 중장비사용 | J6: 기계소계 | K6: 전기소계 | L6: 관리비 | M6: 이윤 | N6: 합 계 | O6: 비 고
A7: =IF(B7>0,1,"") -> 1 | B7: ='포승 I-Pin 헤어핀 성형기'!C$1 -> 포승 I-Pin 헤어핀 성형기 | C7: 1식 | D7: ='포승 I-Pin 헤어핀 성형기'!H123 -> 289226400 | E7: ='포승 I-Pin 헤어핀 성형기'!H124 -> 0 | F7: ='포승 I-Pin 헤어핀 성형기'!H125+'포승 I-Pin 헤어핀 성형기'!H126+'포승 I-Pin 헤어핀 성형기'!H127+'포승 I-Pin 헤어핀 성형기'!H131 -> 0 | G7: ='포승 I-Pin 헤어핀 성형기'!H128+'포승 I-Pin 헤어핀 성형기'!H129 -> 0 | H7: ='포승 I-Pin 헤어핀 성형기'!H130 -> 0 | I7: =IF($B7>0,'원가항목별(집계)'!I$38*$P7/$P$17,0) -> 7778363.7 | J7: =SUM(D7:I7) -> 2.9700476e+08 | K7: =IF(B7>0,'원가항목별(집계)'!I$34*P7/P$17,0) -> 0 | M7: ='포승 I-Pin 헤어핀 성형기'!H134+'포승 I-Pin 헤어핀 성형기'!H135 -> 43383960 | N7: =SUM(J7:M7) -> 3.4038872e+08 | P7: =D7+E7+F7+G7+H7+M7 -> 332610360
A8: =IF(B8>0,A7+1,"") -> 2 | B8: ='U핀 가정열 설비'!C$1 -> U핀 가정열 설비 | C8: 1식 | D8: ='U핀 가정열 설비'!H72 -> 280594640 | E8: ='U핀 가정열 설비'!H73 -> 0 | F8: ='U핀 가정열 설비'!H74+'U핀 가정열 설비'!H75+'U핀 가정열 설비'!H76+'U핀 가정열 설비'!H80 -> 0 | G8: ='U핀 가정열 설비'!H77+'U핀 가정열 설비'!H78 -> 0 | H8: ='U핀 가정열 설비'!H79 -> 0 | I8: =IF($B8>0,'원가항목별(집계)'!I$38*$P8/$P$17,0) -> 7546223.9 | J8: =SUM(D8:I8) -> 2.8814086e+08 | K8: =IF(B8>0,'원가항목별(집계)'!I$34*P8/P$17,0) -> 0 | M8: ='U핀 가정열 설비'!H83+'U핀 가정열 설비'!H84 -> 42089196 | N8: =SUM(J8:M8) -> 3.3023006e+08 | P8: =D8+E8+F8+G8+H8+M8 -> 322683836
A9: =IF(B9>0,A8+1,"") -> 3 | B9: ='I핀 가정열 설비'!C$1 -> I핀 가정열 설비 | C9: 1식 | D9: ='I핀 가정열 설비'!H67 -> 86846400 | E9: ='I핀 가정열 설비'!H68 -> 0 | F9: ='I핀 가정열 설비'!H69+'I핀 가정열 설비'!H70+'I핀 가정열 설비'!H71+'I핀 가정열 설비'!H75 -> 0 | G9: ='I핀 가정열 설비'!H72+'I핀 가정열 설비'!H73 -> 0 | H9: ='I핀 가정열 설비'!H74 -> 0 | I9: =IF($B9>0,'원가항목별(집계)'!I$38*$P9/$P$17,0) -> 2335619.7 | J9: =SUM(D9:I9) -> 89182020 | K9: =IF(B9>0,'원가항목별(집계)'!I$34*P9/P$17,0) -> 0 | M9: ='I핀 가정열 설비'!H78+'I핀 가정열 설비'!H79 -> 13026960 | N9: =SUM(J9:M9) -> 1.0220898e+08 | P9: =D9+E9+F9+G9+H9+M9 -> 99873360
A10: =IF(B10>0,A9+1,"") -> 4 | B10: ='코어 자동화 로딩기'!C1 -> 코어 자동화 로딩기 | C10: 1식 | D10: ='코어 자동화 로딩기'!H116 -> 611443000 | E10: ='코어 자동화 로딩기'!H117 -> 0 | F10: ='코어 자동화 로딩기'!H118+'코어 자동화 로딩기'!H119+'코어 자동화 로딩기'!H120+'코어 자동화 로딩기'!H124 -> 0 | G10: ='코어 자동화 로딩기'!H121+'코어 자동화 로딩기'!H122 -> 0 | H10: ='코어 자동화 로딩기'!H123 -> 0 | I10: =IF($B10>0,'원가항목별(집계)'!I$38*$P10/$P$17,0) -> 16443955 | J10: =SUM(D10:I10) -> 6.2788696e+08 | K10: =IF(B10>0,'원가항목별(집계)'!I$34*P10/P$17,0) -> 0 | M10: ='코어 자동화 로딩기'!H127+'코어 자동화 로딩기'!H128 -> 91716450 | N10: =SUM(J10:M10) -> 7.1960341e+08 | P10: =D10+E10+F10+G10+H10+M10 -> 703159450
A11: =IF(B11>0,A10+1,"") -> 5 | B11: ='절연지 삽입'!C1 -> 절연지 삽입 | C11: 1식 | D11: ='절연지 삽입'!H101 -> 150095600 | E11: ='절연지 삽입'!H102 -> 0 | F11: ='절연지 삽입'!H103+'절연지 삽입'!H104+'절연지 삽입'!H105+'절연지 삽입'!H109 -> 0 | G11: ='절연지 삽입'!H106+'절연지 삽입'!H107 -> 0 | H11: ='절연지 삽입'!H108 -> 0 | I11: =IF($B11>0,'원가항목별(집계)'!I$38*$P11/$P$17,0) -> 4036623.8 | J11: =SUM(D11:I11) -> 1.5413222e+08 | K11: =IF(B11>0,'원가항목별(집계)'!I$34*P11/P$17,0) -> 0 | M11: ='절연지 삽입'!H112+'절연지 삽입'!H113 -> 22514340 | N11: =SUM(J11:M11) -> 1.7664656e+08 | P11: =D11+E11+F11+G11+H11+M11 -> 172609940
A12: =IF(B12>0,A11+1,"") -> 6 | B12: =인서팅!C$1 -> 인서팅 | C12: 1식 | D12: =인서팅!H75 -> 146509300 | E12: =인서팅!H76 -> 0 | F12: =인서팅!H77+인서팅!H78+인서팅!H79+인서팅!H83 -> 0 | G12: =인서팅!H80+인서팅!H81 -> 0 | H12: =인서팅!H82 -> 0 | I12: =IF($B12>0,'원가항목별(집계)'!I$38*$P12/$P$17,0) -> 3940175 | J12: =SUM(D12:I12) -> 1.5044947e+08 | K12: =IF(B12>0,'원가항목별(집계)'!I$34*P12/P$17,0) -> 0 | M12: =인서팅!H85+인서팅!H86 -> 21976395 | N12: =SUM(J12:M12) -> 1.7242587e+08 | P12: =D12+E12+F12+G12+H12+M12 -> 168485695
A13: =IF(B13>0,A12+1,"") -> 7 | B13: =확관!C$1 -> 확관 | C13: 1식 | D13: =확관!H72 -> 143892580 | E13: =확관!H73 -> 0 | F13: =확관!H74+확관!H75+확관!H76+확관!H80 -> 0 | G13: =확관!H77+확관!H78 -> 0 | H13: =확관!H79 -> 0 | I13: =IF($B13>0,'원가항목별(집계)'!I$38*$P13/$P$17,0) -> 3869801.7 | J13: =SUM(D13:I13) -> 1.4776238e+08 | K13: =IF(B13>0,'원가항목별(집계)'!I$34*P13/P$17,0) -> 0 | M13: =확관!H82+확관!H83 -> 21583887 | N13: =SUM(J13:M13) -> 1.6934627e+08 | P13: =D13+E13+F13+G13+H13+M13 -> 165476467
A14: =IF(B14>0,A13+1,"") -> 8 | B14: =트위스팅!C$1 -> 트위스팅 | C14: 1식 | D14: =트위스팅!H79 -> 280407100 | E14: =트위스팅!H80 -> 0 | F14: =트위스팅!H81+트위스팅!H82+트위스팅!H83+트위스팅!H87 -> 0 | G14: =트위스팅!H84+트위스팅!H85 -> 0 | H14: =트위스팅!H86 -> 0 | I14: =IF($B14>0,'원가항목별(집계)'!I$38*$P14/$P$17,0) -> 7541180.2 | J14: =SUM(D14:I14) -> 2.8794828e+08 | K14: =IF(B14>0,'원가항목별(집계)'!I$34*P14/P$17,0) -> 0 | M14: =트위스팅!H90+트위스팅!H91 -> 42061065 | N14: =SUM(J14:M14) -> 3.3000935e+08 | P14: =D14+E14+F14+G14+H14+M14 -> 322468165
A15: =IF(B15>0,A14+1,"") -> 9 | B15: =하부컷팅!C$1 -> 하부컷팅 | C15: 1식 | D15: =하부컷팅!H55 -> 93525800 | E15: =하부컷팅!H56 -> 0 | F15: =하부컷팅!H57+하부컷팅!H58+하부컷팅!H59+하부컷팅!H60 -> 0 | G15: =하부컷팅!H61+하부컷팅!H72 -> 0 | H15: =하부컷팅!H63 -> 0 | I15: =IF($B15>0,'원가항목별(집계)'!I$38*$P15/$P$17,0) -> 2515253.4 | J15: =SUM(D15:I15) -> 96041053 | K15: =IF(B15>0,'원가항목별(집계)'!I$34*P15/P$17,0) -> 0 | M15: =하부컷팅!H66+하부컷팅!H67 -> 14028870 | N15: =SUM(J15:M15) -> 1.1006992e+08 | P15: =D15+E15+F15+G15+H15+M15 -> 107554670
A16: =IF(B16>0,A15+1,"") -> 10 | B16: ='납품, 현지설치 및 이벤트 양산대응'!C$1 -> 납품, 현지설치 및 이벤트 양산대응 | C16: 1식 | D16: ='납품, 현지설치 및 이벤트 양산대응'!H64 -> 0 | E16: ='납품, 현지설치 및 이벤트 양산대응'!H65 -> 0 | F16: ='납품, 현지설치 및 이벤트 양산대응'!H66+'납품, 현지설치 및 이벤트 양산대응'!H67+'납품, 현지설치 및 이벤트 양산대응'!H68+'납품, 현지설치 및 이벤트 양산대응'!H72 -> 0 | G16: ='납품, 현지설치 및 이벤트 양산대응'!H69+'납품, 현지설치 및 이벤트 양산대응'!H70 -> 0 | H16: ='납품, 현지설치 및 이벤트 양산대응'!H71 -> 0 | I16: =IF($B16>0,'원가항목별(집계)'!I$38*$P16/$P$17,0) -> 7992803.2 | J16: =SUM(D16:I16) -> 7992803.2 | K16: =IF(B16>0,'원가항목별(집계)'!I$34*P16/P$17,0) -> 0 | M16: ='납품, 현지설치 및 이벤트 양산대응'!H75+'납품, 현지설치 및 이벤트 양산대응'!H76 -> 341780000 | N16: =SUM(J16:M16) -> 3.497728e+08 | P16: =D16+E16+F16+G16+H16+M16 -> 341780000
A17: 합 계 | D17: =SUM(D7:D16) -> 2082540820 | E17: =SUM(E7:E16) -> 0 | F17: =SUM(F7:F16) -> 0 | G17: =SUM(G7:G16) -> 0 | H17: =SUM(H7:H16) -> 0 | I17: =SUM(I7:I16) -> 64000000 | J17: =SUM(D17:I17) -> 2146540820 | K17: =SUM(K7:K16) -> 0 | L17: =SUM(L7:L16) -> 0 | M17: =SUM(M7:M16) -> 654161123 | N17: =SUM(N7:N16) -> 2800701943 | P17: =SUM(P7:P16) -> 2736701943
D18: =IF(D17=0,"",D17/$N17) -> 0.74357817 | E18: =IF(E17=0,"",E17/$N17) | F18: =IF(F17=0,"",F17/$N17) | G18: =IF(G17=0,"",G17/$N17) | H18: =IF(H17=0,"",H17/$N17) | I18: =IF(I17=0,"",I17/$N17) -> 0.022851414 | J18: =IF(J17=0,"",J17/$N17) -> 0.76642958 | K18: =IF(K17=0,"",K17/$N17) | ... N18: =IF(N17=0,"",N17/$N17) -> 1
A19: 주) 전기비용은 턴키장비의 공통비용으로서 총 전기비용을 단위장비별 기계금액의 비율에 따라 배분함
N20: =IF('원가항목별(집계)'!I42='단위공사별(집계)'!N17,"","DATA오류입니다!")

Sheet 전기
B1: □ 전기부문: | I1: (첨부)
A2: 구분 | C2: 품 명 | D2: 규격 | E2: 단위 | F2: 수량 | G2: 단가(원) | H2: 금액(원) | I2: 原MAKER
A3: 자 재 비 | B3: 철자재 | H3: =IF(F3=0,G3,G3*F3) -> 0
H4: =IF(F4=0,G4,G4*F4) -> 0
H5: =IF(F5=0,G5,G5*F5) -> 0
H6: =IF(F6=0,G6,G6*F6) -> 0
H7: =IF(F7=0,G7,G7*F7) -> 0
H8: =IF(F8=0,G8,G8*F8) -> 0
H9: =SUM(H3:H8) -> 0
B10: 설치/해체/ | H10: =IF(F10=0,G10,G10*F10) -> 0
B11: 시운전 공사 | H11: =IF(F11=0,G11,G11*F11) -> 0
B12: 자재 | H12: =IF(F12=0,G12,G12*F12) -> 0
H13: =IF(F13=0,G13,G13*F13) -> 0
H14: =IF(F14=0,G14,G14*F14) -> 0
C15: 기타자재 | E15: ST | H15: =IF(F15=0,G15,G15*F15) -> 0
H16: =SUM(H10:H15) -> 0
B17: 전기자재 | H17: =IF(F17=0,G17,G17*F17) -> 0
H18: =IF(F18=0,G18,G18*F18) -> 0
H19: =IF(F19=0,G19,G19*F19) -> 0
H20: =IF(F20=0,G20,G20*F20) -> 0
H21: =IF(F21=0,G21,G21*F21) -> 0
H22: =IF(F22=0,G22,G22*F22) -> 0
H23: =IF(F23=0,G23,G23*F23) -> 0
H24: =IF(F24=0,G24,G24*F24) -> 0
H25: =IF(F25=0,G25,G25*F25) -> 0
H26: =IF(F26=0,G26,G26*F26) -> 0
H27: =IF(F27=0,G27,G27*F27) -> 0
H28: =IF(F28=0,G28,G28*F28) -> 0
H29: =IF(F29=0,G29,G29*F29) -> 0
... H53: =IF(F53=0,G53,G53*F53) -> 0
H54: =SUM(H17:H53) -> 0
B55: 자재비 소계 | H55: =SUM(H54,H9,H16) -> 0
A56: 노 무 비 | B56: 기존설비 철거 | E56: M/D | H56: =F56*G56 -> 0
B57: 작화. PROGRAM 비 | E57: M/D | H57: =F57*G57 -> 0
B58: 전기 제작 | E58: M/D | H58: =F58*G58 -> 0
B59: 전기 조립 | E59: M/D | H59: =F59*G59 -> 0
B60: 전기 설치 | E60: M/D | H60: =F60*G60 -> 0
B61: 전기 시운전 | E61: M/D | H61: =F61*G61 -> 0
B62: 전기 양산대응 | E62: M/D | H62: =F62*G62 -> 0
B63: 노무비 소계 | H63: =SUM(H56:H62) -> 0
...

Sheet 포승 I-Pin 헤어핀 성형기
B1: □ 단위공사명(전기제외): | C1: 포승 I-Pin 헤어핀 성형기 | I1: (첨부)
A2: 구분 | C2: 품 명 | D2: 규격 | E2: 단위 | F2: 수량 | G2: 단가(원) | H2: 금액(원) | I2: 原MAKER
A3: 자 재 비 | B3: 철자재 | C3: FRAME Unit | E3: 식 | F3: 1 | G3: 4824000 | H3: =F3*G3 -> 4824000
C4: Bracket Unit | E4: 식 | F4: 1 | G4: 2592000 | H4: =F4*G4 -> 2592000
C5: REELASSYUnit | E5: 식 | F5: 1 | G5: 7128000 | H5: =F5*G5 -> 7128000
C6: BOBBINEXCHANGE Unit | E6: 식 | F6: 1 | G6: 2304000 | H6: =F6*G6 -> 2304000
C7: TENSIONERASSY Unit | E7: 식 | F7: 1 | G7: 1152000 | H7: =F7*G7 -> 1152000
C8: COVERASSY Unit | E8: 식 | F8: 1 | G8: 2664000 | H8: =F8*G8 -> 2664000
C9: SUBFEEDER Unit | E9: 식 | F9: 1 | G9: 1296000 | H9: =F9*G9 -> 1296000
C10: DOUBLEWIRESTRAIGHT Unit | E10: 식 | F10: 1 | G10: 1008000 | H10: =F10*G10 -> 1008000
C11: WIRESTRAIGHTENER Unit | E11: 식 | F11: 1 | G11: 2952000 | H11: =F11*G11 -> 2952000
C12: WIRESTRAIGHTENER Unit | E12: 식 | F12: 1 | G12: 2160000 | H12: =F12*G12 -> 2160000
C13: VER.DECOATING Unit | E13: 식 | F13: 1 | G13: 4032000 | H13: =F13*G13 -> 4032000
C14: HOR.DECOATING Unit | E14: 식 | F14: 1 | G14: 3024000 | H14: =F14*G14 -> 3024000
C15: MAINFEEDER Unit | E15: 식 | F15: 2 | G15: 2808000 | H15: =F15*G15 -> 5616000
... C38: OP | E38: 식 | F38: 1 | G38: 720000 | H38: =F38*G38 -> 720000
C39: DUCT ASSY Part | E39: 식 | F39: 1 | G39: 4320000 | H39: 4320000
H40: =IF(F40=0,G40,G40*F40) -> 0
H41: =SUM(H3:H40) -> 146124000
B42: 설치/해체/시운전 | C42: 기계 설계 | E42: M/D | F42: 7 | G42: 300000 | H42: =IF(F42=0,G42,G42*F42) -> 2100000
B43: 공사 관련 자재 | C43: 기계 조립 | E43: M/D | F43: 18 | G43: 300000 | H43: =IF(F43=0,G43,G43*F43) -> 5400000
C44: 기계 시운전 | E44: M/D | F44: 25 | G44: 300000 | H44: =IF(F44=0,G44,G44*F44) -> 7500000
H45: =IF(F45=0,G45,G45*F45) -> 0
H46: =IF(F46=0,G46,G46*F46) -> 0
H47: =SUM(H42:H46) -> 15000000
B48: 구매품 | C48: REEL ASSY Air Part | E48: 식 | F48: 1 | G48: 360000 | H48: =IF(F48=0,G48,G48*F48) -> 360000 | I48: SMC
B49: (유공압품외) | C49: BOBBIN EXCHANGE Air Part | E49: 식 | F49: 1 | G49: 3600000 | H49: =IF(F49=0,G49,G49*F49) -> 3600000 | I49: SMC
C50: TENSIONER ASSY Air Part | E50: 식 | F50: 1 | G50: 1260000 | H50: =IF(F50=0,G50,G50*F50) -> 1260000 | I50: SMC
C51: SUB FEEDER Air Part | E51: 식 | F51: 1 | G51: 324000 | H51: =IF(F51=0,G51,G51*F51) -> 324000 | I51: SMC
C52: WIRE STRAIGHTENER Part 1 Air Part | E52: 식 | F52: 1 | G52: 576000 | H52: =IF(F52=0,G52,G52*F52) -> 576000 | I52: SMC
C53: WIRE STRAIGHTENER Part 2 Air Part | E53: 식 | F53: 1 | G53: 648000 | H53: =IF(F53=0,G53,G53*F53) -> 648000 | I53: SMC
C54: STOPPER Air Part | E54: 식 | F54: 1 | G54: 108000 | H54: =IF(F54=0,G54,G54*F54) -> 108000 | I54: SMC
C55: Drive Body & Air | E55: 식 | F55: 3 | G55: 2664000 | H55: =IF(F55=0,G55,G55*F55) -> 7992000 | I55: Festo/SMC
C56: BENDING Air Part | E56: 식 | F56: 1 | G56: 396000 | H56: =IF(F56=0,G56,G56*F56) -> 396000 | I56: SMC
C57: 헤어핀 Chute Air Part | E57: 식 | F57: 1 | G57: 1728000 | H57: =IF(F57=0,G57,G57*F57) -> 1728000 | I57: SMC
C58: 적재 대차 Guide & RFID Air Part | E58: 식 | F58: 1 | G58: 1296000 | H58: =IF(F58=0,G58,G58*F58) -> 1296000 | I58: SMC
C59: Main Air & Main folder | E59: 식 | F59: 1 | G59: 4176000 | H59: =IF(F59=0,G59,G59*F59) -> 4176000 | I59: SMC 외
C60: Air | E60: 식 | F60: 1 | G60: 1368000 | H60: =IF(F60=0,G60,G60*F60) -> 1368000 | I60: Festo
C61: Servo Motor | E61: 식 | F61: 22 | H61: 사급 | I61: Mitsubishi
C62: Induction Motor | E62: 식 | F62: 1 | G62: 180000 | H62: =IF(F62=0,G62,G62*F62) -> 180000 | I62: INA ORIENTAL
...

Sheet U핀 가정열 설비
B1: □ 단위공사명(전기제외): | C1: U핀 가정열 설비 | I1: (첨부)
A2: 구분 | C2: 품 명 | D2: 규격 | E2: 단위 | F2: 수량 | G2: 단가(원) | H2: 금액(원) | I2: 原MAKER
A3: 자 재 비 | B3: 철자재 | C3: Main Frame Unit | E3: 식 | F3: 1 | G3: 2880000 | H3: =IF(F3=0,G3,G3*F3) -> 2880000
C4: Main Base Unit | E4: 식 | F4: 1 | G4: 3960000 | H4: =IF(F4=0,G4,G4*F4) -> 3960000
C5: 상부 Cover Unit | E5: 식 | F5: 1 | G5: 7200000 | H5: =IF(F5=0,G5,G5*F5) -> 7200000
C6: RFID B/K Unit | E6: 식 | F6: 10 | G6: 216000 | H6: =IF(F6=0,G6,G6*F6) -> 2160000
C7: 매거진 로딩 Unit | E7: 식 | F7: 8 | G7: 1440000 | H7: =IF(F7=0,G7,G7*F7) -> 11520000
C8: 매거진 Loader Unit | E8: 식 | F8: 1 | G8: 4320000 | H8: =IF(F8=0,G8,G8*F8) -> 4320000
C9: 매거진 Chuck Unit | E9: 식 | F9: 1 | G9: 1152000 | H9: =IF(F9=0,G9,G9*F9) -> 1152000
C10: 매거진 Tilting Unit | E10: 식 | F10: 2 | G10: 2880000 | H10: =IF(F10=0,G10,G10*F10) -> 5760000
C11: X-Y Shuttle Assy Unit | E11: 식 | F11: 2 | G11: 1944000 | H11: =IF(F11=0,G11,G11*F11) -> 3888000
C12: 삽입 헤드 Assy Unit | E12: 식 | F12: 2 | G12: 7560000 | H12: =IF(F12=0,G12,G12*F12) -> 15120000
C13: POP UP & Roation Unit | E13: 식 | F13: 1 | G13: 2880000 | H13: =IF(F13=0,G13,G13*F13) -> 2880000
C14: Hair pin 조립 Sub Unit | E14: 식 | F14: 1 | G14: 1152000 | H14: =IF(F14=0,G14,G14*F14) -> 1152000
C15: O/P B/K Unit | E15: 식 | F15: 1 | G15: 518400 | H15: =IF(F15=0,G15,G15*F15) -> 518400
... C18: U핀 매거진 | E18: set | F18: 88 | G18: 1080000 | H18: =IF(F18=0,G18,G18*F18) -> 95040000
H19: =IF(F19=0,G19,G19*F19) -> 0
H20: =IF(F20=0,G20,G20*F20) -> 0
H21: =IF(F21=0,G21,G21*F21) -> 0
H22: =IF(F22=0,G22,G22*F22) -> 0
H23: =IF(F23=0,G23,G23*F23) -> 0
H24: =SUM(H3:H23) -> 202910400
B25: 설치/해체/시운전 | C25: 기계 설계 | F25: 9 | G25: 300000 | H25: =IF(F25=0,G25,G25*F25) -> 2700000
B26: 공사 관련 자재 | C26: 기계 조립 | F26: 15 | G26: 300000 | H26: =IF(F26=0,G26,G26*F26) -> 4500000
C27: 기계 시운전 | F27: 18 | G27: 300000 | H27: =IF(F27=0,G27,G27*F27) -> 5400000
H30: =SUM(H25:H29) -> 12600000
B31: 구매품 | C31: Air Part | E31: 식 | F31: 6 | G31: 918000 | H31: =IF(F31=0,G31,G31*F31) -> 5508000 | I31: SMC
B32: (유공압품외) | C32: Main Air & Main folder | E32: 식 | F32: 1 | G32: 2160000 | H32: =IF(F32=0,G32,G32*F32) -> 2160000 | I32: SMC
C33: RFID | E33: 식 | F33: 10 | G33: 518400 | H33: =IF(F33=0,G33,G33*F33) -> 5184000 | I33: PEPPERL
C34: RFID TAG | E34: 식 | F34: 108 | G34: 17280 | H34: =IF(F34=0,G34,G34*F34) -> 1866240 | I34: PEPPERL
C35: 직교(X,Y,Z,G) Robot | E35: 식 | F35: 1 | G35: 18720000 | H35: =IF(F35=0,G35,G35*F35) -> 18720000 | I35: Robostar
C36: Sensor Part | E36: 식 | F36: 1 | G36: 540000 | H36: =IF(F36=0,G36,G36*F36) -> 540000 | I36: Omron
C37: Sensor Part | E37: 식 | F37: 2 | G37: 864000 | H37: =IF(F37=0,G37,G37*F37) -> 1728000 | I37: Omron
C38: 감속기 | E38: 식 | F38: 2 | G38: 540000 | H38: =IF(F38=0,G38,G38*F38) -> 1080000 | I38: Apex
C39: LM, Ball Screw 외 | E39: 식 | F39: 2 | G39: 684000 | H39: =IF(F39=0,G39,G39*F39) -> 1368000 | I39: THK
C40: E-Gripper | E40: 식 | F40: 2 | G40: 1404000 | H40: =IF(F40=0,G40,G40*F40) -> 2808000 | I40: SMC
C41: LM, Ball Screw 외 | E41: 식 | F41: 2 | G41: 432000 | H41: =IF(F41=0,G41,G41*F41) -> 864000 | I41: THK
C42: 감속기 | E42: 식 | F42: 1 | G42: 612000 | H42: =IF(F42=0,G42,G42*F42) -> 612000 | I42: Apex
C43: LM, Ball Bush 외 | E43: 식 | F43: 1 | G43: 432000 | H43: =IF(F43=0,G43,G43*F43) -> 432000 | I43: THK
C44: Sensor Part | E44: 식 | F44: 1 | G44: 432000 | H44: =IF(F44=0,G44,G44*F44) -> 432000 | I44: Omron
...

Sheet I핀 가정열 설비
B1: □ 단위공사명(전기제외): | C1: I핀 가정열 설비 | I1: (첨부)
A2: 구분 | C2: 품 명 | D2: 규격 | E2: 단위 | F2: 수량 | G2: 단가(원) | H2: 금액(원) | I2: 原MAKER
A3: 자 재 비 | B3: 철자재 | C3: Main Frame Unit | E3: 식 | F3: 1 | G3: 1440000 | H3: =IF(F3=0,G3,G3*F3) -> 1440000
C4: Main Base Unit | E4: 식 | F4: 1 | G4: 1440000 | H4: =IF(F4=0,G4,G4*F4) -> 1440000
C5: POP UP & Roation Unit | E5: 식 | F5: 1 | G5: 2880000 | H5: =IF(F5=0,G5,G5*F5) -> 2880000
C6: Hair pin 조립 Sub Unit | E6: 식 | F6: 1 | G6: 1152000 | H6: =IF(F6=0,G6,G6*F6) -> 1152000
C7: 매거진 Feeding Unit | E7: 식 | F7: 2 | G7: 1944000 | H7: =IF(F7=0,G7,G7*F7) -> 3888000
C8: RFID B/K Unit | E8: 식 | F8: 2 | G8: 216000 | H8: =IF(F8=0,G8,G8*F8) -> 432000
C9: Main Air & Main folder | E9: 식 | F9: 1 | G9: 1440000 | H9: =IF(F9=0,G9,G9*F9) -> 1440000
C10: I핀 매거진 | E10: set | F10: 10 | G10: 1080000 | H10: =IF(F10=0,G10,G10*F10) -> 10800000
C11: 대차 | E11: set | F11: 50 | G11: 864000 | H11: =IF(F11=0,G11,G11*F11) -> 43200000
C12: 수작업 공구 Part | E12: 식 | F12: 1 | G12: 1008000 | H12: 1008000
C13: DUCT ASSY Part | E13: 식 | F13: 1 | G13: 1440000 | H13: 1440000
C14: 매거진 Part 기타부자재 | E14: 식 | F14: 2 | G14: 216000 | H14: 432000
C15: 기타 Part 부자재 | E15: 식 | F15: 1 | G15: 360000 | H15: 360000
C16: O/P B/K Unit | E16: 식 | F16: 1 | G16: 432000 | H16: 432000 | I16: 가공/시중품
H17: =IF(F17=0,G17,G17*F17) -> 0
H18: =IF(F18=0,G18,G18*F18) -> 0
H19: =IF(F19=0,G19,G19*F19) -> 0
H20: =IF(F20=0,G20,G20*F20) -> 0
H21: =IF(F21=0,G21,G21*F21) -> 0
H22: =IF(F22=0,G22,G22*F22) -> 0
H23: =IF(F23=0,G23,G23*F23) -> 0
H24: =SUM(H3:H23) -> 70344000
B25: 설치/해체/시운전 | C25: 기계 설계 | E25: M/D | F25: 7 | G25: 300000 | H25: =IF(F25=0,G25,G25*F25) -> 2100000
B26: 공사 관련 자재 | C26: 기계 조립 | E26: M/D | F26: 7 | G26: 300000 | H26: =IF(F26=0,G26,G26*F26) -> 2100000
C27: 기계 시운전 | E27: M/D | F27: 7 | G27: 300000 | H27: =IF(F27=0,G27,G27*F27) -> 2100000
H28: =IF(F28=0,G28,G28*F28) -> 0
H29: =IF(F27=0,G29,G29*F27) -> 0
H30: =SUM(H25:H29) -> 6300000
B31: 구매품 | C31: Main Air Part | E31: 식 | F31: 1 | G31: 864000 | H31: =IF(F31=0,G31,G31*F31) -> 864000 | I31: SMC
B32: (유공압품외) | C32: Pallet POP UP & Roation Part Air Part | E32: 식 | F32: 1 | G32: 684000 | H32: =IF(F32=0,G32,G32*F32) -> 684000 | I32: SMC
C33: 매거진 Part Air Part | E33: 식 | F33: 2 | G33: 288000 | H33: =IF(F33=0,G33,G33*F33) -> 576000 | I33: SMC
C34: 감속기 | E34: 식 | F34: 1 | G34: 612000 | H34: =IF(F34=0,G34,G34*F34) -> 612000 | I34: Apex
C35: LM, Ball Bush 외 | E35: 식 | F35: 1 | G35: 432000 | H35: =IF(F35=0,G35,G35*F35) -> 432000 | I35: THK
C36: Sensor Part | E36: 식 | F36: 1 | G36: 432000 | H36: =IF(F36=0,G36,G36*F36) -> 432000 | I36: Omron
C37: Sensor Part | E37: 식 | F37: 2 | G37: 216000 | H37: =IF(F37=0,G37,G37*F37) -> 432000 | I37: Omron
C38: RFID | E38: 식 | F38: 2 | G38: 684000 | H38: =IF(F38=0,G38,G38*F38) -> 1368000 | I38: PEPPERL
C39: RFID TAG | E39: 식 | F39: 10 | G39: 17280 | H39: =IF(F39=0,G39,G39*F39) -> 172800 | I39: PEPPERL
C40: 기타부자재(Bolt, Pin. 액세서리 외) | E40: 식 | F40: 1 | G40: 216000 | H40: 216000 | I40: MISUMI
...

Sheet 코어 자동화 로딩기
B1: □ 단위공사명(전기제외): | C1: 코어 자동화 로딩기 | I1: (첨부)
A2: 구분 | C2: 품 명 | D2: 규격 | E2: 단위 | F2: 수량 | G2: 단가(원) | H2: 금액(원) | I2: 原MAKER
A3: 자 재 비 | B3: 철자재 | C3: Frame Unit | E3: 식 | F3: 2 | G3: 3744000 | H3: =IF(F3=0,G3,G3*F3) -> 7488000
C4: 대차 Guide Unit | E4: 식 | F4: 2 | G4: 2880000 | H4: =IF(F4=0,G4,G4*F4) -> 5760000
C5: 대차 Lift Unit | E5: 식 | F5: 2 | G5: 2880000 | H5: =IF(F5=0,G5,G5*F5) -> 5760000
C6: Main Frame Unit | E6: 식 | F6: 1 | G6: 4320000 | H6: =IF(F6=0,G6,G6*F6) -> 4320000
C7: Other B/K Unit | E7: 식 | F7: 1 | G7: 864000 | H7: =IF(F7=0,G7,G7*F7) -> 864000
C8: Box Conveyor Unit | E8: 식 | F8: 1 | G8: 5760000 | H8: =IF(F8=0,G8,G8*F8) -> 5760000
C9: Box Centering Unit | E9: 식 | F9: 1 | G9: 2160000 | H9: =IF(F9=0,G9,G9*F9) -> 2160000
C10: Box Escape Unit | E10: 식 | F10: 2 | G10: 2160000 | H10: =IF(F10=0,G10,G10*F10) -> 4320000
C11: Box 이송 Unit | E11: 식 | F11: 1 | G11: 3456000 | H11: =IF(F11=0,G11,G11*F11) -> 3456000
C12: Box Push Unit | E12: 식 | F12: 1 | G12: 936000 | H12: =IF(F12=0,G12,G12*F12) -> 936000
C13: 비전 검사 Unit | E13: 식 | F13: 2 | G13: 720000 | H13: =IF(F13=0,G13,G13*F13) -> 1440000
C14: Robot Frame Unit | E14: 식 | F14: 1 | G14: 1152000 | H14: =IF(F14=0,G14,G14*F14) -> 1152000
C15: Gripper 가공 Unit | E15: 식 | F15: 1 | G15: 1008000 | H15: =IF(F15=0,G15,G15*F15) -> 1008000
... C21: OP | E21: 식 | F21: 1 | G21: 1440000 | H21: =IF(F21=0,G21,G21*F21) -> 1440000
C22: 메인 스키드 | E22: set | F22: 130 | G22: 864000 | H22: =IF(F22=0,G22,G22*F22) -> 112320000
C23: 마스터(5set) & NG(3set) 대차 | E23: set | F23: 8 | G23: 2880000 | H23: =IF(F23=0,G23,G23*F23) -> 23040000
C24: Empty SKID Cleaning Part | F24: 1 | G24: 5304000 | H24: 5304000
C25: DUCT ASSY Part | F25: 1 | G25: 2040000 | H25: 2040000
H26: =IF(F26=0,G26,G26*F26) -> 0
H27: =IF(F27=0,G27,G27*F27) -> 0
H28: =IF(F28=0,G28,G28*F28) -> 0
H29: =IF(F29=0,G29,G29*F29) -> 0
H30: =IF(F30=0,G30,G30*F30) -> 0
H31: =IF(F31=0,G31,G31*F31) -> 0
H32: =IF(F32=0,G32,G32*F32) -> 0
H33: =IF(F33=0,G33,G33*F33) -> 0
H34: =IF(F34=0,G34,G34*F34) -> 0
H35: =IF(F35=0,G35,G35*F35) -> 0
H36: =IF(F36=0,G36,G36*F36) -> 0
H37: =IF(F37=0,G37,G37*F37) -> 0
... H39: =IF(F39=0,G39,G39*F39) -> 0
H40: =SUM(H3:H39) -> 204840000
B41: 설치/해체/시운전 | C41: 기계 설계 | E41: M/D | F41: 25 | G41: 219000 | H41: =IF(F41=0,G41,G41*F41) -> 5475000
B42: 공사 관련 자재 | C42: 기계 조립 | E42: M/D | F42: 25 | G42: 219000 | H42: =IF(F42=0,G42,G42*F42) -> 5475000
C43: 기계 시운전 | E43: M/D | F43: 35 | G43: 219000 | H43: =IF(F43=0,G43,G43*F43) -> 7665000
H44: =IF(F44=0,G44,G44*F44) -> 0
H45: =IF(F45=0,G45,G45*F45) -> 0
H46: =SUM(H41:H45) -> 18615000
...

Sheet 절연지 삽입
B1: □ 단위공사명(전기제외): | C1: 절연지 삽입 | I1: (첨부)
A2: 구분 | C2: 품 명 | D2: 규격 | E2: 단위 | F2: 수량 | G2: 단가(원) | H2: 금액(원) | I2: 原MAKER
A3: 자 재 비 | B3: 철자재 | C3: Main Frame Unit | E3: 식 | F3: 1 | G3: 3744000 | H3: =IF(F3=0,G3,G3*F3) -> 3744000
C4: Main Base Unit | E4: 식 | F4: 1 | G4: 4104000 | H4: =IF(F4=0,G4,G4*F4) -> 4104000
C5: Post Unit | E5: 식 | F5: 1 | G5: 2448000 | H5: =IF(F5=0,G5,G5*F5) -> 2448000
C6: 상부 Cover Unit | E6: 식 | F6: 1 | G6: 5616000 | H6: =IF(F6=0,G6,G6*F6) -> 5616000
C7: Other B/K | E7: 식 | F7: 1 | G7: 648000 | H7: =IF(F7=0,G7,G7*F7) -> 648000
C8: Barcode scanner B/K Unit | E8: 식 | F8: 1 | G8: 144000 | H8: =IF(F8=0,G8,G8*F8) -> 144000
C9: Frame & Base Unit | E9: 식 | F9: 1 | G9: 2088000 | H9: =IF(F9=0,G9,G9*F9) -> 2088000
C10: Core 반전 Unit | E10: 식 | F10: 1 | G10: 2232000 | H10: =IF(F10=0,G10,G10*F10) -> 2232000
C11: Index Plate ass'y Unit | E11: 식 | F11: 1 | G11: 6120000 | H11: =IF(F11=0,G11,G11*F11) -> 6120000
C12: Cutting & Forming Unit | E12: 식 | F12: 2 | G12: 5688000 | H12: =IF(F12=0,G12,G12*F12) -> 11376000
C13: Frame Unit Unit | E13: 식 | F13: 2 | G13: 2520000 | H13: =IF(F13=0,G13,G13*F13) -> 5040000
C14: Paper feeder Unit | E14: 식 | F14: 2 | G14: 1152000 | H14: =IF(F14=0,G14,G14*F14) -> 2304000
C15: Paper Preforming feed Unit | E15: 식 | F15: 2 | G15: 2448000 | H15: =IF(F15=0,G15,G15*F15) -> 4896000
... C30: OP | E30: 식 | F30: 1 | G30: 720000 | H30: =IF(F30=0,G30,G30*F30) -> 720000
H31: =IF(F31=0,G31,G31*F31) -> 0
H32: =IF(F32=0,G32,G32*F32) -> 0
H33: =IF(F33=0,G33,G33*F33) -> 0
H34: =IF(F34=0,G34,G34*F34) -> 0
H35: =IF(F35=0,G35,G35*F35) -> 0
H36: =SUM(H3:H35) -> 100944000
B37: 설치/해체/시운전 | C37: 기계 설계 | E37: M/D | F37: 18 | G37: 300000 | H37: =IF(F37=0,G37,G37*F37) -> 5400000
B38: 공사 관련 자재 | C38: 기계 조립 | E38: M/D | F38: 18 | G38: 300000 | H38: =IF(F38=0,G38,G38*F38) -> 5400000
C39: 기계 시운전 | E39: M/D | F39: 25 | G39: 300000 | H39: =IF(F39=0,G39,G39*F39) -> 7500000
H42: =SUM(H37:H41) -> 18300000
B43: 구매품 | C43: Core 반전 Part Air Part | E43: 식 | F43: 1 | G43: 2244000 | H43: =IF(F43=0,G43,G43*F43) -> 2244000 | I43: smc
B44: (유공압품외) | C44: Paper feeder Part A Air Part | E44: 식 | F44: 2 | G44: 102000 | H44: =IF(F44=0,G44,G44*F44) -> 204000 | I44: smc
C45: Electric Cylinde | E45: 식 | F45: 2 | G45: 1224000 | H45: =IF(F45=0,G45,G45*F45) -> 2448000 | I45: smc
C46: Core Lift Part Air Part | E46: 식 | F46: 1 | G46: 340000 | H46: =IF(F46=0,G46,G46*F46) -> 340000 | I46: smc
C47: Core Clamp Part Air Part | E47: 식 | F47: 1 | G47: 510000 | H47: =IF(F47=0,G47,G47*F47) -> 510000 | I47: smc
C48: Position Unit | E48: 식 | F48: 1 | G48: 1020000 | H48: =IF(F48=0,G48,G48*F48) -> 1020000 | I48: Unicon
C49: Pallet stopper | E49: 식 | F49: 2 | G49: 340000 | H49: =IF(F49=0,G49,G49*F49) -> 680000 | I49: Unicon
C50: Barcod scanner | D50: SR-X100 | E50: 식 | F50: 1 | G50: 1496000 | H50: =IF(F50=0,G50,G50*F50) -> 1496000 | I50: Keyence
C51: LM & Ball Bush Part | E51: 식 | F51: 1 | G51: 204000 | H51: =IF(F51=0,G51,G51*F51) -> 204000 | I51: THK
C52: 감속기 | E52: 식 | F52: 1 | G52: 408000 | H52: =IF(F52=0,G52,G52*F52) -> 408000 | I52: APEX
C53: Bearing SD140XP0 | E53: 식 | F53: 1 | G53: 1360000 | H53: =IF(F53=0,G53,G53*F53) -> 1360000 | I53: SILVERTHIN
C54: Laser Sensor | E54: 식 | F54: 2 | G54: 258400 | H54: =IF(F54=0,G54,G54*F54) -> 516800 | I54: Keyence
C55: 감속기 | E55: 식 | F55: 2 | G55: 408000 | H55: =IF(F55=0,G55,G55*F55) -> 816000 | I55: APEX
C56: LM & Ball Bush Part | E56: 식 | F56: 2 | G56: 170000 | H56: =IF(F56=0,G56,G56*F56) -> 340000 | I56: THK
...

Sheet 인서팅
B1: □ 단위공사명(전기제외): | C1: 인서팅 | I1: (첨부)
A2: 구분 | C2: 품 명 | D2: 규격 | E2: 단위 | F2: 수량 | G2: 단가(원) | H2: 금액(원) | I2: 原MAKER
A3: 자 재 비 | B3: 철자재 | C3: Main Frame Unit | E3: 식 | F3: 1 | G3: 3600000 | H3: =IF(F3=0,G3,G3*F3) -> 3600000
C4: Main Base Unit | E4: 식 | F4: 1 | G4: 4608000 | H4: =IF(F4=0,G4,G4*F4) -> 4608000
C5: 상부 Cover Unit | E5: 식 | F5: 1 | G5: 3456000 | H5: =IF(F5=0,G5,G5*F5) -> 3456000
C6: Other B/K | E6: 식 | F6: 1 | G6: 1584000 | H6: =IF(F6=0,G6,G6*F6) -> 1584000
C7: RFID B/K Unit | E7: 식 | F7: 1 | G7: 216000 | H7: =IF(F7=0,G7,G7*F7) -> 216000
C8: Barcode scanner B/K Unit | E8: 식 | F8: 1 | G8: 144000 | H8: =IF(F8=0,G8,G8*F8) -> 144000
C9: Frame & Base Unit | E9: 식 | F9: 1 | G9: 4680000 | H9: =IF(F9=0,G9,G9*F9) -> 4680000
C10: Core X-Y Unit | E10: 식 | F10: 1 | G10: 7056000 | H10: =IF(F10=0,G10,G10*F10) -> 7056000
C11: Load Head Unit | E11: 식 | F11: 2 | G11: 7056000 | H11: =IF(F11=0,G11,G11*F11) -> 14112000
C12: 인서팅 Unit | E12: 식 | F12: 1 | G12: 19440000 | H12: =IF(F12=0,G12,G12*F12) -> 19440000
C13: 인서팅 삽입 Unit | E13: 식 | F13: 1 | G13: 14400000 | H13: =IF(F13=0,G13,G13*F13) -> 14400000
C14: Work Rotation Unit | E14: 식 | F14: 1 | G14: 5328000 | H14: =IF(F14=0,G14,G14*F14) -> 5328000
C15: OP | E15: 식 | F15: 1 | G15: 720000 | H15: =IF(F15=0,G15,G15*F15) -> 720000
C16: Buffer Part | E16: 식 | F16: 1 | G16: 6210000 | H16: 6210000
C17: DUCT ASSY Part | E17: 식 | F17: 1 | G17: 1656000 | H17: 1656000
H19: =SUM(H3:H18) -> 87210000
B20: 설치/해체/시운전 | C20: 기계 설계 | E20: 식 | F20: 1 | G20: 8760000 | H20: =IF(F20=0,G20,G20*F20) -> 8760000
B21: 공사 관련 자재 | C21: 기계 조립 | E21: 식 | F21: 1 | G21: 8030000 | H21: =IF(F21=0,G21,G21*F21) -> 8030000
C22: 기계 시운전 | E22: 식 | F22: 1 | G22: 8030000 | H22: =IF(F22=0,G22,G22*F22) -> 8030000
C24: 기타자재
H25: =SUM(H20:H24) -> 24820000
B26: 구매품 | C26: Main Frame Part Sensor Part | E26: 식 | F26: 1 | G26: 414000 | H26: =IF(F26=0,G26,G26*F26) -> 414000 | I26: Omron
B27: (유공압품외) | C27: Electric Cylinde | E27: 식 | F27: 2 | G27: 1242000 | H27: =IF(F27=0,G27,G27*F27) -> 2484000 | I27: FESTO
C28: Load Head Part Air Part | E28: 식 | F28: 2 | G28: 276000 | H28: =IF(F28=0,G28,G28*F28) -> 552000 | I28: SMC
C29: Air Gripper | E29: 식 | F29: 1 | G29: 1518000 | H29: =IF(F29=0,G29,G29*F29) -> 1518000 | I29: SMC
C30: Work Rotation Part Air Part | E30: 식 | F30: 1 | G30: 655500 | H30: =IF(F30=0,G30,G30*F30) -> 655500 | I30: SMC
C31: Main Air/Sol V/V/Air 부자재 | E31: 식 | F31: 1 | G31: 1932000 | H31: =IF(F31=0,G31,G31*F31) -> 1932000 | I31: SMC
C32: RFID | E32: 식 | F32: 1 | G32: 496800 | H32: =IF(F32=0,G32,G32*F32) -> 496800 | I32: PEPPERL
C33: Position Unit | E33: 식 | F33: 1 | G33: 1035000 | H33: =IF(F33=0,G33,G33*F33) -> 1035000 | I33: Unicon
C34: Pallet stopper | E34: 식 | F34: 2 | G34: 345000 | H34: =IF(F34=0,G34,G34*F34) -> 690000 | I34: Unicon
C35: Barcod scanner | E35: 식 | F35: 1 | G35: 1518000 | H35: =IF(F35=0,G35,G35*F35) -> 1518000 | I35: Keyence
C36: 감속기 | E36: 식 | F36: 2 | G36: 2070000 | H36: =IF(F36=0,G36,G36*F36) -> 4140000 | I36: APEX
C37: LM & Ball Bush Part | E37: 식 | F37: 1 | G37: 1518000 | H37: =IF(F37=0,G37,G37*F37) -> 1518000 | I37: THK
C38: 감속기 | E38: 식 | F38: 4 | G38: 1380000 | H38: =IF(F38=0,G38,G38*F38) -> 5520000 | I38: APEX
C39: LM & Ballscrew Part | E39: 식 | F39: 1 | G39: 1242000 | H39: =IF(F39=0,G39,G39*F39) -> 1242000 | I39: THK
... C45: 라이트커텐(600mm) | E45: 식 | F45: 2 | G45: 690000 | H45: =IF(F45=0,G45,G45*F45) -> 1380000 | I45: Keyence
C46: Main Frame Part 기타부자재 | E46: 식 | F46: 1 | G46: 552000 | H46: 552000 | I46: misumi
C47: Sensor 및 기타부자재 | E47: 식 | F47: 1 | G47: 241500 | H47: 241500 | I47: misumi
...

Sheet 확관
B1: □ 단위공사명(전기제외): | C1: 확관 | I1: (첨부)
A2: 구분 | C2: 품 명 | D2: 규격 | E2: 단위 | F2: 수량 | G2: 단가(원) | H2: 금액(원) | I2: 原MAKER
A3: 자 재 비 | B3: 철자재 | C3: Main Frame Unit | F3: 1 | G3: 3600000 | H3: =IF(F3=0,G3,G3*F3) -> 3600000
C4: Main Base Unit | F4: 1 | G4: 4608000 | H4: =IF(F4=0,G4,G4*F4) -> 4608000
C5: 상부 Cover Unit | F5: 1 | G5: 3456000 | H5: =IF(F5=0,G5,G5*F5) -> 3456000
C6: Other B/K | F6: 1 | G6: 1584000 | H6: =IF(F6=0,G6,G6*F6) -> 1584000
C7: Barcode scanner B/K Unit | F7: 1 | G7: 144000 | H7: =IF(F7=0,G7,G7*F7) -> 144000
C8: Frame & Base Unit | F8: 1 | G8: 5616000 | H8: =IF(F8=0,G8,G8*F8) -> 5616000
C9: Core X-Y Unit | F9: 1 | G9: 8280000 | H9: =IF(F9=0,G9,G9*F9) -> 8280000
C10: Load Head Unit | F10: 1 | G10: 7056000 | H10: =IF(F10=0,G10,G10*F10) -> 7056000
C11: 확관 Unit | F11: 1 | G11: 19440000 | H11: =IF(F11=0,G11,G11*F11) -> 19440000
C12: Cuff Unit | F12: 1 | G12: 19440000 | H12: =IF(F12=0,G12,G12*F12) -> 19440000
C13: Work Rotation Unit | F13: 1 | G13: 5328000 | H13: =IF(F13=0,G13,G13*F13) -> 5328000
C14: OP | F14: 1 | G14: 720000 | H14: =IF(F14=0,G14,G14*F14) -> 720000
C15: DUCT ASSY Part | E15: 식 | F15: 1 | G15: 1656000 | H15: 1656000
H18: =SUM(H3:H17) -> 80928000
B19: 설치/해체/시운전 | C19: 기계 설계 | E19: 식 | F19: 1 | G19: 8760000 | H19: =IF(F19=0,G19,G19*F19) -> 8760000
B20: 공사 관련 자재 | C20: 기계 조립 | E20: 식 | F20: 1 | G20: 8030000 | H20: =IF(F20=0,G20,G20*F20) -> 8030000
C21: 기계 시운전 | E21: 식 | F21: 1 | G21: 8030000 | H21: =IF(F21=0,G21,G21*F21) -> 8030000
C23: 기타자재
H24: =SUM(H19:H23) -> 24820000
B25: 구매품 | C25: Sensor Part | E25: 식 | F25: 1 | G25: 414000 | H25: =IF(F25=0,G25,G25*F25) -> 414000 | I25: Omron
B26: (유공압품외) | C26: Position Unit | E26: 식 | F26: 1 | G26: 1035000 | H26: =IF(F26=0,G26,G26*F26) -> 1035000 | I26: Unicon
C27: Pallet stopper | E27: 식 | F27: 2 | G27: 345000 | H27: =IF(F27=0,G27,G27*F27) -> 690000 | I27: Unicon
C28: Barcod scanner | E28: 식 | F28: 1 | G28: 1518000 | H28: =IF(F28=0,G28,G28*F28) -> 1518000 | I28: Keyence
C29: 감속기 | E29: 식 | F29: 2 | G29: 2070000 | H29: =IF(F29=0,G29,G29*F29) -> 4140000 | I29: APEX
C30: LM & Ball Bush Part | E30: 식 | F30: 1 | G30: 1518000 | H30: =IF(F30=0,G30,G30*F30) -> 1518000 | I30: THK
C31: Electric Cylinde | E31: 식 | F31: 1 | G31: 1242000 | H31: =IF(F31=0,G31,G31*F31) -> 1242000 | I31: FESTO
C32: 감속기 | E32: 식 | F32: 2 | G32: 1242000 | H32: =IF(F32=0,G32,G32*F32) -> 2484000 | I32: APEX
C33: Cross Roller Bearing | E33: 식 | F33: 2 | G33: 952200 | H33: =IF(F33=0,G33,G33*F33) -> 1904400 | I33: THK
C34: Cam Follower | E34: 식 | F34: 96 | G34: 22080 | H34: =IF(F34=0,G34,G34*F34) -> 2119680 | I34: Misumi
C35: 감속기 | E35: 식 | F35: 5 | G35: 1518000 | H35: =IF(F35=0,G35,G35*F35) -> 7590000 | I35: APEX
C36: LM & Ballscrew Part | E36: 식 | F36: 1 | G36: 1242000 | H36: =IF(F36=0,G36,G36*F36) -> 1242000 | I36: THK
C37: 감속기 | E37: 식 | F37: 1 | G37: 1380000 | H37: =IF(F37=0,G37,G37*F37) -> 1380000 | I37: APEX
C38: LM & Ballscrew Part | E38: 식 | F38: 1 | G38: 655500 | H38: =IF(F38=0,G38,G38*F38) -> 655500 | I38: THK
C39: PPC Unit | D39: UTC320KP2302-T | E39: 식 | F39: 1 | G39: 1656000 | H39: =IF(F39=0,G39,G39*F39) -> 1656000 | I39: Advantech
C40: 핸디 바코드 Unit | D40: HR-X100 | E40: 식 | F40: 1 | G40: 690000 | H40: =IF(F40=0,G40,G40*F40) -> 690000 | I40: Keyence
C41: 라이트커텐(600mm) | E41: 식 | F41: 2 | G41: 690000 | H41: =IF(F41=0,G41,G41*F41) -> 1380000 | I41: Keyence
C42: Main Frame Part 기타부자재 | E42: 식 | F42: 1 | G42: 552000 | H42: 552000 | I42: misumi
C43: Position Part Sensor 및 기타부자재 | E43: 식 | F43: 1 | G43: 241500 | H43: 241500 | I43: misumi
...

Sheet 트위스팅
B1: □ 단위공사명(전기제외): | C1: 트위스팅 | I1: (첨부)
A2: 구분 | C2: 품 명 | D2: 규격 | E2: 단위 | F2: 수량 | G2: 단가(원) | H2: 금액(원) | I2: 原MAKER
A3: 자 재 비 | B3: 철자재 | C3: Main Frame Unit | F3: 1 | G3: 3600000 | H3: =IF(F3=0,G3,G3*F3) -> 3600000
C4: Main Base Unit | F4: 1 | G4: 4608000 | H4: =IF(F4=0,G4,G4*F4) -> 4608000
C5: 상부 Cover Unit | F5: 1 | G5: 3456000 | H5: =IF(F5=0,G5,G5*F5) -> 3456000
C6: Other B/K | F6: 1 | G6: 1584000 | H6: =IF(F6=0,G6,G6*F6) -> 1584000
C7: Barcode scanner B/K Unit | F7: 1 | G7: 144000 | H7: =IF(F7=0,G7,G7*F7) -> 144000
C8: Frame & Base Unit | F8: 1 | G8: 5616000 | H8: =IF(F8=0,G8,G8*F8) -> 5616000
C9: Core X-Y Unit | F9: 1 | G9: 8280000 | H9: =IF(F9=0,G9,G9*F9) -> 8280000
C10: Load Head Unit | F10: 1 | G10: 7056000 | H10: =IF(F10=0,G10,G10*F10) -> 7056000
C11: 트위스팅 Unit | F11: 1 | G11: 48240000 | H11: =IF(F11=0,G11,G11*F11) -> 48240000
C12: Cuff Unit | F12: 1 | G12: 19440000 | H12: =IF(F12=0,G12,G12*F12) -> 19440000
C13: Work Rotation Unit | F13: 1 | G13: 5328000 | H13: =IF(F13=0,G13,G13*F13) -> 5328000
C14: OP | F14: 1 | G14: 720000 | H14: =IF(F14=0,G14,G14*F14) -> 720000
C15: DUCT ASSY Part | F15: 1 | G15: 1656000 | H15: 1656000
C33: 기타자재
H34: =SUM(H3:H33) -> 109728000
B35: 설치/해체/시운전 | C35: 기계 설계 | E35: 식 | F35: 1 | G35: 8760000 | H35: =IF(F35=0,G35,G35*F35) -> 8760000
B36: 공사 관련 자재 | C36: 기계 조립 | E36: 식 | F36: 1 | G36: 8030000 | H36: =IF(F36=0,G36,G36*F36) -> 8030000
C37: 기계 시운전 | E37: 식 | F37: 1 | G37: 8030000 | H37: =IF(F37=0,G37,G37*F37) -> 8030000
H38: =IF(F38=0,G38,G38*F38) -> 0
C39: 기타자재 | H39: =IF(F39=0,G39,G39*F39) -> 0
H40: =SUM(H35:H39) -> 24820000
B41: 구매품 | C41: Sensor Part | F41: 1 | G41: 414000 | H41: =IF(F41=0,G41,G41*F41) -> 414000 | I41: Omron
B42: (유공압품외) | C42: Position Unit | F42: 1 | G42: 1035000 | H42: =IF(F42=0,G42,G42*F42) -> 1035000 | I42: Unicon
C43: Pallet stopper | F43: 2 | G43: 345000 | H43: =IF(F43=0,G43,G43*F43) -> 690000 | I43: Unicon
C44: Barcod scanner | D44: SR-X100 | F44: 1 | G44: 1518000 | H44: =IF(F44=0,G44,G44*F44) -> 1518000 | I44: Keyence
C45: 감속기 | F45: 2 | G45: 2070000 | H45: =IF(F45=0,G45,G45*F45) -> 4140000 | I45: APEX
C46: LM & Ball Bush Part | F46: 1 | G46: 1518000 | H46: =IF(F46=0,G46,G46*F46) -> 1518000 | I46: THK
C47: Electric Cylinde | F47: 1 | G47: 1242000 | H47: =IF(F47=0,G47,G47*F47) -> 1242000 | I47: FESTO
C48: 감속기 | F48: 20 | G48: 3036000 | H48: =IF(F48=0,G48,G48*F48) -> 60720000 | I48: APEX
C49: Cross Roller Bearing | F49: 22 | G49: 2394300 | H49: =IF(F49=0,G49,G49*F49) -> 52674600 | I49: THK
C50: 감속기 | F50: 2 | G50: 1794000 | H50: =IF(F50=0,G50,G50*F50) -> 3588000 | I50: APEX
C51: LM & Ballscrew Part | F51: 1 | G51: 1242000 | H51: =IF(F51=0,G51,G51*F51) -> 1242000 | I51: THK
C52: 감속기 | F52: 1 | G52: 1380000 | H52: =IF(F52=0,G52,G52*F52) -> 1380000 | I52: APEX
C53: LM & Ballscrew Part | F53: 1 | G53: 655500 | H53: =IF(F53=0,G53,G53*F53) -> 655500 | I53: THK
C54: PPC Unit | F54: 1 | G54: 1656000 | H54: =IF(F54=0,G54,G54*F54) -> 1656000 | I54: Advantech
C55: 핸디 바코드 Unit | F55: 1 | G55: 690000 | H55: =IF(F55=0,G55,G55*F55) -> 690000 | I55: Keyence
C56: 라이트커텐(600mm) | F56: 2 | G56: 690000 | H56: =IF(F56=0,G56,G56*F56) -> 1380000 | I56: Keyence
C57: Load Head Part Air Part | F57: 1 | G57: 276000 | H57: 276000 | I57: SMC
...

Sheet 하부컷팅
B1: □ 단위공사명(전기제외): | C1: 하부컷팅 | I1: (첨부)
A2: 구분 | C2: 품 명 | D2: 규격 | E2: 단위 | F2: 수량 | G2: 단가(원) | H2: 금액(원) | I2: 原MAKER
A3: 자 재 비 | B3: 철자재 | C3: Main Frame Unit | E3: 식 | F3: 1 | G3: 3600000 | H3: =IF(F3=0,G3,G3*F3) -> 3600000
C4: Main Base Unit | E4: 식 | F4: 1 | G4: 4608000 | H4: =IF(F4=0,G4,G4*F4) -> 4608000
C5: 상부 Cover Unit | E5: 식 | F5: 1 | G5: 3456000 | H5: =IF(F5=0,G5,G5*F5) -> 3456000
C6: Other B/K | E6: 식 | F6: 1 | G6: 1584000 | H6: =IF(F6=0,G6,G6*F6) -> 1584000
C7: Barcode scanner B/K Unit | E7: 식 | F7: 1 | G7: 144000 | H7: =IF(F7=0,G7,G7*F7) -> 144000
C8: Frame & Base Unit | E8: 식 | F8: 1 | G8: 4176000 | H8: =IF(F8=0,G8,G8*F8) -> 4176000
C9: Core X-Y Unit | E9: 식 | F9: 1 | G9: 5976000 | H9: =IF(F9=0,G9,G9*F9) -> 5976000
C10: Load Head Unit | E10: 식 | F10: 1 | G10: 7056000 | H10: =IF(F10=0,G10,G10*F10) -> 7056000
C11: Cutting Unit | E11: 식 | F11: 1 | G11: 19440000 | H11: =IF(F11=0,G11,G11*F11) -> 19440000
C12: Work Rotation Unit | E12: 식 | F12: 1 | G12: 5328000 | H12: =IF(F12=0,G12,G12*F12) -> 5328000
C13: OP | E13: 식 | F13: 1 | G13: 720000 | H13: 720000
C14: DUCT ASSY Part | E14: 식 | F14: 1 | G14: 1656000 | H14: 1656000
H15: =SUM(H3:H14) -> 57744000
B16: 설치/해체/시운전 | C16: 기계 설계 | E16: 식 | F16: 1 | G16: 8760000 | H16: =IF(F16=0,G16,G16*F16) -> 8760000
B17: 공사 관련 자재 | C17: 기계 조립 | E17: 식 | F17: 1 | G17: 8030000 | H17: =IF(F17=0,G17,G17*F17) -> 8030000
C18: 기계 시운전 | E18: 식 | F18: 1 | G18: 8030000 | H18: =IF(F18=0,G18,G18*F18) -> 8030000
H19: =IF(F19=0,G19,G19*F19) -> 0
H20: =SUM(H18:H19) -> 8030000
B21: 구매품 | C21: Sensor Part | E21: 식 | F21: 1 | G21: 414000 | H21: =IF(F21=0,G21,G21*F21) -> 414000 | I21: Omron
B22: (유공압품외) | C22: Position Unit | E22: 식 | F22: 1 | G22: 1035000 | H22: =IF(F22=0,G22,G22*F22) -> 1035000 | I22: Unicon
C23: Pallet stopper | E23: 식 | F23: 2 | G23: 345000 | H23: =IF(F23=0,G23,G23*F23) -> 690000 | I23: Unicon
C24: Barcod scanner | E24: 식 | F24: 1 | G24: 1518000 | H24: =IF(F24=0,G24,G24*F24) -> 1518000 | I24: Keyence
C25: 감속기 | E25: 식 | F25: 2 | G25: 2070000 | H25: =IF(F25=0,G25,G25*F25) -> 4140000 | I25: APEX
C26: LM & Ball Bush Part | E26: 식 | F26: 1 | G26: 1173000 | H26: =IF(F26=0,G26,G26*F26) -> 1173000 | I26: THK
C27: Electric Cylinde | E27: 식 | F27: 1 | G27: 1242000 | H27: =IF(F27=0,G27,G27*F27) -> 1242000 | I27: FESTO
C28: 감속기 | E28: 식 | F28: 1 | G28: 3795000 | H28: =IF(F28=0,G28,G28*F28) -> 3795000 | I28: APEX
C29: Cross Roller Bearing | E29: 식 | F29: 1 | G29: 2394300 | H29: =IF(F29=0,G29,G29*F29) -> 2394300 | I29: THK
C30: 감속기 | E30: 식 | F30: 1 | G30: 1380000 | H30: =IF(F30=0,G30,G30*F30) -> 1380000 | I30: APEX
C31: LM & Ballscrew Part | E31: 식 | F31: 1 | G31: 655500 | H31: =IF(F31=0,G31,G31*F31) -> 655500 | I31: THK
C32: PPC Unit | E32: 식 | F32: 1 | G32: 1656000 | H32: =IF(F32=0,G32,G32*F32) -> 1656000 | I32: Advantech
C33: 핸디 바코드 Unit | E33: 식 | F33: 1 | G33: 690000 | H33: =IF(F33=0,G33,G33*F33) -> 690000 | I33: Keyence
C34: 라이트커텐(600mm) | E34: 식 | F34: 2 | G34: 690000 | H34: =IF(F34=0,G34,G34*F34) -> 1380000 | I34: Keyence
C35: Load Head Part Air Part | E35: 식 | F35: 1 | G35: 276000 | H35: 276000 | I35: SMC
C36: Work Rotation Part Air Part | E36: 식 | F36: 1 | G36: 655500 | H36: 655500 | I36: SMC
C37: Main Air/Sol V/V/Air 부자재 | E37: 식 | F37: 1 | G37: 1932000 | H37: 1932000 | I37: SMC
C38: 기타부자재 | E38: 식 | F38: 1 | G38: 552000 | H38: 552000 | I38: SMC
C39: Sensor 및 기타부자재 | E39: 식 | F39: 1 | G39: 241500 | H39: 241500 | I39: misumi
C40: Sensor 및 기타부자재 | E40: 식 | F40: 1 | G40: 621000 | H40: 621000 | I40: Omron
...

Sheet 납품, 현지설치 및 이벤트 양산대응
B1: □ 단위공사명(전기제외): | C1: 납품, 현지설치 및 이벤트 양산대응 | I1: (첨부)
A2: 구분 | C2: 품 명 | D2: 규격 | E2: 단위 | F2: 수량 | G2: 단가(원) | H2: 금액(원) | I2: 原MAKER
A3: 자 재 비 | B3: 철자재 | H3: =IF(F3=0,G3,G3*F3) -> 0
H4: =IF(F4=0,G4,G4*F4) -> 0
H5: =IF(F5=0,G5,G5*F5) -> 0
H6: =IF(F6=0,G6,G6*F6) -> 0
H7: =IF(F7=0,G7,G7*F7) -> 0
H8: =IF(F8=0,G8,G8*F8) -> 0
H9: =IF(F9=0,G9,G9*F9) -> 0
H10: =IF(F10=0,G10,G10*F10) -> 0
H11: =IF(F11=0,G11,G11*F11) -> 0
H12: =IF(F12=0,G12,G12*F12) -> 0
H13: =IF(F13=0,G13,G13*F13) -> 0
H14: =IF(F14=0,G14,G14*F14) -> 0
H15: =IF(F15=0,G15,G15*F15) -> 0
... H22: =IF(F22=0,G22,G22*F22) -> 0
C23: 기타자재 | H23: =IF(F23=0,G23,G23*F23) -> 0
H24: =SUM(H3:H23) -> 0
B25: 설치/해체/시운전 | C25: 포장 및 납품 | E25: 식 | F25: 1 | G25: 6500000 | H25: =IF(F25=0,G25,G25*F25) -> 6500000
B26: 공사 관련 자재 | C26: 현지 설치 및 숙식비 | E26: M/D | F26: 223 | G26: 300000 | H26: =IF(F26=0,G26,G26*F26) -> 66900000
C27: 이벤트 대응 (PV/SP1) : 국내 대응 | E27: M/D | F27: 28 | G27: 350000 | H27: =IF(F27=0,G27,G27*F27) -> 9800000
C28: 현지 설치 및 숙식비 | E28: M/D | F28: 180 | G28: 500000 | H28: =IF(F28=0,G28,G28*F28) -> 90000000
C29: 이벤트 대응 (LP2/M) : 현지 대응_7일*4회 | E29: M/D | F29: 28 | G29: 500000 | H29: =IF(F29=0,G29,G29*F29) -> 14000000
C30: 양산 대응 : 현지 대응_20일*주/야 | E30: M/D | F30: 40 | G30: 650000 | H30: =IF(F30=0,G30,G30*F30) -> 26000000
C31: 라인 운영 교육 : 현지 대응_14일 | E31: M/D | F31: 28 | G31: 500000 | H31: =IF(F31=0,G31,G31*F31) -> 14000000
C32: 항공비 10인 X 왕복 1회 | E32: 식 | F32: 1 | G32: 30000000 | H32: =IF(F32=0,G32,G32*F32) -> 30000000
C33: 안전관리자 | G33: 견적제외 | H33: 견적제외
H35: =IF(F35=0,G35,G35*F35) -> 0
H36: =SUM(H25:H35) -> 257200000
B37: 구매품 | H37: =IF(F37=0,G37,G37*F37) -> 0
B38: (유공압품외) | H38: =IF(F38=0,G38,G38*F38) -> 0
H39: =IF(F39=0,G39,G39*F39) -> 0
H40: =IF(F40=0,G40,G40*F40) -> 0
H41: =IF(F41=0,G41,G41*F41) -> 0
H42: =IF(F42=0,G42,G42*F42) -> 0
H43: =IF(F43=0,G43,G43*F43) -> 0
H44: =IF(F44=0,G44,G44*F44) -> 0
H45: =IF(F45=0,G45,G45*F45) -> 0
H46: =IF(F46=0,G46,G46*F46) -> 0
H47: =IF(F47=0,G47,G47*F47) -> 0
...

Sheet 첨부(견적조건차이내역)
A1: ※ 현대/기아차의 요구사양과 업체견적사양이 다른경우만 작성
D2: (첨부)
A3: 현대/기아차 요구사양대비 견적조건 상이내역
A5: 항 목 | B5: 현대/기아차 요구사양 | C5: 업체 견적기준 사양 | D5: 비 고
