Workbook

Sheet 갑지
B1: (현대/기아차 설비협력업체 견적통일양식)
B2: 見 積 書
B4: 현대위아 貴下 | G4: ㈜ 지 팩
B5: 견적일자 | D5: 2023. 06. 10 | G5: 대표 : 김 회윤
B6: 견적번호 | D6: Q2023060003872 | G6: 주소 : 경남 김해시 서부로 1701번길 328
B7: 납기 | C7: 입하 | G7: (덕암리)
C8: 최종검수 | G8: 전화: 055-343-7848
B9: 견적유효기간 | D9: 30일 | G9: Fax: 055-343-7849
B10: 인도장소 | G10: 견적담당: | H10: 김일영
B11: 지불조건 | G11: 연 락 처 : | H11: 010-2555-1869
B13: 견적금액 : | D13: 一金 일억이천오백만원整(\125,00,000)
B15: 번호 | C15: 상세품목내역 | E15: 견적금액 (천원) | I15: 비 고
E16: 기계부문 | F16: 전기부문 | G16: 관리/이윤 (안전관리비포함) | H16: 합 계
B17: 1 | C17: DMG | E17: =IF('단위공사별(집계)'!N7>1,('단위공사별(집계)'!D7+'단위공사별(집계)'!E7+'단위공사별(집계)'!F7+'단위공사별(집계)'!G7+'단위공사별(집계)'!H7+'단위공사별(집계)'!I7)/1000," ") -> 63061.2 | F17: =IF('단위공사별(집계)'!N7>0,'단위공사별(집계)'!K17/1000,"") -> 39375.6 | G17: =IF('단위공사별(집계)'!N7>0,('단위공사별(집계)'!L7+'단위공사별(집계)'!M7)/1000,"") -> 22573.379 | H17: 125000
B18: 2 | C18: =IF('단위공사별(집계)'!N8>0,'단위공사별(집계)'!B8,"") | E18: =IF('단위공사별(집계)'!N8>1,('단위공사별(집계)'!D8+'단위공사별(집계)'!E8+'단위공사별(집계)'!F8+'단위공사별(집계)'!G8+'단위공사별(집계)'!H8+'단위공사별(집계)'!I8)/1000," ") | G18: =IF('단위공사별(집계)'!N8>0,('단위공사별(집계)'!L8+'단위공사별(집계)'!M8)/1000,"") | H18: =IF('단위공사별(집계)'!N8>0,'단위공사별(집계)'!N8/1000,"")
B19: 3 | C19: =IF('단위공사별(집계)'!N9>0,'단위공사별(집계)'!B9,"") | E19: =IF('단위공사별(집계)'!N9>1,('단위공사별(집계)'!D9+'단위공사별(집계)'!E9+'단위공사별(집계)'!F9+'단위공사별(집계)'!G9+'단위공사별(집계)'!H9+'단위공사별(집계)'!I9)/1000," ") | G19: =IF('단위공사별(집계)'!N9>0,('단위공사별(집계)'!L9+'단위공사별(집계)'!M9)/1000,"") | H19: =IF('단위공사별(집계)'!N9>0,'단위공사별(집계)'!N9/1000,"")
B20: 4 | C20: =IF('단위공사별(집계)'!N10>0,'단위공사별(집계)'!B10,"") | E20: =IF('단위공사별(집계)'!N10>1,('단위공사별(집계)'!D10+'단위공사별(집계)'!E10+'단위공사별(집계)'!F10+'단위공사별(집계)'!G10+'단위공사별(집계)'!H10+'단위공사별(집계)'!I10)/1000," ") | G20: =IF('단위공사별(집계)'!N10>0,('단위공사별(집계)'!L10+'단위공사별(집계)'!M10)/1000,"") | H20: =IF('단위공사별(집계)'!N10>0,'단위공사별(집계)'!N10/1000,"")
B21: 5 | C21: =IF('단위공사별(집계)'!N11>0,'단위공사별(집계)'!B11,"") | E21: =IF('단위공사별(집계)'!N11>1,('단위공사별(집계)'!D11+'단위공사별(집계)'!E11+'단위공사별(집계)'!F11+'단위공사별(집계)'!G11+'단위공사별(집계)'!H11+'단위공사별(집계)'!I11)/1000," ") | G21: =IF('단위공사별(집계)'!N11>0,('단위공사별(집계)'!L11+'단위공사별(집계)'!M11)/1000,"") | H21: =IF('단위공사별(집계)'!N11>0,'단위공사별(집계)'!N11/1000,"")
B22: 6 | C22: =IF('단위공사별(집계)'!N12>0,'단위공사별(집계)'!B12,"") | E22: =IF('단위공사별(집계)'!N12>1,('단위공사별(집계)'!D12+'단위공사별(집계)'!E12+'단위공사별(집계)'!F12+'단위공사별(집계)'!G12+'단위공사별(집계)'!H12+'단위공사별(집계)'!I12)/1000," ") | G22: =IF('단위공사별(집계)'!N12>0,('단위공사별(집계)'!L12+'단위공사별(집계)'!M12)/1000,"") | H22: =IF('단위공사별(집계)'!N12>0,'단위공사별(집계)'!N12/1000,"")
B23: 7 | C23: =IF('단위공사별(집계)'!N13>0,'단위공사별(집계)'!B13,"") | E23: =IF('단위공사별(집계)'!N13>1,('단위공사별(집계)'!D13+'단위공사별(집계)'!E13+'단위공사별(집계)'!F13+'단위공사별(집계)'!G13+'단위공사별(집계)'!H13+'단위공사별(집계)'!I13)/1000," ") | G23: =IF('단위공사별(집계)'!N13>0,('단위공사별(집계)'!L13+'단위공사별(집계)'!M13)/1000,"") | H23: =IF('단위공사별(집계)'!N13>0,'단위공사별(집계)'!N13/1000,"")
B24: 8 | C24: =IF('단위공사별(집계)'!N14>0,'단위공사별(집계)'!B14,"") | E24: =IF('단위공사별(집계)'!N14>1,('단위공사별(집계)'!D14+'단위공사별(집계)'!E14+'단위공사별(집계)'!F14+'단위공사별(집계)'!G14+'단위공사별(집계)'!H14+'단위공사별(집계)'!I14)/1000," ") | G24: =IF('단위공사별(집계)'!N14>0,('단위공사별(집계)'!L14+'단위공사별(집계)'!M14)/1000,"") | H24: =IF('단위공사별(집계)'!N14>0,'단위공사별(집계)'!N14/1000,"")
B25: 9 | C25: =IF('단위공사별(집계)'!N15>0,'단위공사별(집계)'!B15,"") | E25: =IF('단위공사별(집계)'!N15>1,('단위공사별(집계)'!D15+'단위공사별(집계)'!E15+'단위공사별(집계)'!F15+'단위공사별(집계)'!G15+'단위공사별(집계)'!H15+'단위공사별(집계)'!I15)/1000," ") | G25: =IF('단위공사별(집계)'!N15>0,('단위공사별(집계)'!L15+'단위공사별(집계)'!M15)/1000,"") | H25: =IF('단위공사별(집계)'!N15>0,'단위공사별(집계)'!N15/1000,"")
B26: 10 | C26: =IF('단위공사별(집계)'!N16>0,'단위공사별(집계)'!B16,"") | E26: =IF('단위공사별(집계)'!N16>1,('단위공사별(집계)'!D16+'단위공사별(집계)'!E16+'단위공사별(집계)'!F16+'단위공사별(집계)'!G16+'단위공사별(집계)'!H16+'단위공사별(집계)'!I16)/1000," ") | G26: =IF('단위공사별(집계)'!N16>0,('단위공사별(집계)'!L16+'단위공사별(집계)'!M16)/1000,"") | H26: =IF('단위공사별(집계)'!N16>0,'단위공사별(집계)'!N16/1000,"")
B27: 견적 합계 | E27: =SUM(E17:E23) -> 63061.2 | F27: =SUM(F17:F23) -> 39375.6 | G27: =SUM(G17:G23) -> 22573.379 | H27: 125000
F29: 공개입찰가 (견적時 공란)
B31: 특기사항 | C31: 1. VAT 제외 | F31: 외주계획 업체명 (자작時 공란)
C32: 2. 기본 유틸리티공사 제외 | F32: 설계외주
F33: 제작외주
F34: 전기외주
F35: 설치외주

Sheet 원가항목별(집계)
C2: A. 원가항목별 견적가 종합(상세견적 첨부)
B4: □ 현대/기아 요구사양과 견적조건 일치여부 CHECK: 1.일치함 2.일부상이(상이내역 첨부참조)
B6: 순번 | C6: 원가구분 | F6: 단위 | G6: 수량 | H6: 단가 | I6: 금 액(원) | J6: 비 고
B7: 1 | C7: 기계 부문 | D7: 자재비 | E7: 철자재(SS.SUS등) | F7: kg | G7: =단위장비1!F30+단위장비2!F30+단위장비3!F30+단위장비4!F30+단위장비5!F30+단위장비6!F30+단위장비7!F30+단위장비8!F30+단위장비9!F30+단위장비10!F30 -> 0 | I7: =단위장비1!H24+단위장비2!H24+단위장비3!H24+단위장비4!H24+단위장비5!H24+단위장비6!H24+단위장비7!H24+단위장비8!H24+단위장비9!H24+단위장비10!H24 -> 1200 | J7: 加工必要資材
E8: 일반구매품 | F8: 식 | G8: 1 | I8: =단위장비1!H46+단위장비2!H47+단위장비3!H47+단위장비4!H47+단위장비5!H47+단위장비6!H47+단위장비7!H47+단위장비8!H47+단위장비9!H47+단위장비10!H47 -> 750000 | J8: 加工不要資材
E9: 외주제작품 | F9: 식 | G9: 1 | I9: =단위장비1!H54+단위장비2!H55+단위장비3!H55+단위장비4!H55+단위장비5!H55+단위장비6!H55+단위장비7!H55+단위장비8!H55+단위장비9!H55+단위장비10!H55 -> 0 | J9: 旣加工SUB資材
E10: 설치/해체 공사 자재 | F10: 식 | G10: 1 | I10: =단위장비1!H30+단위장비2!H30+단위장비3!H30+단위장비4!H30+단위장비5!H30+단위장비6!H30+단위장비7!H30+단위장비8!H30+단위장비9!H30+단위장비10!H30 -> 810000 | J10: 시운전 자재 포함
E11: 소계 | I11: =SUM(I7:I10) -> 1561200
D12: 노무비 | E12: 기존설비 철거 | F12: M/D | G12: =단위장비1!F56+단위장비2!F57+단위장비3!F57+단위장비4!F57+단위장비5!F57+단위장비6!F57+단위장비7!F57+단위장비8!F57+단위장비9!F57+단위장비10!F57 -> 6 | H12: =IF(단위장비1!G56>0,단위장비1!G56,"") -> 350000 | I12: =단위장비1!H56+단위장비2!H57+단위장비3!H57+단위장비4!H57+단위장비5!H57+단위장비6!H57+단위장비7!H57+단위장비8!H57+단위장비9!H57+단위장비10!H57 -> 2100000 | J12: 개조공사時
E13: 설계 | F13: M/D | G13: =단위장비1!F57+단위장비2!F58+단위장비3!F58+단위장비4!F58+단위장비5!F58+단위장비6!F58+단위장비7!F58+단위장비8!F58+단위장비9!F58+단위장비10!F58 -> 25 | H13: =IF(단위장비1!G57>0,단위장비1!G57,"") -> 350000 | I13: =단위장비1!H57+단위장비2!H58+단위장비3!H58+단위장비4!H58+단위장비5!H58+단위장비6!H58+단위장비7!H58+단위장비8!H58+단위장비9!H58+단위장비10!H58 -> 8750000
E14: 제작(제관,가공) | F14: M/D | G14: =단위장비1!F58+단위장비2!F59+단위장비3!F59+단위장비4!F59+단위장비5!F59+단위장비6!F59+단위장비7!F59+단위장비8!F59+단위장비9!F59+단위장비10!F59 -> 8 | H14: =IF(단위장비1!G58>0,단위장비1!G58,"") -> 350000 | I14: =단위장비1!H58+단위장비2!H59+단위장비3!H59+단위장비4!H59+단위장비5!H59+단위장비6!H59+단위장비7!H59+단위장비8!H59+단위장비9!H59+단위장비10!H59 -> 2800000
E15: 조립 | F15: M/D | G15: =단위장비1!F59+단위장비2!F60+단위장비3!F60+단위장비4!F60+단위장비5!F60+단위장비6!F60+단위장비7!F60+단위장비8!F60+단위장비9!F60+단위장비10!F60 -> 75 | H15: =IF(단위장비1!G59>0,단위장비1!G59,"") -> 350000 | I15: =단위장비1!H59+단위장비2!H60+단위장비3!H60+단위장비4!H60+단위장비5!H60+단위장비6!H60+단위장비7!H60+단위장비8!H60+단위장비9!H60+단위장비10!H60 -> 26250000 | J15: 정도검사포함
E16: 설치 | F16: M/D | G16: =단위장비1!F60+단위장비2!F61+단위장비3!F61+단위장비4!F61+단위장비5!F61+단위장비6!F61+단위장비7!F61+단위장비8!F61+단위장비9!F61+단위장비10!F61 -> 8 | H16: =IF(단위장비1!G60>0,단위장비1!G60,"") -> 350000 | I16: =단위장비1!H60+단위장비2!H61+단위장비3!H61+단위장비4!H61+단위장비5!H61+단위장비6!H61+단위장비7!H61+단위장비8!H61+단위장비9!H61+단위장비10!H61 -> 2800000 | J16: 위아內 설치/시운전
E17: 시운전 | F17: M/D | G17: =단위장비1!F61+단위장비2!F62+단위장비3!F62+단위장비4!F62+단위장비5!F62+단위장비6!F62+단위장비7!F62+단위장비8!F62+단위장비9!F62+단위장비10!F62 -> 20 | H17: =IF(단위장비1!G61>0,단위장비1!G61,"") -> 350000 | I17: =단위장비1!H61+단위장비2!H62+단위장비3!H62+단위장비4!H62+단위장비5!H62+단위장비6!H62+단위장비7!H62+단위장비8!H62+단위장비9!H62+단위장비10!H62 -> 7000000
E18: 양산대응 | F18: M/D | G18: =단위장비1!F62+단위장비2!F63+단위장비3!F63+단위장비4!F63+단위장비5!F63+단위장비6!F63+단위장비7!F63+단위장비8!F63+단위장비9!F63+단위장비10!F63 -> 15 | H18: =IF(단위장비1!G62>0,단위장비1!G62,"") -> 350000 | I18: =단위장비1!H62+단위장비2!H63+단위장비3!H63+단위장비4!H63+단위장비5!H63+단위장비6!H63+단위장비7!H63+단위장비8!H63+단위장비9!H63+단위장비10!H63 -> 5250000
E19: 도장 | F19: M/D | G19: =단위장비1!F63+단위장비2!F64+단위장비3!F64+단위장비4!F64+단위장비5!F64+단위장비6!F64+단위장비7!F64+단위장비8!F64+단위장비9!F64+단위장비10!F64 -> 1 | H19: =IF(단위장비1!G63>0,단위장비1!G63,"") -> 2550000 | I19: =단위장비1!H63+단위장비2!H64+단위장비3!H64+단위장비4!H64+단위장비5!H64+단위장비6!H64+단위장비7!H64+단위장비8!H64+단위장비9!H64+단위장비10!H64 -> 2550000
E20: 소계 | I20: =SUM(I12:I19) -> 57500000
D21: 일반관리 및 이윤 | I21: =단위장비1!H66+단위장비1!H67+단위장비2!H67+단위장비2!H68+단위장비3!H67+단위장비3!H68+단위장비4!H67+단위장비4!H68+단위장비5!H67+단위장비5!H68+단위장비6!H67+단위장비6!H68+단위장비7!H67+단위장비7!H68+단위장비8!H67+단위장비8!H68+단위장비9!H67+단위장비9!H68+단위장비10!H67+단위장비10!H68 -> 21869168
E22: 기계 소계 | I22: =I20+I11+I21 -> 80930368
B23: 2 | C23: 전기 부문 | D23: 자재비 | E23: 기계/전기자재 | F23: 식 | G23: 1 | I23: =전기!H55 -> 6250000
E24: 설치/해체 공사 자재 | F24: 식 | G24: 1 | I24: =전기!H16 -> 80000 | J24: 시운전 자재 포함
D25: 노무비 | E25: 철거(개조시) | F25: M/D | G25: =전기!F56 -> 6 | H25: =IF(전기!G56>0,전기!G56,"") -> 350000 | I25: =전기!H56 -> 2100000
E26: 설계,프로그램 | F26: M/D | G26: =전기!F57 -> 10 | H26: =IF(전기!G57>0,전기!G57,"") -> 500000 | I26: =전기!H57 -> 5000000
E27: 제작 | F27: M/D | G27: =전기!F58 -> 0 | H27: =IF(전기!G58>0,전기!G58,"") -> 350000 | I27: =전기!H58 -> 0
E28: 조립 | F28: M/D | G28: =전기!F59 -> 10 | H28: =IF(전기!G59>0,전기!G59,"") -> 350000 | I28: =전기!H59 -> 3500000
E29: 설치 | F29: M/D | G29: =전기!F60 -> 4 | H29: =IF(전기!G60>0,전기!G60,"") -> 350000 | I29: =전기!H60 -> 1400000 | J29: 위아內 설치/시운전
E30: 시운전 | F30: M/D | G30: =전기!F61 -> 13 | H30: =IF(전기!G61>0,전기!G61,"") -> 500000 | I30: =전기!H61 -> 6500000
E31: 양산대응 | F31: M/D | G31: =전기!F62 -> 10 | H31: =IF(전기!G62>0,전기!G62,"") -> 500000 | I31: =전기!H62 -> 5000000
E32: 소계 | I32: =SUM(I25:I31) -> 23500000
D33: 일반관리 및 이윤 | I33: =전기!H65+전기!H66 -> 9545600
E34: 전기 소계 | I34: =I32+I23+I33+I24 -> 39375600
B35: 3 | C35: 자재비 합계 | I35: =I23+I11+I24 -> 7891200
C36: 노무비 합계 | I36: =I32+I20 -> 81000000
C37: 중간 합계 | I37: =I36+I35 -> 88891200
B38: 4 | C38: 포장,운송 및 중장비 사용료 | I38: 4000000
B39: 5 | C39: 표준안전관리비 | F39: 설치/철거/수리 0.4억 이상 | I39: =IF(J39<50000000,J39*0.0309,1)*IF(J39<4000000,0,1)+IF(J39>50000000,J39*0.0199+549900)*IF(J39<4000000,0,1)*IF(J39>500000000,0,1)+IF(J39>500000000,J39*0.021,0) -> 704211 | J39: =I30+I29+I25+I24+I17+I16+I12+I10 -> 22790000
B40: 6 | C40: 일반관리비 | I40: =전기!H65+단위장비1!H66+단위장비2!H67+단위장비3!H67+단위장비4!H67+단위장비5!H67+단위장비6!H67+단위장비7!H67+단위장비8!H67+단위장비9!H67+단위장비10!H67 -> 9770240
B41: 7 | C41: 이 윤 | I41: =전기!H66+단위장비1!H67+단위장비2!H68+단위장비3!H68+단위장비4!H68+단위장비5!H68+단위장비6!H68+단위장비7!H68+단위장비8!H68+단위장비9!H68+단위장비10!H68 -> 21644528
C42: 합 계 | F42: 3~7항 합계 | I42: =I22+I34+I38+I39 -> 125010179
B43: 주1. 표준안전관리비:(설치/철거/시운전 공사 관련 금액)의 ⓐ3.09%,ⓑ1.99%+기초액(5,499천원),ⓒ2.10%(50억 이상일경우)
...

Sheet 단위공사별(집계)
A2: B. 단위장비별 견적가 종합(상세견적 첨부)
N3: 단위:원
I5: 포장/운송 | L5: 표준안전 | M5: 일반관리비
A6: 순번 | B6: 단위장비명 | C6: 수량 | D6: 자재비 | E6: 철거 | F6: 제작 | G6: 설치/시운전 | H6: 양산대응 | I6: 중장비사용 | J6: 기계소계 | K6: 전기소계 | L6: 관리비 | M6: 이윤 | N6: 합 계 | O6: 비 고
A7: =IF(B7>0,1,"") -> 1 | B7: =단위장비1!C$1 -> DMG | C7: 1식 | D7: =단위장비1!H55 -> 1561200 | E7: =단위장비1!H56 -> 2100000 | F7: =단위장비1!H57+단위장비1!H58+단위장비1!H59+단위장비1!H63 -> 40350000 | G7: =단위장비1!H60+단위장비1!H61 -> 9800000 | H7: =단위장비1!H62 -> 5250000 | I7: =IF($B7>0,'원가항목별(집계)'!I$38*$P7/$P$17,0) -> 4000000 | J7: =SUM(D7:I7) -> 63061200 | K7: =IF(B7>0,'원가항목별(집계)'!I$34*P7/P$17,0) -> 39375600 | L7: =IF($B7>0,'원가항목별(집계)'!I$39*$P7/$P$17,0) -> 704211 | M7: =단위장비1!H66+단위장비1!H67 -> 21869168 | N7: =SUM(J7:M7) -> 125010179 | P7: =D7+E7+F7+G7+H7+M7 -> 80930368
A8: =IF(B8>0,A7+1,"") | B8: =단위장비2!C$1 -> 0 | C8: 1식 | D8: =단위장비2!H56 -> 0 | E8: =단위장비2!H57 -> 0 | F8: =단위장비2!H58+단위장비2!H59+단위장비2!H60+단위장비2!H64 -> 0 | G8: =단위장비2!H61+단위장비2!H62 -> 0 | H8: =단위장비2!H63 -> 0 | I8: =IF($B8>0,'원가항목별(집계)'!I$38*$P8/$P$17,0) -> 0 | J8: =SUM(D8:I8) -> 0 | K8: =IF(B8>0,'원가항목별(집계)'!I$34*P8/P$17,0) -> 0 | L8: =IF($B8>0,'원가항목별(집계)'!I$39*$P8/$P$17,0) -> 0 | M8: =단위장비2!H67+단위장비2!H68 -> 0 | N8: =SUM(J8:M8) -> 0 | P8: =D8+E8+F8+G8+H8+M8 -> 0
A9: =IF(B9>0,A8+1,"") | B9: =단위장비3!C$1 -> 0 | C9: 1식 | D9: =단위장비3!H56 -> 0 | E9: =단위장비3!H57 -> 0 | F9: =단위장비3!H58+단위장비3!H59+단위장비3!H60+단위장비3!H64 -> 0 | G9: =단위장비3!H61+단위장비3!H62 -> 0 | H9: =단위장비3!H63 -> 0 | I9: =IF($B9>0,'원가항목별(집계)'!I$38*$P9/$P$17,0) -> 0 | J9: =SUM(D9:I9) -> 0 | K9: =IF(B9>0,'원가항목별(집계)'!I$34*P9/P$17,0) -> 0 | L9: =IF($B9>0,'원가항목별(집계)'!I$39*$P9/$P$17,0) -> 0 | M9: =단위장비3!H67+단위장비3!H68 -> 0 | N9: =SUM(J9:M9) -> 0 | P9: =D9+E9+F9+G9+H9+M9 -> 0
A10: =IF(B10>0,A9+1,"") | B10: =단위장비4!C$1 -> 0 | C10: 1식 | D10: =단위장비4!H56 -> 0 | E10: =단위장비4!H57 -> 0 | F10: =단위장비4!H58+단위장비4!H59+단위장비4!H60+단위장비4!H64 -> 0 | G10: =단위장비4!H61+단위장비4!H62 -> 0 | H10: =단위장비4!H63 -> 0 | I10: =IF($B10>0,'원가항목별(집계)'!I$38*$P10/$P$17,0) -> 0 | J10: =SUM(D10:I10) -> 0 | K10: =IF(B10>0,'원가항목별(집계)'!I$34*P10/P$17,0) -> 0 | L10: =IF($B10>0,'원가항목별(집계)'!I$39*$P10/$P$17,0) -> 0 | M10: =단위장비4!H67+단위장비4!H68 -> 0 | N10: =SUM(J10:M10) -> 0 | P10: =D10+E10+F10+G10+H10+M10 -> 0
A11: =IF(B11>0,A10+1,"") | B11: =단위장비5!C$1 -> 0 | C11: 1식 | D11: =단위장비5!H56 -> 0 | E11: =단위장비5!H57 -> 0 | F11: =단위장비5!H58+단위장비5!H59+단위장비5!H60+단위장비5!H64 -> 0 | G11: =단위장비5!H61+단위장비5!H62 -> 0 | H11: =단위장비5!H63 -> 0 | I11: =IF($B11>0,'원가항목별(집계)'!I$38*$P11/$P$17,0) -> 0 | J11: =SUM(D11:I11) -> 0 | K11: =IF(B11>0,'원가항목별(집계)'!I$34*P11/P$17,0) -> 0 | L11: =IF($B11>0,'원가항목별(집계)'!I$39*$P11/$P$17,0) -> 0 | M11: =단위장비5!H67+단위장비5!H68 -> 0 | N11: =SUM(J11:M11) -> 0 | P11: =D11+E11+F11+G11+H11+M11 -> 0
A12: =IF(B12>0,A11+1,"") | B12: =단위장비6!C$1 -> 0 | C12: 1식 | D12: =단위장비6!H56 -> 0 | E12: =단위장비6!H57 -> 0 | F12: =단위장비6!H58+단위장비6!H59+단위장비6!H60+단위장비6!H64 -> 0 | G12: =단위장비6!H61+단위장비6!H62 -> 0 | H12: =단위장비6!H63 -> 0 | I12: =IF($B12>0,'원가항목별(집계)'!I$38*$P12/$P$17,0) -> 0 | J12: =SUM(D12:I12) -> 0 | K12: =IF(B12>0,'원가항목별(집계)'!I$34*P12/P$17,0) -> 0 | L12: =IF($B12>0,'원가항목별(집계)'!I$39*$P12/$P$17,0) -> 0 | M12: =단위장비6!H67+단위장비6!H68 -> 0 | N12: =SUM(J12:M12) -> 0 | P12: =D12+E12+F12+G12+H12+M12 -> 0
A13: =IF(B13>0,A8+1,"") | B13: =단위장비7!C$1 -> 0 | C13: 1식 | D13: =단위장비7!H56 -> 0 | E13: =단위장비7!H57 -> 0 | F13: =단위장비7!H58+단위장비7!H59+단위장비7!H60+단위장비7!H64 -> 0 | G13: =단위장비7!H61+단위장비7!H62 -> 0 | H13: =단위장비7!H63 -> 0 | I13: =IF($B13>0,'원가항목별(집계)'!I$38*$P13/$P$17,0) -> 0 | J13: =SUM(D13:I13) -> 0 | K13: =IF(B13>0,'원가항목별(집계)'!I$34*P13/P$17,0) -> 0 | L13: =IF($B13>0,'원가항목별(집계)'!I$39*$P13/$P$17,0) -> 0 | M13: =단위장비7!H67+단위장비7!H68 -> 0 | N13: =SUM(J13:M13) -> 0 | P13: =D13+E13+F13+G13+H13+M13 -> 0
A14: =IF(B14>0,A13+1,"") | B14: =단위장비8!C$1 -> 0 | C14: 1식 | D14: =단위장비8!H56 -> 0 | E14: =단위장비8!H57 -> 0 | F14: =단위장비8!H58+단위장비8!H59+단위장비8!H60+단위장비8!H64 -> 0 | G14: =단위장비8!H61+단위장비8!H62 -> 0 | H14: =단위장비8!H63 -> 0 | I14: =IF($B14>0,'원가항목별(집계)'!I$38*$P14/$P$17,0) -> 0 | J14: =SUM(D14:I14) -> 0 | K14: =IF(B14>0,'원가항목별(집계)'!I$34*P14/P$17,0) -> 0 | L14: =IF($B14>0,'원가항목별(집계)'!I$39*$P14/$P$17,0) -> 0 | M14: =단위장비8!H67+단위장비8!H68 -> 0 | N14: =SUM(J14:M14) -> 0 | P14: =D14+E14+F14+G14+H14+M14 -> 0
A15: =IF(B15>0,A14+1,"") | B15: =단위장비9!C$1 -> 0 | C15: 1식 | D15: =단위장비9!H57 -> 0 | E15: =단위장비9!H58 -> 0 | F15: =단위장비9!H59+단위장비9!H60+단위장비9!H61+단위장비9!H65 -> 0 | G15: =단위장비9!H62+단위장비9!H63 -> 0 | H15: =단위장비9!H64 -> 0 | I15: =IF($B15>0,'원가항목별(집계)'!I$38*$P15/$P$17,0) -> 0 | J15: =SUM(D15:I15) -> 0 | K15: =IF(B15>0,'원가항목별(집계)'!I$34*P15/P$17,0) -> 0 | L15: =IF($B15>0,'원가항목별(집계)'!I$39*$P15/$P$17,0) -> 0 | M15: =단위장비9!H68+단위장비9!H69 -> 0 | N15: =SUM(J15:M15) -> 0 | P15: =D15+E15+F15+G15+H15+M15 -> 0
A16: =IF(B16>0,A15+1,"") | B16: =단위장비10!C$1 -> 0 | C16: 1식 | D16: =단위장비10!H58 -> 0 | E16: =단위장비10!H59 -> 0 | F16: =단위장비10!H60+단위장비10!H61+단위장비10!H62+단위장비10!H66 -> 0 | G16: =단위장비10!H63+단위장비10!H64 -> 0 | H16: =단위장비10!H65 -> 0 | I16: =IF($B16>0,'원가항목별(집계)'!I$38*$P16/$P$17,0) -> 0 | J16: =SUM(D16:I16) -> 0 | K16: =IF(B16>0,'원가항목별(집계)'!I$34*P16/P$17,0) -> 0 | L16: =IF($B16>0,'원가항목별(집계)'!I$39*$P16/$P$17,0) -> 0 | M16: =단위장비10!H69+단위장비10!H70 -> 0 | N16: =SUM(J16:M16) -> 0 | P16: =D16+E16+F16+G16+H16+M16 -> 0
A17: 합 계 | D17: =SUM(D7:D16) -> 1561200 | E17: =SUM(E7:E16) -> 2100000 | F17: =SUM(F7:F16) -> 40350000 | G17: =SUM(G7:G16) -> 9800000 | H17: =SUM(H7:H16) -> 5250000 | I17: =SUM(I7:I16) -> 4000000 | J17: =SUM(D17:I17) -> 63061200 | K17: =SUM(K7:K16) -> 39375600 | L17: =SUM(L7:L16) -> 704211 | M17: =SUM(M7:M16) -> 21869168 | N17: =SUM(N7:N14) -> 125010179 | P17: =SUM(P7:P16) -> 80930368
D18: =IF(D17=0,"",D17/$N17) -> 0.012488583 | E18: =IF(E17=0,"",E17/$N17) -> 0.016798632 | F18: =IF(F17=0,"",F17/$N17) -> 0.32277372 | G18: =IF(G17=0,"",G17/$N17) -> 0.078393616 | H18: =IF(H17=0,"",H17/$N17) -> 0.04199658 | I18: =IF(I17=0,"",I17/$N17) -> 0.031997394 | J18: =IF(J17=0,"",J17/$N17) -> 0.50444852 | K18: =IF(K17=0,"",K17/$N17) -> 0.31497915 | ... N18: =IF(N17=0,"",N17/$N17) -> 1
A19: 주) 전기비용은 턴키장비의 공통비용으로서 총 전기비용을 단위장비별 기계금액의 비율에 따라 배분함
N20: =IF('원가항목별(집계)'!I42='단위공사별(집계)'!N17,"","DATA오류입니다!")

Sheet 전기
B1: □ 전기부문: | C1: 전기부문(공통) | I1: (첨부)
A2: 구분 | C2: 품 명 | D2: 규격 | E2: 단위 | F2: 수량 | G2: 단가(원) | H2: 금액(원) | I2: 原MAKER
A3: 자 재 비 | B3: 철자재 | H3: =IF(F3=0,G3,G3*F3) -> 0
H4: =IF(F4=0,G4,G4*F4) -> 0
H5: =IF(F5=0,G5,G5*F5) -> 0
H6: =IF(F6=0,G6,G6*F6) -> 0
H7: =IF(F7=0,G7,G7*F7) -> 0
C8: 기타자재 | H8: =IF(F8=0,G8,G8*F8) -> 0
H9: =SUM(H3:H8) -> 0
B10: 설치/해체/ | C10: 일회용 작업복 | E10: EA | F10: 8 | G10: 10000 | H10: =SUM(G10*F10) -> 80000
B11: 시운전 공사
B12: 자재
C15: 기타자재 | H15: =IF(F15=0,G15,G15*F15) -> 0
H16: =SUM(H10:H15) -> 80000
B17: 전기자재 | C17: LAPP CABLE | D17: 0.75*3C, 0.75*20C 외 | E17: 식 | F17: 1 | G17: 2800000 | H17: =IF(F17=0,G17,G17*F17) -> 2800000
C18: SENSOR CABLE | D18: M12-5M | E18: 식 | F18: 1 | G18: 500000 | H18: =IF(F18=0,G18,G18*F18) -> 500000
C19: WORK LIGHT | D19: 220V LED | E19: 식 | F19: 1 | G19: 90000 | H19: =IF(F19=0,G19,G19*F19) -> 90000
C20: 각종소모부품 | D20: 마그넷,단자대 외 | E20: 식 | F20: 1 | G20: 2300000 | H20: =IF(F20=0,G20,G20*F20) -> 2300000
H21: =IF(F21=0,G21,G21*F21) -> 0
H22: =IF(F22=0,G22,G22*F22) -> 0
H23: =IF(F23=0,G23,G23*F23) -> 0
H24: =IF(F24=0,G24,G24*F24) -> 0
H25: =IF(F25=0,G25,G25*F25) -> 0
H26: =IF(F26=0,G26,G26*F26) -> 0
H27: =IF(F27=0,G27,G27*F27) -> 0
H28: =IF(F28=0,G28,G28*F28) -> 0
H29: =IF(F29=0,G29,G29*F29) -> 0
H30: =IF(F30=0,G30,G30*F30) -> 0
H31: =IF(F31=0,G31,G31*F31) -> 0
H32: =IF(F32=0,G32,G32*F32) -> 0
... H52: =IF(F52=0,G52,G52*F52) -> 0
C53: 기타자재 | D53: 핀,타이 외 | E53: 식 | F53: 1 | G53: 480000 | H53: =IF(F53=0,G53,G53*F53) -> 480000
H54: =SUM(H17:H53) -> 6170000
B55: 자재비 소계 | H55: =SUM(H54,H9,H16) -> 6250000
A56: 노 무 비 | B56: 기존설비 분해 | E56: M/D | F56: 6 | G56: 350000 | H56: =F56*G56 -> 2100000
B57: 전기 설계/프로그램 | E57: M/D | F57: 10 | G57: 500000 | H57: =F57*G57 -> 5000000
B58: 전기 제작 | E58: M/D | F58: 0 | G58: 350000 | H58: =F58*G58 -> 0
B59: 전기 조립 | E59: M/D | F59: 10 | G59: 350000 | H59: =F59*G59 -> 3500000
B60: 전기 설치 | E60: M/D | F60: 4 | G60: 350000 | H60: =F60*G60 -> 1400000
B61: 전기 시운전 | E61: M/D | F61: 13 | G61: 500000 | H61: =F61*G61 -> 6500000
...

Sheet 단위장비1
B1: □ 단위공사명(전기제외): | C1: DMG | I1: (첨부)
A2: 구분 | C2: 품 명 | D2: 규격 | E2: 단위 | F2: 수량 | G2: 단가(원) | H2: 금액(원) | I2: 原MAKER
A3: 자 재 비 | B3: 철자재 | E3: Kg | G3: 1200 | H3: =IF(F3=0,G3,G3*F3) -> 1200
H4: =IF(F4=0,G4,G4*F4) -> 0
H5: =IF(F5=0,G5,G5*F5) -> 0
H6: =IF(F6=0,G6,G6*F6) -> 0
H7: =IF(F7=0,G7,G7*F7) -> 0
H8: =IF(F8=0,G8,G8*F8) -> 0
H9: =IF(F9=0,G9,G9*F9) -> 0
H10: =IF(F10=0,G10,G10*F10) -> 0
H11: =IF(F11=0,G11,G11*F11) -> 0
H12: =IF(F12=0,G12,G12*F12) -> 0
H13: =IF(F13=0,G13,G13*F13) -> 0
H14: =IF(F14=0,G14,G14*F14) -> 0
H15: =IF(F15=0,G15,G15*F15) -> 0
... H22: =IF(F22=0,G22,G22*F22) -> 0
C23: 기타자재 | H23: =IF(F23=0,G23,G23*F23) -> 0
H24: =SUM(H3:H23) -> 1200
B25: 설치/해체/시운전 | C25: 일회용 작업복 | F25: 24 | G25: 10000 | H25: =IF(F25=0,G25,G25*F25) -> 240000
B26: 공사 관련 자재 | C26: 흡착 부직포 | E26: SET | F26: 1 | G26: 120000 | H26: =IF(F26=0,G26,G26*F26) -> 120000
C27: 보루 | E27: 포 | F27: 5 | G27: 10000 | H27: =IF(F27=0,G27,G27*F27) -> 50000
C28: 세척제 외 | E28: 식 | F28: 1 | G28: 400000 | H28: =IF(F28=0,G28,G28*F28) -> 400000
C29: 기타자재 | H29: =IF(F29=0,G29,G29*F29) -> 0
H30: =SUM(H25:H29) -> 810000
B31: 구매품 | C31: 오링 | E31: 식 | F31: 1 | G31: 100000 | H31: =IF(F31=0,G31,G31*F31) -> 100000
B32: (유공압품외) | C32: 고압호스 | E32: 식 | F32: 1 | G32: 500000 | H32: =IF(F32=0,G32,G32*F32) -> 500000
H33: =IF(F33=0,G33,G33*F33) -> 0
H34: =IF(F34=0,G34,G34*F34) -> 0
H35: =IF(F35=0,G35,G35*F35) -> 0
H36: =IF(F36=0,G36,G36*F36) -> 0
H37: =IF(F37=0,G37,G37*F37) -> 0
H38: =IF(F38=0,G38,G38*F38) -> 0
H39: =IF(F39=0,G39,G39*F39) -> 0
H40: =IF(F40=0,G40,G40*F40) -> 0
H41: =IF(F41=0,G41,G41*F41) -> 0
H42: =IF(F42=0,G42,G42*F42) -> 0
H43: =IF(F43=0,G43,G43*F43) -> 0
H44: =IF(F44=0,G44,G44*F44) -> 0
C45: 기타자재 | D45: 소모부품 외 | E45: 식 | F45: 1 | G45: 150000 | H45: =IF(F45=0,G45,G45*F45) -> 150000
H46: =SUM(H31:H45) -> 750000
...

Sheet 단위장비2
B1: □ 단위공사명(전기제외): | I1: (첨부)
A2: 구분 | C2: 품 명 | D2: 규격 | E2: 단위 | F2: 수량 | G2: 단가(원) | H2: 금액(원) | I2: 原MAKER
A3: 자 재 비 | B3: 철자재 | H3: =IF(F3=0,G3,G3*F3) -> 0
H4: =IF(F4=0,G4,G4*F4) -> 0
H5: =IF(F5=0,G5,G5*F5) -> 0
H6: =IF(F6=0,G6,G6*F6) -> 0
H7: =IF(F7=0,G7,G7*F7) -> 0
H8: =IF(F8=0,G8,G8*F8) -> 0
H9: =IF(F9=0,G9,G9*F9) -> 0
H10: =IF(F10=0,G10,G10*F10) -> 0
H11: =IF(F11=0,G11,G11*F11) -> 0
H12: =IF(F12=0,G12,G12*F12) -> 0
H13: =IF(F13=0,G13,G13*F13) -> 0
H14: =IF(F14=0,G14,G14*F14) -> 0
H15: =IF(F15=0,G15,G15*F15) -> 0
... H22: =IF(F22=0,G22,G22*F22) -> 0
C23: 기타자재 | H23: =IF(F23=0,G23,G23*F23) -> 0
H24: =SUM(H3:H23) -> 0
B25: 설치/해체/시운전 | H25: =IF(F25=0,G25,G25*F25) -> 0
B26: 공사 관련 자재 | H26: =IF(F26=0,G26,G26*F26) -> 0
H27: =IF(F27=0,G27,G27*F27) -> 0
H28: =IF(F28=0,G28,G28*F28) -> 0
C29: 기타자재 | H29: =IF(F29=0,G29,G29*F29) -> 0
H30: =SUM(H25:H29) -> 0
B31: 구매품 | H31: =IF(F31=0,G31,G31*F31) -> 0
B32: (유공압품외) | H32: =IF(F32=0,G32,G32*F32) -> 0
H33: =IF(F33=0,G33,G33*F33) -> 0
H34: =IF(F34=0,G34,G34*F34) -> 0
H35: =IF(F35=0,G35,G35*F35) -> 0
H36: =IF(F36=0,G36,G36*F36) -> 0
H37: =IF(F37=0,G37,G37*F37) -> 0
H38: =IF(F38=0,G38,G38*F38) -> 0
H39: =IF(F39=0,G39,G39*F39) -> 0
H40: =IF(F40=0,G40,G40*F40) -> 0
H41: =IF(F41=0,G41,G41*F41) -> 0
H42: =IF(F42=0,G42,G42*F42) -> 0
H43: =IF(F43=0,G43,G43*F43) -> 0
H44: =IF(F44=0,G44,G44*F44) -> 0
H45: =IF(F45=0,G45,G45*F45) -> 0
C46: 기타자재 | H46: =IF(F46=0,G46,G46*F46) -> 0
...

Sheet 단위장비3
B1: □ 단위공사명(전기제외): | I1: (첨부)
A2: 구분 | C2: 품 명 | D2: 규격 | E2: 단위 | F2: 수량 | G2: 단가(원) | H2: 금액(원) | I2: 原MAKER
A3: 자 재 비 | B3: 철자재 | H3: =IF(F3=0,G3,G3*F3) -> 0
H4: =IF(F4=0,G4,G4*F4) -> 0
H5: =IF(F5=0,G5,G5*F5) -> 0
H6: =IF(F6=0,G6,G6*F6) -> 0
H7: =IF(F7=0,G7,G7*F7) -> 0
H8: =IF(F8=0,G8,G8*F8) -> 0
H9: =IF(F9=0,G9,G9*F9) -> 0
H10: =IF(F10=0,G10,G10*F10) -> 0
H11: =IF(F11=0,G11,G11*F11) -> 0
H12: =IF(F12=0,G12,G12*F12) -> 0
H13: =IF(F13=0,G13,G13*F13) -> 0
H14: =IF(F14=0,G14,G14*F14) -> 0
H15: =IF(F15=0,G15,G15*F15) -> 0
... H22: =IF(F22=0,G22,G22*F22) -> 0
C23: 기타자재 | H23: =IF(F23=0,G23,G23*F23) -> 0
H24: =SUM(H3:H23) -> 0
B25: 설치/해체/시운전 | H25: =IF(F25=0,G25,G25*F25) -> 0
B26: 공사 관련 자재 | H26: =IF(F26=0,G26,G26*F26) -> 0
H27: =IF(F27=0,G27,G27*F27) -> 0
H28: =IF(F28=0,G28,G28*F28) -> 0
C29: 기타자재 | H29: =IF(F29=0,G29,G29*F29) -> 0
H30: =SUM(H25:H29) -> 0
B31: 구매품 | H31: =IF(F31=0,G31,G31*F31) -> 0
B32: (유공압품외) | H32: =IF(F32=0,G32,G32*F32) -> 0
H33: =IF(F33=0,G33,G33*F33) -> 0
H34: =IF(F34=0,G34,G34*F34) -> 0
H35: =IF(F35=0,G35,G35*F35) -> 0
H36: =IF(F36=0,G36,G36*F36) -> 0
H37: =IF(F37=0,G37,G37*F37) -> 0
H38: =IF(F38=0,G38,G38*F38) -> 0
H39: =IF(F39=0,G39,G39*F39) -> 0
H40: =IF(F40=0,G40,G40*F40) -> 0
H41: =IF(F41=0,G41,G41*F41) -> 0
H42: =IF(F42=0,G42,G42*F42) -> 0
H43: =IF(F43=0,G43,G43*F43) -> 0
H44: =IF(F44=0,G44,G44*F44) -> 0
H45: =IF(F45=0,G45,G45*F45) -> 0
C46: 기타자재 | H46: =IF(F46=0,G46,G46*F46) -> 0
...

Sheet 단위장비4
B1: □ 단위공사명(전기제외): | I1: (첨부)
A2: 구분 | C2: 품 명 | D2: 규격 | E2: 단위 | F2: 수량 | G2: 단가(원) | H2: 금액(원) | I2: 原MAKER
A3: 자 재 비 | B3: 철자재 | H3: =IF(F3=0,G3,G3*F3) -> 0
H4: =IF(F4=0,G4,G4*F4) -> 0
H5: =IF(F5=0,G5,G5*F5) -> 0
H6: =IF(F6=0,G6,G6*F6) -> 0
H7: =IF(F7=0,G7,G7*F7) -> 0
H8: =IF(F8=0,G8,G8*F8) -> 0
H9: =IF(F9=0,G9,G9*F9) -> 0
H10: =IF(F10=0,G10,G10*F10) -> 0
H11: =IF(F11=0,G11,G11*F11) -> 0
H12: =IF(F12=0,G12,G12*F12) -> 0
H13: =IF(F13=0,G13,G13*F13) -> 0
H14: =IF(F14=0,G14,G14*F14) -> 0
H15: =IF(F15=0,G15,G15*F15) -> 0
... H22: =IF(F22=0,G22,G22*F22) -> 0
C23: 기타자재 | H23: =IF(F23=0,G23,G23*F23) -> 0
H24: =SUM(H3:H23) -> 0
B25: 설치/해체/시운전 | H25: =IF(F25=0,G25,G25*F25) -> 0
B26: 공사 관련 자재 | H26: =IF(F26=0,G26,G26*F26) -> 0
H27: =IF(F27=0,G27,G27*F27) -> 0
H28: =IF(F28=0,G28,G28*F28) -> 0
C29: 기타자재 | H29: =IF(F29=0,G29,G29*F29) -> 0
H30: =SUM(H25:H29) -> 0
B31: 구매품 | H31: =IF(F31=0,G31,G31*F31) -> 0
B32: (유공압품외) | H32: =IF(F32=0,G32,G32*F32) -> 0
H33: =IF(F33=0,G33,G33*F33) -> 0
H34: =IF(F34=0,G34,G34*F34) -> 0
H35: =IF(F35=0,G35,G35*F35) -> 0
H36: =IF(F36=0,G36,G36*F36) -> 0
H37: =IF(F37=0,G37,G37*F37) -> 0
H38: =IF(F38=0,G38,G38*F38) -> 0
H39: =IF(F39=0,G39,G39*F39) -> 0
H40: =IF(F40=0,G40,G40*F40) -> 0
H41: =IF(F41=0,G41,G41*F41) -> 0
H42: =IF(F42=0,G42,G42*F42) -> 0
H43: =IF(F43=0,G43,G43*F43) -> 0
H44: =IF(F44=0,G44,G44*F44) -> 0
H45: =IF(F45=0,G45,G45*F45) -> 0
C46: 기타자재 | H46: =IF(F46=0,G46,G46*F46) -> 0
...

Sheet 단위장비5
B1: □ 단위공사명(전기제외): | I1: (첨부)
A2: 구분 | C2: 품 명 | D2: 규격 | E2: 단위 | F2: 수량 | G2: 단가(원) | H2: 금액(원) | I2: 原MAKER
A3: 자 재 비 | B3: 철자재 | H3: =IF(F3=0,G3,G3*F3) -> 0
H4: =IF(F4=0,G4,G4*F4) -> 0
H5: =IF(F5=0,G5,G5*F5) -> 0
H6: =IF(F6=0,G6,G6*F6) -> 0
H7: =IF(F7=0,G7,G7*F7) -> 0
H8: =IF(F8=0,G8,G8*F8) -> 0
H9: =IF(F9=0,G9,G9*F9) -> 0
H10: =IF(F10=0,G10,G10*F10) -> 0
H11: =IF(F11=0,G11,G11*F11) -> 0
H12: =IF(F12=0,G12,G12*F12) -> 0
H13: =IF(F13=0,G13,G13*F13) -> 0
H14: =IF(F14=0,G14,G14*F14) -> 0
H15: =IF(F15=0,G15,G15*F15) -> 0
... H22: =IF(F22=0,G22,G22*F22) -> 0
C23: 기타자재 | H23: =IF(F23=0,G23,G23*F23) -> 0
H24: =SUM(H3:H23) -> 0
B25: 설치/해체/시운전 | H25: =IF(F25=0,G25,G25*F25) -> 0
B26: 공사 관련 자재 | H26: =IF(F26=0,G26,G26*F26) -> 0
H27: =IF(F27=0,G27,G27*F27) -> 0
H28: =IF(F28=0,G28,G28*F28) -> 0
C29: 기타자재 | H29: =IF(F29=0,G29,G29*F29) -> 0
H30: =SUM(H25:H29) -> 0
B31: 구매품 | H31: =IF(F31=0,G31,G31*F31) -> 0
B32: (유공압품외) | H32: =IF(F32=0,G32,G32*F32) -> 0
H33: =IF(F33=0,G33,G33*F33) -> 0
H34: =IF(F34=0,G34,G34*F34) -> 0
H35: =IF(F35=0,G35,G35*F35) -> 0
H36: =IF(F36=0,G36,G36*F36) -> 0
H37: =IF(F37=0,G37,G37*F37) -> 0
H38: =IF(F38=0,G38,G38*F38) -> 0
H39: =IF(F39=0,G39,G39*F39) -> 0
H40: =IF(F40=0,G40,G40*F40) -> 0
H41: =IF(F41=0,G41,G41*F41) -> 0
H42: =IF(F42=0,G42,G42*F42) -> 0
H43: =IF(F43=0,G43,G43*F43) -> 0
H44: =IF(F44=0,G44,G44*F44) -> 0
H45: =IF(F45=0,G45,G45*F45) -> 0
C46: 기타자재 | H46: =IF(F46=0,G46,G46*F46) -> 0
...

Sheet 단위장비6
B1: □ 단위공사명(전기제외): | I1: (첨부)
A2: 구분 | C2: 품 명 | D2: 규격 | E2: 단위 | F2: 수량 | G2: 단가(원) | H2: 금액(원) | I2: 原MAKER
A3: 자 재 비 | B3: 철자재 | H3: =IF(F3=0,G3,G3*F3) -> 0
H4: =IF(F4=0,G4,G4*F4) -> 0
H5: =IF(F5=0,G5,G5*F5) -> 0
H6: =IF(F6=0,G6,G6*F6) -> 0
H7: =IF(F7=0,G7,G7*F7) -> 0
H8: =IF(F8=0,G8,G8*F8) -> 0
H9: =IF(F9=0,G9,G9*F9) -> 0
H10: =IF(F10=0,G10,G10*F10) -> 0
H11: =IF(F11=0,G11,G11*F11) -> 0
H12: =IF(F12=0,G12,G12*F12) -> 0
H13: =IF(F13=0,G13,G13*F13) -> 0
H14: =IF(F14=0,G14,G14*F14) -> 0
H15: =IF(F15=0,G15,G15*F15) -> 0
... H22: =IF(F22=0,G22,G22*F22) -> 0
C23: 기타자재 | H23: =IF(F23=0,G23,G23*F23) -> 0
H24: =SUM(H3:H23) -> 0
B25: 설치/해체/시운전 | H25: =IF(F25=0,G25,G25*F25) -> 0
B26: 공사 관련 자재 | H26: =IF(F26=0,G26,G26*F26) -> 0
H27: =IF(F27=0,G27,G27*F27) -> 0
H28: =IF(F28=0,G28,G28*F28) -> 0
C29: 기타자재 | H29: =IF(F29=0,G29,G29*F29) -> 0
H30: =SUM(H25:H29) -> 0
B31: 구매품 | H31: =IF(F31=0,G31,G31*F31) -> 0
B32: (유공압품외) | H32: =IF(F32=0,G32,G32*F32) -> 0
H33: =IF(F33=0,G33,G33*F33) -> 0
H34: =IF(F34=0,G34,G34*F34) -> 0
H35: =IF(F35=0,G35,G35*F35) -> 0
H36: =IF(F36=0,G36,G36*F36) -> 0
H37: =IF(F37=0,G37,G37*F37) -> 0
H38: =IF(F38=0,G38,G38*F38) -> 0
H39: =IF(F39=0,G39,G39*F39) -> 0
H40: =IF(F40=0,G40,G40*F40) -> 0
H41: =IF(F41=0,G41,G41*F41) -> 0
H42: =IF(F42=0,G42,G42*F42) -> 0
H43: =IF(F43=0,G43,G43*F43) -> 0
H44: =IF(F44=0,G44,G44*F44) -> 0
H45: =IF(F45=0,G45,G45*F45) -> 0
C46: 기타자재 | H46: =IF(F46=0,G46,G46*F46) -> 0
...

Sheet 단위장비7
B1: □ 단위공사명(전기제외): | I1: (첨부)
A2: 구분 | C2: 품 명 | D2: 규격 | E2: 단위 | F2: 수량 | G2: 단가(원) | H2: 금액(원) | I2: 原MAKER
A3: 자 재 비 | B3: 철자재 | H3: =IF(F3=0,G3,G3*F3) -> 0
H4: =IF(F4=0,G4,G4*F4) -> 0
H5: =IF(F5=0,G5,G5*F5) -> 0
H6: =IF(F6=0,G6,G6*F6) -> 0
H7: =IF(F7=0,G7,G7*F7) -> 0
H8: =IF(F8=0,G8,G8*F8) -> 0
H9: =IF(F9=0,G9,G9*F9) -> 0
H10: =IF(F10=0,G10,G10*F10) -> 0
H11: =IF(F11=0,G11,G11*F11) -> 0
H12: =IF(F12=0,G12,G12*F12) -> 0
H13: =IF(F13=0,G13,G13*F13) -> 0
H14: =IF(F14=0,G14,G14*F14) -> 0
H15: =IF(F15=0,G15,G15*F15) -> 0
... H22: =IF(F22=0,G22,G22*F22) -> 0
C23: 기타자재 | H23: =IF(F23=0,G23,G23*F23) -> 0
H24: =SUM(H3:H23) -> 0
B25: 설치/해체/시운전 | H25: =IF(F25=0,G25,G25*F25) -> 0
B26: 공사 관련 자재 | H26: =IF(F26=0,G26,G26*F26) -> 0
H27: =IF(F27=0,G27,G27*F27) -> 0
H28: =IF(F28=0,G28,G28*F28) -> 0
C29: 기타자재 | H29: =IF(F29=0,G29,G29*F29) -> 0
H30: =SUM(H25:H29) -> 0
B31: 구매품 | H31: =IF(F31=0,G31,G31*F31) -> 0
B32: (유공압품외) | H32: =IF(F32=0,G32,G32*F32) -> 0
H33: =IF(F33=0,G33,G33*F33) -> 0
H34: =IF(F34=0,G34,G34*F34) -> 0
H35: =IF(F35=0,G35,G35*F35) -> 0
H36: =IF(F36=0,G36,G36*F36) -> 0
H37: =IF(F37=0,G37,G37*F37) -> 0
H38: =IF(F38=0,G38,G38*F38) -> 0
H39: =IF(F39=0,G39,G39*F39) -> 0
H40: =IF(F40=0,G40,G40*F40) -> 0
H41: =IF(F41=0,G41,G41*F41) -> 0
H42: =IF(F42=0,G42,G42*F42) -> 0
H43: =IF(F43=0,G43,G43*F43) -> 0
H44: =IF(F44=0,G44,G44*F44) -> 0
H45: =IF(F45=0,G45,G45*F45) -> 0
C46: 기타자재 | H46: =IF(F46=0,G46,G46*F46) -> 0
...

Sheet 단위장비8
B1: □ 단위공사명(전기제외): | I1: (첨부)
A2: 구분 | C2: 품 명 | D2: 규격 | E2: 단위 | F2: 수량 | G2: 단가(원) | H2: 금액(원) | I2: 原MAKER
A3: 자 재 비 | B3: 철자재 | H3: =IF(F3=0,G3,G3*F3) -> 0
H4: =IF(F4=0,G4,G4*F4) -> 0
H5: =IF(F5=0,G5,G5*F5) -> 0
H6: =IF(F6=0,G6,G6*F6) -> 0
H7: =IF(F7=0,G7,G7*F7) -> 0
H8: =IF(F8=0,G8,G8*F8) -> 0
H9: =IF(F9=0,G9,G9*F9) -> 0
H10: =IF(F10=0,G10,G10*F10) -> 0
H11: =IF(F11=0,G11,G11*F11) -> 0
H12: =IF(F12=0,G12,G12*F12) -> 0
H13: =IF(F13=0,G13,G13*F13) -> 0
H14: =IF(F14=0,G14,G14*F14) -> 0
H15: =IF(F15=0,G15,G15*F15) -> 0
... H22: =IF(F22=0,G22,G22*F22) -> 0
C23: 기타자재 | H23: =IF(F23=0,G23,G23*F23) -> 0
H24: =SUM(H3:H23) -> 0
B25: 설치/해체/시운전 | H25: =IF(F25=0,G25,G25*F25) -> 0
B26: 공사 관련 자재 | H26: =IF(F26=0,G26,G26*F26) -> 0
H27: =IF(F27=0,G27,G27*F27) -> 0
H28: =IF(F28=0,G28,G28*F28) -> 0
C29: 기타자재 | H29: =IF(F29=0,G29,G29*F29) -> 0
H30: =SUM(H25:H29) -> 0
B31: 구매품 | H31: =IF(F31=0,G31,G31*F31) -> 0
B32: (유공압품외) | H32: =IF(F32=0,G32,G32*F32) -> 0
H33: =IF(F33=0,G33,G33*F33) -> 0
H34: =IF(F34=0,G34,G34*F34) -> 0
H35: =IF(F35=0,G35,G35*F35) -> 0
H36: =IF(F36=0,G36,G36*F36) -> 0
H37: =IF(F37=0,G37,G37*F37) -> 0
H38: =IF(F38=0,G38,G38*F38) -> 0
H39: =IF(F39=0,G39,G39*F39) -> 0
H40: =IF(F40=0,G40,G40*F40) -> 0
H41: =IF(F41=0,G41,G41*F41) -> 0
H42: =IF(F42=0,G42,G42*F42) -> 0
H43: =IF(F43=0,G43,G43*F43) -> 0
H44: =IF(F44=0,G44,G44*F44) -> 0
H45: =IF(F45=0,G45,G45*F45) -> 0
C46: 기타자재 | H46: =IF(F46=0,G46,G46*F46) -> 0
...

Sheet 단위장비9
B1: □ 단위공사명(전기제외): | I1: (첨부)
A2: 구분 | C2: 품 명 | D2: 규격 | E2: 단위 | F2: 수량 | G2: 단가(원) | H2: 금액(원) | I2: 原MAKER
A3: 자 재 비 | B3: 철자재 | H3: =IF(F3=0,G3,G3*F3) -> 0
H4: =IF(F4=0,G4,G4*F4) -> 0
H5: =IF(F5=0,G5,G5*F5) -> 0
H6: =IF(F6=0,G6,G6*F6) -> 0
H7: =IF(F7=0,G7,G7*F7) -> 0
H8: =IF(F8=0,G8,G8*F8) -> 0
H9: =IF(F9=0,G9,G9*F9) -> 0
H10: =IF(F10=0,G10,G10*F10) -> 0
H11: =IF(F11=0,G11,G11*F11) -> 0
H12: =IF(F12=0,G12,G12*F12) -> 0
H13: =IF(F13=0,G13,G13*F13) -> 0
H14: =IF(F14=0,G14,G14*F14) -> 0
H15: =IF(F15=0,G15,G15*F15) -> 0
... H22: =IF(F22=0,G22,G22*F22) -> 0
C23: 기타자재 | H23: =IF(F23=0,G23,G23*F23) -> 0
H24: =SUM(H3:H23) -> 0
B25: 설치/해체/시운전 | H25: =IF(F25=0,G25,G25*F25) -> 0
B26: 공사 관련 자재 | H26: =IF(F26=0,G26,G26*F26) -> 0
H27: =IF(F27=0,G27,G27*F27) -> 0
H28: =IF(F28=0,G28,G28*F28) -> 0
C29: 기타자재 | H29: =IF(F29=0,G29,G29*F29) -> 0
H30: =SUM(H25:H29) -> 0
B31: 구매품 | H31: =IF(F31=0,G31,G31*F31) -> 0
B32: (유공압품외) | H32: =IF(F32=0,G32,G32*F32) -> 0
H33: =IF(F33=0,G33,G33*F33) -> 0
H34: =IF(F34=0,G34,G34*F34) -> 0
H35: =IF(F35=0,G35,G35*F35) -> 0
H36: =IF(F36=0,G36,G36*F36) -> 0
H37: =IF(F37=0,G37,G37*F37) -> 0
H38: =IF(F38=0,G38,G38*F38) -> 0
H39: =IF(F39=0,G39,G39*F39) -> 0
H40: =IF(F40=0,G40,G40*F40) -> 0
H41: =IF(F41=0,G41,G41*F41) -> 0
H42: =IF(F42=0,G42,G42*F42) -> 0
H43: =IF(F43=0,G43,G43*F43) -> 0
H44: =IF(F44=0,G44,G44*F44) -> 0
H45: =IF(F45=0,G45,G45*F45) -> 0
C46: 기타자재 | H46: =IF(F46=0,G46,G46*F46) -> 0
...

Sheet 단위장비10
B1: □ 단위공사명(전기제외): | I1: (첨부)
A2: 구분 | C2: 품 명 | D2: 규격 | E2: 단위 | F2: 수량 | G2: 단가(원) | H2: 금액(원) | I2: 原MAKER
A3: 자 재 비 | B3: 철자재 | H3: =IF(F3=0,G3,G3*F3) -> 0
H4: =IF(F4=0,G4,G4*F4) -> 0
H5: =IF(F5=0,G5,G5*F5) -> 0
H6: =IF(F6=0,G6,G6*F6) -> 0
H7: =IF(F7=0,G7,G7*F7) -> 0
H8: =IF(F8=0,G8,G8*F8) -> 0
H9: =IF(F9=0,G9,G9*F9) -> 0
H10: =IF(F10=0,G10,G10*F10) -> 0
H11: =IF(F11=0,G11,G11*F11) -> 0
H12: =IF(F12=0,G12,G12*F12) -> 0
H13: =IF(F13=0,G13,G13*F13) -> 0
H14: =IF(F14=0,G14,G14*F14) -> 0
H15: =IF(F15=0,G15,G15*F15) -> 0
... H22: =IF(F22=0,G22,G22*F22) -> 0
C23: 기타자재 | H23: =IF(F23=0,G23,G23*F23) -> 0
H24: =SUM(H3:H23) -> 0
B25: 설치/해체/시운전 | H25: =IF(F25=0,G25,G25*F25) -> 0
B26: 공사 관련 자재 | H26: =IF(F26=0,G26,G26*F26) -> 0
H27: =IF(F27=0,G27,G27*F27) -> 0
H28: =IF(F28=0,G28,G28*F28) -> 0
C29: 기타자재 | H29: =IF(F29=0,G29,G29*F29) -> 0
H30: =SUM(H25:H29) -> 0
B31: 구매품 | H31: =IF(F31=0,G31,G31*F31) -> 0
B32: (유공압품외) | H32: =IF(F32=0,G32,G32*F32) -> 0
H33: =IF(F33=0,G33,G33*F33) -> 0
H34: =IF(F34=0,G34,G34*F34) -> 0
H35: =IF(F35=0,G35,G35*F35) -> 0
H36: =IF(F36=0,G36,G36*F36) -> 0
H37: =IF(F37=0,G37,G37*F37) -> 0
H38: =IF(F38=0,G38,G38*F38) -> 0
H39: =IF(F39=0,G39,G39*F39) -> 0
H40: =IF(F40=0,G40,G40*F40) -> 0
H41: =IF(F41=0,G41,G41*F41) -> 0
H42: =IF(F42=0,G42,G42*F42) -> 0
H43: =IF(F43=0,G43,G43*F43) -> 0
H44: =IF(F44=0,G44,G44*F44) -> 0
H45: =IF(F45=0,G45,G45*F45) -> 0
C46: 기타자재 | H46: =IF(F46=0,G46,G46*F46) -> 0
...

Sheet 첨부(견적조건차이내역)
A1: ※ 현대/기아차의 요구사양과 업체견적사양이 다른경우만 작성
D2: (첨부)
A3: 현대/기아차 요구사양대비 견적조건 상이내역
A5: 항 목 | B5: 현대/기아차 요구사양 | C5: 업체 견적기준 사양 | D5: 비 고
