Workbook

Sheet 갑지
B1: (현대/기아차 설비협력업체 견적통일양식)
B2: 見 積 書
B4: 현대위아(주) 貴下 | G4: ㈜동서기전
B5: 견적일자 | D5: 45744 | G5: 대표 : 김 연 규 (인)
B6: 견적번호 | D6: QZ250304-03 | G6: 주소 : 창원시 의창구 북면 동전산단동로12번길45
B7: 납기 | C7: 입하 | D7: 2025-06-31 | G7: 전화: 82-55-297-3115
C8: 최종검수 | D8: 45843 | G8: Fax: 82-55-296-3669
B9: 견적유효기간 | D9: 견적일로부터30일 | G9: E-mail: chrcho@dongseomecha.co.kr
B10: 인도장소 | D10: 창원3공장 | G10: 견적담당: 조 충 래 상무
B11: 담 당 자 | D11: 설비구매팀/박혜인 님 | G11: 연 락 처 : 82-55-290-3232
B13: 공 사 명: | D13: CT CVJ 생산준비 대응 스태킹 설비 리툴링 件
B14: 최종견적금액: | D14: ="一金"&NUMBERSTRING(H28*1000,1)&"원整 ("&TEXT(H28*1000,"\#,#)") -> 一金일억삼천팔백칠십만원整 (₩138,700,000)
B16: 번호 | C16: 상세품목내역 | E16: 견적금액 (천원) | I16: 비 고
E17: 기계부문 | F17: 전기부문 | G17: 관리/이윤 (안전관리비포함) | H17: 합 계
B18: 1 | C18: =IF('단위공사별(집계)'!N7>0,'단위공사별(집계)'!B7,"") -> 투입 CONVEYOR | E18: =IF('단위공사별(집계)'!N7>1,('단위공사별(집계)'!D7+'단위공사별(집계)'!E7+'단위공사별(집계)'!F7+'단위공사별(집계)'!G7+'단위공사별(집계)'!H7+'단위공사별(집계)'!I7)/1000," ") -> 48190.072 | F18: =IF('단위공사별(집계)'!N7>0,'단위공사별(집계)'!K17/1000,"") -> 39445 | G18: =IF('단위공사별(집계)'!N7>0,('단위공사별(집계)'!L7+'단위공사별(집계)'!M7)/1000,"") -> 7407.0332 | H18: =IF('단위공사별(집계)'!N7>0,'단위공사별(집계)'!N7/1000,"") -> 77691.99
B19: 2 | C19: =IF('단위공사별(집계)'!N8>0,'단위공사별(집계)'!B8,"") -> 스태킹 M/C 개조 | E19: =IF('단위공사별(집계)'!N8>1,('단위공사별(집계)'!D8+'단위공사별(집계)'!E8+'단위공사별(집계)'!F8+'단위공사별(집계)'!G8+'단위공사별(집계)'!H8+'단위공사별(집계)'!I8)/1000," ") -> 37835.928 | G19: =IF('단위공사별(집계)'!N8>0,('단위공사별(집계)'!L8+'단위공사별(집계)'!M8)/1000,"") -> 5821.9668 | H19: =IF('단위공사별(집계)'!N8>0,'단위공사별(집계)'!N8/1000,"") -> 61008.01
B20: 3 | C20: =IF('단위공사별(집계)'!N9>0,'단위공사별(집계)'!B9,"") | E20: =IF('단위공사별(집계)'!N9>1,('단위공사별(집계)'!D9+'단위공사별(집계)'!E9+'단위공사별(집계)'!F9+'단위공사별(집계)'!G9+'단위공사별(집계)'!H9+'단위공사별(집계)'!I9)/1000," ") | G20: =IF('단위공사별(집계)'!N9>0,('단위공사별(집계)'!L9+'단위공사별(집계)'!M9)/1000,"") | H20: =IF('단위공사별(집계)'!N9>0,'단위공사별(집계)'!N9/1000,"")
B21: 4 | C21: =IF('단위공사별(집계)'!N10>0,'단위공사별(집계)'!B10,"") | E21: =IF('단위공사별(집계)'!N10>1,('단위공사별(집계)'!D10+'단위공사별(집계)'!E10+'단위공사별(집계)'!F10+'단위공사별(집계)'!G10+'단위공사별(집계)'!H10+'단위공사별(집계)'!I10)/1000," ") | G21: =IF('단위공사별(집계)'!N10>0,('단위공사별(집계)'!L10+'단위공사별(집계)'!M10)/1000,"") | H21: =IF('단위공사별(집계)'!N10>0,'단위공사별(집계)'!N10/1000,"")
B22: 5 | C22: =IF('단위공사별(집계)'!N11>0,'단위공사별(집계)'!B11,"") | E22: =IF('단위공사별(집계)'!N11>1,('단위공사별(집계)'!D11+'단위공사별(집계)'!E11+'단위공사별(집계)'!F11+'단위공사별(집계)'!G11+'단위공사별(집계)'!H11+'단위공사별(집계)'!I11)/1000," ") | G22: =IF('단위공사별(집계)'!N11>0,('단위공사별(집계)'!L11+'단위공사별(집계)'!M11)/1000,"") | H22: =IF('단위공사별(집계)'!N11>0,'단위공사별(집계)'!N11/1000,"")
B23: 6 | C23: =IF('단위공사별(집계)'!N12>0,'단위공사별(집계)'!B12,"") | E23: =IF('단위공사별(집계)'!N12>1,('단위공사별(집계)'!D12+'단위공사별(집계)'!E12+'단위공사별(집계)'!F12+'단위공사별(집계)'!G12+'단위공사별(집계)'!H12+'단위공사별(집계)'!I12)/1000," ") | G23: =IF('단위공사별(집계)'!N12>0,('단위공사별(집계)'!L12+'단위공사별(집계)'!M12)/1000,"") | H23: =IF('단위공사별(집계)'!N12>0,'단위공사별(집계)'!N12/1000,"")
B24: 7 | C24: =IF('단위공사별(집계)'!N13>0,'단위공사별(집계)'!B13,"") | E24: =IF('단위공사별(집계)'!N13>1,('단위공사별(집계)'!D13+'단위공사별(집계)'!E13+'단위공사별(집계)'!F13+'단위공사별(집계)'!G13+'단위공사별(집계)'!H13+'단위공사별(집계)'!I13)/1000," ") | G24: =IF('단위공사별(집계)'!N13>0,('단위공사별(집계)'!L13+'단위공사별(집계)'!M13)/1000,"") | H24: =IF('단위공사별(집계)'!N13>0,'단위공사별(집계)'!N13/1000,"")
B25: 8 | C25: =IF('단위공사별(집계)'!N14>0,'단위공사별(집계)'!B14,"") | E25: =IF('단위공사별(집계)'!N14>1,('단위공사별(집계)'!D14+'단위공사별(집계)'!E14+'단위공사별(집계)'!F14+'단위공사별(집계)'!G14+'단위공사별(집계)'!H14+'단위공사별(집계)'!I14)/1000," ") | G25: =IF('단위공사별(집계)'!N14>0,('단위공사별(집계)'!L14+'단위공사별(집계)'!M14)/1000,"") | H25: =IF('단위공사별(집계)'!N14>0,'단위공사별(집계)'!N14/1000,"")
B26: 9 | C26: =IF('단위공사별(집계)'!N15>0,'단위공사별(집계)'!B15,"") | E26: =IF('단위공사별(집계)'!N15>1,('단위공사별(집계)'!D15+'단위공사별(집계)'!E15+'단위공사별(집계)'!F15+'단위공사별(집계)'!G15+'단위공사별(집계)'!H15+'단위공사별(집계)'!I15)/1000," ") | G26: =IF('단위공사별(집계)'!N15>0,('단위공사별(집계)'!L15+'단위공사별(집계)'!M15)/1000,"") | H26: =IF('단위공사별(집계)'!N15>0,'단위공사별(집계)'!N15/1000,"")
B27: 10 | C27: =IF('단위공사별(집계)'!N16>0,'단위공사별(집계)'!B16,"") | E27: =IF('단위공사별(집계)'!N16>1,('단위공사별(집계)'!D16+'단위공사별(집계)'!E16+'단위공사별(집계)'!F16+'단위공사별(집계)'!G16+'단위공사별(집계)'!H16+'단위공사별(집계)'!I16)/1000," ") | G27: =IF('단위공사별(집계)'!N16>0,('단위공사별(집계)'!L16+'단위공사별(집계)'!M16)/1000,"") | H27: =IF('단위공사별(집계)'!N16>0,'단위공사별(집계)'!N16/1000,"")
B28: 견적 합계 | E28: =SUM(E18:E24) -> 86026 | F28: =SUM(F18:F24) -> 39445 | G28: =SUM(G18:G24) -> 13229 | H28: =SUM(H18:H24) -> 138700
F30: 공개입찰가 (견적時 공란)
B32: 특기사항 | C32: 1. VAT 제외 | F32: 외주계획 업체명 (자작時 공란)
C33: 2. 기본 유틸리티공사 제외 | F33: 설계외주
C34: 3. 서보 프레스 셋팅 제외 | F34: 제작외주
F35: 전기외주
F36: 설치외주

Sheet 원가항목별(집계)
C2: A. 원가항목별 견적가 종합(상세견적 첨부)
B4: □ 현대/기아 요구사양과 견적조건 일치여부 CHECK: 1.일치함 2.일부상이(상이내역 첨부참조)
B6: 순번 | C6: 원가구분 | F6: 단위 | G6: 수량 | H6: 단가 | I6: 금 액(원) | J6: 비 고
B7: 1 | C7: 기계 부문 | D7: 자재비 | E7: 철자재(SS.SUS등) | F7: kg | G7: =단위장비1!F17+단위장비2!F15+단위장비3!F16+단위장비4!F16+단위장비5!F16+단위장비6!F16+단위장비7!F16+단위장비8!F30+단위장비9!F30+단위장비10!F30 -> 0 | I7: =단위장비1!H11+단위장비2!H9+단위장비3!H10+단위장비4!H10+단위장비5!H10+단위장비6!H10+단위장비7!H10+단위장비8!H24+단위장비9!H24+단위장비10!H24 -> 0 | J7: 加工必要資材
E8: 일반구매품 | F8: 식 | G8: 1 | I8: =단위장비1!H37+단위장비2!H33+단위장비3!H34+단위장비4!H33+단위장비5!H33+단위장비6!H33+단위장비7!H33+단위장비8!H47+단위장비9!H47+단위장비10!H47 -> 26650000 | J8: 加工不要資材
E9: 외주제작품 | F9: 식 | G9: 1 | I9: =단위장비1!H53+단위장비2!H52+단위장비3!H52+단위장비4!H52+단위장비5!H52+단위장비6!H52+단위장비7!H52+단위장비8!H55+단위장비9!H55+단위장비10!H55 -> 30126000 | J9: 旣加工SUB資材
E10: 설치/해체 공사 자재 | F10: 식 | G10: 1 | I10: =단위장비1!H17+단위장비2!H15+단위장비3!H16+단위장비4!H16+단위장비5!H16+단위장비6!H16+단위장비7!H16+단위장비8!H30+단위장비9!H30+단위장비10!H30 -> 0 | J10: 시운전 자재 포함
E11: 소계 | I11: =SUM(I7:I10) -> 56776000
D12: 노무비 | E12: 기존설비 철거 | F12: M/D | G12: =단위장비1!F55+단위장비2!F54+단위장비3!F54+단위장비4!F54+단위장비5!F54+단위장비6!F54+단위장비7!F54+단위장비8!F57+단위장비9!F57+단위장비10!F57 -> 6 | H12: =IF(단위장비1!G55>0,단위장비1!G55,"") -> 300000 | I12: =단위장비1!H55+단위장비2!H54+단위장비3!H54+단위장비4!H54+단위장비5!H54+단위장비6!H54+단위장비7!H54+단위장비8!H57+단위장비9!H57+단위장비10!H57 -> 1800000 | J12: 개조공사時
E13: 설계 | F13: M/D | G13: =단위장비1!F56+단위장비2!F55+단위장비3!F55+단위장비4!F55+단위장비5!F55+단위장비6!F55+단위장비7!F55+단위장비8!F58+단위장비9!F58+단위장비10!F58 -> 35 | H13: =IF(단위장비1!G56>0,단위장비1!G56,"") -> 350000 | I13: =단위장비1!H56+단위장비2!H55+단위장비3!H55+단위장비4!H55+단위장비5!H55+단위장비6!H55+단위장비7!H55+단위장비8!H58+단위장비9!H58+단위장비10!H58 -> 12250000
E14: 제작(제관,가공) | F14: M/D | G14: =단위장비1!F57+단위장비2!F56+단위장비3!F56+단위장비4!F56+단위장비5!F56+단위장비6!F56+단위장비7!F56+단위장비8!F59+단위장비9!F59+단위장비10!F59 -> 9 | H14: =IF(단위장비1!G57>0,단위장비1!G57,"") -> 300000 | I14: =단위장비1!H57+단위장비2!H56+단위장비3!H56+단위장비4!H56+단위장비5!H56+단위장비6!H56+단위장비7!H56+단위장비8!H59+단위장비9!H59+단위장비10!H59 -> 2700000
E15: 조립 | F15: M/D | G15: =단위장비1!F58+단위장비2!F57+단위장비3!F57+단위장비4!F57+단위장비5!F57+단위장비6!F57+단위장비7!F57+단위장비8!F60+단위장비9!F60+단위장비10!F60 -> 11 | H15: =IF(단위장비1!G58>0,단위장비1!G58,"") -> 300000 | I15: =단위장비1!H58+단위장비2!H57+단위장비3!H57+단위장비4!H57+단위장비5!H57+단위장비6!H57+단위장비7!H57+단위장비8!H60+단위장비9!H60+단위장비10!H60 -> 3300000 | J15: 정도검사포함
E16: 설치 | F16: M/D | G16: =단위장비1!F59+단위장비2!F58+단위장비3!F58+단위장비4!F58+단위장비5!F58+단위장비6!F58+단위장비7!F58+단위장비8!F61+단위장비9!F61+단위장비10!F61 -> 10 | H16: =IF(단위장비1!G59>0,단위장비1!G59,"") -> 300000 | I16: =단위장비1!H59+단위장비2!H58+단위장비3!H58+단위장비4!H58+단위장비5!H58+단위장비6!H58+단위장비7!H58+단위장비8!H61+단위장비9!H61+단위장비10!H61 -> 3000000
E17: 시운전 | F17: M/D | G17: =단위장비1!F60+단위장비2!F59+단위장비3!F59+단위장비4!F59+단위장비5!F59+단위장비6!F59+단위장비7!F59+단위장비8!F62+단위장비9!F62+단위장비10!F62 -> 8 | H17: =IF(단위장비1!G60>0,단위장비1!G60,"") -> 300000 | I17: =단위장비1!H60+단위장비2!H59+단위장비3!H59+단위장비4!H59+단위장비5!H59+단위장비6!H59+단위장비7!H59+단위장비8!H62+단위장비9!H62+단위장비10!H62 -> 2400000
E18: 양산대응 | F18: M/D | G18: =단위장비1!F61+단위장비2!F60+단위장비3!F60+단위장비4!F60+단위장비5!F60+단위장비6!F60+단위장비7!F60+단위장비8!F63+단위장비9!F63+단위장비10!F63 -> 6 | H18: =IF(단위장비1!G61>0,단위장비1!G61,"") -> 300000 | I18: =단위장비1!H61+단위장비2!H60+단위장비3!H60+단위장비4!H60+단위장비5!H60+단위장비6!H60+단위장비7!H60+단위장비8!H63+단위장비9!H63+단위장비10!H63 -> 1800000
E19: 도장 | F19: M/D | G19: =단위장비1!F62+단위장비2!F61+단위장비3!F61+단위장비4!F61+단위장비5!F61+단위장비6!F61+단위장비7!F61+단위장비8!F64+단위장비9!F64+단위장비10!F64 -> 5 | H19: =IF(단위장비1!G62>0,단위장비1!G62,"") -> 300000 | I19: =단위장비1!H62+단위장비2!H61+단위장비3!H61+단위장비4!H61+단위장비5!H61+단위장비6!H61+단위장비7!H61+단위장비8!H64+단위장비9!H64+단위장비10!H64 -> 1500000
E20: 소계 | I20: =SUM(I12:I19) -> 28750000
D21: 일반관리 및 이윤 | I21: =단위장비1!H65+단위장비1!H66+단위장비2!H64+단위장비2!H65+단위장비3!H64+단위장비3!H65+단위장비4!H64+단위장비4!H65+단위장비5!H64+단위장비5!H65+단위장비6!H64+단위장비6!H65+단위장비7!H64+단위장비7!H65+단위장비8!H67+단위장비8!H68+단위장비9!H67+단위장비9!H68+단위장비10!H67+단위장비10!H68 -> 12820760
E22: 기계 소계 | I22: =I20+I11+I21 -> 98346760
B23: 2 | C23: 전기 부문 | D23: 자재비 | E23: 기계/전기자재 | F23: 식 | G23: 1 | I23: =전기!H54-I24 -> 19800000
E24: 설치/해체 공사 자재 | F24: 식 | G24: 1 | I24: =전기!H16 -> 0 | J24: 시운전 자재 포함
D25: 노무비 | E25: 철거(개조시) | F25: M/D | G25: =전기!F55 -> 3 | H25: =IF(전기!G55>0,전기!G55,"") -> 300000 | I25: =전기!H55 -> 900000
E26: 설계,프로그램 | F26: M/D | G26: =전기!F56 -> 20 | H26: =IF(전기!G56>0,전기!G56,"") -> 350000 | I26: =전기!H56 -> 7000000
E27: 제작 | F27: M/D | G27: =전기!F57 -> 5 | H27: =IF(전기!G57>0,전기!G57,"") -> 300000 | I27: =전기!H57 -> 1500000
E28: 조립 | F28: M/D | G28: =전기!F58 -> 5 | H28: =IF(전기!G58>0,전기!G58,"") -> 300000 | I28: =전기!H58 -> 1500000
E29: 설치 | F29: M/D | G29: =전기!F59 -> 6 | H29: =IF(전기!G59>0,전기!G59,"") -> 300000 | I29: =전기!H59 -> 1800000
E30: 시운전 | F30: M/D | G30: =전기!F60 -> 3 | H30: =IF(전기!G60>0,전기!G60,"") -> 300000 | I30: =전기!H60 -> 900000
E31: 양산대응 | F31: M/D | G31: =전기!F61 -> 3 | H31: =IF(전기!G61>0,전기!G61,"") -> 300000 | I31: =전기!H61 -> 900000
E32: 소계 | I32: =SUM(I25:I31) -> 14500000
D33: 일반관리 및 이윤 | I33: =전기!H64+전기!H65 -> 5145000
E34: 전기 소계 | I34: =I32+I23+I33+I24 -> 39445000
B35: 3 | C35: 자재비 합계 | I35: =I23+I11+I24 -> 76576000
C36: 노무비 합계 | I36: =I32+I20 -> 43250000
C37: 중간 합계 | I37: =I36+I35 -> 119826000
B38: 4 | C38: 포장,운송 및 중장비 사용료 | I38: 500000
B39: 5 | C39: 표준안전관리비 | F39: 설치/철거/수리금액 기준 | I39: =(IF(J48<500000000,J48*0.0315,1)+IF(J48>500000000,J48*0.0199+5499000)*IF(J48>5000000000,0,1)+IF(J48>5000000000,J48*0.021,0))*1.2 -> 408240 | J39: =I30+I29+I25+I24+I17+I16+I12+I10 -> 10800000
B40: 6 | C40: 일반관리비 | I40: =전기!H64+단위장비1!H65+단위장비2!H64+단위장비3!H64+단위장비4!H64+단위장비5!H64+단위장비6!H64+단위장비7!H64+단위장비8!H67+단위장비9!H67+단위장비10!H67 -> 5991300
B41: 7 | C41: 이 윤 | I41: =전기!H65+단위장비1!H66+단위장비2!H65+단위장비3!H65+단위장비4!H65+단위장비5!H65+단위장비6!H65+단위장비7!H65+단위장비8!H68+단위장비9!H68+단위장비10!H68 -> 11974460
C42: 합 계 | F42: 3~7항 합계 | I42: =I22+I34+I38+I39 -> 138700000
B43: 주1. 표준안전관리비:(설치/철거/시운전 공사 관련 금액)의 ⓐ2.66%,ⓑ1.95%+기초액,ⓒ2.02%(50억 이상일경우)
...

Sheet 단위공사별(집계)
A2: B. 단위장비별 견적가 종합(상세견적 첨부)
N3: 단위:원
I5: 포장/운송 | L5: 표준안전 | M5: 일반관리비
A6: 순번 | B6: 단위장비명 | C6: 수량 | D6: 자재비 | E6: 철거 | F6: 제작 | G6: 설치/시운전 | H6: 양산대응 | I6: 중장비사용 | J6: 기계소계 | K6: 전기소계 | L6: 관리비 | M6: 이윤 | N6: 합 계 | O6: 비 고
A7: =IF(B7>0,1,"") -> 1 | B7: =단위장비1!C1 -> 투입 CONVEYOR | C7: 1식 | D7: =단위장비1!H54 -> 34260000 | E7: =단위장비1!H55 -> 900000 | F7: =단위장비1!H56+단위장비1!H57+단위장비1!H58+단위장비1!H62 -> 8850000 | G7: =단위장비1!H59+단위장비1!H60 -> 3000000 | H7: =단위장비1!H61 -> 900000 | I7: =IF($B7>0,'원가항목별(집계)'!I$38*$P7/$P$17,0) -> 280072.06 | J7: =SUM(D7:I7) -> 48190072 | K7: =IF(B7>0,'원가항목별(집계)'!I$34*P7/P$17,0) -> 22094885 | L7: =IF($B7>0,'원가항목별(집계)'!I$39*$P7/$P$17,0) -> 228673.24 | M7: =단위장비1!H65+단위장비1!H66 -> 7178360 | N7: =SUM(J7:M7) -> 77691990 | P7: =D7+E7+F7+G7+H7+M7 -> 55088360
A8: =IF(B8>0,A7+1,"") -> 2 | B8: =단위장비2!C1 -> 스태킹 M/C 개조 | C8: 1식 | D8: =단위장비2!H53 -> 22516000 | E8: =단위장비2!H54 -> 900000 | F8: =단위장비2!H55+단위장비2!H56+단위장비2!H57+단위장비2!H61 -> 10900000 | G8: =단위장비2!H58+단위장비2!H59 -> 2400000 | H8: =단위장비2!H60 -> 900000 | I8: =IF($B8>0,'원가항목별(집계)'!I$38*$P8/$P$17,0) -> 219927.94 | J8: =SUM(D8:I8) -> 37835928 | K8: =IF(B8>0,'원가항목별(집계)'!I$34*P8/P$17,0) -> 17350115 | L8: =IF($B8>0,'원가항목별(집계)'!I$39*$P8/$P$17,0) -> 179566.76 | M8: =단위장비2!H64+단위장비2!H65 -> 5642400 | N8: =SUM(J8:M8) -> 61008010 | P8: =D8+E8+F8+G8+H8+M8 -> 43258400
A9: =IF(B9>0,A8+1,"") | B9: =단위장비3!C1 -> 0 | C9: 1식 | D9: =단위장비3!H53 -> 0 | E9: =단위장비3!H54 -> 0 | F9: =단위장비3!H55+단위장비3!H56+단위장비3!H57+단위장비3!H61 -> 0 | G9: =단위장비3!H58+단위장비3!H59 -> 0 | H9: =단위장비3!H60 -> 0 | I9: =IF($B9>0,'원가항목별(집계)'!I$38*$P9/$P$17,0) -> 0 | J9: =SUM(D9:I9) -> 0 | K9: =IF(B9>0,'원가항목별(집계)'!I$34*P9/P$17,0) -> 0 | L9: =IF($B9>0,'원가항목별(집계)'!I$39*$P9/$P$17,0) -> 0 | M9: =단위장비3!H64+단위장비3!H65 -> 0 | N9: =SUM(J9:M9) -> 0 | P9: =D9+E9+F9+G9+H9+M9 -> 0
A10: =IF(B10>0,A9+1,"") | B10: =단위장비4!C$1 -> 0 | C10: 1식 | D10: =단위장비4!H53 -> 0 | E10: =단위장비4!H54 -> 0 | F10: =단위장비4!H55+단위장비4!H56+단위장비4!H57+단위장비4!H61 -> 0 | G10: =단위장비4!H58+단위장비4!H59 -> 0 | H10: =단위장비4!H60 -> 0 | I10: =IF($B10>0,'원가항목별(집계)'!I$38*$P10/$P$17,0) -> 0 | J10: =SUM(D10:I10) -> 0 | K10: =IF(B10>0,'원가항목별(집계)'!I$34*P10/P$17,0) -> 0 | L10: =IF($B10>0,'원가항목별(집계)'!I$39*$P10/$P$17,0) -> 0 | M10: =단위장비4!H64+단위장비4!H65 -> 0 | N10: =SUM(J10:M10) -> 0 | P10: =D10+E10+F10+G10+H10+M10 -> 0
A11: =IF(B11>0,A10+1,"") | B11: =단위장비5!C$1 -> 0 | C11: 1식 | D11: =단위장비5!H53 -> 0 | E11: =단위장비5!H54 -> 0 | F11: =단위장비5!H55+단위장비5!H56+단위장비5!H57+단위장비5!H61 -> 0 | G11: =단위장비5!H58+단위장비5!H59 -> 0 | H11: =단위장비5!H60 -> 0 | I11: =IF($B11>0,'원가항목별(집계)'!I$38*$P11/$P$17,0) -> 0 | J11: =SUM(D11:I11) -> 0 | K11: =IF(B11>0,'원가항목별(집계)'!I$34*P11/P$17,0) -> 0 | L11: =IF($B11>0,'원가항목별(집계)'!I$39*$P11/$P$17,0) -> 0 | M11: =단위장비5!H64+단위장비5!H65 -> 0 | N11: =SUM(J11:M11) -> 0 | P11: =D11+E11+F11+G11+H11+M11 -> 0
A12: =IF(B12>0,A11+1,"") | B12: =단위장비6!C$1 -> 0 | C12: 1식 | D12: =단위장비6!H53 -> 0 | E12: =단위장비6!H54 -> 0 | F12: =단위장비6!H55+단위장비6!H56+단위장비6!H57+단위장비6!H61 -> 0 | G12: =단위장비6!H58+단위장비6!H59 -> 0 | H12: =단위장비6!H60 -> 0 | I12: =IF($B12>0,'원가항목별(집계)'!I$38*$P12/$P$17,0) -> 0 | J12: =SUM(D12:I12) -> 0 | K12: =IF(B12>0,'원가항목별(집계)'!I$34*P12/P$17,0) -> 0 | L12: =IF($B12>0,'원가항목별(집계)'!I$39*$P12/$P$17,0) -> 0 | M12: =단위장비6!H64+단위장비6!H65 -> 0 | N12: =SUM(J12:M12) -> 0 | P12: =D12+E12+F12+G12+H12+M12 -> 0
A13: =IF(B13>0,A8+1,"") | B13: =단위장비7!C$1 -> 0 | C13: 1식 | D13: =단위장비7!H53 -> 0 | E13: =단위장비7!H54 -> 0 | F13: =단위장비7!H55+단위장비7!H56+단위장비7!H57+단위장비7!H61 -> 0 | G13: =단위장비7!H58+단위장비7!H59 -> 0 | H13: =단위장비7!H60 -> 0 | I13: =IF($B13>0,'원가항목별(집계)'!I$38*$P13/$P$17,0) -> 0 | J13: =SUM(D13:I13) -> 0 | K13: =IF(B13>0,'원가항목별(집계)'!I$34*P13/P$17,0) -> 0 | L13: =IF($B13>0,'원가항목별(집계)'!I$39*$P13/$P$17,0) -> 0 | M13: =단위장비7!H64+단위장비7!H65 -> 0 | N13: =SUM(J13:M13) -> 0 | P13: =D13+E13+F13+G13+H13+M13 -> 0
A14: =IF(B14>0,A13+1,"") | B14: =단위장비8!C$1 -> 0 | C14: 1식 | D14: =단위장비8!H56 -> 0 | E14: =단위장비8!H57 -> 0 | F14: =단위장비8!H58+단위장비8!H59+단위장비8!H60+단위장비8!H64 -> 0 | G14: =단위장비8!H61+단위장비8!H62 -> 0 | H14: =단위장비8!H63 -> 0 | I14: =IF($B14>0,'원가항목별(집계)'!I$38*$P14/$P$17,0) -> 0 | J14: =SUM(D14:I14) -> 0 | K14: =IF(B14>0,'원가항목별(집계)'!I$34*P14/P$17,0) -> 0 | L14: =IF($B14>0,'원가항목별(집계)'!I$39*$P14/$P$17,0) -> 0 | M14: =단위장비8!H67+단위장비8!H68 -> 0 | N14: =SUM(J14:M14) -> 0 | P14: =D14+E14+F14+G14+H14+M14 -> 0
A15: =IF(B15>0,A14+1,"") | B15: =단위장비9!C$1 -> 0 | C15: 1식 | D15: =단위장비9!H57 -> 0 | E15: =단위장비9!H58 -> 0 | F15: =단위장비9!H59+단위장비9!H60+단위장비9!H61+단위장비9!H65 -> 0 | G15: =단위장비9!H62+단위장비9!H63 -> 0 | H15: =단위장비9!H64 -> 0 | I15: =IF($B15>0,'원가항목별(집계)'!I$38*$P15/$P$17,0) -> 0 | J15: =SUM(D15:I15) -> 0 | K15: =IF(B15>0,'원가항목별(집계)'!I$34*P15/P$17,0) -> 0 | L15: =IF($B15>0,'원가항목별(집계)'!I$39*$P15/$P$17,0) -> 0 | M15: =단위장비9!H68+단위장비9!H69 -> 0 | N15: =SUM(J15:M15) -> 0 | P15: =D15+E15+F15+G15+H15+M15 -> 0
A16: =IF(B16>0,A15+1,"") | B16: =단위장비10!C$1 -> 0 | C16: 1식 | D16: =단위장비10!H58 -> 0 | E16: =단위장비10!H59 -> 0 | F16: =단위장비10!H60+단위장비10!H61+단위장비10!H62+단위장비10!H66 -> 0 | G16: =단위장비10!H63+단위장비10!H64 -> 0 | H16: =단위장비10!H65 -> 0 | I16: =IF($B16>0,'원가항목별(집계)'!I$38*$P16/$P$17,0) -> 0 | J16: =SUM(D16:I16) -> 0 | K16: =IF(B16>0,'원가항목별(집계)'!I$34*P16/P$17,0) -> 0 | L16: =IF($B16>0,'원가항목별(집계)'!I$39*$P16/$P$17,0) -> 0 | M16: =단위장비10!H69+단위장비10!H70 -> 0 | N16: =SUM(J16:M16) -> 0 | P16: =D16+E16+F16+G16+H16+M16 -> 0
A17: 합 계 | D17: =SUM(D7:D16) -> 56776000 | E17: =SUM(E7:E16) -> 1800000 | F17: =SUM(F7:F16) -> 19750000 | G17: =SUM(G7:G16) -> 5400000 | H17: =SUM(H7:H16) -> 1800000 | I17: =SUM(I7:I16) -> 500000 | J17: =SUM(D17:I17) -> 86026000 | K17: =SUM(K7:K16) -> 39445000 | L17: =SUM(L7:L16) -> 408240 | M17: =SUM(M7:M16) -> 12820760 | N17: =SUM(N7:N14) -> 138700000 | P17: =D17+E17+F17+G17+H17+M17 -> 98346760
D18: =IF(D17=0,"",D17/$N17) -> 0.40934391 | E18: =IF(E17=0,"",E17/$N17) -> 0.01297765 | F18: =IF(F17=0,"",F17/$N17) -> 0.14239366 | G18: =IF(G17=0,"",G17/$N17) -> 0.038932949 | H18: =IF(H17=0,"",H17/$N17) -> 0.01297765 | I18: =IF(I17=0,"",I17/$N17) -> 0.0036049027 | J18: =IF(J17=0,"",J17/$N17) -> 0.62023071 | K18: =IF(K17=0,"",K17/$N17) -> 0.28439077 | ... N18: =IF(N17=0,"",N17/$N17) -> 1
A19: 주) 전기비용은 턴키장비의 공통비용으로서 총 전기비용을 단위장비별 기계금액의 비율에 따라 배분함

Sheet 전기
B1: □ 전기부문: | C1: 전기부문(공통) | I1: (첨부)
A2: 구분 | C2: 품 명 | D2: 규격 | E2: 단위 | F2: 수량 | G2: 단가(원) | H2: 금액(원) | I2: 原MAKER
A3: 자 재 비 | B3: 철자재
H9: =SUM(H3:H8) -> 0
B10: 설치/해체/
B11: 시운전 공사
B12: 자재
C15: 기타자재
H16: =SUM(H10:H15) -> 0
B17: 전기자재 | C17: PLC - Q13UDEH CPU SERIES 미즈비시 | H17: =F17*G17 -> 0
C18: - PLC-BASE
C19: - PLC-POWER
C20: - PLC-CPU
C21: - PLC-INPUT
C22: - PLC-OUTPUT
C23: - PLC-REMOTE IO
C24: - PLC-REMOTE IO
C25: - PLC-DATA LINK
C26: - PLC용 기타 액세서리 | D26: QD77MS16 | E26: 식 | F26: 1 | G26: 2000000 | H26: =F26*G26 -> 2000000 | I26: MITSUBISHI
C27: 일반구매품 | E27: 식 | F27: 1 | G27: 2000000 | H27: =F27*G27 -> 2000000
C28: - ELB | I28: LS 산전
C29: - NF | I29: 운영전기
C30: - RELAY | I30: OMRON
C31: - EOCR | I31: SCHNEIDER
C32: - PIN BOX | I32: 건흥
C34: DATA PC | D34: IAT-PPC-6191C-DS717 | E34: 식 | F34: 1 | G34: 3500000 | H34: =F34*G34 -> 3500000 | I34: ADVANTECH
C36: 결선 자재 | E36: 식 | F36: 1 | G36: 1000000 | H36: =F36*G36 -> 1000000
C37: 기타 구매 | E37: 식 | F37: 1 | G37: 500000 | H37: =F37*G37 -> 500000
H38: =SUM(H17:H37) -> 9000000
B39: 외주제작품 | C39: MAIN CONTROL PANEL | E39: 식 | G39: 2500000 | H39: =F39*G39 -> 0
C40: RTB BOX | E40: 식 | F40: 1 | G40: 750000 | H40: =F40*G40 -> 750000 | I40: 동서
C41: OP BOX | E41: 식 | G41: 600000 | H41: =F41*G41 -> 0
C42: DUCT 작업 | E42: 식 | F42: 1 | G42: 500000 | H42: =F42*G42 -> 500000 | I42: 동서
C43: PC BOX | E43: 식 | F43: 1 | G43: 650000 | H43: =F43*G43 -> 650000 | I43: 동서
C48: PC 프로그램 | E48: M/D | F48: 21 | G48: 400000 | H48: =F48*G48 -> 8400000
C52: 기타 제작 | E52: 식 | F52: 1 | G52: 500000 | H52: =F52*G52 -> 500000
H53: =SUM(H39:H52) -> 10800000
B54: 자재비 소계 | H54: =SUM(H53,H9,H38) -> 19800000
A55: 노 무 비 | B55: 기존설비 철거 | E55: M/D | F55: 3 | G55: 300000 | H55: =F55*G55 -> 900000
B56: 전기 설계/프로그램 | E56: M/D | F56: 20 | G56: 350000 | H56: =F56*G56 -> 7000000
...

Sheet 단위장비1
B1: □ 단위공사명(전기제외): | C1: 투입 CONVEYOR | I1: (첨부)
A2: 구분 | C2: 품 명 | D2: 규격 | E2: 단위 | F2: 수량 | G2: 단가(원) | H2: 금액(원) | I2: 原MAKER
A3: 자 재 비 | B3: 철자재 | C3: FRAME 류 | D3: SS400 | E3: KG | G3: 1500 | H3: =F3*G3 -> 0
C4: PLATE 류 | D4: SS400 | E4: KG | G4: 1500 | H4: =F4*G4 -> 0
C5: BLOCK 류 | D5: SS400 | E5: KG | G5: 1500 | H5: =F5*G5 -> 0
C10: 기타자재 | E10: 식 | G10: 100000 | H10: =F10*G10 -> 0
H11: =SUM(H3:H10) -> 0
B12: 설치/해체/시운전 | C12: 해제작업 거치대
B13: 공사 관련 자재
C16: 기타자재
H17: =SUM(H12:H16) -> 0
B18: 구매품 | C18: SERVO MOTOR & AMP | D18: HG-KR43BJK | E18: 식 | F18: 2 | G18: 1440000 | H18: =F18*G18 -> 2880000 | I18: MITSUBISHI
B19: (유공압품외) | C19: SERVO CYLINDER | D19: LEFS40NZA | E19: 식 | F19: 4 | G19: 1360000 | H19: =IF(F19=0,G19,G19*F19) -> 5440000 | I19: SMC
C20: 2D 코드 리더기 | D20: SRX300급 | E20: 식 | F20: 1 | G20: 5000000 | H20: =IF(F20=0,G20,G20*F20) -> 5000000 | I20: 키엔스
C21: AIR CYLINDER | D21: CA2F63 | E21: 식 | F21: 5 | G21: 144000 | H21: =IF(F21=0,G21,G21*F21) -> 720000 | I21: SMC
C22: GUIDE CYLINDER | D22: MGPM40 | E22: 식 | F22: 2 | G22: 360000 | H22: =IF(F22=0,G22,G22*F22) -> 720000 | I22: SMC
C23: BALL SCREW | D23: BTK2005-2.6ZZ | E23: 식 | F23: 1 | G23: 300000 | H23: =IF(F23=0,G23,G23*F23) -> 300000 | I23: THK
C24: LINEAR BUSH+SHAFT | D24: LHICD16+E-PSFJ16 | E24: 식 | F24: 4 | G24: 96000 | H24: =IF(F24=0,G24,G24*F24) -> 384000 | I24: MISUMI
C25: HANDLE | D25: AHLNAK80-10 | E25: 식 | F25: 1 | G25: 36000 | H25: =IF(F25=0,G25,G25*F25) -> 36000 | I25: MISUMI
C26: BALL BUSH | D26: LMF20LUU | E26: 식 | F26: 2 | G26: 30000 | H26: =IF(F26=0,G26,G26*F26) -> 60000 | I26: THK
C27: 회전 실린더 | D27: MSQB50A | E27: 식 | F27: 1 | G27: 700000 | H27: =IF(F27=0,G27,G27*F27) -> 700000 | I27: SMC
C28: LM GUIDE+RAIL | D28: HSR35A2QZUU | E28: 식 | F28: 4 | G28: 500000 | H28: =IF(F28=0,G28,G28*F28) -> 2000000 | I28: THK
C29: AIR FINGER | D29: AF02-40 | E29: 식 | F29: 3 | G29: 670000 | H29: =IF(F29=0,G29,G29*F29) -> 2010000 | I29: JRT
C30: SOL V/V | D30: VQC4201 | E30: 식 | F30: 10 | G30: 120000 | H30: =IF(F30=0,G30,G30*F30) -> 1200000 | I30: SMC
C31: 근접 센서 | D31: E2E-X7D1-M1GJ | E31: 식 | F31: 10 | G31: 50000 | H31: =IF(F31=0,G31,G31*F31) -> 500000 | I31: OMRON
C32: 포터 센서 | D32: E3ZM-CT61-M1TJ | E32: 식 | F32: 5 | G32: 200000 | H32: =IF(F32=0,G32,G32*F32) -> 1000000 | I32: OMRON
C35: 조립/배관 자재 | E35: 식 | F35: 1 | G35: 500000 | H35: =IF(F35=0,G35,G35*F35) -> 500000
C36: 기타 자재 | E36: 식 | F36: 1 | G36: 1500000 | H36: =IF(F36=0,G36,G36*F36) -> 1500000
H37: =SUM(H18:H36) -> 24950000
B38: 외주제작품 | C38: 이스케이퍼 UNIT | E38: 식 | F38: 1 | G38: 1250000 | H38: =F38*G38 -> 1250000 | I38: 동서
C39: STOPPER JIG | E39: 식 | F39: 1 | G39: 360000 | H39: =IF(F39=0,G39,G39*F39) -> 360000 | I39: ↑
C40: 안착 포지션 JIG | E40: 식 | F40: 1 | G40: 400000 | H40: =IF(F40=0,G40,G40*F40) -> 400000 | I40: ↑
C41: WORO CLAMP | E41: 식 | F41: 1 | G41: 600000 | H41: =IF(F41=0,G41,G41*F41) -> 600000 | I41: ↑
C42: 바코드 리드기 UNIT | E42: 식 | F42: 1 | G42: 1180000 | H42: =IF(F42=0,G42,G42*F42) -> 1180000 | I42: ↑
C43: CAGE 정렬 UNIT + JIG | E43: 식 | F43: 1 | G43: 2520000 | H43: =IF(F43=0,G43,G43*F43) -> 2520000 | I43: ↑
C44: WORK 이송 UNIT | E44: 식 | F44: 1 | G44: 2000000 | H44: =IF(F44=0,G44,G44*F44) -> 2000000 | I44: ↑
C52: 기타 가공 | E52: 식 | F52: 1 | G52: 1000000 | H52: =F52*G52 -> 1000000
H53: =SUM(H38:H52) -> 9310000
B54: 자재비 소계 | H54: =SUM(H53,H37,H17,H11) -> 34260000
A55: 노 무 비 | B55: 기존설비 철거 | E55: M/D | F55: 3 | G55: 300000 | H55: =F55*G55 -> 900000 | I55: 기계/전기
...

Sheet 단위장비2
B1: □ 단위공사명(전기제외): | C1: 스태킹 M/C 개조 | I1: (첨부)
A2: 구분 | C2: 품 명 | D2: 규격 | E2: 단위 | F2: 수량 | G2: 단가(원) | H2: 금액(원) | I2: 原MAKER
A3: 자 재 비 | B3: 철자재 | C3: FRAME 류 | D3: SS400 | E3: 식 | G3: 1500 | H3: =F3*G3 -> 0
C4: BLOCK 류 | D4: SS400 | E4: 식 | G4: 1500 | H4: =F4*G4 -> 0
C5: BKT 류 | D5: SS400 | E5: 식 | G5: 1500 | H5: =F5*G5 -> 0
C8: 기타자재 | E8: 식
H9: =SUM(H3:H8) -> 0
B10: 설치/해체/시운전
B11: 공사 관련 자재
C14: 기타자재
H15: =SUM(H10:H14) -> 0
B16: 구매품 | C16: 베어링 | D16: 6826 | E16: 식 | F16: 1 | G16: 100000 | H16: =F16*G16 -> 100000 | I16: NSK
B17: (유공압품외) | C17: 근접 센서 | D17: E2E-X7D1-M1GJ | E17: 식 | F17: 4 | G17: 50000 | H17: =F17*G17 -> 200000 | I17: OMRON
C18: 포터 센서 | D18: E3ZM-CT61-M1TJ | E18: 식 | F18: 4 | G18: 200000 | H18: =F18*G18 -> 800000 | I18: OMRON
C31: 조립/배관 자재 | E31: 식 | F31: 1 | G31: 300000 | H31: =IF(F31=0,G31,G31*F31) -> 300000
C32: 기타 자재 | E32: 식 | F32: 1 | G32: 300000 | H32: =IF(F32=0,G32,G32*F32) -> 300000
H33: =SUM(H16:H32) -> 1700000
B34: 외주제작품 | C34: 로드 TEST JIG | D34: #20, #26,#27, #28 | E34: 식 | F34: 4 | G34: 800000 | H34: =F34*G34 -> 3200000 | I34: 동서
C35: 방향정렬 JIG | D35: #20 | E35: 식 | F35: 1 | G35: 572000 | H35: =F35*G35 -> 572000 | I35: ↑
C36: 스태킹 JIG | D36: #20 | E36: 식 | F36: 1 | G36: 4444000 | H36: =F36*G36 -> 4444000 | I36: ↑
C37: 스테이션 하부 JIG | D37: 방향/스태킹/풀로드/비젼 | E37: 식 | F37: 4 | G37: 1500000 | H37: =F37*G37 -> 6000000 | I37: ↑
C38: TRANSFER JOB | E38: 식 | F38: 4 | G38: 400000 | H38: =F38*G38 -> 1600000 | I38: ↑
C39: 상부 커버 수정 | E39: 식 | F39: 1 | G39: 1500000 | H39: =F39*G39 -> 1500000 | I39: ↑
C40: 지그 보관함 | E40: 식 | F40: 1 | G40: 2500000 | H40: =F40*G40 -> 2500000 | I40: ↑
C51: 기타자재 | E51: 식 | F51: 1 | G51: 1000000 | H51: =IF(F51=0,G51,G51*F51) -> 1000000
H52: =SUM(H34:H51) -> 20816000
B53: 자재비 소계 | H53: =SUM(H52,H33,H15,H9) -> 22516000
A54: 노 무 비 | B54: 기존설비 철거 | E54: M/D | F54: 3 | G54: 300000 | H54: =F54*G54 -> 900000
B55: 기계 설계 | E55: M/D | F55: 20 | G55: 350000 | H55: =F55*G55 -> 7000000
B56: 기계 제작(제관,가공) | E56: M/D | F56: 5 | G56: 300000 | H56: =F56*G56 -> 1500000
B57: 기계 조립 | E57: M/D | F57: 5 | G57: 300000 | H57: =F57*G57 -> 1500000
B58: 기계 설치 | E58: M/D | F58: 5 | G58: 300000 | H58: =F58*G58 -> 1500000
B59: 기계 시운전 | E59: M/D | F59: 3 | G59: 300000 | H59: =F59*G59 -> 900000
B60: 기계 양산대응 | E60: M/D | F60: 3 | G60: 300000 | H60: =F60*G60 -> 900000
B61: 기계 도장 | E61: M/D | F61: 3 | G61: 300000 | H61: =F61*G61 -> 900000
B62: 노무비 소계 | H62: =SUM(H54:H61) -> 15100000
B63: 운반및중장비사용 | H63: ='단위공사별(집계)'!L8+'단위공사별(집계)'!I8 -> 399494.7
B64: 일반관리비 | H64: =SUM(H53,H62) * 0.05 -> 1880800
B65: 이 윤 | H65: =SUM(H53,H62) * 0.1 -> 3761600
B66: 합 계 | H66: =H53+H62+H63+H64+H65 -> 43657895

Sheet 단위장비3
B1: □ 단위공사명(전기제외): | I1: (첨부)
A2: 구분 | C2: 품 명 | D2: 규격 | E2: 단위 | F2: 수량 | G2: 단가(원) | H2: 금액(원) | I2: 原MAKER
A3: 자 재 비 | B3: 철자재 | C3: FRAME 류 | D3: SS400 | E3: KG | G3: 1500 | H3: =F3*G3 -> 0
C4: BLOCK 류 | D4: SS400 | E4: KG | G4: 1500 | H4: =F4*G4 -> 0
C5: BKT 류 | D5: SS400 | E5: KG | G5: 1500 | H5: =F5*G5 -> 0
C9: 기타자재 | E9: 식 | F9: 1 | H9: =IF(F9=0,G9,G9*F9) -> 0
H10: =SUM(H3:H9) -> 0
B11: 설치/해체/시운전
B12: 공사 관련 자재
C15: 기타자재
H16: =SUM(H11:H15) -> 0
B17: 구매품 | H17: =IF(F17=0,G17,G17*F17) -> 0
B18: (유공압품외) | H18: =IF(F18=0,G18,G18*F18) -> 0
H19: =IF(F19=0,G19,G19*F19) -> 0
H20: =IF(F20=0,G20,G20*F20) -> 0
H21: =IF(F21=0,G21,G21*F21) -> 0
H22: =IF(F22=0,G22,G22*F22) -> 0
H23: =F23*G23 -> 0
H24: =F24*G24 -> 0
H25: =F25*G25 -> 0
H26: =F26*G26 -> 0
H27: =F27*G27 -> 0
H28: =F28*G28 -> 0
H29: =F29*G29 -> 0
H30: =F30*G30 -> 0
H31: =F31*G31 -> 0
H32: =F32*G32 -> 0
C33: 기타 자재 | E33: 식 | F33: 1 | H33: =F33*G33 -> 0
H34: =SUM(H17:H33) -> 0
B35: 외주제작품 | H35: =IF(F35=0,G35,G35*F35) -> 0
H36: =IF(F36=0,G36,G36*F36) -> 0
H37: =IF(F37=0,G37,G37*F37) -> 0
H38: =IF(F38=0,G38,G38*F38) -> 0
H39: =IF(F39=0,G39,G39*F39) -> 0
H40: =IF(F40=0,G40,G40*F40) -> 0
H41: =IF(F41=0,G41,G41*F41) -> 0
H42: =IF(F42=0,G42,G42*F42) -> 0
H43: =IF(F43=0,G43,G43*F43) -> 0
H44: =IF(F44=0,G44,G44*F44) -> 0
H45: =IF(F45=0,G45,G45*F45) -> 0
...

Sheet 단위장비4
B1: □ 단위공사명(전기제외): | I1: (첨부)
A2: 구분 | C2: 품 명 | D2: 규격 | E2: 단위 | F2: 수량 | G2: 단가(원) | H2: 금액(원) | I2: 原MAKER
A3: 자 재 비 | B3: 철자재 | C3: FRAME 류 | D3: SS400 | E3: KG | G3: 1500
C4: BLOCK 류 | D4: SS400 | E4: KG | G4: 1500
C5: BKT 류 | D5: SS400 | E5: KG | G5: 1500
C9: 기타자재
H10: =SUM(H3:H9) -> 0
B11: 설치/해체/시운전
B12: 공사 관련 자재
C15: 기타자재
H16: =SUM(H11:H15) -> 0
B17: 구매품 | H17: =IF(F17=0,G17,G17*F17) -> 0
B18: (유공압품외) | H18: =IF(F18=0,G18,G18*F18) -> 0
H19: =IF(F19=0,G19,G19*F19) -> 0
H20: =IF(F20=0,G20,G20*F20) -> 0
H21: =IF(F21=0,G21,G21*F21) -> 0
C31: 조립/배관 자재 | E31: 식 | H31: =IF(F31=0,G31,G31*F31) -> 0
C32: 기타자재 | E32: 식 | H32: =F32*G32 -> 0
H33: =SUM(H17:H32) -> 0
B34: 외주제작품 | H34: =IF(F34=0,G34,G34*F34) -> 0
H35: =IF(F35=0,G35,G35*F35) -> 0
C51: 기타자재 | E51: 식 | H51: =F51*G51 -> 0
H52: =SUM(H34:H51) -> 0
B53: 자재비 소계 | H53: =SUM(H52,H33,H16,H10) -> 0
A54: 노 무 비 | B54: 기존설비 철거 | E54: M/D | G54: 300000 | H54: =F54*G54 -> 0
B55: 기계 설계 | E55: M/D | G55: 350000 | H55: =F55*G55 -> 0
B56: 기계 제작(제관,가공) | E56: M/D | G56: 300000 | H56: =F56*G56 -> 0
B57: 기계 조립 | E57: M/D | G57: 300000 | H57: =F57*G57 -> 0
B58: 기계 설치 | E58: M/D | G58: 300000 | H58: =F58*G58 -> 0
B59: 기계 시운전 | E59: M/D | G59: 300000 | H59: =F59*G59 -> 0
B60: 기계 양산대응 | E60: M/D | G60: 300000 | H60: =F60*G60 -> 0
B61: 기계 도장 | E61: M/D | G61: 300000 | H61: =F61*G61 -> 0
B62: 노무비 소계 | H62: =SUM(H54:H61) -> 0
B63: 운반및중장비사용 | H63: ='단위공사별(집계)'!L10+'단위공사별(집계)'!I10 -> 0
B64: 일반관리비 | H64: =(H53+H62)*0.05 -> 0
B65: 이 윤 | H65: =(H53+H62)*0.1 -> 0
B66: 합 계 | H66: =H53+H62+H63+H64+H65 -> 0

Sheet 단위장비5
B1: □ 단위공사명(전기제외): | I1: (첨부)
A2: 구분 | C2: 품 명 | D2: 규격 | E2: 단위 | F2: 수량 | G2: 단가(원) | H2: 금액(원) | I2: 原MAKER
A3: 자 재 비 | B3: 철자재 | C3: FRAME 류 | D3: SS400
C4: BLOCK 류 | D4: SS400
C5: BKT 류 | D5: SS400
C9: 기타자재
H10: =SUM(H3:H9) -> 0
B11: 설치/해체/시운전
B12: 공사 관련 자재
C15: 기타자재
H16: =SUM(H11:H15) -> 0
B17: 구매품
B18: (유공압품외)
C31: 조립/배관 자재 | H31: =F31*G31 -> 0
C32: 기타자재
H33: =SUM(H17:H32) -> 0
B34: 외주제작품 | H34: =IF(F34=0,G34,G34*F34) -> 0
C51: 기타자재
H52: =SUM(H34:H51) -> 0
B53: 자재비 소계 | H53: =SUM(H52,H33,H16,H10) -> 0
A54: 노 무 비 | B54: 기존설비 철거 | E54: M/D | H54: =F54*G54 -> 0
B55: 기계 설계 | E55: M/D | H55: =F55*G55 -> 0
B56: 기계 제작(제관,가공) | E56: M/D
B57: 기계 조립 | E57: M/D
B58: 기계 설치 | E58: M/D | H58: =F58*G58 -> 0
B59: 기계 시운전 | E59: M/D | H59: =F59*G59 -> 0
B60: 기계 양산대응 | E60: M/D | H60: =F60*G60 -> 0
B61: 기계 도장 | E61: M/D
B62: 노무비 소계 | H62: =SUM(H54:H61) -> 0
B63: 운반및중장비사용 | H63: ='단위공사별(집계)'!I11+'단위공사별(집계)'!L11 -> 0
B64: 일반관리비 | H64: =(H53+H62)*0.05 -> 0
B65: 이 윤 | H65: =(H53+H62)*0.1 -> 0
B66: 합 계 | H66: =H53+H62+H63+H64+H65 -> 0

Sheet 단위장비6
B1: □ 단위공사명(전기제외): | I1: (첨부)
A2: 구분 | C2: 품 명 | D2: 규격 | E2: 단위 | F2: 수량 | G2: 단가(원) | H2: 금액(원) | I2: 原MAKER
A3: 자 재 비 | B3: 철자재 | C3: FRAME 류 | D3: SS400
C4: BLOCK 류 | D4: SS400
C5: BKT 류 | D5: SS400
C9: 기타자재
H10: =SUM(H3:H9) -> 0
B11: 설치/해체/시운전
B12: 공사 관련 자재
C15: 기타자재
H16: =SUM(H11:H15) -> 0
B17: 구매품 | H17: =IF(F17=0,G17,G17*F17) -> 0
B18: (유공압품외) | H18: =IF(F18=0,G18,G18*F18) -> 0
C31: 조립/배관 자재 | H31: =IF(F31=0,G31,G31*F31) -> 0
C32: 기타자재 | H32: =IF(F32=0,G32,G32*F32) -> 0
H33: =SUM(H17:H32) -> 0
B34: 외주제작품 | H34: =IF(F34=0,G34,G34*F34) -> 0
H35: =IF(F35=0,G35,G35*F35) -> 0
C51: 기타자재 | H51: =IF(F51=0,G51,G51*F51) -> 0
H52: =SUM(H34:H51) -> 0
B53: 자재비 소계 | H53: =SUM(H52,H33,H16,H10) -> 0
A54: 노 무 비 | B54: 기존설비 철거 | E54: M/D
B55: 기계 설계 | E55: M/D | H55: =F55*G55 -> 0
B56: 기계 제작(제관,가공) | E56: M/D
B57: 기계 조립 | E57: M/D | H57: =F57*G57 -> 0
B58: 기계 설치 | E58: M/D | H58: =F58*G58 -> 0
B59: 기계 시운전 | E59: M/D | H59: =F59*G59 -> 0
B60: 기계 양산대응 | E60: M/D | H60: =F60*G60 -> 0
B61: 기계 도장 | E61: M/D
B62: 노무비 소계 | H62: =SUM(H54:H61) -> 0
B63: 운반및중장비사용 | H63: ='단위공사별(집계)'!L12+'단위공사별(집계)'!I12 -> 0
B64: 일반관리비 | H64: =(H53+H62)*0.05 -> 0
B65: 이 윤 | H65: =(H53+H62)*0.1 -> 0
B66: 합 계 | H66: =H53+H62+H63+H64+H65 -> 0

Sheet 단위장비7
B1: □ 단위공사명(전기제외): | I1: (첨부)
A2: 구분 | C2: 품 명 | D2: 규격 | E2: 단위 | F2: 수량 | G2: 단가(원) | H2: 금액(원) | I2: 原MAKER
A3: 자 재 비 | B3: 철자재 | C3: FRAME 류 | D3: SS400 | E3: KG
C4: BLOCK 류 | D4: SS400 | E4: KG
C5: BKT 류 | D5: SS400 | E5: KG
C9: 기타자재 | E9: 식
H10: =SUM(H3:H9) -> 0
B11: 설치/해체/시운전
B12: 공사 관련 자재
C15: 기타자재
H16: =SUM(H11:H15) -> 0
B17: 구매품
B18: (유공압품외)
C31: 조립/배관 자재
C32: 기타자재
H33: =SUM(H17:H32) -> 0
B34: 외주제작품 | C34: 파렛트 JIG
C35: 제용 이송용 JIG
C36: 홀 위치 결정용 JIG
C51: 기타자재
H52: =SUM(H34:H51) -> 0
B53: 자재비 소계 | H53: =SUM(H52,H33,H16,H10) -> 0
A54: 노 무 비 | B54: 기존설비 철거 | E54: M/D | H54: =F54*G54 -> 0
B55: 기계 설계 | E55: M/D | H55: =F55*G55 -> 0
B56: 기계 제작(제관,가공) | E56: M/D | H56: =F56*G56 -> 0
B57: 기계 조립 | E57: M/D | H57: =F57*G57 -> 0
B58: 기계 설치 | E58: M/D | H58: =F58*G58 -> 0
B59: 기계 시운전 | E59: M/D | H59: =F59*G59 -> 0
B60: 기계 양산대응 | E60: M/D | H60: =F60*G60 -> 0
B61: 기계 도장 | E61: M/D | H61: =F61*G61 -> 0
B62: 노무비 소계 | H62: =SUM(H54:H61) -> 0
B63: 운반및중장비사용 | H63: ='단위공사별(집계)'!L13+'단위공사별(집계)'!I13 -> 0
B64: 일반관리비
B65: 이 윤
B66: 합 계 | H66: =H53+H62+H63+H64+H65 -> 0

Sheet 단위장비8
B1: □ 단위공사명(전기제외): | I1: (첨부)
A2: 구분 | C2: 품 명 | D2: 규격 | E2: 단위 | F2: 수량 | G2: 단가(원) | H2: 금액(원) | I2: 原MAKER
A3: 자 재 비 | B3: 철자재 | H3: =IF(F3=0,G3,G3*F3) -> 0
H4: =IF(F4=0,G4,G4*F4) -> 0
H5: =IF(F5=0,G5,G5*F5) -> 0
H6: =IF(F6=0,G6,G6*F6) -> 0
H7: =IF(F7=0,G7,G7*F7) -> 0
H8: =IF(F8=0,G8,G8*F8) -> 0
H9: =IF(F9=0,G9,G9*F9) -> 0
H10: =IF(F10=0,G10,G10*F10) -> 0
H11: =IF(F11=0,G11,G11*F11) -> 0
H12: =IF(F12=0,G12,G12*F12) -> 0
H13: =IF(F13=0,G13,G13*F13) -> 0
H14: =IF(F14=0,G14,G14*F14) -> 0
H15: =IF(F15=0,G15,G15*F15) -> 0
... H22: =IF(F22=0,G22,G22*F22) -> 0
C23: 기타자재 | H23: =IF(F23=0,G23,G23*F23) -> 0
H24: =SUM(H3:H23) -> 0
B25: 설치/해체/시운전 | H25: =IF(F25=0,G25,G25*F25) -> 0
B26: 공사 관련 자재 | H26: =IF(F26=0,G26,G26*F26) -> 0
H27: =IF(F27=0,G27,G27*F27) -> 0
H28: =IF(F28=0,G28,G28*F28) -> 0
C29: 기타자재 | H29: =IF(F29=0,G29,G29*F29) -> 0
H30: =SUM(H25:H29) -> 0
B31: 구매품 | H31: =IF(F31=0,G31,G31*F31) -> 0
B32: (유공압품외) | H32: =IF(F32=0,G32,G32*F32) -> 0
H33: =IF(F33=0,G33,G33*F33) -> 0
H34: =IF(F34=0,G34,G34*F34) -> 0
H35: =IF(F35=0,G35,G35*F35) -> 0
H36: =IF(F36=0,G36,G36*F36) -> 0
H37: =IF(F37=0,G37,G37*F37) -> 0
H38: =IF(F38=0,G38,G38*F38) -> 0
H39: =IF(F39=0,G39,G39*F39) -> 0
H40: =IF(F40=0,G40,G40*F40) -> 0
H41: =IF(F41=0,G41,G41*F41) -> 0
H42: =IF(F42=0,G42,G42*F42) -> 0
H43: =IF(F43=0,G43,G43*F43) -> 0
H44: =IF(F44=0,G44,G44*F44) -> 0
H45: =IF(F45=0,G45,G45*F45) -> 0
C46: 기타자재 | H46: =IF(F46=0,G46,G46*F46) -> 0
...

Sheet 단위장비9
B1: □ 단위공사명(전기제외): | I1: (첨부)
A2: 구분 | C2: 품 명 | D2: 규격 | E2: 단위 | F2: 수량 | G2: 단가(원) | H2: 금액(원) | I2: 原MAKER
A3: 자 재 비 | B3: 철자재 | H3: =IF(F3=0,G3,G3*F3) -> 0
H4: =IF(F4=0,G4,G4*F4) -> 0
H5: =IF(F5=0,G5,G5*F5) -> 0
H6: =IF(F6=0,G6,G6*F6) -> 0
H7: =IF(F7=0,G7,G7*F7) -> 0
H8: =IF(F8=0,G8,G8*F8) -> 0
H9: =IF(F9=0,G9,G9*F9) -> 0
H10: =IF(F10=0,G10,G10*F10) -> 0
H11: =IF(F11=0,G11,G11*F11) -> 0
H12: =IF(F12=0,G12,G12*F12) -> 0
H13: =IF(F13=0,G13,G13*F13) -> 0
H14: =IF(F14=0,G14,G14*F14) -> 0
H15: =IF(F15=0,G15,G15*F15) -> 0
... H22: =IF(F22=0,G22,G22*F22) -> 0
C23: 기타자재 | H23: =IF(F23=0,G23,G23*F23) -> 0
H24: =SUM(H3:H23) -> 0
B25: 설치/해체/시운전 | H25: =IF(F25=0,G25,G25*F25) -> 0
B26: 공사 관련 자재 | H26: =IF(F26=0,G26,G26*F26) -> 0
H27: =IF(F27=0,G27,G27*F27) -> 0
H28: =IF(F28=0,G28,G28*F28) -> 0
C29: 기타자재 | H29: =IF(F29=0,G29,G29*F29) -> 0
H30: =SUM(H25:H29) -> 0
B31: 구매품 | H31: =IF(F31=0,G31,G31*F31) -> 0
B32: (유공압품외) | H32: =IF(F32=0,G32,G32*F32) -> 0
H33: =IF(F33=0,G33,G33*F33) -> 0
H34: =IF(F34=0,G34,G34*F34) -> 0
H35: =IF(F35=0,G35,G35*F35) -> 0
H36: =IF(F36=0,G36,G36*F36) -> 0
H37: =IF(F37=0,G37,G37*F37) -> 0
H38: =IF(F38=0,G38,G38*F38) -> 0
H39: =IF(F39=0,G39,G39*F39) -> 0
H40: =IF(F40=0,G40,G40*F40) -> 0
H41: =IF(F41=0,G41,G41*F41) -> 0
H42: =IF(F42=0,G42,G42*F42) -> 0
H43: =IF(F43=0,G43,G43*F43) -> 0
H44: =IF(F44=0,G44,G44*F44) -> 0
H45: =IF(F45=0,G45,G45*F45) -> 0
C46: 기타자재 | H46: =IF(F46=0,G46,G46*F46) -> 0
...

Sheet 단위장비10
B1: □ 단위공사명(전기제외): | I1: (첨부)
A2: 구분 | C2: 품 명 | D2: 규격 | E2: 단위 | F2: 수량 | G2: 단가(원) | H2: 금액(원) | I2: 原MAKER
A3: 자 재 비 | B3: 철자재 | H3: =IF(F3=0,G3,G3*F3) -> 0
H4: =IF(F4=0,G4,G4*F4) -> 0
H5: =IF(F5=0,G5,G5*F5) -> 0
H6: =IF(F6=0,G6,G6*F6) -> 0
H7: =IF(F7=0,G7,G7*F7) -> 0
H8: =IF(F8=0,G8,G8*F8) -> 0
H9: =IF(F9=0,G9,G9*F9) -> 0
H10: =IF(F10=0,G10,G10*F10) -> 0
H11: =IF(F11=0,G11,G11*F11) -> 0
H12: =IF(F12=0,G12,G12*F12) -> 0
H13: =IF(F13=0,G13,G13*F13) -> 0
H14: =IF(F14=0,G14,G14*F14) -> 0
H15: =IF(F15=0,G15,G15*F15) -> 0
... H22: =IF(F22=0,G22,G22*F22) -> 0
C23: 기타자재 | H23: =IF(F23=0,G23,G23*F23) -> 0
H24: =SUM(H3:H23) -> 0
B25: 설치/해체/시운전 | H25: =IF(F25=0,G25,G25*F25) -> 0
B26: 공사 관련 자재 | H26: =IF(F26=0,G26,G26*F26) -> 0
H27: =IF(F27=0,G27,G27*F27) -> 0
H28: =IF(F28=0,G28,G28*F28) -> 0
C29: 기타자재 | H29: =IF(F29=0,G29,G29*F29) -> 0
H30: =SUM(H25:H29) -> 0
B31: 구매품 | H31: =IF(F31=0,G31,G31*F31) -> 0
B32: (유공압품외) | H32: =IF(F32=0,G32,G32*F32) -> 0
H33: =IF(F33=0,G33,G33*F33) -> 0
H34: =IF(F34=0,G34,G34*F34) -> 0
H35: =IF(F35=0,G35,G35*F35) -> 0
H36: =IF(F36=0,G36,G36*F36) -> 0
H37: =IF(F37=0,G37,G37*F37) -> 0
H38: =IF(F38=0,G38,G38*F38) -> 0
H39: =IF(F39=0,G39,G39*F39) -> 0
H40: =IF(F40=0,G40,G40*F40) -> 0
H41: =IF(F41=0,G41,G41*F41) -> 0
H42: =IF(F42=0,G42,G42*F42) -> 0
H43: =IF(F43=0,G43,G43*F43) -> 0
H44: =IF(F44=0,G44,G44*F44) -> 0
H45: =IF(F45=0,G45,G45*F45) -> 0
C46: 기타자재 | H46: =IF(F46=0,G46,G46*F46) -> 0
...

Sheet 첨부(견적조건차이내역)
A1: ※ 현대/기아차의 요구사양과 업체견적사양이 다른경우만 작성
D2: (첨부)
A3: 현대/기아차 요구사양대비 견적조건 상이내역
A5: 항 목 | B5: 현대/기아차 요구사양 | C5: 업체 견적기준 사양 | D5: 비 고
