Workbook

Sheet 커버
B1: 135-937 서울특별시 강남구 강남대로 308 랜드마크타워 T:02 2016 2300
C2: E S T I M A T E | K2: =TODAY() -> 46017
C4: ▶ Client | D4: : | E4: 현대위아
C5: ▶ 행 사 명 | D5: : | E5: CES2026 현대위아관
C6: ▶ 행 사 기 간 | D6: : | E6: 2026년 1월 6일 ~ 1월 9일 (총 4일)
C7: ▶ 행 사 장 소 | D7: : | E7: 미국 네바다주, 라스베가스 컨벤션 센터 (LVCC) 웨스트홀
C8: ▶ 행 사 금 액 | D8: : | E8: =I8 -> 2286800000 | H8: 원정 | I8: =총괄!E13 -> 2286800000 | J8: VAT 별도
C9: ▶ 비 고 | D9: :
C10: ▶ 기 타 | D10: :

Sheet 총괄
B1: ■ CES 2026 현대위아관_총괄예산 내역
B3: 구 분 | D3: 내 용 | E3: 금 액(원)
B4: 1 | C4: 기획 / 디자인 | D4: 전시관 기획 및 2D, 3D 디자인 등 | E4: =세부내역!I5 -> 8000000
B5: 2 | C5: 전시관 제작 | D5: 전시관 설계 및 전시관 제작 (자재비, 인건비 등) | E5: =세부내역!I74 -> 825076000
B6: 3 | C6: 콘텐츠 제작 | D6: 영상 및 전시 콘텐츠 등 | E6: =세부내역!I107 -> 285900000
B7: 4 | C7: 시스템 | D7: 전시관 LED 영상 시스템, 조명, 음향 및 오퍼레이팅 등 | E7: =세부내역!I140 -> 312600000
B8: 5 | C8: 쇼서비스 | D8: LVCC 현장 설치, 운영 지원 서비스 비용 | E8: =세부내역!I165 -> 374354910
B9: 6 | C9: 인력 / 운영 | D9: 현지 운영 및 안내 인력, 기타 운영 제반 사항 및 진행비, 예비비 등 | E9: =세부내역!I206 -> 236635000
B10: 7 | C10: 출장비 | D10: 대행사 출장비 | E10: =세부내역!I208 -> 40000000
B11: 합 계 | E11: =SUM(E4:E10) -> 2082565910
B12: 대행수수료(1~6 합계의 10%) | E12: =SUM(E4:E9)*0.1 -> 204256591
B13: 총계 (VAT 별도) | E13: =ROUNDDOWN(SUM(E11:E12),-5) -> 2286800000

Sheet 세부내역
B1: ■ CES 2026 현대위아관_세부예산 내역
B2: 구분 | D2: 내용 | E2: 단위 | F2: 일수 | G2: 수량 | H2: 단가 | I2: 금액 | J2: 비고
H3: 원화(KRW) | I3: 원화(KRW)
B4: 기획 | D4: 기획, 섭외, 운영, 매뉴얼 개발 | E4: 식 | F4: 1 | G4: 1 | H4: 8000000 | I4: =H4 -> 8000000
B5: 소 계 | I5: =SUM(I4:I4) -> 8000000
A6: ㅐ | B6: 전시관 제작 | C6: 바닥 공사 | D6: 바닥 18T 합판 2PLY / 바닥 몰딩 등 | E6: ㎡ | F6: 1 | G6: 140 | H6: 168000 | I6: =H6*G6*F6 -> 23520000
D7: 바닥 마감 | E7: ㎡ | F7: 1 | G7: 140 | H7: 124000 | I7: =H7*G7*F7 -> 17360000
D8: 설치 철거 보양재 | E8: ㎡ | F8: 1 | G8: 140 | H8: 15000 | I8: =H8*G8*F8 -> 2100000
A9: ㅐ | C9: 외부 목공 구조 | D9: 후면 외부 구조 (15,240mmL x 5,000mmH x 70mmD) | E9: ㎡ | F9: 1 | G9: 77 | H9: 380000 | I9: =H9*G9*F9 -> 29260000
D10: 우측면 외부 구조 (6,731mmL x 5,000mmH x 70mmD) | E10: ㎡ | F10: 1 | G10: 34 | H10: 300000 | I10: =H10*G10*F10 -> 10200000
C11: 벽체 구조 | D11: 목공구조, 라미네이트 마감 / 25,000mm x 5,000mmH | E11: ㎡ | F11: 1 | G11: 102 | H11: 300000 | I11: =H11*G11*F11 -> 30600000
D12: 목공구조, 라미네이트 마감 / 18,000mm x 3,000mmH | E12: ㎡ | F12: 1 | G12: 42 | H12: 300000 | I12: =H12*G12*F12 -> 12600000
D13: Seamless Comport Zone 금속 프레임 | E13: ㎡ | F13: 0 | G13: 40 | H13: 420000 | I13: =H13*G13*F13 -> 0
D14: 우든도어 | E14: 식 | F14: 1 | G14: 1 | H14: 800000 | I14: =H14*G14*F14 -> 800000
D15: 유리 강화 도어 / 손잡이 / 힌지 | E15: 식 | F15: 1 | G15: 1 | H15: 1200000 | I15: =H15*G15*F15 -> 1200000
D16: 유리프레임 | E16: ㎡ | F16: 1 | G16: 16 | H16: 360000 | I16: =H16*G16*F16 -> 5760000
D17: VIP룸 유리 | E17: 자평 | F17: 1 | G17: 172 | H17: 45000 | I17: =H17*G17*F17 -> 7740000
D18: Seamless Connection Zone 개별 목공구조, 라미네이트 마감 | E18: 식 | F18: 1 | G18: 1 | H18: 11000000 | I18: =H18*G18*F18 -> 11000000
D19: 메인 LED 프레임 제작 | E19: 식 | F19: 1 | G19: 1 | H19: 3500000 | I19: =H19*G19*F19 -> 3500000
A20: ㅐ | C20: 전시관 및 룸 천장 구조 | D20: Control, Connection Zone 구조천장 / 목공구조, 라미네이트 마감 | E20: ㎡ | F20: 1 | G20: 28 | H20: 300000 | I20: =H20*G20*F20 -> 8400000
D21: 미팅, 스태프 룸 구조 천장 / 목공구조, 라미네이트 마감 | E21: ㎡ | F21: 1 | G21: 12 | H21: 300000 | I21: =H21*G21*F21 -> 3600000
C22: Enginerring Drawing | D22: 제작 드로잉 | E22: 식 | F22: 1 | G22: 1 | H22: 2600000 | I22: =H22*G22*F22 -> 2600000
D23: 구조 계산 및 Wet Stamp | E23: 식 | F23: 1 | G23: 1 | H23: 2000000 | I23: =H23*G23*F23 -> 2000000
C24: Shipping | D24: 우든 크레이트 & 팔레트 제작 / 팩킹 | E24: 식 | F24: 1 | G24: 1 | H24: 2000000 | I24: =H24*G24*F24 -> 2000000
D25: 현지 운송비 / LA ~ Las Vegas | E25: 식 | F25: 1 | G25: 5 | H25: 3500000 | I25: =H25*G25*F25 -> 17500000
C26: 제작 가구 공사 | D26: 인포메이션 데스크 | E26: 식 | F26: 1 | G26: 1 | H26: 4000000 | I26: =H26*G26*F26 -> 4000000
D27: HVAC 키오스크 | E27: 식 | F27: 1 | G27: 1 | H27: 3200000 | I27: =H27*G27*F27 -> 3200000
D28: TMS 전시 집기 | E28: 식 | F28: 1 | G28: 1 | H28: 5500000 | I28: =H28*G28*F28 -> 5500000
D29: AMR 전시대 | E29: 식 | F29: 1 | G29: 1 | H29: 2800000 | I29: =H29*G29*F29 -> 2800000
D30: WDS 목공 구조 집기, 마감 | E30: 식 | F30: 1 | G30: 1 | H30: 2000000 | I30: =H30*G30*F30 -> 2000000
D31: Dual CVJ 목공 구조 집기, 마감 | E31: 식 | F31: 1 | G31: 1 | H31: 2800000 | I31: =H31*G31*F31 -> 2800000
D32: ARS 전시 집기 목공 구조 집기, 마감 / 구조 보강 등 | E32: 식 | F32: 1 | G32: 1 | H32: 6800000 | I32: =H32*G32*F32 -> 6800000
D33: Control Zone 기타 제품 (IDA, e-LSD, e-TVTC) 전시 테이블 | E33: 식 | F33: 1 | G33: 1 | H33: 5500000 | I33: =H33*G33*F33 -> 5500000
D34: 헤리티지 존 전시 집기 (테이블, HW등) | E34: 식 | F34: 1 | G34: 1 | H34: 4500000 | I34: =H34*G34*F34 -> 4500000
C35: 트러스 공사 | D35: 블랙 스틸 트러스 | E35: m | F35: 1 | G35: 130 | H35: 380000 | I35: =H35*G35*F35 -> 49400000
D36: 트러스 천장 가림막 (설치 작업 포함) | E36: 식 | F36: 1 | G36: 1 | H36: 24000000 | I36: =H36*G36*F36 -> 24000000
D37: 체인 모터 | E37: ea | F37: 1 | G37: 16 | H37: 1250000 | I37: =H37*G37*F37 -> 20000000
D38: 컨트롤 박스 | E38: ea | F38: 1 | G38: 2 | H38: 2500000 | I38: =H38*G38*F38 -> 5000000
D39: 리깅 하드웨어 (Grapple, Shackles, GAC Flex Turn buckle 등) | E39: 식 | F39: 1 | G39: 1 | H39: 5000000 | I39: =H39*G39*F39 -> 5000000
A40: ㅐ | D40: 잔넬 리깅 프레임 | E40: set | F40: 1 | G40: 2 | H40: 3500000 | I40: =H40*G40*F40 -> 7000000
...
