Workbook

Sheet 갑지
B1: (현대/기아차 설비협력업체 견적통일양식)
B2: 見 積 書
B4: 현대 위아 貴下 | G4: ㈜지이엠
B5: 견적일자 | D5: 44175 | G5: 대표 : 송 칠 영 (인)
B6: 견적번호 | D6: GD1_201210-001 | G6: 주소 : 경남 창원시 성산구
B7: 납기 | C7: 입하 | G7: 성산패총로24번길 1
C8: 최종검수 | G8: 전화: 055-282-9488
B9: 견적유효기간 | D9: 견적일로부터30일 | G9: Fax: 055-282-9484 / 9490
B10: 인도장소 | D10: 현대위아 공장 | G10: 견적담당: | H10: 정대헌부장
B11: 지불조건 | D11: 현대위아 기준 | G11: 연 락 처 : | H11: 010-3452-0737
B13: 견적금액: 一金이억삼천칠백칠십만원整(\237,700,000 )
B15: 번호 | C15: 상세품목내역 | E15: 견적금액 (천원) | I15: 비 고
E16: 기계부분 | F16: 전기부문 | G16: 관리/이윤 (안전관리비포함) | H16: 합 계
B17: 1 | C17: =IF('단위공사별(집계)'!N7>0,'단위공사별(집계)'!B7,"") -> 허버베어링 에어블로잉 공정 추가 | E17: =IF('단위공사별(집계)'!N7>1,('단위공사별(집계)'!D7+'단위공사별(집계)'!E7+'단위공사별(집계)'!F7+'단위공사별(집계)'!G7+'단위공사별(집계)'!H7+'단위공사별(집계)'!I7)/1000," ") -> 17983.922 | F17: =IF('단위공사별(집계)'!N7>0,'단위공사별(집계)'!K17/1000,"") -> 70400 | G17: =IF('단위공사별(집계)'!N7>0,('단위공사별(집계)'!L7+'단위공사별(집계)'!M7)/1000,"") -> 62.441176 | H17: =IF('단위공사별(집계)'!N7>0,'단위공사별(집계)'!N7/1000,"") -> 25638.52
B18: 2 | C18: =IF('단위공사별(집계)'!N8>0,'단위공사별(집계)'!B8,"") -> 허버볼트 이종사양 검출 | E18: =IF('단위공사별(집계)'!N8>1,('단위공사별(집계)'!D8+'단위공사별(집계)'!E8+'단위공사별(집계)'!F8+'단위공사별(집계)'!G8+'단위공사별(집계)'!H8+'단위공사별(집계)'!I8)/1000," ") -> 4764.2849 | G18: =IF('단위공사별(집계)'!N8>0,('단위공사별(집계)'!L8+'단위공사별(집계)'!M8)/1000,"") -> 16.541862 | H18: =IF('단위공사별(집계)'!N8>0,'단위공사별(집계)'!N8/1000,"") -> 6792.1343
B19: 3 | C19: =IF('단위공사별(집계)'!N9>0,'단위공사별(집계)'!B9,"") -> 허버베어링 2D리딩추가 | E19: =IF('단위공사별(집계)'!N9>1,('단위공사별(집계)'!D9+'단위공사별(집계)'!E9+'단위공사별(집계)'!F9+'단위공사별(집계)'!G9+'단위공사별(집계)'!H9+'단위공사별(집계)'!I9)/1000," ") -> 7171.5025 | G19: =IF('단위공사별(집계)'!N9>0,('단위공사별(집계)'!L9+'단위공사별(집계)'!M9)/1000,"") -> 24.899856 | H19: =IF('단위공사별(집계)'!N9>0,'단위공사별(집계)'!N9/1000,"") -> 10223.95
B20: 4 | C20: =IF('단위공사별(집계)'!N10>0,'단위공사별(집계)'!B10,"") -> 허버베어링 센트링디바이스추가 | E20: =IF('단위공사별(집계)'!N10>1,('단위공사별(집계)'!D10+'단위공사별(집계)'!E10+'단위공사별(집계)'!F10+'단위공사별(집계)'!G10+'단위공사별(집계)'!H10+'단위공사별(집계)'!I10)/1000," ") -> 6369.0966 | G20: =IF('단위공사별(집계)'!N10>0,('단위공사별(집계)'!L10+'단위공사별(집계)'!M10)/1000,"") -> 22.113858 | H20: =IF('단위공사별(집계)'!N10>0,'단위공사별(집계)'!N10/1000,"") -> 9080.0111
B21: 5 | C21: =IF('단위공사별(집계)'!N11>0,'단위공사별(집계)'!B11,"") -> 이너레이스 자동박스 2D 바코드 리더기 추가 | E21: =IF('단위공사별(집계)'!N11>1,('단위공사별(집계)'!D11+'단위공사별(집계)'!E11+'단위공사별(집계)'!F11+'단위공사별(집계)'!G11+'단위공사별(집계)'!H11+'단위공사별(집계)'!I11)/1000," ") -> 16148.418 | G21: =IF('단위공사별(집계)'!N11>0,('단위공사별(집계)'!L11+'단위공사별(집계)'!M11)/1000,"") -> 56.068206 | H21: =IF('단위공사별(집계)'!N11>0,'단위공사별(집계)'!N11/1000,"") -> 23021.76
B22: 6 | C22: =IF('단위공사별(집계)'!N12>0,'단위공사별(집계)'!B12,"") -> I/B 모니트링 장치 추가 | E22: =IF('단위공사별(집계)'!N12>1,('단위공사별(집계)'!D12+'단위공사별(집계)'!E12+'단위공사별(집계)'!F12+'단위공사별(집계)'!G12+'단위공사별(집계)'!H12+'단위공사별(집계)'!I12)/1000," ") -> 2958.8716 | G22: =IF('단위공사별(집계)'!N12>0,('단위공사별(집계)'!L12+'단위공사별(집계)'!M12)/1000,"") -> 10.273367 | H22: =IF('단위공사별(집계)'!N12>0,'단위공사별(집계)'!N12/1000,"") -> 4218.2729
B23: 7 | C23: =IF('단위공사별(집계)'!N13>0,'단위공사별(집계)'!B13,"") -> I/B저상리프트 추가 | E23: =IF('단위공사별(집계)'!N13>1,('단위공사별(집계)'!D13+'단위공사별(집계)'!E13+'단위공사별(집계)'!F13+'단위공사별(집계)'!G13+'단위공사별(집계)'!H13+'단위공사별(집계)'!I13)/1000," ") -> 14042.103 | G23: =IF('단위공사별(집계)'!N13>0,('단위공사별(집계)'!L13+'단위공사별(집계)'!M13)/1000,"") -> 48.754962 | H23: =IF('단위공사별(집계)'!N13>0,'단위공사별(집계)'!N13/1000,"") -> 20018.922
B24: 8 | C24: =IF('단위공사별(집계)'!N14>0,'단위공사별(집계)'!B14,"") -> 드레그토크 측정기 | E24: =IF('단위공사별(집계)'!N14>1,('단위공사별(집계)'!D14+'단위공사별(집계)'!E14+'단위공사별(집계)'!F14+'단위공사별(집계)'!G14+'단위공사별(집계)'!H14+'단위공사별(집계)'!I14)/1000," ") -> 30601.754 | G24: =IF('단위공사별(집계)'!N14>0,('단위공사별(집계)'!L14+'단위공사별(집계)'!M14)/1000,"") -> 106.25099 | H24: =IF('단위공사별(집계)'!N14>0,'단위공사별(집계)'!N14/1000,"") -> 43626.951
B25: 9 | C25: =IF('단위공사별(집계)'!N15>0,'단위공사별(집계)'!B15,"") -> RG3공유 리툴링 | E25: =IF('단위공사별(집계)'!N15>1,('단위공사별(집계)'!D15+'단위공사별(집계)'!E15+'단위공사별(집계)'!F15+'단위공사별(집계)'!G15+'단위공사별(집계)'!H15+'단위공사별(집계)'!I15)/1000," ") -> 10290.855 | G25: =IF('단위공사별(집계)'!N15>0,('단위공사별(집계)'!L15+'단위공사별(집계)'!M15)/1000,"") -> 35.730422 | H25: =IF('단위공사별(집계)'!N15>0,'단위공사별(집계)'!N15/1000,"") -> 14671.01
B26: 10 | C26: =IF('단위공사별(집계)'!N16>0,'단위공사별(집계)'!B16,"") -> 스토퍼링 P/FROOF | E26: =IF('단위공사별(집계)'!N16>1,('단위공사별(집계)'!D16+'단위공사별(집계)'!E16+'단위공사별(집계)'!F16+'단위공사별(집계)'!G16+'단위공사별(집계)'!H16+'단위공사별(집계)'!I16)/1000," ") -> 56429.193 | G26: =IF('단위공사별(집계)'!N16>0,('단위공사별(집계)'!L16+'단위공사별(집계)'!M16)/1000,"") -> 195.9253 | H26: =IF('단위공사별(집계)'!N16>0,'단위공사별(집계)'!N16/1000,"") -> 80447.469
B27: 견적 합계 | E27: =SUM(E17:E26) -> 166760 | F27: =SUM(F17:F23) -> 70400 | G27: =SUM(G17:G26) -> 579 | H27: =ROUNDDOWN(SUM(H17:H26),-2) -> 237700
F29: 공개입찰가 (견적時 공란) | H29: 237700
B31: 특기사항 | C31: 1. VAT 제외 | F31: 외주계획 업체명 (자작時 공란)
C32: 2. 기본 유틸리티공사 제외 | F32: 설계외주
C33: ='원가항목별(집계)'!I39 -> 579000 | F33: 제작외주
F34: 전기외주
F35: 설치외주

Sheet 원가항목별(집계)
C2: A. 원가항목별 견적가 종합(상세견적 첨부)
B4: □ 현대/기아 요구사양과 견적조건 일치여부 CHECK: 1.일치함 2.일부상이(상이내역 첨부참조)
B6: 순번 | C6: 원가구분 | F6: 단위 | G6: 수량 | H6: 단가 | I6: 금 액(원) | J6: 비 고
B7: 1 | C7: 기계 부문 | D7: 자재비 | E7: 철자재(SS.SUS등) | F7: kg | G7: ='#10'!F19+'#20'!F30+'#30'!F30+'#40'!F30+'#50'!F30+'#60'!F30+'#70'!F27+'#80'!F30+'#90'!F30+'#100'!F30 -> 0 | I7: ='#10'!H13+'#20'!H24+'#30'!H24+'#40'!H24+'#50'!H24+'#60'!H24+'#70'!H21+'#80'!H24+'#90'!H24+'#100'!H24 -> 35250000 | J7: 加工必要資材
E8: 일반구매품 | F8: 식 | G8: 1 | I8: ='#10'!H37+'#20'!H47+'#30'!H47+'#40'!H47+'#50'!H47+'#60'!H64+'#70'!H44+'#80'!H59+'#90'!H47+'#100'!H47 -> 87560000 | J8: 加工不要資材
E9: 외주제작품 | F9: 식 | G9: 1 | I9: ='#10'!H45+'#20'!H55+'#30'!H55+'#40'!H55+'#50'!H55+'#60'!H72+'#70'!H52+'#80'!H67+'#90'!H55+'#100'!H55 -> 0 | J9: 旣加工SUB資材
E10: 설치/해체 공사 자재 | F10: 식 | G10: 1 | I10: ='#10'!H19+'#20'!H30+'#30'!H30+'#40'!H30+'#50'!H30+'#60'!H30+'#70'!H27+'#80'!H30+'#90'!H30+'#100'!H30 -> 0 | J10: 시운전 자재 포함
E11: 소계 | I11: =SUM(I7:I10) -> 122810000
D12: 노무비 | E12: 기존설비 철거 | F12: M/D | G12: ='#10'!F47+'#20'!F57+'#30'!F57+'#40'!F57+'#50'!F57+'#60'!F74+'#70'!F54+'#80'!F69+'#90'!F57+'#100'!F57 -> 1 | H12: =IF('#10'!G47>0,'#10'!G47,"") -> 250000 | I12: ='#10'!H47+'#20'!H57+'#30'!H57+'#40'!H57+'#50'!H57+'#60'!H74+'#70'!H54+'#80'!H69+'#90'!H57+'#100'!H57 -> 300000 | J12: 개조공사時
E13: 설계 | F13: M/D | G13: ='#10'!F48+'#20'!F58+'#30'!F58+'#40'!F58+'#50'!F58+'#60'!F75+'#70'!F55+'#80'!F70+'#90'!F58+'#100'!F58 -> 45 | H13: =IF('#10'!G48>0,'#10'!G48,"") -> 300000 | I13: ='#10'!H48+'#20'!H58+'#30'!H58+'#40'!H58+'#50'!H58+'#60'!H75+'#70'!H55+'#80'!H70+'#90'!H58+'#100'!H58 -> 13500000
E14: 제작(제관,가공) | F14: M/D | G14: ='#10'!F49+'#20'!F59+'#30'!F59+'#40'!F59+'#50'!F59+'#60'!F76+'#70'!F56+'#80'!F71+'#90'!F59+'#100'!F59 -> 18 | H14: =IF('#10'!G49>0,'#10'!G49,"") -> 250000 | I14: ='#10'!H49+'#20'!H59+'#30'!H59+'#40'!H59+'#50'!H59+'#60'!H76+'#70'!H56+'#80'!H71+'#90'!H59+'#100'!H59 -> 4500000
E15: 조립 | F15: M/D | G15: ='#10'!F50+'#20'!F60+'#30'!F60+'#40'!F60+'#50'!F60+'#60'!F77+'#70'!F57+'#80'!F72+'#90'!F60+'#100'!F60 -> 31 | H15: =IF('#10'!G50>0,'#10'!G50,"") -> 250000 | I15: ='#10'!H50+'#20'!H60+'#30'!H60+'#40'!H60+'#50'!H60+'#60'!H77+'#70'!H57+'#80'!H72+'#90'!H60+'#100'!H60 -> 7750000 | J15: 정도검사포함
E16: 설치 | F16: M/D | G16: ='#10'!F51+'#20'!F61+'#30'!F61+'#40'!F61+'#50'!F61+'#60'!F78+'#70'!F58+'#80'!F73+'#90'!F61+'#100'!F61 -> 15 | H16: =IF('#10'!G51>0,'#10'!G51,"") -> 300000 | I16: ='#10'!H51+'#20'!H61+'#30'!H61+'#40'!H61+'#50'!H61+'#60'!H78+'#70'!H58+'#80'!H73+'#90'!H61+'#100'!H61 -> 4500000
E17: 시운전 | F17: M/D | G17: ='#10'!F52+'#20'!F62+'#30'!F62+'#40'!F62+'#50'!F62+'#60'!F79+'#70'!F59+'#80'!F74+'#90'!F62+'#100'!F62 -> 16 | H17: =IF('#10'!G52>0,'#10'!G52,"") -> 300000 | I17: ='#10'!H52+'#20'!H62+'#30'!H62+'#40'!H62+'#50'!H62+'#60'!H79+'#70'!H59+'#80'!H74+'#90'!H62+'#100'!H62 -> 4800000
E18: 양산대응 | F18: M/D | G18: ='#10'!F53+'#20'!F63+'#30'!F63+'#40'!F63+'#50'!F63+'#60'!F80+'#70'!F60+'#80'!F75+'#90'!F63+'#100'!F63 -> 12 | H18: =IF('#10'!G53>0,'#10'!G53,"") -> 300000 | I18: ='#10'!H53+'#20'!H63+'#30'!H63+'#40'!H63+'#50'!H63+'#60'!H80+'#70'!H60+'#80'!H75+'#90'!H63+'#100'!H63 -> 3600000
E19: 도장 | F19: M/D | G19: ='#10'!F54+'#20'!F64+'#30'!F64+'#40'!F64+'#50'!F64+'#60'!F81+'#70'!F61+'#80'!F76+'#90'!F64+'#100'!F64 -> 18 | H19: =IF('#10'!G54>0,'#10'!G54,"") -> 250000 | I19: ='#10'!H54+'#20'!H64+'#30'!H64+'#40'!H64+'#50'!H64+'#60'!H81+'#70'!H61+'#80'!H76+'#90'!H64+'#100'!H64 -> 4500000
E20: 소계 | I20: =SUM(I12:I19) -> 43450000
D21: 일반관리 및 이윤 | I21: ='#10'!H57+'#10'!H58+'#20'!H67+'#20'!H68+'#30'!H67+'#30'!H68+'#40'!H67+'#40'!H68+'#50'!H67+'#50'!H68+'#60'!H84+'#60'!H85+'#70'!H64+'#70'!H65+'#80'!H79+'#80'!H80+'#90'!H67+'#90'!H68+'#100'!H67+'#100'!H68 -> 0
E22: 기계 소계 | I22: =I20+I11+I21 -> 166260000
B23: 2 | C23: 전기 부문 | D23: 자재비 | E23: 기계/전기자재 | F23: 식 | G23: 1 | I23: =전기!H50-I24 -> 52200000
E24: 설치/해체 공사 자재 | F24: 식 | G24: 1 | I24: =전기!H16 -> 0 | J24: 시운전 자재 포함
D25: 노무비 | E25: 철거(개조시) | F25: M/D | G25: =전기!F51 -> 0 | H25: =IF(전기!G51>0,전기!G51,"") -> 300000 | I25: =전기!H51 -> 0
E26: 설계,프로그램 | F26: M/D | G26: =전기!F52 -> 20 | H26: =IF(전기!G52>0,전기!G52,"") -> 300000 | I26: =전기!H52 -> 6000000
E27: 제작 | F27: M/D | G27: =전기!F53 -> 10 | H27: =IF(전기!G53>0,전기!G53,"") -> 250000 | I27: =전기!H53 -> 2500000
E28: 조립 | F28: M/D | G28: =전기!F54 -> 10 | H28: =IF(전기!G54>0,전기!G54,"") -> 250000 | I28: =전기!H54 -> 2500000
E29: 설치 | F29: M/D | G29: =전기!F55 -> 10 | H29: =IF(전기!G55>0,전기!G55,"") -> 300000 | I29: =전기!H55 -> 3000000
E30: 시운전 | F30: M/D | G30: =전기!F56 -> 10 | H30: =IF(전기!G56>0,전기!G56,"") -> 300000 | I30: =전기!H56 -> 3000000
E31: 양산대응 | F31: M/D | G31: =전기!F57 -> 4 | H31: =IF(전기!G57>0,전기!G57,"") -> 300000 | I31: =전기!H57 -> 1200000
E32: 소계 | I32: =SUM(I25:I31) -> 18200000
D33: 일반관리 및 이윤 | I33: =전기!H60+전기!H61 -> 0
E34: 전기 소계 | I34: =I32+I23+I33+I24 -> 70400000
B35: 3 | C35: 자재비 합계 | I35: =I23+I11+I24 -> 175010000
C36: 노무비 합계 | I36: =I32+I20 -> 61650000
C37: 중간 합계 | I37: =I36+I35 -> 236660000
B38: 4 | C38: 포장,운송 및 중장비 사용료 | I38: 500000
B39: 5 | C39: 표준안전관리비 | F39: 설치/철거/수리금액 기준 | I39: =CEILING(MIN(I47:I48),1000) -> 579000 | J39: =I30+I29+I25+I24+I17+I16+I12+I10 -> 15600000
B40: 6 | C40: 일반관리비 | I40: =전기!H60+'#10'!H57+'#20'!H67+'#30'!H67+'#40'!H67+'#50'!H67+'#60'!H84+'#70'!H64+'#80'!H79+'#90'!H67+'#100'!H67 -> 0
B41: 7 | C41: 이 윤 | I41: =전기!H61+'#10'!H58+'#20'!H68+'#30'!H68+'#40'!H68+'#50'!H68+'#60'!H85+'#70'!H65+'#80'!H80+'#90'!H68+'#100'!H68 -> 0
C42: 합 계 | F42: 3~7항 합계 | I42: =I22+I34+I38+I39 -> 237739000
B43: 주1. 표준안전관리비:(설치/철거/시운전 공사 관련 금액)의 ⓐ2.66%,ⓑ1.95%+기초액,ⓒ2.02%(50억 이상일경우)
...

Sheet 단위공사별(집계)
A2: B. 단위장비별 견적가 종합(상세견적 첨부)
N3: 단위:원
I5: 포장/운송 | L5: 표준안전 | M5: 일반관리비
A6: 순번 | B6: 단위장비명 | C6: 수량 | D6: 자재비 | E6: 철거 | F6: 제작 | G6: 설치/시운전 | H6: 양산대응 | I6: 중장비사용 | J6: 기계소계 | K6: 전기소계 | L6: 관리비 | M6: 이윤 | N6: 합 계 | O6: 비 고
A7: =IF(B7>0,1,"") -> 1 | B7: ='#10'!C$1 -> 허버베어링 에어블로잉 공정 추가 | C7: 1식 | D7: ='#10'!H46 -> 9980000 | E7: ='#10'!H47 -> 0 | F7: ='#10'!H48+'#10'!H49+'#10'!H50+'#10'!H54 -> 6150000 | G7: ='#10'!H51+'#10'!H52 -> 1200000 | H7: ='#10'!H53 -> 600000 | I7: =IF($B7>0,'원가항목별(집계)'!I$38*$P7/$P$17,0) -> 53921.569 | J7: =SUM(D7:I7) -> 17983922 | K7: =IF(B7>0,'원가항목별(집계)'!I$34*P7/P$17,0) -> 7592156.9 | L7: =IF($B7>0,'원가항목별(집계)'!I$39*$P7/$P$17,0) -> 62441.176 | M7: ='#10'!H57+'#10'!H58 -> 0 | N7: =SUM(J7:M7) -> 25638520 | P7: =D7+E7+F7+G7+H7+M7 -> 17930000
A8: =IF(B8>0,A7+1,"") -> 2 | B8: ='#20'!C$1 -> 허버볼트 이종사양 검출 | C8: 1식 | D8: ='#20'!H56 -> 2500000 | E8: ='#20'!H57 -> 0 | F8: ='#20'!H58+'#20'!H59+'#20'!H60+'#20'!H64 -> 1350000 | G8: ='#20'!H61+'#20'!H62 -> 600000 | H8: ='#20'!H63 -> 300000 | I8: =IF($B8>0,'원가항목별(집계)'!I$38*$P8/$P$17,0) -> 14284.855 | J8: =SUM(D8:I8) -> 4764284.9 | K8: =IF(B8>0,'원가항목별(집계)'!I$34*P8/P$17,0) -> 2011307.6 | L8: =IF($B8>0,'원가항목별(집계)'!I$39*$P8/$P$17,0) -> 16541.862 | M8: ='#20'!H67+'#20'!H68 -> 0 | N8: =SUM(J8:M8) -> 6792134.3 | P8: =D8+E8+F8+G8+H8+M8 -> 4750000
A9: =IF(B9>0,A8+1,"") -> 3 | B9: ='#30'!C$1 -> 허버베어링 2D리딩추가 | C9: 1식 | D9: ='#30'!H56 -> 4900000 | E9: ='#30'!H57 -> 0 | F9: ='#30'!H58+'#30'!H59+'#30'!H60+'#30'!H64 -> 1350000 | G9: ='#30'!H61+'#30'!H62 -> 600000 | H9: ='#30'!H63 -> 300000 | I9: =IF($B9>0,'원가항목별(집계)'!I$38*$P9/$P$17,0) -> 21502.466 | J9: =SUM(D9:I9) -> 7171502.5 | K9: =IF(B9>0,'원가항목별(집계)'!I$34*P9/P$17,0) -> 3027547.2 | L9: =IF($B9>0,'원가항목별(집계)'!I$39*$P9/$P$17,0) -> 24899.856 | M9: ='#30'!H67+'#30'!H68 -> 0 | N9: =SUM(J9:M9) -> 10223950 | P9: =D9+E9+F9+G9+H9+M9 -> 7150000
A10: =IF(B10>0,A9+1,"") -> 4 | B10: ='#40'!C$1 -> 허버베어링 센트링디바이스추가 | C10: 1식 | D10: ='#40'!H56 -> 4100000 | E10: ='#40'!H57 -> 0 | F10: ='#40'!H58+'#40'!H59+'#40'!H60+'#40'!H64 -> 1350000 | G10: ='#40'!H61+'#40'!H62 -> 600000 | H10: ='#40'!H63 -> 300000 | I10: =IF($B10>0,'원가항목별(집계)'!I$38*$P10/$P$17,0) -> 19096.596 | J10: =SUM(D10:I10) -> 6369096.6 | K10: =IF(B10>0,'원가항목별(집계)'!I$34*P10/P$17,0) -> 2688800.7 | L10: =IF($B10>0,'원가항목별(집계)'!I$39*$P10/$P$17,0) -> 22113.858 | M10: ='#40'!H67+'#40'!H68 -> 0 | N10: =SUM(J10:M10) -> 9080011.1 | P10: =D10+E10+F10+G10+H10+M10 -> 6350000
A11: =IF(B11>0,A10+1,"") -> 5 | B11: ='#50'!C$1 -> 이너레이스 자동박스 2D 바코드 리더기 추가 | C11: 1식 | D11: ='#50'!H56 -> 12700000 | E11: ='#50'!H57 -> 0 | F11: ='#50'!H58+'#50'!H59+'#50'!H60+'#50'!H64 -> 1900000 | G11: ='#50'!H61+'#50'!H62 -> 1200000 | H11: ='#50'!H63 -> 300000 | I11: =IF($B11>0,'원가항목별(집계)'!I$38*$P11/$P$17,0) -> 48418.14 | J11: =SUM(D11:I11) -> 16148418 | K11: =IF(B11>0,'원가항목별(집계)'!I$34*P11/P$17,0) -> 6817274.1 | L11: =IF($B11>0,'원가항목별(집계)'!I$39*$P11/$P$17,0) -> 56068.206 | M11: ='#50'!H67+'#50'!H68 -> 0 | N11: =SUM(J11:M11) -> 23021760 | P11: =D11+E11+F11+G11+H11+M11 -> 16100000
A12: =IF(B12>0,A11+1,"") -> 6 | B12: ='#60'!C$1 -> I/B 모니트링 장치 추가 | C12: 1식 | D12: ='#60'!H73 -> 700000 | E12: ='#60'!H74 -> 0 | F12: ='#60'!H75+'#60'!H76+'#60'!H77+'#60'!H81 -> 1350000 | G12: ='#60'!H78+'#60'!H79 -> 600000 | H12: ='#60'!H80 -> 300000 | I12: =IF($B12>0,'원가항목별(집계)'!I$38*$P12/$P$17,0) -> 8871.6468 | J12: =SUM(D12:I12) -> 2958871.6 | K12: =IF(B12>0,'원가항목별(집계)'!I$34*P12/P$17,0) -> 1249127.9 | L12: =IF($B12>0,'원가항목별(집계)'!I$39*$P12/$P$17,0) -> 10273.367 | M12: ='#60'!H84+'#60'!H85 -> 0 | N12: =SUM(J12:M12) -> 4218272.9 | P12: =D12+E12+F12+G12+H12+M12 -> 2950000
A13: =IF(B13>0,A12+1,"") -> 7 | B13: ='#70'!C$1 -> I/B저상리프트 추가 | C13: 1식 | D13: ='#70'!H53 -> 14000000 | E13: ='#70'!H54 -> 0 | F13: ='#70'!H55+'#70'!H56+'#70'!H57+'#70'!H61 -> 0 | G13: ='#70'!H58+'#70'!H59 -> 0 | H13: ='#70'!H60 -> 0 | I13: =IF($B13>0,'원가항목별(집계)'!I$38*$P13/$P$17,0) -> 42102.731 | J13: =SUM(D13:I13) -> 14042103 | K13: =IF(B13>0,'원가항목별(집계)'!I$34*P13/P$17,0) -> 5928064.5 | L13: =IF($B13>0,'원가항목별(집계)'!I$39*$P13/$P$17,0) -> 48754.962 | M13: ='#70'!H64+'#70'!H65 -> 0 | N13: =SUM(J13:M13) -> 20018922 | P13: =D13+E13+F13+G13+H13+M13 -> 14000000
A14: =IF(B14>0,A13+1,"") -> 8 | B14: ='#80'!C$1 -> 드레그토크 측정기 | C14: 1식 | D14: ='#80'!H68 -> 17060000 | E14: ='#80'!H69 -> 0 | F14: ='#80'!H70+'#80'!H71+'#80'!H72+'#80'!H76 -> 10750000 | G14: ='#80'!H73+'#80'!H74 -> 2100000 | H14: ='#80'!H75 -> 600000 | I14: =IF($B14>0,'원가항목별(집계)'!I$38*$P14/$P$17,0) -> 91753.879 | J14: =SUM(D14:I14) -> 30601754 | K14: =IF(B14>0,'원가항목별(집계)'!I$34*P14/P$17,0) -> 12918946 | L14: =IF($B14>0,'원가항목별(집계)'!I$39*$P14/$P$17,0) -> 106250.99 | M14: ='#80'!H79+'#80'!H80 -> 0 | N14: =SUM(J14:M14) -> 43626951 | P14: =D14+E14+F14+G14+H14+M14 -> 30510000
A15: =IF(B15>0,A14+1,"") -> 9 | B15: ='#90'!C$1 -> RG3공유 리툴링 | C15: 1식 | D15: ='#90'!H56 -> 8010000 | E15: ='#90'!H57 -> 300000 | F15: ='#90'!H58+'#90'!H59+'#90'!H60+'#90'!H64 -> 1050000 | G15: ='#90'!H61+'#90'!H62 -> 600000 | H15: ='#90'!H63 -> 300000 | I15: =IF($B15>0,'원가항목별(집계)'!I$38*$P15/$P$17,0) -> 30855.287 | J15: =SUM(D15:I15) -> 10290855 | K15: =IF(B15>0,'원가항목별(집계)'!I$34*P15/P$17,0) -> 4344424.4 | L15: =IF($B15>0,'원가항목별(집계)'!I$39*$P15/$P$17,0) -> 35730.422 | M15: ='#90'!H67+'#90'!H68 -> 0 | N15: =SUM(J15:M15) -> 14671010 | P15: =D15+E15+F15+G15+H15+M15 -> 10260000
A16: =IF(B16>0,A15+1,"") -> 10 | B16: ='#100'!C$1 -> 스토퍼링 P/FROOF | C16: 1식 | D16: ='#100'!H56 -> 48860000 | E16: ='#100'!H57 -> 0 | F16: ='#100'!H58+'#100'!H59+'#100'!H60+'#100'!H64 -> 5000000 | G16: ='#100'!H61+'#100'!H62 -> 1800000 | H16: ='#100'!H63 -> 600000 | I16: =IF($B16>0,'원가항목별(집계)'!I$38*$P16/$P$17,0) -> 169192.83 | J16: =SUM(D16:I16) -> 56429193 | K16: =IF(B16>0,'원가항목별(집계)'!I$34*P16/P$17,0) -> 23822351 | L16: =IF($B16>0,'원가항목별(집계)'!I$39*$P16/$P$17,0) -> 195925.3 | M16: ='#100'!H67+'#100'!H68 -> 0 | N16: =SUM(J16:M16) -> 80447469 | P16: =D16+E16+F16+G16+H16+M16 -> 56260000
A17: 합 계 | D17: =SUM(D7:D16) -> 122810000 | E17: =SUM(E7:E16) -> 300000 | F17: =SUM(F7:F16) -> 30250000 | G17: =SUM(G7:G16) -> 9300000 | H17: =SUM(H7:H16) -> 3600000 | I17: =SUM(I7:I16) -> 500000 | J17: =SUM(D17:I17) -> 166760000 | K17: =SUM(K7:K16) -> 70400000 | L17: =SUM(L7:L16) -> 579000 | M17: =SUM(M7:M16) -> 0 | N17: =SUM(N7:N16) -> 237739000 | P17: =SUM(P7:P16) -> 166260000
D18: =IF(D17=0,"",D17/$N17) -> 0.5165749 | E18: =IF(E17=0,"",E17/$N17) -> 0.001261888 | F18: =IF(F17=0,"",F17/$N17) -> 0.12724038 | G18: =IF(G17=0,"",G17/$N17) -> 0.039118529 | H18: =IF(H17=0,"",H17/$N17) -> 0.015142656 | I18: =IF(I17=0,"",I17/$N17) -> 0.0021031467 | J18: =IF(J17=0,"",J17/$N17) -> 0.7014415 | K18: =IF(K17=0,"",K17/$N17) -> 0.29612306 | ... N18: =IF(N17=0,"",N17/$N17) -> 1
A19: 주) 전기비용은 턴키장비의 공통비용으로서 총 전기비용을 단위장비별 기계금액의 비율에 따라 배분함
N20: =IF('원가항목별(집계)'!I42='단위공사별(집계)'!N17,"","DATA오류입니다!")

Sheet 전기
B1: □ 전기부문: | C1: 전기부문(공통) | I1: (첨부)
A2: 구분 | C2: 품 명 | D2: 규격 | E2: 단위 | F2: 수량 | G2: 단가(원) | H2: 금액(원) | I2: 原MAKER
A3: 자 재 비 | B3: 철자재 | H3: =IF(F3=0,G3,G3*F3) -> 0
H4: =IF(F4=0,G4,G4*F4) -> 0
H5: =IF(F5=0,G5,G5*F5) -> 0
H6: =IF(F6=0,G6,G6*F6) -> 0
H7: =IF(F7=0,G7,G7*F7) -> 0
H8: =IF(F8=0,G8,G8*F8) -> 0
H9: =SUM(H3:H8) -> 0
B10: 설치/해체/ | H10: =IF(F10=0,G10,G10*F10) -> 0
B11: 시운전 공사 | H11: =IF(F11=0,G11,G11*F11) -> 0
B12: 자재 | H12: =IF(F12=0,G12,G12*F12) -> 0
H13: =IF(F13=0,G13,G13*F13) -> 0
H14: =IF(F14=0,G14,G14*F14) -> 0
H15: =IF(F15=0,G15,G15*F15) -> 0
H16: =SUM(H10:H15) -> 0
B17: 전기자재 | C17: 에어블로우 공정 추가 | D17: 잡자재 | E17: 식 | F17: 1 | G17: 500000 | H17: =IF(F17=0,G17,G17*F17) -> 500000
C18: 허브볼트이종사양검출 | D18: 잡자재 | E18: 식 | F18: 1 | G18: 500000 | H18: =IF(F18=0,G18,G18*F18) -> 500000
C19: 허버베어링 2D바코드추가 | D19: 잡자재 | E19: 식 | F19: 1 | G19: 2000000 | H19: =IF(F19=0,G19,G19*F19) -> 2000000
C20: 이너레이스 2D바코드추가 | D20: 잡자재 | E20: 식 | F20: 1 | G20: 2000000 | H20: =IF(F20=0,G20,G20*F20) -> 2000000
C21: I/B모니터링 장치 추가 | D21: 터치등 | E21: 식 | F21: 1 | G21: 3200000 | H21: =IF(F21=0,G21,G21*F21) -> 3200000
C22: 드레그토크측정기 | D22: PLC등 | E22: 식 | F22: 1 | G22: 3000000 | H22: =IF(F22=0,G22,G22*F22) -> 3000000
C23: 스토퍼링비젼대응 | H23: =IF(F23=0,G23,G23*F23) -> 0
C24: ■PLC구매품 | D24: PLC등 | E24: 식 | F24: 1 | G24: 1000000 | H24: =IF(F24=0,G24,G24*F24) -> 1000000
C25: ■PC구매품 | D25: PC등 | E25: 식 | F25: 1 | G25: 10000000 | H25: =IF(F25=0,G25,G25*F25) -> 10000000
C26: ■PC P/G | E26: 식 | F26: 1 | G26: 30000000 | H26: =IF(F26=0,G26,G26*F26) -> 30000000
H27: =IF(F27=0,G27,G27*F27) -> 0
H28: =IF(F28=0,G28,G28*F28) -> 0
H29: =IF(F29=0,G29,G29*F29) -> 0
H30: =IF(F30=0,G30,G30*F30) -> 0
H31: =IF(F31=0,G31,G31*F31) -> 0
H32: =IF(F32=0,G32,G32*F32) -> 0
H33: =IF(F33=0,G33,G33*F33) -> 0
H34: =IF(F34=0,G34,G34*F34) -> 0
H35: =IF(F35=0,G35,G35*F35) -> 0
H36: =IF(F36=0,G36,G36*F36) -> 0
H37: =IF(F37=0,G37,G37*F37) -> 0
H38: =IF(F38=0,G38,G38*F38) -> 0
... H47: =IF(F47=0,G47,G47*F47) -> 0
C48: 기타 | E48: 식 | H48: =IF(F48=0,G48,G48*F48) -> 0
...

Sheet #10
B1: □ 단위공사명(전기제외): | C1: 허버베어링 에어블로잉 공정 추가 | I1: (첨부)
A2: 구분 | C2: 품 명 | D2: 규격 | E2: 단위 | F2: 수량 | G2: 단가(원) | H2: 금액(원) | I2: 原MAKER
B3: 철자재 | C3: ■FRAME류 | D3: 제관,가공 | E3: 식 | F3: 2 | G3: 500000 | H3: =IF(F3=0,G3,G3*F3) -> 1000000
C4: ■BASE 류 | D4: 가공 | E4: 식 | F4: 2 | G4: 500000 | H4: =IF(F4=0,G4,G4*F4) -> 1000000
C5: ■일반 부품류 | D5: 판금품,가공품 | E5: 식 | F5: 40 | G5: 70000 | H5: =IF(F5=0,G5,G5*F5) -> 2800000
C6: ■정도 부품류 | D6: 가공품 | E6: 식 | F6: 20 | G6: 150000 | H6: =IF(F6=0,G6,G6*F6) -> 3000000
H7: =IF(F7=0,G7,G7*F7) -> 0
H8: =IF(F8=0,G8,G8*F8) -> 0
H9: =IF(F9=0,G9,G9*F9) -> 0
H10: =IF(F10=0,G10,G10*F10) -> 0
H11: =IF(F11=0,G11,G11*F11) -> 0
C12: 기타자재 | H12: =IF(F12=0,G12,G12*F12) -> 0
H13: =SUM(H3:H12) -> 7800000
B14: 설치/해체/시운전 | H14: =IF(F14=0,G14,G14*F14) -> 0
B15: 공사 관련 자재 | H15: =IF(F15=0,G15,G15*F15) -> 0
H16: =IF(F16=0,G16,G16*F16) -> 0
H17: =IF(F17=0,G17,G17*F17) -> 0
H18: =IF(F18=0,G18,G18*F18) -> 0
H19: =SUM(H14:H18) -> 0
B20: 구매품 | C20: 집진기 | E20: 식 | F20: 1 | G20: 1000000 | H20: =IF(F20=0,0,G20*F20) -> 1000000
B21: (유공압품외) | C21: 기타 구입품 | E21: 식 | F21: 1 | G21: 500000 | H21: =IF(F21=0,0,G21*F21) -> 500000
H22: =IF(F22=0,0,G22*F22) -> 0
H23: =IF(F23=0,0,G23*F23) -> 0
C24: ■일반 자재류 | H24: =IF(F24=0,0,G24*F24) -> 0
C25: F.R.L Unit | E25: 식 | F25: 0 | G25: 350000 | H25: =IF(F25=0,0,G25*F25) -> 0
C26: Shut off Valve | E26: 식 | F26: 4 | G26: 70000 | H26: =IF(F26=0,0,G26*F26) -> 280000
C27: Manifold | E27: 식 | F27: 0 | G27: 800000 | H27: =IF(F27=0,0,G27*F27) -> 0
C28: Speed Con. | E28: 식 | F28: 2 | G28: 50000 | H28: =IF(F28=0,0,G28*F28) -> 100000
C29: 배관자재 | E29: 식 | F29: 2 | G29: 50000 | H29: =IF(F29=0,0,G29*F29) -> 100000
C30: 잡자재 | E30: 식 | F30: 2 | G30: 50000 | H30: =IF(F30=0,0,G30*F30) -> 100000
H31: =IF(F31=0,0,G31*F31) -> 0
H32: =IF(F32=0,0,G32*F32) -> 0
H33: =IF(F33=0,0,G33*F33) -> 0
H34: =IF(F34=0,0,G34*F34) -> 0
H35: =IF(F35=0,0,G35*F35) -> 0
C36: 기타자재 | E36: 식 | F36: 1 | G36: 100000 | H36: =IF(F36=0,0,G36*F36) -> 100000
H37: =SUM(H20:H36) -> 2180000
B38: 외주제작품 | H38: =IF(F38=0,G38,G38*F38) -> 0
H39: =IF(F39=0,G39,G39*F39) -> 0
H40: =IF(F40=0,G40,G40*F40) -> 0
...

Sheet #20
B1: □ 단위공사명(전기제외): | C1: 허버볼트 이종사양 검출 | I1: (첨부)
A2: 구분 | C2: 품 명 | D2: 규격 | E2: 단위 | F2: 수량 | G2: 단가(원) | H2: 금액(원) | I2: 原MAKER
A3: 자 재 비 | B3: 철자재 | C3: ■일반 부품류 | D3: 판금품,가공품 | E3: 식 | F3: 1 | G3: 1000000 | H3: =IF(F3=0,G3,G3*F3) -> 1000000
H4: =IF(F4=0,G4,G4*F4) -> 0
H5: =IF(F5=0,G5,G5*F5) -> 0
H6: =IF(F6=0,G6,G6*F6) -> 0
H7: =IF(F7=0,G7,G7*F7) -> 0
H8: =IF(F8=0,G8,G8*F8) -> 0
H9: =IF(F9=0,G9,G9*F9) -> 0
H10: =IF(F10=0,G10,G10*F10) -> 0
H11: =IF(F11=0,G11,G11*F11) -> 0
H12: =IF(F12=0,G12,G12*F12) -> 0
H13: =IF(F13=0,G13,G13*F13) -> 0
H14: =IF(F14=0,G14,G14*F14) -> 0
H15: =IF(F15=0,G15,G15*F15) -> 0
... H22: =IF(F22=0,G22,G22*F22) -> 0
C23: 기타 | E23: 식 | F23: 1 | G23: 200000 | H23: =IF(F23=0,G23,G23*F23) -> 200000
H24: =SUM(H3:H23) -> 1200000
B25: 설치/해체/시운전 | H25: =IF(F25=0,G25,G25*F25) -> 0
B26: 공사 관련 자재 | H26: =IF(F26=0,G26,G26*F26) -> 0
H27: =IF(F27=0,G27,G27*F27) -> 0
H28: =IF(F28=0,G28,G28*F28) -> 0
H29: =IF(F29=0,G29,G29*F29) -> 0
H30: =SUM(H25:H29) -> 0
B31: 구매품 | C31: ■이종검출부 | H31: =IF(F31=0,0,G31*F31) -> 0
B32: (유공압품외) | C32: 검출센스 | D32: ZX1 변위센스 | E32: 식 | F32: 1 | G32: 1200000 | H32: =IF(F32=0,0,G32*F32) -> 1200000 | I32: OMRON
H33: =IF(F33=0,G33,G33*F33) -> 0
H34: =IF(F34=0,G34,G34*F34) -> 0
H35: =IF(F35=0,G35,G35*F35) -> 0
H36: =IF(F36=0,G36,G36*F36) -> 0
H37: =IF(F37=0,G37,G37*F37) -> 0
H38: =IF(F38=0,G38,G38*F38) -> 0
H39: =IF(F39=0,G39,G39*F39) -> 0
H40: =IF(F40=0,G40,G40*F40) -> 0
H41: =IF(F41=0,G41,G41*F41) -> 0
H42: =IF(F42=0,G42,G42*F42) -> 0
H43: =IF(F43=0,G43,G43*F43) -> 0
H44: =IF(F44=0,G44,G44*F44) -> 0
H45: =IF(F45=0,G45,G45*F45) -> 0
C46: 기타자재 | E46: 식 | F46: 1 | G46: 100000 | H46: =IF(F46=0,G46,G46*F46) -> 100000
...

Sheet #30
B1: □ 단위공사명(전기제외): | C1: 허버베어링 2D리딩추가 | I1: (첨부)
A2: 구분 | C2: 품 명 | D2: 규격 | E2: 단위 | F2: 수량 | G2: 단가(원) | H2: 금액(원) | I2: 原MAKER
A3: 자 재 비 | B3: 철자재 | C3: ■일반 부품류 | D3: 판금품,가공품 | E3: 식 | F3: 1 | G3: 1000000 | H3: =IF(F3=0,G3,G3*F3) -> 1000000
H4: =IF(F4=0,G4,G4*F4) -> 0
H5: =IF(F5=0,G5,G5*F5) -> 0
H6: =IF(F6=0,G6,G6*F6) -> 0
H7: =IF(F7=0,G7,G7*F7) -> 0
H8: =IF(F8=0,G8,G8*F8) -> 0
H9: =IF(F9=0,G9,G9*F9) -> 0
H10: =IF(F10=0,G10,G10*F10) -> 0
H11: =IF(F11=0,G11,G11*F11) -> 0
H12: =IF(F12=0,G12,G12*F12) -> 0
H13: =IF(F13=0,G13,G13*F13) -> 0
H14: =IF(F14=0,G14,G14*F14) -> 0
H15: =IF(F15=0,G15,G15*F15) -> 0
... H22: =IF(F22=0,G22,G22*F22) -> 0
C23: 기타자재 | E23: 식 | F23: 1 | G23: 200000 | H23: =IF(F23=0,G23,G23*F23) -> 200000
H24: =SUM(H3:H23) -> 1200000
B25: 설치/해체/시운전 | H25: =IF(F25=0,G25,G25*F25) -> 0
B26: 공사 관련 자재 | H26: =IF(F26=0,G26,G26*F26) -> 0
H27: =IF(F27=0,G27,G27*F27) -> 0
H28: =IF(F28=0,G28,G28*F28) -> 0
H29: =IF(F29=0,G29,G29*F29) -> 0
H30: =SUM(H25:H29) -> 0
B31: 구매품 | C31: ■2D 리더 | D31: SR-2000 | E31: 식 | F31: 1 | G31: 3500000 | H31: =IF(F31=0,G31,G31*F31) -> 3500000 | I31: KEYENCE
B32: (유공압품외) | H32: =IF(F32=0,G32,G32*F32) -> 0
H33: =IF(F33=0,G33,G33*F33) -> 0
H34: =IF(F34=0,G34,G34*F34) -> 0
H35: =IF(F35=0,G35,G35*F35) -> 0
H36: =IF(F36=0,G36,G36*F36) -> 0
H37: =IF(F37=0,G37,G37*F37) -> 0
H38: =IF(F38=0,G38,G38*F38) -> 0
H39: =IF(F39=0,G39,G39*F39) -> 0
H40: =IF(F40=0,G40,G40*F40) -> 0
H41: =IF(F41=0,G41,G41*F41) -> 0
H42: =IF(F42=0,G42,G42*F42) -> 0
H43: =IF(F43=0,G43,G43*F43) -> 0
H44: =IF(F44=0,G44,G44*F44) -> 0
H45: =IF(F45=0,G45,G45*F45) -> 0
C46: 기타자재 | E46: 식 | F46: 1 | G46: 200000 | H46: =IF(F46=0,G46,G46*F46) -> 200000
...

Sheet #40
B1: □ 단위공사명(전기제외): | C1: 허버베어링 센트링디바이스추가 | I1: (첨부)
A2: 구분 | C2: 품 명 | D2: 규격 | E2: 단위 | F2: 수량 | G2: 단가(원) | H2: 금액(원) | I2: 原MAKER
A3: 자 재 비 | B3: 철자재 | C3: ■일반 부품류 | D3: 판금품,가공품 | E3: 식 | F3: 1 | G3: 1200000 | H3: =IF(F3=0,G3,G3*F3) -> 1200000
H4: =IF(F4=0,G4,G4*F4) -> 0
H5: =IF(F5=0,G5,G5*F5) -> 0
H6: =IF(F6=0,G6,G6*F6) -> 0
H7: =IF(F7=0,G7,G7*F7) -> 0
H8: =IF(F8=0,G8,G8*F8) -> 0
H9: =IF(F9=0,G9,G9*F9) -> 0
H10: =IF(F10=0,G10,G10*F10) -> 0
H11: =IF(F11=0,G11,G11*F11) -> 0
H12: =IF(F12=0,G12,G12*F12) -> 0
H13: =IF(F13=0,G13,G13*F13) -> 0
H14: =IF(F14=0,G14,G14*F14) -> 0
H15: =IF(F15=0,G15,G15*F15) -> 0
... H22: =IF(F22=0,G22,G22*F22) -> 0
C23: 기타 가공물 | E23: 식 | F23: 1 | G23: 200000 | H23: =IF(F23=0,G23,G23*F23) -> 200000
H24: =SUM(H3:H23) -> 1400000
B25: 설치/해체/시운전 | H25: =IF(F25=0,G25,G25*F25) -> 0
B26: 공사 관련 자재 | H26: =IF(F26=0,G26,G26*F26) -> 0
H27: =IF(F27=0,G27,G27*F27) -> 0
H28: =IF(F28=0,G28,G28*F28) -> 0
C29: 기타자재 | H29: =IF(F29=0,G29,G29*F29) -> 0
H30: =SUM(H25:H29) -> 0
B31: 구매품 | C31: 센트링 디바이스 | D31: 모비코 7톤 | E31: 식 | F31: 1 | G31: 2500000 | H31: =IF(F31=0,G31,G31*F31) -> 2500000
B32: (유공압품외) | H32: =IF(F32=0,G32,G32*F32) -> 0
H33: =IF(F33=0,G33,G33*F33) -> 0
H34: =IF(F34=0,G34,G34*F34) -> 0
H35: =IF(F35=0,G35,G35*F35) -> 0
H36: =IF(F36=0,G36,G36*F36) -> 0
H37: =IF(F37=0,G37,G37*F37) -> 0
H38: =IF(F38=0,G38,G38*F38) -> 0
H39: =IF(F39=0,G39,G39*F39) -> 0
H40: =IF(F40=0,G40,G40*F40) -> 0
H41: =IF(F41=0,G41,G41*F41) -> 0
H42: =IF(F42=0,G42,G42*F42) -> 0
H43: =IF(F43=0,G43,G43*F43) -> 0
H44: =IF(F44=0,G44,G44*F44) -> 0
H45: =IF(F45=0,G45,G45*F45) -> 0
C46: 기타자재 | E46: 식 | F46: 1 | G46: 200000 | H46: =IF(F46=0,G46,G46*F46) -> 200000
...

Sheet #50
B1: □ 단위공사명(전기제외): | C1: 이너레이스 자동박스 2D 바코드 리더기 추가 | I1: (첨부)
A2: 구분 | C2: 품 명 | D2: 규격 | E2: 단위 | F2: 수량 | G2: 단가(원) | H2: 금액(원) | I2: 原MAKER
A3: 자 재 비 | B3: 철자재 | C3: ■일반 부품류 | D3: 판금품,가공품 | E3: 식 | F3: 1 | G3: 500000 | H3: =IF(F3=0,G3,G3*F3) -> 500000
H4: =IF(F4=0,G4,G4*F4) -> 0
H5: =IF(F5=0,G5,G5*F5) -> 0
H6: =IF(F6=0,G6,G6*F6) -> 0
H7: =IF(F7=0,G7,G7*F7) -> 0
H8: =IF(F8=0,G8,G8*F8) -> 0
H9: =IF(F9=0,G9,G9*F9) -> 0
H10: =IF(F10=0,G10,G10*F10) -> 0
H11: =IF(F11=0,G11,G11*F11) -> 0
H12: =IF(F12=0,G12,G12*F12) -> 0
H13: =IF(F13=0,G13,G13*F13) -> 0
H14: =IF(F14=0,G14,G14*F14) -> 0
H15: =IF(F15=0,G15,G15*F15) -> 0
... H22: =IF(F22=0,G22,G22*F22) -> 0
C23: 기타자재 | E23: 식 | F23: 1 | G23: 100000 | H23: =IF(F23=0,G23,G23*F23) -> 100000
H24: =SUM(H3:H23) -> 600000
B25: 설치/해체/시운전 | H25: =IF(F25=0,G25,G25*F25) -> 0
B26: 공사 관련 자재 | H26: =IF(F26=0,G26,G26*F26) -> 0
H27: =IF(F27=0,G27,G27*F27) -> 0
H28: =IF(F28=0,G28,G28*F28) -> 0
C29: 기타자재 | H29: =IF(F29=0,G29,G29*F29) -> 0
H30: =SUM(H25:H29) -> 0
B31: 구매품 | C31: ■TRAY 및 BOX | E31: 식 | F31: 1 | G31: 7500000 | H31: =IF(F31=0,G31,G31*F31) -> 7500000
B32: (유공압품외) | C32: ■2D BARCODE부 | H32: =IF(F32=0,G32,G32*F32) -> 0
C33: 2D BARCODE | E33: 식 | F33: 1 | G33: 3500000 | H33: =IF(F33=0,G33,G33*F33) -> 3500000
C34: 1축동작부 | E34: 식 | F34: 1 | G34: 1000000 | H34: =IF(F34=0,G34,G34*F34) -> 1000000
H35: =IF(F35=0,G35,G35*F35) -> 0
H36: =IF(F36=0,G36,G36*F36) -> 0
H37: =IF(F37=0,G37,G37*F37) -> 0
H38: =IF(F38=0,G38,G38*F38) -> 0
H39: =IF(F39=0,G39,G39*F39) -> 0
H40: =IF(F40=0,G40,G40*F40) -> 0
H41: =IF(F41=0,G41,G41*F41) -> 0
H42: =IF(F42=0,G42,G42*F42) -> 0
H43: =IF(F43=0,G43,G43*F43) -> 0
H44: =IF(F44=0,G44,G44*F44) -> 0
H45: =IF(F45=0,G45,G45*F45) -> 0
C46: 기타자재 | E46: 식 | F46: 1 | G46: 100000 | H46: =IF(F46=0,G46,G46*F46) -> 100000
...

Sheet #60
B1: □ 단위공사명(전기제외): | C1: I/B 모니트링 장치 추가 | I1: (첨부)
A2: 구분 | C2: 품 명 | D2: 규격 | E2: 단위 | F2: 수량 | G2: 단가(원) | H2: 금액(원) | I2: 原MAKER
A3: 자 재 비 | B3: 철자재 | C3: ■일반 부품류 | D3: 판금품,가공품 | E3: 식 | F3: 1 | G3: 600000 | H3: =IF(F3=0,G3,G3*F3) -> 600000
H4: =F4*G4 -> 0
H5: =F5*G5 -> 0
H6: =F6*G6 -> 0
H7: =F7*G7 -> 0
H8: =F8*G8 -> 0
H9: =F9*G9 -> 0
H10: =F10*G10 -> 0
H11: =F11*G11 -> 0
H12: =F12*G12 -> 0
H13: =F13*G13 -> 0
H14: =F14*G14 -> 0
H15: =F15*G15 -> 0
... H21: =F21*G21 -> 0
H22: =IF(F22=0,G22,G22*F22) -> 0
C23: 기타 가공물 | E23: 식 | F23: 1 | G23: 100000 | H23: =IF(F23=0,G23,G23*F23) -> 100000
H24: =SUM(H3:H23) -> 700000
B25: 설치/해체/시운전 | H25: =IF(F25=0,G25,G25*F25) -> 0
B26: 공사 관련 자재 | H26: =IF(F26=0,G26,G26*F26) -> 0
H27: =IF(F27=0,G27,G27*F27) -> 0
H28: =IF(F28=0,G28,G28*F28) -> 0
C29: 기타자재 | H29: =IF(F29=0,G29,G29*F29) -> 0
H30: =SUM(H25:H29) -> 0
B31: 구매품 | H31: =IF(F31=0,G31,G31*F31) -> 0
B32: (유공압품외) | H32: =IF(F32=0,G32,G32*F32) -> 0
H33: =IF(F33=0,G33,G33*F33) -> 0
H34: =IF(F34=0,G34,G34*F34) -> 0
H35: =IF(F35=0,G35,G35*F35) -> 0
H36: =IF(F36=0,G36,G36*F36) -> 0
H37: =IF(F37=0,G37,G37*F37) -> 0
H38: =IF(F38=0,G38,G38*F38) -> 0
H39: =IF(F39=0,G39,G39*F39) -> 0
H40: =IF(F40=0,G40,G40*F40) -> 0
H41: =IF(F41=0,G41,G41*F41) -> 0
H42: =IF(F42=0,G42,G42*F42) -> 0
H43: =IF(F43=0,G43,G43*F43) -> 0
H44: =IF(F44=0,G44,G44*F44) -> 0
... H47: =IF(F47=0,G47,G47*F47) -> 0
...

Sheet #70
B1: □ 단위공사명(전기제외): | C1: I/B저상리프트 추가 | I1: (첨부)
A2: 구분 | C2: 품 명 | D2: 규격 | E2: 단위 | F2: 수량 | G2: 단가(원) | H2: 금액(원) | I2: 原MAKER
A3: 자 재 비 | B3: 철자재 | H3: =IF(F3=0,G3,G3*F3) -> 0
H4: =IF(F4=0,G4,G4*F4) -> 0
H5: =IF(F5=0,G5,G5*F5) -> 0
H6: =IF(F6=0,G6,G6*F6) -> 0
H7: =IF(F7=0,G7,G7*F7) -> 0
H8: =IF(F8=0,G8,G8*F8) -> 0
H9: =IF(F9=0,G9,G9*F9) -> 0
H10: =IF(F10=0,G10,G10*F10) -> 0
H11: =IF(F11=0,G11,G11*F11) -> 0
H12: =IF(F12=0,G12,G12*F12) -> 0
H13: =IF(F13=0,G13,G13*F13) -> 0
H14: =IF(F14=0,G14,G14*F14) -> 0
H15: =IF(F15=0,G15,G15*F15) -> 0
... H20: =IF(F20=0,G20,G20*F20) -> 0
H21: =SUM(H3:H20) -> 0
B22: 설치/해체/시운전 | H22: =IF(F22=0,G22,G22*F22) -> 0
B23: 공사 관련 자재 | H23: =IF(F23=0,G23,G23*F23) -> 0
H24: =IF(F24=0,G24,G24*F24) -> 0
H25: =IF(F25=0,G25,G25*F25) -> 0
C26: 기타자재 | H26: =IF(F26=0,G26,G26*F26) -> 0
H27: =SUM(H22:H26) -> 0
B28: 구매품 | C28: 저상리프트 | E28: 식 | F28: 2 | G28: 7000000 | H28: =IF(F28=0,G28,G28*F28) -> 14000000
B29: (유공압품외) | H29: =IF(F29=0,G29,G29*F29) -> 0
H30: =IF(F30=0,G30,G30*F30) -> 0
H31: =IF(F31=0,G31,G31*F31) -> 0
H32: =IF(F32=0,G32,G32*F32) -> 0
H33: =IF(F33=0,G33,G33*F33) -> 0
H34: =IF(F34=0,G34,G34*F34) -> 0
H35: =IF(F35=0,G35,G35*F35) -> 0
H36: =IF(F36=0,G36,G36*F36) -> 0
H37: =IF(F37=0,G37,G37*F37) -> 0
H38: =IF(F38=0,G38,G38*F38) -> 0
H39: =IF(F39=0,G39,G39*F39) -> 0
H40: =IF(F40=0,G40,G40*F40) -> 0
H41: =IF(F41=0,G41,G41*F41) -> 0
... H43: =IF(F43=0,G43,G43*F43) -> 0
H44: =SUM(H28:H43) -> 14000000
B45: 외주제작품 | H45: =IF(F45=0,G45,G45*F45) -> 0
...

Sheet #80
B1: □ 단위공사명(전기제외): | C1: 드레그토크 측정기 | I1: (첨부)
A2: 구분 | C2: 품 명 | D2: 규격 | E2: 단위 | F2: 수량 | G2: 단가(원) | H2: 금액(원) | I2: 原MAKER
A3: 자 재 비 | B3: 철자재 | C3: ■FRAME류 | D3: 제관,가공 | E3: 식 | F3: 1 | G3: 1500000 | H3: =F3*G3 -> 1500000
C4: ■BASE 류 | D4: 가공 | E4: 식 | F4: 1 | G4: 1000000 | H4: =F4*G4 -> 1000000
C5: ■각종 COVER류 | E5: 식 | F5: 1 | G5: 500000 | H5: =F5*G5 -> 500000
C6: ■OP BOX | E6: 식 | F6: 0 | G6: 600000 | H6: =F6*G6 -> 0
C7: ■일반 부품류 | D7: 판금품,가공품 | E7: 식 | F7: 40 | G7: 70000 | H7: =F7*G7 -> 2800000
C8: ■정도 부품류 | D8: 가공품 | E8: 식 | F8: 10 | G8: 150000 | H8: =F8*G8 -> 1500000
C9: ■치구류 | D9: 가공품 | E9: 식 | F9: 5 | G9: 200000 | H9: =F9*G9 -> 1000000
H10: =IF(F10=0,G10,G10*F10) -> 0
H11: =IF(F11=0,G11,G11*F11) -> 0
H12: =IF(F12=0,G12,G12*F12) -> 0
H13: =IF(F13=0,G13,G13*F13) -> 0
H14: =IF(F14=0,G14,G14*F14) -> 0
H15: =IF(F15=0,G15,G15*F15) -> 0
H16: =IF(F16=0,G16,G16*F16) -> 0
H17: =IF(F17=0,G17,G17*F17) -> 0
H18: =IF(F18=0,G18,G18*F18) -> 0
H19: =IF(F19=0,G19,G19*F19) -> 0
H20: =IF(F20=0,G20,G20*F20) -> 0
H21: =IF(F21=0,G21,G21*F21) -> 0
H22: =IF(F22=0,G22,G22*F22) -> 0
C23: 기타자재 | E23: 식 | F23: 1 | G23: 300000 | H23: =IF(F23=0,G23,G23*F23) -> 300000
H24: =SUM(H3:H23) -> 8600000
B25: 설치/해체/시운전 | H25: =IF(F25=0,G25,G25*F25) -> 0
B26: 공사 관련 자재 | H26: =IF(F26=0,G26,G26*F26) -> 0
H27: =IF(F27=0,G27,G27*F27) -> 0
H28: =IF(F28=0,G28,G28*F28) -> 0
C29: 기타자재 | H29: =IF(F29=0,G29,G29*F29) -> 0
H30: =SUM(H25:H29) -> 0
B31: 구매품 | C31: ■상하 1축 | H31: =IF(F31=0,G31,G31*F31) -> 0
B32: (유공압품외) | C32: #상하실린더 | E32: 식 | F32: 1 | G32: 300000 | H32: =IF(F32=0,G32,G32*F32) -> 300000
C33: #LM GUIDE | E33: 식 | F33: 1 | G33: 500000 | H33: =IF(F33=0,G33,G33*F33) -> 500000
C34: #센스류 | E34: 식 | F34: 1 | G34: 300000 | H34: =IF(F34=0,G34,G34*F34) -> 300000
C35: #기타(케이블베어등) | E35: 식 | F35: 1 | G35: 500000 | H35: =IF(F35=0,G35,G35*F35) -> 500000
H36: =IF(F36=0,G36,G36*F36) -> 0
C37: ■측정부 | H37: =IF(F37=0,G37,G37*F37) -> 0
C38: #인덕션모타 | E38: 식 | F38: 1 | G38: 600000 | H38: =IF(F38=0,G38,G38*F38) -> 600000
C39: #베어링류 | E39: 식 | F39: 1 | G39: 400000 | H39: =IF(F39=0,G39,G39*F39) -> 400000
C40: #센스류 | E40: 식 | F40: 1 | G40: 200000 | H40: =IF(F40=0,G40,G40*F40) -> 200000
...

Sheet #90
B1: □ 단위공사명(전기제외): | C1: RG3공유 리툴링 | I1: (첨부)
A2: 구분 | C2: 품 명 | D2: 규격 | E2: 단위 | F2: 수량 | G2: 단가(원) | H2: 금액(원) | I2: 原MAKER
A3: 자 재 비 | B3: 철자재 | C3: ■정도 부품류 | D3: 가공품(PALLETS) | E3: 식 | F3: 1 | G3: 150000 | H3: =IF(F3=0,G3,G3*F3) -> 150000
C4: HOLDER | D4: 수정->신규 | E4: EA | F4: 20 | G4: 100000 | H4: =IF(F4=0,G4,G4*F4) -> 2000000
C5: EV용 장착 지그 | D5: 신규 | E5: EA | F5: 20 | G5: 100000 | H5: =IF(F5=0,G5,G5*F5) -> 2000000
C6: RG3 장착 지그 | D6: 신규 | E6: EA | F6: 20 | G6: 100000 | H6: =IF(F6=0,G6,G6*F6) -> 2000000
C7: RG3 세레이션 지그 | D7: 신규 | E7: EA | F7: 20 | G7: 60000 | H7: =IF(F7=0,G7,G7*F7) -> 1200000
H8: =IF(F8=0,G8,G8*F8) -> 0
H9: =IF(F9=0,G9,G9*F9) -> 0
H10: =IF(F10=0,G10,G10*F10) -> 0
H11: =IF(F11=0,G11,G11*F11) -> 0
H12: =IF(F12=0,G12,G12*F12) -> 0
H13: =IF(F13=0,G13,G13*F13) -> 0
H14: =IF(F14=0,G14,G14*F14) -> 0
H15: =IF(F15=0,G15,G15*F15) -> 0
H16: =IF(F16=0,G16,G16*F16) -> 0
H17: =IF(F17=0,G17,G17*F17) -> 0
H18: =IF(F18=0,G18,G18*F18) -> 0
H19: =IF(F19=0,G19,G19*F19) -> 0
... H22: =IF(F22=0,G22,G22*F22) -> 0
C23: 기타자재 | E23: 식 | F23: 1 | G23: 200000 | H23: =IF(F23=0,G23,G23*F23) -> 200000
H24: =SUM(H3:H23) -> 7550000
B25: 설치/해체/시운전 | H25: =IF(F25=0,G25,G25*F25) -> 0
B26: 공사 관련 자재 | H26: =IF(F26=0,G26,G26*F26) -> 0
H27: =IF(F27=0,G27,G27*F27) -> 0
H28: =IF(F28=0,G28,G28*F28) -> 0
C29: 기타자재 | H29: =IF(F29=0,G29,G29*F29) -> 0
H30: =SUM(H25:H29) -> 0
B31: 구매품 | C31: 인덱스부란저 | E31: EA | F31: 20 | G31: 18000 | H31: =IF(F31=0,G31,G31*F31) -> 360000
B32: (유공압품외) | H32: =IF(F32=0,G32,G32*F32) -> 0
H33: =IF(F33=0,G33,G33*F33) -> 0
H34: =IF(F34=0,G34,G34*F34) -> 0
H35: =IF(F35=0,G35,G35*F35) -> 0
H36: =IF(F36=0,G36,G36*F36) -> 0
H37: =IF(F37=0,G37,G37*F37) -> 0
H38: =IF(F38=0,G38,G38*F38) -> 0
H39: =IF(F39=0,G39,G39*F39) -> 0
H40: =IF(F40=0,G40,G40*F40) -> 0
H41: =IF(F41=0,G41,G41*F41) -> 0
H42: =IF(F42=0,G42,G42*F42) -> 0
...

Sheet #100
B1: □ 단위공사명(전기제외): | C1: 스토퍼링 P/FROOF | I1: (첨부)
A2: 구분 | C2: 품 명 | D2: 규격 | E2: 단위 | F2: 수량 | G2: 단가(원) | H2: 금액(원) | I2: 原MAKER
A3: 자 재 비 | B3: 철자재 | C3: ■비젼시스템 | E3: 식 | F3: 2 | G3: 2000000 | H3: 4000000
C4: ■좌우1축 | E4: 식 | F4: 2 | G4: 1000000 | H4: 2000000
H5: =IF(F5=0,G5,G5*F5) -> 0
H6: =IF(F6=0,G6,G6*F6) -> 0
H7: =IF(F7=0,G7,G7*F7) -> 0
H8: =IF(F8=0,G8,G8*F8) -> 0
H9: =IF(F9=0,G9,G9*F9) -> 0
H10: =IF(F10=0,G10,G10*F10) -> 0
H11: =IF(F11=0,G11,G11*F11) -> 0
H12: =IF(F12=0,G12,G12*F12) -> 0
H13: =IF(F13=0,G13,G13*F13) -> 0
H14: =IF(F14=0,G14,G14*F14) -> 0
H15: =IF(F15=0,G15,G15*F15) -> 0
H16: =IF(F16=0,G16,G16*F16) -> 0
... H22: =IF(F22=0,G22,G22*F22) -> 0
C23: 기타 | E23: 식 | F23: 1 | G23: 200000 | H23: =IF(F23=0,G23,G23*F23) -> 200000
H24: =SUM(H3:H23) -> 6200000
B25: 설치/해체/시운전 | H25: =IF(F25=0,G25,G25*F25) -> 0
B26: 공사 관련 자재 | H26: =IF(F26=0,G26,G26*F26) -> 0
H27: =IF(F27=0,G27,G27*F27) -> 0
H28: =IF(F28=0,G28,G28*F28) -> 0
C29: 기타자재 | H29: =IF(F29=0,G29,G29*F29) -> 0
H30: =SUM(H25:H29) -> 0
B31: 구매품 | C31: ■비젼시스템 | D31: 1600 X 1400 컬러 | E31: 식 | F31: 2 | G31: 20000000 | H31: 40000000
B32: (유공압품외) | C32: ■좌우1축 | D32: 실린더 | E32: 식 | F32: 2 | G32: 1000000 | H32: 2000000
C33: ■PROXIMITY SENSOR | E33: EA | F33: 4 | G33: 40000 | H33: 160000
H34: =IF(F34=0,G34,G34*F34) -> 0
H35: =IF(F35=0,G35,G35*F35) -> 0
H36: =IF(F36=0,G36,G36*F36) -> 0
H37: =IF(F37=0,G37,G37*F37) -> 0
H38: =IF(F38=0,G38,G38*F38) -> 0
H39: =IF(F39=0,G39,G39*F39) -> 0
H40: =IF(F40=0,G40,G40*F40) -> 0
H41: =IF(F41=0,G41,G41*F41) -> 0
H42: =IF(F42=0,G42,G42*F42) -> 0
H43: =IF(F43=0,G43,G43*F43) -> 0
H44: =IF(F44=0,G44,G44*F44) -> 0
H45: =IF(F45=0,G45,G45*F45) -> 0
...

Sheet 첨부(견적조건차이내역)
A1: ※ 현대/기아차의 요구사양과 업체견적사양이 다른경우만 작성
D2: (첨부)
A3: 현대/기아차 요구사양대비 견적조건 상이내역
A5: 항 목 | B5: 현대/기아차 요구사양 | C5: 업체 견적기준 사양 | D5: 비 고

Sheet Sheet1
