Workbook

Sheet 갑지
B1: (현대/기아차 설비협력업체 견적통일양식)
B2: 見 積 書
B4: 현대 위아 貴下 | G4: ㈜지이엠
B5: 견적일자 | D5: 44056 | G5: 대표 : 송 칠 영 (인)
B6: 견적번호 | D6: GD1_200813-001 | G6: 주소 : 경남 창원시 성산구
B7: 납기 | C7: 입하 | G7: 성산패총로24번길 1
C8: 최종검수 | G8: 전화: 055-282-9488
B9: 견적유효기간 | D9: 견적일로부터30일 | G9: Fax: 055-282-9484 / 9490
B10: 인도장소 | D10: 현대위아 공장 | G10: 견적담당: | H10: 정대헌부장
B11: 지불조건 | D11: 현대위아 기준 | G11: 연 락 처 : | H11: 010-3452-0737
B13: 견적금액: 一金오억오천만원整(\550,000,000 )
B15: 번호 | C15: 상세품목내역 | E15: 견적금액 (천원) | I15: 비 고
E16: 기계부분 | F16: 전기부문 | G16: 관리/이윤 (안전관리비포함) | H16: 합 계
B17: 1 | C17: =IF('단위공사별(집계)'!N7>0,'단위공사별(집계)'!B7,"") -> 볼조립 | E17: =IF('단위공사별(집계)'!N7>1,('단위공사별(집계)'!D7+'단위공사별(집계)'!E7+'단위공사별(집계)'!F7+'단위공사별(집계)'!G7+'단위공사별(집계)'!H7+'단위공사별(집계)'!I7)/1000," ") -> 37274.303 | F17: =IF('단위공사별(집계)'!N7>0,'단위공사별(집계)'!K17/1000,"") -> 131250 | G17: =IF('단위공사별(집계)'!N7>0,('단위공사별(집계)'!L7+'단위공사별(집계)'!M7)/1000,"") -> 204.68217 | H17: =IF('단위공사별(집계)'!N7>0,'단위공사별(집계)'!N7/1000,"") -> 49199.987
B18: 2 | C18: =IF('단위공사별(집계)'!N8>0,'단위공사별(집계)'!B8,"") -> 절각 토크측정 | E18: =IF('단위공사별(집계)'!N8>1,('단위공사별(집계)'!D8+'단위공사별(집계)'!E8+'단위공사별(집계)'!F8+'단위공사별(집계)'!G8+'단위공사별(집계)'!H8+'단위공사별(집계)'!I8)/1000," ") -> 52821.551 | G18: =IF('단위공사별(집계)'!N8>0,('단위공사별(집계)'!L8+'단위공사별(집계)'!M8)/1000,"") -> 290.05586 | H18: =IF('단위공사별(집계)'!N8>0,'단위공사별(집계)'!N8/1000,"") -> 69721.482
B19: 3 | C19: =IF('단위공사별(집계)'!N9>0,'단위공사별(집계)'!B9,"") -> 스파이더 비젼 | E19: =IF('단위공사별(집계)'!N9>1,('단위공사별(집계)'!D9+'단위공사별(집계)'!E9+'단위공사별(집계)'!F9+'단위공사별(집계)'!G9+'단위공사별(집계)'!H9+'단위공사별(집계)'!I9)/1000," ") -> 53874.073 | G19: =IF('단위공사별(집계)'!N9>0,('단위공사별(집계)'!L9+'단위공사별(집계)'!M9)/1000,"") -> 295.83551 | H19: =IF('단위공사별(집계)'!N9>0,'단위공사별(집계)'!N9/1000,"") -> 71110.751
B20: 4 | C20: =IF('단위공사별(집계)'!N10>0,'단위공사별(집계)'!B10,"") -> TJ PUMPING | E20: =IF('단위공사별(집계)'!N10>1,('단위공사별(집계)'!D10+'단위공사별(집계)'!E10+'단위공사별(집계)'!F10+'단위공사별(집계)'!G10+'단위공사별(집계)'!H10+'단위공사별(집계)'!I10)/1000," ") -> 34449.535 | G20: =IF('단위공사별(집계)'!N10>0,('단위공사별(집계)'!L10+'단위공사별(집계)'!M10)/1000,"") -> 189.17069 | H20: =IF('단위공사별(집계)'!N10>0,'단위공사별(집계)'!N10/1000,"") -> 45471.452
B21: 5 | C21: =IF('단위공사별(집계)'!N11>0,'단위공사별(집계)'!B11,"") -> MAIN PALLETS | E21: =IF('단위공사별(집계)'!N11>1,('단위공사별(집계)'!D11+'단위공사별(집계)'!E11+'단위공사별(집계)'!F11+'단위공사별(집계)'!G11+'단위공사별(집계)'!H11+'단위공사별(집계)'!I11)/1000," ") -> 21301.034 | G21: =IF('단위공사별(집계)'!N11>0,('단위공사별(집계)'!L11+'단위공사별(집계)'!M11)/1000,"") -> 116.96911 | H21: =IF('단위공사별(집계)'!N11>0,'단위공사별(집계)'!N11/1000,"") -> 28116.168
B22: 6 | C22: =IF('단위공사별(집계)'!N12>0,'단위공사별(집계)'!B12,"") -> 그리스 펌프 | E22: =IF('단위공사별(집계)'!N12>1,('단위공사별(집계)'!D12+'단위공사별(집계)'!E12+'단위공사별(집계)'!F12+'단위공사별(집계)'!G12+'단위공사별(집계)'!H12+'단위공사별(집계)'!I12)/1000," ") -> 52826.563 | G22: =IF('단위공사별(집계)'!N12>0,('단위공사별(집계)'!L12+'단위공사별(집계)'!M12)/1000,"") -> 290.08338 | H22: =IF('단위공사별(집계)'!N12>0,'단위공사별(집계)'!N12/1000,"") -> 69728.097
B23: 7 | C23: =IF('단위공사별(집계)'!N13>0,'단위공사별(집계)'!B13,"") -> 장비 리툴링 | E23: =IF('단위공사별(집계)'!N13>1,('단위공사별(집계)'!D13+'단위공사별(집계)'!E13+'단위공사별(집계)'!F13+'단위공사별(집계)'!G13+'단위공사별(집계)'!H13+'단위공사별(집계)'!I13)/1000," ") -> 164844.94 | G23: =IF('단위공사별(집계)'!N13>0,('단위공사별(집계)'!L13+'단위공사별(집계)'!M13)/1000,"") -> 905.20327 | H23: =IF('단위공사별(집계)'!N13>0,'단위공사별(집계)'!N13/1000,"") -> 217586.06
B24: 8 | C24: =IF('단위공사별(집계)'!N14>0,'단위공사별(집계)'!B14,"") | E24: =IF('단위공사별(집계)'!N14>1,('단위공사별(집계)'!D14+'단위공사별(집계)'!E14+'단위공사별(집계)'!F14+'단위공사별(집계)'!G14+'단위공사별(집계)'!H14+'단위공사별(집계)'!I14)/1000," ") | G24: =IF('단위공사별(집계)'!N14>0,('단위공사별(집계)'!L14+'단위공사별(집계)'!M14)/1000,"") | H24: =IF('단위공사별(집계)'!N14>0,'단위공사별(집계)'!N14/1000,"")
B25: 9 | C25: =IF('단위공사별(집계)'!N15>0,'단위공사별(집계)'!B15,"") | E25: =IF('단위공사별(집계)'!N15>1,('단위공사별(집계)'!D15+'단위공사별(집계)'!E15+'단위공사별(집계)'!F15+'단위공사별(집계)'!G15+'단위공사별(집계)'!H15+'단위공사별(집계)'!I15)/1000," ") | G25: =IF('단위공사별(집계)'!N15>0,('단위공사별(집계)'!L15+'단위공사별(집계)'!M15)/1000,"") | H25: =IF('단위공사별(집계)'!N15>0,'단위공사별(집계)'!N15/1000,"")
B26: 10 | C26: =IF('단위공사별(집계)'!N16>0,'단위공사별(집계)'!B16,"") | E26: =IF('단위공사별(집계)'!N16>1,('단위공사별(집계)'!D16+'단위공사별(집계)'!E16+'단위공사별(집계)'!F16+'단위공사별(집계)'!G16+'단위공사별(집계)'!H16+'단위공사별(집계)'!I16)/1000," ") | G26: =IF('단위공사별(집계)'!N16>0,('단위공사별(집계)'!L16+'단위공사별(집계)'!M16)/1000,"") | H26: =IF('단위공사별(집계)'!N16>0,'단위공사별(집계)'!N16/1000,"")
B27: 견적 합계 | E27: =SUM(E17:E26) -> 417392 | F27: =SUM(F17:F23) -> 131250 | G27: =SUM(G17:G26) -> 2292 | H27: =ROUNDDOWN(SUM(H17:H26),-3) -> 550000
F29: 공개입찰가 (견적時 공란) | H29: 550000
B31: 특기사항 | C31: 1. VAT 제외 | F31: 외주계획 업체명 (자작時 공란)
C32: 2. 기본 유틸리티공사 제외 | F32: 설계외주
C33: ='원가항목별(집계)'!I39 -> 2292000 | F33: 제작외주
F34: 전기외주
F35: 설치외주

Sheet 원가항목별(집계)
C2: A. 원가항목별 견적가 종합(상세견적 첨부)
B4: □ 현대/기아 요구사양과 견적조건 일치여부 CHECK: 1.일치함 2.일부상이(상이내역 첨부참조)
B6: 순번 | C6: 원가구분 | F6: 단위 | G6: 수량 | H6: 단가 | I6: 금 액(원) | J6: 비 고
B7: 1 | C7: 기계 부문 | D7: 자재비 | E7: 철자재(SS.SUS등) | F7: kg | G7: ='#10'!F37+'#20'!F30+'#30'!F30+'#40'!F31+'#50'!F30+'#60'!F30+'#70'!F32+'#80'!F30+'#90'!F30+'#100'!F30 -> 0 | I7: ='#10'!H31+'#20'!H24+'#30'!H24+'#40'!H25+'#50'!H24+'#60'!H24+'#70'!H26+'#80'!H24+'#90'!H24+'#100'!H24 -> 98940000 | J7: 加工必要資材
E8: 일반구매품 | F8: 식 | G8: 1 | I8: ='#10'!H55+'#20'!H47+'#30'!H47+'#40'!H50+'#50'!H48+'#60'!H47+'#70'!H59+'#80'!H47+'#90'!H47+'#100'!H47 -> 185502000 | J8: 加工不要資材
E9: 외주제작품 | F9: 식 | G9: 1 | I9: ='#10'!H63+'#20'!H55+'#30'!H55+'#40'!H58+'#50'!H56+'#60'!H55+'#70'!H67+'#80'!H55+'#90'!H55+'#100'!H55 -> 0 | J9: 旣加工SUB資材
E10: 설치/해체 공사 자재 | F10: 식 | G10: 1 | I10: ='#10'!H37+'#20'!H30+'#30'!H30+'#40'!H31+'#50'!H30+'#60'!H30+'#70'!H32+'#80'!H30+'#90'!H30+'#100'!H30 -> 0 | J10: 시운전 자재 포함
E11: 소계 | I11: =SUM(I7:I10) -> 284442000
D12: 노무비 | E12: 기존설비 철거 | F12: M/D | G12: ='#10'!F65+'#20'!F57+'#30'!F57+'#40'!F60+'#50'!F58+'#60'!F57+'#70'!F69+'#80'!F57+'#90'!F57+'#100'!F57 -> 0 | H12: =IF('#10'!G65>0,'#10'!G65,"") -> 300000 | I12: ='#10'!H65+'#20'!H57+'#30'!H57+'#40'!H60+'#50'!H58+'#60'!H57+'#70'!H69+'#80'!H57+'#90'!H57+'#100'!H57 -> 0 | J12: 개조공사時
E13: 설계 | F13: M/D | G13: ='#10'!F66+'#20'!F58+'#30'!F58+'#40'!F61+'#50'!F59+'#60'!F58+'#70'!F70+'#80'!F58+'#90'!F58+'#100'!F58 -> 145 | H13: =IF('#10'!G66>0,'#10'!G66,"") -> 300000 | I13: ='#10'!H66+'#20'!H58+'#30'!H58+'#40'!H61+'#50'!H59+'#60'!H58+'#70'!H70+'#80'!H58+'#90'!H58+'#100'!H58 -> 43500000
E14: 제작(제관,가공) | F14: M/D | G14: ='#10'!F67+'#20'!F59+'#30'!F59+'#40'!F62+'#50'!F60+'#60'!F59+'#70'!F71+'#80'!F59+'#90'!F59+'#100'!F59 -> 53 | H14: =IF('#10'!G67>0,'#10'!G67,"") -> 250000 | I14: ='#10'!H67+'#20'!H59+'#30'!H59+'#40'!H62+'#50'!H60+'#60'!H59+'#70'!H71+'#80'!H59+'#90'!H59+'#100'!H59 -> 13250000
E15: 조립 | F15: M/D | G15: ='#10'!F68+'#20'!F60+'#30'!F60+'#40'!F63+'#50'!F61+'#60'!F60+'#70'!F72+'#80'!F60+'#90'!F60+'#100'!F60 -> 123 | H15: =IF('#10'!G68>0,'#10'!G68,"") -> 250000 | I15: ='#10'!H68+'#20'!H60+'#30'!H60+'#40'!H63+'#50'!H61+'#60'!H60+'#70'!H72+'#80'!H60+'#90'!H60+'#100'!H60 -> 30750000 | J15: 정도검사포함
E16: 설치 | F16: M/D | G16: ='#10'!F69+'#20'!F61+'#30'!F61+'#40'!F64+'#50'!F62+'#60'!F61+'#70'!F73+'#80'!F61+'#90'!F61+'#100'!F61 -> 65 | H16: =IF('#10'!G69>0,'#10'!G69,"") -> 300000 | I16: ='#10'!H69+'#20'!H61+'#30'!H61+'#40'!H64+'#50'!H62+'#60'!H61+'#70'!H73+'#80'!H61+'#90'!H61+'#100'!H61 -> 19500000
E17: 시운전 | F17: M/D | G17: ='#10'!F70+'#20'!F62+'#30'!F62+'#40'!F65+'#50'!F63+'#60'!F62+'#70'!F74+'#80'!F62+'#90'!F62+'#100'!F62 -> 51 | H17: =IF('#10'!G70>0,'#10'!G70,"") -> 300000 | I17: ='#10'!H70+'#20'!H62+'#30'!H62+'#40'!H65+'#50'!H63+'#60'!H62+'#70'!H74+'#80'!H62+'#90'!H62+'#100'!H62 -> 15300000
E18: 양산대응 | F18: M/D | G18: ='#10'!F71+'#20'!F63+'#30'!F63+'#40'!F66+'#50'!F64+'#60'!F63+'#70'!F75+'#80'!F63+'#90'!F63+'#100'!F63 -> 18 | H18: =IF('#10'!G71>0,'#10'!G71,"") -> 300000 | I18: ='#10'!H71+'#20'!H63+'#30'!H63+'#40'!H66+'#50'!H64+'#60'!H63+'#70'!H75+'#80'!H63+'#90'!H63+'#100'!H63 -> 5400000
E19: 도장 | F19: M/D | G19: ='#10'!F72+'#20'!F64+'#30'!F64+'#40'!F67+'#50'!F65+'#60'!F64+'#70'!F76+'#80'!F64+'#90'!F64+'#100'!F64 -> 17 | H19: =IF('#10'!G72>0,'#10'!G72,"") -> 250000 | I19: ='#10'!H72+'#20'!H64+'#30'!H64+'#40'!H67+'#50'!H65+'#60'!H64+'#70'!H76+'#80'!H64+'#90'!H64+'#100'!H64 -> 4250000
E20: 소계 | I20: =SUM(I12:I19) -> 131950000
D21: 일반관리 및 이윤 | I21: ='#10'!H75+'#10'!H76+'#20'!H67+'#20'!H68+'#30'!H67+'#30'!H68+'#40'!H70+'#40'!H71+'#50'!H68+'#50'!H69+'#60'!H67+'#60'!H68+'#70'!H79+'#70'!H80+'#80'!H67+'#80'!H68+'#90'!H67+'#90'!H68+'#100'!H67+'#100'!H68 -> 0
E22: 기계 소계 | I22: =I20+I11+I21 -> 416392000
B23: 2 | C23: 전기 부문 | D23: 자재비 | E23: 기계/전기자재 | F23: 식 | G23: 1 | I23: =전기!H49-I24 -> 54000000
E24: 설치/해체 공사 자재 | F24: 식 | G24: 1 | I24: =전기!H16 -> 0 | J24: 시운전 자재 포함
D25: 노무비 | E25: 철거(개조시) | F25: M/D | G25: =전기!F50 -> 0 | H25: =IF(전기!G50>0,전기!G50,"") -> 300000 | I25: =전기!H50 -> 0
E26: 설계,프로그램 | F26: M/D | G26: =전기!F51 -> 60 | H26: =IF(전기!G51>0,전기!G51,"") -> 300000 | I26: =전기!H51 -> 18000000
E27: 제작 | F27: M/D | G27: =전기!F52 -> 15 | H27: =IF(전기!G52>0,전기!G52,"") -> 250000 | I27: =전기!H52 -> 3750000
E28: 조립 | F28: M/D | G28: =전기!F53 -> 90 | H28: =IF(전기!G53>0,전기!G53,"") -> 250000 | I28: =전기!H53 -> 22500000
E29: 설치 | F29: M/D | G29: =전기!F54 -> 30 | H29: =IF(전기!G54>0,전기!G54,"") -> 300000 | I29: =전기!H54 -> 9000000
E30: 시운전 | F30: M/D | G30: =전기!F55 -> 60 | H30: =IF(전기!G55>0,전기!G55,"") -> 300000 | I30: =전기!H55 -> 18000000
E31: 양산대응 | F31: M/D | G31: =전기!F56 -> 20 | H31: =IF(전기!G56>0,전기!G56,"") -> 300000 | I31: =전기!H56 -> 6000000
E32: 소계 | I32: =SUM(I25:I31) -> 77250000
D33: 일반관리 및 이윤 | I33: =전기!H59+전기!H60 -> 0
E34: 전기 소계 | I34: =I32+I23+I33+I24 -> 131250000
B35: 3 | C35: 자재비 합계 | I35: =I23+I11+I24 -> 338442000
C36: 노무비 합계 | I36: =I32+I20 -> 209200000
C37: 중간 합계 | I37: =I36+I35 -> 547642000
B38: 4 | C38: 포장,운송 및 중장비 사용료 | I38: 1000000
B39: 5 | C39: 표준안전관리비 | F39: 설치/철거/수리금액 기준 | I39: =CEILING(MIN(I47:I48),1000) -> 2292000 | J39: =I30+I29+I25+I24+I17+I16+I12+I10 -> 61800000
B40: 6 | C40: 일반관리비 | I40: =전기!H59+'#10'!H75+'#20'!H67+'#30'!H67+'#40'!H70+'#50'!H68+'#60'!H67+'#70'!H79+'#80'!H67+'#90'!H67+'#100'!H67 -> 0
B41: 7 | C41: 이 윤 | I41: =전기!H60+'#10'!H76+'#20'!H68+'#30'!H68+'#40'!H71+'#50'!H69+'#60'!H68+'#70'!H80+'#80'!H68+'#90'!H68+'#100'!H68 -> 0
C42: 합 계 | F42: 3~7항 합계 | I42: =I22+I34+I38+I39 -> 550934000
B43: 주1. 표준안전관리비:(설치/철거/시운전 공사 관련 금액)의 ⓐ2.66%,ⓑ1.95%+기초액,ⓒ2.02%(50억 이상일경우)
...

Sheet 단위공사별(집계)
A2: B. 단위장비별 견적가 종합(상세견적 첨부)
N3: 단위:원
I5: 포장/운송 | L5: 표준안전 | M5: 일반관리비
A6: 순번 | B6: 단위장비명 | C6: 수량 | D6: 자재비 | E6: 철거 | F6: 제작 | G6: 설치/시운전 | H6: 양산대응 | I6: 중장비사용 | J6: 기계소계 | K6: 전기소계 | L6: 관리비 | M6: 이윤 | N6: 합 계 | O6: 비 고
A7: =IF(B7>0,1,"") -> 1 | B7: ='#10'!C$1 -> 볼조립 | C7: 1식 | D7: ='#10'!H64 -> 17985000 | E7: ='#10'!H65 -> 0 | F7: ='#10'!H66+'#10'!H67+'#10'!H68+'#10'!H72 -> 13500000 | G7: ='#10'!H69+'#10'!H70 -> 5100000 | H7: ='#10'!H71 -> 600000 | I7: =IF($B7>0,'원가항목별(집계)'!I$38*$P7/$P$17,0) -> 89302.868 | J7: =SUM(D7:I7) -> 37274303 | K7: =IF(B7>0,'원가항목별(집계)'!I$34*P7/P$17,0) -> 11721001 | L7: =IF($B7>0,'원가항목별(집계)'!I$39*$P7/$P$17,0) -> 204682.17 | M7: ='#10'!H75+'#10'!H76 -> 0 | N7: =SUM(J7:M7) -> 49199987 | P7: =D7+E7+F7+G7+H7+M7 -> 37185000
A8: =IF(B8>0,A7+1,"") -> 2 | B8: ='#20'!C$1 -> 절각 토크측정 | C8: 1식 | D8: ='#20'!H56 -> 30745000 | E8: ='#20'!H57 -> 0 | F8: ='#20'!H58+'#20'!H59+'#20'!H60+'#20'!H64 -> 16250000 | G8: ='#20'!H61+'#20'!H62 -> 5100000 | H8: ='#20'!H63 -> 600000 | I8: =IF($B8>0,'원가항목별(집계)'!I$38*$P8/$P$17,0) -> 126551.42 | J8: =SUM(D8:I8) -> 52821551 | K8: =IF(B8>0,'원가항목별(집계)'!I$34*P8/P$17,0) -> 16609874 | L8: =IF($B8>0,'원가항목별(집계)'!I$39*$P8/$P$17,0) -> 290055.86 | M8: ='#20'!H67+'#20'!H68 -> 0 | N8: =SUM(J8:M8) -> 69721482 | P8: =D8+E8+F8+G8+H8+M8 -> 52695000
A9: =IF(B9>0,A8+1,"") -> 3 | B9: ='#30'!C$1 -> 스파이더 비젼 | C9: 1식 | D9: ='#30'!H56 -> 34545000 | E9: ='#30'!H57 -> 0 | F9: ='#30'!H58+'#30'!H59+'#30'!H60+'#30'!H64 -> 13500000 | G9: ='#30'!H61+'#30'!H62 -> 5100000 | H9: ='#30'!H63 -> 600000 | I9: =IF($B9>0,'원가항목별(집계)'!I$38*$P9/$P$17,0) -> 129073.08 | J9: =SUM(D9:I9) -> 53874073 | K9: =IF(B9>0,'원가항목별(집계)'!I$34*P9/P$17,0) -> 16940842 | L9: =IF($B9>0,'원가항목별(집계)'!I$39*$P9/$P$17,0) -> 295835.51 | M9: ='#30'!H67+'#30'!H68 -> 0 | N9: =SUM(J9:M9) -> 71110751 | P9: =D9+E9+F9+G9+H9+M9 -> 53745000
A10: =IF(B10>0,A9+1,"") -> 4 | B10: ='#40'!C$1 -> TJ PUMPING | C10: 1식 | D10: ='#40'!H59 -> 21867000 | E10: ='#40'!H60 -> 0 | F10: ='#40'!H61+'#40'!H62+'#40'!H63+'#40'!H67 -> 9500000 | G10: ='#40'!H64+'#40'!H65 -> 2400000 | H10: ='#40'!H66 -> 600000 | I10: =IF($B10>0,'원가항목별(집계)'!I$38*$P10/$P$17,0) -> 82535.207 | J10: =SUM(D10:I10) -> 34449535 | K10: =IF(B10>0,'원가항목별(집계)'!I$34*P10/P$17,0) -> 10832746 | L10: =IF($B10>0,'원가항목별(집계)'!I$39*$P10/$P$17,0) -> 189170.69 | M10: ='#40'!H70+'#40'!H71 -> 0 | N10: =SUM(J10:M10) -> 45471452 | P10: =D10+E10+F10+G10+H10+M10 -> 34367000
A11: =IF(B11>0,A10+1,"") -> 5 | B11: ='#50'!C$1 -> MAIN PALLETS | C11: 1식 | D11: ='#50'!H57 -> 19000000 | E11: ='#50'!H58 -> 0 | F11: ='#50'!H59+'#50'!H60+'#50'!H61+'#50'!H65 -> 1050000 | G11: ='#50'!H62+'#50'!H63 -> 1200000 | H11: ='#50'!H64 -> 0 | I11: =IF($B11>0,'원가항목별(집계)'!I$38*$P11/$P$17,0) -> 51033.641 | J11: =SUM(D11:I11) -> 21301034 | K11: =IF(B11>0,'원가항목별(집계)'!I$34*P11/P$17,0) -> 6698165.4 | L11: =IF($B11>0,'원가항목별(집계)'!I$39*$P11/$P$17,0) -> 116969.11 | M11: ='#50'!H68+'#50'!H69 -> 0 | N11: =SUM(J11:M11) -> 28116168 | P11: =D11+E11+F11+G11+H11+M11 -> 21250000
A12: =IF(B12>0,A11+1,"") -> 6 | B12: ='#60'!C$1 -> 그리스 펌프 | C12: 1식 | D12: ='#60'!H56 -> 50000000 | E12: ='#60'!H57 -> 0 | F12: ='#60'!H58+'#60'!H59+'#60'!H60+'#60'!H64 -> 0 | G12: ='#60'!H61+'#60'!H62 -> 2700000 | H12: ='#60'!H63 -> 0 | I12: =IF($B12>0,'원가항목별(집계)'!I$38*$P12/$P$17,0) -> 126563.43 | J12: =SUM(D12:I12) -> 52826563 | K12: =IF(B12>0,'원가항목별(집계)'!I$34*P12/P$17,0) -> 16611450 | L12: =IF($B12>0,'원가항목별(집계)'!I$39*$P12/$P$17,0) -> 290083.38 | M12: ='#60'!H67+'#60'!H68 -> 0 | N12: =SUM(J12:M12) -> 69728097 | P12: =D12+E12+F12+G12+H12+M12 -> 52700000
A13: =IF(B13>0,A12+1,"") -> 7 | B13: ='#70'!C$1 -> 장비 리툴링 | C13: 1식 | D13: ='#70'!H68 -> 110300000 | E13: ='#70'!H69 -> 0 | F13: ='#70'!H70+'#70'!H71+'#70'!H72+'#70'!H76 -> 37950000 | G13: ='#70'!H73+'#70'!H74 -> 13200000 | H13: ='#70'!H75 -> 3000000 | I13: =IF($B13>0,'원가항목별(집계)'!I$38*$P13/$P$17,0) -> 394940.34 | J13: =SUM(D13:I13) -> 1.6484494e+08 | K13: =IF(B13>0,'원가항목별(집계)'!I$34*P13/P$17,0) -> 51835920 | L13: =IF($B13>0,'원가항목별(집계)'!I$39*$P13/$P$17,0) -> 905203.27 | M13: ='#70'!H79+'#70'!H80 -> 0 | N13: =SUM(J13:M13) -> 2.1758606e+08 | P13: =D13+E13+F13+G13+H13+M13 -> 164450000
A14: =IF(B14>0,A13+1,"") | B14: ='#80'!C$1 -> 0 | C14: 1식 | D14: ='#80'!H56 -> 0 | E14: ='#80'!H57 -> 0 | F14: ='#80'!H58+'#80'!H59+'#80'!H60+'#80'!H64 -> 0 | G14: ='#80'!H61+'#80'!H62 -> 0 | H14: ='#80'!H63 -> 0 | I14: =IF($B14>0,'원가항목별(집계)'!I$38*$P14/$P$17,0) -> 0 | J14: =SUM(D14:I14) -> 0 | K14: =IF(B14>0,'원가항목별(집계)'!I$34*P14/P$17,0) -> 0 | L14: =IF($B14>0,'원가항목별(집계)'!I$39*$P14/$P$17,0) -> 0 | M14: ='#80'!H67+'#80'!H68 -> 0 | N14: =SUM(J14:M14) -> 0 | P14: =D14+E14+F14+G14+H14+M14 -> 0
A15: =IF(B15>0,A14+1,"") | B15: ='#90'!C$1 -> 0 | C15: 1식 | D15: ='#90'!H56 -> 0 | E15: ='#90'!H57 -> 0 | F15: ='#90'!H58+'#90'!H59+'#90'!H60+'#90'!H64 -> 0 | G15: ='#90'!H61+'#90'!H62 -> 0 | H15: ='#90'!H63 -> 0 | I15: =IF($B15>0,'원가항목별(집계)'!I$38*$P15/$P$17,0) -> 0 | J15: =SUM(D15:I15) -> 0 | K15: =IF(B15>0,'원가항목별(집계)'!I$34*P15/P$17,0) -> 0 | L15: =IF($B15>0,'원가항목별(집계)'!I$39*$P15/$P$17,0) -> 0 | M15: ='#90'!H67+'#90'!H68 -> 0 | N15: =SUM(J15:M15) -> 0 | P15: =D15+E15+F15+G15+H15+M15 -> 0
A16: =IF(B16>0,A15+1,"") | B16: ='#100'!C$1 -> 0 | C16: 1식 | D16: ='#100'!H56 -> 0 | E16: ='#100'!H57 -> 0 | F16: ='#100'!H58+'#100'!H59+'#100'!H60+'#100'!H64 -> 0 | G16: ='#100'!H61+'#100'!H62 -> 0 | H16: ='#100'!H63 -> 0 | I16: =IF($B16>0,'원가항목별(집계)'!I$38*$P16/$P$17,0) -> 0 | J16: =SUM(D16:I16) -> 0 | K16: =IF(B16>0,'원가항목별(집계)'!I$34*P16/P$17,0) -> 0 | L16: =IF($B16>0,'원가항목별(집계)'!I$39*$P16/$P$17,0) -> 0 | M16: ='#100'!H67+'#100'!H68 -> 0 | N16: =SUM(J16:M16) -> 0 | P16: =D16+E16+F16+G16+H16+M16 -> 0
A17: 합 계 | D17: =SUM(D7:D16) -> 284442000 | E17: =SUM(E7:E16) -> 0 | F17: =SUM(F7:F16) -> 91750000 | G17: =SUM(G7:G16) -> 34800000 | H17: =SUM(H7:H16) -> 5400000 | I17: =SUM(I7:I16) -> 1000000 | J17: =SUM(D17:I17) -> 417392000 | K17: =SUM(K7:K16) -> 131250000 | L17: =SUM(L7:L16) -> 2292000 | M17: =SUM(M7:M16) -> 0 | N17: =SUM(N7:N16) -> 550934000 | P17: =SUM(P7:P16) -> 416392000
D18: =IF(D17=0,"",D17/$N17) -> 0.51629052 | E18: =IF(E17=0,"",E17/$N17) | F18: =IF(F17=0,"",F17/$N17) -> 0.16653537 | G18: =IF(G17=0,"",G17/$N17) -> 0.063165461 | H18: =IF(H17=0,"",H17/$N17) -> 0.009801537 | I18: =IF(I17=0,"",I17/$N17) -> 0.0018150994 | J18: =IF(J17=0,"",J17/$N17) -> 0.75760799 | K18: =IF(K17=0,"",K17/$N17) -> 0.2382318 | ... N18: =IF(N17=0,"",N17/$N17) -> 1
A19: 주) 전기비용은 턴키장비의 공통비용으로서 총 전기비용을 단위장비별 기계금액의 비율에 따라 배분함
N20: =IF('원가항목별(집계)'!I42='단위공사별(집계)'!N17,"","DATA오류입니다!")

Sheet 전기
B1: □ 전기부문: | C1: 전기부문(공통) | I1: (첨부)
A2: 구분 | C2: 품 명 | D2: 규격 | E2: 단위 | F2: 수량 | G2: 단가(원) | H2: 금액(원) | I2: 原MAKER
A3: 자 재 비 | B3: 철자재 | C3: MAIN OP PANEL | E3: 식 | F3: 1 | G3: 200000 | H3: =IF(F3=0,G3,G3*F3) -> 200000
C4: RT BOX | E4: 식 | F4: 4 | G4: 150000 | H4: =IF(F4=0,G4,G4*F4) -> 600000
C5: S/W BOX | E5: 식 | F5: 1 | G5: 200000 | H5: =IF(F5=0,G5,G5*F5) -> 200000
C6: 단자대 BOX(주물 BOX) | E6: 식 | F6: 1 | G6: 1000000 | H6: =IF(F6=0,G6,G6*F6) -> 1000000
H7: =IF(F7=0,G7,G7*F7) -> 0
H8: =IF(F8=0,G8,G8*F8) -> 0
H9: =SUM(H3:H8) -> 2000000
B10: 설치/해체/ | H10: =IF(F10=0,G10,G10*F10) -> 0
B11: 시운전 공사 | H11: =IF(F11=0,G11,G11*F11) -> 0
B12: 자재 | H12: =IF(F12=0,G12,G12*F12) -> 0
H13: =IF(F13=0,G13,G13*F13) -> 0
H14: =IF(F14=0,G14,G14*F14) -> 0
H15: =IF(F15=0,G15,G15*F15) -> 0
H16: =SUM(H10:H15) -> 0
B17: 전기자재 | C17: TOUCH SCREEN외 | E17: 식 | F17: 1 | G17: 30000000 | H17: =IF(F17=0,G17,G17*F17) -> 30000000
H18: =IF(F18=0,G18,G18*F18) -> 0
H19: =IF(F19=0,G19,G19*F19) -> 0
H20: =IF(F20=0,G20,G20*F20) -> 0
H21: =IF(F21=0,G21,G21*F21) -> 0
H22: =IF(F22=0,G22,G22*F22) -> 0
H23: =IF(F23=0,G23,G23*F23) -> 0
H24: =IF(F24=0,G24,G24*F24) -> 0
H25: =IF(F25=0,G25,G25*F25) -> 0
H26: =IF(F26=0,G26,G26*F26) -> 0
H27: =IF(F27=0,G27,G27*F27) -> 0
H28: =IF(F28=0,G28,G28*F28) -> 0
H29: =IF(F29=0,G29,G29*F29) -> 0
... H42: =IF(F42=0,G42,G42*F42) -> 0
C43: PC프로그램 개발 | E43: 식 | F43: 1 | G43: 20000000 | H43: =IF(F43=0,G43,G43*F43) -> 20000000
H44: =IF(F44=0,G44,G44*F44) -> 0
H45: =IF(F45=0,G45,G45*F45) -> 0
H46: =IF(F46=0,G46,G46*F46) -> 0
C47: 기타 잡자재 | E47: 식 | F47: 1 | G47: 2000000 | H47: =IF(F47=0,G47,G47*F47) -> 2000000
H48: =SUM(H17:H47) -> 52000000
B49: 자재비 소계 | H49: =SUM(H48,H9,H16) -> 54000000
A50: 노 무 비 | B50: 기존설비 철거 | E50: M/D | F50: 0 | G50: 300000 | H50: =F50*G50 -> 0
B51: 전기 설계/프로그램 | E51: M/D | F51: 60 | G51: 300000 | H51: =F51*G51 -> 18000000
B52: 전기 제작 | E52: M/D | F52: 15 | G52: 250000 | H52: =F52*G52 -> 3750000
...

Sheet #10
B1: □ 단위공사명(전기제외): | C1: 볼조립 | I1: (첨부)
A2: 구분 | C2: 품 명 | D2: 규격 | E2: 단위 | F2: 수량 | G2: 단가(원) | H2: 금액(원) | I2: 原MAKER
A3: 자 재 비 | B3: 철자재 | C3: ■BASE | D3: 제관,가공 | E3: 식 | F3: 1 | G3: 2000000 | H3: =IF(F3=0,G3,G3*F3) -> 2000000
C4: ■FRAME | D4: 제관,가공,카바 | E4: 식 | F4: 1 | G4: 1500000 | H4: =IF(F4=0,G4,G4*F4) -> 1500000
C5: ■상측 COVER | D5: 제관,가공 | E5: 식 | F5: 1 | G5: 1000000 | H5: =IF(F5=0,G5,G5*F5) -> 1000000
C6: ■OP POST | E6: 식 | F6: 1 | G6: 600000 | H6: =IF(F6=0,G6,G6*F6) -> 600000
C7: ■적재렉 | E7: 식 | F7: 1 | G7: 1040000 | H7: =IF(F7=0,G7,G7*F7) -> 1040000
C8: ■볼공급부 | E8: 식 | F8: 1 | G8: 2500000 | H8: =IF(F8=0,G8,G8*F8) -> 2500000
C9: ■이종체크 | E9: 식 | F9: 1 | G9: 2000000 | H9: =IF(F9=0,G9,G9*F9) -> 2000000
C10: ■치구보관함 | E10: 식 | F10: 1 | G10: 1000000 | H10: =IF(F10=0,G10,G10*F10) -> 1000000
H11: =IF(F11=0,G11,G11*F11) -> 0
H12: =IF(F12=0,G12,G12*F12) -> 0
H13: =IF(F13=0,G13,G13*F13) -> 0
H14: =IF(F14=0,G14,G14*F14) -> 0
H15: =IF(F15=0,G15,G15*F15) -> 0
H16: =IF(F16=0,G16,G16*F16) -> 0
H17: =IF(F17=0,G17,G17*F17) -> 0
H18: =IF(F18=0,G18,G18*F18) -> 0
H19: =IF(F19=0,G19,G19*F19) -> 0
H20: =IF(F20=0,G20,G20*F20) -> 0
H21: =IF(F21=0,G21,G21*F21) -> 0
H22: =IF(F22=0,G22,G22*F22) -> 0
... H29: =IF(F29=0,G29,G29*F29) -> 0
C30: 기타자재 | E30: 식 | F30: 0 | G30: 0 | H30: =IF(F30=0,G30,G30*F30) -> 0
H31: =SUM(H3:H30) -> 11640000
B32: 설치/해체/시운전 | H32: =IF(F32=0,G32,G32*F32) -> 0
B33: 공사 관련 자재 | H33: =IF(F33=0,G33,G33*F33) -> 0
H34: =IF(F34=0,G34,G34*F34) -> 0
H35: =IF(F35=0,G35,G35*F35) -> 0
H36: =IF(F36=0,G36,G36*F36) -> 0
H37: =SUM(H32:H36) -> 0
B38: 구매품 | C38: ■FRAME | E38: 식 | F38: 1 | G38: 100000 | H38: =IF(F38=0,G38,G38*F38) -> 100000
B39: (유공압품외) | C39: ■적재랙 | E39: 식 | F39: 1 | G39: 200000 | H39: =IF(F39=0,G39,G39*F39) -> 200000
C40: ■볼공급부 | E40: 식 | F40: 1 | G40: 1100000 | H40: =IF(F40=0,G40,G40*F40) -> 1100000
C41: ■이종체크 | E41: 식 | F41: 1 | G41: 2500000 | H41: =IF(F41=0,G41,G41*F41) -> 2500000
C42: ■치구보관함 | E42: 식 | F42: 1 | G42: 600000 | H42: =IF(F42=0,G42,G42*F42) -> 600000
H43: =IF(F43=0,G43,G43*F43) -> 0
H44: =IF(F44=0,G44,G44*F44) -> 0
C45: ■일반 자재류 | H45: =IF(F45=0,G45,G45*F45) -> 0
C46: F.R.L Unit | D46: AV4000 | E46: 식 | F46: 1 | G46: 350000 | H46: =IF(F46=0,G46,G46*F46) -> 350000
...

Sheet #20
B1: □ 단위공사명(전기제외): | C1: 절각 토크측정 | I1: (첨부)
A2: 구분 | C2: 품 명 | D2: 규격 | E2: 단위 | F2: 수량 | G2: 단가(원) | H2: 금액(원) | I2: 原MAKER
A3: 자 재 비 | B3: 철자재 | C3: ■BASE | D3: 제관,가공 | E3: 식 | F3: 1 | G3: 2000000 | H3: =IF(F3=0,G3,G3*F3) -> 2000000
C4: ■FRAME | D4: 제관,가공,카바 | E4: 식 | F4: 1 | G4: 1500000 | H4: =IF(F4=0,G4,G4*F4) -> 1500000
C5: ■상측 COVER | D5: 제관,가공 | E5: 식 | F5: 1 | G5: 1000000 | H5: =IF(F5=0,G5,G5*F5) -> 1000000
C6: ■측정부 | E6: 식 | F6: 1 | G6: 5000000 | H6: =IF(F6=0,G6,G6*F6) -> 5000000
C7: ■소재 클램프부 | E7: 식 | F7: 1 | G7: 800000 | H7: =IF(F7=0,G7,G7*F7) -> 800000
C8: ■상하 이송부 | E8: 식 | F8: 1 | G8: 3000000 | H8: =IF(F8=0,G8,G8*F8) -> 3000000
H9: =IF(F9=0,G9,G9*F9) -> 0
H10: =IF(F10=0,G10,G10*F10) -> 0
H11: =IF(F11=0,G11,G11*F11) -> 0
H12: =IF(F12=0,G12,G12*F12) -> 0
H13: =IF(F13=0,G13,G13*F13) -> 0
H14: =IF(F14=0,G14,G14*F14) -> 0
H15: =IF(F15=0,G15,G15*F15) -> 0
H16: =IF(F16=0,G16,G16*F16) -> 0
H17: =IF(F17=0,G17,G17*F17) -> 0
H18: =IF(F18=0,G18,G18*F18) -> 0
H19: =IF(F19=0,G19,G19*F19) -> 0
H20: =IF(F20=0,G20,G20*F20) -> 0
... H22: =IF(F22=0,G22,G22*F22) -> 0
C23: 기타자재 | E23: 식 | F23: 1 | G23: 0 | H23: =IF(F23=0,G23,G23*F23) -> 0
H24: =SUM(H3:H23) -> 13300000
B25: 설치/해체/시운전 | H25: =IF(F25=0,G25,G25*F25) -> 0
B26: 공사 관련 자재 | H26: =IF(F26=0,G26,G26*F26) -> 0
H27: =IF(F27=0,G27,G27*F27) -> 0
H28: =IF(F28=0,G28,G28*F28) -> 0
H29: =IF(F29=0,G29,G29*F29) -> 0
H30: =SUM(H25:H29) -> 0
B31: 구매품 | C31: ■FRAME | E31: 식 | F31: 1 | G31: 100000 | H31: =IF(F31=0,G31,G31*F31) -> 100000
B32: (유공압품외) | C32: ■측정부 | E32: 식 | F32: 1 | G32: 9000000 | H32: =IF(F32=0,G32,G32*F32) -> 9000000
C33: ■소재 클램프부 | E33: 식 | F33: 1 | G33: 2500000 | H33: =IF(F33=0,G33,G33*F33) -> 2500000
C34: ■상하 이송부 | E34: 식 | F34: 1 | G34: 4000000 | H34: =IF(F34=0,G34,G34*F34) -> 4000000
H35: =IF(F35=0,G35,G35*F35) -> 0
H36: =IF(F36=0,G36,G36*F36) -> 0
C37: ■일반 자재류 | H37: =IF(F37=0,G37,G37*F37) -> 0
C38: F.R.L Unit | D38: AV4000 | E38: 식 | F38: 1 | G38: 350000 | H38: =IF(F38=0,G38,G38*F38) -> 350000
C39: SOL V/V | D39: VQC4201 | E39: 식 | F39: 5 | G39: 75000 | H39: =IF(F39=0,G39,G39*F39) -> 375000
C40: Manifold | D40: VV5QC41 | E40: 식 | F40: 1 | G40: 850000 | H40: =IF(F40=0,G40,G40*F40) -> 850000
C41: Speed Con | E41: 식 | F41: 10 | G41: 7000 | H41: =IF(F41=0,G41,G41*F41) -> 70000
...

Sheet #30
B1: □ 단위공사명(전기제외): | C1: 스파이더 비젼 | I1: (첨부)
A2: 구분 | C2: 품 명 | D2: 규격 | E2: 단위 | F2: 수량 | G2: 단가(원) | H2: 금액(원) | I2: 原MAKER
A3: 자 재 비 | B3: 철자재 | C3: ■BASE | D3: 제관,가공 | E3: 식 | F3: 0 | G3: 2000000 | H3: =F3*G3 -> 0
C4: ■FRAME | D4: 제관,가공,카바 | E4: 식 | F4: 0 | G4: 2500000 | H4: =F4*G4 -> 0
C5: ■상측 COVER | D5: 제관,가공 | E5: 식 | F5: 0 | G5: 1500000 | H5: =F5*G5 -> 0
C6: ■OP POST | E6: 식 | F6: 0 | G6: 600000 | H6: =F6*G6 -> 0
C7: ■비젼부 | E7: 식 | F7: 1 | G7: 2500000 | H7: =F7*G7 -> 2500000
C8: ■상하 이송부 | E8: 식 | F8: 1 | G8: 3000000 | H8: =F8*G8 -> 3000000
C9: ■리프트 | E9: 식 | F9: 1 | G9: 1300000 | H9: =F9*G9 -> 1300000
H10: =IF(F10=0,G10,G10*F10) -> 0
H11: =IF(F11=0,G11,G11*F11) -> 0
H12: =IF(F12=0,G12,G12*F12) -> 0
H13: =IF(F13=0,G13,G13*F13) -> 0
H14: =IF(F14=0,G14,G14*F14) -> 0
H15: =IF(F15=0,G15,G15*F15) -> 0
H16: =IF(F16=0,G16,G16*F16) -> 0
H17: =IF(F17=0,G17,G17*F17) -> 0
H18: =IF(F18=0,G18,G18*F18) -> 0
H19: =IF(F19=0,G19,G19*F19) -> 0
H20: =IF(F20=0,G20,G20*F20) -> 0
H21: =IF(F21=0,G21,G21*F21) -> 0
H22: =IF(F22=0,G22,G22*F22) -> 0
C23: 기타자재 | E23: 식 | F23: 1 | G23: 0 | H23: =IF(F23=0,G23,G23*F23) -> 0
H24: =SUM(H3:H23) -> 6800000
B25: 설치/해체/시운전 | H25: =IF(F25=0,G25,G25*F25) -> 0
B26: 공사 관련 자재 | H26: =IF(F26=0,G26,G26*F26) -> 0
H27: =IF(F27=0,G27,G27*F27) -> 0
H28: =IF(F28=0,G28,G28*F28) -> 0
H29: =IF(F29=0,G29,G29*F29) -> 0
H30: =SUM(H25:H29) -> 0
B31: 구매품 | C31: ■비젼부 | E31: 식 | F31: 1 | G31: 20000000 | H31: =IF(F31=0,G31,G31*F31) -> 20000000
B32: (유공압품외) | C32: ■상하 이송부 | E32: 식 | F32: 1 | G32: 3800000 | H32: =IF(F32=0,G32,G32*F32) -> 3800000
C33: ■리프트 | E33: 식 | F33: 1 | G33: 600000 | H33: =IF(F33=0,G33,G33*F33) -> 600000
C34: ■RFID | E34: 식 | F34: 1 | G34: 1500000 | H34: =IF(F34=0,G34,G34*F34) -> 1500000
H35: =IF(F35=0,G35,G35*F35) -> 0
H36: =IF(F36=0,G36,G36*F36) -> 0
C37: ■일반 자재류 | H37: =IF(F37=0,G37,G37*F37) -> 0
C38: F.R.L Unit | D38: AV4000 | E38: 식 | F38: 1 | G38: 350000 | H38: =IF(F38=0,G38,G38*F38) -> 350000
C39: SOL V/V | D39: VQC4201 | E39: 식 | F39: 5 | G39: 75000 | H39: =IF(F39=0,G39,G39*F39) -> 375000
C40: Manifold | D40: VV5QC41 | E40: 식 | F40: 1 | G40: 850000 | H40: =IF(F40=0,G40,G40*F40) -> 850000
...

Sheet #40
B1: □ 단위공사명(전기제외): | C1: TJ PUMPING | I1: (첨부)
A2: 구분 | C2: 품 명 | D2: 규격 | E2: 단위 | F2: 수량 | G2: 단가(원) | H2: 금액(원) | I2: 原MAKER
A3: 자 재 비 | B3: 철자재 | C3: ■BASE | D3: 제관,가공 | E3: 식 | F3: 0 | G3: 2000000 | H3: =F3*G3 -> 0
C4: ■FRAME | D4: 제관,가공,카바 | E4: 식 | F4: 0 | G4: 2500000 | H4: =F4*G4 -> 0
C5: ■상측 COVER | D5: 제관,가공 | E5: 식 | F5: 0 | G5: 1500000 | H5: =F5*G5 -> 0
C6: ■OP POST | E6: 식 | F6: 0 | G6: 600000 | H6: =F6*G6 -> 0
C7: ■펌핑부 | E7: 식 | F7: 1 | G7: 2500000 | H7: =F7*G7 -> 2500000
C8: ■소재클램프부 | E8: 식 | F8: 1 | G8: 1500000 | H8: =F8*G8 -> 1500000
C9: ■상하 이송부 | E9: 식 | F9: 1 | G9: 3000000 | H9: =F9*G9 -> 3000000
C10: ■리프트 | E10: 식 | F10: 1 | G10: 1300000 | H10: =F10*G10 -> 1300000
H11: =IF(F11=0,G11,G11*F11) -> 0
H12: =IF(F12=0,G12,G12*F12) -> 0
H13: =IF(F13=0,G13,G13*F13) -> 0
H14: =IF(F14=0,G14,G14*F14) -> 0
H15: =IF(F15=0,G15,G15*F15) -> 0
H16: =IF(F16=0,G16,G16*F16) -> 0
H17: =IF(F17=0,G17,G17*F17) -> 0
H18: =IF(F18=0,G18,G18*F18) -> 0
H19: =IF(F19=0,G19,G19*F19) -> 0
H20: =IF(F20=0,G20,G20*F20) -> 0
H21: =IF(F21=0,G21,G21*F21) -> 0
H22: =IF(F22=0,G22,G22*F22) -> 0
H23: =IF(F23=0,G23,G23*F23) -> 0
C24: 기타자재 | E24: 식 | F24: 1 | G24: 0 | H24: =IF(F24=0,G24,G24*F24) -> 0
H25: =SUM(H3:H24) -> 8300000
B26: 설치/해체/시운전 | H26: =IF(F26=0,G26,G26*F26) -> 0
B27: 공사 관련 자재 | H27: =IF(F27=0,G27,G27*F27) -> 0
H28: =IF(F28=0,G28,G28*F28) -> 0
H29: =IF(F29=0,G29,G29*F29) -> 0
C30: 기타자재 | H30: =IF(F30=0,G30,G30*F30) -> 0
H31: =SUM(H26:H30) -> 0
B32: 구매품 | C32: ■펌핑부 | E32: 식 | F32: 1 | G32: 3000000 | H32: =IF(F32=0,G32,G32*F32) -> 3000000
B33: (유공압품외) | C33: ■소재클램프부 | E33: 식 | F33: 1 | G33: 3000000 | H33: =IF(F33=0,G33,G33*F33) -> 3000000
C34: ■상하 이송부 | E34: 식 | F34: 1 | G34: 3800000 | H34: =IF(F34=0,G34,G34*F34) -> 3800000
C35: ■리프트 | E35: 식 | F35: 1 | G35: 600000 | H35: =IF(F35=0,G35,G35*F35) -> 600000
C36: ■RFID | E36: 식 | F36: 1 | G36: 1500000 | H36: =IF(F36=0,G36,G36*F36) -> 1500000
H37: =IF(F37=0,G37,G37*F37) -> 0
H38: =IF(F38=0,G38,G38*F38) -> 0
C39: ■일반 자재류 | H39: =IF(F39=0,G39,G39*F39) -> 0
C40: F.R.L Unit | D40: AV4000 | E40: 식 | F40: 1 | G40: 350000 | H40: =IF(F40=0,G40,G40*F40) -> 350000
...

Sheet #50
B1: □ 단위공사명(전기제외): | C1: MAIN PALLETS | I1: (첨부)
A2: 구분 | C2: 품 명 | D2: 규격 | E2: 단위 | F2: 수량 | G2: 단가(원) | H2: 금액(원) | I2: 原MAKER
A3: 자 재 비 | B3: 철자재 | C3: ■PALLET | E3: 식 | F3: 5 | G3: 3000000 | H3: =F3*G3 -> 15000000
H4: 0
H5: 0
H6: 0
H7: 0
H8: 0
H9: 0
H10: =IF(F10=0,G10,G10*F10) -> 0
H11: =IF(F11=0,G11,G11*F11) -> 0
H12: =IF(F12=0,G12,G12*F12) -> 0
H13: =IF(F13=0,G13,G13*F13) -> 0
H14: =IF(F14=0,G14,G14*F14) -> 0
H15: =IF(F15=0,G15,G15*F15) -> 0
H16: =IF(F16=0,G16,G16*F16) -> 0
H17: =IF(F17=0,G17,G17*F17) -> 0
H18: =IF(F18=0,G18,G18*F18) -> 0
H19: =IF(F19=0,G19,G19*F19) -> 0
H20: =IF(F20=0,G20,G20*F20) -> 0
H21: =IF(F21=0,G21,G21*F21) -> 0
H22: =IF(F22=0,G22,G22*F22) -> 0
C23: 기타자재 | E23: 식 | H23: =IF(F23=0,G23,G23*F23) -> 0
H24: =SUM(H3:H23) -> 15000000
B25: 설치/해체/시운전 | H25: =IF(F25=0,G25,G25*F25) -> 0
B26: 공사 관련 자재 | H26: =IF(F26=0,G26,G26*F26) -> 0
H27: =IF(F27=0,G27,G27*F27) -> 0
H28: =IF(F28=0,G28,G28*F28) -> 0
C29: 기타자재 | H29: =IF(F29=0,G29,G29*F29) -> 0
H30: =SUM(H25:H29) -> 0
B31: 구매품 | C31: 그리퍼 | E31: 식 | F31: 5 | G31: 800000 | H31: =F31*G31 -> 4000000
B32: (유공압품외) | H32: 0
H33: 0
H34: 0
H35: 0
H36: 0
H37: 0
H38: 0
H39: 0
H40: 0
...

Sheet #60
B1: □ 단위공사명(전기제외): | C1: 그리스 펌프 | I1: (첨부)
A2: 구분 | C2: 품 명 | D2: 규격 | E2: 단위 | F2: 수량 | G2: 단가(원) | H2: 금액(원) | I2: 原MAKER
A3: 자 재 비 | B3: 철자재 | H3: =IF(F3=0,G3,G3*F3) -> 0
H4: =IF(F4=0,G4,G4*F4) -> 0
H5: =IF(F5=0,G5,G5*F5) -> 0
H6: =IF(F6=0,G6,G6*F6) -> 0
H7: =IF(F7=0,G7,G7*F7) -> 0
H8: =IF(F8=0,G8,G8*F8) -> 0
H9: =IF(F9=0,G9,G9*F9) -> 0
H10: =IF(F10=0,G10,G10*F10) -> 0
H11: =IF(F11=0,G11,G11*F11) -> 0
H12: =IF(F12=0,G12,G12*F12) -> 0
H13: =IF(F13=0,G13,G13*F13) -> 0
H14: =IF(F14=0,G14,G14*F14) -> 0
H15: =IF(F15=0,G15,G15*F15) -> 0
... H22: =IF(F22=0,G22,G22*F22) -> 0
C23: 기타자재 | H23: =IF(F23=0,G23,G23*F23) -> 0
H24: =SUM(H3:H23) -> 0
B25: 설치/해체/시운전 | H25: =IF(F25=0,G25,G25*F25) -> 0
B26: 공사 관련 자재 | H26: =IF(F26=0,G26,G26*F26) -> 0
H27: =IF(F27=0,G27,G27*F27) -> 0
H28: =IF(F28=0,G28,G28*F28) -> 0
C29: 기타자재 | H29: =IF(F29=0,G29,G29*F29) -> 0
H30: =SUM(H25:H29) -> 0
B31: 구매품 | C31: RBA GREASE 정량시스템 | E31: 식 | F31: 1 | G31: 25000000 | H31: =IF(F31=0,G31,G31*F31) -> 25000000
B32: (유공압품외) | C32: CW13 GREASE 정량시스템 | E32: 식 | F32: 1 | G32: 25000000 | H32: =IF(F32=0,G32,G32*F32) -> 25000000
H33: =IF(F33=0,G33,G33*F33) -> 0
H34: =IF(F34=0,G34,G34*F34) -> 0
H35: =IF(F35=0,G35,G35*F35) -> 0
H36: =IF(F36=0,G36,G36*F36) -> 0
H37: =IF(F37=0,G37,G37*F37) -> 0
H38: =IF(F38=0,G38,G38*F38) -> 0
H39: =IF(F39=0,G39,G39*F39) -> 0
H40: =IF(F40=0,G40,G40*F40) -> 0
H41: =IF(F41=0,G41,G41*F41) -> 0
H42: =IF(F42=0,G42,G42*F42) -> 0
H43: =IF(F43=0,G43,G43*F43) -> 0
H44: =IF(F44=0,G44,G44*F44) -> 0
H45: =IF(F45=0,G45,G45*F45) -> 0
C46: 기타자재 | E46: 식 | H46: =IF(F46=0,G46,G46*F46) -> 0
...

Sheet #70
B1: □ 단위공사명(전기제외): | C1: 장비 리툴링 | I1: (첨부)
A2: 구분 | C2: 품 명 | D2: 규격 | E2: 단위 | F2: 수량 | G2: 단가(원) | H2: 금액(원) | I2: 原MAKER
A3: 자 재 비 | B3: 철자재 | C3: ■O/B SUB PALLETS | E3: 식 | F3: 66 | G3: 200000 | H3: =IF(F3=0,G3,G3*F3) -> 13200000
C4: ■HCG 클립 조립 | E4: 식 | F4: 1 | G4: 2000000 | H4: =IF(F4=0,G4,G4*F4) -> 2000000
C5: ■O/R 선별기 | E5: 식 | F5: 1 | G5: 600000 | H5: =IF(F5=0,G5,G5*F5) -> 600000
C6: ■I/B SUB PALLETS | E6: 식 | F6: 25 | G6: 300000 | H6: =IF(F6=0,G6,G6*F6) -> 7500000
C7: ■BOOT SUB조립장치 | E7: 식 | F7: 1 | G7: 2000000 | H7: =IF(F7=0,G7,G7*F7) -> 2000000
C8: ■샤프트압입,R/RING | E8: 식 | F8: 1 | G8: 1500000 | H8: =IF(F8=0,G8,G8*F8) -> 1500000
C9: ■O/B런아웃 측정장치 개조 | E9: 식
C10: 측정부 가변 대응 | E10: 식 | F10: 1 | G10: 2000000 | H10: =IF(F10=0,G10,G10*F10) -> 2000000
C11: ■O/B SUB그리스 주입 개조 | H11: =IF(F11=0,G11,G11*F11) -> 0
C12: 기타가공물 | E12: 식 | F12: 1 | G12: 200000 | H12: =IF(F12=0,G12,G12*F12) -> 200000
C13: ■I/B SUB 그리스 주입 개조 | H13: =IF(F13=0,G13,G13*F13) -> 0
C14: 기타가공물 | E14: 식 | F14: 1 | G14: 200000 | H14: =IF(F14=0,G14,G14*F14) -> 200000
C15: ■BOOT SUB 조립장치 개조 | H15: =IF(F15=0,G15,G15*F15) -> 0
C16: 밴드체결 | E16: 식 | F16: 1 | G16: 1200000 | H16: =IF(F16=0,G16,G16*F16) -> 1200000
C17: ■샤프트압입,R/RING 개조 | H17: =IF(F17=0,G17,G17*F17) -> 0
C18: 샤프트압입지그 | E18: 식 | F18: 1 | G18: 500000 | H18: =IF(F18=0,G18,G18*F18) -> 500000
C19: R/RING조립 및공급 | E19: 식 | F19: 1 | G19: 2500000 | H19: =IF(F19=0,G19,G19*F19) -> 2500000
C20: ■하우징조립/밴드체결 개조 | H20: =IF(F20=0,G20,G20*F20) -> 0
C21: 밴드체결 | E21: 식 | F21: 1 | G21: 1000000 | H21: =IF(F21=0,G21,G21*F21) -> 1000000
C22: ■완성배출개조 | E22: 식 | H22: =IF(F22=0,G22,G22*F22) -> 0
C23: 대차 가변대응 | E23: 식 | F23: 1 | G23: 9000000 | H23: =IF(F23=0,G23,G23*F23) -> 9000000
E24: 식 | H24: =IF(F24=0,G24,G24*F24) -> 0
C25: 기타자재 | E25: 식 | F25: 1 | G25: 500000 | H25: =IF(F25=0,G25,G25*F25) -> 500000
H26: =SUM(H3:H25) -> 43900000
B27: 설치/해체/시운전 | H27: =IF(F27=0,G27,G27*F27) -> 0
B28: 공사 관련 자재 | H28: =IF(F28=0,G28,G28*F28) -> 0
H29: =IF(F29=0,G29,G29*F29) -> 0
H30: =IF(F30=0,G30,G30*F30) -> 0
C31: 기타자재 | H31: =IF(F31=0,G31,G31*F31) -> 0
H32: =SUM(H27:H31) -> 0
B33: 구매품 | C33: ■O/B런아웃 측정장치 개조 | E33: 식 | H33: =IF(F33=0,G33,G33*F33) -> 0
B34: (유공압품외) | C34: 측정부 가변 대응 | E34: 식 | F34: 1 | G34: 2000000 | H34: =IF(F34=0,G34,G34*F34) -> 2000000
C35: ■O/B SUB그리스 주입 개조 | E35: 식 | H35: =IF(F35=0,G35,G35*F35) -> 0
C36: 잡자재 | E36: 식 | F36: 1 | G36: 500000 | H36: =IF(F36=0,G36,G36*F36) -> 500000
C37: ■I/B SUB 그리스 주입 개조 | E37: 식 | H37: =IF(F37=0,G37,G37*F37) -> 0
C38: 잡자재 | E38: 식 | F38: 1 | G38: 500000 | H38: =IF(F38=0,G38,G38*F38) -> 500000
C39: ■BOOT SUB 조립장치 개조 | H39: =IF(F39=0,G39,G39*F39) -> 0
C40: 오이티커핀서 | D40: HO 7000EL | E40: 식 | F40: 1 | G40: 4800000 | H40: =IF(F40=0,G40,G40*F40) -> 4800000
...

Sheet #80
B1: □ 단위공사명(전기제외): | I1: (첨부)
A2: 구분 | C2: 품 명 | D2: 규격 | E2: 단위 | F2: 수량 | G2: 단가(원) | H2: 금액(원) | I2: 原MAKER
A3: 자 재 비 | B3: 철자재 | H3: =IF(F3=0,G3,G3*F3) -> 0
H4: =IF(F4=0,G4,G4*F4) -> 0
H5: =IF(F5=0,G5,G5*F5) -> 0
H6: =IF(F6=0,G6,G6*F6) -> 0
H7: =IF(F7=0,G7,G7*F7) -> 0
H8: =IF(F8=0,G8,G8*F8) -> 0
H9: =IF(F9=0,G9,G9*F9) -> 0
H10: =IF(F10=0,G10,G10*F10) -> 0
H11: =IF(F11=0,G11,G11*F11) -> 0
H12: =IF(F12=0,G12,G12*F12) -> 0
H13: =IF(F13=0,G13,G13*F13) -> 0
H14: =IF(F14=0,G14,G14*F14) -> 0
H15: =IF(F15=0,G15,G15*F15) -> 0
... H22: =IF(F22=0,G22,G22*F22) -> 0
C23: 기타자재 | H23: =IF(F23=0,G23,G23*F23) -> 0
H24: =SUM(H3:H23) -> 0
B25: 설치/해체/시운전 | H25: =IF(F25=0,G25,G25*F25) -> 0
B26: 공사 관련 자재 | H26: =IF(F26=0,G26,G26*F26) -> 0
H27: =IF(F27=0,G27,G27*F27) -> 0
H28: =IF(F28=0,G28,G28*F28) -> 0
C29: 기타자재 | H29: =IF(F29=0,G29,G29*F29) -> 0
H30: =SUM(H25:H29) -> 0
B31: 구매품 | H31: =IF(F31=0,G31,G31*F31) -> 0
B32: (유공압품외) | H32: =IF(F32=0,G32,G32*F32) -> 0
H33: =IF(F33=0,G33,G33*F33) -> 0
H34: =IF(F34=0,G34,G34*F34) -> 0
H35: =IF(F35=0,G35,G35*F35) -> 0
H36: =IF(F36=0,G36,G36*F36) -> 0
H37: =IF(F37=0,G37,G37*F37) -> 0
H38: =IF(F38=0,G38,G38*F38) -> 0
H39: =IF(F39=0,G39,G39*F39) -> 0
H40: =IF(F40=0,G40,G40*F40) -> 0
H41: =IF(F41=0,G41,G41*F41) -> 0
H42: =IF(F42=0,G42,G42*F42) -> 0
H43: =IF(F43=0,G43,G43*F43) -> 0
H44: =IF(F44=0,G44,G44*F44) -> 0
H45: =IF(F45=0,G45,G45*F45) -> 0
C46: 기타자재 | E46: 식 | H46: =IF(F46=0,G46,G46*F46) -> 0
...

Sheet #90
B1: □ 단위공사명(전기제외): | I1: (첨부)
A2: 구분 | C2: 품 명 | D2: 규격 | E2: 단위 | F2: 수량 | G2: 단가(원) | H2: 금액(원) | I2: 原MAKER
A3: 자 재 비 | B3: 철자재 | H3: =IF(F3=0,G3,G3*F3) -> 0
H4: =IF(F4=0,G4,G4*F4) -> 0
H5: =IF(F5=0,G5,G5*F5) -> 0
H6: =IF(F6=0,G6,G6*F6) -> 0
H7: =IF(F7=0,G7,G7*F7) -> 0
H8: =IF(F8=0,G8,G8*F8) -> 0
H9: =IF(F9=0,G9,G9*F9) -> 0
H10: =IF(F10=0,G10,G10*F10) -> 0
H11: =IF(F11=0,G11,G11*F11) -> 0
H12: =IF(F12=0,G12,G12*F12) -> 0
H13: =IF(F13=0,G13,G13*F13) -> 0
H14: =IF(F14=0,G14,G14*F14) -> 0
H15: =IF(F15=0,G15,G15*F15) -> 0
... H22: =IF(F22=0,G22,G22*F22) -> 0
C23: 기타자재 | H23: =IF(F23=0,G23,G23*F23) -> 0
H24: =SUM(H3:H23) -> 0
B25: 설치/해체/시운전 | H25: =IF(F25=0,G25,G25*F25) -> 0
B26: 공사 관련 자재 | H26: =IF(F26=0,G26,G26*F26) -> 0
H27: =IF(F27=0,G27,G27*F27) -> 0
H28: =IF(F28=0,G28,G28*F28) -> 0
C29: 기타자재 | H29: =IF(F29=0,G29,G29*F29) -> 0
H30: =SUM(H25:H29) -> 0
B31: 구매품 | H31: =IF(F31=0,G31,G31*F31) -> 0
B32: (유공압품외) | H32: =IF(F32=0,G32,G32*F32) -> 0
H33: =IF(F33=0,G33,G33*F33) -> 0
H34: =IF(F34=0,G34,G34*F34) -> 0
H35: =IF(F35=0,G35,G35*F35) -> 0
H36: =IF(F36=0,G36,G36*F36) -> 0
H37: =IF(F37=0,G37,G37*F37) -> 0
H38: =IF(F38=0,G38,G38*F38) -> 0
H39: =IF(F39=0,G39,G39*F39) -> 0
H40: =IF(F40=0,G40,G40*F40) -> 0
H41: =IF(F41=0,G41,G41*F41) -> 0
H42: =IF(F42=0,G42,G42*F42) -> 0
H43: =IF(F43=0,G43,G43*F43) -> 0
H44: =IF(F44=0,G44,G44*F44) -> 0
H45: =IF(F45=0,G45,G45*F45) -> 0
C46: 기타자재 | E46: 식 | H46: =IF(F46=0,G46,G46*F46) -> 0
...

Sheet #100
B1: □ 단위공사명(전기제외): | I1: (첨부)
A2: 구분 | C2: 품 명 | D2: 규격 | E2: 단위 | F2: 수량 | G2: 단가(원) | H2: 금액(원) | I2: 原MAKER
A3: 자 재 비 | B3: 철자재 | H3: =IF(F3=0,G3,G3*F3) -> 0
H4: =IF(F4=0,G4,G4*F4) -> 0
H5: =IF(F5=0,G5,G5*F5) -> 0
H6: =IF(F6=0,G6,G6*F6) -> 0
H7: =IF(F7=0,G7,G7*F7) -> 0
H8: =IF(F8=0,G8,G8*F8) -> 0
H9: =IF(F9=0,G9,G9*F9) -> 0
H10: =IF(F10=0,G10,G10*F10) -> 0
H11: =IF(F11=0,G11,G11*F11) -> 0
H12: =IF(F12=0,G12,G12*F12) -> 0
H13: =IF(F13=0,G13,G13*F13) -> 0
H14: =IF(F14=0,G14,G14*F14) -> 0
H15: =IF(F15=0,G15,G15*F15) -> 0
... H22: =IF(F22=0,G22,G22*F22) -> 0
C23: 기타자재 | H23: =IF(F23=0,G23,G23*F23) -> 0
H24: =SUM(H3:H23) -> 0
B25: 설치/해체/시운전 | H25: =IF(F25=0,G25,G25*F25) -> 0
B26: 공사 관련 자재 | H26: =IF(F26=0,G26,G26*F26) -> 0
H27: =IF(F27=0,G27,G27*F27) -> 0
H28: =IF(F28=0,G28,G28*F28) -> 0
C29: 기타자재 | H29: =IF(F29=0,G29,G29*F29) -> 0
H30: =SUM(H25:H29) -> 0
B31: 구매품 | H31: =IF(F31=0,G31,G31*F31) -> 0
B32: (유공압품외) | H32: =IF(F32=0,G32,G32*F32) -> 0
H33: =IF(F33=0,G33,G33*F33) -> 0
H34: =IF(F34=0,G34,G34*F34) -> 0
H35: =IF(F35=0,G35,G35*F35) -> 0
H36: =IF(F36=0,G36,G36*F36) -> 0
H37: =IF(F37=0,G37,G37*F37) -> 0
H38: =IF(F38=0,G38,G38*F38) -> 0
H39: =IF(F39=0,G39,G39*F39) -> 0
H40: =IF(F40=0,G40,G40*F40) -> 0
H41: =IF(F41=0,G41,G41*F41) -> 0
H42: =IF(F42=0,G42,G42*F42) -> 0
H43: =IF(F43=0,G43,G43*F43) -> 0
H44: =IF(F44=0,G44,G44*F44) -> 0
H45: =IF(F45=0,G45,G45*F45) -> 0
C46: 기타자재 | H46: =IF(F46=0,G46,G46*F46) -> 0
...

Sheet 첨부(견적조건차이내역)
A1: ※ 현대/기아차의 요구사양과 업체견적사양이 다른경우만 작성
D2: (첨부)
A3: 현대/기아차 요구사양대비 견적조건 상이내역
A5: 항 목 | B5: 현대/기아차 요구사양 | C5: 업체 견적기준 사양 | D5: 비 고
