Workbook

Sheet 갑지
B1: (현대/기아차 설비협력업체 견적통일양식)
B2: 見 積 書
B4: 현대 위아 貴下 | G4: ㈜디엠테크놀러지
B5: 견적일자 | D5: 46168 | G5: 대표 : 조 창 제
B6: 견적번호 | D6: DM260526-1 | G6: 주소 : 대구 달성군 구지면
B7: 납기 | C7: 입하 | D7: 2026 년 7월 15일 | G7: 국가산단대로 33길 245
C8: 최종검수 | D8: 2026 년 월 일 | G8: 전화: 053-716-1775
B9: 견적유효기간 | D9: 제출후 30 일 | G9: Fax: 053-710-9236
B10: 인도장소 | D10: 귀사 지정장소 | G10: 견적담당: 전 용 준 책임매니저
B11: 지불조건 | D11: 협의사항 | G11: 연 락 처 : 010-7588-1775
B13: 공 사 명 | D13: 창원2공장 승용액슬 기어가공라인 12만 증량 대응 자동화 신규&개조(선삭,연삭,자동창고) 件
B14: 견적금액 | D14: ="一金"&NUMBERSTRING(G14,1)&"원" -> 一金일십팔억오천오백이십만칠천팔백오십원 | G14: =H28*1000 -> 1855207850
B16: 번호 | C16: 상세품목내역 | E16: 견적금액 (천원) | I16: 비 고
E17: 기계부문 | F17: 전기부문 | G17: 관리/이윤 (안전관리비포함) | H17: 합 계
B18: 1 | C18: =단위장비1!C1 -> 선삭 신규 라인 IN ROBOT SYSTEM | E18: =IF('단위공사별(집계)'!N7>1,('단위공사별(집계)'!D7+'단위공사별(집계)'!E7+'단위공사별(집계)'!F7+'단위공사별(집계)'!G7+'단위공사별(집계)'!H7+'단위공사별(집계)'!I7)/1000," ") -> 101860 | F18: =IF('단위공사별(집계)'!N7>0,'단위공사별(집계)'!K17/1000,"") -> 348287.85 | G18: =IF('단위공사별(집계)'!N7>0,('단위공사별(집계)'!L7+'단위공사별(집계)'!M7)/1000,"") -> 16060.588 | H18: =IF('단위공사별(집계)'!N7>0,'단위공사별(집계)'!N7/1000,"") -> 145175.06
B19: 2 | C19: =단위장비2!C1 -> 선삭 신규 라인 2AXIS-I GANTRY SYSTEM | E19: =IF('단위공사별(집계)'!N8>1,('단위공사별(집계)'!D8+'단위공사별(집계)'!E8+'단위공사별(집계)'!F8+'단위공사별(집계)'!G8+'단위공사별(집계)'!H8+'단위공사별(집계)'!I8)/1000," ") -> 180690 | G19: =IF('단위공사별(집계)'!N8>0,('단위공사별(집계)'!L8+'단위공사별(집계)'!M8)/1000,"") -> 28489.963 | H19: =IF('단위공사별(집계)'!N8>0,'단위공사별(집계)'!N8/1000,"") -> 257526.82
B20: 3 | C20: =단위장비3!C1 -> 선삭 개조 라인 | E20: =IF('단위공사별(집계)'!N9>1,('단위공사별(집계)'!D9+'단위공사별(집계)'!E9+'단위공사별(집계)'!F9+'단위공사별(집계)'!G9+'단위공사별(집계)'!H9+'단위공사별(집계)'!I9)/1000," ") -> 239050 | G20: =IF('단위공사별(집계)'!N9>0,('단위공사별(집계)'!L9+'단위공사별(집계)'!M9)/1000,"") -> 37691.769 | H20: =IF('단위공사별(집계)'!N9>0,'단위공사별(집계)'!N9/1000,"") -> 340703.89
B21: 4 | C21: =단위장비4!C1 -> 피니언 연삭 신규라인 | E21: =IF('단위공사별(집계)'!N10>1,('단위공사별(집계)'!D10+'단위공사별(집계)'!E10+'단위공사별(집계)'!F10+'단위공사별(집계)'!G10+'단위공사별(집계)'!H10+'단위공사별(집계)'!I10)/1000," ") -> 177370 | G21: =IF('단위공사별(집계)'!N10>0,('단위공사별(집계)'!L10+'단위공사별(집계)'!M10)/1000,"") -> 27966.489 | H21: =IF('단위공사별(집계)'!N10>0,'단위공사별(집계)'!N10/1000,"") -> 252795.02
B22: 5 | C22: =단위장비5!C1 -> 액슬용접 자동창고 개조 | E22: =IF('단위공사별(집계)'!N11>1,('단위공사별(집계)'!D11+'단위공사별(집계)'!E11+'단위공사별(집계)'!F11+'단위공사별(집계)'!G11+'단위공사별(집계)'!H11+'단위공사별(집계)'!I11)/1000," ") -> 182120 | G22: =IF('단위공사별(집계)'!N11>0,('단위공사별(집계)'!L11+'단위공사별(집계)'!M11)/1000,"") -> 28715.436 | H22: =IF('단위공사별(집계)'!N11>0,'단위공사별(집계)'!N11/1000,"") -> 259564.91
B23: 6 | C23: =단위장비6!C1 -> 액슬용접 자동창고 신작 | E23: =IF('단위공사별(집계)'!N12>1,('단위공사별(집계)'!D12+'단위공사별(집계)'!E12+'단위공사별(집계)'!F12+'단위공사별(집계)'!G12+'단위공사별(집계)'!H12+'단위공사별(집계)'!I12)/1000," ") -> 420590 | G23: =IF('단위공사별(집계)'!N12>0,('단위공사별(집계)'!L12+'단위공사별(집계)'!M12)/1000,"") -> 66315.755 | H23: =IF('단위공사별(집계)'!N12>0,'단위공사별(집계)'!N12/1000,"") -> 599442.16
B24: 7 | C24: =단위장비7!C1 -> 0 | E24: =IF('단위공사별(집계)'!N13>1,('단위공사별(집계)'!D13+'단위공사별(집계)'!E13+'단위공사별(집계)'!F13+'단위공사별(집계)'!G13+'단위공사별(집계)'!H13+'단위공사별(집계)'!I13)/1000," ") | G24: =IF('단위공사별(집계)'!N13>0,('단위공사별(집계)'!L13+'단위공사별(집계)'!M13)/1000,"") | H24: =IF('단위공사별(집계)'!N13>0,'단위공사별(집계)'!N13/1000,"")
B25: 8 | C25: =단위장비8!C1 -> 0 | E25: =IF('단위공사별(집계)'!N14>1,('단위공사별(집계)'!D14+'단위공사별(집계)'!E14+'단위공사별(집계)'!F14+'단위공사별(집계)'!G14+'단위공사별(집계)'!H14+'단위공사별(집계)'!I14)/1000," ") | G25: =IF('단위공사별(집계)'!N14>0,('단위공사별(집계)'!L14+'단위공사별(집계)'!M14)/1000,"") | H25: =IF('단위공사별(집계)'!N14>0,'단위공사별(집계)'!N14/1000,"")
B26: 9 | C26: =단위장비9!C1 -> 0 | E26: =IF('단위공사별(집계)'!N15>1,('단위공사별(집계)'!D15+'단위공사별(집계)'!E15+'단위공사별(집계)'!F15+'단위공사별(집계)'!G15+'단위공사별(집계)'!H15+'단위공사별(집계)'!I15)/1000," ") | G26: =IF('단위공사별(집계)'!N15>0,('단위공사별(집계)'!L15+'단위공사별(집계)'!M15)/1000,"") | H26: =IF('단위공사별(집계)'!N15>0,'단위공사별(집계)'!N15/1000,"")
B27: 10 | C27: =단위장비10!C1 -> 0 | E27: =IF('단위공사별(집계)'!N16>1,('단위공사별(집계)'!D16+'단위공사별(집계)'!E16+'단위공사별(집계)'!F16+'단위공사별(집계)'!G16+'단위공사별(집계)'!H16+'단위공사별(집계)'!I16)/1000," ") | G27: =IF('단위공사별(집계)'!N16>0,('단위공사별(집계)'!L16+'단위공사별(집계)'!M16)/1000,"") | H27: =IF('단위공사별(집계)'!N16>0,'단위공사별(집계)'!N16/1000,"")
B28: 견적 합계 | E28: =SUM(E18:E27) -> 1301680 | F28: =SUM(F18) -> 348287.85 | G28: =SUM(G18:G27) -> 205240 | H28: =SUM(H18:H27) -> 1855207.9
F30: 공개입찰가 (견적時 공란) | H30: 1855000000
B32: 특기사항 | C32: 1. VAT 제외 | F32: 외주계획 업체명 (자작時 공란)
C33: 2. 기본 유틸리티공사 제외 | F33: 설계외주
C34: ='원가항목별(집계)'!I39 -> 9988000 | F34: 제작외주
F35: 전기외주 | G35: 오토라인
F36: 설치외주

Sheet 원가항목별(집계)
C2: A. 원가항목별 견적가 종합(상세견적 첨부)
B4: □ 현대/기아 요구사양과 견적조건 일치여부 CHECK: 1.일치함 2.일부상이(상이내역 첨부참조)
B6: 순번 | C6: 원가구분 | F6: 단위 | G6: 수량 | H6: 단가 | I6: 금 액(원) | J6: 비 고
B7: 1 | C7: 기계 부문 | D7: 자재비 | E7: 철자재(SS.SUS등) | F7: kg | G7: =단위장비1!F16+단위장비2!F17+단위장비3!F20+단위장비5!F17+단위장비4!F17+단위장비6!F18+단위장비7!F30+단위장비8!F30+단위장비9!F30+단위장비10!F30 -> 0 | I7: =단위장비1!H10+단위장비2!H11+단위장비3!H14+단위장비5!H11+단위장비4!H11+단위장비6!H12+단위장비7!H24+단위장비8!H24+단위장비9!H24+단위장비10!H24 -> 11420000 | J7: 加工必要資材
E8: 일반구매품 | F8: 식 | G8: 1 | I8: =단위장비1!H26+단위장비2!H24+단위장비3!H32+단위장비5!H25+단위장비4!H27+단위장비6!H25+단위장비7!H47+단위장비8!H47+단위장비9!H47+단위장비10!H47 -> 13320000 | J8: 加工不要資材
E9: 외주제작품 | F9: 식 | G9: 1 | I9: =단위장비1!H35+단위장비2!H36+단위장비3!H47+단위장비5!H37+단위장비4!H38+단위장비6!H49+단위장비7!H55+단위장비8!H55+단위장비9!H55+단위장비10!H55 -> 1030390000 | J9: 旣加工SUB資材
E10: 설치/해체 공사 자재 | F10: 식 | G10: 1 | I10: =단위장비1!H16+단위장비2!H17+단위장비3!H20+단위장비5!H17+단위장비4!H17+단위장비6!H18+단위장비7!H30+단위장비8!H30+단위장비9!H30+단위장비10!H30 -> 0 | J10: 시운전 자재 포함
E11: 소계 | I11: =SUM(I7:I10) -> 1055130000
D12: 노무비 | E12: 기존설비 철거 | F12: M/D | G12: =단위장비1!F37+단위장비2!F38+단위장비3!F49+단위장비5!F39+단위장비4!F40+단위장비6!F51+단위장비7!F57+단위장비8!F57+단위장비9!F57+단위장비10!F57 -> 70 | H12: =IF(단위장비1!G37>0,단위장비1!G37,"") | I12: =단위장비1!H37+단위장비2!H38+단위장비3!H49+단위장비5!H39+단위장비4!H40+단위장비6!H51+단위장비7!H57+단위장비8!H57+단위장비9!H57+단위장비10!H57 -> 22400000 | J12: 개조공사時
E13: 설계 | F13: M/D | G13: =단위장비1!F38+단위장비2!F39+단위장비3!F50+단위장비5!F40+단위장비4!F41+단위장비6!F52+단위장비7!F58+단위장비8!F58+단위장비9!F58+단위장비10!F58 -> 0 | H13: =IF(단위장비1!G38>0,단위장비1!G38,"") | I13: =단위장비1!H38+단위장비2!H39+단위장비3!H50+단위장비5!H40+단위장비4!H41+단위장비6!H52+단위장비7!H58+단위장비8!H58+단위장비9!H58+단위장비10!H58 -> 0
E14: 제작(제관,가공) | F14: M/D | H14: =IF(단위장비1!G39>0,단위장비1!G39,"") | I14: =단위장비1!H39+단위장비2!H40+단위장비3!H51+단위장비5!H41+단위장비4!H42+단위장비6!H53+단위장비7!H59+단위장비8!H59+단위장비9!H59+단위장비10!H59 -> 0
E15: 조립 | F15: M/D | G15: =단위장비1!F40+단위장비2!F41+단위장비3!F52+단위장비5!F42+단위장비4!F43+단위장비6!F54+단위장비7!F60+단위장비8!F60+단위장비9!F60+단위장비10!F60 -> 185 | H15: =IF(단위장비1!G40>0,단위장비1!G40,"") -> 250000 | I15: =단위장비1!H40+단위장비2!H41+단위장비3!H52+단위장비5!H42+단위장비4!H43+단위장비6!H54+단위장비7!H60+단위장비8!H60+단위장비9!H60+단위장비10!H60 -> 46250000 | J15: 정도검사포함
E16: 설치 | F16: M/D | G16: =단위장비1!F41+단위장비2!F42+단위장비3!F53+단위장비5!F43+단위장비4!F44+단위장비6!F55+단위장비7!F61+단위장비8!F61+단위장비9!F61+단위장비10!F61 -> 199 | H16: =IF(단위장비1!G41>0,단위장비1!G41,"") -> 320000 | I16: =단위장비1!H41+단위장비2!H42+단위장비3!H53+단위장비5!H43+단위장비4!H44+단위장비6!H55+단위장비7!H61+단위장비8!H61+단위장비9!H61+단위장비10!H61 -> 63680000
E17: 시운전 | F17: M/D | G17: =단위장비1!F42+단위장비2!F43+단위장비3!F54+단위장비5!F44+단위장비4!F45+단위장비6!F56+단위장비7!F62+단위장비8!F62+단위장비9!F62+단위장비10!F62 -> 214 | H17: =IF(단위장비1!G42>0,단위장비1!G42,"") -> 500000 | I17: =단위장비1!H42+단위장비2!H43+단위장비3!H54+단위장비5!H44+단위장비4!H45+단위장비6!H56+단위장비7!H62+단위장비8!H62+단위장비9!H62+단위장비10!H62 -> 84140000
E18: 양산대응 | F18: M/D | G18: =단위장비1!F43+단위장비2!F44+단위장비3!F55+단위장비5!F45+단위장비4!F46+단위장비6!F57+단위장비7!F63+단위장비8!F63+단위장비9!F63+단위장비10!F63 -> 94 | H18: =IF(단위장비1!G43>0,단위장비1!G43,"") | I18: =단위장비1!H43+단위장비2!H44+단위장비3!H55+단위장비5!H45+단위장비4!H46+단위장비6!H57+단위장비7!H63+단위장비8!H63+단위장비9!H63+단위장비10!H63 -> 30080000
E19: 도장 | F19: M/D | G19: =단위장비1!F44+단위장비2!F45+단위장비3!F56+단위장비5!F46+단위장비4!F47+단위장비6!F58+단위장비7!F64+단위장비8!F64+단위장비9!F64+단위장비10!F64 -> 0 | H19: =IF(단위장비1!G44>0,단위장비1!G44,"") | I19: =단위장비1!H44+단위장비2!H45+단위장비3!H56+단위장비5!H46+단위장비4!H47+단위장비6!H58+단위장비7!H64+단위장비8!H64+단위장비9!H64+단위장비10!H64 -> 0
E20: 소계 | I20: =SUM(I12:I19) -> 246550000
D21: 일반관리 및 이윤 | I21: =단위장비1!H47+단위장비1!H48+단위장비2!H48+단위장비2!H49+단위장비3!H59+단위장비3!H60+단위장비5!H49+단위장비5!H50+단위장비4!H50+단위장비4!H51+단위장비6!H61+단위장비6!H62+단위장비7!H67+단위장비7!H68+단위장비8!H67+단위장비8!H68+단위장비9!H67+단위장비9!H68+단위장비10!H67+단위장비10!H68 -> 195252000
E22: 기계 소계 | I22: =I20+I11+I21 -> 1496932000
B23: 2 | C23: 전기 부문 | D23: 자재비 | E23: 기계/전기자재 | F23: 식 | G23: 1 | I23: =전기!H48-I24 -> 76759000
E24: 설치/해체 공사 자재 | F24: 식 | G24: 1 | I24: =전기!H16 -> 0 | J24: 시운전 자재 포함
D25: 노무비 | E25: 철거(개조시) | F25: M/D | G25: =전기!F49 -> 50 | H25: =IF(전기!G49>0,전기!G49,"") -> 300000 | I25: =전기!H49 -> 15000000
E26: 설계,프로그램 | F26: M/D | G26: =전기!F50 -> 100 | H26: =IF(전기!G50>0,전기!G50,"") -> 500000 | I26: =전기!H50 -> 50000000
E27: 제작 | F27: M/D | G27: =전기!F51 -> 107 | H27: =IF(전기!G51>0,전기!G51,"") -> 300000 | I27: =전기!H51 -> 32100000
E28: 조립 | F28: M/D | G28: =전기!F52 -> 100 | H28: =IF(전기!G52>0,전기!G52,"") -> 300000 | I28: =전기!H52 -> 30000000
E29: 설치 | F29: M/D | G29: =전기!F53 -> 100 | H29: =IF(전기!G53>0,전기!G53,"") -> 300000 | I29: =전기!H53 -> 30000000
E30: 시운전 | F30: M/D | G30: =전기!F54 -> 98 | H30: =IF(전기!G54>0,전기!G54,"") -> 500000 | I30: =전기!H54 -> 49000000
E31: 양산대응 | F31: M/D | G31: =전기!F55 -> 40 | H31: =IF(전기!G55>0,전기!G55,"") -> 500000 | I31: =전기!H55 -> 20000000
E32: 소계 | I32: =SUM(I25:I31) -> 226100000
D33: 일반관리 및 이윤 | I33: =전기!H58+전기!H59 -> 45428850
E34: 전기 소계 | I34: =I32+I23+I33+I24 -> 348287850
B35: 3 | C35: 자재비 합계 | I35: =I23+I11+I24 -> 1131889000
C36: 노무비 합계 | I36: =I32+I20 -> 472650000
C37: 중간 합계 | I37: =I36+I35 -> 1604539000
B38: 4 | C38: 포장,운송 및 중장비 사용료
B39: 5 | C39: 표준안전관리비 | F39: 설치/철거/수리금액 기준 | I39: =CEILING(MIN(I48:I49),1000) -> 9988000 | J39: =I30+I29+I25+I24+I17+I16+I12+I10 -> 264220000
B40: 6 | C40: 일반관리비 | I40: =전기!H58+단위장비1!H47+단위장비2!H48+단위장비3!H59+단위장비5!H49+단위장비4!H50+단위장비6!H61+단위장비7!H67+단위장비8!H67+단위장비9!H67+단위장비10!H67 -> 80226950
B41: 7 | C41: 이 윤 | I41: =전기!H59+단위장비1!H48+단위장비2!H49+단위장비3!H60+단위장비5!H50+단위장비4!H51+단위장비6!H62+단위장비7!H68+단위장비8!H68+단위장비9!H68+단위장비10!H68 -> 160453900
C42: 합 계 | F42: 3~7항 합계 | I42: =I22+I34+I38+I39 -> 1855207850
B43: 주1. 표준안전관리비:(설치/철거/시운전 공사 관련 금액)의
...

Sheet 단위공사별(집계)
A2: B. 단위장비별 견적가 종합(상세견적 첨부)
N3: 단위:원
I5: 포장/운송 | L5: 표준안전 | M5: 일반관리비
A6: 순번 | B6: 단위장비명 | C6: 수량 | D6: 자재비 | E6: 철거 | F6: 제작 | G6: 설치/시운전 | H6: 양산대응 | I6: 중장비사용 | J6: 기계소계 | K6: 전기소계 | L6: 관리비 | M6: 이윤 | N6: 합 계 | O6: 비 고
A7: =IF(B7>0,1,"") -> 1 | B7: =단위장비1!C$1 -> 선삭 신규 라인 IN ROBOT SYSTEM | C7: 1식 | D7: =단위장비1!H36 -> 75170000 | E7: =단위장비1!H37 -> 0 | F7: =단위장비1!H38+단위장비1!H39+단위장비1!H40+단위장비1!H44 -> 4250000 | G7: =단위장비1!H41+단위장비1!H42 -> 22440000 | H7: =단위장비1!H43 -> 0 | I7: =IF($B7>0,'원가항목별(집계)'!I$38*$P7/$P$17,0) -> 0 | J7: =SUM(D7:I7) -> 101860000 | K7: =IF(B7>0,'원가항목별(집계)'!I$34*P7/P$17,0) -> 27254471 | L7: =IF($B7>0,'원가항목별(집계)'!I$39*$P7/$P$17,0) -> 781588.16 | M7: =단위장비1!H47+단위장비1!H48 -> 15279000 | N7: =SUM(J7:M7) -> 1.4517506e+08 | P7: =D7+E7+F7+G7+H7+M7 -> 117139000
A8: =IF(B8>0,A7+1,"") -> 2 | B8: =단위장비2!C$1 -> 선삭 신규 라인 2AXIS-I GANTRY SYSTEM | C8: 1식 | D8: =단위장비2!H37 -> 141490000 | E8: =단위장비2!H38 -> 1600000 | F8: =단위장비2!H39+단위장비2!H40+단위장비2!H41+단위장비2!H45 -> 12000000 | G8: =단위장비2!H42+단위장비2!H43 -> 16000000 | H8: =단위장비2!H44 -> 9600000 | I8: =IF($B8>0,'원가항목별(집계)'!I$38*$P8/$P$17,0) -> 0 | J8: =SUM(D8:I8) -> 180690000 | K8: =IF(B8>0,'원가항목별(집계)'!I$34*P8/P$17,0) -> 48346853 | L8: =IF($B8>0,'원가항목별(집계)'!I$39*$P8/$P$17,0) -> 1386463.4 | M8: =단위장비2!H48+단위장비2!H49 -> 27103500 | N8: =SUM(J8:M8) -> 2.5752682e+08 | P8: =D8+E8+F8+G8+H8+M8 -> 207793500
A9: =IF(B9>0,A8+1,"") -> 3 | B9: =단위장비3!C$1 -> 선삭 개조 라인 | C9: 1식 | D9: =단위장비3!H48 -> 190610000 | E9: =단위장비3!H49 -> 2560000 | F9: =단위장비3!H50+단위장비3!H51+단위장비3!H52+단위장비3!H56 -> 8500000 | G9: =단위장비3!H53+단위장비3!H54 -> 37380000 | H9: =단위장비3!H55 -> 0 | I9: =IF($B9>0,'원가항목별(집계)'!I$38*$P9/$P$17,0) -> 0 | J9: =SUM(D9:I9) -> 239050000 | K9: =IF(B9>0,'원가항목별(집계)'!I$34*P9/P$17,0) -> 63962119 | L9: =IF($B9>0,'원가항목별(집계)'!I$39*$P9/$P$17,0) -> 1834269.1 | M9: =단위장비3!H59+단위장비3!H60 -> 35857500 | N9: =SUM(J9:M9) -> 3.4070389e+08 | P9: =D9+E9+F9+G9+H9+M9 -> 274907500
A10: =IF(B10>0,A9+1,"") -> 4 | B10: =단위장비4!C1 -> 피니언 연삭 신규라인 | C10: 1식 | D10: =단위장비4!H39 -> 146610000 | E10: =단위장비4!H40 -> 0 | F10: =단위장비4!H41+단위장비4!H42+단위장비4!H43+단위장비4!H47 -> 9000000 | G10: =단위장비4!H44+단위장비4!H45 -> 16960000 | H10: =단위장비4!H46 -> 4800000 | I10: =IF($B10>0,'원가항목별(집계)'!I$38*$P10/$P$17,0) -> 0 | J10: =SUM(D10:I10) -> 177370000 | K10: =IF(B10>0,'원가항목별(집계)'!I$34*P10/P$17,0) -> 47458527 | L10: =IF($B10>0,'원가항목별(집계)'!I$39*$P10/$P$17,0) -> 1360988.5 | M10: =단위장비4!H50+단위장비4!H51 -> 26605500 | N10: =SUM(J10:M10) -> 2.5279502e+08 | P10: =D10+E10+F10+G10+H10+M10 -> 203975500
A11: =IF(B11>0,A10+1,"") -> 5 | B11: =단위장비5!C1 -> 액슬용접 자동창고 개조 | C11: 1식 | D11: =단위장비5!H38 -> 126120000 | E11: =단위장비5!H39 -> 18240000 | F11: =단위장비5!H40+단위장비5!H41+단위장비5!H42+단위장비5!H46 -> 0 | G11: =단위장비5!H43+단위장비5!H44 -> 30080000 | H11: =단위장비5!H45 -> 7680000 | I11: =IF($B11>0,'원가항목별(집계)'!I$38*$P11/$P$17,0) -> 0 | J11: =SUM(D11:I11) -> 182120000 | K11: =IF(B11>0,'원가항목별(집계)'!I$34*P11/P$17,0) -> 48729475 | L11: =IF($B11>0,'원가항목별(집계)'!I$39*$P11/$P$17,0) -> 1397436.1 | M11: =단위장비5!H49+단위장비5!H50 -> 27318000 | N11: =SUM(J11:M11) -> 2.5956491e+08 | P11: =D11+E11+F11+G11+H11+M11 -> 209438000
A12: =IF(B12>0,A11+1,"") -> 6 | B12: =단위장비6!C$1 -> 액슬용접 자동창고 신작 | C12: 1식 | D12: =단위장비6!H50 -> 375130000 | E12: =단위장비6!H51 -> 0 | F12: =단위장비6!H52+단위장비6!H53+단위장비6!H54+단위장비6!H58 -> 12500000 | G12: =단위장비6!H55+단위장비6!H56 -> 24960000 | H12: =단위장비6!H57 -> 8000000 | I12: =IF($B12>0,'원가항목별(집계)'!I$38*$P12/$P$17,0) -> 0 | J12: =SUM(D12:I12) -> 420590000 | K12: =IF(B12>0,'원가항목별(집계)'!I$34*P12/P$17,0) -> 1.125364e+08 | L12: =IF($B12>0,'원가항목별(집계)'!I$39*$P12/$P$17,0) -> 3227254.7 | M12: =단위장비6!H61+단위장비6!H62 -> 63088500 | N12: =SUM(J12:M12) -> 5.9944216e+08 | P12: =D12+E12+F12+G12+H12+M12 -> 483678500
A13: =IF(B13>0,A12+1,"") | B13: =단위장비7!C$1 -> 0 | C13: 1식 | D13: =단위장비7!H56 -> 0 | E13: =단위장비7!H57 -> 0 | F13: =단위장비7!H58+단위장비7!H59+단위장비7!H60+단위장비7!H64 -> 0 | G13: =단위장비7!H61+단위장비7!H62 -> 0 | H13: =단위장비7!H63 -> 0 | I13: =IF($B13>0,'원가항목별(집계)'!I$38*$P13/$P$17,0) -> 0 | J13: =SUM(D13:I13) -> 0 | K13: =IF(B13>0,'원가항목별(집계)'!I$34*P13/P$17,0) -> 0 | L13: =IF($B13>0,'원가항목별(집계)'!I$39*$P13/$P$17,0) -> 0 | M13: =단위장비7!H67+단위장비7!H68 -> 0 | N13: =SUM(J13:M13) -> 0 | P13: =D13+E13+F13+G13+H13+M13 -> 0
A14: =IF(B14>0,A13+1,"") | B14: =단위장비8!C$1 -> 0 | C14: 1식 | D14: =단위장비8!H57 -> 0 | E14: =단위장비8!H57 -> 0 | F14: =단위장비8!H58+단위장비8!H59+단위장비8!H60+단위장비8!H64 -> 0 | H14: =단위장비8!H63 -> 0 | I14: =IF($B14>0,'원가항목별(집계)'!I$38*$P14/$P$17,0) -> 0 | J14: =SUM(D14:I14) -> 0 | K14: =IF(B14>0,'원가항목별(집계)'!I$34*P14/P$17,0) -> 0 | L14: =IF($B14>0,'원가항목별(집계)'!I$39*$P14/$P$17,0) -> 0 | M14: =단위장비8!H67+단위장비8!H68 -> 0 | N14: =SUM(J14:M14) -> 0 | P14: =D14+E14+F14+G14+H14+M14 -> 0
A15: =IF(B15>0,A14+1,"") | B15: =단위장비9!C$1 -> 0 | C15: 1식 | D15: =단위장비9!H57 -> 0 | E15: =단위장비9!H58 -> 0 | F15: =단위장비9!H59+단위장비9!H60+단위장비9!H61+단위장비9!H65 -> 0 | G15: =단위장비9!H62+단위장비9!H63 -> 0 | H15: =단위장비9!H64 -> 0 | I15: =IF($B15>0,'원가항목별(집계)'!I$38*$P15/$P$17,0) -> 0 | J15: =SUM(D15:I15) -> 0 | K15: =IF(B15>0,'원가항목별(집계)'!I$34*P15/P$17,0) -> 0 | L15: =IF($B15>0,'원가항목별(집계)'!I$39*$P15/$P$17,0) -> 0 | M15: =단위장비9!H68+단위장비9!H69 -> 0 | N15: =SUM(J15:M15) -> 0 | P15: =D15+E15+F15+G15+H15+M15 -> 0
A16: =IF(B16>0,A15+1,"") | B16: =단위장비10!C$1 -> 0 | C16: 1식 | D16: =단위장비10!H58 -> 0 | E16: =단위장비10!H59 -> 0 | F16: =단위장비10!H60+단위장비10!H61+단위장비10!H62+단위장비10!H66 -> 0 | G16: =단위장비10!H63+단위장비10!H64 -> 0 | H16: =단위장비10!H65 -> 0 | I16: =IF($B16>0,'원가항목별(집계)'!I$38*$P16/$P$17,0) -> 0 | J16: =SUM(D16:I16) -> 0 | K16: =IF(B16>0,'원가항목별(집계)'!I$34*P16/P$17,0) -> 0 | L16: =IF($B16>0,'원가항목별(집계)'!I$39*$P16/$P$17,0) -> 0 | M16: =단위장비10!H69+단위장비10!H70 -> 0 | N16: =SUM(J16:M16) -> 0 | P16: =D16+E16+F16+G16+H16+M16 -> 0
A17: 합 계 | D17: =SUM(D7:D16) -> 1055130000 | E17: =SUM(E7:E16) -> 22400000 | F17: =SUM(F7:F16) -> 46250000 | G17: =SUM(G7:G16) -> 147820000 | H17: =SUM(H7:H16) -> 30080000 | I17: =SUM(I7:I16) -> 0 | J17: =SUM(D17:I17) -> 1301680000 | K17: =SUM(K7:K16) -> 348287850 | L17: =SUM(L7:L16) -> 9988000 | M17: =SUM(M7:M16) -> 195252000 | N17: =SUM(N7:N16) -> 1855207850 | P17: =SUM(P7:P16) -> 1496932000
D18: =IF(D17=0,"",D17/$N17) -> 0.56873951 | E18: =IF(E17=0,"",E17/$N17) -> 0.012074119 | F18: =IF(F17=0,"",F17/$N17) -> 0.024929821 | G18: =IF(G17=0,"",G17/$N17) -> 0.079678404 | H18: =IF(H17=0,"",H17/$N17) -> 0.016213817 | I18: =IF(I17=0,"",I17/$N17) | J18: =IF(J17=0,"",J17/$N17) -> 0.70163567 | K18: =IF(K17=0,"",K17/$N17) -> 0.18773522 | ... N18: =IF(N17=0,"",N17/$N17) -> 1
A19: 주) 전기비용은 턴키장비의 공통비용으로서 총 전기비용을 단위장비별 기계금액의 비율에 따라 배분함
N20: =IF('원가항목별(집계)'!I42='단위공사별(집계)'!N17,"","DATA오류입니다!")

Sheet 전기
B1: □ 전기부문: | I1: (첨부)
A2: 구분 | C2: 품 명 | D2: 규격 | E2: 단위 | F2: 수량 | G2: 단가(원) | H2: 금액(원) | I2: 原MAKER
A3: 자 재 비 | B3: 철자재 | C3: MAIN PANEL | D3: W1200xH2000xD500 | E3: EA | F3: 6 | G3: 1500000 | H3: =IF(F3=0,G3,G3*F3) -> 9000000
C4: OP PANEL | D4: W400xH550xD200 | E4: EA | F4: 6 | G4: 350000 | H4: =IF(F4=0,G4,G4*F4) -> 2100000
C5: TB BOX | D5: W200xH280xD180 | E5: EA | F5: 20 | G5: 200000 | H5: =IF(F5=0,G5,G5*F5) -> 4000000
H6: =IF(F6=0,G6,G6*F6) -> 0
H7: =IF(F7=0,G7,G7*F7) -> 0
H8: =IF(F8=0,G8,G8*F8) -> 0
H9: =SUM(H3:H8) -> 15100000
B10: 설치/해체/ | H10: =IF(F10=0,G10,G10*F10) -> 0
B11: 시운전 공사 | H11: =IF(F11=0,G11,G11*F11) -> 0
B12: 자재 | H12: =IF(F12=0,G12,G12*F12) -> 0
H13: =IF(F13=0,G13,G13*F13) -> 0
H14: =IF(F14=0,G14,G14*F14) -> 0
H15: =IF(F15=0,G15,G15*F15) -> 0
H16: =SUM(H10:H15) -> 0
B17: 전기자재 | C17: BASE | D17: Q312B | E17: EA | F17: 6 | G17: 196000 | H17: =IF(F17=0,G17,G17*F17) -> 1176000 | I17: 미쯔비시
C18: POWER | D18: Q61P | E18: EA | F18: 6 | G18: 101000 | H18: =IF(F18=0,G18,G18*F18) -> 606000 | I18: 미쯔비시
C19: CPU | D19: Q13UDV CPU | E19: EA | F19: 6 | G19: 1950000 | H19: =IF(F19=0,G19,G19*F19) -> 11700000 | I19: 미쯔비시
C20: DP MASTER | D20: QJ71PB92V | E20: EA | F20: 6 | G20: 1104000 | H20: =IF(F20=0,G20,G20*F20) -> 6624000 | I20: 미쯔비시
C21: ETHERNET | D21: QJ71E71-100 | E21: EA | F21: 6 | G21: 738000 | H21: =IF(F21=0,G21,G21*F21) -> 4428000 | I21: 미쯔비시
C22: POS | D22: QD77MS2 | E22: EA | F22: 3 | G22: 549000 | H22: =IF(F22=0,G22,G22*F22) -> 1647000 | I22: 미쯔비시
C23: CC-LINK MASTER | D23: QJ61BT11N | E23: EA | F23: 6 | G23: 179000 | H23: =IF(F23=0,G23,G23*F23) -> 1074000 | I23: 미쯔비시
C24: INPUT | D24: QX42 | E24: EA | F24: 15 | G24: 271000 | H24: =IF(F24=0,G24,G24*F24) -> 4065000 | I24: 미쯔비시
C25: OUTPUT | D25: QY42P | E25: EA | F25: 15 | G25: 271000 | H25: =IF(F25=0,G25,G25*F25) -> 4065000 | I25: 미쯔비시
C26: TOUCH PANEL | D26: GT2712-STBD | E26: EA | F26: 6 | G26: 1678000 | H26: =IF(F26=0,G26,G26*F26) -> 10068000 | I26: 미쯔비시
C27: HUB | D27: IES10-SW8 | E27: EA | F27: 6 | G27: 188000 | H27: =IF(F27=0,G27,G27*F27) -> 1128000 | I27: 미쯔비시
C28: CC-LINK REMOTE | D28: AJ65SBTB1-32D | E28: EA | F28: 15 | G28: 186000 | H28: =IF(F28=0,G28,G28*F28) -> 2790000 | I28: 미쯔비시
C29: CC-LINK REMOTE | D29: AJ65SBTB1-16D | E29: EA | F29: 15 | G29: 110000 | H29: =IF(F29=0,G29,G29*F29) -> 1650000 | I29: 미쯔비시
... C33: 전장반 에어컨 | D33: AMPS-500F | E33: EA | F33: 6 | G33: 1000000 | H33: =IF(F33=0,G33,G33*F33) -> 6000000 | I33: 에어메이져
H34: =IF(F34=0,G34,G34*F34) -> 0
H35: =IF(F35=0,G35,G35*F35) -> 0
H36: =IF(F36=0,G36,G36*F36) -> 0
H37: =IF(F37=0,G37,G37*F37) -> 0
H38: =IF(F38=0,G38,G38*F38) -> 0
H39: =IF(F39=0,G39,G39*F39) -> 0
H40: =IF(F40=0,G40,G40*F40) -> 0
H41: =IF(F41=0,G41,G41*F41) -> 0
H42: =IF(F42=0,G42,G42*F42) -> 0
H43: =IF(F43=0,G43,G43*F43) -> 0
...

Sheet 단위장비1
B1: □ 단위공사명(전기제외): | C1: 선삭 신규 라인 IN ROBOT SYSTEM | I1: (첨부)
A2: 구분 | C2: 품 명 | D2: 규격 | E2: 단위 | F2: 수량 | G2: 단가(원) | H2: 금액(원) | I2: 原MAKER
A3: 자 재 비 | B3: 철자재 | C3: Robot Base | D3: Robot Base | E3: SET | F3: 1 | G3: 1420000 | H3: =IF(F3=0,G3,G3*F3) -> 1420000
C4: Duct Ass'y | D4: Duct Ass'y | E4: SET | F4: 1 | G4: 2380000 | H4: =IF(F4=0,G4,G4*F4) -> 2380000
H5: =F5*G5 -> 0
H6: =F6*G6 -> 0
H7: =F7*G7 -> 0
H8: =IF(F8=0,G8,G8*F8) -> 0
H9: =IF(F9=0,G9,G9*F9) -> 0
H10: =SUM(H3:H9) -> 3800000
B11: 설치/해체/시운전 | H11: =IF(F11=0,G11,G11*F11) -> 0
B12: 공사 관련 자재 | H12: =IF(F12=0,G12,G12*F12) -> 0
H13: =IF(F13=0,G13,G13*F13) -> 0
H14: =IF(F14=0,G14,G14*F14) -> 0
H15: =IF(F15=0,G15,G15*F15) -> 0
H16: =SUM(H11:H15) -> 0
B17: 구매품 | C17: 드레스팩 | D17: TR.RSE.50/TRE.50 Assy | E17: SET | F17: 1 | G17: 3600000 | H17: =IF(F17=0,G17,G17*F17) -> 3600000 | I17: 이구스
B18: (유공압품외) | C18: MONITOR & 거치대 | D18: 22인치 MONITOR & 거치대 | E18: SET | F18: 1 | G18: 840000 | H18: =IF(F18=0,G18,G18*F18) -> 840000 | I18: LG전자
H19: =IF(F19=0,G19,G19*F19) -> 0
H20: =IF(F20=0,G20,G20*F20) -> 0
H21: =IF(F21=0,G21,G21*F21) -> 0
H22: =IF(F22=0,G22,G22*F22) -> 0
H23: =IF(F23=0,G23,G23*F23) -> 0
H24: =IF(F24=0,G24,G24*F24) -> 0
H25: =IF(F25=0,G25,G25*F25) -> 0
H26: =SUM(H17:H25) -> 4440000
B27: 외주제작품 | C27: 2D VISION SYSTEM | D27: 키엔스 비젼적용 | E27: SET | F27: 1 | G27: 28440000 | H27: =IF(F27=0,G27,G27*F27) -> 28440000 | I27: OEM제작
C28: Gripper Ass'y | D28: Gripper Ass'y | E28: SET | F28: 1 | G28: 2510000 | H28: =IF(F28=0,G28,G28*F28) -> 2510000 | I28: OEM제작
C29: AIR 부품 및 배관 | D29: AIR 부품 및 배관 | E29: SET | F29: 1 | G29: 920000 | H29: =IF(F29=0,G29,G29*F29) -> 920000 | I29: OEM제작
C30: Safety Fence & sensor | D30: Safety Fence & sensor | E30: SET | F30: 1 | G30: 14220000 | H30: =IF(F30=0,G30,G30*F30) -> 14220000 | I30: OEM제작
C31: Pallet 고정 FRAME | D31: Pallet 고정 FRAME | E31: SET | F31: 2 | G31: 3600000 | H31: =IF(F31=0,G31,G31*F31) -> 7200000 | I31: OEM제작
C32: SHIFTER UNIT | D32: SHIFTER UNIT | E32: SET | F32: 1 | G32: 10290000 | H32: =IF(F32=0,G32,G32*F32) -> 10290000 | I32: OEM제작
C33: 위상정렬장치 | D33: 위상정렬 | E33: SET | F33: 1 | G33: 3350000 | H33: =IF(F33=0,G33,G33*F33) -> 3350000 | I33: OEM제작
H35: =SUM(H27:H34) -> 66930000
B36: 자재비 소계 | H36: =SUM(H35,H26,H16,H10) -> 75170000
A37: 노 무 비 | B37: 기존설비 철거 | E37: M/D | H37: =G37*F37 -> 0
B38: 기계 설계 | E38: M/D | H38: =F38*G38 -> 0
B39: 기계 제작(제관,가공) | E39: M/D | H39: =F39*G39 -> 0
B40: 기계 조립 | E40: M/D | F40: 17 | G40: 250000 | H40: =F40*G40 -> 4250000
B41: 기계 설치 | E41: M/D | F41: 17 | G41: 320000 | H41: =F41*G41 -> 5440000
...

Sheet 단위장비2
B1: □ 단위공사명(전기제외): | C1: 선삭 신규 라인 2AXIS-I GANTRY SYSTEM | I1: (첨부)
A2: 구분 | C2: 품 명 | D2: 규격 | E2: 단위 | F2: 수량 | G2: 단가(원) | H2: 금액(원) | I2: 原MAKER
A3: 자 재 비 | B3: 철자재 | H3: =IF(F3=0,G3,G3*F3) -> 0
H4: =F4*G4 -> 0
H5: =F5*G5 -> 0
H6: =F6*G6 -> 0
H7: =IF(F7=0,G7,G7*F7) -> 0
H8: =IF(F8=0,G8,G8*F8) -> 0
H9: =IF(F9=0,G9,G9*F9) -> 0
H10: =IF(F10=0,G10,G10*F10) -> 0
H11: =SUM(H3:H10) -> 0
B12: 설치/해체/시운전 | H12: =IF(F12=0,G12,G12*F12) -> 0
B13: 공사 관련 자재 | H13: =IF(F13=0,G13,G13*F13) -> 0
H14: =IF(F14=0,G14,G14*F14) -> 0
H15: =IF(F15=0,G15,G15*F15) -> 0
H16: =IF(F16=0,G16,G16*F16) -> 0
H17: =SUM(H12:H16) -> 0
B18: 구매품 | H18: =IF(F18=0,G18,G18*F18) -> 0
B19: (유공압품외) | H19: =IF(F19=0,G19,G19*F19) -> 0
H20: =IF(F20=0,G20,G20*F20) -> 0
H21: =IF(F21=0,G21,G21*F21) -> 0
H22: =IF(F22=0,G22,G22*F22) -> 0
H23: =IF(F23=0,G23,G23*F23) -> 0
H24: =SUM(H18:H23) -> 0
B25: 외주제작품 | C25: 2AXIS-I TYPE HEAD ASS'Y | D25: 가반 10KG | E25: SET | F25: 1 | G25: 19110000 | H25: =IF(F25=0,G25,G25*F25) -> 19110000 | I25: OEM제작
C26: GANTRY 주행빔 ASS'Y | D26: LP 200/200-20V | E26: m | F26: 16 | G26: 2310000 | H26: =IF(F26=0,G26,G26*F26) -> 36960000 | I26: OEM제작
C27: Post & Base Plate | D27: 200*200 | E27: SET | F27: 3 | G27: 2650000 | H27: =IF(F27=0,G27,G27*F27) -> 7950000 | I27: OEM제작
C28: AIR BLOWER | D28: 칩제거 & 틸팅장치 | E28: SET | F28: 1 | G28: 12550000 | H28: =IF(F28=0,G28,G28*F28) -> 12550000 | I28: OEM제작
C29: GRIPPER JAW | D29: GRIPPER JAW | E29: SET | F29: 1 | G29: 2510000 | H29: =IF(F29=0,G29,G29*F29) -> 2510000 | I29: OEM제작
C30: GRIPPER JAW TIP | D30: GRIPPER JAW TIP | E30: SET | F30: 1 | G30: 2510000 | H30: =IF(F30=0,G30,G30*F30) -> 2510000 | I30: OEM제작
C31: STOCKER 상부 PALLET | D31: 상부 PALLET | E31: EA | F31: 70 | G31: 70000 | H31: =IF(F31=0,G31,G31*F31) -> 4900000 | I31: OEM제작
C32: OUT STOCKER | D32: FLAT CHAIN CONVEYOR | E32: SET | F32: 1 | G32: 55000000 | H32: =IF(F32=0,G32,G32*F32) -> 55000000 | I32: OEM제작
H36: =SUM(H25:H35) -> 141490000
B37: 자재비 소계 | H37: =SUM(H36,H24,H17,H11) -> 141490000
A38: 노 무 비 | B38: 기존설비 철거 | E38: M/D | F38: 5 | G38: 320000 | H38: =G38*F38 -> 1600000
B39: 기계 설계 | E39: M/D | H39: =F39*G39 -> 0
B40: 기계 제작(제관,가공) | E40: M/D
B41: 기계 조립 | E41: M/D | F41: 48 | G41: 250000 | H41: =F41*G41 -> 12000000
B42: 기계 설치 | E42: M/D | F42: 25 | G42: 320000 | H42: =F42*G42 -> 8000000
B43: 기계 시운전 | E43: M/D | F43: 25 | G43: 320000 | H43: =F43*G43 -> 8000000
...

Sheet 단위장비3
B1: □ 단위공사명(전기제외): | C1: 선삭 개조 라인 | I1: (첨부)
A2: 구분 | C2: 품 명 | D2: 규격 | E2: 단위 | F2: 수량 | G2: 단가(원) | H2: 금액(원) | I2: 原MAKER
A3: 자 재 비 | B3: 철자재 | C3: Robot Base | D3: Robot Base | E3: SET | F3: 2 | G3: 1420000 | H3: =IF(F3=0,G3,G3*F3) -> 2840000 | I3: Manifold
C4: Duct Ass'y | D4: Duct Ass'y | E4: SET | F4: 2 | G4: 2390000 | H4: =IF(F4=0,G4,G4*F4) -> 4780000
H5: =IF(F5=0,G5,G5*F5) -> 0
H6: =IF(F6=0,G6,G6*F6) -> 0
H7: =IF(F7=0,G7,G7*F7) -> 0
H8: =IF(F8=0,G8,G8*F8) -> 0
H9: =IF(F9=0,G9,G9*F9) -> 0
H10: =IF(F10=0,G10,G10*F10) -> 0
H11: =IF(F11=0,G11,G11*F11) -> 0
H12: =IF(F12=0,G12,G12*F12) -> 0
H13: =IF(F13=0,G13,G13*F13) -> 0
H14: =SUM(H3:H13) -> 7620000
B15: 설치/해체/시운전 | H15: =IF(F15=0,G15,G15*F15) -> 0
B16: 공사 관련 자재 | H16: =IF(F16=0,G16,G16*F16) -> 0
H17: =IF(F17=0,G17,G17*F17) -> 0
H18: =IF(F18=0,G18,G18*F18) -> 0
H19: =IF(F19=0,G19,G19*F19) -> 0
H20: =SUM(H15:H19) -> 0
B21: 구매품 | C21: 드레스팩 | D21: TR.RSE.50/TRE.50 Assy | E21: SET | F21: 2 | G21: 3600000 | H21: =IF(F21=0,G21,G21*F21) -> 7200000 | I21: 이구스
B22: (유공압품외) | C22: MONITOR & 거치대 | D22: 22인치 MONITOR & 거치대 | E22: SET | F22: 2 | G22: 840000 | H22: =IF(F22=0,G22,G22*F22) -> 1680000 | I22: LG전자
H23: =IF(F23=0,G23,G23*F23) -> 0
H24: =IF(F24=0,G24,G24*F24) -> 0
H25: =IF(F25=0,G25,G25*F25) -> 0
H26: =IF(F26=0,G26,G26*F26) -> 0
H27: =IF(F27=0,G27,G27*F27) -> 0
H28: =IF(F28=0,G28,G28*F28) -> 0
H29: =IF(F29=0,G29,G29*F29) -> 0
H30: =IF(F30=0,G30,G30*F30) -> 0
H31: =IF(F31=0,G31,G31*F31) -> 0
H32: =SUM(H21:H31) -> 8880000
B33: 외주제작품 | C33: 2D VISION SYSTEM | D33: 키엔스 비젼적용 | E33: SET | F33: 2 | G33: 28440000 | H33: =IF(F33=0,G33,G33*F33) -> 56880000 | I33: OEM제작
C34: Gripper Ass'y | D34: Gripper Ass'y | E34: SET | F34: 2 | G34: 2510000 | H34: =IF(F34=0,G34,G34*F34) -> 5020000 | I34: OEM제작
C35: AIR 부품 및 배관 | D35: AIR 부품 및 배관 | E35: SET | F35: 2 | G35: 920000 | H35: =IF(F35=0,G35,G35*F35) -> 1840000 | I35: OEM제작
C36: Safety Fence & sensor | D36: Safety Fence & sensor | E36: SET | F36: 2 | G36: 14220000 | H36: =IF(F36=0,G36,G36*F36) -> 28440000 | I36: OEM제작
C37: Pallet 고정 FRAME | D37: Pallet 고정 FRAME | E37: SET | F37: 4 | G37: 3600000 | H37: =IF(F37=0,G37,G37*F37) -> 14400000 | I37: OEM제작
C38: SHIFTER UNIT | D38: SHIFTER UNIT | E38: SET | F38: 2 | G38: 10290000 | H38: =IF(F38=0,G38,G38*F38) -> 20580000 | I38: OEM제작
C39: 위상정렬장치 | D39: 위상정렬 | E39: SET | F39: 2 | G39: 3350000 | H39: =IF(F39=0,G39,G39*F39) -> 6700000 | I39: OEM제작
C40: 연삭라인 연삭기 판넬에어컨 변경 | D40: AMPS-1000F | E40: SET | F40: 2 | G40: 3090000 | H40: =IF(F40=0,G40,G40*F40) -> 6180000 | I40: OEM제작
...

Sheet 단위장비4
B1: □ 단위공사명(전기제외): | C1: 피니언 연삭 신규라인 | I1: (첨부)
A2: 구분 | C2: 품 명 | D2: 규격 | E2: 단위 | F2: 수량 | G2: 단가(원) | H2: 금액(원) | I2: 原MAKER
A3: 자 재 비 | B3: 철자재 | H3: =IF(F3=0,G3,G3*F3) -> 0
H4: =IF(F4=0,G4,G4*F4) -> 0
H5: =IF(F5=0,G5,G5*F5) -> 0
H6: =IF(F6=0,G6,G6*F6) -> 0
H7: =IF(F7=0,G7,G7*F7) -> 0
H8: =IF(F8=0,G8,G8*F8) -> 0
H9: =IF(F9=0,G9,G9*F9) -> 0
H10: =IF(F10=0,G10,G10*F10) -> 0
H11: =SUM(H3:H10) -> 0
B12: 설치/해체/시운전 | H12: =IF(F12=0,G12,G12*F12) -> 0
B13: 공사 관련 자재 | H13: =IF(F13=0,G13,G13*F13) -> 0
H14: =IF(F14=0,G14,G14*F14) -> 0
H15: =IF(F15=0,G15,G15*F15) -> 0
H16: =IF(F16=0,G16,G16*F16) -> 0
H17: =SUM(H12:H16) -> 0
B18: 구매품 | H18: =IF(F18=0,G18,G18*F18) -> 0
B19: (유공압품외) | H19: =IF(F19=0,G19,G19*F19) -> 0
H20: =IF(F20=0,G20,G20*F20) -> 0
H21: =IF(F21=0,G21,G21*F21) -> 0
H22: =IF(F22=0,G22,G22*F22) -> 0
H23: =IF(F23=0,G23,G23*F23) -> 0
H24: =IF(F24=0,G24,G24*F24) -> 0
H25: =IF(F25=0,G25,G25*F25) -> 0
H26: =IF(F26=0,G26,G26*F26) -> 0
H27: =SUM(H18:H26) -> 0
B28: 외주제작품 | C28: 2AXIS-I TYPE HEAD ASS'Y | D28: 가반 10KG | E28: SET | F28: 1 | G28: 19110000 | H28: =IF(F28=0,G28,G28*F28) -> 19110000 | I28: OEM제작
C29: GANTRY 주행빔 ASS'Y | D29: LP 200/200-20V | E29: m | F29: 8 | G29: 2310000 | H29: =IF(F29=0,G29,G29*F29) -> 18480000 | I29: OEM제작
C30: Post & Base Plate | D30: 200*200 | E30: SET | F30: 2 | G30: 2650000 | H30: =IF(F30=0,G30,G30*F30) -> 5300000 | I30: OEM제작
C31: IN STOCKER | D31: FLAT CHAIN CONVEYOR | E31: SET | F31: 1 | G31: 43490000 | H31: =IF(F31=0,G31,G31*F31) -> 43490000 | I31: OEM제작
C32: OUT STOCKER | D32: FLAT CHAIN CONVEYOR | E32: SET | F32: 1 | G32: 43490000 | H32: =IF(F32=0,G32,G32*F32) -> 43490000 | I32: OEM제작
C33: 90도 틸팅 | D33: 90도 틸팅 | E33: SET | F33: 2 | G33: 3350000 | H33: =IF(F33=0,G33,G33*F33) -> 6700000 | I33: OEM제작
C34: GRIPPER JAW | D34: GRIPPER JAW | E34: SET | F34: 2 | G34: 2510000 | H34: =IF(F34=0,G34,G34*F34) -> 5020000 | I34: OEM제작
C35: GRIPPER JAW TIP | D35: GRIPPER JAW TIP | E35: SET | F35: 2 | G35: 2510000 | H35: =IF(F35=0,G35,G35*F35) -> 5020000 | I35: OEM제작
H38: =SUM(H28:H37) -> 146610000
B39: 자재비 소계 | H39: =SUM(H38,H27,H17,H11) -> 146610000
A40: 노 무 비 | B40: 기존설비 철거 | E40: M/D | H40: =F40*G40 -> 0
B41: 기계 설계 | E41: M/D | H41: =F41*G41 -> 0
B42: 기계 제작(제관,가공) | E42: M/D | H42: =F42*G42 -> 0
...

Sheet 단위장비5
B1: □ 단위공사명(전기제외): | C1: 액슬용접 자동창고 개조 | I1: (첨부)
A2: 구분 | C2: 품 명 | D2: 규격 | E2: 단위 | F2: 수량 | G2: 단가(원) | H2: 금액(원) | I2: 原MAKER
A3: 자 재 비 | B3: 철자재 | H3: =IF(F3=0,G3,G3*F3) -> 0
H4: =IF(F4=0,G4,G4*F4) -> 0
H5: =IF(F5=0,G5,G5*F5) -> 0
H6: =IF(F6=0,G6,G6*F6) -> 0
H7: =IF(F7=0,G7,G7*F7) -> 0
H8: =IF(F8=0,G8,G8*F8) -> 0
H9: =IF(F9=0,G9,G9*F9) -> 0
H10: =IF(F10=0,G10,G10*F10) -> 0
H11: =SUM(H3:H10) -> 0
B12: 설치/해체/시운전 | H12: =IF(F12=0,G12,G12*F12) -> 0
B13: 공사 관련 자재 | H13: =IF(F13=0,G13,G13*F13) -> 0
H14: =IF(F14=0,G14,G14*F14) -> 0
H15: =IF(F15=0,G15,G15*F15) -> 0
H16: =IF(F16=0,G16,G16*F16) -> 0
H17: =SUM(H12:H16) -> 0
B18: 구매품 | H18: =IF(F18=0,G18,G18*F18) -> 0
B19: (유공압품외) | H19: =IF(F19=0,G19,G19*F19) -> 0
H20: =IF(F20=0,G20,G20*F20) -> 0
H21: =IF(F21=0,G21,G21*F21) -> 0
H22: =IF(F22=0,G22,G22*F22) -> 0
H23: =IF(F23=0,G23,G23*F23) -> 0
H24: =IF(F24=0,G24,G24*F24) -> 0
H25: =SUM(H18:H24) -> 0
B26: 외주제작품 | C26: Post-300*300*700mm | D26: 제작후 mtg부 가공 | E26: SET | F26: 8 | G26: 840000 | H26: =IF(F26=0,G26,G26*F26) -> 6720000 | I26: OEM제작
C27: Carriage Ass'y | D27: With Roller / Upper Plate | E27: SET | F27: 1 | G27: 4030000 | H27: =IF(F27=0,G27,G27*F27) -> 4030000 | I27: OEM제작
C28: Z axis & Box 파지 Gripper | D28: 2단 Telescopic | E28: SET | F28: 1 | G28: 35700000 | H28: =IF(F28=0,G28,G28*F28) -> 35700000 | I28: OEM제작
C29: Z axis -Gear Box & Coupling | D29: ATLANTA 075 with Pinion | E29: SET | F29: 1 | G29: 3440000 | H29: =IF(F29=0,G29,G29*F29) -> 3440000 | I29: OEM제작
C30: Box-Base 거치대 | D30: 5900*350 | E30: SET | F30: 23 | G30: 1090000 | H30: =IF(F30=0,G30,G30*F30) -> 25070000 | I30: OEM제작
C31: AMR 도킹 BKT & ROLLER | E31: SET | F31: 2 | G31: 800000 | H31: =IF(F31=0,G31,G31*F31) -> 1600000 | I31: OEM제작
C32: 자동창고 운영 시스템 | D32: WCS<->물류관제 I/F | E32: SET | F32: 1 | G32: 26880000 | H32: =IF(F32=0,G32,G32*F32) -> 26880000 | I32: OEM제작
C33: 창고 물류 관제 시스템 | D33: 통합 연동 시운전 및 운영 지원 | E33: SET | F33: 1 | G33: 21000000 | H33: =IF(F33=0,G33,G33*F33) -> 21000000 | I33: OEM제작
C34: 현황판 모니터 | E34: SET | F34: 1 | G34: 1680000 | H34: =IF(F34=0,G34,G34*F34) -> 1680000 | I34: OEM제작
E35: SET | H35: =IF(F35=0,G35,G35*F35) -> 0
H36: =IF(F36=0,G36,G36*F36) -> 0
H37: =SUM(H26:H36) -> 126120000
B38: 자재비 소계 | H38: =SUM(H37,H25,H17,H11) -> 126120000
A39: 노 무 비 | B39: 기존설비 철거 | E39: M/D | F39: 57 | G39: 320000 | H39: =F39*G39 -> 18240000
B40: 기계 설계 | E40: M/D | H40: =F40*G40 -> 0
...

Sheet 단위장비6
B1: □ 단위공사명(전기제외): | C1: 액슬용접 자동창고 신작 | I1: (첨부)
A2: 구분 | C2: 품 명 | D2: 규격 | E2: 단위 | F2: 수량 | G2: 단가(원) | H2: 금액(원) | I2: 原MAKER
A3: 자 재 비 | B3: 철자재 | H3: =IF(F3=0,G3,G3*F3) -> 0
H4: =IF(F4=0,G4,G4*F4) -> 0
H5: =IF(F5=0,G5,G5*F5) -> 0
H6: =IF(F6=0,G6,G6*F6) -> 0
H7: =IF(F7=0,G7,G7*F7) -> 0
H8: =IF(F8=0,G8,G8*F8) -> 0
H9: =IF(F9=0,G9,G9*F9) -> 0
H10: =IF(F10=0,G10,G10*F10) -> 0
C11: 기타자재 | H11: =IF(F11=0,G11,G11*F11) -> 0
H12: =SUM(H3:H11) -> 0
B13: 설치/해체/시운전 | H13: =IF(F13=0,G13,G13*F13) -> 0
B14: 공사 관련 자재 | H14: =IF(F14=0,G14,G14*F14) -> 0
H15: =IF(F15=0,G15,G15*F15) -> 0
H16: =IF(F16=0,G16,G16*F16) -> 0
C17: 기타자재 | H17: =IF(F17=0,G17,G17*F17) -> 0
H18: =SUM(H13:H17) -> 0
B19: 구매품 | H19: =IF(F19=0,G19,G19*F19) -> 0
B20: (유공압품외) | H20: =IF(F20=0,G20,G20*F20) -> 0
H21: =IF(F21=0,G21,G21*F21) -> 0
H22: =IF(F22=0,G22,G22*F22) -> 0
H23: =IF(F23=0,G23,G23*F23) -> 0
C24: 기타자재 | E24: ST | H24: =IF(F24=0,G24,G24*F24) -> 0
H25: =SUM(H19:H24) -> 0
B26: 외주제작품 | C26: 주행 AXIS-1 | D26: LP 200/200 35 VZ 20,000mm | E26: SET | F26: 1 | G26: 37800000 | H26: =IF(F26=0,G26,G26*F26) -> 37800000 | I26: OEM제작
C27: 주행 AXIS-2 | D27: LP 200/200 35 FZ 20,000mm | E27: SET | F27: 1 | G27: 35280000 | H27: =G27*F27 -> 35280000 | I27: OEM제작
C28: Gear Box | D28: ATLANTA 90 | E28: SET | F28: 1 | G28: 4030000 | H28: =G28*F28 -> 4030000 | I28: OEM제작
C29: 동력 전달 | D29: Shaft & Coupling & Pinion | E29: SET | F29: 1 | G29: 3780000 | H29: =G29*F29 -> 3780000 | I29: OEM제작
C30: Carriage Ass'y | D30: With Roller / Upper Plate | E30: SET | F30: 2 | G30: 3440000 | H30: =G30*F30 -> 6880000 | I30: OEM제작
C31: Post & Base Plate & Support Beam | E31: SET | F31: 8 | G31: 3020000 | H31: =G31*F31 -> 24160000 | I31: OEM제작
C32: 상부 Walkway & Starway | D32: 20m | E32: SET | F32: 1 | G32: 7980000 | H32: =G32*F32 -> 7980000 | I32: OEM제작
C33: Duct Ass'y | E33: SET | F33: 1 | G33: 5460000 | H33: =G33*F33 -> 5460000 | I33: OEM제작
C34: Cross AXIS | D34: LP 250/200 35 VZ/VS-8,000mm | E34: SET | F34: 1 | G34: 16800000 | H34: =G34*F34 -> 16800000 | I34: OEM제작
C35: Gear Box | D35: ATLANTA 75 | E35: SET | F35: 1 | G35: 3440000 | H35: =G35*F35 -> 3440000 | I35: OEM제작
C36: Carriage Ass'y | D36: With Roller / Upper Plate | E36: SET | F36: 1 | G36: 4030000 | H36: =G36*F36 -> 4030000 | I36: OEM제작
C37: Duct Ass'y | E37: SET | F37: 1 | G37: 2100000 | H37: =G37*F37 -> 2100000 | I37: OEM제작
C38: Cross Support beam | E38: SET | F38: 2 | G38: 2520000 | H38: =G38*F38 -> 5040000 | I38: OEM제작
C39: Z axis & Box 파지 Gripper | D39: 2단 Telescopic 구조 | E39: SET | F39: 1 | G39: 35700000 | H39: =G39*F39 -> 35700000 | I39: OEM제작
C40: Z axis -Gear Box & Coupling | D40: ATLANTA 075 with Pinion | E40: SET | F40: 1 | G40: 3440000 | H40: =G40*F40 -> 3440000 | I40: OEM제작
...

Sheet 단위장비7
B1: □ 단위공사명(전기제외): | I1: (첨부)
A2: 구분 | C2: 품 명 | D2: 규격 | E2: 단위 | F2: 수량 | G2: 단가(원) | H2: 금액(원) | I2: 原MAKER
A3: 자 재 비 | B3: 철자재 | H3: =IF(F3=0,G3,G3*F3) -> 0
H4: =IF(F4=0,G4,G4*F4) -> 0
H5: =IF(F5=0,G5,G5*F5) -> 0
H6: =IF(F6=0,G6,G6*F6) -> 0
H7: =IF(F7=0,G7,G7*F7) -> 0
H8: =IF(F8=0,G8,G8*F8) -> 0
H9: =IF(F9=0,G9,G9*F9) -> 0
H10: =IF(F10=0,G10,G10*F10) -> 0
H11: =IF(F11=0,G11,G11*F11) -> 0
H12: =IF(F12=0,G12,G12*F12) -> 0
H13: =IF(F13=0,G13,G13*F13) -> 0
H14: =IF(F14=0,G14,G14*F14) -> 0
H15: =IF(F15=0,G15,G15*F15) -> 0
... H22: =IF(F22=0,G22,G22*F22) -> 0
C23: 기타자재 | E23: ST | H23: =IF(F23=0,G23,G23*F23) -> 0
H24: =SUM(H3:H23) -> 0
B25: 설치/해체/시운전 | H25: =IF(F25=0,G25,G25*F25) -> 0
B26: 공사 관련 자재 | H26: =IF(F26=0,G26,G26*F26) -> 0
H27: =IF(F27=0,G27,G27*F27) -> 0
H28: =IF(F28=0,G28,G28*F28) -> 0
C29: 기타자재 | H29: =IF(F29=0,G29,G29*F29) -> 0
H30: =SUM(H25:H29) -> 0
B31: 구매품 | H31: =IF(F31=0,G31,G31*F31) -> 0
B32: (유공압품외) | H32: =IF(F32=0,G32,G32*F32) -> 0
H33: =IF(F33=0,G33,G33*F33) -> 0
H34: =IF(F34=0,G34,G34*F34) -> 0
H35: =IF(F35=0,G35,G35*F35) -> 0
H36: =IF(F36=0,G36,G36*F36) -> 0
H37: =IF(F37=0,G37,G37*F37) -> 0
H38: =IF(F38=0,G38,G38*F38) -> 0
H39: =IF(F39=0,G39,G39*F39) -> 0
H40: =IF(F40=0,G40,G40*F40) -> 0
H41: =IF(F41=0,G41,G41*F41) -> 0
H42: =IF(F42=0,G42,G42*F42) -> 0
H43: =IF(F43=0,G43,G43*F43) -> 0
H44: =IF(F44=0,G44,G44*F44) -> 0
H45: =IF(F45=0,G45,G45*F45) -> 0
C46: 기타자재 | E46: ST | H46: =IF(F46=0,G46,G46*F46) -> 0
...

Sheet 단위장비8
B1: □ 단위공사명(전기제외): | I1: (첨부)
A2: 구분 | C2: 품 명 | D2: 규격 | E2: 단위 | F2: 수량 | G2: 단가(원) | H2: 금액(원) | I2: 原MAKER
A3: 자 재 비 | B3: 철자재 | H3: =IF(F3=0,G3,G3*F3) -> 0
H4: =IF(F4=0,G4,G4*F4) -> 0
H5: =IF(F5=0,G5,G5*F5) -> 0
H6: =IF(F6=0,G6,G6*F6) -> 0
H7: =IF(F7=0,G7,G7*F7) -> 0
H8: =IF(F8=0,G8,G8*F8) -> 0
H9: =IF(F9=0,G9,G9*F9) -> 0
H10: =IF(F10=0,G10,G10*F10) -> 0
H11: =IF(F11=0,G11,G11*F11) -> 0
H12: =IF(F12=0,G12,G12*F12) -> 0
H13: =IF(F13=0,G13,G13*F13) -> 0
H14: =IF(F14=0,G14,G14*F14) -> 0
H15: =IF(F15=0,G15,G15*F15) -> 0
... H22: =IF(F22=0,G22,G22*F22) -> 0
C23: 기타자재 | H23: =IF(F23=0,G23,G23*F23) -> 0
H24: =SUM(H3:H23) -> 0
B25: 설치/해체/시운전 | H25: =IF(F25=0,G25,G25*F25) -> 0
B26: 공사 관련 자재 | H26: =IF(F26=0,G26,G26*F26) -> 0
H27: =IF(F27=0,G27,G27*F27) -> 0
H28: =IF(F28=0,G28,G28*F28) -> 0
C29: 기타자재 | H29: =IF(F29=0,G29,G29*F29) -> 0
H30: =SUM(H25:H29) -> 0
B31: 구매품 | H31: =IF(F31=0,G31,G31*F31) -> 0
B32: (유공압품외) | H32: =IF(F32=0,G32,G32*F32) -> 0
H33: =IF(F33=0,G33,G33*F33) -> 0
H34: =IF(F34=0,G34,G34*F34) -> 0
H35: =IF(F35=0,G35,G35*F35) -> 0
H36: =IF(F36=0,G36,G36*F36) -> 0
H37: =IF(F37=0,G37,G37*F37) -> 0
H38: =IF(F38=0,G38,G38*F38) -> 0
H39: =IF(F39=0,G39,G39*F39) -> 0
H40: =IF(F40=0,G40,G40*F40) -> 0
H41: =IF(F41=0,G41,G41*F41) -> 0
H42: =IF(F42=0,G42,G42*F42) -> 0
H43: =IF(F43=0,G43,G43*F43) -> 0
H44: =IF(F44=0,G44,G44*F44) -> 0
H45: =IF(F45=0,G45,G45*F45) -> 0
C46: 기타자재 | H46: =IF(F46=0,G46,G46*F46) -> 0
...

Sheet 단위장비9
B1: □ 단위공사명(전기제외): | I1: (첨부)
A2: 구분 | C2: 품 명 | D2: 규격 | E2: 단위 | F2: 수량 | G2: 단가(원) | H2: 금액(원) | I2: 原MAKER
A3: 자 재 비 | B3: 철자재 | H3: =IF(F3=0,G3,G3*F3) -> 0
H4: =IF(F4=0,G4,G4*F4) -> 0
H5: =IF(F5=0,G5,G5*F5) -> 0
H6: =IF(F6=0,G6,G6*F6) -> 0
H7: =IF(F7=0,G7,G7*F7) -> 0
H8: =IF(F8=0,G8,G8*F8) -> 0
H9: =IF(F9=0,G9,G9*F9) -> 0
H10: =IF(F10=0,G10,G10*F10) -> 0
H11: =IF(F11=0,G11,G11*F11) -> 0
H12: =IF(F12=0,G12,G12*F12) -> 0
H13: =IF(F13=0,G13,G13*F13) -> 0
H14: =IF(F14=0,G14,G14*F14) -> 0
H15: =IF(F15=0,G15,G15*F15) -> 0
... H22: =IF(F22=0,G22,G22*F22) -> 0
C23: 기타자재 | H23: =IF(F23=0,G23,G23*F23) -> 0
H24: =SUM(H3:H23) -> 0
B25: 설치/해체/시운전 | H25: =IF(F25=0,G25,G25*F25) -> 0
B26: 공사 관련 자재 | H26: =IF(F26=0,G26,G26*F26) -> 0
H27: =IF(F27=0,G27,G27*F27) -> 0
H28: =IF(F28=0,G28,G28*F28) -> 0
C29: 기타자재 | H29: =IF(F29=0,G29,G29*F29) -> 0
H30: =SUM(H25:H29) -> 0
B31: 구매품 | H31: =IF(F31=0,G31,G31*F31) -> 0
B32: (유공압품외) | H32: =IF(F32=0,G32,G32*F32) -> 0
H33: =IF(F33=0,G33,G33*F33) -> 0
H34: =IF(F34=0,G34,G34*F34) -> 0
H35: =IF(F35=0,G35,G35*F35) -> 0
H36: =IF(F36=0,G36,G36*F36) -> 0
H37: =IF(F37=0,G37,G37*F37) -> 0
H38: =IF(F38=0,G38,G38*F38) -> 0
H39: =IF(F39=0,G39,G39*F39) -> 0
H40: =IF(F40=0,G40,G40*F40) -> 0
H41: =IF(F41=0,G41,G41*F41) -> 0
H42: =IF(F42=0,G42,G42*F42) -> 0
H43: =IF(F43=0,G43,G43*F43) -> 0
H44: =IF(F44=0,G44,G44*F44) -> 0
H45: =IF(F45=0,G45,G45*F45) -> 0
C46: 기타자재 | H46: =IF(F46=0,G46,G46*F46) -> 0
...

Sheet 단위장비10
B1: □ 단위공사명(전기제외): | I1: (첨부)
A2: 구분 | C2: 품 명 | D2: 규격 | E2: 단위 | F2: 수량 | G2: 단가(원) | H2: 금액(원) | I2: 原MAKER
A3: 자 재 비 | B3: 철자재 | H3: =IF(F3=0,G3,G3*F3) -> 0
H4: =IF(F4=0,G4,G4*F4) -> 0
H5: =IF(F5=0,G5,G5*F5) -> 0
H6: =IF(F6=0,G6,G6*F6) -> 0
H7: =IF(F7=0,G7,G7*F7) -> 0
H8: =IF(F8=0,G8,G8*F8) -> 0
H9: =IF(F9=0,G9,G9*F9) -> 0
H10: =IF(F10=0,G10,G10*F10) -> 0
H11: =IF(F11=0,G11,G11*F11) -> 0
H12: =IF(F12=0,G12,G12*F12) -> 0
H13: =IF(F13=0,G13,G13*F13) -> 0
H14: =IF(F14=0,G14,G14*F14) -> 0
H15: =IF(F15=0,G15,G15*F15) -> 0
... H22: =IF(F22=0,G22,G22*F22) -> 0
C23: 기타자재 | H23: =IF(F23=0,G23,G23*F23) -> 0
H24: =SUM(H3:H23) -> 0
B25: 설치/해체/시운전 | H25: =IF(F25=0,G25,G25*F25) -> 0
B26: 공사 관련 자재 | H26: =IF(F26=0,G26,G26*F26) -> 0
H27: =IF(F27=0,G27,G27*F27) -> 0
H28: =IF(F28=0,G28,G28*F28) -> 0
C29: 기타자재 | H29: =IF(F29=0,G29,G29*F29) -> 0
H30: =SUM(H25:H29) -> 0
B31: 구매품 | H31: =IF(F31=0,G31,G31*F31) -> 0
B32: (유공압품외) | H32: =IF(F32=0,G32,G32*F32) -> 0
H33: =IF(F33=0,G33,G33*F33) -> 0
H34: =IF(F34=0,G34,G34*F34) -> 0
H35: =IF(F35=0,G35,G35*F35) -> 0
H36: =IF(F36=0,G36,G36*F36) -> 0
H37: =IF(F37=0,G37,G37*F37) -> 0
H38: =IF(F38=0,G38,G38*F38) -> 0
H39: =IF(F39=0,G39,G39*F39) -> 0
H40: =IF(F40=0,G40,G40*F40) -> 0
H41: =IF(F41=0,G41,G41*F41) -> 0
H42: =IF(F42=0,G42,G42*F42) -> 0
H43: =IF(F43=0,G43,G43*F43) -> 0
H44: =IF(F44=0,G44,G44*F44) -> 0
H45: =IF(F45=0,G45,G45*F45) -> 0
C46: 기타자재 | H46: =IF(F46=0,G46,G46*F46) -> 0
...

Sheet 첨부(견적조건차이내역)
A1: ※ 현대/기아차의 요구사양과 업체견적사양이 다른경우만 작성
D2: (첨부)
A3: 현대/기아차 요구사양대비 견적조건 상이내역
A5: 항 목 | B5: 현대/기아차 요구사양 | C5: 업체 견적기준 사양 | D5: 비 고
