Workbook

Sheet 갑지
B1: (현대/기아차 설비협력업체 견적통일양식)
B2: 見 積 書
B4: 현대 위아 貴下 | G4: 업체명
B5: 견적일자 | D5: 2019.7.18 | G5: 대표 : | H5: 조만돈
B6: 견적번호 | D6: 019-037 | G6: 주소 : 부산시 기장군 정관읍 산단5로 84
B7: 납기 | C7: 입하 | D7: 2019.1031
C8: 최종검수 | G8: 전화: 051-727-6465
B9: 견적유효기간 | D9: 60 일 | G9: Fax: 051-727-5525
B10: 인도장소 | D10: 위아 3공장 | G10: 견적담당: | H10: 조 만 돈
B11: 지불조건 | D11: 30%,50%,20% | G11: 연 락 처 : | H11: 010-2549-6371
B13: 견적금액: 一金 만원整(\ ) | D13: 일억육천칠백칠십이만팔천구백오십원정
B15: 번호 | C15: 상세품목내역 | E15: 견적금액 (원) | I15: 비 고
E16: 수량 | F16: 단위 | G16: 전기+단위 | H16: 합 계
B17: 1 | C17: PTU 17만 증산용접라인세척기 | E17: 1 | F17: 대 | G17: =단위장비1!H69+전기!H67 -> 1.6772895e+08 | H17: =E17*G17 -> 1.6772895e+08
B18: 2 | C18: =IF('단위공사별(집계)'!N8>0,'단위공사별(집계)'!B8,"") | H18: =E18*G18 -> 0
B19: 3 | C19: =IF('단위공사별(집계)'!N9>0,'단위공사별(집계)'!B9,"") | H19: =E19*G19 -> 0
B20: 4 | C20: =IF('단위공사별(집계)'!N10>0,'단위공사별(집계)'!B10,"") | G20: =IF('단위공사별(집계)'!N10>0,('단위공사별(집계)'!L10+'단위공사별(집계)'!M10)/1000,"") | H20: =IF('단위공사별(집계)'!N10>0,'단위공사별(집계)'!N10/1000,"")
B21: 5 | C21: =IF('단위공사별(집계)'!N11>0,'단위공사별(집계)'!B11,"") | E21: =IF('단위공사별(집계)'!N11>1,('단위공사별(집계)'!D11+'단위공사별(집계)'!E11+'단위공사별(집계)'!F11+'단위공사별(집계)'!G11+'단위공사별(집계)'!H11+'단위공사별(집계)'!I11)/1000," ") | G21: =IF('단위공사별(집계)'!N11>0,('단위공사별(집계)'!L11+'단위공사별(집계)'!M11)/1000,"") | H21: =IF('단위공사별(집계)'!N11>0,'단위공사별(집계)'!N11/1000,"")
B22: 6 | C22: =IF('단위공사별(집계)'!N12>0,'단위공사별(집계)'!B12,"") | E22: =IF('단위공사별(집계)'!N12>1,('단위공사별(집계)'!D12+'단위공사별(집계)'!E12+'단위공사별(집계)'!F12+'단위공사별(집계)'!G12+'단위공사별(집계)'!H12+'단위공사별(집계)'!I12)/1000," ") | G22: =IF('단위공사별(집계)'!N12>0,('단위공사별(집계)'!L12+'단위공사별(집계)'!M12)/1000,"") | H22: =IF('단위공사별(집계)'!N12>0,'단위공사별(집계)'!N12/1000,"")
B23: 7 | C23: =IF('단위공사별(집계)'!N13>0,'단위공사별(집계)'!B13,"") | E23: =IF('단위공사별(집계)'!N13>1,('단위공사별(집계)'!D13+'단위공사별(집계)'!E13+'단위공사별(집계)'!F13+'단위공사별(집계)'!G13+'단위공사별(집계)'!H13+'단위공사별(집계)'!I13)/1000," ") | G23: =IF('단위공사별(집계)'!N13>0,('단위공사별(집계)'!L13+'단위공사별(집계)'!M13)/1000,"") | H23: =IF('단위공사별(집계)'!N13>0,'단위공사별(집계)'!N13/1000,"")
B24: 8 | C24: =IF('단위공사별(집계)'!N14>0,'단위공사별(집계)'!B14,"") | E24: =IF('단위공사별(집계)'!N14>1,('단위공사별(집계)'!D14+'단위공사별(집계)'!E14+'단위공사별(집계)'!F14+'단위공사별(집계)'!G14+'단위공사별(집계)'!H14+'단위공사별(집계)'!I14)/1000," ") | G24: =IF('단위공사별(집계)'!N14>0,('단위공사별(집계)'!L14+'단위공사별(집계)'!M14)/1000,"") | H24: =IF('단위공사별(집계)'!N14>0,'단위공사별(집계)'!N14/1000,"")
B25: 9 | C25: =IF('단위공사별(집계)'!N15>0,'단위공사별(집계)'!B15,"") | E25: =IF('단위공사별(집계)'!N15>1,('단위공사별(집계)'!D15+'단위공사별(집계)'!E15+'단위공사별(집계)'!F15+'단위공사별(집계)'!G15+'단위공사별(집계)'!H15+'단위공사별(집계)'!I15)/1000," ") | G25: =IF('단위공사별(집계)'!N15>0,('단위공사별(집계)'!L15+'단위공사별(집계)'!M15)/1000,"") | H25: =IF('단위공사별(집계)'!N15>0,'단위공사별(집계)'!N15/1000,"")
B26: 10 | C26: =IF('단위공사별(집계)'!N16>0,'단위공사별(집계)'!B16,"") | E26: =IF('단위공사별(집계)'!N16>1,('단위공사별(집계)'!D16+'단위공사별(집계)'!E16+'단위공사별(집계)'!F16+'단위공사별(집계)'!G16+'단위공사별(집계)'!H16+'단위공사별(집계)'!I16)/1000," ") | G26: =IF('단위공사별(집계)'!N16>0,('단위공사별(집계)'!L16+'단위공사별(집계)'!M16)/1000,"") | H26: =IF('단위공사별(집계)'!N16>0,'단위공사별(집계)'!N16/1000,"")
B27: 견적 합계 | E27: =SUM(E17:E23) -> 1 | F27: =SUM(F17:F23) -> 0 | G27: =SUM(G17:G23) -> 1.6772895e+08 | H27: =SUM(H17:H26) -> 1.6772895e+08
F29: 공개입찰가 (견적時 공란)
B31: 특기사항 | C31: 1. VAT 제외 | F31: 외주계획 업체명 (자작時 공란)
C32: 2. 기본 유틸리티공사 제외 | F32: 설계외주
C33: ='원가항목별(집계)'!I39 -> 251000 | F33: 제작외주
F34: 전기외주
F35: 설치외주
L44: =전기!H67+단위장비1!H69+단위장비2!H69+단위장비3!H69+단위장비4!H69+단위장비5!H69+단위장비6!H69+단위장비7!H69+단위장비8!H69+단위장비9!H69+단위장비10!H69 -> 1.6772895e+08

Sheet 원가항목별(집계)
C2: A. 원가항목별 견적가 종합(상세견적 첨부)
B4: □ 현대/기아 요구사양과 견적조건 일치여부 CHECK: 1.일치함 2.일부상이(상이내역 첨부참조)
B6: 순번 | C6: 원가구분 | F6: 단위 | G6: 수량 | H6: 단가 | I6: 금 액(원) | J6: 비 고
B7: 1 | C7: 기계 부문 | D7: 자재비 | E7: 철자재(SS.SUS등) | F7: kg | G7: =단위장비1!F30+단위장비2!F30+단위장비3!F30+단위장비4!F30+단위장비5!F30+단위장비6!F30+단위장비7!F30+단위장비8!F30+단위장비9!F30+단위장비10!F30 -> 0 | I7: =단위장비1!H24+단위장비2!H24+단위장비3!H24+단위장비4!H24+단위장비5!H24+단위장비6!H24+단위장비7!H24+단위장비8!H24+단위장비9!H24+단위장비10!H24 -> 13781826 | J7: 加工必要資材
E8: 일반구매품 | F8: 식 | G8: 1 | I8: =단위장비1!H47+단위장비2!H47+단위장비3!H47+단위장비4!H47+단위장비5!H47+단위장비6!H47+단위장비7!H47+단위장비8!H47+단위장비9!H47+단위장비10!H47 -> 29400000 | J8: 加工不要資材
E9: 외주제작품 | F9: 식 | G9: 1 | I9: =단위장비1!H55+단위장비2!H55+단위장비3!H55+단위장비4!H55+단위장비5!H55+단위장비6!H55+단위장비7!H55+단위장비8!H55+단위장비9!H55+단위장비10!H55 -> 17800000 | J9: 旣加工SUB資材
E10: 설치/해체 공사 자재 | F10: 식 | G10: 1 | I10: =단위장비1!H30+단위장비2!H30+단위장비3!H30+단위장비4!H30+단위장비5!H30+단위장비6!H30+단위장비7!H30+단위장비8!H30+단위장비9!H30+단위장비10!H30 -> 0 | J10: 시운전 자재 포함
E11: 소계 | I11: =SUM(I7:I10) -> 60981826
D12: 노무비 | E12: 기존설비 철거 | F12: M/D | G12: =단위장비1!F57+단위장비2!F57+단위장비3!F57+단위장비4!F57+단위장비5!F57+단위장비6!F57+단위장비7!F57+단위장비8!F57+단위장비9!F57+단위장비10!F57 -> 0 | H12: =IF(단위장비1!G57>0,단위장비1!G57,"") | I12: =단위장비1!H57+단위장비2!H57+단위장비3!H57+단위장비4!H57+단위장비5!H57+단위장비6!H57+단위장비7!H57+단위장비8!H57+단위장비9!H57+단위장비10!H57 -> 0 | J12: 개조공사時
E13: 설계 | F13: M/D | G13: =단위장비1!F58+단위장비2!F58+단위장비3!F58+단위장비4!F58+단위장비5!F58+단위장비6!F58+단위장비7!F58+단위장비8!F58+단위장비9!F58+단위장비10!F58 -> 30 | H13: =IF(단위장비1!G58>0,단위장비1!G58,"") -> 150000 | I13: =단위장비1!H58+단위장비2!H58+단위장비3!H58+단위장비4!H58+단위장비5!H58+단위장비6!H58+단위장비7!H58+단위장비8!H58+단위장비9!H58+단위장비10!H58 -> 4500000
E14: 제작(제관,가공) | F14: M/D | G14: =단위장비1!F59+단위장비2!F59+단위장비3!F59+단위장비4!F59+단위장비5!F59+단위장비6!F59+단위장비7!F59+단위장비8!F59+단위장비9!F59+단위장비10!F59 -> 290 | H14: =IF(단위장비1!G59>0,단위장비1!G59,"") -> 150000 | I14: =단위장비1!H59+단위장비2!H59+단위장비3!H59+단위장비4!H59+단위장비5!H59+단위장비6!H59+단위장비7!H59+단위장비8!H59+단위장비9!H59+단위장비10!H59 -> 43500000
E15: 조립 | F15: M/D | G15: =단위장비1!F60+단위장비2!F60+단위장비3!F60+단위장비4!F60+단위장비5!F60+단위장비6!F60+단위장비7!F60+단위장비8!F60+단위장비9!F60+단위장비10!F60 -> 15 | H15: =IF(단위장비1!G60>0,단위장비1!G60,"") -> 150000 | I15: =단위장비1!H60+단위장비2!H60+단위장비3!H60+단위장비4!H60+단위장비5!H60+단위장비6!H60+단위장비7!H60+단위장비8!H60+단위장비9!H60+단위장비10!H60 -> 2250000 | J15: 정도검사포함
E16: 설치 | F16: M/D | G16: =단위장비1!F61+단위장비2!F61+단위장비3!F61+단위장비4!F61+단위장비5!F61+단위장비6!F61+단위장비7!F61+단위장비8!F61+단위장비9!F61+단위장비10!F61 -> 15 | H16: =IF(단위장비1!G61>0,단위장비1!G61,"") -> 150000 | I16: =단위장비1!H61+단위장비2!H61+단위장비3!H61+단위장비4!H61+단위장비5!H61+단위장비6!H61+단위장비7!H61+단위장비8!H61+단위장비9!H61+단위장비10!H61 -> 2250000
E17: 시운전 | F17: M/D | G17: =단위장비1!F62+단위장비2!F62+단위장비3!F62+단위장비4!F62+단위장비5!F62+단위장비6!F62+단위장비7!F62+단위장비8!F62+단위장비9!F62+단위장비10!F62 -> 15 | H17: =IF(단위장비1!G62>0,단위장비1!G62,"") -> 150000 | I17: =단위장비1!H62+단위장비2!H62+단위장비3!H62+단위장비4!H62+단위장비5!H62+단위장비6!H62+단위장비7!H62+단위장비8!H62+단위장비9!H62+단위장비10!H62 -> 2250000
E18: 양산대응 | F18: M/D | G18: =단위장비1!F63+단위장비2!F63+단위장비3!F63+단위장비4!F63+단위장비5!F63+단위장비6!F63+단위장비7!F63+단위장비8!F63+단위장비9!F63+단위장비10!F63 -> 10 | H18: =IF(단위장비1!G63>0,단위장비1!G63,"") -> 150000 | I18: =단위장비1!H63+단위장비2!H63+단위장비3!H63+단위장비4!H63+단위장비5!H63+단위장비6!H63+단위장비7!H63+단위장비8!H63+단위장비9!H63+단위장비10!H63 -> 1500000
E19: 도장 | F19: M/D | G19: =단위장비1!F64+단위장비2!F64+단위장비3!F64+단위장비4!F64+단위장비5!F64+단위장비6!F64+단위장비7!F64+단위장비8!F64+단위장비9!F64+단위장비10!F64 -> 15 | H19: =IF(단위장비1!G64>0,단위장비1!G64,"") -> 150000 | I19: =단위장비1!H64+단위장비2!H64+단위장비3!H64+단위장비4!H64+단위장비5!H64+단위장비6!H64+단위장비7!H64+단위장비8!H64+단위장비9!H64+단위장비10!H64 -> 2250000
E20: 소계 | I20: =SUM(I12:I19) -> 58500000
D21: 일반관리 및 이윤 | I21: =단위장비1!H67+단위장비1!H68+단위장비2!H67+단위장비2!H68+단위장비3!H67+단위장비3!H68+단위장비4!H67+단위장비4!H68+단위장비5!H67+단위장비5!H68+단위장비6!H67+단위장비6!H68+단위장비7!H67+단위장비7!H68+단위장비8!H67+단위장비8!H68+단위장비9!H67+단위장비9!H68+단위장비10!H67+단위장비10!H68 -> 17922274
E22: 기계 소계 | I22: =I20+I11+I21 -> 1.374041e+08
B23: 2 | C23: 전기 부문 | D23: 자재비 | E23: 기계/전기자재 | F23: 식 | G23: 1 | I23: =전기!H55-I24 -> 17999000
E24: 설치/해체 공사 자재 | F24: 식 | G24: 1 | I24: =전기!H16 -> 0 | J24: 시운전 자재 포함
D25: 노무비 | E25: 철거(개조시) | F25: M/D | G25: =전기!F56 -> 0 | H25: =IF(전기!G56>0,전기!G56,"") | I25: =전기!H56 -> 0
E26: 설계,프로그램 | F26: M/D | G26: =전기!F57 -> 5 | H26: =IF(전기!G57>0,전기!G57,"") -> 150000 | I26: =전기!H57 -> 750000
E27: 제작 | F27: M/D | G27: =전기!F58 -> 15 | H27: =IF(전기!G58>0,전기!G58,"") -> 150000 | I27: =전기!H58 -> 2250000
E28: 조립 | F28: M/D | G28: =전기!F59 -> 10 | H28: =IF(전기!G59>0,전기!G59,"") -> 150000 | I28: =전기!H59 -> 1500000
E29: 설치 | F29: M/D | G29: =전기!F60 -> 5 | H29: =IF(전기!G60>0,전기!G60,"") -> 150000 | I29: =전기!H60 -> 750000
E30: 시운전 | F30: M/D | G30: =전기!F61 -> 10 | H30: =IF(전기!G61>0,전기!G61,"") -> 150000 | I30: =전기!H61 -> 1500000
E31: 양산대응 | F31: M/D | G31: =전기!F62 -> 5 | H31: =IF(전기!G62>0,전기!G62,"") -> 150000 | I31: =전기!H62 -> 750000
E32: 소계 | I32: =SUM(I25:I31) -> 7500000
D33: 일반관리 및 이윤 | I33: =전기!H65+전기!H66 -> 3824850
E34: 전기 소계 | I34: =I32+I23+I33+I24 -> 29323850
B35: 3 | C35: 자재비 합계 | I35: =I23+I11+I24 -> 78980826
C36: 노무비 합계 | I36: =I32+I20 -> 66000000
C37: 중간 합계 | I37: =I36+I35 -> 144980826
B38: 4 | C38: 포장,운송 및 중장비 사용료 | I38: 750000
B39: 5 | C39: 표준안전관리비 | F39: 설치/철거/수리금액 기준 | I39: =CEILING(MIN(I47:I48),1000) -> 251000 | J39: =I30+I29+I25+I24+I17+I16+I12+I10 -> 6750000
B40: 6 | C40: 일반관리비 | I40: 7283791
B41: 7 | C41: 이 윤 | I41: =전기!H66+단위장비1!H68+단위장비2!H68+단위장비3!H68+단위장비4!H68+단위장비5!H68+단위장비6!H68+단위장비7!H68+단위장비8!H68+단위장비9!H68+단위장비10!H68 -> 14498083
C42: 합 계 | F42: 3~7항 합계 | I42: =I22+I34+I38+I39 -> 1.6772895e+08
B43: 주1. 표준안전관리비:(설치/철거/시운전 공사 관련 금액)의 ⓐ2.66%,ⓑ1.95%+기초액,ⓒ2.02%(50억 이상일경우)
...

Sheet 단위공사별(집계)
A2: B. 단위장비별 견적가 종합(상세견적 첨부)
N3: 단위:원
I5: 포장/운송 | L5: 표준안전 | M5: 일반관리비
A6: 순번 | B6: 단위장비명 | C6: 수량 | D6: 자재비 | E6: 철거 | F6: 제작 | G6: 설치/시운전 | H6: 양산대응 | I6: 중장비사용 | J6: 기계소계 | K6: 전기소계 | L6: 관리비 | M6: 이윤 | N6: 합 계 | O6: 비 고
A7: =IF(B7>0,1,"") -> 1 | B7: PTU 17만 증산용접라인세척기 | C7: 1식 | D7: =단위장비1!H56 -> 60981826 | E7: =단위장비1!H57 -> 0 | F7: =단위장비1!H58+단위장비1!H59+단위장비1!H60+단위장비1!H64 -> 52500000 | G7: =단위장비1!H61+단위장비1!H62 -> 4500000 | H7: =단위장비1!H63 -> 1500000 | I7: =IF($B7>0,'원가항목별(집계)'!I$38*$P7/$P$17,0) -> 750000 | J7: =SUM(D7:I7) -> 120231826 | K7: =IF(B7>0,'원가항목별(집계)'!I$34*P7/P$17,0) -> 29323850 | L7: =IF($B7>0,'원가항목별(집계)'!I$39*$P7/$P$17,0) -> 251000 | M7: =단위장비1!H67+단위장비1!H68 -> 17922274 | N7: =SUM(J7:M7) -> 1.6772895e+08 | P7: =D7+E7+F7+G7+H7+M7 -> 1.374041e+08
A8: =IF(B8>0,A7+1,"") | B8: =단위장비2!C$1 -> 0 | C8: 1식 | D8: =단위장비2!H56 -> 0 | E8: =단위장비2!H57 -> 0 | F8: =단위장비2!H58+단위장비2!H59+단위장비2!H60+단위장비2!H64 -> 0 | G8: =단위장비2!H61+단위장비2!H62 -> 0 | H8: =단위장비2!H63 -> 0 | I8: =IF($B8>0,'원가항목별(집계)'!I$38*$P8/$P$17,0) -> 0 | J8: =SUM(D8:I8) -> 0 | K8: =IF(B8>0,'원가항목별(집계)'!I$34*P8/P$17,0) -> 0 | L8: =IF($B8>0,'원가항목별(집계)'!I$39*$P8/$P$17,0) -> 0 | M8: =단위장비2!H67+단위장비2!H68 -> 0 | N8: =SUM(J8:M8) -> 0 | P8: =D8+E8+F8+G8+H8+M8 -> 0
A9: =IF(B9>0,A8+1,"") | B9: =단위장비3!C$1 -> 0 | C9: 1식 | D9: =단위장비3!H56 -> 0 | E9: =단위장비3!H57 -> 0 | F9: =단위장비3!H58+단위장비3!H59+단위장비3!H60+단위장비3!H64 -> 0 | G9: =단위장비3!H61+단위장비3!H62 -> 0 | H9: =단위장비3!H63 -> 0 | I9: =IF($B9>0,'원가항목별(집계)'!I$38*$P9/$P$17,0) -> 0 | J9: =SUM(D9:I9) -> 0 | K9: =IF(B9>0,'원가항목별(집계)'!I$34*P9/P$17,0) -> 0 | L9: =IF($B9>0,'원가항목별(집계)'!I$39*$P9/$P$17,0) -> 0 | M9: =단위장비3!H67+단위장비3!H68 -> 0 | N9: =SUM(J9:M9) -> 0 | P9: =D9+E9+F9+G9+H9+M9 -> 0
A10: =IF(B10>0,A9+1,"") | B10: =단위장비4!C$1 -> 0 | C10: 1식 | D10: =단위장비4!H56 -> 0 | E10: =단위장비4!H57 -> 0 | F10: =단위장비4!H58+단위장비4!H59+단위장비4!H60+단위장비4!H64 -> 0 | G10: =단위장비4!H61+단위장비4!H62 -> 0 | H10: =단위장비4!H63 -> 0 | I10: =IF($B10>0,'원가항목별(집계)'!I$38*$P10/$P$17,0) -> 0 | J10: =SUM(D10:I10) -> 0 | K10: =IF(B10>0,'원가항목별(집계)'!I$34*P10/P$17,0) -> 0 | L10: =IF($B10>0,'원가항목별(집계)'!I$39*$P10/$P$17,0) -> 0 | M10: =단위장비4!H67+단위장비4!H68 -> 0 | N10: =SUM(J10:M10) -> 0 | P10: =D10+E10+F10+G10+H10+M10 -> 0
A11: =IF(B11>0,A10+1,"") | B11: =단위장비5!C$1 -> 0 | C11: 1식 | D11: =단위장비5!H56 -> 0 | E11: =단위장비5!H57 -> 0 | F11: =단위장비5!H58+단위장비5!H59+단위장비5!H60+단위장비5!H64 -> 0 | G11: =단위장비5!H61+단위장비5!H62 -> 0 | H11: =단위장비5!H63 -> 0 | I11: =IF($B11>0,'원가항목별(집계)'!I$38*$P11/$P$17,0) -> 0 | J11: =SUM(D11:I11) -> 0 | K11: =IF(B11>0,'원가항목별(집계)'!I$34*P11/P$17,0) -> 0 | L11: =IF($B11>0,'원가항목별(집계)'!I$39*$P11/$P$17,0) -> 0 | M11: =단위장비5!H67+단위장비5!H68 -> 0 | N11: =SUM(J11:M11) -> 0 | P11: =D11+E11+F11+G11+H11+M11 -> 0
A12: =IF(B12>0,A11+1,"") | B12: =단위장비6!C$1 -> 0 | C12: 1식 | D12: =단위장비6!H56 -> 0 | E12: =단위장비6!H57 -> 0 | F12: =단위장비6!H58+단위장비6!H59+단위장비6!H60+단위장비6!H64 -> 0 | G12: =단위장비6!H61+단위장비6!H62 -> 0 | H12: =단위장비6!H63 -> 0 | I12: =IF($B12>0,'원가항목별(집계)'!I$38*$P12/$P$17,0) -> 0 | J12: =SUM(D12:I12) -> 0 | K12: =IF(B12>0,'원가항목별(집계)'!I$34*P12/P$17,0) -> 0 | L12: =IF($B12>0,'원가항목별(집계)'!I$39*$P12/$P$17,0) -> 0 | M12: =단위장비6!H67+단위장비6!H68 -> 0 | N12: =SUM(J12:M12) -> 0 | P12: =D12+E12+F12+G12+H12+M12 -> 0
A13: =IF(B13>0,A8+1,"") | B13: =단위장비7!C$1 -> 0 | C13: 1식 | D13: =단위장비7!H56 -> 0 | E13: =단위장비7!H57 -> 0 | F13: =단위장비7!H58+단위장비7!H59+단위장비7!H60+단위장비7!H64 -> 0 | G13: =단위장비7!H61+단위장비7!H62 -> 0 | H13: =단위장비7!H63 -> 0 | I13: =IF($B13>0,'원가항목별(집계)'!I$38*$P13/$P$17,0) -> 0 | J13: =SUM(D13:I13) -> 0 | K13: =IF(B13>0,'원가항목별(집계)'!I$34*P13/P$17,0) -> 0 | L13: =IF($B13>0,'원가항목별(집계)'!I$39*$P13/$P$17,0) -> 0 | M13: =단위장비7!H67+단위장비7!H68 -> 0 | N13: =SUM(J13:M13) -> 0 | P13: =D13+E13+F13+G13+H13+M13 -> 0
A14: =IF(B14>0,A13+1,"") | B14: =단위장비8!C$1 -> 0 | C14: 1식 | D14: =단위장비8!H56 -> 0 | E14: =단위장비8!H57 -> 0 | F14: =단위장비8!H58+단위장비8!H59+단위장비8!H60+단위장비8!H64 -> 0 | G14: =단위장비8!H61+단위장비8!H62 -> 0 | H14: =단위장비8!H63 -> 0 | I14: =IF($B14>0,'원가항목별(집계)'!I$38*$P14/$P$17,0) -> 0 | J14: =SUM(D14:I14) -> 0 | K14: =IF(B14>0,'원가항목별(집계)'!I$34*P14/P$17,0) -> 0 | L14: =IF($B14>0,'원가항목별(집계)'!I$39*$P14/$P$17,0) -> 0 | M14: =단위장비8!H67+단위장비8!H68 -> 0 | N14: =SUM(J14:M14) -> 0 | P14: =D14+E14+F14+G14+H14+M14 -> 0
A15: =IF(B15>0,A14+1,"") | B15: =단위장비9!C$1 -> 0 | C15: 1식 | D15: =단위장비9!H57 -> 0 | E15: =단위장비9!H58 -> 0 | F15: =단위장비9!H59+단위장비9!H60+단위장비9!H61+단위장비9!H65 -> 0 | G15: =단위장비9!H62+단위장비9!H63 -> 0 | H15: =단위장비9!H64 -> 0 | I15: =IF($B15>0,'원가항목별(집계)'!I$38*$P15/$P$17,0) -> 0 | J15: =SUM(D15:I15) -> 0 | K15: =IF(B15>0,'원가항목별(집계)'!I$34*P15/P$17,0) -> 0 | L15: =IF($B15>0,'원가항목별(집계)'!I$39*$P15/$P$17,0) -> 0 | M15: =단위장비9!H68+단위장비9!H69 -> 0 | N15: =SUM(J15:M15) -> 0 | P15: =D15+E15+F15+G15+H15+M15 -> 0
A16: =IF(B16>0,A15+1,"") | B16: =단위장비10!C$1 -> 0 | C16: 1식 | D16: =단위장비10!H58 -> 0 | E16: =단위장비10!H59 -> 0 | F16: =단위장비10!H60+단위장비10!H61+단위장비10!H62+단위장비10!H66 -> 0 | G16: =단위장비10!H63+단위장비10!H64 -> 0 | H16: =단위장비10!H65 -> 0 | I16: =IF($B16>0,'원가항목별(집계)'!I$38*$P16/$P$17,0) -> 0 | J16: =SUM(D16:I16) -> 0 | K16: =IF(B16>0,'원가항목별(집계)'!I$34*P16/P$17,0) -> 0 | L16: =IF($B16>0,'원가항목별(집계)'!I$39*$P16/$P$17,0) -> 0 | M16: =단위장비10!H69+단위장비10!H70 -> 0 | N16: =SUM(J16:M16) -> 0 | P16: =D16+E16+F16+G16+H16+M16 -> 0
A17: 합 계 | D17: =SUM(D7:D16) -> 60981826 | E17: =SUM(E7:E16) -> 0 | F17: =SUM(F7:F16) -> 52500000 | G17: =SUM(G7:G16) -> 4500000 | H17: =SUM(H7:H16) -> 1500000 | I17: =SUM(I7:I16) -> 750000 | J17: =SUM(D17:I17) -> 120231826 | K17: =SUM(K7:K16) -> 29323850 | L17: =SUM(L7:L16) -> 251000 | M17: =SUM(M7:M16) -> 17922274 | N17: =SUM(N7:N14) -> 1.6772895e+08 | P17: =SUM(P7:P16) -> 1.374041e+08
D18: =IF(D17=0,"",D17/$N17) -> 0.36357365 | E18: =IF(E17=0,"",E17/$N17) | F18: =IF(F17=0,"",F17/$N17) -> 0.313005 | G18: =IF(G17=0,"",G17/$N17) -> 0.026829 | H18: =IF(H17=0,"",H17/$N17) -> 0.008943 | I18: =IF(I17=0,"",I17/$N17) -> 0.0044715 | J18: =IF(J17=0,"",J17/$N17) -> 0.71682215 | K18: =IF(K17=0,"",K17/$N17) -> 0.17482879 | ... N18: =IF(N17=0,"",N17/$N17) -> 1
A19: 주) 전기비용은 턴키장비의 공통비용으로서 총 전기비용을 단위장비별 기계금액의 비율에 따라 배분함
N20: =IF('원가항목별(집계)'!I42='단위공사별(집계)'!N17,"","DATA오류입니다!")

Sheet 전기
B1: □ 전기부문: | C1: 전기부문(공통) | I1: (첨부)
A2: 구분 | C2: 품 명 | D2: 규격 | E2: 단위 | F2: 수량 | G2: 단가(원) | H2: 금액(원) | I2: 原MAKER
A3: 자 재 비 | B3: 철자재 | C3: PANEL | D3: 1200x1800x450 | E3: EA | F3: 1 | G3: 1800000 | H3: =G3*F3 -> 1800000
C4: MAIN OP | D4: 500x600x200 | E4: EA | F4: 1 | G4: 250000 | H4: =G4*F4 -> 250000
C5: SUB OP | D5: 500x500x180 | E5: EA | F5: 2 | G5: 100000 | H5: =G5*F5 -> 200000
C6: ELB BOX | D6: 250x400x130 | E6: EA | F6: 1 | G6: 50000 | H6: =G6*F6 -> 50000
H7: =IF(F7=0,G7,G7*F7) -> 0
H8: =IF(F8=0,G8,G8*F8) -> 0
H9: =SUM(H3:H8) -> 2300000
B10: 설치/해체/ | H10: =IF(F10=0,G10,G10*F10) -> 0
B11: 시운전 공사 | H11: =IF(F11=0,G11,G11*F11) -> 0
B12: 자재 | H12: =IF(F12=0,G12,G12*F12) -> 0
H13: =IF(F13=0,G13,G13*F13) -> 0
H14: =IF(F14=0,G14,G14*F14) -> 0
H15: =IF(F15=0,G15,G15*F15) -> 0
H16: =SUM(H10:H15) -> 0
B17: 전기자재 | C17: CPU | D17: Q02H CPU | E17: EA | F17: 1 | G17: 1200000 | H17: 1200000
C18: POWER | E18: EA | F18: 1 | G18: 160000 | H18: =G18*F18 -> 160000
C19: BASE & CC LINK | E19: EA | F19: 3 | G19: 213000 | H19: =G19*F19 -> 639000
C20: 입력CARD | E20: EA | F20: 4 | G20: 275000 | H20: =G20*F20 -> 1100000
C21: 출력CARD | E21: EA | F21: 4 | G21: 275000 | H21: =G21*F21 -> 1100000
C22: 통신 CARD | E22: EA | F22: 1 | G22: 650000 | H22: =G22*F22 -> 650000
C23: CABLE & TML | E23: 식 | H23: 1200000
C24: TOUCH PNL | E24: EA | F24: 1 | H24: 1900000
C25: 에어컨,가습기 | H25: 1800000
C26: INVERTER | E26: EA | F26: 1 | G26: 200000 | H26: =G26*F26 -> 200000
C27: TIMMER | F27: 3 | G27: 170000 | H27: =F27*G27 -> 510000
C28: 온도 콘트롤러 | F28: 4 | G28: 125000 | H28: =F28*G28 -> 500000
C29: I/D | D29: BIS-S400 | E29: ST | H29: 350000
C30: 조립자재 | D30: NFB, M/G외 | E30: 식 | H30: 1600000
C31: S/W | D31: PB외 | E31: 식 | G31: 300000 | H31: 300000
C32: 근접 S/W | D32: OMRON | E32: EA | F32: 6 | G32: 60000 | H32: =G32*F32 -> 360000
C33: LIMIT S/W | D33: OMRON | E33: EA | F33: 4 | G33: 65000 | H33: =F33*G33 -> 260000
C34: PHOTO S/W | D34: E3JK-5U1 | E34: EA | F34: 2 | G34: 85000 | H34: =G34*F34 -> 170000
C35: CABLE | H35: 900000
C36: CONNECTOR | E36: 식 | H36: 300000
C37: FLEXIBLE TUBE | E37: 식 | H37: 250000
C38: 배선용 덕트 | H38: 250000
H39: =IF(F39=0,G39,G39*F39) -> 0
H40: =IF(F40=0,G40,G40*F40) -> 0
...

Sheet 단위장비1
B1: □ 단위공사명(전기제외): | C1: PTU 17만증산 용접라인세척기 | I1: (첨부)
A2: 구분 | C2: 품 명 | D2: 규격 | E2: 단위 | F2: 수량 | G2: 단가(원) | H2: 금액(원) | I2: 原MAKER
A3: 자 재 비 | B3: 철자재 | C3: CHANNEL | D3: 100x50x5x7.5 | E3: Kg | F3: 2400 | G3: 2200 | H3: =IF(F3=0,G3,G3*F3) -> 5280000
C4: SQUARE PIPE | D4: 75x40x3.2 | E4: Kg | F4: 150 | G4: 2200 | H4: =IF(F4=0,G4,G4*F4) -> 330000
C5: ANGLE | D5: 50x50x6 | E5: Kg | F5: 70 | G5: 2300 | H5: =IF(F5=0,G5,G5*F5) -> 161000
C6: SS41 PLATE | D6: 4자x8자x12t | E6: Kg | F6: 150 | G6: 2200 | H6: =IF(F6=0,G6,G6*F6) -> 330000
C7: SS41 R/BAR | D7: Ø40 외 | E7: Kg | F7: 60 | G7: 2400 | H7: =IF(F7=0,G7,G7*F7) -> 144000
C8: S45C PLATE | D8: 3자x6자x20t | E8: Kg | F8: 140 | G8: 2200 | H8: =IF(F8=0,G8,G8*F8) -> 308000
C9: S45C R/BAR | D9: Ø60 외 | E9: Kg | F9: 60 | G9: 2400 | H9: 124826
C10: SUS PLATE | D10: 4자x8자x3t 외 | E10: Kg | F10: 1200 | G10: 4600 | H10: =IF(F10=0,G10,G10*F10) -> 5520000
C11: SUS R/BAR | D11: Ø12 외 | E11: Kg | F11: 30 | G11: 4800 | H11: =IF(F11=0,G11,G11*F11) -> 144000
C12: SUS S/Q TUBE | D12: 50x50x3.2 외 | E12: Kg | F12: 120 | G12: 4800 | H12: =IF(F12=0,G12,G12*F12) -> 576000
C13: SUS PIPE | D13: 50 A 외 | E13: Kg | F13: 180 | G13: 4800 | H13: =IF(F13=0,G13,G13*F13) -> 864000
H14: =IF(F14=0,G14,G14*F14) -> 0
H15: =IF(F15=0,G15,G15*F15) -> 0
H16: =IF(F16=0,G16,G16*F16) -> 0
H17: =IF(F17=0,G17,G17*F17) -> 0
H18: =IF(F18=0,G18,G18*F18) -> 0
H19: =IF(F19=0,G19,G19*F19) -> 0
H20: =IF(F20=0,G20,G20*F20) -> 0
H21: =IF(F21=0,G21,G21*F21) -> 0
H22: =IF(F22=0,G22,G22*F22) -> 0
H23: =IF(F23=0,G23,G23*F23) -> 0
H24: =SUM(H3:H23) -> 13781826
B25: 설치/해체/시운전 | H25: =IF(F25=0,G25,G25*F25) -> 0
B26: 공사 관련 자재 | H26: =IF(F26=0,G26,G26*F26) -> 0
H27: =IF(F27=0,G27,G27*F27) -> 0
H28: =IF(F28=0,G28,G28*F28) -> 0
H29: =IF(F29=0,G29,G29*F29) -> 0
H30: =SUM(H25:H29) -> 0
B31: 구매품 | C31: NOZZLE | H31: 700000
B32: (유공압품외) | C32: LM RAL & BEARING | H32: 800000
C33: AIR CYLINDER | H33: 2400000
C34: SOLENOID 외 | H34: 3400000
C35: 쓰미토모 외 | E35: SET | F35: 4 | H35: 3400000
C36: UCT208 외 | H36: 700000
C37: 그런퍼스 외 | E37: SET | F37: 5 | H37: 8700000
C38: 페인트 | H38: 600000
C39: 알루미늄 프로파일 | F39: 1 | H39: 800000
C40: HEATER | H40: 1800000
...

Sheet 단위장비2
B1: □ 단위공사명(전기제외): | I1: (첨부)
A2: 구분 | C2: 품 명 | D2: 규격 | E2: 단위 | F2: 수량 | G2: 단가(원) | H2: 금액(원) | I2: 原MAKER
A3: 자 재 비 | B3: 철자재 | H3: =IF(F3=0,G3,G3*F3) -> 0
H4: =IF(F4=0,G4,G4*F4) -> 0
H5: =IF(F5=0,G5,G5*F5) -> 0
H6: =IF(F6=0,G6,G6*F6) -> 0
H7: =IF(F7=0,G7,G7*F7) -> 0
H8: =IF(F8=0,G8,G8*F8) -> 0
H9: =IF(F9=0,G9,G9*F9) -> 0
H10: =IF(F10=0,G10,G10*F10) -> 0
H11: =IF(F11=0,G11,G11*F11) -> 0
H12: =IF(F12=0,G12,G12*F12) -> 0
H13: =IF(F13=0,G13,G13*F13) -> 0
H14: =IF(F14=0,G14,G14*F14) -> 0
H15: =IF(F15=0,G15,G15*F15) -> 0
... H23: =IF(F23=0,G23,G23*F23) -> 0
H24: =SUM(H3:H23) -> 0
B25: 설치/해체/시운전 | H25: =IF(F25=0,G25,G25*F25) -> 0
B26: 공사 관련 자재 | H26: =IF(F26=0,G26,G26*F26) -> 0
H27: =IF(F27=0,G27,G27*F27) -> 0
H28: =IF(F28=0,G28,G28*F28) -> 0
H29: =IF(F29=0,G29,G29*F29) -> 0
H30: =SUM(H25:H29) -> 0
B31: 구매품 | H31: =IF(F31=0,G31,G31*F31) -> 0
B32: (유공압품외) | H32: =IF(F32=0,G32,G32*F32) -> 0
H33: =IF(F33=0,G33,G33*F33) -> 0
H34: =IF(F34=0,G34,G34*F34) -> 0
H35: =IF(F35=0,G35,G35*F35) -> 0
H36: =IF(F36=0,G36,G36*F36) -> 0
H37: =IF(F37=0,G37,G37*F37) -> 0
H38: =IF(F38=0,G38,G38*F38) -> 0
H39: =IF(F39=0,G39,G39*F39) -> 0
H40: =IF(F40=0,G40,G40*F40) -> 0
H41: =IF(F41=0,G41,G41*F41) -> 0
H42: =IF(F42=0,G42,G42*F42) -> 0
H43: =IF(F43=0,G43,G43*F43) -> 0
H44: =IF(F44=0,G44,G44*F44) -> 0
... H46: =IF(F46=0,G46,G46*F46) -> 0
H47: =SUM(H31:H46) -> 0
B48: 외주제작품 | H48: =IF(F48=0,G48,G48*F48) -> 0
...

Sheet 단위장비3
B1: □ 단위공사명(전기제외): | I1: (첨부)
A2: 구분 | C2: 품 명 | D2: 규격 | E2: 단위 | F2: 수량 | G2: 단가(원) | H2: 금액(원) | I2: 原MAKER
A3: 자 재 비 | B3: 철자재 | H3: =IF(F3=0,G3,G3*F3) -> 0
H4: =IF(F4=0,G4,G4*F4) -> 0
H5: =IF(F5=0,G5,G5*F5) -> 0
H6: =IF(F6=0,G6,G6*F6) -> 0
H7: =IF(F7=0,G7,G7*F7) -> 0
H8: =IF(F8=0,G8,G8*F8) -> 0
H9: =IF(F9=0,G9,G9*F9) -> 0
H10: =IF(F10=0,G10,G10*F10) -> 0
H11: =IF(F11=0,G11,G11*F11) -> 0
H12: =IF(F12=0,G12,G12*F12) -> 0
H13: =IF(F13=0,G13,G13*F13) -> 0
H14: =IF(F14=0,G14,G14*F14) -> 0
H15: =IF(F15=0,G15,G15*F15) -> 0
... H23: =IF(F23=0,G23,G23*F23) -> 0
H24: =SUM(H3:H23) -> 0
B25: 설치/해체/시운전 | H25: =IF(F25=0,G25,G25*F25) -> 0
B26: 공사 관련 자재 | H26: =IF(F26=0,G26,G26*F26) -> 0
H27: =IF(F27=0,G27,G27*F27) -> 0
H28: =IF(F28=0,G28,G28*F28) -> 0
H29: =IF(F29=0,G29,G29*F29) -> 0
H30: =SUM(H25:H29) -> 0
B31: 구매품 | H31: =IF(F31=0,G31,G31*F31) -> 0
B32: (유공압품외) | H32: =IF(F32=0,G32,G32*F32) -> 0
H33: =IF(F33=0,G33,G33*F33) -> 0
H34: =IF(F34=0,G34,G34*F34) -> 0
H35: =IF(F35=0,G35,G35*F35) -> 0
H36: =IF(F36=0,G36,G36*F36) -> 0
H37: =IF(F37=0,G37,G37*F37) -> 0
H38: =IF(F38=0,G38,G38*F38) -> 0
H39: =IF(F39=0,G39,G39*F39) -> 0
H40: =IF(F40=0,G40,G40*F40) -> 0
H41: =IF(F41=0,G41,G41*F41) -> 0
H42: =IF(F42=0,G42,G42*F42) -> 0
H43: =IF(F43=0,G43,G43*F43) -> 0
H44: =IF(F44=0,G44,G44*F44) -> 0
... H46: =IF(F46=0,G46,G46*F46) -> 0
H47: =SUM(H31:H46) -> 0
B48: 외주제작품 | H48: =IF(F48=0,G48,G48*F48) -> 0
...

Sheet 단위장비4
B1: □ 단위공사명(전기제외): | I1: (첨부)
A2: 구분 | C2: 품 명 | D2: 규격 | E2: 단위 | F2: 수량 | G2: 단가(원) | H2: 금액(원) | I2: 原MAKER
A3: 자 재 비 | B3: 철자재 | H3: =IF(F3=0,G3,G3*F3) -> 0
H4: =IF(F4=0,G4,G4*F4) -> 0
H5: =IF(F5=0,G5,G5*F5) -> 0
H6: =IF(F6=0,G6,G6*F6) -> 0
H7: =IF(F7=0,G7,G7*F7) -> 0
H8: =IF(F8=0,G8,G8*F8) -> 0
H9: =IF(F9=0,G9,G9*F9) -> 0
H10: =IF(F10=0,G10,G10*F10) -> 0
H11: =IF(F11=0,G11,G11*F11) -> 0
H12: =IF(F12=0,G12,G12*F12) -> 0
H13: =IF(F13=0,G13,G13*F13) -> 0
H14: =IF(F14=0,G14,G14*F14) -> 0
H15: =IF(F15=0,G15,G15*F15) -> 0
... H22: =IF(F22=0,G22,G22*F22) -> 0
C23: 기타자재 | H23: =IF(F23=0,G23,G23*F23) -> 0
H24: =SUM(H3:H23) -> 0
B25: 설치/해체/시운전 | H25: =IF(F25=0,G25,G25*F25) -> 0
B26: 공사 관련 자재 | H26: =IF(F26=0,G26,G26*F26) -> 0
H27: =IF(F27=0,G27,G27*F27) -> 0
H28: =IF(F28=0,G28,G28*F28) -> 0
C29: 기타자재 | H29: =IF(F29=0,G29,G29*F29) -> 0
H30: =SUM(H25:H29) -> 0
B31: 구매품 | H31: =IF(F31=0,G31,G31*F31) -> 0
B32: (유공압품외) | H32: =IF(F32=0,G32,G32*F32) -> 0
H33: =IF(F33=0,G33,G33*F33) -> 0
H34: =IF(F34=0,G34,G34*F34) -> 0
H35: =IF(F35=0,G35,G35*F35) -> 0
H36: =IF(F36=0,G36,G36*F36) -> 0
H37: =IF(F37=0,G37,G37*F37) -> 0
H38: =IF(F38=0,G38,G38*F38) -> 0
H39: =IF(F39=0,G39,G39*F39) -> 0
H40: =IF(F40=0,G40,G40*F40) -> 0
H41: =IF(F41=0,G41,G41*F41) -> 0
H42: =IF(F42=0,G42,G42*F42) -> 0
H43: =IF(F43=0,G43,G43*F43) -> 0
H44: =IF(F44=0,G44,G44*F44) -> 0
H45: =IF(F45=0,G45,G45*F45) -> 0
C46: 기타자재 | H46: =IF(F46=0,G46,G46*F46) -> 0
...

Sheet 단위장비5
B1: □ 단위공사명(전기제외): | I1: (첨부)
A2: 구분 | C2: 품 명 | D2: 규격 | E2: 단위 | F2: 수량 | G2: 단가(원) | H2: 금액(원) | I2: 原MAKER
A3: 자 재 비 | B3: 철자재 | H3: =IF(F3=0,G3,G3*F3) -> 0
H4: =IF(F4=0,G4,G4*F4) -> 0
H5: =IF(F5=0,G5,G5*F5) -> 0
H6: =IF(F6=0,G6,G6*F6) -> 0
H7: =IF(F7=0,G7,G7*F7) -> 0
H8: =IF(F8=0,G8,G8*F8) -> 0
H9: =IF(F9=0,G9,G9*F9) -> 0
H10: =IF(F10=0,G10,G10*F10) -> 0
H11: =IF(F11=0,G11,G11*F11) -> 0
H12: =IF(F12=0,G12,G12*F12) -> 0
H13: =IF(F13=0,G13,G13*F13) -> 0
H14: =IF(F14=0,G14,G14*F14) -> 0
H15: =IF(F15=0,G15,G15*F15) -> 0
... H22: =IF(F22=0,G22,G22*F22) -> 0
C23: 기타자재 | H23: =IF(F23=0,G23,G23*F23) -> 0
H24: =SUM(H3:H23) -> 0
B25: 설치/해체/시운전 | H25: =IF(F25=0,G25,G25*F25) -> 0
B26: 공사 관련 자재 | H26: =IF(F26=0,G26,G26*F26) -> 0
H27: =IF(F27=0,G27,G27*F27) -> 0
H28: =IF(F28=0,G28,G28*F28) -> 0
C29: 기타자재 | H29: =IF(F29=0,G29,G29*F29) -> 0
H30: =SUM(H25:H29) -> 0
B31: 구매품 | H31: =IF(F31=0,G31,G31*F31) -> 0
B32: (유공압품외) | H32: =IF(F32=0,G32,G32*F32) -> 0
H33: =IF(F33=0,G33,G33*F33) -> 0
H34: =IF(F34=0,G34,G34*F34) -> 0
H35: =IF(F35=0,G35,G35*F35) -> 0
H36: =IF(F36=0,G36,G36*F36) -> 0
H37: =IF(F37=0,G37,G37*F37) -> 0
H38: =IF(F38=0,G38,G38*F38) -> 0
H39: =IF(F39=0,G39,G39*F39) -> 0
H40: =IF(F40=0,G40,G40*F40) -> 0
H41: =IF(F41=0,G41,G41*F41) -> 0
H42: =IF(F42=0,G42,G42*F42) -> 0
H43: =IF(F43=0,G43,G43*F43) -> 0
H44: =IF(F44=0,G44,G44*F44) -> 0
H45: =IF(F45=0,G45,G45*F45) -> 0
C46: 기타자재 | H46: =IF(F46=0,G46,G46*F46) -> 0
...

Sheet 단위장비6
B1: □ 단위공사명(전기제외): | I1: (첨부)
A2: 구분 | C2: 품 명 | D2: 규격 | E2: 단위 | F2: 수량 | G2: 단가(원) | H2: 금액(원) | I2: 原MAKER
A3: 자 재 비 | B3: 철자재 | H3: =IF(F3=0,G3,G3*F3) -> 0
H4: =IF(F4=0,G4,G4*F4) -> 0
H5: =IF(F5=0,G5,G5*F5) -> 0
H6: =IF(F6=0,G6,G6*F6) -> 0
H7: =IF(F7=0,G7,G7*F7) -> 0
H8: =IF(F8=0,G8,G8*F8) -> 0
H9: =IF(F9=0,G9,G9*F9) -> 0
H10: =IF(F10=0,G10,G10*F10) -> 0
H11: =IF(F11=0,G11,G11*F11) -> 0
H12: =IF(F12=0,G12,G12*F12) -> 0
H13: =IF(F13=0,G13,G13*F13) -> 0
H14: =IF(F14=0,G14,G14*F14) -> 0
H15: =IF(F15=0,G15,G15*F15) -> 0
... H22: =IF(F22=0,G22,G22*F22) -> 0
C23: 기타자재 | H23: =IF(F23=0,G23,G23*F23) -> 0
H24: =SUM(H3:H23) -> 0
B25: 설치/해체/시운전 | H25: =IF(F25=0,G25,G25*F25) -> 0
B26: 공사 관련 자재 | H26: =IF(F26=0,G26,G26*F26) -> 0
H27: =IF(F27=0,G27,G27*F27) -> 0
H28: =IF(F28=0,G28,G28*F28) -> 0
C29: 기타자재 | H29: =IF(F29=0,G29,G29*F29) -> 0
H30: =SUM(H25:H29) -> 0
B31: 구매품 | H31: =IF(F31=0,G31,G31*F31) -> 0
B32: (유공압품외) | H32: =IF(F32=0,G32,G32*F32) -> 0
H33: =IF(F33=0,G33,G33*F33) -> 0
H34: =IF(F34=0,G34,G34*F34) -> 0
H35: =IF(F35=0,G35,G35*F35) -> 0
H36: =IF(F36=0,G36,G36*F36) -> 0
H37: =IF(F37=0,G37,G37*F37) -> 0
H38: =IF(F38=0,G38,G38*F38) -> 0
H39: =IF(F39=0,G39,G39*F39) -> 0
H40: =IF(F40=0,G40,G40*F40) -> 0
H41: =IF(F41=0,G41,G41*F41) -> 0
H42: =IF(F42=0,G42,G42*F42) -> 0
H43: =IF(F43=0,G43,G43*F43) -> 0
H44: =IF(F44=0,G44,G44*F44) -> 0
H45: =IF(F45=0,G45,G45*F45) -> 0
C46: 기타자재 | H46: =IF(F46=0,G46,G46*F46) -> 0
...

Sheet 단위장비7
B1: □ 단위공사명(전기제외): | I1: (첨부)
A2: 구분 | C2: 품 명 | D2: 규격 | E2: 단위 | F2: 수량 | G2: 단가(원) | H2: 금액(원) | I2: 原MAKER
A3: 자 재 비 | B3: 철자재 | H3: =IF(F3=0,G3,G3*F3) -> 0
H4: =IF(F4=0,G4,G4*F4) -> 0
H5: =IF(F5=0,G5,G5*F5) -> 0
H6: =IF(F6=0,G6,G6*F6) -> 0
H7: =IF(F7=0,G7,G7*F7) -> 0
H8: =IF(F8=0,G8,G8*F8) -> 0
H9: =IF(F9=0,G9,G9*F9) -> 0
H10: =IF(F10=0,G10,G10*F10) -> 0
H11: =IF(F11=0,G11,G11*F11) -> 0
H12: =IF(F12=0,G12,G12*F12) -> 0
H13: =IF(F13=0,G13,G13*F13) -> 0
H14: =IF(F14=0,G14,G14*F14) -> 0
H15: =IF(F15=0,G15,G15*F15) -> 0
... H22: =IF(F22=0,G22,G22*F22) -> 0
C23: 기타자재 | H23: =IF(F23=0,G23,G23*F23) -> 0
H24: =SUM(H3:H23) -> 0
B25: 설치/해체/시운전 | H25: =IF(F25=0,G25,G25*F25) -> 0
B26: 공사 관련 자재 | H26: =IF(F26=0,G26,G26*F26) -> 0
H27: =IF(F27=0,G27,G27*F27) -> 0
H28: =IF(F28=0,G28,G28*F28) -> 0
C29: 기타자재 | H29: =IF(F29=0,G29,G29*F29) -> 0
H30: =SUM(H25:H29) -> 0
B31: 구매품 | H31: =IF(F31=0,G31,G31*F31) -> 0
B32: (유공압품외) | H32: =IF(F32=0,G32,G32*F32) -> 0
H33: =IF(F33=0,G33,G33*F33) -> 0
H34: =IF(F34=0,G34,G34*F34) -> 0
H35: =IF(F35=0,G35,G35*F35) -> 0
H36: =IF(F36=0,G36,G36*F36) -> 0
H37: =IF(F37=0,G37,G37*F37) -> 0
H38: =IF(F38=0,G38,G38*F38) -> 0
H39: =IF(F39=0,G39,G39*F39) -> 0
H40: =IF(F40=0,G40,G40*F40) -> 0
H41: =IF(F41=0,G41,G41*F41) -> 0
H42: =IF(F42=0,G42,G42*F42) -> 0
H43: =IF(F43=0,G43,G43*F43) -> 0
H44: =IF(F44=0,G44,G44*F44) -> 0
H45: =IF(F45=0,G45,G45*F45) -> 0
C46: 기타자재 | H46: =IF(F46=0,G46,G46*F46) -> 0
...

Sheet 단위장비8
B1: □ 단위공사명(전기제외): | I1: (첨부)
A2: 구분 | C2: 품 명 | D2: 규격 | E2: 단위 | F2: 수량 | G2: 단가(원) | H2: 금액(원) | I2: 原MAKER
A3: 자 재 비 | B3: 철자재 | H3: =IF(F3=0,G3,G3*F3) -> 0
H4: =IF(F4=0,G4,G4*F4) -> 0
H5: =IF(F5=0,G5,G5*F5) -> 0
H6: =IF(F6=0,G6,G6*F6) -> 0
H7: =IF(F7=0,G7,G7*F7) -> 0
H8: =IF(F8=0,G8,G8*F8) -> 0
H9: =IF(F9=0,G9,G9*F9) -> 0
H10: =IF(F10=0,G10,G10*F10) -> 0
H11: =IF(F11=0,G11,G11*F11) -> 0
H12: =IF(F12=0,G12,G12*F12) -> 0
H13: =IF(F13=0,G13,G13*F13) -> 0
H14: =IF(F14=0,G14,G14*F14) -> 0
H15: =IF(F15=0,G15,G15*F15) -> 0
... H22: =IF(F22=0,G22,G22*F22) -> 0
C23: 기타자재 | H23: =IF(F23=0,G23,G23*F23) -> 0
H24: =SUM(H3:H23) -> 0
B25: 설치/해체/시운전 | H25: =IF(F25=0,G25,G25*F25) -> 0
B26: 공사 관련 자재 | H26: =IF(F26=0,G26,G26*F26) -> 0
H27: =IF(F27=0,G27,G27*F27) -> 0
H28: =IF(F28=0,G28,G28*F28) -> 0
C29: 기타자재 | H29: =IF(F29=0,G29,G29*F29) -> 0
H30: =SUM(H25:H29) -> 0
B31: 구매품 | H31: =IF(F31=0,G31,G31*F31) -> 0
B32: (유공압품외) | H32: =IF(F32=0,G32,G32*F32) -> 0
H33: =IF(F33=0,G33,G33*F33) -> 0
H34: =IF(F34=0,G34,G34*F34) -> 0
H35: =IF(F35=0,G35,G35*F35) -> 0
H36: =IF(F36=0,G36,G36*F36) -> 0
H37: =IF(F37=0,G37,G37*F37) -> 0
H38: =IF(F38=0,G38,G38*F38) -> 0
H39: =IF(F39=0,G39,G39*F39) -> 0
H40: =IF(F40=0,G40,G40*F40) -> 0
H41: =IF(F41=0,G41,G41*F41) -> 0
H42: =IF(F42=0,G42,G42*F42) -> 0
H43: =IF(F43=0,G43,G43*F43) -> 0
H44: =IF(F44=0,G44,G44*F44) -> 0
H45: =IF(F45=0,G45,G45*F45) -> 0
C46: 기타자재 | H46: =IF(F46=0,G46,G46*F46) -> 0
...

Sheet 단위장비9
B1: □ 단위공사명(전기제외): | I1: (첨부)
A2: 구분 | C2: 품 명 | D2: 규격 | E2: 단위 | F2: 수량 | G2: 단가(원) | H2: 금액(원) | I2: 原MAKER
A3: 자 재 비 | B3: 철자재 | H3: =IF(F3=0,G3,G3*F3) -> 0
H4: =IF(F4=0,G4,G4*F4) -> 0
H5: =IF(F5=0,G5,G5*F5) -> 0
H6: =IF(F6=0,G6,G6*F6) -> 0
H7: =IF(F7=0,G7,G7*F7) -> 0
H8: =IF(F8=0,G8,G8*F8) -> 0
H9: =IF(F9=0,G9,G9*F9) -> 0
H10: =IF(F10=0,G10,G10*F10) -> 0
H11: =IF(F11=0,G11,G11*F11) -> 0
H12: =IF(F12=0,G12,G12*F12) -> 0
H13: =IF(F13=0,G13,G13*F13) -> 0
H14: =IF(F14=0,G14,G14*F14) -> 0
H15: =IF(F15=0,G15,G15*F15) -> 0
... H22: =IF(F22=0,G22,G22*F22) -> 0
C23: 기타자재 | H23: =IF(F23=0,G23,G23*F23) -> 0
H24: =SUM(H3:H23) -> 0
B25: 설치/해체/시운전 | H25: =IF(F25=0,G25,G25*F25) -> 0
B26: 공사 관련 자재 | H26: =IF(F26=0,G26,G26*F26) -> 0
H27: =IF(F27=0,G27,G27*F27) -> 0
H28: =IF(F28=0,G28,G28*F28) -> 0
C29: 기타자재 | H29: =IF(F29=0,G29,G29*F29) -> 0
H30: =SUM(H25:H29) -> 0
B31: 구매품 | H31: =IF(F31=0,G31,G31*F31) -> 0
B32: (유공압품외) | H32: =IF(F32=0,G32,G32*F32) -> 0
H33: =IF(F33=0,G33,G33*F33) -> 0
H34: =IF(F34=0,G34,G34*F34) -> 0
H35: =IF(F35=0,G35,G35*F35) -> 0
H36: =IF(F36=0,G36,G36*F36) -> 0
H37: =IF(F37=0,G37,G37*F37) -> 0
H38: =IF(F38=0,G38,G38*F38) -> 0
H39: =IF(F39=0,G39,G39*F39) -> 0
H40: =IF(F40=0,G40,G40*F40) -> 0
H41: =IF(F41=0,G41,G41*F41) -> 0
H42: =IF(F42=0,G42,G42*F42) -> 0
H43: =IF(F43=0,G43,G43*F43) -> 0
H44: =IF(F44=0,G44,G44*F44) -> 0
H45: =IF(F45=0,G45,G45*F45) -> 0
C46: 기타자재 | H46: =IF(F46=0,G46,G46*F46) -> 0
...

Sheet 단위장비10
B1: □ 단위공사명(전기제외): | I1: (첨부)
A2: 구분 | C2: 품 명 | D2: 규격 | E2: 단위 | F2: 수량 | G2: 단가(원) | H2: 금액(원) | I2: 原MAKER
A3: 자 재 비 | B3: 철자재 | H3: =IF(F3=0,G3,G3*F3) -> 0
H4: =IF(F4=0,G4,G4*F4) -> 0
H5: =IF(F5=0,G5,G5*F5) -> 0
H6: =IF(F6=0,G6,G6*F6) -> 0
H7: =IF(F7=0,G7,G7*F7) -> 0
H8: =IF(F8=0,G8,G8*F8) -> 0
H9: =IF(F9=0,G9,G9*F9) -> 0
H10: =IF(F10=0,G10,G10*F10) -> 0
H11: =IF(F11=0,G11,G11*F11) -> 0
H12: =IF(F12=0,G12,G12*F12) -> 0
H13: =IF(F13=0,G13,G13*F13) -> 0
H14: =IF(F14=0,G14,G14*F14) -> 0
H15: =IF(F15=0,G15,G15*F15) -> 0
... H22: =IF(F22=0,G22,G22*F22) -> 0
C23: 기타자재 | H23: =IF(F23=0,G23,G23*F23) -> 0
H24: =SUM(H3:H23) -> 0
B25: 설치/해체/시운전 | H25: =IF(F25=0,G25,G25*F25) -> 0
B26: 공사 관련 자재 | H26: =IF(F26=0,G26,G26*F26) -> 0
H27: =IF(F27=0,G27,G27*F27) -> 0
H28: =IF(F28=0,G28,G28*F28) -> 0
C29: 기타자재 | H29: =IF(F29=0,G29,G29*F29) -> 0
H30: =SUM(H25:H29) -> 0
B31: 구매품 | H31: =IF(F31=0,G31,G31*F31) -> 0
B32: (유공압품외) | H32: =IF(F32=0,G32,G32*F32) -> 0
H33: =IF(F33=0,G33,G33*F33) -> 0
H34: =IF(F34=0,G34,G34*F34) -> 0
H35: =IF(F35=0,G35,G35*F35) -> 0
H36: =IF(F36=0,G36,G36*F36) -> 0
H37: =IF(F37=0,G37,G37*F37) -> 0
H38: =IF(F38=0,G38,G38*F38) -> 0
H39: =IF(F39=0,G39,G39*F39) -> 0
H40: =IF(F40=0,G40,G40*F40) -> 0
H41: =IF(F41=0,G41,G41*F41) -> 0
H42: =IF(F42=0,G42,G42*F42) -> 0
H43: =IF(F43=0,G43,G43*F43) -> 0
H44: =IF(F44=0,G44,G44*F44) -> 0
H45: =IF(F45=0,G45,G45*F45) -> 0
C46: 기타자재 | H46: =IF(F46=0,G46,G46*F46) -> 0
...

Sheet 첨부(견적조건차이내역)
A1: ※ 현대/기아차의 요구사양과 업체견적사양이 다른경우만 작성
D2: (첨부)
A3: 현대/기아차 요구사양대비 견적조건 상이내역
A5: 항 목 | B5: 현대/기아차 요구사양 | C5: 업체 견적기준 사양 | D5: 비 고
