Workbook

Sheet 갑지
B1: (현대/기아차 설비협력업체 견적통일양식)
B2: 見 積 書
B4: 현대위아 貴下 | G4: 주식회사 화인
B5: 견적일자 | D5: 45910 | G5: 대표 : 이상준
B6: 견적번호 | D6: ES25-094M-L | G6: 주소 : 부산 강서구 화전산단6로 60
B7: 납기 | C7: 입하
C8: 최종검수 | G8: 전화: 051-262-1237
B9: 견적유효기간 | D9: 제출후 30 일 | G9: Fax: 051-262-1278
B10: 인도장소 | D10: 부산항 FOB | G10: 견적담당: | H10: FA영업팀 이형수
B11: 지불조건 | D11: 협의사항 | G11: 연 락 처 : | H11: 010-5150-6542
B13: 공사명 | D13: 현대트랜시스 멕시코 TMED-II 모터 후처리라인 증설 PJT件_함침라인(턴키)
B14: 견적금액 | D14: ="一金"&NUMBERSTRING(H34*1000,1)&"원整" -> 一金삼십팔억원整 | G14: =H34*1000 -> 3.8e+09 | I14: )
B16: 번호 | C16: 상세품목내역 | E16: 견적금액 (천원) | I16: 비 고
E17: 기계부문 | F17: 전기부문 | G17: 관리/이윤 (안전관리비포함) | H17: 합 계
B18: 1 | C18: =단위장비1!C1 -> 0 | E18: =IF('단위공사별(집계)'!N7>1,('단위공사별(집계)'!D7+'단위공사별(집계)'!E7+'단위공사별(집계)'!F7+'단위공사별(집계)'!G7+'단위공사별(집계)'!H7+'단위공사별(집계)'!I7)/1000," ") | F18: =SUM('단위공사별(집계)'!K23)/1000 -> 755050 | G18: =IF('단위공사별(집계)'!N7>0,('단위공사별(집계)'!L7+'단위공사별(집계)'!M7)/1000,"") | H18: =IF('단위공사별(집계)'!N7>0,'단위공사별(집계)'!N7/1000,"")
B19: 2 | C19: =단위장비2!C1 -> 0 | E19: =IF('단위공사별(집계)'!N8>1,('단위공사별(집계)'!D8+'단위공사별(집계)'!E8+'단위공사별(집계)'!F8+'단위공사별(집계)'!G8+'단위공사별(집계)'!H8+'단위공사별(집계)'!I8)/1000," ") | G19: =IF('단위공사별(집계)'!N8>0,('단위공사별(집계)'!L8+'단위공사별(집계)'!M8)/1000,"") | H19: =IF('단위공사별(집계)'!N8>0,'단위공사별(집계)'!N8/1000,"")
B20: 1 | C20: =단위장비3!C1 -> 바니쉬 도포기 | E20: =IF('단위공사별(집계)'!N9>1,('단위공사별(집계)'!D9+'단위공사별(집계)'!E9+'단위공사별(집계)'!F9+'단위공사별(집계)'!G9+'단위공사별(집계)'!H9+'단위공사별(집계)'!I9)/1000," ") -> 878513.8 | G20: =IF('단위공사별(집계)'!N9>0,('단위공사별(집계)'!L9+'단위공사별(집계)'!M9)/1000,"") -> 0 | H20: =IF('단위공사별(집계)'!N9>0,'단위공사별(집계)'!N9/1000,"") -> 1129112.4
B21: 2 | C21: =단위장비4!C1 -> 와이어 포밍기 | E21: =IF('단위공사별(집계)'!N10>1,('단위공사별(집계)'!D10+'단위공사별(집계)'!E10+'단위공사별(집계)'!F10+'단위공사별(집계)'!G10+'단위공사별(집계)'!H10+'단위공사별(집계)'!I10)/1000," ") -> 127336.41 | G21: =IF('단위공사별(집계)'!N10>0,('단위공사별(집계)'!L10+'단위공사별(집계)'!M10)/1000,"") -> 0 | H21: =IF('단위공사별(집계)'!N10>0,'단위공사별(집계)'!N10/1000,"") -> 163659.48
B22: 3 | C22: =단위장비5!C1 -> 터미널 조립기 | E22: =IF('단위공사별(집계)'!N11>1,('단위공사별(집계)'!D11+'단위공사별(집계)'!E11+'단위공사별(집계)'!F11+'단위공사별(집계)'!G11+'단위공사별(집계)'!H11+'단위공사별(집계)'!I11)/1000," ") -> 109430.53 | G22: =IF('단위공사별(집계)'!N11>0,('단위공사별(집계)'!L11+'단위공사별(집계)'!M11)/1000,"") -> 0 | H22: =IF('단위공사별(집계)'!N11>0,'단위공사별(집계)'!N11/1000,"") -> 140645.9
B23: 4 | C23: =단위장비6!C1 -> 코킹 & 컷팅기 | E23: =IF('단위공사별(집계)'!N12>1,('단위공사별(집계)'!D12+'단위공사별(집계)'!E12+'단위공사별(집계)'!F12+'단위공사별(집계)'!G12+'단위공사별(집계)'!H12+'단위공사별(집계)'!I12)/1000," ") -> 184174.8 | G23: =IF('단위공사별(집계)'!N12>0,('단위공사별(집계)'!L12+'단위공사별(집계)'!M12)/1000,"") -> 0 | H23: =IF('단위공사별(집계)'!N12>0,'단위공사별(집계)'!N12/1000,"") -> 236711.18
B24: 5 | C24: =단위장비7!C1 -> 퓨징기 | E24: =IF('단위공사별(집계)'!N13>1,('단위공사별(집계)'!D13+'단위공사별(집계)'!E13+'단위공사별(집계)'!F13+'단위공사별(집계)'!G13+'단위공사별(집계)'!H13+'단위공사별(집계)'!I13)/1000," ") -> 470668.93 | G24: =IF('단위공사별(집계)'!N13>0,('단위공사별(집계)'!L13+'단위공사별(집계)'!M13)/1000,"") -> 0 | H24: =IF('단위공사별(집계)'!N13>0,'단위공사별(집계)'!N13/1000,"") -> 604928.58
B25: 8 | C25: =단위장비8!C1 -> 0 | E25: =IF('단위공사별(집계)'!N14>1,('단위공사별(집계)'!D14+'단위공사별(집계)'!E14+'단위공사별(집계)'!F14+'단위공사별(집계)'!G14+'단위공사별(집계)'!H14+'단위공사별(집계)'!I14)/1000," ") | G25: =IF('단위공사별(집계)'!N14>0,('단위공사별(집계)'!L14+'단위공사별(집계)'!M14)/1000,"") | H25: =IF('단위공사별(집계)'!N14>0,'단위공사별(집계)'!N14/1000,"")
B26: 6 | C26: =단위장비9!C1 -> 온도센서 조립 및 에폭시 도포 | E26: =IF('단위공사별(집계)'!N15>1,('단위공사별(집계)'!D15+'단위공사별(집계)'!E15+'단위공사별(집계)'!F15+'단위공사별(집계)'!G15+'단위공사별(집계)'!H15+'단위공사별(집계)'!I15)/1000," ") -> 101551.94 | G26: =IF('단위공사별(집계)'!N15>0,('단위공사별(집계)'!L15+'단위공사별(집계)'!M15)/1000,"") -> 0 | H26: =IF('단위공사별(집계)'!N15>0,'단위공사별(집계)'!N15/1000,"") -> 130519.92
B27: 7 | C27: =단위장비10!C1 -> 에폭시 도포기 | E27: =IF('단위공사별(집계)'!N16>1,('단위공사별(집계)'!D16+'단위공사별(집계)'!E16+'단위공사별(집계)'!F16+'단위공사별(집계)'!G16+'단위공사별(집계)'!H16+'단위공사별(집계)'!I16)/1000," ") -> 341490.78 | G27: =IF('단위공사별(집계)'!N16>0,('단위공사별(집계)'!L16+'단위공사별(집계)'!M16)/1000,"") -> 0 | H27: =IF('단위공사별(집계)'!N16>0,'단위공사별(집계)'!N16/1000,"") -> 438901.99
B28: 8 | C28: =단위장비11!C1 -> 에폭시 경화/냉각 및 온도센서 탈거 | E28: =IF('단위공사별(집계)'!N17>1,('단위공사별(집계)'!D17+'단위공사별(집계)'!E17+'단위공사별(집계)'!F17+'단위공사별(집계)'!G17+'단위공사별(집계)'!H17+'단위공사별(집계)'!I17)/1000," ") -> 433782.81 | G28: =IF('단위공사별(집계)'!N17>0,('단위공사별(집계)'!L17+'단위공사별(집계)'!M17)/1000,"") -> 0 | H28: =IF('단위공사별(집계)'!N17>0,'단위공사별(집계)'!N17/1000,"") -> 557520.59
B29: 12 | C29: =단위장비12!C1 -> 0 | E29: =IF('단위공사별(집계)'!N18>1,('단위공사별(집계)'!D18+'단위공사별(집계)'!E18+'단위공사별(집계)'!F18+'단위공사별(집계)'!G18+'단위공사별(집계)'!H18+'단위공사별(집계)'!I18)/1000," ") | G29: =IF('단위공사별(집계)'!N18>0,('단위공사별(집계)'!L18+'단위공사별(집계)'!M18)/1000,"") | H29: =IF('단위공사별(집계)'!N18>0,'단위공사별(집계)'!N18/1000,"")
B30: 13 | C30: =단위장비13!C1 -> 0 | E30: =IF('단위공사별(집계)'!N19>1,('단위공사별(집계)'!D19+'단위공사별(집계)'!E19+'단위공사별(집계)'!F19+'단위공사별(집계)'!G19+'단위공사별(집계)'!H19+'단위공사별(집계)'!I19)/1000," ") | G30: =IF('단위공사별(집계)'!N19>0,('단위공사별(집계)'!L19+'단위공사별(집계)'!M19)/1000,"") | H30: =IF('단위공사별(집계)'!N19>0,'단위공사별(집계)'!N19/1000,"")
B31: 14 | C31: =단위장비14!C1 -> 0 | E31: =IF('단위공사별(집계)'!N20>1,('단위공사별(집계)'!D20+'단위공사별(집계)'!E20+'단위공사별(집계)'!F20+'단위공사별(집계)'!G20+'단위공사별(집계)'!H20+'단위공사별(집계)'!I20)/1000," ") | G31: =IF('단위공사별(집계)'!N20>0,('단위공사별(집계)'!L20+'단위공사별(집계)'!M20)/1000,"") | H31: =IF('단위공사별(집계)'!N20>0,'단위공사별(집계)'!N20/1000,"")
B32: 15 | C32: =단위장비15!C1 -> 0 | E32: =IF('단위공사별(집계)'!N21>1,('단위공사별(집계)'!D21+'단위공사별(집계)'!E21+'단위공사별(집계)'!F21+'단위공사별(집계)'!G21+'단위공사별(집계)'!H21+'단위공사별(집계)'!I21)/1000," ") | G32: =IF('단위공사별(집계)'!N21>0,('단위공사별(집계)'!L21+'단위공사별(집계)'!M21)/1000,"") | H32: =IF('단위공사별(집계)'!N21>0,'단위공사별(집계)'!N21/1000,"")
B33: 9 | C33: =단위장비16!C1 -> 현지설치 | E33: =IF('단위공사별(집계)'!N22>1,('단위공사별(집계)'!D22+'단위공사별(집계)'!E22+'단위공사별(집계)'!F22+'단위공사별(집계)'!G22+'단위공사별(집계)'!H22+'단위공사별(집계)'!I22)/1000," ") -> 0 | G33: =IF('단위공사별(집계)'!N22>0,('단위공사별(집계)'!L22+'단위공사별(집계)'!M22)/1000,"") -> 0 | H33: =IF('단위공사별(집계)'!N22>0,'단위공사별(집계)'!N22/1000,"") -> 398000
B34: 견적 합계 | E34: =SUM(E18:E33) -> 2646950 | F34: =SUM(F18) -> 755050 | G34: =SUM(G18:G33) -> 0 | H34: =SUM(H18:H33) -> 3800000
F36: 공개입찰가 (견적時 공란)
B38: 특기사항 | C38: 1. VAT 제외 | F38: 외주계획 업체명 (자작時 공란)
C39: 2. 기본 유틸리티공사 제외 | F39: 설계외주
C40: 3. 수출조건 FOB | F40: 제작외주
C41: 4. 현지 설치 도비 견적 제외 | F41: 전기외주
F42: 설치외주
K51: =전기!H63+단위장비1!H73+단위장비2!H63+단위장비3!H64+단위장비5!H68+단위장비4!H75+단위장비6!H63+단위장비7!H54+단위장비8!H65+단위장비9!H65+단위장비10!H68 -> 2.9592672e+09

Sheet 원가항목별(집계)
C2: A. 원가항목별 견적가 종합(상세견적 첨부)
B4: □ 현대/기아 요구사양과 견적조건 일치여부 CHECK: 1.일치함 2.일부상이(상이내역 첨부참조)
B6: 순번 | C6: 원가구분 | F6: 단위 | G6: 수량 | H6: 단가 | I6: 금 액(원) | J6: 비 고
B7: 1 | C7: 기계 부문 | D7: 자재비 | E7: 철자재(SS.SUS등) | F7: kg | G7: =단위장비1!F26+단위장비2!F25+단위장비3!F23+단위장비5!F24+단위장비4!F26+단위장비6!F26+단위장비7!F17+단위장비8!F26+단위장비9!F22+단위장비10!F21+단위장비11!F22+단위장비12!F21+단위장비13!F20+단위장비14!F23+단위장비15!F18+단위장비16!F16 -> 0 | I7: =단위장비1!H20+단위장비2!H19+단위장비3!H17+단위장비5!H18+단위장비4!H20+단위장비6!H20+단위장비7!H11+단위장비8!H20+단위장비9!H16+단위장비10!H15+단위장비11!H16+단위장비12!H15+단위장비13!H14+단위장비14!H17+단위장비15!H12 -> 533400000 | J7: 加工必要資材
E8: 일반구매품 | F8: 식 | G8: 1 | I8: =단위장비1!H51+단위장비2!H41+단위장비3!H45+단위장비5!H46+단위장비4!H53+단위장비6!H41+단위장비7!H32+단위장비8!H43+단위장비9!H43+단위장비10!H46+단위장비11!H45+단위장비12!H44+단위장비13!H37+단위장비14!H41+단위장비15!H28 -> 628550000 | J8: 加工不要資材
E9: 외주제작품 | F9: 식 | G9: 1 | I9: =단위장비1!H59+단위장비2!H49+단위장비3!H50+단위장비5!H54+단위장비4!H61+단위장비6!H49+단위장비7!H40+단위장비8!H51+단위장비9!H51+단위장비10!H54+단위장비11!H53+단위장비12!H52+단위장비13!H45+단위장비14!H49+단위장비15!H34 -> 1200000000 | J9: 旣加工SUB資材
E10: 설치/해체 공사 자재 | F10: 식 | G10: 1 | I10: =단위장비1!H26+단위장비2!H25+단위장비3!H23+단위장비5!H24+단위장비4!H26+단위장비6!H26+단위장비7!H17+단위장비8!H26+단위장비9!H22+단위장비10!H21+단위장비11!H22+단위장비12!H21+단위장비13!H20+단위장비14!H23+단위장비15!H18+단위장비16!H16 -> 0 | J10: 시운전 자재 포함
E11: 소계 | I11: =SUM(I7:I10) -> 2361950000
D12: 노무비 | E12: 기존설비 철거 | F12: M/D | G12: =단위장비1!F61+단위장비2!F51+단위장비3!F52+단위장비5!F56+단위장비4!F63+단위장비6!F51+단위장비7!F42+단위장비8!F53+단위장비9!F53+단위장비10!F56+단위장비11!F55+단위장비12!F54+단위장비13!F47+단위장비14!F51+단위장비15!F36+단위장비16!F36 -> 0 | H12: =IF(단위장비1!G61>0,단위장비1!G61,"") | I12: =단위장비1!H61+단위장비2!H51+단위장비3!H52+단위장비5!H56+단위장비4!H63+단위장비6!H51+단위장비7!H42+단위장비8!H53+단위장비9!H53+단위장비10!H56 -> 0 | J12: 개조공사時
E13: 설계 | F13: M/D | G13: =단위장비1!F62+단위장비2!F52+단위장비3!F53+단위장비5!F57+단위장비4!F64+단위장비6!F52+단위장비7!F43+단위장비8!F54+단위장비9!F54+단위장비10!F57+단위장비11!F56+단위장비12!F55+단위장비13!F48+단위장비14!F52+단위장비15!F37+단위장비16!F37 -> 370 | H13: =IF(단위장비1!G62>0,단위장비1!G62,"") | I13: =단위장비1!H62+단위장비2!H52+단위장비3!H53+단위장비5!H57+단위장비4!H64+단위장비6!H52+단위장비7!H43+단위장비8!H54+단위장비9!H54+단위장비10!H57+단위장비11!H56+단위장비12!H55+단위장비13!H48+단위장비14!H52+단위장비15!H37 -> 66000000
E14: 제작(제관,가공) | F14: M/D | G14: =단위장비1!F63+단위장비2!F53+단위장비3!F54+단위장비5!F58+단위장비4!F65+단위장비6!F53+단위장비7!F44+단위장비8!F55+단위장비9!F55+단위장비10!F58+단위장비11!F57+단위장비12!F56+단위장비13!F49+단위장비14!F53+단위장비15!F38+단위장비16!F38 -> 310 | H14: =IF(단위장비1!G63>0,단위장비1!G63,"") | I14: =단위장비1!H63+단위장비2!H53+단위장비3!H54+단위장비5!H58+단위장비4!H65+단위장비6!H53+단위장비7!H44+단위장비8!H55+단위장비9!H55+단위장비10!H58+단위장비11!H57+단위장비12!H56+단위장비13!H49+단위장비14!H53+단위장비15!H38 -> 66000000
E15: 조립 | F15: M/D | G15: =단위장비1!F64+단위장비2!F54+단위장비3!F55+단위장비5!F59+단위장비4!F66+단위장비6!F54+단위장비7!F45+단위장비8!F56+단위장비9!F56+단위장비10!F59+단위장비11!F58+단위장비12!F57+단위장비13!F50+단위장비14!F54+단위장비15!F39+단위장비16!F39 -> 430 | H15: =IF(단위장비1!G64>0,단위장비1!G64,"") | I15: =단위장비1!H64+단위장비2!H54+단위장비3!H55+단위장비5!H59+단위장비4!H66+단위장비6!H54+단위장비7!H45+단위장비8!H56+단위장비9!H56+단위장비10!H59+단위장비11!H58+단위장비12!H57+단위장비13!H50+단위장비14!H54+단위장비15!H39 -> 93000000 | J15: 정도검사포함
E16: 설치 | F16: M/D | G16: =단위장비1!F65+단위장비2!F55+단위장비3!F56+단위장비5!F60+단위장비4!F67+단위장비6!F55+단위장비7!F46+단위장비8!F57+단위장비9!F57+단위장비10!F60+단위장비11!F59+단위장비12!F58+단위장비13!F51+단위장비14!F55+단위장비15!F40+단위장비16!F40 -> 120 | H16: =IF(단위장비1!G65>0,단위장비1!G65,"") | I16: =단위장비1!H65+단위장비2!H55+단위장비3!H56+단위장비5!H60+단위장비4!H67+단위장비6!H55+단위장비7!H46+단위장비8!H57+단위장비9!H57+단위장비10!H60+단위장비11!H59+단위장비12!H58+단위장비13!H51+단위장비14!H55+단위장비15!H40 -> 0
E17: 시운전 | F17: M/D | H17: =IF(단위장비1!G66>0,단위장비1!G66,"")
E18: 양산대응 | F18: M/D | G18: =단위장비1!F67+단위장비2!F57+단위장비3!F58+단위장비5!F62+단위장비4!F69+단위장비6!F57+단위장비7!F48+단위장비8!F59+단위장비9!F59+단위장비10!F62+단위장비11!F61+단위장비12!F60+단위장비13!F53+단위장비14!F57+단위장비15!F42+단위장비16!F42 -> 0 | H18: =IF(단위장비1!G67>0,단위장비1!G67,"") | I18: =단위장비1!H67+단위장비2!H57+단위장비3!H58+단위장비5!H62+단위장비4!H69+단위장비6!H57+단위장비7!H48+단위장비8!H59+단위장비9!H59+단위장비10!H62+단위장비11!H61+단위장비12!H60+단위장비13!H53+단위장비14!H57+단위장비15!H42 -> 0
E19: 도장 | F19: M/D | G19: =단위장비1!F68+단위장비2!F58+단위장비3!F59+단위장비5!F63+단위장비4!F70+단위장비6!F58+단위장비7!F49+단위장비8!F60+단위장비9!F60+단위장비10!F63 -> 0 | H19: =IF(단위장비1!G68>0,단위장비1!G68,"") | I19: =단위장비1!H68+단위장비2!H58+단위장비3!H59+단위장비5!H63+단위장비4!H70+단위장비6!H58+단위장비7!H49+단위장비8!H60+단위장비9!H60+단위장비10!H63+단위장비11!H62+단위장비12!H61+단위장비13!H54+단위장비14!H58+단위장비15!H43+단위장비16!H44 -> 0
E20: 소계 | I20: =SUM(I12:I19) -> 225000000
D21: 일반관리 및 이윤 | I21: =단위장비1!H71+단위장비1!H72+단위장비2!H61+단위장비2!H62+단위장비3!H62+단위장비3!H63+단위장비5!H66+단위장비5!H67+단위장비4!H73+단위장비4!H74+단위장비6!H61+단위장비6!H62+단위장비7!H52+단위장비7!H53+단위장비8!H63+단위장비8!H64+단위장비9!H63+단위장비9!H64+단위장비10!H66+단위장비10!H67+단위장비11!H65+단위장비11!H66+단위장비12!H64+단위장비12!H65+단위장비13!H57+단위장비13!H58+단위장비14!H61+단위장비14!H62+단위장비15!H46+단위장비15!H47 -> 0
E22: 기계 소계 | I22: =I20+I11+I21 -> 2586950000
B23: 2 | C23: 전기 부문 | D23: 자재비 | E23: 기계/전기자재 | F23: 식 | G23: 1 | I23: =전기!H51-I24 -> 746100000
E24: 설치/해체 공사 자재 | F24: 식 | G24: 1 | I24: =전기!H18 -> 0 | J24: 시운전 자재 포함
D25: 노무비 | E25: 철거(개조시) | F25: M/D | G25: =전기!F52 -> 0 | H25: =IF(전기!G52>0,전기!G52,"") | I25: =전기!H52 -> 0
E26: 설계,프로그램 | F26: M/D | G26: =전기!F53 -> 0 | H26: =IF(전기!G53>0,전기!G53,"") | I26: =전기!H53 -> 0
E27: 제작 | F27: M/D | G27: =전기!F54 -> 0 | H27: =IF(전기!G54>0,전기!G54,"") | I27: =전기!H54 -> 0
E28: 조립 | F28: M/D | G28: =전기!F55 -> 0 | H28: =IF(전기!G55>0,전기!G55,"") | I28: =전기!H55 -> 0
E29: 설치 | F29: M/D | G29: =전기!F56 -> 0 | H29: =IF(전기!G56>0,전기!G56,"") | I29: =전기!H56 -> 0
E30: 시운전 | F30: M/D | G30: =전기!F57 -> 0 | H30: =IF(전기!G57>0,전기!G57,"") | I30: =전기!H57 -> 0
E31: 양산대응 | F31: M/D | G31: =전기!F58 -> 0 | H31: =IF(전기!G58>0,전기!G58,"") | I31: =전기!H58 -> 0
E32: 소계 | I32: =SUM(I25:I31) -> 0
D33: 일반관리 및 이윤 | I33: 8950000
E34: 전기 소계 | I34: =I32+I23+I33+I24 -> 755050000
B35: 3 | C35: 자재비 합계 | I35: =I23+I11+I24 -> 3108050000
C36: 노무비 합계 | I36: =I32+I20 -> 225000000
C37: 중간 합계 | I37: =I36+I35 -> 3333050000
B38: 4 | C38: 포장,운송 | I38: 60000000
B39: 5 | C39: 표준안전관리비 | F39: 설치/철거/수리금액 기준 | J39: 해당없음
B40: 6 | C40: 현지설치 | I40: =SUM(단위장비16!H49) -> 398000000
B41: 7 | C41: 일반관리비 | I41: =전기!H61+단위장비1!H71+단위장비2!H61+단위장비3!H62+단위장비5!H66+단위장비4!H73+단위장비6!H61+단위장비7!H52+단위장비8!H63+단위장비9!H63+단위장비10!H66+단위장비11!H65+단위장비12!H64+단위장비13!H57+단위장비14!H61+단위장비15!H46 -> 0
B42: 8 | C42: 이 윤 | I42: =전기!H62+단위장비1!H72+단위장비2!H62+단위장비3!H63+단위장비5!H67+단위장비4!H74+단위장비6!H62+단위장비7!H53+단위장비8!H64+단위장비9!H64+단위장비10!H67+단위장비11!H66+단위장비12!H65+단위장비13!H58+단위장비14!H62+단위장비15!H47 -> 0
C43: 합 계 | F43: 3~8항 합계 | I43: =I22+I34+I38+I39+I40+I41+I42 -> 3800000000
...

Sheet 단위공사별(집계)
A2: B. 단위장비별 견적가 종합(상세견적 첨부)
N3: 단위:원
I5: 포장/운송 | L5: 표준안전 | M5: 일반관리비
A6: 순번 | B6: 단위장비명 | C6: 수량 | D6: 자재비 | E6: 철거 | F6: 제작 | G6: 설치/시운전 | H6: 양산대응 | I6: 중장비사용 | J6: 기계소계 | K6: 전기소계 | L6: 관리비 | M6: 이윤 | N6: 합 계 | O6: 비 고
A7: =IF(B7>0,1,"") | B7: =단위장비1!C$1 -> 0 | C7: 1식 | D7: =단위장비1!H60 -> 0 | E7: =단위장비1!H61 -> 0 | F7: =단위장비1!H62+단위장비1!H63+단위장비1!H64+단위장비1!H68 -> 0 | G7: =단위장비1!H65+단위장비1!H66 -> 0 | H7: =단위장비1!H67 -> 0 | I7: =IF($B7>0,'원가항목별(집계)'!I$38*$P7/$P$23,0) -> 0 | J7: =SUM(D7:I7) -> 0 | K7: =IF(B7>0,'원가항목별(집계)'!I$34*P7/P$23,0) -> 0 | L7: =IF($B7>0,'원가항목별(집계)'!I$39*$P7/$P$23,0) -> 0 | M7: =단위장비1!H71+단위장비1!H72 -> 0 | N7: =SUM(J7:M7) -> 0 | P7: =D7+E7+F7+G7+H7+M7 -> 0
A8: =IF(B8>0,A7+1,"") | B8: =단위장비2!C$1 -> 0 | C8: 1식 | D8: =단위장비2!H50 -> 0 | E8: =단위장비2!H51 -> 0 | F8: =단위장비2!H52+단위장비2!H53+단위장비2!H54+단위장비2!H58 -> 0 | G8: =단위장비2!H55+단위장비2!H56 -> 0 | H8: =단위장비2!H57 -> 0 | I8: =IF($B8>0,'원가항목별(집계)'!I$38*$P8/$P$23,0) -> 0 | J8: =SUM(D8:I8) -> 0 | K8: =IF(B8>0,'원가항목별(집계)'!I$34*P8/P$23,0) -> 0 | L8: =IF($B8>0,'원가항목별(집계)'!I$39*$P8/$P$23,0) -> 0 | M8: =단위장비2!H61+단위장비2!H62 -> 0 | N8: =SUM(J8:M8) -> 0 | P8: =D8+E8+F8+G8+H8+M8 -> 0
A9: =IF(B9>0,A8+1,"") -> #VALUE! | B9: =단위장비3!C$1 -> 바니쉬 도포기 | C9: 1식 | D9: =단위장비3!H51 -> 804600000 | E9: =단위장비3!H52 -> 0 | F9: =단위장비3!H53+단위장비3!H54+단위장비3!H55+단위장비3!H59 -> 54000000 | G9: =단위장비3!H56+단위장비3!H57 -> 0 | H9: =단위장비3!H58 -> 0 | I9: =IF($B9>0,'원가항목별(집계)'!I$38*$P9/$P$23,0) -> 19913798 | J9: =SUM(D9:I9) -> 8.785138e+08 | K9: =IF(B9>0,'원가항목별(집계)'!I$34*P9/P$23,0) -> 2.5059855e+08 | L9: =IF($B9>0,'원가항목별(집계)'!I$39*$P9/$P$23,0) -> 0 | M9: =단위장비3!H62+단위장비3!H63 -> 0 | N9: =SUM(J9:M9) -> 1.1291124e+09 | P9: =D9+E9+F9+G9+H9+M9 -> 858600000
A10: =IF(B10>0,A9+1,"") -> #VALUE! | B10: =단위장비4!C1 -> 와이어 포밍기 | C10: 1식 | D10: =단위장비4!H62 -> 94450000 | E10: =단위장비4!H63 -> 0 | F10: =단위장비4!H64+단위장비4!H65+단위장비4!H66+단위장비4!H70 -> 30000000 | G10: =단위장비4!H67+단위장비4!H68 -> 0 | H10: =단위장비4!H69 -> 0 | I10: =IF($B10>0,'원가항목별(집계)'!I$38*$P10/$P$23,0) -> 2886410.6 | J10: =SUM(D10:I10) -> 1.2733641e+08 | K10: =IF(B10>0,'원가항목별(집계)'!I$34*P10/P$23,0) -> 36323073 | L10: =IF($B10>0,'원가항목별(집계)'!I$39*$P10/$P$23,0) -> 0 | M10: =단위장비4!H73+단위장비4!H74 -> 0 | N10: =SUM(J10:M10) -> 1.6365948e+08 | P10: =D10+E10+F10+G10+H10+M10 -> 124450000
A11: =IF(B11>0,A10+1,"") -> #VALUE! | B11: =단위장비5!C1 -> 터미널 조립기 | C11: 1식 | D11: =단위장비5!H55 -> 85950000 | E11: =단위장비5!H56 -> 0 | F11: =단위장비5!H57+단위장비5!H58+단위장비5!H59+단위장비5!H63 -> 21000000 | G11: =단위장비5!H60+단위장비5!H61 -> 0 | H11: =단위장비5!H62 -> 0 | I11: =IF($B11>0,'원가항목별(집계)'!I$38*$P11/$P$23,0) -> 2480527.3 | J11: =SUM(D11:I11) -> 1.0943053e+08 | K11: =IF(B11>0,'원가항목별(집계)'!I$34*P11/P$23,0) -> 31215368 | L11: =IF($B11>0,'원가항목별(집계)'!I$39*$P11/$P$23,0) -> 0 | M11: =단위장비5!H66+단위장비5!H67 -> 0 | N11: =SUM(J11:M11) -> 1.406459e+08 | P11: =D11+E11+F11+G11+H11+M11 -> 106950000
A12: =IF(B12>0,A11+1,"") -> #VALUE! | B12: =단위장비6!C$1 -> 코킹 & 컷팅기 | C12: 1식 | D12: =단위장비6!H50 -> 180000000 | E12: =단위장비6!H51 -> 0 | F12: =단위장비6!H52+단위장비6!H53+단위장비6!H54+단위장비6!H58 -> 0 | G12: =단위장비6!H55+단위장비6!H56 -> 0 | H12: =단위장비6!H57 -> 0 | I12: =IF($B12>0,'원가항목별(집계)'!I$38*$P12/$P$23,0) -> 4174800.4 | J12: =SUM(D12:I12) -> 1.841748e+08 | K12: =IF(B12>0,'원가항목별(집계)'!I$34*P12/P$23,0) -> 52536385 | L12: =IF($B12>0,'원가항목별(집계)'!I$39*$P12/$P$23,0) -> 0 | M12: =단위장비6!H61+단위장비6!H62 -> 0 | N12: =SUM(J12:M12) -> 2.3671118e+08 | P12: =D12+E12+F12+G12+H12+M12 -> 180000000
A13: =IF(B13>0,A12+1,"") -> #VALUE! | B13: =단위장비7!C$1 -> 퓨징기 | C13: 1식 | D13: =단위장비7!H41 -> 460000000 | E13: =단위장비7!H42 -> 0 | F13: =단위장비7!H43+단위장비7!H44+단위장비7!H45+단위장비7!H49 -> 0 | G13: =단위장비7!H46+단위장비7!H47 -> 0 | H13: =단위장비7!H48 -> 0 | I13: =IF($B13>0,'원가항목별(집계)'!I$38*$P13/$P$23,0) -> 10668934 | J13: =SUM(D13:I13) -> 4.7066893e+08 | K13: =IF(B13>0,'원가항목별(집계)'!I$34*P13/P$23,0) -> 1.3425965e+08 | L13: =IF($B13>0,'원가항목별(집계)'!I$39*$P13/$P$23,0) -> 0 | M13: =단위장비7!H52+단위장비7!H53 -> 0 | N13: =SUM(J13:M13) -> 6.0492858e+08 | P13: =D13+E13+F13+G13+H13+M13 -> 460000000
A14: =IF(B14>0,A13+1,"") | B14: =단위장비8!C$1 -> 0 | C14: 1식 | D14: =단위장비8!H52 -> 0 | E14: =단위장비8!H53 -> 0 | F14: =단위장비8!H54+단위장비8!H55+단위장비8!H56+단위장비8!H60 -> 0 | G14: =단위장비8!H57+단위장비8!H58 -> 0 | H14: =단위장비8!H59 -> 0 | I14: =IF($B14>0,'원가항목별(집계)'!I$38*$P14/$P$23,0) -> 0 | J14: =SUM(D14:I14) -> 0 | K14: =IF(B14>0,'원가항목별(집계)'!I$34*P14/P$23,0) -> 0 | L14: =IF($B14>0,'원가항목별(집계)'!I$39*$P14/$P$23,0) -> 0 | M14: =단위장비8!H63+단위장비8!H64 -> 0 | N14: =SUM(J14:M14) -> 0 | P14: =D14+E14+F14+G14+H14+M14 -> 0
A15: =IF(B15>0,A14+1,"") -> #VALUE! | B15: =단위장비9!C$1 -> 온도센서 조립 및 에폭시 도포 | C15: 1식 | D15: =단위장비9!H52 -> 69250000 | E15: =단위장비9!H53 -> 0 | F15: =단위장비9!H54+단위장비9!H55+단위장비9!H56+단위장비9!H60 -> 30000000 | G15: =단위장비9!H58+단위장비9!H59 -> 0 | H15: =단위장비9!H60 -> 0 | I15: =IF($B15>0,'원가항목별(집계)'!I$38*$P15/$P$23,0) -> 2301938.6 | J15: =SUM(D15:I15) -> 1.0155194e+08 | K15: =IF(B15>0,'원가항목별(집계)'!I$34*P15/P$23,0) -> 28967979 | L15: =IF($B15>0,'원가항목별(집계)'!I$39*$P15/$P$23,0) -> 0 | M15: =단위장비9!H63+단위장비9!H64 -> 0 | N15: =SUM(J15:M15) -> 1.3051992e+08 | P15: =D15+E15+F15+G15+H15+M15 -> 99250000
A16: =IF(B16>0,A15+1,"") -> #VALUE! | B16: =단위장비10!C$1 -> 에폭시 도포기 | C16: 1식 | D16: =단위장비10!H55 -> 291750000 | E16: =단위장비10!H56 -> 0 | F16: =단위장비10!H57+단위장비10!H58+단위장비10!H59+단위장비10!H63 -> 42000000 | G16: =단위장비10!H62+단위장비10!H63 -> 0 | H16: =단위장비10!H62 -> 0 | I16: =IF($B16>0,'원가항목별(집계)'!I$38*$P16/$P$23,0) -> 7740775.8 | J16: =SUM(D16:I16) -> 3.4149078e+08 | K16: =IF(B16>0,'원가항목별(집계)'!I$34*P16/P$23,0) -> 97411213 | L16: =IF($B16>0,'원가항목별(집계)'!I$39*$P16/$P$23,0) -> 0 | M16: =단위장비10!H66+단위장비10!H67 -> 0 | N16: =SUM(J16:M16) -> 4.3890199e+08 | P16: =D16+E16+F16+G16+H16+M16 -> 333750000
A17: =IF(B17>0,A16+1,"") -> #VALUE! | B17: =단위장비11!C$1 -> 에폭시 경화/냉각 및 온도센서 탈거 | C17: 1식 | D17: =단위장비11!H54 -> 375950000 | E17: =단위장비11!H55 -> 0 | F17: =단위장비11!H56+단위장비11!H57+단위장비11!H58+단위장비11!H62 -> 48000000 | G17: =단위장비11!H59+단위장비11!H60 -> 0 | H17: =단위장비10!H62 -> 0 | I17: =IF($B17>0,'원가항목별(집계)'!I$38*$P17/$P$23,0) -> 9832814.7 | J17: =SUM(D17:I17) -> 4.3378281e+08 | K17: =IF(B17>0,'원가항목별(집계)'!I$34*P17/P$23,0) -> 1.2373778e+08 | L17: =IF($B17>0,'원가항목별(집계)'!I$39*$P17/$P$23,0) -> 0 | M17: =단위장비11!H65+단위장비11!H66 -> 0 | N17: =SUM(J17:M17) -> 5.5752059e+08 | P17: =D17+E17+F17+G17+H17+M17 -> 423950000
A18: =IF(B18>0,A17+1,"") | B18: =단위장비12!C$1 -> 0 | C18: 1식 | D18: =단위장비12!H53 -> 0 | E18: =단위장비12!H54 -> 0 | F18: =단위장비12!H55+단위장비12!H56+단위장비12!H57+단위장비12!H61 -> 0 | G18: =단위장비12!H58+단위장비12!H59 -> 0 | H18: =단위장비11!H61 -> 0 | I18: =IF($B18>0,'원가항목별(집계)'!I$38*$P18/$P$23,0) -> 0 | J18: =SUM(D18:I18) -> 0 | K18: =IF(B18>0,'원가항목별(집계)'!I$34*P18/P$23,0) -> 0 | L18: =IF($B18>0,'원가항목별(집계)'!I$39*$P18/$P$23,0) -> 0 | M18: =단위장비12!H64+단위장비12!H65 -> 0 | N18: =SUM(J18:M18) -> 0 | P18: =D18+E18+F18+G18+H18+M18 -> 0
A19: =IF(B19>0,A18+1,"") | B19: =단위장비13!C$1 -> 0 | C19: 1식 | D19: =단위장비13!H46 -> 0 | E19: =단위장비13!H47 -> 0 | F19: =단위장비13!H48+단위장비13!H49+단위장비13!H50+단위장비13!H54 -> 0 | G19: =단위장비13!H51+단위장비13!H52 -> 0 | H19: =단위장비13!H53 -> 0 | I19: =IF($B19>0,'원가항목별(집계)'!I$38*$P19/$P$23,0) -> 0 | J19: =SUM(D19:I19) -> 0 | K19: =IF(B19>0,'원가항목별(집계)'!I$34*P19/P$23,0) -> 0 | L19: =IF($B19>0,'원가항목별(집계)'!I$39*$P19/$P$23,0) -> 0 | M19: =단위장비13!H57+단위장비13!H58 -> 0 | N19: =SUM(J19:M19) -> 0 | P19: =D19+E19+F19+G19+H19+M19 -> 0
A20: =IF(B20>0,A19+1,"") | B20: =단위장비14!C$1 -> 0 | C20: 1식 | D20: =단위장비14!H50 -> 0 | E20: =단위장비14!H51 -> 0 | F20: =단위장비14!H52+단위장비14!H53+단위장비14!H54+단위장비14!H58 -> 0 | G20: =단위장비14!H55+단위장비14!H56 -> 0 | H20: =단위장비14!H57 -> 0 | I20: =IF($B20>0,'원가항목별(집계)'!I$38*$P20/$P$23,0) -> 0 | J20: =SUM(D20:I20) -> 0 | K20: =IF(B20>0,'원가항목별(집계)'!I$34*P20/P$23,0) -> 0 | L20: =IF($B20>0,'원가항목별(집계)'!I$39*$P20/$P$23,0) -> 0 | M20: =단위장비14!H61+단위장비14!H62 -> 0 | N20: =SUM(J20:M20) -> 0 | P20: =D20+E20+F20+G20+H20+M20 -> 0
A21: =IF(B21>0,A20+1,"") | B21: =단위장비15!C$1 -> 0 | C21: 1식 | D21: =단위장비15!H35 -> 0 | E21: =단위장비15!H36 -> 0 | F21: =단위장비15!H37+단위장비15!H38+단위장비15!H39+단위장비15!H43 -> 0 | G21: =단위장비15!H40+단위장비15!H41 -> 0 | H21: =단위장비15!H42 -> 0 | I21: =IF($B21>0,'원가항목별(집계)'!I$38*$P21/$P$23,0) -> 0 | J21: =SUM(D21:I21) -> 0 | K21: =IF(B21>0,'원가항목별(집계)'!I$34*P21/P$23,0) -> 0 | L21: =IF($B21>0,'원가항목별(집계)'!I$39*$P21/$P$23,0) -> 0 | M21: =단위장비15!H46+단위장비15!H47 -> 0 | N21: =SUM(J21:M21) -> 0 | P21: =D21+E21+F21+G21+H21+M21 -> 0
A22: =IF(B22>0,A21+1,"") -> #VALUE! | B22: =단위장비16!C$1 -> 현지설치 | C22: 1식 | N22: =SUM(단위장비16!H49) -> 398000000 | P22: =D22+E22+F22+G22+H22+M22 -> 0
A23: 합 계 | D23: =SUM(D7:D22) -> 2361950000 | E23: =SUM(E7:E22) -> 0 | F23: =SUM(F7:F22) -> 225000000 | G23: =SUM(G7:G22) -> 0 | H23: =SUM(H7:H22) -> 0 | I23: =SUM(I7:I22) -> 60000000 | J23: =SUM(VALUE(D23),VALUE(F23)) -> 2586950000 | K23: =SUM(K7:K22) -> 7.5505e+08 | L23: =SUM(L7:L22) -> 0 | M23: =SUM(M7:M22) -> 0 | N23: =SUM(N7:N22) -> 3800000000 | P23: =SUM(P7:P22) -> 2586950000
D24: =IF(D23=0,"",D23/$N23) -> 0.62156579 | E24: =IF(E23=0,"",E23/$N23) | F24: =IF(F23=0,"",F23/$N23) -> 0.059210526 | G24: =IF(G23=0,"",G23/$N23) | H24: =IF(H23=0,"",H23/$N23) | I24: =IF(I23=0,"",I23/$N23) -> 0.015789474 | J24: =IF(J23=0,"",J23/$N23) -> 0.68077632 | K24: =IF(K23=0,"",K23/$N23) -> 0.19869737 | L24: =IF(L23=0,"",L23/$N23) | M24: 0 | N24: =IF(N23=0,"",N23/$N23) -> 1
A25: 주) 전기비용은 턴키장비의 공통비용으로서 총 전기비용을 단위장비별 기계금액의 비율에 따라 배분함
N26: =IF('원가항목별(집계)'!I43='단위공사별(집계)'!N23,"","DATA오류입니다!")

Sheet 전기
B1: □ 전기부문: | I1: (첨부)
A2: 구분 | C2: 품 명 | D2: 규격 | E2: 단위 | F2: 수량 | G2: 단가(원) | H2: 금액(원) | I2: 原MAKER
A3: 자 재 비 | B3: 철자재 | C3: Main Pannel | E3: SET | F3: 8 | G3: 8000000 | H3: =IF(F3=0,G3,G3*F3) -> 64000000 | I3: 제작품
C4: Operation Pannel | E4: SET | F4: 36 | G4: 400000 | H4: =IF(F4=0,G4,G4*F4) -> 14400000 | I4: 제작품
C5: Remote box | E5: SET | F5: 8 | G5: 3000000 | H5: =IF(F5=0,G5,G5*F5) -> 24000000 | I5: 제작품
C6: Terminal Box | E6: SET | F6: 8 | G6: 1000000 | H6: =IF(F6=0,G6,G6*F6) -> 8000000 | I6: 제작품
C7: Duct | E7: SET | F7: 1 | G7: 20000000 | H7: =IF(F7=0,G7,G7*F7) -> 20000000 | I7: 제작품
H8: =IF(F8=0,G8,G8*F8) -> 0
H9: =IF(F9=0,G9,G9*F9) -> 0
H10: =IF(F10=0,G10,G10*F10) -> 0
H11: =SUM(H3:H10) -> 130400000
B12: 설치/해체/ | H12: =IF(F12=0,G12,G12*F12) -> 0
B13: 시운전 공사 | H13: =IF(F13=0,G13,G13*F13) -> 0
B14: 자재 | H14: =IF(F14=0,G14,G14*F14) -> 0
H15: =IF(F15=0,G15,G15*F15) -> 0
H16: =IF(F16=0,G16,G16*F16) -> 0
C17: 기타자재 | E17: ST | H17: =IF(F17=0,G17,G17*F17) -> 0
H18: =SUM(H12:H17) -> 0
B19: 전기자재 | C19: PLC | D19: 6ES7517-3AP00-0AB0 | E19: SET | F19: 8 | G19: 5300000 | H19: =IF(F19=0,G19,G19*F19) -> 42400000 | I19: 지멘스
C20: 플래쉬 메모리 | D20: 6ES7954-8LP04-0AA0 | E20: SET | F20: 8 | G20: 600000 | H20: =IF(F20=0,G20,G20*F20) -> 4800000 | I20: 지멘스
C21: ETHERNET 통신 모듈 | D21: 6GK7543-1AX00-0XE0 | E21: SET | F21: 8 | G21: 2200000 | H21: =IF(F21=0,G21,G21*F21) -> 17600000 | I21: 지멘스
C22: 마운팅용 레일 | D22: 6ES7590-1AF30-0AA0 | E22: SET | F22: 8 | G22: 100000 | H22: =IF(F22=0,G22,G22*F22) -> 800000 | I22: 지멘스
C23: 입,출력 카드 | D23: 6ES7521-1BL10-0AA0 | E23: SET | F23: 11 | G23: 700000 | H23: =IF(F23=0,G23,G23*F23) -> 7700000 | I23: 지멘스
C24: HMI | D24: 6AV2124-0MC01-0AX0 | E24: SET | F24: =SUM(F4) -> 36 | G24: 2100000 | H24: =IF(F24=0,G24,G24*F24) -> 75600000 | I24: 지멘스
C25: ET 200SP 인터페이스 모듈 | D25: 6ES7155-6AU02-0BN0 | E25: SET | F25: 20 | G25: 600000 | H25: =IF(F25=0,G25,G25*F25) -> 12000000 | I25: 지멘스
C26: ET 200SP I/O module | D26: 6ES7131-6BH01-0BA0 | E26: SET | F26: 75 | G26: 320000 | H26: =IF(F26=0,G26,G26*F26) -> 24000000 | I26: 지멘스
C27: ET 200SP Analog input module | D27: 6ES7134-6HB00-0CA1 | E27: SET | F27: 8 | G27: 200000 | H27: =IF(F27=0,G27,G27*F27) -> 1600000 | I27: 지멘스
C28: 시리얼 통신 module | D28: 6ES7137-6AA01-0BA0 | E28: SET | F28: 20 | G28: 280000 | H28: =IF(F28=0,G28,G28*F28) -> 5600000 | I28: 지멘스
C29: ET 200SP, BaseUnit | D29: 6ES7193-6BP00-0DA0 | E29: SET | F29: 40 | G29: 50000 | H29: =IF(F29=0,G29,G29*F29) -> 2000000 | I29: 지멘스
C30: Servo motor 0.2kw | D30: 1FL6032-2AF21-1LA1 | E30: SET | F30: 6 | G30: 950000 | H30: =IF(F30=0,G30,G30*F30) -> 5700000 | I30: 지멘스
C31: Servo motor 0.4kw | D31: 1FL6034-2AF21-1LA1 | E31: SET | F31: 11 | G31: 1100000 | H31: =IF(F31=0,G31,G31*F31) -> 12100000 | I31: 지멘스
C32: Servo motor 0.75kw | D32: 1FL6044-1AF61-2LA1 | E32: SET | F32: 26 | G32: 1300000 | H32: =IF(F32=0,G32,G32*F32) -> 33800000 | I32: 지멘스
C33: 에어컨 | D33: AP-ES340 | E33: SET | F33: 8 | G33: 2500000 | H33: =IF(F33=0,G33,G33*F33) -> 20000000 | I33: 에어메이저
H34: =IF(F34=0,G34,G34*F34) -> 0
H35: =IF(F35=0,G35,G35*F35) -> 0
H36: =IF(F36=0,G36,G36*F36) -> 0
H37: =IF(F37=0,G37,G37*F37) -> 0
H38: =IF(F38=0,G38,G38*F38) -> 0
H39: =IF(F39=0,G39,G39*F39) -> 0
H40: =IF(F40=0,G40,G40*F40) -> 0
...

Sheet 단위장비3
B1: □ 단위공사명(전기제외): | C1: 바니쉬 도포기 | I1: (첨부)
A2: 구분 | C2: 품 명 | D2: 규격 | E2: 단위 | F2: 수량 | G2: 단가(원) | H2: 금액(원) | I2: 原MAKER
A3: 자 재 비 | B3: 철자재 | C3: 겐트리 로더 | E3: SET | F3: 1 | G3: 100000000 | H3: =IF(F3=0,G3,G3*F3) -> 100000000 | I3: 제작품
C4: 고주파 예열 FRAME | E4: SET | F4: 1 | G4: 6000000 | H4: =F4*G4 -> 6000000 | I4: 제작품
C5: 고주파 시프트 UNIT | E5: SET | F5: 1 | G5: 3500000 | H5: =IF(F5=0,G5,G5*F5) -> 3500000 | I5: 제작품
C6: 스테이터 시프트 UNIT | E6: SET | F6: 1 | G6: 4000000 | H6: =IF(F6=0,G6,G6*F6) -> 4000000 | I6: 제작품
C7: 바니시 도포 FRAME | E7: SET | F7: 6 | G7: 8000000 | H7: =IF(F7=0,G7,G7*F7) -> 48000000 | I7: 제작품
C8: 스테이터 회전 장치 | E8: SET | F8: 6 | G8: 9000000 | H8: =IF(F8=0,G8,G8*F8) -> 54000000 | I8: 제작품
C9: 바니시 노즐 UNIT | E9: SET | F9: 6 | G9: 1500000 | H9: =IF(F9=0,G9,G9*F9) -> 9000000 | I9: 제작품
C10: 2축 직교로보트 프레임 | E10: SET | F10: 6 | G10: 2500000 | H10: =F10*G10 -> 15000000 | I10: 제작품
C11: 고주파 가열 FRAME | E11: SET | F11: 2 | G11: 6000000 | H11: =F11*G11 -> 12000000 | I11: 제작품
C12: 고주파 시프트 UNIT | E12: SET | F12: 2 | G12: 3000000 | H12: =IF(F12=0,G12,G12*F12) -> 6000000 | I12: 제작품
C13: Duct & Accessary | E13: SET | F13: 1 | G13: 4000000 | H13: =IF(F13=0,G13,G13*F13) -> 4000000 | I13: 제작품
H14: =IF(F14=0,G14,G14*F14) -> 0
H15: =IF(F15=0,G15,G15*F15) -> 0
H16: =IF(F16=0,G16,G16*F16) -> 0
H17: =SUM(H3:H16) -> 261500000
B18: 설치/해체/시운전 | H18: =IF(F18=0,G18,G18*F18) -> 0
B19: 공사 관련 자재 | H19: =IF(F19=0,G19,G19*F19) -> 0
H20: =IF(F20=0,G20,G20*F20) -> 0
H21: =IF(F21=0,G21,G21*F21) -> 0
H22: =IF(F22=0,G22,G22*F22) -> 0
H23: =SUM(H18:H22) -> 0
B24: 구매품 | C24: Air cylinder | D24: CQ2A100-30DMZ | E24: SET | F24: 10 | G24: 150000 | H24: =IF(F24=0,G24,G24*F24) -> 1500000 | I24: SMC
B25: (유공압품외) | C25: Sol Valve | D25: SY7400-5U1 | E25: SET | F25: 10 | G25: 200000 | H25: =IF(F25=0,G25,G25*F25) -> 2000000 | I25: SMC
C26: BALL BUSH | D26: LMK40LUU | E26: SET | F26: 12 | G26: 50000 | H26: =IF(F26=0,G26,G26*F26) -> 600000 | I26: 삼익THK
C27: Sensor & 케이블 | D27: E2E-X2C112-M1TJ-0.3M | E27: SET | F27: 1 | G27: 1000000 | H27: =IF(F27=0,G27,G27*F27) -> 1000000 | I27: OMRON
C28: RFID SYSTEM & Cable | D28: BIS V 시리즈 | E28: SET | F28: 1 | G28: 2500000 | H28: =IF(F28=0,G28,G28*F28) -> 2500000 | I28: 발루프
C29: 도어락 | D29: KEY TYPE | E29: SET | F29: 12 | G29: 300000 | H29: =IF(F29=0,G29,G29*F29) -> 3600000 | I29: 오이너
C30: HMI POST | D30: ST 080101 | E30: SET | F30: 6 | G30: 500000 | H30: =IF(F30=0,G30,G30*F30) -> 3000000 | I30: 코로보
C31: 바코드 스캐너 | D31: DMR-374X | E31: SET | F31: 2 | G31: 2500000 | H31: =IF(F31=0,G31,G31*F31) -> 5000000 | I31: 코그닉스
C32: 2축 직교로보트 | D32: 200/500 | E32: SET | F32: 6 | G32: 2200000 | H32: =IF(F32=0,G32,G32*F32) -> 13200000 | I32: 로보스타
C33: 고주파 가열기 | D33: 50Kw | E33: SET | F33: 3 | G33: 28000000 | H33: =IF(F33=0,G33,G33*F33) -> 84000000 | I33: 오성
C34: 칠러 | D34: 15RT | E34: SET | F34: 1 | G34: 18600000 | H34: =IF(F34=0,G34,G34*F34) -> 18600000 | I34: 쿨트론
C35: 칠러 | D35: 7.5RT | E35: SET | F35: 1 | G35: 12600000 | H35: =IF(F35=0,G35,G35*F35) -> 12600000 | I35: 쿨트론
C36: CO2 자동 소화 장치 | E36: SET | F36: 1 | G36: 2000000 | H36: =IF(F36=0,G36,G36*F36) -> 2000000
C37: DISPENSER | D37: VIPRO | E37: SET | F37: 6 | G37: 12500000 | H37: =IF(F37=0,G37,G37*F37) -> 75000000 | I37: VEX | J37: 모터 제외
C38: 공급탱크 | D38: 2 PUMP | E38: SET | F38: 1 | G38: 37000000 | H38: =IF(F38=0,G38,G38*F38) -> 37000000 | I38: VEX
C39: 핸디스캐너 | D39: LI-4278 | E39: SET | F39: 1 | G39: 1500000 | H39: =IF(F39=0,G39,G39*F39) -> 1500000 | I39: SYMBOL
H45: =SUM(H24:H44) -> 263100000
...

Sheet 단위장비4
B1: □ 단위공사명(전기제외): | C1: 와이어 포밍기 | I1: (첨부)
A2: 구분 | C2: 품 명 | D2: 규격 | E2: 단위 | F2: 수량 | G2: 단가(원) | H2: 금액(원) | I2: 原MAKER
A3: 자 재 비 | B3: 철자재 | C3: TURN LIFT & STOPPER UNIT | E3: SET | F3: 3 | G3: 4000000 | H3: =IF(F3=0,G3,G3*F3) -> 12000000 | I3: 제작품
C4: 포밍 FRAME | E4: SET | F4: 2 | G4: 8000000 | H4: =IF(F4=0,G4,G4*F4) -> 16000000 | I4: 제작품
C5: 비전 FRAME | E5: SET | F5: 1 | G5: 3000000 | H5: =IF(F5=0,G5,G5*F5) -> 3000000 | I5: 제작품
C6: 3축 직교로보트 프레임 | E6: SET | F6: 2 | G6: 5500000 | H6: =F6*G6 -> 11000000 | I6: 제작품
C7: 에어블로잉 | E7: SET | F7: 1 | G7: 5000000 | H7: =IF(F7=0,G7,G7*F7) -> 5000000 | I7: 제작품
C8: 암실 | E8: SET | F8: 1 | G8: 1500000 | H8: =IF(F8=0,G8,G8*F8) -> 1500000 | I8: 제작품
C9: 마스터 지그 | E9: SET | F9: 1 | G9: 1200000 | H9: =IF(F9=0,G9,G9*F9) -> 1200000 | I9: 제작품
C10: Duct & Accessary | E10: SET | F10: 1 | G10: 2000000 | H10: =IF(F10=0,G10,G10*F10) -> 2000000 | I10: 제작품
H11: =IF(F11=0,G11,G11*F11) -> 0
H12: =IF(F12=0,G12,G12*F12) -> 0
H13: =IF(F13=0,G13,G13*F13) -> 0
H14: =IF(F14=0,G14,G14*F14) -> 0
H15: =IF(F15=0,G15,G15*F15) -> 0
H16: =IF(F16=0,G16,G16*F16) -> 0
H17: =IF(F17=0,G17,G17*F17) -> 0
H18: =IF(F18=0,G18,G18*F18) -> 0
H19: =IF(F19=0,G19,G19*F19) -> 0
H20: =SUM(H3:H19) -> 51700000
B21: 설치/해체/시운전 | H21: =IF(F21=0,G21,G21*F21) -> 0
B22: 공사 관련 자재 | H22: =IF(F22=0,G22,G22*F22) -> 0
H23: =IF(F23=0,G23,G23*F23) -> 0
H24: =IF(F24=0,G24,G24*F24) -> 0
H25: =IF(F25=0,G25,G25*F25) -> 0
H26: =SUM(H21:H25) -> 0
B27: 구매품 | C27: POWER INTERFACE | D27: EX260-SPN1 | E27: SET | F27: 1 | G27: 500000 | H27: =IF(F27=0,G27,G27*F27) -> 500000 | I27: SMC
B28: (유공압품외) | C28: MANIFOLD | D28: SS5Y7-10S0-06B-C8-NA | E28: SET | F28: 1 | G28: 300000 | H28: =IF(F28=0,G28,G28*F28) -> 300000 | I28: SMC
C29: SOLENOID VALVE | D29: SY7400-5U1-NA | E29: SET | F29: 5 | G29: 60000 | H29: =IF(F29=0,G29,G29*F29) -> 300000 | I29: SMC
C30: RELIEF VALVE | D30: VHS40-04-D | E30: SET | F30: 1 | G30: 30000 | H30: =IF(F30=0,G30,G30*F30) -> 30000 | I30: SMC
C31: FILTER/REGULATOR | D31: AW40-04D-D | E31: SET | F31: 1 | G31: 100000 | H31: =IF(F31=0,G31,G31*F31) -> 100000 | I31: SMC
C32: SOFT START UP V/V | D32: AV4000-04-5DZ | E32: SET | F32: 1 | G32: 150000 | H32: =IF(F32=0,G32,G32*F32) -> 150000 | I32: SMC
C33: PRESSURE SWITCH | D33: ISE20A-Y-01-J-X505 | E33: SET | F33: 1 | G33: 90000 | H33: =IF(F33=0,G33,G33*F33) -> 90000 | I33: SMC
C34: EXHAUST CLEANER | D34: AMC520-04BD | E34: SET | F34: 1 | G34: 80000 | H34: =IF(F34=0,G34,G34*F34) -> 80000 | I34: SMC
C35: AIR CYLINDER | D35: RS2H80-40BM | E35: SET | F35: 2 | G35: 500000 | H35: =IF(F35=0,G35,G35*F35) -> 1000000 | I35: SMC
C36: AIR CYLINDER | D36: CQ2A80-30DMZ | E36: SET | F36: 2 | G36: 100000 | H36: =IF(F36=0,G36,G36*F36) -> 200000 | I36: SMC
C37: Sensor & 케이블 | D37: E2E-X2C112-M1TJ-0.3M | E37: SET | F37: 3 | G37: 1000000 | H37: =IF(F37=0,G37,G37*F37) -> 3000000 | I37: OMRON
C38: RFID SYSTEM & Cable | D38: BIS V 시리즈 | E38: SET | F38: 3 | G38: 2500000 | H38: =IF(F38=0,G38,G38*F38) -> 7500000 | I38: 발루프
C39: HMI POST | D39: ST 080101 | E39: SET | F39: 5 | G39: 500000 | H39: =IF(F39=0,G39,G39*F39) -> 2500000 | I39: 코로보
C40: 바코드 스캐너 | D40: DMR-374X | E40: SET | F40: 2 | G40: 2500000 | H40: =IF(F40=0,G40,G40*F40) -> 5000000 | I40: 코그닉스
...

Sheet 단위장비5
B1: □ 단위공사명(전기제외): | C1: 터미널 조립기 | I1: (첨부)
A2: 구분 | C2: 품 명 | D2: 규격 | E2: 단위 | F2: 수량 | G2: 단가(원) | H2: 금액(원) | I2: 原MAKER
A3: 자 재 비 | B3: 철자재 | C3: TURN LIFT & STOPPER UNIT | E3: SET | F3: 2 | G3: 4000000 | H3: =IF(F3=0,G3,G3*F3) -> 8000000 | I3: 제작품
C4: 무한궤도 CONVEYOR | E4: SET | F4: 1 | G4: 20000000 | H4: =IF(F4=0,G4,G4*F4) -> 20000000 | I4: 제작품
C5: BASE FRAME | E5: SET | F5: 1 | G5: 5000000 | H5: =IF(F5=0,G5,G5*F5) -> 5000000 | I5: 제작품
C6: 터미널 상승/회전/정렬 | E6: SET | F6: 1 | G6: 10000000 | H6: =F6*G6 -> 10000000 | I6: 제작품
C7: 2축 직교로보트 프레임 | E7: SET | F7: 2 | G7: 4000000 | H7: =F7*G7 -> 8000000 | I7: 제작품
C8: 직교로보트 GRIPPER | E8: SET | F8: 2 | G8: 3500000 | H8: =IF(F8=0,G8,G8*F8) -> 7000000 | I8: 제작품
C9: 마스터 지그 | E9: SET | F9: 1 | G9: 1200000 | H9: =IF(F9=0,G9,G9*F9) -> 1200000 | I9: 제작품
C10: PPC 거치대 | E10: SET | F10: 1 | G10: 500000 | H10: =IF(F10=0,G10,G10*F10) -> 500000 | I10: 제작품
C11: Duct & Accessary | E11: SET | F11: 1 | G11: 1000000 | H11: =IF(F11=0,G11,G11*F11) -> 1000000 | I11: 제작품
H12: =IF(F12=0,G12,G12*F12) -> 0
H13: =IF(F13=0,G13,G13*F13) -> 0
H14: =IF(F14=0,G14,G14*F14) -> 0
H15: =IF(F15=0,G15,G15*F15) -> 0
H16: =IF(F16=0,G16,G16*F16) -> 0
H17: =IF(F17=0,G17,G17*F17) -> 0
H18: =SUM(H3:H17) -> 60700000
B19: 설치/해체/시운전 | H19: =IF(F19=0,G19,G19*F19) -> 0
B20: 공사 관련 자재 | H20: =IF(F20=0,G20,G20*F20) -> 0
H21: =IF(F21=0,G21,G21*F21) -> 0
H22: =IF(F22=0,G22,G22*F22) -> 0
H23: =IF(F23=0,G23,G23*F23) -> 0
H24: =SUM(H19:H23) -> 0
B25: 구매품 | C25: POWER INTERFACE | D25: EX260-SPN1 | E25: SET | F25: 1 | G25: 500000 | H25: =IF(F25=0,G25,G25*F25) -> 500000 | I25: SMC
B26: (유공압품외) | C26: MANIFOLD | D26: SS5Y7-10S0-06B-C8-NA | E26: SET | F26: 1 | G26: 300000 | H26: =IF(F26=0,G26,G26*F26) -> 300000 | I26: SMC
C27: SOLENOID VALVE | D27: SY7400-5U1-NA | E27: SET | F27: 5 | G27: 60000 | H27: =IF(F27=0,G27,G27*F27) -> 300000 | I27: SMC
C28: RELIEF VALVE | D28: VHS40-04-D | E28: SET | F28: 1 | G28: 30000 | H28: =IF(F28=0,G28,G28*F28) -> 30000 | I28: SMC
C29: FILTER/REGULATOR | D29: AW40-04D-D | E29: SET | F29: 1 | G29: 100000 | H29: =IF(F29=0,G29,G29*F29) -> 100000 | I29: SMC
C30: SOFT START UP V/V | D30: AV4000-04-5DZ | E30: SET | F30: 1 | G30: 150000 | H30: =IF(F30=0,G30,G30*F30) -> 150000 | I30: SMC
C31: PRESSURE SWITCH | D31: ISE20A-Y-01-J-X505 | E31: SET | F31: 1 | G31: 90000 | H31: =IF(F31=0,G31,G31*F31) -> 90000 | I31: SMC
C32: EXHAUST CLEANER | D32: AMC520-04BD | E32: SET | F32: 1 | G32: 80000 | H32: =IF(F32=0,G32,G32*F32) -> 80000 | I32: SMC
C33: AIR CYLINDER | D33: RS2H80-40BM | E33: SET | F33: 2 | G33: 500000 | H33: =IF(F33=0,G33,G33*F33) -> 1000000 | I33: SMC
C34: AIR CYLINDER | D34: CQ2A80-30DMZ | E34: SET | F34: 2 | G34: 100000 | H34: =IF(F34=0,G34,G34*F34) -> 200000 | I34: SMC
C35: Sensor & 케이블 | D35: E2E-X2C112-M1TJ-0.3M | E35: SET | F35: 1 | G35: 1000000 | H35: =IF(F35=0,G35,G35*F35) -> 1000000 | I35: OMRON
C36: RFID SYSTEM & Cable | D36: BIS V 시리즈 | E36: SET | F36: 1 | G36: 2500000 | H36: =IF(F36=0,G36,G36*F36) -> 2500000 | I36: 발루프
C37: HMI POST | D37: ST 080101 | E37: SET | F37: 2 | G37: 500000 | H37: =IF(F37=0,G37,G37*F37) -> 1000000 | I37: 코로보
C38: 바코드 스캐너 | D38: DMR-374X | E38: SET | F38: 2 | G38: 2500000 | H38: =IF(F38=0,G38,G38*F38) -> 5000000 | I38: 코그닉스
... C42: 핸디스캐너 | D42: LI-4278 | E42: SET | F42: 1 | G42: 1500000 | H42: =IF(F42=0,G42,G42*F42) -> 1500000 | I42: SYMBOL
H43: =IF(F43=0,G43,G43*F43) -> 0
...

Sheet 단위장비6
B1: □ 단위공사명(전기제외): | C1: 코킹 & 컷팅기 | I1: (첨부)
A2: 구분 | C2: 품 명 | D2: 규격 | E2: 단위 | F2: 수량 | G2: 단가(원) | H2: 금액(원) | I2: 原MAKER
A3: 자 재 비 | B3: 철자재 | H3: =IF(F3=0,G3,G3*F3) -> 0
H4: =IF(F4=0,G4,G4*F4) -> 0
H5: =IF(F5=0,G5,G5*F5) -> 0
H6: =IF(F6=0,G6,G6*F6) -> 0
H7: =IF(F7=0,G7,G7*F7) -> 0
H8: =IF(F8=0,G8,G8*F8) -> 0
H9: =IF(F9=0,G9,G9*F9) -> 0
H10: =IF(F10=0,G10,G10*F10) -> 0
H11: =IF(F11=0,G11,G11*F11) -> 0
H12: =IF(F12=0,G12,G12*F12) -> 0
H13: =IF(F13=0,G13,G13*F13) -> 0
H14: =IF(F14=0,G14,G14*F14) -> 0
H15: =IF(F15=0,G15,G15*F15) -> 0
... H18: =IF(F18=0,G18,G18*F18) -> 0
C19: 기타자재 | H19: =IF(F19=0,G19,G19*F19) -> 0
H20: =SUM(H3:H19) -> 0
B21: 설치/해체/시운전 | H21: =IF(F21=0,G21,G21*F21) -> 0
B22: 공사 관련 자재 | H22: =IF(F22=0,G22,G22*F22) -> 0
H23: =IF(F23=0,G23,G23*F23) -> 0
H24: =IF(F24=0,G24,G24*F24) -> 0
C25: 기타자재 | H25: =IF(F25=0,G25,G25*F25) -> 0
H26: =SUM(H21:H25) -> 0
B27: 구매품 | H27: =IF(F27=0,G27,G27*F27) -> 0
B28: (유공압품외) | H28: =IF(F28=0,G28,G28*F28) -> 0
H29: =IF(F29=0,G29,G29*F29) -> 0
H30: =IF(F30=0,G30,G30*F30) -> 0
H31: =IF(F31=0,G31,G31*F31) -> 0
H32: =IF(F32=0,G32,G32*F32) -> 0
H33: =IF(F33=0,G33,G33*F33) -> 0
H34: =IF(F34=0,G34,G34*F34) -> 0
H35: =IF(F35=0,G35,G35*F35) -> 0
H36: =IF(F36=0,G36,G36*F36) -> 0
H37: =IF(F37=0,G37,G37*F37) -> 0
H38: =IF(F38=0,G38,G38*F38) -> 0
H39: =IF(F39=0,G39,G39*F39) -> 0
H40: =IF(F40=0,G40,G40*F40) -> 0
H41: =SUM(H27:H40) -> 0
B42: 외주제작품 | C42: 코킹 & 컷팅기 기구부 | E42: 식 | F42: 3 | G42: 60000000 | H42: =IF(F42=0,G42,G42*F42) -> 180000000 | I42: 아마다
...

Sheet 단위장비7
B1: □ 단위공사명(전기제외): | C1: 퓨징기 | I1: (첨부)
A2: 구분 | C2: 품 명 | D2: 규격 | E2: 단위 | F2: 수량 | G2: 단가(원) | H2: 금액(원) | I2: 原MAKER
A3: 자 재 비 | B3: 철자재 | H3: =IF(F3=0,G3,G3*F3) -> 0
H4: =IF(F4=0,G4,G4*F4) -> 0
H5: =IF(F5=0,G5,G5*F5) -> 0
H6: =IF(F6=0,G6,G6*F6) -> 0
H7: =IF(F7=0,G7,G7*F7) -> 0
H8: =IF(F8=0,G8,G8*F8) -> 0
H9: =IF(F9=0,G9,G9*F9) -> 0
C10: 기타자재 | E10: ST | H10: =IF(F10=0,G10,G10*F10) -> 0
H11: =SUM(H3:H10) -> 0
B12: 설치/해체/시운전 | H12: =IF(F12=0,G12,G12*F12) -> 0
B13: 공사 관련 자재 | H13: =IF(F13=0,G13,G13*F13) -> 0
H14: =IF(F14=0,G14,G14*F14) -> 0
H15: =IF(F15=0,G15,G15*F15) -> 0
C16: 기타자재 | H16: =IF(F16=0,G16,G16*F16) -> 0
H17: =SUM(H12:H16) -> 0
B18: 구매품 | H18: =IF(F18=0,G18,G18*F18) -> 0
B19: (유공압품외) | H19: =IF(F19=0,G19,G19*F19) -> 0
H20: =IF(F20=0,G20,G20*F20) -> 0
H21: =IF(F21=0,G21,G21*F21) -> 0
H22: =IF(F22=0,G22,G22*F22) -> 0
H23: =IF(F23=0,G23,G23*F23) -> 0
H24: =IF(F24=0,G24,G24*F24) -> 0
H25: =IF(F25=0,G25,G25*F25) -> 0
H26: =IF(F26=0,G26,G26*F26) -> 0
H27: =IF(F27=0,G27,G27*F27) -> 0
H28: =IF(F28=0,G28,G28*F28) -> 0
H29: =IF(F29=0,G29,G29*F29) -> 0
H30: =IF(F30=0,G30,G30*F30) -> 0
H31: =IF(F31=0,G31,G31*F31) -> 0
H32: =SUM(H18:H31) -> 0
B33: 외주제작품 | C33: 퓨징설비 기구부 | E33: 식 | F33: 4 | G33: 115000000 | H33: =IF(F33=0,G33,G33*F33) -> 460000000 | I33: 아마다
H34: =IF(F34=0,G34,G34*F34) -> 0
H35: =IF(F35=0,G35,G35*F35) -> 0
H36: =IF(F36=0,G36,G36*F36) -> 0
H37: =IF(F37=0,G37,G37*F37) -> 0
H38: =IF(F38=0,G38,G38*F38) -> 0
C39: 기타자재 | E39: ST | H39: =IF(F39=0,G39,G39*F39) -> 0
H40: =SUM(H33:H39) -> 460000000
...

Sheet 단위장비10
B1: □ 단위공사명(전기제외): | C1: 에폭시 도포기 | I1: (첨부)
A2: 구분 | C2: 품 명 | D2: 규격 | E2: 단위 | F2: 수량 | G2: 단가(원) | H2: 금액(원) | I2: 原MAKER
A3: 자 재 비 | B3: 철자재 | C3: LIFT & STOPPER UNIT | E3: SET | F3: 4 | G3: 2500000 | H3: =IF(F3=0,G3,G3*F3) -> 10000000 | I3: 제작품
C4: 에폭시 FRAME | E4: SET | F4: 4 | G4: 7000000 | H4: =IF(F4=0,G4,G4*F4) -> 28000000 | I4: 제작품
C5: 비전 FRAME | E5: SET | F5: 1 | G5: 3000000 | H5: =IF(F5=0,G5,G5*F5) -> 3000000 | I5: 제작품
C6: 직교로보트 프레임 | E6: SET | F6: 4 | G6: 4000000 | H6: =F6*G6 -> 16000000 | I6: 제작품
C7: 마스터 지그 및 보관함 | E7: SET | F7: 1 | G7: 2500000 | H7: =IF(F7=0,G7,G7*F7) -> 2500000 | I7: 제작품
C8: PPC 거치대 | E8: SET | F8: 1 | G8: 1000000 | H8: =IF(F8=0,G8,G8*F8) -> 1000000 | I8: 제작품
C9: Duct & Accessary | E9: SET | F9: 1 | G9: 3000000 | H9: =IF(F9=0,G9,G9*F9) -> 3000000 | I9: 제작품
H10: =IF(F10=0,G10,G10*F10) -> 0
H11: =IF(F11=0,G11,G11*F11) -> 0
H12: =IF(F12=0,G12,G12*F12) -> 0
H13: =IF(F13=0,G13,G13*F13) -> 0
C14: 기타자재 | H14: =IF(F14=0,G14,G14*F14) -> 0
H15: =SUM(H3:H14) -> 63500000
B16: 설치/해체/시운전 | H16: =IF(F16=0,G16,G16*F16) -> 0
B17: 공사 관련 자재 | H17: =IF(F17=0,G17,G17*F17) -> 0
H18: =IF(F18=0,G18,G18*F18) -> 0
H19: =IF(F19=0,G19,G19*F19) -> 0
C20: 기타자재 | H20: =IF(F20=0,G20,G20*F20) -> 0
H21: =SUM(H16:H20) -> 0
B22: 구매품 | C22: POWER INTERFACE | D22: EX260-SPN1 | E22: SET | F22: 1 | G22: 500000 | H22: =IF(F22=0,G22,G22*F22) -> 500000 | I22: SMC
B23: (유공압품외) | C23: MANIFOLD | D23: SS5Y7-10S0-06B-C8-NA | E23: SET | F23: 1 | G23: 300000 | H23: =IF(F23=0,G23,G23*F23) -> 300000 | I23: SMC
C24: SOLENOID VALVE | D24: SY7400-5U1-NA | E24: SET | F24: 5 | G24: 60000 | H24: =IF(F24=0,G24,G24*F24) -> 300000 | I24: SMC
C25: RELIEF VALVE | D25: VHS40-04-D | E25: SET | F25: 1 | G25: 30000 | H25: =IF(F25=0,G25,G25*F25) -> 30000 | I25: SMC
C26: FILTER/REGULATOR | D26: AW40-04D-D | E26: SET | F26: 1 | G26: 100000 | H26: =IF(F26=0,G26,G26*F26) -> 100000 | I26: SMC
C27: SOFT START UP V/V | D27: AV4000-04-5DZ | E27: SET | F27: 1 | G27: 150000 | H27: =IF(F27=0,G27,G27*F27) -> 150000 | I27: SMC
C28: PRESSURE SWITCH | D28: ISE20A-Y-01-J-X505 | E28: SET | F28: 1 | G28: 90000 | H28: =IF(F28=0,G28,G28*F28) -> 90000 | I28: SMC
C29: EXHAUST CLEANER | D29: AMC520-04BD | E29: SET | F29: 1 | G29: 80000 | H29: =IF(F29=0,G29,G29*F29) -> 80000 | I29: SMC
C30: AIR CYLINDER | D30: RS2H80-40BM | E30: SET | F30: 2 | G30: 500000 | H30: =IF(F30=0,G30,G30*F30) -> 1000000 | I30: SMC
C31: AIR CYLINDER | D31: CQ2A80-30DMZ | E31: SET | F31: 2 | G31: 100000 | H31: =IF(F31=0,G31,G31*F31) -> 200000 | I31: SMC
C32: 직교로봇 | D32: RS-120/800*400*150 | E32: SET | F32: 4 | G32: 8000000 | H32: =IF(F32=0,G32,G32*F32) -> 32000000 | I32: 로보스타
C33: Sensor & 케이블 | D33: E2E-X2C112-M1TJ-0.3M | E33: SET | F33: 5 | G33: 1000000 | H33: =IF(F33=0,G33,G33*F33) -> 5000000 | I33: OMRON
C34: RFID SYSTEM & Cable | D34: BIS V 시리즈 | E34: SET | F34: 5 | G34: 2500000 | H34: =IF(F34=0,G34,G34*F34) -> 12500000 | I34: 발루프
C35: HMI POST | D35: ST 080101 | E35: SET | F35: 8 | G35: 500000 | H35: =IF(F35=0,G35,G35*F35) -> 4000000 | I35: 코로보
... C38: 전자저울 | D38: CBX-32KH | E38: SET | F38: 4 | G38: 2000000 | H38: =IF(F38=0,G38,G38*F38) -> 8000000 | I38: CAS
C39: DISPENSER | D39: VIPRO | E39: SET | F39: 4 | G39: 12500000 | H39: =IF(F39=0,G39,G39*F39) -> 50000000 | I39: VEX | J39: 모터 제외
C40: 공급탱크 | D40: 2 PUMP | E40: SET | F40: 4 | G40: 22000000 | H40: =IF(F40=0,G40,G40*F40) -> 88000000 | I40: VEX
C41: PPC | D41: UTC320 | E41: SET | F41: 1 | G41: 2500000 | H41: =IF(F41=0,G41,G41*F41) -> 2500000 | I41: 어드밴텍
C42: 핸디스캐너 | D42: LI-4278 | E42: SET | F42: 1 | G42: 1500000 | H42: =IF(F42=0,G42,G42*F42) -> 1500000 | I42: SYMBOL
...

Sheet 단위장비9
B1: □ 단위공사명(전기제외): | C1: 온도센서 조립 및 에폭시 도포 | I1: (첨부)
A2: 구분 | C2: 품 명 | D2: 규격 | E2: 단위 | F2: 수량 | G2: 단가(원) | H2: 금액(원) | I2: 原MAKER
A3: 자 재 비 | B3: 철자재 | C3: LIFT & STOPPER UNIT | E3: SET | F3: 1 | G3: 2500000 | H3: =IF(F3=0,G3,G3*F3) -> 2500000 | I3: 제작품
C4: BASE & FRAME | E4: SET | F4: 1 | G4: 5000000 | H4: =IF(F4=0,G4,G4*F4) -> 5000000 | I4: 제작품
C5: 보관함+이동대차 | E5: SET | F5: 3 | G5: 2000000 | H5: =IF(F5=0,G5,G5*F5) -> 6000000 | I5: 제작품
C6: 온도센서 조립지그 | E6: SET | F6: 500 | G6: 50000 | H6: =IF(F6=0,G6,G6*F6) -> 25000000 | I6: 제작품 | J6: 수량 2배
C7: 수동 에폭시 공급 장치 | E7: SET | F7: 1 | G7: 5000000 | H7: =IF(F7=0,G7,G7*F7) -> 5000000 | I7: 제작품
C8: PPC 거치대 | E8: SET | F8: 1 | G8: 1000000 | H8: =IF(F8=0,G8,G8*F8) -> 1000000 | I8: 제작품
C9: Duct & Accessary | E9: SET | F9: 1 | G9: 1000000 | H9: =IF(F9=0,G9,G9*F9) -> 1000000 | I9: 제작품
H10: =IF(F10=0,G10,G10*F10) -> 0
H11: =IF(F11=0,G11,G11*F11) -> 0
H12: =IF(F12=0,G12,G12*F12) -> 0
H13: =IF(F13=0,G13,G13*F13) -> 0
H14: =IF(F14=0,G14,G14*F14) -> 0
C15: 기타자재 | H15: =IF(F15=0,G15,G15*F15) -> 0
H16: =SUM(H3:H15) -> 45500000
B17: 설치/해체/시운전 | H17: =IF(F17=0,G17,G17*F17) -> 0
B18: 공사 관련 자재 | H18: =IF(F18=0,G18,G18*F18) -> 0
H19: =IF(F19=0,G19,G19*F19) -> 0
H20: =IF(F20=0,G20,G20*F20) -> 0
C21: 기타자재 | H21: =IF(F21=0,G21,G21*F21) -> 0
H22: =SUM(H17:H21) -> 0
B23: 구매품 | C23: AIR COMBINATION | D23: AC40D-06G-A | E23: AY | F23: 1 | G23: 100000 | H23: =G23*F23 -> 100000 | I23: SMC
B24: (유공압품외) | C24: MANIFOLD | D24: SS5Y7-10S0-10B-C8-NA | E24: AY | F24: 1 | G24: 200000 | H24: =G24*F24 -> 200000 | I24: SMC
C25: AIR REGULATOR | D25: AR40-06BG-A | E25: AY | F25: 6 | G25: 60000 | H25: =G25*F25 -> 360000 | I25: SMC
C26: SOLENOID VALVE | D26: SY7200-5U1-NA | E26: AY | F26: 4 | G26: 100000 | H26: =G26*F26 -> 400000 | I26: SMC
C27: SPEED CONTROL V/V | D27: AS3201F-03-08W2 | E27: AY | F27: 8 | G27: 10000 | H27: =G27*F27 -> 80000 | I27: SMC
C28: 블랭킹플래이트 | D28: SY70M-26-2A-NA | E28: AY | F28: 1 | G28: 10000 | H28: =G28*F28 -> 10000 | I28: SMC
C29: 에어호스 | D29: TU0604B-100 | E29: AY | F29: 1 | G29: 100000 | H29: =G29*F29 -> 100000 | I29: SMC
C30: Sensor & 케이블 | D30: E2E-X2C112-M1TJ-0.3M | E30: SET | F30: 1 | G30: 1000000 | H30: =IF(F30=0,G30,G30*F30) -> 1000000 | I30: OMRON
C31: RFID SYSTEM & Cable | D31: BIS V 시리즈 | E31: SET | F31: 1 | G31: 2500000 | H31: =IF(F31=0,G31,G31*F31) -> 2500000 | I31: 발루프
C32: HMI POST | D32: ST 080101 | E32: SET | F32: 2 | G32: 500000 | H32: =IF(F32=0,G32,G32*F32) -> 1000000 | I32: 코로보
C33: 바코드 스캐너 | D33: DMR-374X | E33: SET | F33: 1 | G33: 2500000 | H33: =IF(F33=0,G33,G33*F33) -> 2500000 | I33: 코그닉스
C34: 서지탱크 | D34: 1000L | E34: SET | F34: 1 | G34: 2000000 | H34: =IF(F34=0,G34,G34*F34) -> 2000000 | I34: 부일
C35: 레이저 포인터 | E35: SET | F35: 3 | G35: 100000 | H35: =IF(F35=0,G35,G35*F35) -> 300000 | I35: 인터넷
C36: 수동 에폭시건 | D36: AD3300C | E36: SET | F36: 1 | G36: 9200000 | H36: =IF(F36=0,G36,G36*F36) -> 9200000 | I36: VEX
C37: 핸디스캐너 | D37: LI-4278 | E37: SET | F37: 1 | G37: 1500000 | H37: =IF(F37=0,G37,G37*F37) -> 1500000 | I37: SYMBOL
C38: PPC | D38: UTC320 | E38: SET | F38: 1 | G38: 2500000 | H38: =IF(F38=0,G38,G38*F38) -> 2500000 | I38: 어드밴텍
H42: =IF(F42=0,G42,G42*F42) -> 0
H43: =SUM(H23:H42) -> 23750000
...

Sheet 단위장비11
B1: □ 단위공사명(전기제외): | C1: 에폭시 경화/냉각 및 온도센서 탈거 | I1: (첨부)
A2: 구분 | C2: 품 명 | D2: 규격 | E2: 단위 | F2: 수량 | G2: 단가(원) | H2: 금액(원) | I2: 原MAKER
A3: 자 재 비 | B3: 철자재 | C3: LIFT & STOPPER UNIT | E3: SET | F3: 2 | G3: 2500000 | H3: =IF(F3=0,G3,G3*F3) -> 5000000 | I3: 제작품
C4: 3축 직교로보트 프레임 | E4: SET | F4: 3 | G4: 6000000 | H4: =F4*G4 -> 18000000 | I4: 제작품
C5: 직교로보트 그리퍼 | E5: SET | F5: 3 | G5: 4000000 | H5: =IF(F5=0,G5,G5*F5) -> 12000000 | I5: 제작품
C6: 로보트 베이스 | E6: SET | F6: 1 | G6: 1500000 | H6: =IF(F6=0,G6,G6*F6) -> 1500000 | I6: 제작품
C7: 로보트 그리퍼 | E7: SET | F7: 1 | G7: 3000000 | H7: =F7*G7 -> 3000000 | I7: 제작품
C8: 마그넷 제거 슈드 외 | E8: SET | F8: 1 | G8: 5000000 | H8: =IF(F8=0,G8,G8*F8) -> 5000000 | I8: 제작품
C9: 안전펜스 | E9: SET | F9: 1 | G9: 4000000 | H9: =IF(F9=0,G9,G9*F9) -> 4000000 | I9: 제작품
C10: Duct & Accessary | E10: SET | F10: 1 | G10: 2000000 | H10: =IF(F10=0,G10,G10*F10) -> 2000000 | I10: 제작품
H11: =IF(F11=0,G11,G11*F11) -> 0
H12: =IF(F12=0,G12,G12*F12) -> 0
H13: =IF(F13=0,G13,G13*F13) -> 0
H14: =IF(F14=0,G14,G14*F14) -> 0
H15: =IF(F15=0,G15,G15*F15) -> 0
H16: =SUM(H3:H15) -> 50500000
B17: 설치/해체/시운전 | H17: =IF(F17=0,G17,G17*F17) -> 0
B18: 공사 관련 자재 | H18: =IF(F18=0,G18,G18*F18) -> 0
H19: =IF(F19=0,G19,G19*F19) -> 0
H20: =IF(F20=0,G20,G20*F20) -> 0
H21: =IF(F21=0,G21,G21*F21) -> 0
H22: =SUM(H17:H21) -> 0
B23: 구매품 | C23: POWER INTERFACE | D23: EX260-SPN1 | E23: SET | F23: 1 | G23: 500000 | H23: =IF(F23=0,G23,G23*F23) -> 500000 | I23: SMC
B24: (유공압품외) | C24: MANIFOLD | D24: SS5Y7-10S0-06B-C8-NA | E24: SET | F24: 1 | G24: 300000 | H24: =IF(F24=0,G24,G24*F24) -> 300000 | I24: SMC
C25: SOLENOID VALVE | D25: SY7400-5U1-NA | E25: SET | F25: 5 | G25: 60000 | H25: =IF(F25=0,G25,G25*F25) -> 300000 | I25: SMC
C26: RELIEF VALVE | D26: VHS40-04-D | E26: SET | F26: 1 | G26: 30000 | H26: =IF(F26=0,G26,G26*F26) -> 30000 | I26: SMC
C27: FILTER/REGULATOR | D27: AW40-04D-D | E27: SET | F27: 1 | G27: 100000 | H27: =IF(F27=0,G27,G27*F27) -> 100000 | I27: SMC
C28: SOFT START UP V/V | D28: AV4000-04-5DZ | E28: SET | F28: 1 | G28: 150000 | H28: =IF(F28=0,G28,G28*F28) -> 150000 | I28: SMC
C29: PRESSURE SWITCH | D29: ISE20A-Y-01-J-X505 | E29: SET | F29: 1 | G29: 90000 | H29: =IF(F29=0,G29,G29*F29) -> 90000 | I29: SMC
C30: EXHAUST CLEANER | D30: AMC520-04BD | E30: SET | F30: 1 | G30: 80000 | H30: =IF(F30=0,G30,G30*F30) -> 80000 | I30: SMC
C31: AIR CYLINDER | D31: RS2H80-40BM | E31: SET | F31: 2 | G31: 500000 | H31: =IF(F31=0,G31,G31*F31) -> 1000000 | I31: SMC
C32: AIR CYLINDER | D32: CQ2A80-30DMZ | E32: SET | F32: 2 | G32: 100000 | H32: =IF(F32=0,G32,G32*F32) -> 200000 | I32: SMC
C33: Sensor & 케이블 | D33: E2E-X2C112-M1TJ-0.3M | E33: SET | F33: 1 | G33: 1000000 | H33: =IF(F33=0,G33,G33*F33) -> 1000000 | I33: OMRON
C34: RFID SYSTEM & Cable | D34: BIS V 시리즈 | E34: SET | F34: 1 | G34: 2500000 | H34: =IF(F34=0,G34,G34*F34) -> 2500000 | I34: 발루프
C35: HMI POST | D35: ST 080101 | E35: SET | F35: 3 | G35: 500000 | H35: =IF(F35=0,G35,G35*F35) -> 1500000 | I35: 코로보
C36: 바코드 스캐너 | D36: DMR-374X | E36: SET | F36: 2 | G36: 2500000 | H36: =IF(F36=0,G36,G36*F36) -> 5000000 | I36: 코그닉스
C37: 3축 직교로보트 | D37: 2000/800/700 | E37: SET | F37: 3 | G37: 8000000 | H37: =IF(F37=0,G37,G37*F37) -> 24000000 | I37: 로보스타
C38: CO2 자동 소화 장치 | E38: SET | F38: 1 | G38: 2000000 | H38: =IF(F38=0,G38,G38*F38) -> 2000000
C39: 에어컨 | D39: HSC-5000A | E39: SET | F39: 1 | G39: 6700000 | H39: =IF(F39=0,G39,G39*F39) -> 6700000 | I39: 에어렉스
H44: =IF(F44=0,G44,G44*F44) -> 0
...

Sheet 단위장비16
B1: □ 단위공사명(전기제외): | C1: 현지설치 | I1: (첨부)
A2: 구분 | C2: 품 명 | D2: 규격 | E2: 단위 | F2: 수량 | G2: 단가(원) | H2: 금액(원) | I2: 原MAKER
A3: 자 재 비 | B3: 철자재 | H3: =IF(F3=0,G3,G3*F3) -> 0
H4: =IF(F4=0,G4,G4*F4) -> 0
H5: =F5*G5 -> 0
H6: =IF(F6=0,G6,G6*F6) -> 0
H7: =IF(F7=0,G7,G7*F7) -> 0
H8: =IF(F8=0,G8,G8*F8) -> 0
H9: =IF(F9=0,G9,G9*F9) -> 0
H10: =SUM(H3:H9) -> 0
B11: 설치/해체/시운전 | H11: =IF(F11=0,G11,G11*F11) -> 0
B12: 공사 관련 자재 | H12: =IF(F12=0,G12,G12*F12) -> 0
H13: =IF(F13=0,G13,G13*F13) -> 0
H14: =IF(F14=0,G14,G14*F14) -> 0
H15: =IF(F15=0,G15,G15*F15) -> 0
H16: =SUM(H11:H15) -> 0
B17: 구매품 | H17: =IF(F17=0,G17,G17*F17) -> 0
B18: (유공압품외) | H18: =IF(F18=0,G18,G18*F18) -> 0
H19: =IF(F19=0,G19,G19*F19) -> 0
H20: =IF(F20=0,G20,G20*F20) -> 0
H21: =IF(F21=0,G21,G21*F21) -> 0
H22: =IF(F22=0,G22,G22*F22) -> 0
H23: =IF(F23=0,G23,G23*F23) -> 0
H24: =IF(F24=0,G24,G24*F24) -> 0
H25: =IF(F25=0,G25,G25*F25) -> 0
H26: =SUM(H17:H25) -> 0
B27: 경비 | C27: 왕복항공료 | E27: SET | F27: 20 | G27: 2500000 | H27: =IF(F27=0,G27,G27*F27) -> 50000000
C28: 해외출장비 | E28: SET | F28: =SUM(F37:F42) -> 480 | G28: 300000 | H28: =IF(F28=0,G28,G28*F28) -> 144000000
H29: =IF(F29=0,G29,G29*F29) -> 0
H30: =IF(F30=0,G30,G30*F30) -> 0
H31: =IF(F31=0,G31,G31*F31) -> 0
H32: =IF(F32=0,G32,G32*F32) -> 0
H33: =IF(F33=0,G33,G33*F33) -> 0
H34: =SUM(H27:H33) -> 194000000
B35: 자재비 소계 | H35: =SUM(H34,H26,H16,H10) -> 194000000
A36: 노 무 비 | B36: 현지설치공사 | H36: =F36*G36 -> 0
B37: 기계설치 | E37: M/D | F37: 150 | G37: 400000 | H37: =F37*G37 -> 60000000
B38: 제어설치(배선) | E38: M/D | F38: 90 | G38: 400000 | H38: =F38*G38 -> 36000000
B39: 기계 시운전 | E39: M/D | F39: 120 | G39: 400000 | H39: =F39*G39 -> 48000000
B40: 제어 시운전 | E40: M/D | F40: 120 | G40: 500000 | H40: =F40*G40 -> 60000000
...

Sheet 단위장비1
B1: □ 단위공사명(전기제외): | I1: (첨부)
A2: 구분 | C2: 품 명 | D2: 규격 | E2: 단위 | F2: 수량 | G2: 단가(원) | H2: 금액(원) | I2: 原MAKER
A3: 자 재 비 | B3: 철자재 | H3: =IF(F3=0,G3,G3*F3) -> 0
H4: =F4*G4 -> 0
H5: =F5*G5 -> 0
H6: =F6*G6 -> 0
H7: =F7*G7 -> 0
H8: =F8*G8 -> 0
H9: =F9*G9 -> 0
H10: =IF(F10=0,G10,G10*F10) -> 0
H11: =F11*G11 -> 0
H12: =F12*G12 -> 0
H13: =F13*G13 -> 0
H14: =F14*G14 -> 0
H15: =F15*G15 -> 0
H16: =IF(F16=0,G16,G16*F16) -> 0
H17: =F17*G17 -> 0
H18: =F18*G18 -> 0
H19: =IF(F19=0,G19,G19*F19) -> 0
H20: =SUM(H3:H19) -> 0
B21: 설치/해체/시운전 | H21: =IF(F21=0,G21,G21*F21) -> 0
B22: 공사 관련 자재 | H22: =IF(F22=0,G22,G22*F22) -> 0
H23: =IF(F23=0,G23,G23*F23) -> 0
H24: =IF(F24=0,G24,G24*F24) -> 0
H25: =IF(F25=0,G25,G25*F25) -> 0
H26: =SUM(H21:H25) -> 0
B27: 구매품 | H27: =IF(F27=0,G27,G27*F27) -> 0
B28: (유공압품외) | H28: =IF(F28=0,G28,G28*F28) -> 0
H29: =IF(F29=0,G29,G29*F29) -> 0
H30: =IF(F30=0,G30,G30*F30) -> 0
H31: =IF(F31=0,G31,G31*F31) -> 0
H32: =IF(F32=0,G32,G32*F32) -> 0
H33: =IF(F33=0,G33,G33*F33) -> 0
H34: =IF(F34=0,G34,G34*F34) -> 0
H35: =IF(F35=0,G35,G35*F35) -> 0
H36: =IF(F36=0,G36,G36*F36) -> 0
H37: =IF(F37=0,G37,G37*F37) -> 0
H38: =IF(F38=0,G38,G38*F38) -> 0
H39: =IF(F39=0,G39,G39*F39) -> 0
H40: =IF(F40=0,G40,G40*F40) -> 0
...

Sheet 단위장비2
B1: □ 단위공사명(전기제외): | I1: (첨부)
A2: 구분 | C2: 품 명 | D2: 규격 | E2: 단위 | F2: 수량 | G2: 단가(원) | H2: 금액(원) | I2: 原MAKER
A3: 자 재 비 | B3: 철자재 | H3: =IF(F3=0,G3,G3*F3) -> 0
H4: =F4*G4 -> 0
H5: =F5*G5 -> 0
H6: =F6*G6 -> 0
H7: =F7*G7 -> 0
H8: =IF(F8=0,G8,G8*F8) -> 0
H9: =IF(F9=0,G9,G9*F9) -> 0
H10: =IF(F10=0,G10,G10*F10) -> 0
H11: =IF(F11=0,G11,G11*F11) -> 0
H12: =IF(F12=0,G12,G12*F12) -> 0
H13: =IF(F13=0,G13,G13*F13) -> 0
H14: =IF(F14=0,G14,G14*F14) -> 0
H15: =IF(F15=0,G15,G15*F15) -> 0
H16: =IF(F16=0,G16,G16*F16) -> 0
H17: =IF(F17=0,G17,G17*F17) -> 0
H18: =IF(F18=0,G18,G18*F18) -> 0
H19: =SUM(H3:H18) -> 0
B20: 설치/해체/시운전 | H20: =IF(F20=0,G20,G20*F20) -> 0
B21: 공사 관련 자재 | H21: =IF(F21=0,G21,G21*F21) -> 0
H22: =IF(F22=0,G22,G22*F22) -> 0
H23: =IF(F23=0,G23,G23*F23) -> 0
H24: =IF(F24=0,G24,G24*F24) -> 0
H25: =SUM(H20:H24) -> 0
B26: 구매품 | H26: =IF(F26=0,G26,G26*F26) -> 0
B27: (유공압품외) | H27: =IF(F27=0,G27,G27*F27) -> 0
H28: =IF(F28=0,G28,G28*F28) -> 0
H29: =IF(F29=0,G29,G29*F29) -> 0
H30: =IF(F30=0,G30,G30*F30) -> 0
H31: =IF(F31=0,G31,G31*F31) -> 0
H32: =IF(F32=0,G32,G32*F32) -> 0
H33: =IF(F33=0,G33,G33*F33) -> 0
H34: =IF(F34=0,G34,G34*F34) -> 0
H35: =IF(F35=0,G35,G35*F35) -> 0
H36: =IF(F36=0,G36,G36*F36) -> 0
H37: =IF(F37=0,G37,G37*F37) -> 0
H38: =IF(F38=0,G38,G38*F38) -> 0
H39: =IF(F39=0,G39,G39*F39) -> 0
H40: =IF(F40=0,G40,G40*F40) -> 0
...

Sheet 단위장비8
B1: □ 단위공사명(전기제외): | I1: (첨부)
A2: 구분 | C2: 품 명 | D2: 규격 | E2: 단위 | F2: 수량 | G2: 단가(원) | H2: 금액(원) | I2: 原MAKER
A3: 자 재 비 | B3: 철자재 | H3: =IF(F3=0,G3,G3*F3) -> 0
H4: =IF(F4=0,G4,G4*F4) -> 0
H5: =IF(F5=0,G5,G5*F5) -> 0
H6: =IF(F6=0,G6,G6*F6) -> 0
H7: =IF(F7=0,G7,G7*F7) -> 0
H8: =IF(F8=0,G8,G8*F8) -> 0
H9: =IF(F9=0,G9,G9*F9) -> 0
H10: =IF(F10=0,G10,G10*F10) -> 0
H11: =IF(F11=0,G11,G11*F11) -> 0
H12: =IF(F12=0,G12,G12*F12) -> 0
H13: =IF(F13=0,G13,G13*F13) -> 0
H14: =IF(F14=0,G14,G14*F14) -> 0
H15: =IF(F15=0,G15,G15*F15) -> 0
... H18: =IF(F18=0,G18,G18*F18) -> 0
C19: 기타자재 | H19: =IF(F19=0,G19,G19*F19) -> 0
H20: =SUM(H3:H19) -> 0
B21: 설치/해체/시운전 | H21: =IF(F21=0,G21,G21*F21) -> 0
B22: 공사 관련 자재 | H22: =IF(F22=0,G22,G22*F22) -> 0
H23: =IF(F23=0,G23,G23*F23) -> 0
H24: =IF(F24=0,G24,G24*F24) -> 0
C25: 기타자재 | H25: =IF(F25=0,G25,G25*F25) -> 0
H26: =SUM(H21:H25) -> 0
B27: 구매품 | H27: =IF(F27=0,G27,G27*F27) -> 0
B28: (유공압품외) | H28: =IF(F28=0,G28,G28*F28) -> 0
H29: =IF(F29=0,G29,G29*F29) -> 0
H30: =IF(F30=0,G30,G30*F30) -> 0
H31: =IF(F31=0,G31,G31*F31) -> 0
H32: =IF(F32=0,G32,G32*F32) -> 0
H33: =IF(F33=0,G33,G33*F33) -> 0
H34: =IF(F34=0,G34,G34*F34) -> 0
H35: =IF(F35=0,G35,G35*F35) -> 0
H36: =IF(F36=0,G36,G36*F36) -> 0
H37: =IF(F37=0,G37,G37*F37) -> 0
H38: =IF(F38=0,G38,G38*F38) -> 0
H39: =IF(F39=0,G39,G39*F39) -> 0
H40: =IF(F40=0,G40,G40*F40) -> 0
H41: =IF(F41=0,G41,G41*F41) -> 0
C42: 기타자재 | H42: =IF(F42=0,G42,G42*F42) -> 0
...

Sheet 단위장비12
B1: □ 단위공사명(전기제외): | I1: (첨부)
A2: 구분 | C2: 품 명 | D2: 규격 | E2: 단위 | F2: 수량 | G2: 단가(원) | H2: 금액(원) | I2: 原MAKER
A3: 자 재 비 | B3: 철자재 | H3: =IF(F3=0,G3,G3*F3) -> 0
H4: =IF(F4=0,G4,G4*F4) -> 0
H5: =IF(F5=0,G5,G5*F5) -> 0
H6: =IF(F6=0,G6,G6*F6) -> 0
H7: =IF(F7=0,G7,G7*F7) -> 0
H8: =IF(F8=0,G8,G8*F8) -> 0
H9: =IF(F9=0,G9,G9*F9) -> 0
H10: =IF(F10=0,G10,G10*F10) -> 0
H11: =IF(F11=0,G11,G11*F11) -> 0
H12: =IF(F12=0,G12,G12*F12) -> 0
H13: =IF(F13=0,G13,G13*F13) -> 0
H14: =IF(F14=0,G14,G14*F14) -> 0
H15: =SUM(H3:H14) -> 0
B16: 설치/해체/시운전 | H16: =IF(F16=0,G16,G16*F16) -> 0
B17: 공사 관련 자재 | H17: =IF(F17=0,G17,G17*F17) -> 0
H18: =IF(F18=0,G18,G18*F18) -> 0
H19: =IF(F19=0,G19,G19*F19) -> 0
H20: =IF(F20=0,G20,G20*F20) -> 0
H21: =SUM(H16:H20) -> 0
B22: 구매품 | H22: =IF(F22=0,G22,G22*F22) -> 0
B23: (유공압품외) | H23: =IF(F23=0,G23,G23*F23) -> 0
H24: =IF(F24=0,G24,G24*F24) -> 0
H25: =IF(F25=0,G25,G25*F25) -> 0
H26: =IF(F26=0,G26,G26*F26) -> 0
H27: =IF(F27=0,G27,G27*F27) -> 0
H28: =IF(F28=0,G28,G28*F28) -> 0
H29: =IF(F29=0,G29,G29*F29) -> 0
H30: =IF(F30=0,G30,G30*F30) -> 0
H31: =IF(F31=0,G31,G31*F31) -> 0
H32: =IF(F32=0,G32,G32*F32) -> 0
H33: =IF(F33=0,G33,G33*F33) -> 0
H34: =IF(F34=0,G34,G34*F34) -> 0
H35: =IF(F35=0,G35,G35*F35) -> 0
... H43: =IF(F43=0,G43,G43*F43) -> 0
H44: =SUM(H22:H43) -> 0
B45: 외주제작품 | H45: =IF(F45=0,G45,G45*F45) -> 0
H46: =IF(F46=0,G46,G46*F46) -> 0
H49: =IF(F49=0,G49,G49*F49) -> 0
...

Sheet 단위장비13
B1: □ 단위공사명(전기제외): | I1: (첨부)
A2: 구분 | C2: 품 명 | D2: 규격 | E2: 단위 | F2: 수량 | G2: 단가(원) | H2: 금액(원) | I2: 原MAKER
A3: 자 재 비 | B3: 철자재 | H3: =IF(F3=0,G3,G3*F3) -> 0
H4: =IF(F4=0,G4,G4*F4) -> 0
H5: =IF(F5=0,G5,G5*F5) -> 0
H6: =IF(F6=0,G6,G6*F6) -> 0
H7: =IF(F7=0,G7,G7*F7) -> 0
H8: =IF(F8=0,G8,G8*F8) -> 0
H9: =IF(F9=0,G9,G9*F9) -> 0
H10: =IF(F10=0,G10,G10*F10) -> 0
H11: =IF(F11=0,G11,G11*F11) -> 0
H12: =IF(F12=0,G12,G12*F12) -> 0
H13: =IF(F13=0,G13,G13*F13) -> 0
H14: =SUM(H3:H13) -> 0
B15: 설치/해체/시운전 | H15: =IF(F15=0,G15,G15*F15) -> 0
B16: 공사 관련 자재 | H16: =IF(F16=0,G16,G16*F16) -> 0
H17: =IF(F17=0,G17,G17*F17) -> 0
H18: =IF(F18=0,G18,G18*F18) -> 0
H19: =IF(F19=0,G19,G19*F19) -> 0
H20: =SUM(H15:H19) -> 0
B21: 구매품 | H21: =IF(F21=0,G21,G21*F21) -> 0
B22: (유공압품외) | H22: =IF(F22=0,G22,G22*F22) -> 0
H23: =IF(F23=0,G23,G23*F23) -> 0
H24: =IF(F24=0,G24,G24*F24) -> 0
H25: =IF(F25=0,G25,G25*F25) -> 0
H26: =IF(F26=0,G26,G26*F26) -> 0
H27: =IF(F27=0,G27,G27*F27) -> 0
H28: =IF(F28=0,G28,G28*F28) -> 0
H29: =IF(F29=0,G29,G29*F29) -> 0
H30: =IF(F30=0,G30,G30*F30) -> 0
H31: =IF(F31=0,G31,G31*F31) -> 0
H32: =IF(F32=0,G32,G32*F32) -> 0
H33: =IF(F33=0,G33,G33*F33) -> 0
H34: =IF(F34=0,G34,G34*F34) -> 0
... H36: =IF(F36=0,G36,G36*F36) -> 0
H37: =SUM(H21:H36) -> 0
B38: 외주제작품 | H38: =IF(F38=0,G38,G38*F38) -> 0
H39: =IF(F39=0,G39,G39*F39) -> 0
H40: =IF(F40=0,G40,G40*F40) -> 0
H41: =IF(F41=0,G41,G41*F41) -> 0
...

Sheet 단위장비14
B1: □ 단위공사명(전기제외): | I1: (첨부)
A2: 구분 | C2: 품 명 | D2: 규격 | E2: 단위 | F2: 수량 | G2: 단가(원) | H2: 금액(원) | I2: 原MAKER
A3: 자 재 비 | B3: 철자재 | H3: =IF(F3=0,G3,G3*F3) -> 0
H4: =IF(F4=0,G4,G4*F4) -> 0
H5: =IF(F5=0,G5,G5*F5) -> 0
H6: =IF(F6=0,G6,G6*F6) -> 0
H7: =IF(F7=0,G7,G7*F7) -> 0
H8: =IF(F8=0,G8,G8*F8) -> 0
H9: =IF(F9=0,G9,G9*F9) -> 0
H10: =IF(F10=0,G10,G10*F10) -> 0
H11: =IF(F11=0,G11,G11*F11) -> 0
H12: =IF(F12=0,G12,G12*F12) -> 0
H13: =IF(F13=0,G13,G13*F13) -> 0
H14: =IF(F14=0,G14,G14*F14) -> 0
H15: =IF(F15=0,G15,G15*F15) -> 0
H16: =IF(F16=0,G16,G16*F16) -> 0
H17: =SUM(H3:H16) -> 0
B18: 설치/해체/시운전 | H18: =IF(F18=0,G18,G18*F18) -> 0
B19: 공사 관련 자재 | H19: =IF(F19=0,G19,G19*F19) -> 0
H20: =IF(F20=0,G20,G20*F20) -> 0
H21: =IF(F21=0,G21,G21*F21) -> 0
H22: =IF(F22=0,G22,G22*F22) -> 0
H23: =SUM(H18:H22) -> 0
B24: 구매품 | H24: =IF(F24=0,G24,G24*F24) -> 0
B25: (유공압품외) | H25: =IF(F25=0,G25,G25*F25) -> 0
H26: =IF(F26=0,G26,G26*F26) -> 0
H27: =IF(F27=0,G27,G27*F27) -> 0
H28: =IF(F28=0,G28,G28*F28) -> 0
H29: =IF(F29=0,G29,G29*F29) -> 0
H30: =IF(F30=0,G30,G30*F30) -> 0
H31: =IF(F31=0,G31,G31*F31) -> 0
H32: =IF(F32=0,G32,G32*F32) -> 0
H33: =IF(F33=0,G33,G33*F33) -> 0
H34: =IF(F34=0,G34,G34*F34) -> 0
H35: =IF(F35=0,G35,G35*F35) -> 0
H36: =IF(F36=0,G36,G36*F36) -> 0
H37: =IF(F37=0,G37,G37*F37) -> 0
... H40: =IF(F40=0,G40,G40*F40) -> 0
H41: =SUM(H24:H40) -> 0
B42: 외주제작품 | H42: =IF(F42=0,G42,G42*F42) -> 0
...

Sheet 단위장비15
B1: □ 단위공사명(전기제외): | I1: (첨부)
A2: 구분 | C2: 품 명 | D2: 규격 | E2: 단위 | F2: 수량 | G2: 단가(원) | H2: 금액(원) | I2: 原MAKER
A3: 자 재 비 | B3: 철자재 | H3: =IF(F3=0,G3,G3*F3) -> 0
H4: =IF(F4=0,G4,G4*F4) -> 0
H5: =F5*G5 -> 0
H6: =IF(F6=0,G6,G6*F6) -> 0
H7: =IF(F7=0,G7,G7*F7) -> 0
H8: =IF(F8=0,G8,G8*F8) -> 0
H9: =IF(F9=0,G9,G9*F9) -> 0
H10: =IF(F10=0,G10,G10*F10) -> 0
H11: =IF(F11=0,G11,G11*F11) -> 0
H12: =SUM(H3:H11) -> 0
B13: 설치/해체/시운전 | H13: =IF(F13=0,G13,G13*F13) -> 0
B14: 공사 관련 자재 | H14: =IF(F14=0,G14,G14*F14) -> 0
H15: =IF(F15=0,G15,G15*F15) -> 0
H16: =IF(F16=0,G16,G16*F16) -> 0
H17: =IF(F17=0,G17,G17*F17) -> 0
H18: =SUM(H13:H17) -> 0
B19: 구매품 | H19: =IF(F19=0,G19,G19*F19) -> 0
B20: (유공압품외) | H20: =IF(F20=0,G20,G20*F20) -> 0
H21: =IF(F21=0,G21,G21*F21) -> 0
H22: =IF(F22=0,G22,G22*F22) -> 0
H23: =IF(F23=0,G23,G23*F23) -> 0
H24: =IF(F24=0,G24,G24*F24) -> 0
H25: =IF(F25=0,G25,G25*F25) -> 0
H26: =IF(F26=0,G26,G26*F26) -> 0
H27: =IF(F27=0,G27,G27*F27) -> 0
H28: =SUM(H19:H27) -> 0
B29: 외주제작품 | H29: =IF(F29=0,G29,G29*F29) -> 0
H30: =IF(F30=0,G30,G30*F30) -> 0
H31: =IF(F31=0,G31,G31*F31) -> 0
H32: =IF(F32=0,G32,G32*F32) -> 0
H33: =IF(F33=0,G33,G33*F33) -> 0
H34: =SUM(H29:H33) -> 0
B35: 자재비 소계 | H35: =SUM(H34,H28,H18,H12) -> 0
A36: 노 무 비 | B36: 기존설비 철거 | E36: M/D | H36: =F36*G36 -> 0
B37: 기계 설계 | E37: M/D | H37: =F37*G37 -> 0
B38: 기계 제작(제관,가공) | E38: M/D | H38: =F38*G38 -> 0
B39: 기계 조립 | E39: M/D | H39: =F39*G39 -> 0
B40: 기계 설치 | E40: M/D | H40: =F40*G40 -> 0
...

Sheet 첨부(견적조건차이내역)
