Workbook

Sheet 갑지
B1: (현대/기아차 설비협력업체 견적통일양식)
B2: 見 積 書
B4: 현대위아(주) 貴下 | G4: ㈜피앤에스
B5: 견적일자 | D5: 43320 | G5: 대표 : 박 봉 수 (인)
B6: 견적번호 | D6: PBQ-18178-1 | G6: 주소 : 경기도 포천시 군내면 마전길25-11
B7: 납기 | C7: 입하 | D7: 2018.08.30 | G7: 전화: 031-750-9331
C8: 최종검수 | G8: Fax: 031-750-9334
B9: 견적유효기간 | D9: 견적일로부터30일 | G9: E-mail:
B10: 인도장소 | D10: FCA INCHON | G10: 견적담당: 송우영 차장
B11: 담 당 자 | D11: 설비구매팀/이찬민 님 | G11: 연 락 처 : 010-6614-8124
B13: 공 사 명: | D13: WIA MEXICO CVJ - UST READING공정추가
B14: 최종견적금액: | D14: 一金팔천이백만원整(\82,000,000)만단위이하절사
B16: 번호 | C16: 상세품목내역 | E16: 견적금액 (천원) | I16: 비 고
E17: 기계부문 | F17: 전기부문 | G17: 관리/이윤 (안전관리비포함) | H17: 합 계
B18: 1 | C18: 전기 | F18: ='단위공사별(집계)'!J7/1000 -> 25000 | G18: ='단위공사별(집계)'!M7/1000 -> 2500 | H18: =IF('단위공사별(집계)'!N7>0,'단위공사별(집계)'!N7/1000,"") -> 27500
B19: 2 | C19: 기계 | E19: ='단위공사별(집계)'!J8/1000 -> 25678 | F19: =IF('단위공사별(집계)'!N8>0,'단위공사별(집계)'!K18/1000,"") -> 0 | G19: =IF('단위공사별(집계)'!N8>0,('단위공사별(집계)'!L8+'단위공사별(집계)'!M8)/1000,"") -> 2658 | H19: =IF('단위공사별(집계)'!N8>0,'단위공사별(집계)'!N8/1000,"") -> 28336
B20: 3 | C20: 현지 SV | E20: ='단위공사별(집계)'!J9*0.7/1000 -> 16660 | F20: ='단위공사별(집계)'!J9*0.3/1000 -> 7140 | G20: =IF('단위공사별(집계)'!N9>0,('단위공사별(집계)'!L9+'단위공사별(집계)'!M9)/1000,"") -> 2380 | H20: =IF('단위공사별(집계)'!N9>0,'단위공사별(집계)'!N9/1000,"") -> 26180
B21: 4 | C21: ㅡ 이하여백 ㅡ | E21: =IF('단위공사별(집계)'!N10>1,('단위공사별(집계)'!D10+'단위공사별(집계)'!E10+'단위공사별(집계)'!F10+'단위공사별(집계)'!G10+'단위공사별(집계)'!H10+'단위공사별(집계)'!I10)/1000," ") | G21: =IF('단위공사별(집계)'!N10>0,('단위공사별(집계)'!L10+'단위공사별(집계)'!M10)/1000,"") | H21: =IF('단위공사별(집계)'!N10>0,'단위공사별(집계)'!N10/1000,"")
B22: 5 | C22: =IF('단위공사별(집계)'!N11>0,'단위공사별(집계)'!B11,"") | E22: =IF('단위공사별(집계)'!N11>1,('단위공사별(집계)'!D11+'단위공사별(집계)'!E11+'단위공사별(집계)'!F11+'단위공사별(집계)'!G11+'단위공사별(집계)'!H11+'단위공사별(집계)'!I11)/1000," ") | G22: =IF('단위공사별(집계)'!N11>0,('단위공사별(집계)'!L11+'단위공사별(집계)'!M11)/1000,"") | H22: =IF('단위공사별(집계)'!N11>0,'단위공사별(집계)'!N11/1000,"")
B23: 6 | C23: =IF('단위공사별(집계)'!N12>0,'단위공사별(집계)'!B12,"") | E23: =IF('단위공사별(집계)'!N12>1,('단위공사별(집계)'!D12+'단위공사별(집계)'!E12+'단위공사별(집계)'!F12+'단위공사별(집계)'!G12+'단위공사별(집계)'!H12+'단위공사별(집계)'!I12)/1000," ") | G23: =IF('단위공사별(집계)'!N12>0,('단위공사별(집계)'!L12+'단위공사별(집계)'!M12)/1000,"") | H23: =IF('단위공사별(집계)'!N12>0,'단위공사별(집계)'!N12/1000,"")
B24: 7 | C24: =IF('단위공사별(집계)'!N13>0,'단위공사별(집계)'!B13,"") | E24: =IF('단위공사별(집계)'!N13>1,('단위공사별(집계)'!D13+'단위공사별(집계)'!E13+'단위공사별(집계)'!F13+'단위공사별(집계)'!G13+'단위공사별(집계)'!H13+'단위공사별(집계)'!I13)/1000," ") | G24: =IF('단위공사별(집계)'!N13>0,('단위공사별(집계)'!L13+'단위공사별(집계)'!M13)/1000,"") | H24: =IF('단위공사별(집계)'!N13>0,'단위공사별(집계)'!N13/1000,"")
B25: 8 | C25: =IF('단위공사별(집계)'!N14>0,'단위공사별(집계)'!B14,"") | E25: =IF('단위공사별(집계)'!N14>1,('단위공사별(집계)'!D14+'단위공사별(집계)'!E14+'단위공사별(집계)'!F14+'단위공사별(집계)'!G14+'단위공사별(집계)'!H14+'단위공사별(집계)'!I14)/1000," ") | G25: =IF('단위공사별(집계)'!N14>0,('단위공사별(집계)'!L14+'단위공사별(집계)'!M14)/1000,"") | H25: =IF('단위공사별(집계)'!N14>0,'단위공사별(집계)'!N14/1000,"")
B26: 9 | C26: =IF('단위공사별(집계)'!N15>0,'단위공사별(집계)'!B15,"") | E26: =IF('단위공사별(집계)'!N15>1,('단위공사별(집계)'!D15+'단위공사별(집계)'!E15+'단위공사별(집계)'!F15+'단위공사별(집계)'!G15+'단위공사별(집계)'!H15+'단위공사별(집계)'!I15)/1000," ") | G26: =IF('단위공사별(집계)'!N15>0,('단위공사별(집계)'!L15+'단위공사별(집계)'!M15)/1000,"") | H26: =IF('단위공사별(집계)'!N15>0,'단위공사별(집계)'!N15/1000,"")
B27: 10 | C27: =IF('단위공사별(집계)'!N16>0,'단위공사별(집계)'!B16,"") | E27: =IF('단위공사별(집계)'!N16>1,('단위공사별(집계)'!D16+'단위공사별(집계)'!E16+'단위공사별(집계)'!F16+'단위공사별(집계)'!G16+'단위공사별(집계)'!H16+'단위공사별(집계)'!I16)/1000," ") | G27: =IF('단위공사별(집계)'!N16>0,('단위공사별(집계)'!L16+'단위공사별(집계)'!M16)/1000,"") | H27: =IF('단위공사별(집계)'!N16>0,'단위공사별(집계)'!N16/1000,"")
B28: 견적 합계 | E28: =SUM(E18:E25) -> 42338 | F28: =SUM(F18:F25) -> 32140 | G28: =SUM(G18:G25) -> 7538 | H28: 82000 | I28: 만단위이하 절사
F30: 공개입찰가 (견적時 공란)
B32: 특기사항 | C32: 1. VAT 제외 | F32: 외주계획 업체명 (자작時 공란)
C33: 2. 기본 유틸리티공사 제외 | F33: 설계외주
C34: 3. 시설 취득 완료 후 100%결재조건 | F34: 제작외주
F35: 전기외주
F36: 설치외주

Sheet 원가항목별(집계)
C2: A. 원가항목별 견적가 종합(상세견적 첨부)
B4: □ 현대/기아 요구사양과 견적조건 일치여부 CHECK: 1.일치함 2.일부상이(상이내역 첨부참조)
B6: 순번 | C6: 원가구분 | F6: 단위 | G6: 수량 | H6: 단가 | I6: 금 액(원) | J6: 비 고
B7: 1 | C7: 기계 부문 | D7: 자재비 | E7: 철자재(SS.SUS등) | F7: kg | G7: ='단위장비1(기계)'!F30+'단위장비2(MEXICO LOCAL)'!F20+단위장비3!F30+단위장비4!F30+단위장비5!F30+단위장비6!F30+단위장비7!F30+단위장비8!F30+단위장비9!F30+단위장비10!F30 -> 0 | I7: ='단위장비1(기계)'!H24+'단위장비2(MEXICO LOCAL)'!H14 -> 11100000 | J7: 加工必要資材
E8: 일반구매품 | F8: 식 | G8: 1 | I8: ='단위장비1(기계)'!H46+'단위장비2(MEXICO LOCAL)'!H37 -> 23478000 | J8: 加工不要資材
E9: 외주제작품 | F9: 식 | G9: 1 | I9: ='단위장비1(기계)'!H57+'단위장비2(MEXICO LOCAL)'!H45+단위장비3!H55+단위장비4!H55+단위장비5!H55+단위장비6!H55+단위장비7!H55+단위장비8!H55+단위장비9!H55+단위장비10!H55 -> 0 | J9: 旣加工SUB資材
E10: 설치/해체 공사 자재 | F10: 식 | G10: 1 | I10: ='단위장비1(기계)'!H30+'단위장비2(MEXICO LOCAL)'!H20 -> 100000 | J10: 시운전 자재 포함
E11: 소계 | I11: =SUM(I7:I10) -> 34678000
D12: 노무비 | E12: 기존설비 철거 | F12: M/D | G12: ='단위장비1(기계)'!F59+'단위장비2(MEXICO LOCAL)'!F47+단위장비3!F57+단위장비4!F57+단위장비5!F57+단위장비6!F57+단위장비7!F57+단위장비8!F57+단위장비9!F57+단위장비10!F57 -> 0 | H12: =IF('단위장비1(기계)'!G59>0,'단위장비1(기계)'!G59,"") | I12: ='단위장비1(기계)'!H59+'단위장비2(MEXICO LOCAL)'!H47+단위장비3!H57+단위장비4!H57+단위장비5!H57+단위장비6!H57+단위장비7!H57+단위장비8!H57+단위장비9!H57+단위장비10!H57 -> 0 | J12: 개조공사時
E13: 설계 | F13: M/D | G13: 40 | H13: =IF('단위장비1(기계)'!G60>0,'단위장비1(기계)'!G60,"") -> 250000 | I13: ='단위장비1(기계)'!H60+'단위장비2(MEXICO LOCAL)'!H48 -> 10800000
E14: 제작(제관,가공) | F14: M/D | G14: ='단위장비1(기계)'!F61+'단위장비2(MEXICO LOCAL)'!F49+단위장비3!F59+단위장비4!F59+단위장비5!F59+단위장비6!F59+단위장비7!F59+단위장비8!F59+단위장비9!F59+단위장비10!F59 -> 0 | H14: =IF('단위장비1(기계)'!G61>0,'단위장비1(기계)'!G61,"") | I14: ='단위장비1(기계)'!H61+'단위장비2(MEXICO LOCAL)'!H49+단위장비3!H59+단위장비4!H59+단위장비5!H59+단위장비6!H59+단위장비7!H59+단위장비8!H59+단위장비9!H59+단위장비10!H59 -> 0
E15: 조립 | F15: M/D | G15: ='단위장비1(기계)'!F62+'단위장비2(MEXICO LOCAL)'!F50+단위장비3!F60+단위장비4!F60+단위장비5!F60+단위장비6!F60+단위장비7!F60+단위장비8!F60+단위장비9!F60+단위장비10!F60 -> 0 | H15: =IF('단위장비1(기계)'!G62>0,'단위장비1(기계)'!G62,"") | I15: ='단위장비1(기계)'!H62+'단위장비2(MEXICO LOCAL)'!H50+단위장비3!H60+단위장비4!H60+단위장비5!H60+단위장비6!H60+단위장비7!H60+단위장비8!H60+단위장비9!H60+단위장비10!H60 -> 0 | J15: 정도검사포함
E16: 설치 | F16: M/D | G16: ='단위장비1(기계)'!F63+'단위장비2(MEXICO LOCAL)'!F51+단위장비3!F61+단위장비4!F61+단위장비5!F61+단위장비6!F61+단위장비7!F61+단위장비8!F61+단위장비9!F61+단위장비10!F61 -> 10 | H16: =IF('단위장비1(기계)'!G63>0,'단위장비1(기계)'!G63,"") -> 200000 | I16: ='단위장비1(기계)'!H63+'단위장비2(MEXICO LOCAL)'!H51 -> 2000000
E17: 시운전 | F17: M/D | G17: ='단위장비1(기계)'!F64+'단위장비2(MEXICO LOCAL)'!F52+단위장비3!F62+단위장비4!F62+단위장비5!F62+단위장비6!F62+단위장비7!F62+단위장비8!F62+단위장비9!F62+단위장비10!F62 -> 5 | H17: =IF('단위장비1(기계)'!G64>0,'단위장비1(기계)'!G64,"") -> 200000 | I17: ='단위장비1(기계)'!H64+'단위장비2(MEXICO LOCAL)'!H52 -> 1000000
E18: 양산대응 | F18: M/D | G18: ='단위장비1(기계)'!F65+'단위장비2(MEXICO LOCAL)'!F53+단위장비3!F63+단위장비4!F63+단위장비5!F63+단위장비6!F63+단위장비7!F63+단위장비8!F63+단위장비9!F63+단위장비10!F63 -> 0 | H18: =IF('단위장비1(기계)'!G65>0,'단위장비1(기계)'!G65,"") | I18: ='단위장비1(기계)'!H65+'단위장비2(MEXICO LOCAL)'!H53+단위장비3!H63+단위장비4!H63+단위장비5!H63+단위장비6!H63+단위장비7!H63+단위장비8!H63+단위장비9!H63+단위장비10!H63 -> 0
E19: 도장 | F19: M/D | G19: ='단위장비1(기계)'!F66+'단위장비2(MEXICO LOCAL)'!F54+단위장비3!F64+단위장비4!F64+단위장비5!F64+단위장비6!F64+단위장비7!F64+단위장비8!F64+단위장비9!F64+단위장비10!F64 -> 0 | H19: =IF('단위장비1(기계)'!G66>0,'단위장비1(기계)'!G66,"") | I19: ='단위장비1(기계)'!H66+'단위장비2(MEXICO LOCAL)'!H54+단위장비3!H64+단위장비4!H64+단위장비5!H64+단위장비6!H64+단위장비7!H64+단위장비8!H64+단위장비9!H64+단위장비10!H64 -> 0
E20: 소계 | I20: =SUM(I12:I19) -> 13800000
D21: 일반관리 및 이윤 | I21: ='단위장비1(기계)'!H69+'단위장비1(기계)'!H70+'단위장비2(MEXICO LOCAL)'!H57 -> 3848000
E22: 기계 소계 | I22: =I20+I11+I21 -> 52326000
B23: 2 | C23: 전기 부문 | D23: 자재비 | E23: 기계/전기자재 | F23: 식 | G23: 1 | I23: =전기!H54-I24 -> 13000000
E24: 설치/해체 공사 자재 | F24: 식 | G24: 1 | I24: =전기!H16 -> 0 | J24: 시운전 자재 포함
D25: 노무비 | E25: 철거(개조시) | F25: M/D | G25: =전기!F55 -> 0 | H25: =IF(전기!G55>0,전기!G55,"") | I25: =전기!H55 -> 0
E26: 설계,프로그램 | F26: M/D | G26: =전기!F56 -> 20 | H26: =IF(전기!G56>0,전기!G56,"") -> 300000 | I26: =전기!H56 -> 6000000
E27: 제작 | F27: M/D | G27: =전기!F57 -> 0 | H27: =IF(전기!G57>0,전기!G57,"") | I27: =전기!H57 -> 0
E28: 조립 | F28: M/D | G28: =전기!F58 -> 0 | H28: =IF(전기!G58>0,전기!G58,"") | I28: =전기!H58 -> 0
E29: 설치 | F29: M/D | G29: =전기!F59 -> 12 | H29: =IF(전기!G59>0,전기!G59,"") -> 250000 | I29: =전기!H59 -> 3000000
E30: 시운전 | F30: M/D | G30: =전기!F60 -> 12 | H30: =IF(전기!G60>0,전기!G60,"") -> 250000 | I30: =전기!H60 -> 3000000
E31: 양산대응 | F31: M/D | G31: =전기!F61 -> 0 | H31: =IF(전기!G61>0,전기!G61,"") | I31: =전기!H61 -> 0
E32: 소계 | I32: =SUM(I25:I31) -> 12000000
D33: 일반관리 및 이윤 | I33: =전기!H64+전기!H65 -> 2500000
E34: 전기 소계 | I34: =I32+I23+I33+I24 -> 27500000
B35: 3 | C35: 자재비 합계 | I35: =I23+I11+I24 -> 47678000
C36: 노무비 합계 | I36: =I32+I20 -> 25800000
C37: 중간 합계 | I37: =I36+I35 -> 73478000
B38: 4 | C38: 포장,운송 및 중장비 사용료 | I38: ='단위장비1(기계)'!H68 -> 1000000
B39: 5 | C39: 표준안전관리비 | F39: 설치/철거/수리금액 기준 | J39: =I30+I29+I25+I24+I17+I16+I12+I10 -> 9100000
B40: 6 | C40: 일반관리비 | I40: =전기!H64+'단위장비1(기계)'!H69+'단위장비2(MEXICO LOCAL)'!H57 -> 3769000
B41: 7 | C41: 이 윤 | I41: =전기!H65+'단위장비1(기계)'!H70+'단위장비2(MEXICO LOCAL)'!H58 -> 3769000
C42: 합 계 | F42: 3~7항 합계 | I42: =I37+I38+I40+I41 -> 82016000
B43: 주1. 표준안전관리비:(설치/철거/시운전 공사 관련 금액)의 ⓐ2.66%,ⓑ1.95%+기초액,ⓒ2.02%(50억 이상일경우)
...

Sheet 단위공사별(집계)
A2: B. 단위장비별 견적가 종합(상세견적 첨부)
N3: 단위:원
I5: 포장/운송 | L5: 표준안전 | M5: 일반관리비
A6: 순번 | B6: 단위장비명 | C6: 수량 | D6: 자재비 | E6: 철거 | F6: 제작 | G6: 설치/시운전 | H6: 양산대응 | I6: 중장비사용 | J6: 기계소계 | K6: 전기소계 | L6: 관리비 | M6: 이윤 | N6: 합 계 | O6: 비 고
A7: 1 | B7: 전기 | C7: 1식 | D7: =전기!H54 -> 13000000 | E7: 0 | F7: =SUM('단위장비1(기계)'!H60) -> 6000000 | G7: =SUM(전기!H59,전기!H60) -> 6000000 | H7: 0 | I7: 0 | J7: =SUM(D7:I7) -> 25000000 | L7: 0 | M7: =SUM(전기!H64,전기!H65) -> 2500000 | N7: =SUM(J7:M7) -> 27500000
A8: 2 | B8: 기계 | C8: 1식 | D8: ='단위장비1(기계)'!H58 -> 15678000 | E8: ='단위장비1(기계)'!H59 -> 0 | F8: ='단위장비1(기계)'!H60+'단위장비1(기계)'!H61+'단위장비1(기계)'!H62+'단위장비1(기계)'!H66 -> 6000000 | G8: ='단위장비1(기계)'!H63+'단위장비1(기계)'!H64 -> 3000000 | H8: ='단위장비1(기계)'!H65 -> 0 | I8: ='단위장비1(기계)'!H68 -> 1000000 | J8: =SUM(D8:I8) -> 25678000 | L8: =IF($B8>0,'원가항목별(집계)'!I$39*$P8/$P$18,0) -> 0 | M8: ='단위장비1(기계)'!H69+'단위장비1(기계)'!H70 -> 2658000 | N8: =SUM(J8:M8) -> 28336000 | P8: =D8+E8+F8+G8+H8+M8 -> 27336000
A9: 3 | B9: 현지 SV | C9: 1식 | D9: ='단위장비2(MEXICO LOCAL)'!H46 -> 19000000 | E9: ='단위장비2(MEXICO LOCAL)'!H47 -> 0 | F9: ='단위장비2(MEXICO LOCAL)'!H48+'단위장비2(MEXICO LOCAL)'!H49+'단위장비2(MEXICO LOCAL)'!H50+'단위장비2(MEXICO LOCAL)'!H54 -> 4800000 | G9: ='단위장비2(MEXICO LOCAL)'!H51+'단위장비2(MEXICO LOCAL)'!H52 -> 0 | H9: ='단위장비2(MEXICO LOCAL)'!H53 -> 0 | J9: =SUM(D9:I9) -> 23800000 | L9: =IF($B9>0,'원가항목별(집계)'!I$39*$P9/$P$18,0) -> 0 | M9: ='단위장비2(MEXICO LOCAL)'!H57+'단위장비2(MEXICO LOCAL)'!H58 -> 2380000 | N9: =SUM(J9:M9) -> 26180000 | P9: =D9+E9+F9+G9+H9+M9 -> 26180000
B10: 0 | C10: 1식 | D10: =단위장비3!H56 -> 0 | E10: =단위장비3!H57 -> 0 | F10: =단위장비3!H58+단위장비3!H59+단위장비3!H60+단위장비3!H64 -> 0 | G10: =단위장비3!H61+단위장비3!H62 -> 0 | H10: =단위장비3!H63 -> 0 | I10: =IF($B10>0,'원가항목별(집계)'!I$38*$P10/$P$18,0) -> 0 | J10: =SUM(D10:I10) -> 0 | K10: =IF(B10>0,'원가항목별(집계)'!I$34*P10/P$18,0) -> 0 | L10: =IF($B10>0,'원가항목별(집계)'!I$39*$P10/$P$18,0) -> 0 | M10: =단위장비3!H67+단위장비3!H68 -> 0 | N10: =SUM(J10:M10) -> 0 | P10: =D10+E10+F10+G10+H10+M10 -> 0
A11: =IF(B11>0,A10+1,"") | B11: =단위장비4!C$1 -> 0 | C11: 1식 | D11: =단위장비4!H56 -> 0 | E11: =단위장비4!H57 -> 0 | F11: =단위장비4!H58+단위장비4!H59+단위장비4!H60+단위장비4!H64 -> 0 | G11: =단위장비4!H61+단위장비4!H62 -> 0 | H11: =단위장비4!H63 -> 0 | I11: =IF($B11>0,'원가항목별(집계)'!I$38*$P11/$P$18,0) -> 0 | J11: =SUM(D11:I11) -> 0 | K11: =IF(B11>0,'원가항목별(집계)'!I$34*P11/P$18,0) -> 0 | L11: =IF($B11>0,'원가항목별(집계)'!I$39*$P11/$P$18,0) -> 0 | M11: =단위장비4!H67+단위장비4!H68 -> 0 | N11: =SUM(J11:M11) -> 0 | P11: =D11+E11+F11+G11+H11+M11 -> 0
A12: =IF(B12>0,A11+1,"") | B12: =단위장비5!C$1 -> 0 | C12: 1식 | D12: =단위장비5!H56 -> 0 | E12: =단위장비5!H57 -> 0 | F12: =단위장비5!H58+단위장비5!H59+단위장비5!H60+단위장비5!H64 -> 0 | G12: =단위장비5!H61+단위장비5!H62 -> 0 | H12: =단위장비5!H63 -> 0 | I12: =IF($B12>0,'원가항목별(집계)'!I$38*$P12/$P$18,0) -> 0 | J12: =SUM(D12:I12) -> 0 | K12: =IF(B12>0,'원가항목별(집계)'!I$34*P12/P$18,0) -> 0 | L12: =IF($B12>0,'원가항목별(집계)'!I$39*$P12/$P$18,0) -> 0 | M12: =단위장비5!H67+단위장비5!H68 -> 0 | N12: =SUM(J12:M12) -> 0 | P12: =D12+E12+F12+G12+H12+M12 -> 0
A13: =IF(B13>0,A12+1,"") | B13: =단위장비6!C$1 -> 0 | C13: 1식 | D13: =단위장비6!H56 -> 0 | E13: =단위장비6!H57 -> 0 | F13: =단위장비6!H58+단위장비6!H59+단위장비6!H60+단위장비6!H64 -> 0 | G13: =단위장비6!H61+단위장비6!H62 -> 0 | H13: =단위장비6!H63 -> 0 | I13: =IF($B13>0,'원가항목별(집계)'!I$38*$P13/$P$18,0) -> 0 | J13: =SUM(D13:I13) -> 0 | K13: =IF(B13>0,'원가항목별(집계)'!I$34*P13/P$18,0) -> 0 | L13: =IF($B13>0,'원가항목별(집계)'!I$39*$P13/$P$18,0) -> 0 | M13: =단위장비6!H67+단위장비6!H68 -> 0 | N13: =SUM(J13:M13) -> 0 | P13: =D13+E13+F13+G13+H13+M13 -> 0
A14: =IF(B14>0,A9+1,"") | B14: =단위장비7!C$1 -> 0 | C14: 1식 | D14: =단위장비7!H56 -> 0 | E14: =단위장비7!H57 -> 0 | F14: =단위장비7!H58+단위장비7!H59+단위장비7!H60+단위장비7!H64 -> 0 | G14: =단위장비7!H61+단위장비7!H62 -> 0 | H14: =단위장비7!H63 -> 0 | I14: =IF($B14>0,'원가항목별(집계)'!I$38*$P14/$P$18,0) -> 0 | J14: =SUM(D14:I14) -> 0 | K14: =IF(B14>0,'원가항목별(집계)'!I$34*P14/P$18,0) -> 0 | L14: =IF($B14>0,'원가항목별(집계)'!I$39*$P14/$P$18,0) -> 0 | M14: =단위장비7!H67+단위장비7!H68 -> 0 | N14: =SUM(J14:M14) -> 0 | P14: =D14+E14+F14+G14+H14+M14 -> 0
A15: =IF(B15>0,A14+1,"") | B15: =단위장비8!C$1 -> 0 | C15: 1식 | D15: =단위장비8!H56 -> 0 | E15: =단위장비8!H57 -> 0 | F15: =단위장비8!H58+단위장비8!H59+단위장비8!H60+단위장비8!H64 -> 0 | G15: =단위장비8!H61+단위장비8!H62 -> 0 | H15: =단위장비8!H63 -> 0 | I15: =IF($B15>0,'원가항목별(집계)'!I$38*$P15/$P$18,0) -> 0 | J15: =SUM(D15:I15) -> 0 | K15: =IF(B15>0,'원가항목별(집계)'!I$34*P15/P$18,0) -> 0 | L15: =IF($B15>0,'원가항목별(집계)'!I$39*$P15/$P$18,0) -> 0 | M15: =단위장비8!H67+단위장비8!H68 -> 0 | N15: =SUM(J15:M15) -> 0 | P15: =D15+E15+F15+G15+H15+M15 -> 0
A16: =IF(B16>0,A15+1,"") | B16: =단위장비9!C$1 -> 0 | C16: 1식 | D16: =단위장비9!H57 -> 0 | E16: =단위장비9!H58 -> 0 | F16: =단위장비9!H59+단위장비9!H60+단위장비9!H61+단위장비9!H65 -> 0 | G16: =단위장비9!H62+단위장비9!H63 -> 0 | H16: =단위장비9!H64 -> 0 | I16: =IF($B16>0,'원가항목별(집계)'!I$38*$P16/$P$18,0) -> 0 | J16: =SUM(D16:I16) -> 0 | K16: =IF(B16>0,'원가항목별(집계)'!I$34*P16/P$18,0) -> 0 | L16: =IF($B16>0,'원가항목별(집계)'!I$39*$P16/$P$18,0) -> 0 | M16: =단위장비9!H68+단위장비9!H69 -> 0 | N16: =SUM(J16:M16) -> 0 | P16: =D16+E16+F16+G16+H16+M16 -> 0
A17: =IF(B17>0,A16+1,"") | B17: =단위장비10!C$1 -> 0 | C17: 1식 | D17: =단위장비10!H58 -> 0 | E17: =단위장비10!H59 -> 0 | F17: =단위장비10!H60+단위장비10!H61+단위장비10!H62+단위장비10!H66 -> 0 | G17: =단위장비10!H63+단위장비10!H64 -> 0 | H17: =단위장비10!H65 -> 0 | I17: =IF($B17>0,'원가항목별(집계)'!I$38*$P17/$P$18,0) -> 0 | J17: =SUM(D17:I17) -> 0 | K17: =IF(B17>0,'원가항목별(집계)'!I$34*P17/P$18,0) -> 0 | L17: =IF($B17>0,'원가항목별(집계)'!I$39*$P17/$P$18,0) -> 0 | M17: =단위장비10!H69+단위장비10!H70 -> 0 | N17: =SUM(J17:M17) -> 0 | P17: =D17+E17+F17+G17+H17+M17 -> 0
A18: 합 계 | D18: =SUM(D8:D17) -> 34678000 | E18: =SUM(E8:E17) -> 0 | F18: =SUM(F8:F17) -> 10800000 | G18: =SUM(G8:G17) -> 3000000 | H18: =SUM(H8:H17) -> 0 | I18: =SUM(I8:I17) -> 1000000 | J18: =SUM(D18:I18) -> 49478000 | K18: =SUM(K8:K17) -> 0 | L18: =SUM(L8:L17) -> 0 | M18: =SUM(M8:M17) -> 5038000 | N18: =SUM(N7:N15) -> 82016000 | P18: =D18+E18+F18+G18+H18+M18 -> 53516000
D19: =IF(D18=0,"",D18/$N18) -> 0.42281994 | E19: =IF(E18=0,"",E18/$N18) | F19: =IF(F18=0,"",F18/$N18) -> 0.13168162 | G19: =IF(G18=0,"",G18/$N18) -> 0.036578229 | H19: =IF(H18=0,"",H18/$N18) | I19: =IF(I18=0,"",I18/$N18) -> 0.012192743 | J19: =IF(J18=0,"",J18/$N18) -> 0.60327253 | K19: =IF(K18=0,"",K18/$N18) | ... N19: =IF(N18=0,"",N18/$N18) -> 1
A20: 주) 전기비용은 턴키장비의 공통비용으로서 총 전기비용을 단위장비별 기계금액의 비율에 따라 배분함

Sheet 전기
B1: □ 전기부문: | C1: 전기부문(공통) | I1: (첨부)
A2: 구분 | C2: 품 명 | D2: 규격 | E2: 단위 | F2: 수량 | G2: 단가(원) | H2: 금액(원) | I2: 原MAKER
A3: 자 재 비 | B3: 자재 | C3: Barcode Scanner | D3: Cognex DMR363X | E3: EA | F3: 2 | G3: 5500000 | H3: =IF(F3=0,G3,G3*F3) -> 11000000
H4: =IF(F4=0,G4,G4*F4) -> 0
H5: =IF(F5=0,G5,G5*F5) -> 0
H6: =IF(F6=0,G6,G6*F6) -> 0
H7: =IF(F7=0,G7,G7*F7) -> 0
H8: =IF(F8=0,G8,G8*F8) -> 0
H9: =SUM(H3:H8) -> 11000000
B10: 설치/해체/ | H10: =IF(F10=0,G10,G10*F10) -> 0
B11: 시운전 공사 | H11: =IF(F11=0,G11,G11*F11) -> 0
B12: 자재 | H12: =IF(F12=0,G12,G12*F12) -> 0
H13: =IF(F13=0,G13,G13*F13) -> 0
H14: =IF(F14=0,G14,G14*F14) -> 0
C15: 기타자재 | H15: =IF(F15=0,G15,G15*F15) -> 0
H16: =SUM(H10:H15) -> 0
B17: 전기자재 | C17: Electric Parts | E17: SET | F17: 1 | G17: 2000000 | H17: =IF(F17=0,G17,G17*F17) -> 2000000
H18: =IF(F18=0,G18,G18*F18) -> 0
H19: =IF(F19=0,G19,G19*F19) -> 0
H20: =IF(F20=0,G20,G20*F20) -> 0
H21: =IF(F21=0,G21,G21*F21) -> 0
H22: =IF(F22=0,G22,G22*F22) -> 0
H23: =IF(F23=0,G23,G23*F23) -> 0
H24: =IF(F24=0,G24,G24*F24) -> 0
H25: =IF(F25=0,G25,G25*F25) -> 0
H26: =IF(F26=0,G26,G26*F26) -> 0
H27: =IF(F27=0,G27,G27*F27) -> 0
H28: =IF(F28=0,G28,G28*F28) -> 0
H29: =IF(F29=0,G29,G29*F29) -> 0
... H41: =IF(F41=0,G41,G41*F41) -> 0
H42: =SUM(H17:H41) -> 2000000
B43: 프로그램
H45: =IF(F45=0,G45,G45*F45) -> 0
H46: =IF(F46=0,G46,G46*F46) -> 0
H47: =IF(F47=0,G47,G47*F47) -> 0
H48: =IF(F48=0,G48,G48*F48) -> 0
H49: =IF(F49=0,G49,G49*F49) -> 0
H50: =IF(F50=0,G50,G50*F50) -> 0
H51: =IF(F51=0,G51,G51*F51) -> 0
C52: 기타자재 | H52: =IF(F52=0,G52,G52*F52) -> 0
...

Sheet 단위장비1(기계)
B1: □ 단위공사명(전기제외): | C1: ㅇㅇㅇㅇㅇㅇ | I1: (첨부)
A2: 구분 | C2: 품 명 | D2: 규격 | E2: 단위 | F2: 수량 | G2: 단가(원) | H2: 금액(원) | I2: 原MAKER
A3: 자 재 비 | B3: 자재 | C3: READING UNIT | E3: SET | F3: 1 | G3: 6500000 | H3: =IF(F3=0,G3,G3*F3) -> 6500000
C4: SAFETY FENCE | E4: SET | F4: 1 | G4: 4100000 | H4: =IF(F4=0,G4,G4*F4) -> 4100000
H5: =IF(F5=0,G5,G5*F5) -> 0
H6: =IF(F6=0,G6,G6*F6) -> 0
H7: =IF(F7=0,G7,G7*F7) -> 0
H8: =IF(F8=0,G8,G8*F8) -> 0
H9: =IF(F9=0,G9,G9*F9) -> 0
H10: =IF(F10=0,G10,G10*F10) -> 0
H11: =IF(F11=0,G11,G11*F11) -> 0
H12: =IF(F12=0,G12,G12*F12) -> 0
H13: =IF(F13=0,G13,G13*F13) -> 0
H14: =IF(F14=0,G14,G14*F14) -> 0
H15: =IF(F15=0,G15,G15*F15) -> 0
H16: =IF(F16=0,G16,G16*F16) -> 0
... H22: =IF(F22=0,G22,G22*F22) -> 0
C23: 기타자재 | E23: 식 | F23: 1 | G23: 500000 | H23: =IF(F23=0,G23,G23*F23) -> 500000
H24: =SUM(H3:H23) -> 11100000
B25: 설치/해체/시운전 | H25: =IF(F25=0,G25,G25*F25) -> 0
B26: 공사 관련 자재 | H26: =IF(F26=0,G26,G26*F26) -> 0
H27: =IF(F27=0,G27,G27*F27) -> 0
H28: =IF(F28=0,G28,G28*F28) -> 0
H29: =IF(F29=0,G29,G29*F29) -> 0
H30: =SUM(H25:H29) -> 0
B31: 구매품 | C31: 구동용 MOTOR | D31: BLM6200SHP | E31: EA | F31: 1 | G31: 490000 | H31: =IF(F31=0,G31,G31*F31) -> 490000
B32: (유공압품외) | C32: CONTROLER | D32: BMUD 200-C | E32: EA | F32: 1 | G32: 88000 | H32: =IF(F32=0,G32,G32*F32) -> 88000
C33: CYLINDER외 | E33: SET | F33: 1 | G33: 4000000 | H33: =IF(F33=0,G33,G33*F33) -> 4000000
H34: =IF(F34=0,G34,G34*F34) -> 0
H35: =IF(F35=0,G35,G35*F35) -> 0
H36: =IF(F36=0,G36,G36*F36) -> 0
H37: =IF(F37=0,G37,G37*F37) -> 0
H38: =IF(F38=0,G38,G38*F38) -> 0
H39: =IF(F39=0,G39,G39*F39) -> 0
H40: =IF(F40=0,G40,G40*F40) -> 0
H41: =IF(F41=0,G41,G41*F41) -> 0
H42: =IF(F42=0,G42,G42*F42) -> 0
H43: =IF(F43=0,G43,G43*F43) -> 0
H44: =IF(F44=0,G44,G44*F44) -> 0
H45: =IF(F45=0,G45,G45*F45) -> 0
...

Sheet 단위장비2(MEXICO LOCAL)
B1: □ 단위공사명(전기제외): | C1: ㅇㅇㅇㅇㅇ | I1: (첨부)
A2: 구분 | C2: 품 명 | D2: 규격 | E2: 단위 | F2: 수량 | G2: 단가(원) | H2: 금액(원) | I2: 原MAKER
A3: 자 재 비 | B3: 철자재 | H3: =IF(F3=0,G3,G3*F3) -> 0
H4: =IF(F4=0,G4,G4*F4) -> 0
H5: =IF(F5=0,G5,G5*F5) -> 0
H6: =IF(F6=0,G6,G6*F6) -> 0
H7: =IF(F7=0,G7,G7*F7) -> 0
H8: =IF(F8=0,G8,G8*F8) -> 0
H9: =IF(F9=0,G9,G9*F9) -> 0
H10: =IF(F10=0,G10,G10*F10) -> 0
H11: =IF(F11=0,G11,G11*F11) -> 0
H12: =IF(F12=0,G12,G12*F12) -> 0
H13: =IF(F13=0,G13,G13*F13) -> 0
H14: =SUM(H3:H13) -> 0
B15: 설치/해체/시운전 | E15: SET | F15: 1 | G15: 100000 | H15: =IF(F15=0,G15,G15*F15) -> 100000
B16: 공사 관련 자재 | H16: =IF(F16=0,G16,G16*F16) -> 0
H17: =IF(F17=0,G17,G17*F17) -> 0
H18: =IF(F18=0,G18,G18*F18) -> 0
H19: =IF(F19=0,G19,G19*F19) -> 0
H20: =SUM(H15:H19) -> 100000
B21: 구매품 | C21: FLIGHT | D21: 5인 | E21: SET | F21: 1 | G21: 11000000 | H21: =IF(F21=0,G21,G21*F21) -> 11000000
B22: (유공압품외) | C22: MEXICO STAYOVER | E22: MD | F22: 42 | G22: 150000 | H22: =IF(F22=0,G22,G22*F22) -> 6300000
C23: MEXICO TRANSLATION | E23: SET | F23: 1 | G23: 1600000 | H23: =IF(F23=0,G23,G23*F23) -> 1600000
H24: =IF(F24=0,G24,G24*F24) -> 0
H25: =IF(F25=0,G25,G25*F25) -> 0
H26: =IF(F26=0,G26,G26*F26) -> 0
H27: =IF(F27=0,G27,G27*F27) -> 0
H28: =IF(F28=0,G28,G28*F28) -> 0
H29: =IF(F29=0,G29,G29*F29) -> 0
H30: =IF(F30=0,G30,G30*F30) -> 0
H31: =IF(F31=0,G31,G31*F31) -> 0
H32: =IF(F32=0,G32,G32*F32) -> 0
H33: =IF(F33=0,G33,G33*F33) -> 0
H34: =IF(F34=0,G34,G34*F34) -> 0
H35: =IF(F35=0,G35,G35*F35) -> 0
H36: =IF(F36=0,G36,G36*F36) -> 0
H37: =SUM(H21:H36) -> 18900000
B38: 외주제작품 | H38: =IF(F38=0,G38,G38*F38) -> 0
H39: =IF(F39=0,G39,G39*F39) -> 0
H40: =IF(F40=0,G40,G40*F40) -> 0
...

Sheet 단위장비3
B1: □ 단위공사명(전기제외): | C1: ㅇㅇㅇㅇㅇ | I1: (첨부)
A2: 구분 | C2: 품 명 | D2: 규격 | E2: 단위 | F2: 수량 | G2: 단가(원) | H2: 금액(원) | I2: 原MAKER
A3: 자 재 비 | B3: 철자재 | C3: 형강류 | E3: Kg | H3: =IF(F3=0,G3,G3*F3) -> 0
C4: SS41 PLATE류 | E4: Kg | H4: =IF(F4=0,G4,G4*F4) -> 0
C5: S45C R/BAR류 | E5: Kg | H5: =IF(F5=0,G5,G5*F5) -> 0
C6: SUS | E6: Kg | H6: =IF(F6=0,G6,G6*F6) -> 0
H7: =IF(F7=0,G7,G7*F7) -> 0
H8: =IF(F8=0,G8,G8*F8) -> 0
H9: =IF(F9=0,G9,G9*F9) -> 0
H10: =IF(F10=0,G10,G10*F10) -> 0
H11: =IF(F11=0,G11,G11*F11) -> 0
H12: =IF(F12=0,G12,G12*F12) -> 0
H13: =IF(F13=0,G13,G13*F13) -> 0
H14: =IF(F14=0,G14,G14*F14) -> 0
H15: =IF(F15=0,G15,G15*F15) -> 0
H16: =IF(F16=0,G16,G16*F16) -> 0
H17: =IF(F17=0,G17,G17*F17) -> 0
H18: =IF(F18=0,G18,G18*F18) -> 0
... H22: =IF(F22=0,G22,G22*F22) -> 0
C23: 기타자재 | E23: 식 | F23: 1 | H23: =IF(F23=0,G23,G23*F23) -> 0
H24: =SUM(H3:H23) -> 0
B25: 설치/해체/시운전 | H25: =IF(F25=0,G25,G25*F25) -> 0
B26: 공사 관련 자재 | H26: =IF(F26=0,G26,G26*F26) -> 0
H27: =IF(F27=0,G27,G27*F27) -> 0
H28: =IF(F28=0,G28,G28*F28) -> 0
C29: 기타자재 | H29: =IF(F29=0,G29,G29*F29) -> 0
H30: =SUM(H25:H29) -> 0
B31: 구매품 | C31: 매트 | E31: 식 | F31: 1 | H31: 0
B32: (유공압품외) | C32: 기타자재 | E32: 식 | F32: 1 | H32: 0
H33: =IF(F33=0,G33,G33*F33) -> 0
H34: =IF(F34=0,G34,G34*F34) -> 0
H35: =IF(F35=0,G35,G35*F35) -> 0
H36: =IF(F36=0,G36,G36*F36) -> 0
H37: =IF(F37=0,G37,G37*F37) -> 0
H38: =IF(F38=0,G38,G38*F38) -> 0
H39: =IF(F39=0,G39,G39*F39) -> 0
H40: =IF(F40=0,G40,G40*F40) -> 0
H41: =IF(F41=0,G41,G41*F41) -> 0
H42: =IF(F42=0,G42,G42*F42) -> 0
H43: =IF(F43=0,G43,G43*F43) -> 0
...

Sheet 단위장비4
B1: □ 단위공사명(전기제외): | I1: (첨부)
A2: 구분 | C2: 품 명 | D2: 규격 | E2: 단위 | F2: 수량 | G2: 단가(원) | H2: 금액(원) | I2: 原MAKER
A3: 자 재 비 | B3: 철자재 | H3: =IF(F3=0,G3,G3*F3) -> 0
H4: =IF(F4=0,G4,G4*F4) -> 0
H5: =IF(F5=0,G5,G5*F5) -> 0
H6: =IF(F6=0,G6,G6*F6) -> 0
H7: =IF(F7=0,G7,G7*F7) -> 0
H8: =IF(F8=0,G8,G8*F8) -> 0
H9: =IF(F9=0,G9,G9*F9) -> 0
H10: =IF(F10=0,G10,G10*F10) -> 0
H11: =IF(F11=0,G11,G11*F11) -> 0
H12: =IF(F12=0,G12,G12*F12) -> 0
H13: =IF(F13=0,G13,G13*F13) -> 0
H14: =IF(F14=0,G14,G14*F14) -> 0
H15: =IF(F15=0,G15,G15*F15) -> 0
... H22: =IF(F22=0,G22,G22*F22) -> 0
C23: 기타자재 | H23: =IF(F23=0,G23,G23*F23) -> 0
H24: =SUM(H3:H23) -> 0
B25: 설치/해체/시운전 | H25: =IF(F25=0,G25,G25*F25) -> 0
B26: 공사 관련 자재 | H26: =IF(F26=0,G26,G26*F26) -> 0
H27: =IF(F27=0,G27,G27*F27) -> 0
H28: =IF(F28=0,G28,G28*F28) -> 0
C29: 기타자재 | H29: =IF(F29=0,G29,G29*F29) -> 0
H30: =SUM(H25:H29) -> 0
B31: 구매품 | H31: =IF(F31=0,G31,G31*F31) -> 0
B32: (유공압품외) | H32: =IF(F32=0,G32,G32*F32) -> 0
H33: =IF(F33=0,G33,G33*F33) -> 0
H34: =IF(F34=0,G34,G34*F34) -> 0
H35: =IF(F35=0,G35,G35*F35) -> 0
H36: =IF(F36=0,G36,G36*F36) -> 0
H37: =IF(F37=0,G37,G37*F37) -> 0
H38: =IF(F38=0,G38,G38*F38) -> 0
H39: =IF(F39=0,G39,G39*F39) -> 0
H40: =IF(F40=0,G40,G40*F40) -> 0
H41: =IF(F41=0,G41,G41*F41) -> 0
H42: =IF(F42=0,G42,G42*F42) -> 0
H43: =IF(F43=0,G43,G43*F43) -> 0
H44: =IF(F44=0,G44,G44*F44) -> 0
... H46: =IF(F46=0,G46,G46*F46) -> 0
H47: =SUM(H31:H46) -> 0
...

Sheet 단위장비5
B1: □ 단위공사명(전기제외): | I1: (첨부)
A2: 구분 | C2: 품 명 | D2: 규격 | E2: 단위 | F2: 수량 | G2: 단가(원) | H2: 금액(원) | I2: 原MAKER
A3: 자 재 비 | B3: 철자재 | H3: =IF(F3=0,G3,G3*F3) -> 0
H4: =IF(F4=0,G4,G4*F4) -> 0
H5: =IF(F5=0,G5,G5*F5) -> 0
H6: =IF(F6=0,G6,G6*F6) -> 0
H7: =IF(F7=0,G7,G7*F7) -> 0
H8: =IF(F8=0,G8,G8*F8) -> 0
H9: =IF(F9=0,G9,G9*F9) -> 0
H10: =IF(F10=0,G10,G10*F10) -> 0
H11: =IF(F11=0,G11,G11*F11) -> 0
H12: =IF(F12=0,G12,G12*F12) -> 0
H13: =IF(F13=0,G13,G13*F13) -> 0
H14: =IF(F14=0,G14,G14*F14) -> 0
H15: =IF(F15=0,G15,G15*F15) -> 0
... H22: =IF(F22=0,G22,G22*F22) -> 0
C23: 기타자재 | H23: =IF(F23=0,G23,G23*F23) -> 0
H24: =SUM(H3:H23) -> 0
B25: 설치/해체/시운전 | H25: =IF(F25=0,G25,G25*F25) -> 0
B26: 공사 관련 자재 | H26: =IF(F26=0,G26,G26*F26) -> 0
H27: =IF(F27=0,G27,G27*F27) -> 0
H28: =IF(F28=0,G28,G28*F28) -> 0
C29: 기타자재 | H29: =IF(F29=0,G29,G29*F29) -> 0
H30: =SUM(H25:H29) -> 0
B31: 구매품 | H31: =IF(F31=0,G31,G31*F31) -> 0
B32: (유공압품외) | H32: =IF(F32=0,G32,G32*F32) -> 0
H33: =IF(F33=0,G33,G33*F33) -> 0
H34: =IF(F34=0,G34,G34*F34) -> 0
H35: =IF(F35=0,G35,G35*F35) -> 0
H36: =IF(F36=0,G36,G36*F36) -> 0
H37: =IF(F37=0,G37,G37*F37) -> 0
H38: =IF(F38=0,G38,G38*F38) -> 0
H39: =IF(F39=0,G39,G39*F39) -> 0
H40: =IF(F40=0,G40,G40*F40) -> 0
H41: =IF(F41=0,G41,G41*F41) -> 0
H42: =IF(F42=0,G42,G42*F42) -> 0
H43: =IF(F43=0,G43,G43*F43) -> 0
H44: =IF(F44=0,G44,G44*F44) -> 0
H45: =IF(F45=0,G45,G45*F45) -> 0
C46: 기타자재 | H46: =IF(F46=0,G46,G46*F46) -> 0
...

Sheet 단위장비6
B1: □ 단위공사명(전기제외): | I1: (첨부)
A2: 구분 | C2: 품 명 | D2: 규격 | E2: 단위 | F2: 수량 | G2: 단가(원) | H2: 금액(원) | I2: 原MAKER
A3: 자 재 비 | B3: 철자재 | H3: =IF(F3=0,G3,G3*F3) -> 0
H4: =IF(F4=0,G4,G4*F4) -> 0
H5: =IF(F5=0,G5,G5*F5) -> 0
H6: =IF(F6=0,G6,G6*F6) -> 0
H7: =IF(F7=0,G7,G7*F7) -> 0
H8: =IF(F8=0,G8,G8*F8) -> 0
H9: =IF(F9=0,G9,G9*F9) -> 0
H10: =IF(F10=0,G10,G10*F10) -> 0
H11: =IF(F11=0,G11,G11*F11) -> 0
H12: =IF(F12=0,G12,G12*F12) -> 0
H13: =IF(F13=0,G13,G13*F13) -> 0
H14: =IF(F14=0,G14,G14*F14) -> 0
H15: =IF(F15=0,G15,G15*F15) -> 0
... H22: =IF(F22=0,G22,G22*F22) -> 0
C23: 기타자재 | H23: =IF(F23=0,G23,G23*F23) -> 0
H24: =SUM(H3:H23) -> 0
B25: 설치/해체/시운전 | H25: =IF(F25=0,G25,G25*F25) -> 0
B26: 공사 관련 자재 | H26: =IF(F26=0,G26,G26*F26) -> 0
H27: =IF(F27=0,G27,G27*F27) -> 0
H28: =IF(F28=0,G28,G28*F28) -> 0
C29: 기타자재 | H29: =IF(F29=0,G29,G29*F29) -> 0
H30: =SUM(H25:H29) -> 0
B31: 구매품 | H31: =IF(F31=0,G31,G31*F31) -> 0
B32: (유공압품외) | H32: =IF(F32=0,G32,G32*F32) -> 0
H33: =IF(F33=0,G33,G33*F33) -> 0
H34: =IF(F34=0,G34,G34*F34) -> 0
H35: =IF(F35=0,G35,G35*F35) -> 0
H36: =IF(F36=0,G36,G36*F36) -> 0
H37: =IF(F37=0,G37,G37*F37) -> 0
H38: =IF(F38=0,G38,G38*F38) -> 0
H39: =IF(F39=0,G39,G39*F39) -> 0
H40: =IF(F40=0,G40,G40*F40) -> 0
H41: =IF(F41=0,G41,G41*F41) -> 0
H42: =IF(F42=0,G42,G42*F42) -> 0
H43: =IF(F43=0,G43,G43*F43) -> 0
H44: =IF(F44=0,G44,G44*F44) -> 0
H45: =IF(F45=0,G45,G45*F45) -> 0
C46: 기타자재 | H46: =IF(F46=0,G46,G46*F46) -> 0
...

Sheet 단위장비7
B1: □ 단위공사명(전기제외): | I1: (첨부)
A2: 구분 | C2: 품 명 | D2: 규격 | E2: 단위 | F2: 수량 | G2: 단가(원) | H2: 금액(원) | I2: 原MAKER
A3: 자 재 비 | B3: 철자재 | H3: =IF(F3=0,G3,G3*F3) -> 0
H4: =IF(F4=0,G4,G4*F4) -> 0
H5: =IF(F5=0,G5,G5*F5) -> 0
H6: =IF(F6=0,G6,G6*F6) -> 0
H7: =IF(F7=0,G7,G7*F7) -> 0
H8: =IF(F8=0,G8,G8*F8) -> 0
H9: =IF(F9=0,G9,G9*F9) -> 0
H10: =IF(F10=0,G10,G10*F10) -> 0
H11: =IF(F11=0,G11,G11*F11) -> 0
H12: =IF(F12=0,G12,G12*F12) -> 0
H13: =IF(F13=0,G13,G13*F13) -> 0
H14: =IF(F14=0,G14,G14*F14) -> 0
H15: =IF(F15=0,G15,G15*F15) -> 0
... H22: =IF(F22=0,G22,G22*F22) -> 0
C23: 기타자재 | H23: =IF(F23=0,G23,G23*F23) -> 0
H24: =SUM(H3:H23) -> 0
B25: 설치/해체/시운전 | H25: =IF(F25=0,G25,G25*F25) -> 0
B26: 공사 관련 자재 | H26: =IF(F26=0,G26,G26*F26) -> 0
H27: =IF(F27=0,G27,G27*F27) -> 0
H28: =IF(F28=0,G28,G28*F28) -> 0
C29: 기타자재 | H29: =IF(F29=0,G29,G29*F29) -> 0
H30: =SUM(H25:H29) -> 0
B31: 구매품 | H31: =IF(F31=0,G31,G31*F31) -> 0
B32: (유공압품외) | H32: =IF(F32=0,G32,G32*F32) -> 0
H33: =IF(F33=0,G33,G33*F33) -> 0
H34: =IF(F34=0,G34,G34*F34) -> 0
H35: =IF(F35=0,G35,G35*F35) -> 0
H36: =IF(F36=0,G36,G36*F36) -> 0
H37: =IF(F37=0,G37,G37*F37) -> 0
H38: =IF(F38=0,G38,G38*F38) -> 0
H39: =IF(F39=0,G39,G39*F39) -> 0
H40: =IF(F40=0,G40,G40*F40) -> 0
H41: =IF(F41=0,G41,G41*F41) -> 0
H42: =IF(F42=0,G42,G42*F42) -> 0
H43: =IF(F43=0,G43,G43*F43) -> 0
H44: =IF(F44=0,G44,G44*F44) -> 0
H45: =IF(F45=0,G45,G45*F45) -> 0
C46: 기타자재 | H46: =IF(F46=0,G46,G46*F46) -> 0
...

Sheet 단위장비8
B1: □ 단위공사명(전기제외): | I1: (첨부)
A2: 구분 | C2: 품 명 | D2: 규격 | E2: 단위 | F2: 수량 | G2: 단가(원) | H2: 금액(원) | I2: 原MAKER
A3: 자 재 비 | B3: 철자재 | H3: =IF(F3=0,G3,G3*F3) -> 0
H4: =IF(F4=0,G4,G4*F4) -> 0
H5: =IF(F5=0,G5,G5*F5) -> 0
H6: =IF(F6=0,G6,G6*F6) -> 0
H7: =IF(F7=0,G7,G7*F7) -> 0
H8: =IF(F8=0,G8,G8*F8) -> 0
H9: =IF(F9=0,G9,G9*F9) -> 0
H10: =IF(F10=0,G10,G10*F10) -> 0
H11: =IF(F11=0,G11,G11*F11) -> 0
H12: =IF(F12=0,G12,G12*F12) -> 0
H13: =IF(F13=0,G13,G13*F13) -> 0
H14: =IF(F14=0,G14,G14*F14) -> 0
H15: =IF(F15=0,G15,G15*F15) -> 0
... H22: =IF(F22=0,G22,G22*F22) -> 0
C23: 기타자재 | H23: =IF(F23=0,G23,G23*F23) -> 0
H24: =SUM(H3:H23) -> 0
B25: 설치/해체/시운전 | H25: =IF(F25=0,G25,G25*F25) -> 0
B26: 공사 관련 자재 | H26: =IF(F26=0,G26,G26*F26) -> 0
H27: =IF(F27=0,G27,G27*F27) -> 0
H28: =IF(F28=0,G28,G28*F28) -> 0
C29: 기타자재 | H29: =IF(F29=0,G29,G29*F29) -> 0
H30: =SUM(H25:H29) -> 0
B31: 구매품 | H31: =IF(F31=0,G31,G31*F31) -> 0
B32: (유공압품외) | H32: =IF(F32=0,G32,G32*F32) -> 0
H33: =IF(F33=0,G33,G33*F33) -> 0
H34: =IF(F34=0,G34,G34*F34) -> 0
H35: =IF(F35=0,G35,G35*F35) -> 0
H36: =IF(F36=0,G36,G36*F36) -> 0
H37: =IF(F37=0,G37,G37*F37) -> 0
H38: =IF(F38=0,G38,G38*F38) -> 0
H39: =IF(F39=0,G39,G39*F39) -> 0
H40: =IF(F40=0,G40,G40*F40) -> 0
H41: =IF(F41=0,G41,G41*F41) -> 0
H42: =IF(F42=0,G42,G42*F42) -> 0
H43: =IF(F43=0,G43,G43*F43) -> 0
H44: =IF(F44=0,G44,G44*F44) -> 0
H45: =IF(F45=0,G45,G45*F45) -> 0
C46: 기타자재 | H46: =IF(F46=0,G46,G46*F46) -> 0
...

Sheet 단위장비9
B1: □ 단위공사명(전기제외): | I1: (첨부)
A2: 구분 | C2: 품 명 | D2: 규격 | E2: 단위 | F2: 수량 | G2: 단가(원) | H2: 금액(원) | I2: 原MAKER
A3: 자 재 비 | B3: 철자재 | H3: =IF(F3=0,G3,G3*F3) -> 0
H4: =IF(F4=0,G4,G4*F4) -> 0
H5: =IF(F5=0,G5,G5*F5) -> 0
H6: =IF(F6=0,G6,G6*F6) -> 0
H7: =IF(F7=0,G7,G7*F7) -> 0
H8: =IF(F8=0,G8,G8*F8) -> 0
H9: =IF(F9=0,G9,G9*F9) -> 0
H10: =IF(F10=0,G10,G10*F10) -> 0
H11: =IF(F11=0,G11,G11*F11) -> 0
H12: =IF(F12=0,G12,G12*F12) -> 0
H13: =IF(F13=0,G13,G13*F13) -> 0
H14: =IF(F14=0,G14,G14*F14) -> 0
H15: =IF(F15=0,G15,G15*F15) -> 0
... H22: =IF(F22=0,G22,G22*F22) -> 0
C23: 기타자재 | H23: =IF(F23=0,G23,G23*F23) -> 0
H24: =SUM(H3:H23) -> 0
B25: 설치/해체/시운전 | H25: =IF(F25=0,G25,G25*F25) -> 0
B26: 공사 관련 자재 | H26: =IF(F26=0,G26,G26*F26) -> 0
H27: =IF(F27=0,G27,G27*F27) -> 0
H28: =IF(F28=0,G28,G28*F28) -> 0
C29: 기타자재 | H29: =IF(F29=0,G29,G29*F29) -> 0
H30: =SUM(H25:H29) -> 0
B31: 구매품 | H31: =IF(F31=0,G31,G31*F31) -> 0
B32: (유공압품외) | H32: =IF(F32=0,G32,G32*F32) -> 0
H33: =IF(F33=0,G33,G33*F33) -> 0
H34: =IF(F34=0,G34,G34*F34) -> 0
H35: =IF(F35=0,G35,G35*F35) -> 0
H36: =IF(F36=0,G36,G36*F36) -> 0
H37: =IF(F37=0,G37,G37*F37) -> 0
H38: =IF(F38=0,G38,G38*F38) -> 0
H39: =IF(F39=0,G39,G39*F39) -> 0
H40: =IF(F40=0,G40,G40*F40) -> 0
H41: =IF(F41=0,G41,G41*F41) -> 0
H42: =IF(F42=0,G42,G42*F42) -> 0
H43: =IF(F43=0,G43,G43*F43) -> 0
H44: =IF(F44=0,G44,G44*F44) -> 0
H45: =IF(F45=0,G45,G45*F45) -> 0
C46: 기타자재 | H46: =IF(F46=0,G46,G46*F46) -> 0
...

Sheet 단위장비10
B1: □ 단위공사명(전기제외): | I1: (첨부)
A2: 구분 | C2: 품 명 | D2: 규격 | E2: 단위 | F2: 수량 | G2: 단가(원) | H2: 금액(원) | I2: 原MAKER
A3: 자 재 비 | B3: 철자재 | H3: =IF(F3=0,G3,G3*F3) -> 0
H4: =IF(F4=0,G4,G4*F4) -> 0
H5: =IF(F5=0,G5,G5*F5) -> 0
H6: =IF(F6=0,G6,G6*F6) -> 0
H7: =IF(F7=0,G7,G7*F7) -> 0
H8: =IF(F8=0,G8,G8*F8) -> 0
H9: =IF(F9=0,G9,G9*F9) -> 0
H10: =IF(F10=0,G10,G10*F10) -> 0
H11: =IF(F11=0,G11,G11*F11) -> 0
H12: =IF(F12=0,G12,G12*F12) -> 0
H13: =IF(F13=0,G13,G13*F13) -> 0
H14: =IF(F14=0,G14,G14*F14) -> 0
H15: =IF(F15=0,G15,G15*F15) -> 0
... H22: =IF(F22=0,G22,G22*F22) -> 0
C23: 기타자재 | H23: =IF(F23=0,G23,G23*F23) -> 0
H24: =SUM(H3:H23) -> 0
B25: 설치/해체/시운전 | H25: =IF(F25=0,G25,G25*F25) -> 0
B26: 공사 관련 자재 | H26: =IF(F26=0,G26,G26*F26) -> 0
H27: =IF(F27=0,G27,G27*F27) -> 0
H28: =IF(F28=0,G28,G28*F28) -> 0
C29: 기타자재 | H29: =IF(F29=0,G29,G29*F29) -> 0
H30: =SUM(H25:H29) -> 0
B31: 구매품 | H31: =IF(F31=0,G31,G31*F31) -> 0
B32: (유공압품외) | H32: =IF(F32=0,G32,G32*F32) -> 0
H33: =IF(F33=0,G33,G33*F33) -> 0
H34: =IF(F34=0,G34,G34*F34) -> 0
H35: =IF(F35=0,G35,G35*F35) -> 0
H36: =IF(F36=0,G36,G36*F36) -> 0
H37: =IF(F37=0,G37,G37*F37) -> 0
H38: =IF(F38=0,G38,G38*F38) -> 0
H39: =IF(F39=0,G39,G39*F39) -> 0
H40: =IF(F40=0,G40,G40*F40) -> 0
H41: =IF(F41=0,G41,G41*F41) -> 0
H42: =IF(F42=0,G42,G42*F42) -> 0
H43: =IF(F43=0,G43,G43*F43) -> 0
H44: =IF(F44=0,G44,G44*F44) -> 0
H45: =IF(F45=0,G45,G45*F45) -> 0
C46: 기타자재 | H46: =IF(F46=0,G46,G46*F46) -> 0
...

Sheet 첨부(견적조건차이내역)
A1: ※ 현대/기아차의 요구사양과 업체견적사양이 다른경우만 작성
D2: (첨부)
A3: 현대/기아차 요구사양대비 견적조건 상이내역
A5: 항 목 | B5: 현대/기아차 요구사양 | C5: 업체 견적기준 사양 | D5: 비 고
