Workbook

Sheet 갑지
B1: (현대/기아차 설비협력업체 견적통일양식)
B2: 見 積 書
B4: 현대위아(주) 貴下 | G4: ㈜에스엠이노베이션
B5: 견적일자 | D5: 45012 | G5: 대표 : 박 종 근 (인)
B6: 견적번호 | D6: SM2023032701 | G6: 주소 : 경북칠곡군 왜관읍 아곡7길 16-11
B7: 납기 | C7: 입하 | D7: 발주 후 6개월 | G7: 전화: 054-976-3842~3
C8: 최종검수 | G8: Fax: 054-971-3843
B9: 견적유효기간 | D9: 견적일로부터30일 | G9: E-mail:smibiz@smiwbw.com
B10: 인도장소 | D10: 부산항(FOB) | G10: 견적담당: 강 규 태 상무
B11: 담 당 자 | D11: 차량부품생산기술팀/라진영 책임매니저 님 | G11: 연 락 처 : 010-2525-5112
B13: 공 사 명: | D13: 멕시코 볼보 SPA2 전기차 CVJ 세척기
B14: 최종견적금액: | D14: 一金삼억육천만원整(\360,000,000) VAT.별도
B16: 번호 | C16: 상세품목내역 | E16: 견적금액 (천원) | I16: 비 고
E17: 기계부문 | F17: 전기부문 | G17: 관리/이윤 (안전관리비포함) | H17: 합 계
B18: 1 | C18: CVJ 세척기 | E18: =IF('단위공사별(집계)'!N7>1,('단위공사별(집계)'!D7+'단위공사별(집계)'!E7+'단위공사별(집계)'!F7+'단위공사별(집계)'!G7+'단위공사별(집계)'!H7+'단위공사별(집계)'!I7)/1000," ") -> 253750 | F18: =IF('단위공사별(집계)'!N7>0,'단위공사별(집계)'!K17/1000,"") -> 57450 | G18: =IF('단위공사별(집계)'!N7>0,('단위공사별(집계)'!L7+'단위공사별(집계)'!M7)/1000,"") -> 27800 | H18: =IF('단위공사별(집계)'!N7>0,'단위공사별(집계)'!N7/1000,"") -> 339000
B19: 2 | C19: - UL 인증비 | E19: 0 | F19: 0 | G19: 0 | H19: =SUM(E19:G19) -> 0
B20: 3 | C20: - 현지 경비(2인x30일) | E20: 6000 | F20: 6000 | G20: 0 | H20: =SUM(E20:G20) -> 12000
B21: 4 | C21: - 항공권 外이동경비 | E21: 4500 | F21: 4500 | G21: 0 | H21: =SUM(E21:G21) -> 9000
B22: 5 | C22: (2인X1회)
B23: 6
B24: 7
B25: 8
B26: 9
B27: 10
B28: 견적 합계 | E28: =SUM(E18:E27) -> 264250 | F28: =SUM(F18:F24) -> 67950 | G28: =SUM(G18:G24) -> 27800 | H28: =SUM(H18:H27) -> 360000
F30: 공개입찰가 (견적時 공란)
B32: 특기사항 | C32: 1. VAT 제외 | F32: 외주계획 업체명 (자작時 공란)
C33: 2. 기본 유틸리티공사 제외 | F33: 설계외주
F34: 제작외주
F35: 전기외주
F36: 설치외주

Sheet 원가항목별(집계)
C2: A. 원가항목별 견적가 종합(상세견적 첨부)
B4: □ 현대/기아 요구사양과 견적조건 일치여부 CHECK: 1.일치함 2.일부상이(상이내역 첨부참조)
B6: 순번 | C6: 원가구분 | F6: 단위 | G6: 수량 | H6: 단가 | I6: 금 액(원) | J6: 비 고
B7: 1 | C7: 기계 부문 | D7: 자재비 | E7: 철자재(SS.SUS등) | F7: kg | G7: 1 | I7: =세척기!H40 -> 107300000
E8: 일반구매품 | F8: 식 | G8: 1 | I8: =세척기!H64 -> 61200000
E9: 외주제작품 | F9: 식 | G9: 1 | I9: =세척기!H75 -> 2500000
E10: 설치/해체 공사 자재 | F10: 식 | G10: 1 | I10: =세척기!H46 -> 0
E11: 소계 | I11: =SUM(I7:I10) -> 171000000
D12: 노무비 | E12: 기존설비 철거 | F12: M/D | G12: =세척기!F77 -> 0 | H12: =IF(세척기!G77>0,세척기!G77,"") | I12: =세척기!H77 -> 0
E13: 설계 | F13: M/D | G13: =세척기!F78 -> 50 | H13: =IF(세척기!G78>0,세척기!G78,"") -> 300000 | I13: =세척기!H78 -> 15000000
E14: 제작(제관,가공) | F14: M/D | G14: =세척기!F79 -> 0 | H14: =IF(세척기!G79>0,세척기!G79,"") | I14: =세척기!H79 -> 0
E15: 조립 | F15: M/D | G15: =세척기!F80 -> 125 | H15: =IF(세척기!G80>0,세척기!G80,"") -> 300000 | I15: =세척기!H80 -> 37500000
E16: 설치 | F16: M/D | G16: =세척기!F81 -> 3 | H16: =IF(세척기!G81>0,세척기!G81,"") -> 450000 | I16: =세척기!H81 -> 1350000
E17: 시운전 | F17: M/D | G17: =세척기!F82 -> 15 | H17: =IF(세척기!G82>0,세척기!G82,"") -> 450000 | I17: =세척기!H82 -> 6750000
E18: 양산대응 | F18: M/D | G18: =세척기!F83 -> 7 | H18: =IF(세척기!G83>0,세척기!G83,"") -> 450000 | I18: =세척기!H83 -> 3150000
E19: 도장 | F19: M/D | G19: =세척기!F84 -> 1 | H19: =IF(세척기!G84>0,세척기!G84,"") -> 3000000 | I19: =세척기!H84 -> 3000000
E20: 소계 | I20: =SUM(I12:I19) -> 66750000
D21: 일반관리 및 이윤 | I21: =세척기!H87+세척기!H88 -> 27800000
E22: 기계 소계 | I22: =I20+I11+I21 -> 265550000
B23: 2 | C23: 전기 부문 | D23: 자재비 | E23: 기계/전기자재 | F23: 식 | G23: 1 | I23: =전기!H54-I24 -> 26900000
E24: 설치/해체 공사 자재 | F24: 식 | G24: 1 | I24: =전기!H16 -> 0 | J24: 시운전 자재 포함
D25: 노무비 | E25: 철거(개조시) | F25: M/D | G25: =전기!F55 -> 0 | H25: =IF(전기!G55>0,전기!G55,"") | I25: =전기!H55 -> 0
E26: 설계,프로그램 | F26: M/D | G26: =전기!F56 -> 10 | H26: =IF(전기!G56>0,전기!G56,"") -> 300000 | I26: =전기!H56 -> 3000000
E27: 제작 | F27: M/D | G27: =전기!F57 -> 10 | H27: =IF(전기!G57>0,전기!G57,"") -> 300000 | I27: =전기!H57 -> 3000000
E28: 조립 | F28: M/D | G28: =전기!F58 -> 35 | H28: =IF(전기!G58>0,전기!G58,"") -> 300000 | I28: =전기!H58 -> 10500000
E29: 설치 | F29: M/D | G29: =전기!F59 -> 0 | H29: =IF(전기!G59>0,전기!G59,"") -> 300000 | I29: =전기!H59 -> 0
E30: 시운전 | F30: M/D | G30: =전기!F60 -> 18 | H30: =IF(전기!G60>0,전기!G60,"") -> 450000 | I30: =전기!H60 -> 8100000
E31: 양산대응 | F31: M/D | G31: =전기!F61 -> 7 | H31: =IF(전기!G61>0,전기!G61,"") -> 450000 | I31: =전기!H61 -> 3150000
E32: 소계 | I32: =SUM(I25:I31) -> 27750000
D33: 일반관리 및 이윤 | I33: =전기!H64+전기!H65 -> 2800000
E34: 전기 소계 | I34: =I32+I23+I33+I24 -> 57450000
B35: 3 | C35: 자재비 합계 | I35: =I23+I11+I24 -> 197900000
C36: 노무비 합계 | I36: =I32+I20 -> 94500000
C37: 중간 합계 | I37: =I36+I35 -> 292400000
B38: 4 | C38: 포장,운송 및 중장비 사용료 | I38: 16000000
B39: 5 | C39: 표준안전관리비 | F39: 설치/철거/수리금액 기준 | I39: 0
B40: 6 | C40: 일반관리비 | I40: =전기!H64+세척기!H87 -> 15300000
B41: 7 | C41: 이 윤 | I41: =전기!H65+세척기!H88 -> 15300000
C42: 합 계 | F42: 3~7항 합계 | I42: =I22+I34+I38+I39 -> 339000000
B43: 주1. 표준안전관리비:(설치/철거/시운전 공사 관련 금액)의 ⓐ2.66%,ⓑ1.95%+기초액,ⓒ2.02%(50억 이상일경우)
...

Sheet 단위공사별(집계)
A2: B. 단위장비별 견적가 종합(상세견적 첨부)
N3: 단위:원
I5: 포장/운송 | L5: 표준안전 | M5: 일반관리비
A6: 순번 | B6: 단위장비명 | C6: 수량 | D6: 자재비 | E6: 철거 | F6: 제작 | G6: 설치/시운전 | H6: 양산대응 | I6: 중장비사용 | J6: 기계소계 | K6: 전기소계 | L6: 관리비 | M6: 이윤 | N6: 합 계 | O6: 비 고
A7: =IF(B7>0,1,"") -> 1 | B7: CVJ 세척기 | C7: 1식 | D7: =세척기!H76 -> 171000000 | E7: =세척기!H77 -> 0 | F7: =세척기!H78+세척기!H79+세척기!H80+세척기!H84 -> 55500000 | G7: =세척기!H81+세척기!H82 -> 8100000 | H7: =세척기!H83 -> 3150000 | I7: =IF($B7>0,'원가항목별(집계)'!I$38*$P7/$P$17,0) -> 16000000 | J7: =SUM(D7:I7) -> 253750000 | K7: =IF(B7>0,'원가항목별(집계)'!I$34*P7/P$17,0) -> 57450000 | L7: =IF($B7>0,'원가항목별(집계)'!I$39*$P7/$P$17,0) -> 0 | M7: =세척기!H87+세척기!H88 -> 27800000 | N7: =SUM(J7:M7) -> 339000000 | P7: =D7+E7+F7+G7+H7+M7 -> 265550000
A8: =IF(B8>0,A7+1,"") | I8: =IF($B8>0,'원가항목별(집계)'!I$38*$P8/$P$17,0) -> 0 | J8: =SUM(D8:I8) -> 0 | K8: =IF(B8>0,'원가항목별(집계)'!I$34*P8/P$17,0) -> 0 | L8: =IF($B8>0,'원가항목별(집계)'!I$39*$P8/$P$17,0) -> 0 | N8: =SUM(J8:M8) -> 0 | P8: =D8+E8+F8+G8+H8+M8 -> 0
A9: =IF(B9>0,A8+1,"") | I9: =IF($B9>0,'원가항목별(집계)'!I$38*$P9/$P$17,0) -> 0 | J9: =SUM(D9:I9) -> 0 | K9: =IF(B9>0,'원가항목별(집계)'!I$34*P9/P$17,0) -> 0 | L9: =IF($B9>0,'원가항목별(집계)'!I$39*$P9/$P$17,0) -> 0 | N9: =SUM(J9:M9) -> 0 | P9: =D9+E9+F9+G9+H9+M9 -> 0
A10: =IF(B10>0,A9+1,"") | I10: =IF($B10>0,'원가항목별(집계)'!I$38*$P10/$P$17,0) -> 0 | J10: =SUM(D10:I10) -> 0 | K10: =IF(B10>0,'원가항목별(집계)'!I$34*P10/P$17,0) -> 0 | L10: =IF($B10>0,'원가항목별(집계)'!I$39*$P10/$P$17,0) -> 0 | N10: =SUM(J10:M10) -> 0 | P10: =D10+E10+F10+G10+H10+M10 -> 0
A11: =IF(B11>0,A10+1,"") | I11: =IF($B11>0,'원가항목별(집계)'!I$38*$P11/$P$17,0) -> 0 | J11: =SUM(D11:I11) -> 0 | K11: =IF(B11>0,'원가항목별(집계)'!I$34*P11/P$17,0) -> 0 | L11: =IF($B11>0,'원가항목별(집계)'!I$39*$P11/$P$17,0) -> 0 | N11: =SUM(J11:M11) -> 0 | P11: =D11+E11+F11+G11+H11+M11 -> 0
A12: =IF(B12>0,A11+1,"") | I12: =IF($B12>0,'원가항목별(집계)'!I$38*$P12/$P$17,0) -> 0 | J12: =SUM(D12:I12) -> 0 | K12: =IF(B12>0,'원가항목별(집계)'!I$34*P12/P$17,0) -> 0 | L12: =IF($B12>0,'원가항목별(집계)'!I$39*$P12/$P$17,0) -> 0 | N12: =SUM(J12:M12) -> 0 | P12: =D12+E12+F12+G12+H12+M12 -> 0
A13: =IF(B13>0,A8+1,"") | I13: =IF($B13>0,'원가항목별(집계)'!I$38*$P13/$P$17,0) -> 0 | J13: =SUM(D13:I13) -> 0 | K13: =IF(B13>0,'원가항목별(집계)'!I$34*P13/P$17,0) -> 0 | L13: =IF($B13>0,'원가항목별(집계)'!I$39*$P13/$P$17,0) -> 0 | N13: =SUM(J13:M13) -> 0 | P13: =D13+E13+F13+G13+H13+M13 -> 0
A14: =IF(B14>0,A13+1,"") | I14: =IF($B14>0,'원가항목별(집계)'!I$38*$P14/$P$17,0) -> 0 | J14: =SUM(D14:I14) -> 0 | K14: =IF(B14>0,'원가항목별(집계)'!I$34*P14/P$17,0) -> 0 | L14: =IF($B14>0,'원가항목별(집계)'!I$39*$P14/$P$17,0) -> 0 | N14: =SUM(J14:M14) -> 0 | P14: =D14+E14+F14+G14+H14+M14 -> 0
A15: =IF(B15>0,A14+1,"") | I15: =IF($B15>0,'원가항목별(집계)'!I$38*$P15/$P$17,0) -> 0 | J15: =SUM(D15:I15) -> 0 | K15: =IF(B15>0,'원가항목별(집계)'!I$34*P15/P$17,0) -> 0 | L15: =IF($B15>0,'원가항목별(집계)'!I$39*$P15/$P$17,0) -> 0 | N15: =SUM(J15:M15) -> 0 | P15: =D15+E15+F15+G15+H15+M15 -> 0
A16: =IF(B16>0,A15+1,"") | I16: =IF($B16>0,'원가항목별(집계)'!I$38*$P16/$P$17,0) -> 0 | J16: =SUM(D16:I16) -> 0 | K16: =IF(B16>0,'원가항목별(집계)'!I$34*P16/P$17,0) -> 0 | L16: =IF($B16>0,'원가항목별(집계)'!I$39*$P16/$P$17,0) -> 0 | N16: =SUM(J16:M16) -> 0 | P16: =D16+E16+F16+G16+H16+M16 -> 0
A17: 합 계 | D17: =SUM(D7:D16) -> 171000000 | E17: =SUM(E7:E16) -> 0 | F17: =SUM(F7:F16) -> 55500000 | G17: =SUM(G7:G16) -> 8100000 | H17: =SUM(H7:H16) -> 3150000 | I17: =SUM(I7:I16) -> 16000000 | J17: =SUM(D17:I17) -> 253750000 | K17: =SUM(K7:K16) -> 57450000 | L17: =SUM(L7:L16) -> 0 | M17: =SUM(M7:M16) -> 27800000 | N17: =SUM(N7:N14) -> 339000000 | P17: =D17+E17+F17+G17+H17+M17 -> 265550000
D18: =IF(D17=0,"",D17/$N17) -> 0.50442478 | E18: =IF(E17=0,"",E17/$N17) | F18: =IF(F17=0,"",F17/$N17) -> 0.16371681 | G18: =IF(G17=0,"",G17/$N17) -> 0.023893805 | H18: =IF(H17=0,"",H17/$N17) -> 0.0092920354 | I18: =IF(I17=0,"",I17/$N17) -> 0.04719764 | J18: =IF(J17=0,"",J17/$N17) -> 0.74852507 | K18: =IF(K17=0,"",K17/$N17) -> 0.16946903 | ... N18: =IF(N17=0,"",N17/$N17) -> 1
A19: 주) 전기비용은 턴키장비의 공통비용으로서 총 전기비용을 단위장비별 기계금액의 비율에 따라 배분함

Sheet 전기
B1: □ 전기부문: | C1: 전기부문(공통) | I1: (첨부)
A2: 구분 | C2: 품 명 | D2: 규격 | E2: 단위 | F2: 수량 | G2: 단가(원) | H2: 금액(원) | I2: 原MAKER
A3: 자 재 비 | B3: 철자재 | C3: TB BOX | E3: SET | F3: 1 | G3: 1600000 | H3: =IF(F3=0,G3,G3*F3) -> 1600000
C4: 과열 방지 회로구성 | E4: SET | F4: 1 | G4: 300000 | H4: =IF(F4=0,G4,G4*F4) -> 300000
H5: =IF(F5=0,G5,G5*F5) -> 0
H6: =IF(F6=0,G6,G6*F6) -> 0
H7: =IF(F7=0,G7,G7*F7) -> 0
H8: =IF(F8=0,G8,G8*F8) -> 0
H9: =SUM(H3:H8) -> 1900000
B10: 설치/해체/ | H10: =IF(F10=0,G10,G10*F10) -> 0
B11: 시운전 공사 | H11: =IF(F11=0,G11,G11*F11) -> 0
B12: 자재 | H12: =IF(F12=0,G12,G12*F12) -> 0
H13: =IF(F13=0,G13,G13*F13) -> 0
H14: =IF(F14=0,G14,G14*F14) -> 0
B15: ` | C15: 기타자재 | H15: =IF(F15=0,G15,G15*F15) -> 0
H16: =SUM(H10:H15) -> 0
B17: 전기자재 | C17: PLC UNIT , TOUCH | D17: SIEMENS | E17: SET | F17: 1 | G17: 8000000 | H17: =IF(F17=0,G17,G17*F17) -> 8000000
C18: MAIN PANNEL | D18: RITTAL | E18: SET | F18: 1 | G18: 10000000 | H18: =IF(F18=0,G18,G18*F18) -> 10000000
C19: SENSOR UNIT | E19: SET | F19: 1 | G19: 4000000 | H19: =IF(F19=0,G19,G19*F19) -> 4000000
C20: LOCAL CABLE, 커넥터 | E20: SET | F20: 1 | G20: 3000000 | H20: =IF(F20=0,G20,G20*F20) -> 3000000
H21: =IF(F21=0,G21,G21*F21) -> 0
H22: =IF(F22=0,G22,G22*F22) -> 0
H23: =IF(F23=0,G23,G23*F23) -> 0
H24: =IF(F24=0,G24,G24*F24) -> 0
H25: =IF(F25=0,G25,G25*F25) -> 0
H26: =IF(F26=0,G26,G26*F26) -> 0
H27: =IF(F27=0,G27,G27*F27) -> 0
H28: =IF(F28=0,G28,G28*F28) -> 0
H29: =IF(F29=0,G29,G29*F29) -> 0
H30: =IF(F30=0,G30,G30*F30) -> 0
H31: =IF(F31=0,G31,G31*F31) -> 0
H32: =IF(F32=0,G32,G32*F32) -> 0
... H41: =IF(F41=0,G41,G41*F41) -> 0
H42: =SUM(H17:H41) -> 25000000
B43: 프로그램 | H43: =IF(F43=0,G43,G43*F43) -> 0
H44: =IF(F44=0,G44,G44*F44) -> 0
H45: =IF(F45=0,G45,G45*F45) -> 0
H46: =IF(F46=0,G46,G46*F46) -> 0
H47: =IF(F47=0,G47,G47*F47) -> 0
H48: =IF(F48=0,G48,G48*F48) -> 0
...

Sheet 세척기
B1: □ 단위공사명(전기제외): | C1: CVJ 세척기 | I1: (첨부)
A2: 구분 | C2: 품 명 | D2: 규격 | E2: 단위 | F2: 수량 | G2: 단가(원) | H2: 금액(원) | I2: 原MAKER
A3: 자 재 비 | B3: 철자재 | C3: ROOM CHAMBER & FRAME | D3: SS41/ SUS | E3: SET | F3: 1 | G3: 15000000 | H3: =IF(F3=0,G3,G3*F3) -> 15000000
C4: 입출구 AUTO DOOR | E4: SET | F4: 2 | G4: 700000 | H4: =IF(F4=0,G4,G4*F4) -> 1400000
C5: 공정 AUTO DOOR | E5: SET | F5: 3 | G5: 600000 | H5: =IF(F5=0,G5,G5*F5) -> 1800000
C6: 공정 하부 AUTO DOOR | E6: SET | F6: 3 | G6: 600000 | H6: =IF(F6=0,G6,G6*F6) -> 1800000
C7: 점검창 | E7: SET | F7: 4 | G7: 550000 | H7: =IF(F7=0,G7,G7*F7) -> 2200000
C8: 후면 COVER | E8: SET | F8: 1 | G8: 4000000 | H8: =IF(F8=0,G8,G8*F8) -> 4000000
C9: WASH`G TANK | D9: C/T:400L , D/T : 600L | E9: SET | F9: 1 | G9: 6000000 | H9: =IF(F9=0,G9,G9*F9) -> 6000000
C10: 흡음 COVER | D10: SUS타공판 | E10: SET | F10: 1 | G10: 400000 | H10: =IF(F10=0,G10,G10*F10) -> 400000
C11: 배관재 | D11: 방청유 & AIR | E11: 식 | F11: 1 | G11: 2500000 | H11: =IF(F11=0,G11,G11*F11) -> 2500000
C12: INDEX 구동부 UNIT | E12: SET | F12: 1 | G12: 4000000 | H12: =IF(F12=0,G12,G12*F12) -> 4000000
C13: INDEX SHAFT UNIT | E13: SET | F13: 1 | G13: 3500000 | H13: =IF(F13=0,G13,G13*F13) -> 3500000
C14: INDEX TABLE UNIT | E14: SET | F14: 1 | G14: 4000000 | H14: =IF(F14=0,G14,G14*F14) -> 4000000
C15: INDEX JIG | E15: SET | F15: 5 | G15: 1000000 | H15: =IF(F15=0,G15,G15*F15) -> 5000000
C16: JIG SUB TABLE 및 WORK JIG | E16: SET | F16: 5 | G16: 2500000 | H16: =IF(F16=0,G16,G16*F16) -> 12500000
C17: 작업자 발판 | D17: F.L+600mm | E17: SET | F17: 1 | G17: 2000000 | H17: =IF(F17=0,G17,G17*F17) -> 2000000
C18: 안전펜스 | E18: SET | F18: 1 | G18: 1000000 | H18: =IF(F18=0,G18,G18*F18) -> 1000000
C19: W/NOZZLE | D19: SUS | E19: SET | F19: 20 | G19: 5000 | H19: =IF(F19=0,G19,G19*F19) -> 100000
C20: W/NOZZLE CHAMBER | E20: SET | F20: 1 | G20: 2000000 | H20: =IF(F20=0,G20,G20*F20) -> 2000000
C21: W/NOZZLE TURNING UNIT | E21: SET | F21: 1 | G21: 2500000 | H21: =IF(F21=0,G21,G21*F21) -> 2500000
C22: A/NOZZLE | D22: SUS | E22: SET | F22: 50 | G22: 60000 | H22: =IF(F22=0,G22,G22*F22) -> 3000000
C23: A/NOZZLE CHAMBER | E23: SET | F23: 1 | G23: 2000000 | H23: =IF(F23=0,G23,G23*F23) -> 2000000
C24: A/NOZZLE TURNING UNIT | E24: SET | F24: 1 | G24: 2500000 | H24: =IF(F24=0,G24,G24*F24) -> 2500000
C25: BAG FILTER | D25: 200L-50u | E25: SET | F25: 2 | G25: 2000000 | H25: =IF(F25=0,G25,G25*F25) -> 4000000
C26: MESH BASKET | D26: SUS #40 | E26: SET | F26: 1 | G26: 600000 | H26: =IF(F26=0,G26,G26*F26) -> 600000
C27: FLOAT S/W | E27: SET | F27: 2 | G27: 200000 | H27: =IF(F27=0,G27,G27*F27) -> 400000
C28: KINFE NOZZLE | E28: SET | F28: 1 | G28: 2000000 | H28: =IF(F28=0,G28,G28*F28) -> 2000000
C29: 단열 작업 | E29: SET | F29: 1 | G29: 300000 | H29: =IF(F29=0,G29,G29*F29) -> 300000
C30: 방청 NOZZLE | D30: 고정식 | E30: 식 | F30: 9 | G30: 400000 | H30: =IF(F30=0,G30,G30*F30) -> 3600000
C31: MESH BASCKET(방청) | E31: SET | F31: 1 | G31: 500000 | H31: =IF(F31=0,G31,G31*F31) -> 500000
C32: FLOAT S/W(방청) | E32: SET | F32: 1 | G32: 200000 | H32: =IF(F32=0,G32,G32*F32) -> 200000
C33: 방청 TANK | D33: 200L/min | E33: SET | F33: 1 | G33: 3000000 | H33: =IF(F33=0,G33,G33*F33) -> 3000000
C34: 전기 DUCT | D34: STEEL, 경첩 TYPE | E34: SET | F34: 1 | G34: 2000000 | H34: =IF(F34=0,G34,G34*F34) -> 2000000
C35: 범용 트롤리 | E35: SRT | F35: 1 | G35: 3000000 | H35: =IF(F35=0,G35,G35*F35) -> 3000000
C36: 페수처리 TANK | E36: 식 | F36: 2 | G36: 2000000 | H36: =IF(F36=0,G36,G36*F36) -> 4000000
C37: JIG 보관함 | E37: 식 | F37: 1 | G37: 1000000 | H37: =IF(F37=0,G37,G37*F37) -> 1000000
C38: 생산 SPARE | D38: 보전 SPARE 제외 | E38: 식 | F38: 1 | G38: 1500000 | H38: =IF(F38=0,G38,G38*F38) -> 1500000
C39: 매뉴얼&교육자료 | D39: 매뉴얼(영어),교육자료(현지어) | E39: 식 | F39: 1 | G39: 2000000 | H39: =IF(F39=0,G39,G39*F39) -> 2000000
H40: =SUM(H3:H39) -> 107300000
...

Sheet 첨부(견적조건차이내역)
A1: ※ 현대/기아차의 요구사양과 업체견적사양이 다른경우만 작성
D2: (첨부)
A3: 현대/기아차 요구사양대비 견적조건 상이내역
A5: 항 목 | B5: 현대/기아차 요구사양 | C5: 업체 견적기준 사양 | D5: 비 고
