Workbook

Sheet 갑지
B1: (현대/기아차 설비협력업체 견적통일양식)
B2: 見 積 書
B4: 현대 위아 貴下 | G4: 한국덴끼고교
B5: 견적일자 | D5: 45820 | G5: 대표 : 조덕기
B6: 견적번호 | D6: 205-240910-1 | G6: 주소 : 인천시 남동구 남동동로 33
B7: 납기 | C7: 입하 | D7: 2025 년 7 월 3 일
C8: 최종검수 | D8: 2024 년 7 월 30 일 | G8: 전화:
B9: 견적유효기간 | D9: 제출후 30 일 | G9: Fax:
B10: 인도장소 | D10: 귀사 지정장소 | G10: 견적담당: | H10: 김도훈
B11: 지불조건 | D11: 협의사항 | G11: 연 락 처 : | H11: 010-8297-0768
B13: 견적금액 | D13: ="一金"&NUMBERSTRING(H27,1)&"원整" -> 一金구천구백오십만원整 | G13: =H27 -> 99500000 | I13: )
B15: 번호 | C15: 상세품목내역 | E15: 견적금액 (천원) | I15: 비 고
E16: 수량 | F16: 단위 | G16: 전기+단위 | H16: 합 계
B17: 1 | C17: 고주파열처리기 개조(전기) | E17: 1 | G17: =전기!H67 -> 47150000 | H17: =E17*G17 -> 47150000
B18: 2 | C18: 고주파열처리기 개조(기계) | E18: 1 | G18: =단위장비1!H54 -> 52350000 | H18: =E18*G18 -> 52350000
B19: 3
B20: 4
B21: 5
B22: 6
B23: 7
B24: 8
B25: 9
B26: 10
B27: 견적 합계 | E27: =SUM(E17:E23) -> 2 | F27: =SUM(F17:F23) -> 0 | G27: =SUM(G17:G23) -> 99500000 | H27: =SUM(H17:H18) -> 99500000
F29: 공개입찰가 (견적時 공란)
B31: 특기사항 | C31: 1. VAT 제외 | F31: 외주계획 업체명 (자작時 공란)
C32: 2. 기본 유틸리티공사 제외 | F32: 설계외주
C33: ='원가항목별(집계)'!I39 -> 0 | F33: 제작외주
F34: 전기외주
F35: 설치외주
L44: =전기!H67+단위장비1!H54+단위장비2!H69+단위장비3!H69+단위장비5!H68+단위장비4!H69+단위장비6!H69+단위장비7!H69+단위장비8!H69+단위장비9!H69+단위장비10!H69 -> 99500000

Sheet 원가항목별(집계)
C2: A. 원가항목별 견적가 종합(상세견적 첨부)
B4: □ 현대/기아 요구사양과 견적조건 일치여부 CHECK: 1.일치함 2.일부상이(상이내역 첨부참조)
B6: 순번 | C6: 원가구분 | F6: 단위 | G6: 수량 | H6: 단가 | I6: 금 액(원) | J6: 비 고
B7: 1 | C7: 기계 부문 | D7: 자재비 | E7: 철자재(SS.SUS등) | F7: kg | G7: =단위장비1!F16+단위장비2!F30+단위장비3!F30+단위장비5!F29+단위장비4!F30+단위장비6!F30+단위장비7!F30+단위장비8!F30+단위장비9!F30+단위장비10!F30 -> 0 | I7: =단위장비1!H10+단위장비2!H24+단위장비3!H24+단위장비5!H23+단위장비4!H24+단위장비6!H24+단위장비7!H24+단위장비8!H24+단위장비9!H24+단위장비10!H24 -> 0 | J7: 加工必要資材
E8: 일반구매품 | F8: 식 | G8: 1 | I8: =단위장비1!H32+단위장비2!H47+단위장비3!H47+단위장비5!H46+단위장비4!H47+단위장비6!H47+단위장비7!H47+단위장비8!H47+단위장비9!H47+단위장비10!H47 -> 0 | J8: 加工不要資材
E9: 외주제작품 | F9: 식 | G9: 1 | I9: =단위장비1!H40+단위장비2!H55+단위장비3!H55+단위장비5!H54+단위장비4!H55+단위장비6!H55+단위장비7!H55+단위장비8!H55+단위장비9!H55+단위장비10!H55 -> 0 | J9: 旣加工SUB資材
E10: 설치/해체 공사 자재 | F10: 식 | G10: 1 | I10: =단위장비1!H16+단위장비2!H30+단위장비3!H30+단위장비5!H29+단위장비4!H30+단위장비6!H30+단위장비7!H30+단위장비8!H30+단위장비9!H30+단위장비10!H30 -> 0 | J10: 시운전 자재 포함
E11: 소계 | I11: =SUM(I7:I10) -> 0
D12: 노무비 | E12: 기존설비 철거 | F12: M/D | G12: =단위장비1!F42+단위장비2!F57+단위장비3!F57+단위장비5!F56+단위장비4!F57+단위장비6!F57+단위장비7!F57+단위장비8!F57+단위장비9!F57+단위장비10!F57 -> 0 | H12: =IF(단위장비1!G42>0,단위장비1!G42,"") | I12: =단위장비1!H42+단위장비2!H57+단위장비3!H57+단위장비5!H56+단위장비4!H57+단위장비6!H57+단위장비7!H57+단위장비8!H57+단위장비9!H57+단위장비10!H57 -> 0 | J12: 개조공사時
E13: 설계 | F13: M/D | G13: =단위장비1!F43+단위장비2!F58+단위장비3!F58+단위장비5!F57+단위장비4!F58+단위장비6!F58+단위장비7!F58+단위장비8!F58+단위장비9!F58+단위장비10!F58 -> 0 | H13: =IF(단위장비1!G43>0,단위장비1!G43,"") | I13: =단위장비1!H43+단위장비2!H58+단위장비3!H58+단위장비5!H57+단위장비4!H58+단위장비6!H58+단위장비7!H58+단위장비8!H58+단위장비9!H58+단위장비10!H58 -> 0
E14: 제작(제관,가공) | F14: M/D | G14: =단위장비1!F44+단위장비2!F59+단위장비3!F59+단위장비5!F58+단위장비4!F59+단위장비6!F59+단위장비7!F59+단위장비8!F59+단위장비9!F59+단위장비10!F59 -> 0 | H14: =IF(단위장비1!G44>0,단위장비1!G44,"") | I14: =단위장비1!H44+단위장비2!H59+단위장비3!H59+단위장비5!H58+단위장비4!H59+단위장비6!H59+단위장비7!H59+단위장비8!H59+단위장비9!H59+단위장비10!H59 -> 0
E15: 조립 | F15: M/D | G15: =단위장비1!F45+단위장비2!F60+단위장비3!F60+단위장비5!F59+단위장비4!F60+단위장비6!F60+단위장비7!F60+단위장비8!F60+단위장비9!F60+단위장비10!F60 -> 0 | H15: =IF(단위장비1!G45>0,단위장비1!G45,"") | I15: =단위장비1!H45+단위장비2!H60+단위장비3!H60+단위장비5!H59+단위장비4!H60+단위장비6!H60+단위장비7!H60+단위장비8!H60+단위장비9!H60+단위장비10!H60 -> 0 | J15: 정도검사포함
E16: 설치 | F16: M/D | G16: =단위장비1!F46+단위장비2!F61+단위장비3!F61+단위장비5!F60+단위장비4!F61+단위장비6!F61+단위장비7!F61+단위장비8!F61+단위장비9!F61+단위장비10!F61 -> 2 | H16: =IF(단위장비1!G46>0,단위장비1!G46,"") -> 1400000 | I16: =단위장비1!H46+단위장비2!H61+단위장비3!H61+단위장비5!H60+단위장비4!H61+단위장비6!H61+단위장비7!H61+단위장비8!H61+단위장비9!H61+단위장비10!H61 -> 2800000
E17: 시운전 | F17: M/D | G17: =단위장비1!F47+단위장비2!F62+단위장비3!F62+단위장비5!F61+단위장비4!F62+단위장비6!F62+단위장비7!F62+단위장비8!F62+단위장비9!F62+단위장비10!F62 -> 6 | H17: =IF(단위장비1!G47>0,단위장비1!G47,"") -> 1400000 | I17: =단위장비1!H47+단위장비2!H62+단위장비3!H62+단위장비5!H61+단위장비4!H62+단위장비6!H62+단위장비7!H62+단위장비8!H62+단위장비9!H62+단위장비10!H62 -> 8400000
E18: 양산대응 | F18: M/D | G18: =단위장비1!F48+단위장비2!F63+단위장비3!F63+단위장비5!F62+단위장비4!F63+단위장비6!F63+단위장비7!F63+단위장비8!F63+단위장비9!F63+단위장비10!F63 -> 8 | H18: =IF(단위장비1!G48>0,단위장비1!G48,"") -> 1400000 | I18: =단위장비1!H48+단위장비2!H63+단위장비3!H63+단위장비5!H62+단위장비4!H63+단위장비6!H63+단위장비7!H63+단위장비8!H63+단위장비9!H63+단위장비10!H63 -> 11200000
E19: 도장 | F19: M/D | G19: =단위장비1!F49+단위장비2!F64+단위장비3!F64+단위장비5!F63+단위장비4!F64+단위장비6!F64+단위장비7!F64+단위장비8!F64+단위장비9!F64+단위장비10!F64 -> 0 | H19: =IF(단위장비1!G49>0,단위장비1!G49,"") | I19: =단위장비1!H49+단위장비2!H64+단위장비3!H64+단위장비5!H63+단위장비4!H64+단위장비6!H64+단위장비7!H64+단위장비8!H64+단위장비9!H64+단위장비10!H64 -> 0
E20: 소계 | I20: =SUM(I12:I19) -> 22400000
D21: 일반관리 및 이윤 | I21: =단위장비1!H52+단위장비1!H53+단위장비2!H67+단위장비2!H68+단위장비3!H67+단위장비3!H68+단위장비5!H66+단위장비5!H67+단위장비4!H67+단위장비4!H68+단위장비6!H67+단위장비6!H68+단위장비7!H67+단위장비7!H68+단위장비8!H67+단위장비8!H68+단위장비9!H67+단위장비9!H68+단위장비10!H67+단위장비10!H68 -> 3360000
E22: 기계 소계 | I22: =I20+I11+I21 -> 25760000
B23: 2 | C23: 전기 부문 | D23: 자재비 | E23: 기계/전기자재 | F23: 식 | G23: 1 | I23: =전기!H55-I24 -> 9000000
E24: 설치/해체 공사 자재 | F24: 식 | G24: 1 | I24: =전기!H16 -> 0 | J24: 시운전 자재 포함
D25: 노무비 | E25: 철거(개조시) | F25: M/D | G25: =전기!F56 -> 0 | H25: =IF(전기!G56>0,전기!G56,"") | I25: =전기!H56 -> 0
E26: 설계,프로그램 | F26: M/D | G26: =전기!F57 -> 12 | H26: =IF(전기!G57>0,전기!G57,"") -> 800000 | I26: =전기!H57 -> 9600000
E27: 제작 | F27: M/D | G27: =전기!F58 -> 0 | H27: =IF(전기!G58>0,전기!G58,"") | I27: =전기!H58 -> 0
E28: 조립 | F28: M/D | G28: =전기!F59 -> 0 | H28: =IF(전기!G59>0,전기!G59,"") | I28: =전기!H59 -> 0
E29: 설치 | F29: M/D | G29: =전기!F60 -> 2 | H29: =IF(전기!G60>0,전기!G60,"") -> 1400000 | I29: =전기!H60 -> 2800000
E30: 시운전 | F30: M/D | G30: =전기!F61 -> 6 | H30: =IF(전기!G61>0,전기!G61,"") -> 1400000 | I30: =전기!H61 -> 8400000
E31: 양산대응 | F31: M/D | G31: =전기!F62 -> 8 | H31: =IF(전기!G62>0,전기!G62,"") -> 1400000 | I31: =전기!H62 -> 11200000
E32: 소계 | I32: =SUM(I25:I31) -> 32000000
D33: 일반관리 및 이윤 | I33: =전기!H65+전기!H66 -> 6150000
E34: 전기 소계 | I34: =I32+I23+I33+I24 -> 47150000
B35: 3 | C35: 자재비 합계 | I35: =I23+I11+I24 -> 9000000
C36: 노무비 합계 | I36: =I32+I20 -> 54400000
C37: 중간 합계 | I37: =I36+I35 -> 63400000
B38: 4 | C38: 포장,운송 및 중장비 사용료 | I38: =25743000+847000 -> 26590000
B39: 5 | C39: 표준안전관리비 | F39: 설치/철거/수리금액 기준 | J39: =I30+I29+I25+I24+I17+I16+I12+I10 -> 22400000
B40: 6 | C40: 일반관리비 | I40: =전기!H65+단위장비1!H52+단위장비2!H67+단위장비3!H67+단위장비5!H66+단위장비4!H67+단위장비6!H67+단위장비7!H67+단위장비8!H67+단위장비9!H67+단위장비10!H67 -> 3170000
B41: 7 | C41: 이 윤 | I41: =전기!H66+단위장비1!H53+단위장비2!H68+단위장비3!H68+단위장비5!H67+단위장비4!H68+단위장비6!H68+단위장비7!H68+단위장비8!H68+단위장비9!H68+단위장비10!H68 -> 6340000
C42: 합 계 | F42: 3~7항 합계 | I42: =I22+I34+I38+I39 -> 99500000
B43: 주1. 표준안전관리비:(설치/철거/시운전 공사 관련 금액)의 ⓐ2.66%,ⓑ1.95%+기초액,ⓒ2.02%(50억 이상일경우)
...

Sheet 단위공사별(집계)
A2: B. 단위장비별 견적가 종합(상세견적 첨부)
N3: 단위:원
I5: 포장/운송 | L5: 표준안전 | M5: 일반관리비
A6: 순번 | B6: 단위장비명 | C6: 수량 | D6: 자재비 | E6: 철거 | F6: 제작 | G6: 설치/시운전 | H6: 양산대응 | I6: 중장비사용 | J6: 기계소계 | K6: 전기소계 | L6: 관리비 | M6: 이윤 | N6: 합 계 | O6: 비 고
A7: =IF(B7>0,1,"") -> 1 | B7: =단위장비1!C$1 -> 고주파열처리기 개조 | C7: 1식 | D7: =단위장비1!H41 -> 0 | E7: =단위장비1!H42 -> 0 | F7: =단위장비1!H43+단위장비1!H44+단위장비1!H45+단위장비1!H49 -> 0 | G7: =단위장비1!H46+단위장비1!H47 -> 11200000 | H7: =단위장비1!H48 -> 11200000 | I7: =IF($B7>0,'원가항목별(집계)'!I$38*$P7/$P$17,0) -> 26590000 | J7: =SUM(D7:I7) -> 48990000 | K7: ='원가항목별(집계)'!I34 -> 47150000 | L7: =IF($B7>0,'원가항목별(집계)'!I$39*$P7/$P$17,0) -> 0 | M7: ='원가항목별(집계)'!I40+'원가항목별(집계)'!I41 -> 9510000 | N7: =SUM(J7:M7) -> 105650000 | P7: =D7+E7+F7+G7+H7+M7 -> 31910000
A8: =IF(B8>0,A7+1,"") | B8: =단위장비2!C$1 -> 0 | C8: 1식 | D8: =단위장비2!H56 -> 0 | E8: =단위장비2!H57 -> 0 | F8: =단위장비2!H58+단위장비2!H59+단위장비2!H60+단위장비2!H64 -> 0 | G8: =단위장비2!H61+단위장비2!H62 -> 0 | H8: =단위장비2!H63 -> 0 | I8: =IF($B8>0,'원가항목별(집계)'!I$38*$P8/$P$17,0) -> 0 | J8: =SUM(D8:I8) -> 0 | K8: =IF(B8>0,'원가항목별(집계)'!I$34*P8/P$17,0) -> 0 | L8: =IF($B8>0,'원가항목별(집계)'!I$39*$P8/$P$17,0) -> 0 | M8: =단위장비2!H67+단위장비2!H68 -> 0 | N8: =SUM(J8:M8) -> 0 | P8: =D8+E8+F8+G8+H8+M8 -> 0
A9: =IF(B9>0,A8+1,"") | B9: =단위장비3!C$1 -> 0 | C9: 1식 | D9: =단위장비3!H56 -> 0 | E9: =단위장비3!H57 -> 0 | F9: =단위장비3!H58+단위장비3!H59+단위장비3!H60+단위장비3!H64 -> 0 | G9: =단위장비3!H61+단위장비3!H62 -> 0 | H9: =단위장비3!H63 -> 0 | I9: =IF($B9>0,'원가항목별(집계)'!I$38*$P9/$P$17,0) -> 0 | J9: =SUM(D9:I9) -> 0 | K9: =IF(B9>0,'원가항목별(집계)'!I$34*P9/P$17,0) -> 0 | L9: =IF($B9>0,'원가항목별(집계)'!I$39*$P9/$P$17,0) -> 0 | M9: =단위장비3!H67+단위장비3!H68 -> 0 | N9: =SUM(J9:M9) -> 0 | P9: =D9+E9+F9+G9+H9+M9 -> 0
A10: =IF(B10>0,A9+1,"") | B10: =단위장비4!C1 -> 0 | C10: 1식 | D10: =단위장비4!H56 -> 0 | E10: =단위장비4!H57 -> 0 | F10: =단위장비4!H58+단위장비4!H59+단위장비4!H60+단위장비4!H64 -> 0 | G10: =단위장비4!H61+단위장비4!H62 -> 0 | H10: =단위장비4!H63 -> 0 | I10: =IF($B10>0,'원가항목별(집계)'!I$38*$P10/$P$17,0) -> 0 | J10: =SUM(D10:I10) -> 0 | K10: =IF(B10>0,'원가항목별(집계)'!I$34*P10/P$17,0) -> 0 | L10: =IF($B10>0,'원가항목별(집계)'!I$39*$P10/$P$17,0) -> 0 | M10: =단위장비4!H67+단위장비4!H68 -> 0 | N10: =SUM(J10:M10) -> 0 | P10: =D10+E10+F10+G10+H10+M10 -> 0
A11: =IF(B11>0,A10+1,"") | B11: =단위장비5!C1 -> 0 | C11: 1식 | D11: =단위장비5!H55 -> 0 | E11: =단위장비5!H56 -> 0 | F11: =단위장비5!H57+단위장비5!H58+단위장비5!H59+단위장비5!H63 -> 0 | G11: =단위장비5!H60+단위장비5!H61 -> 0 | H11: =단위장비5!H62 -> 0 | I11: =IF($B11>0,'원가항목별(집계)'!I$38*$P11/$P$17,0) -> 0 | J11: =SUM(D11:I11) -> 0 | K11: =IF(B11>0,'원가항목별(집계)'!I$34*P11/P$17,0) -> 0 | L11: =IF($B11>0,'원가항목별(집계)'!I$39*$P11/$P$17,0) -> 0 | M11: =단위장비5!H66+단위장비5!H67 -> 0 | N11: =SUM(J11:M11) -> 0 | P11: =D11+E11+F11+G11+H11+M11 -> 0
A12: =IF(B12>0,A11+1,"") | B12: =단위장비6!C$1 -> 0 | C12: 1식 | D12: =단위장비6!H56 -> 0 | E12: =단위장비6!H57 -> 0 | F12: =단위장비6!H58+단위장비6!H59+단위장비6!H60+단위장비6!H64 -> 0 | G12: =단위장비6!H61+단위장비6!H62 -> 0 | H12: =단위장비6!H63 -> 0 | I12: =IF($B12>0,'원가항목별(집계)'!I$38*$P12/$P$17,0) -> 0 | J12: =SUM(D12:I12) -> 0 | K12: =IF(B12>0,'원가항목별(집계)'!I$34*P12/P$17,0) -> 0 | L12: =IF($B12>0,'원가항목별(집계)'!I$39*$P12/$P$17,0) -> 0 | M12: =단위장비6!H67+단위장비6!H68 -> 0 | N12: =SUM(J12:M12) -> 0 | P12: =D12+E12+F12+G12+H12+M12 -> 0
A13: =IF(B13>0,A12+1,"") | B13: =단위장비7!C$1 -> 0 | C13: 1식 | D13: =단위장비7!H56 -> 0 | E13: =단위장비7!H57 -> 0 | F13: =단위장비7!H58+단위장비7!H59+단위장비7!H60+단위장비7!H64 -> 0 | G13: =단위장비7!H61+단위장비7!H62 -> 0 | H13: =단위장비7!H63 -> 0 | I13: =IF($B13>0,'원가항목별(집계)'!I$38*$P13/$P$17,0) -> 0 | J13: =SUM(D13:I13) -> 0 | K13: =IF(B13>0,'원가항목별(집계)'!I$34*P13/P$17,0) -> 0 | L13: =IF($B13>0,'원가항목별(집계)'!I$39*$P13/$P$17,0) -> 0 | M13: =단위장비7!H67+단위장비7!H68 -> 0 | N13: =SUM(J13:M13) -> 0 | P13: =D13+E13+F13+G13+H13+M13 -> 0
A14: =IF(B14>0,A13+1,"") | B14: =단위장비8!C$1 -> 0 | C14: 1식 | D14: =단위장비8!H56 -> 0 | E14: =단위장비8!H57 -> 0 | F14: =단위장비8!H58+단위장비8!H59+단위장비8!H60+단위장비8!H64 -> 0 | G14: =단위장비8!H61+단위장비8!H62 -> 0 | H14: =단위장비8!H63 -> 0 | I14: =IF($B14>0,'원가항목별(집계)'!I$38*$P14/$P$17,0) -> 0 | J14: =SUM(D14:I14) -> 0 | K14: =IF(B14>0,'원가항목별(집계)'!I$34*P14/P$17,0) -> 0 | L14: =IF($B14>0,'원가항목별(집계)'!I$39*$P14/$P$17,0) -> 0 | M14: =단위장비8!H67+단위장비8!H68 -> 0 | N14: =SUM(J14:M14) -> 0 | P14: =D14+E14+F14+G14+H14+M14 -> 0
A15: =IF(B15>0,A14+1,"") | B15: =단위장비9!C$1 -> 0 | C15: 1식 | D15: =단위장비9!H57 -> 0 | E15: =단위장비9!H58 -> 0 | F15: =단위장비9!H59+단위장비9!H60+단위장비9!H61+단위장비9!H65 -> 0 | G15: =단위장비9!H62+단위장비9!H63 -> 0 | H15: =단위장비9!H64 -> 0 | I15: =IF($B15>0,'원가항목별(집계)'!I$38*$P15/$P$17,0) -> 0 | J15: =SUM(D15:I15) -> 0 | K15: =IF(B15>0,'원가항목별(집계)'!I$34*P15/P$17,0) -> 0 | L15: =IF($B15>0,'원가항목별(집계)'!I$39*$P15/$P$17,0) -> 0 | M15: =단위장비9!H68+단위장비9!H69 -> 0 | N15: =SUM(J15:M15) -> 0 | P15: =D15+E15+F15+G15+H15+M15 -> 0
A16: =IF(B16>0,A15+1,"") | B16: =단위장비10!C$1 -> 0 | C16: 1식 | D16: =단위장비10!H58 -> 0 | E16: =단위장비10!H59 -> 0 | F16: =단위장비10!H60+단위장비10!H61+단위장비10!H62+단위장비10!H66 -> 0 | G16: =단위장비10!H63+단위장비10!H64 -> 0 | H16: =단위장비10!H65 -> 0 | I16: =IF($B16>0,'원가항목별(집계)'!I$38*$P16/$P$17,0) -> 0 | J16: =SUM(D16:I16) -> 0 | K16: =IF(B16>0,'원가항목별(집계)'!I$34*P16/P$17,0) -> 0 | L16: =IF($B16>0,'원가항목별(집계)'!I$39*$P16/$P$17,0) -> 0 | M16: =단위장비10!H69+단위장비10!H70 -> 0 | N16: =SUM(J16:M16) -> 0 | P16: =D16+E16+F16+G16+H16+M16 -> 0
A17: 합 계 | D17: =SUM(D7:D16) -> 0 | E17: =SUM(E7:E16) -> 0 | F17: =SUM(F7:F16) -> 0 | G17: =SUM(G7:G16) -> 11200000 | H17: =SUM(H7:H16) -> 11200000 | I17: =SUM(I7:I16) -> 26590000 | J17: =SUM(D17:I17) -> 48990000 | K17: =SUM(K7:K16) -> 47150000 | L17: =SUM(L7:L16) -> 0 | M17: =SUM(M7:M16) -> 9510000 | N17: =SUM(N7:N14) -> 105650000 | P17: =SUM(P7:P16) -> 31910000
D18: =IF(D17=0,"",D17/$N17) | E18: =IF(E17=0,"",E17/$N17) | F18: =IF(F17=0,"",F17/$N17) | G18: =IF(G17=0,"",G17/$N17) -> 0.10601041 | H18: =IF(H17=0,"",H17/$N17) -> 0.10601041 | I18: =IF(I17=0,"",I17/$N17) -> 0.25168008 | J18: =IF(J17=0,"",J17/$N17) -> 0.4637009 | K18: =IF(K17=0,"",K17/$N17) -> 0.4462849 | ... N18: =IF(N17=0,"",N17/$N17) -> 1
A19: 주) 전기비용은 턴키장비의 공통비용으로서 총 전기비용을 단위장비별 기계금액의 비율에 따라 배분함

Sheet 전기
B1: □ 전기부문: | I1: (첨부)
A2: 구분 | C2: 품 명 | D2: 규격 | E2: 단위 | F2: 수량 | G2: 단가(원) | H2: 금액(원) | I2: 原MAKER
A3: 자 재 비 | B3: 철자재 | C3: BRAKET | D3: W1700 X H 1200 | E3: 1 | F3: 1 | G3: 500000 | H3: =IF(F3=0,G3,G3*F3) -> 500000 | I3: KDKK
C4: STAND | D4: W1700 X H 15000 | E4: 1 | F4: 1 | G4: 1000000 | H4: =IF(F4=0,G4,G4*F4) -> 1000000 | I4: KDKK
H5: =IF(F5=0,G5,G5*F5) -> 0
H6: =IF(F6=0,G6,G6*F6) -> 0
H7: =IF(F7=0,G7,G7*F7) -> 0
H8: =IF(F8=0,G8,G8*F8) -> 0
H9: =SUM(H3:H8) -> 1500000
B10: 설치/해체/ | H10: =IF(F10=0,G10,G10*F10) -> 0
B11: 시운전 공사 | H11: =IF(F11=0,G11,G11*F11) -> 0
B12: 자재 | H12: =IF(F12=0,G12,G12*F12) -> 0
H13: =IF(F13=0,G13,G13*F13) -> 0
H14: =IF(F14=0,G14,G14*F14) -> 0
C15: 기타자재 | E15: ST | H15: =IF(F15=0,G15,G15*F15) -> 0
H16: =SUM(H10:H15) -> 0
B17: 전기자재 | C17: BARCODE READER | D17: W1500 X H 1000 | E17: 1 | F17: 1 | G17: 7500000 | H17: =IF(F17=0,G17,G17*F17) -> 7500000 | I17: KYENCE
H18: =IF(F18=0,G18,G18*F18) -> 0
H19: =IF(F19=0,G19,G19*F19) -> 0
H20: =IF(F20=0,G20,G20*F20) -> 0
H21: =IF(F21=0,G21,G21*F21) -> 0
H22: =IF(F22=0,G22,G22*F22) -> 0
H23: =IF(F23=0,G23,G23*F23) -> 0
H24: =IF(F24=0,G24,G24*F24) -> 0
H25: =IF(F25=0,G25,G25*F25) -> 0
H26: =IF(F26=0,G26,G26*F26) -> 0
H27: =IF(F27=0,G27,G27*F27) -> 0
H28: =IF(F28=0,G28,G28*F28) -> 0
H29: =IF(F29=0,G29,G29*F29) -> 0
... H53: =IF(F53=0,G53,G53*F53) -> 0
H54: =SUM(H17:H53) -> 7500000
B55: 자재비 소계 | H55: =SUM(H54,H9,H16) -> 9000000
A56: 노 무 비 | B56: 기존설비 철거 | E56: M/D | H56: =F56*G56 -> 0
B57: 작화. PROGRAM 비 | E57: M/D | F57: 12 | G57: 800000 | H57: =F57*G57 -> 9600000
B58: 전기 제작 | E58: M/D | H58: =F58*G58 -> 0
B59: 전기 조립 | E59: M/D | H59: =F59*G59 -> 0
B60: 전기 설치 | E60: M/D | F60: 2 | G60: 1400000 | H60: =F60*G60 -> 2800000
B61: 전기 시운전 | E61: M/D | F61: 6 | G61: 1400000 | H61: =F61*G61 -> 8400000
B62: 전기 양산대응 | E62: M/D | F62: 8 | G62: 1400000 | H62: =F62*G62 -> 11200000
B63: 노무비 소계 | H63: =SUM(H56:H62) -> 32000000
...

Sheet 단위장비1
B1: □ 단위공사명(전기제외): | C1: 고주파열처리기 개조 | I1: (첨부)
A2: 구분 | C2: 품 명 | D2: 규격 | E2: 단위 | F2: 수량 | G2: 단가(원) | H2: 금액(원) | I2: 原MAKER
A3: 자 재 비 | B3: 철자재 | H3: =IF(F3=0,G3,G3*F3) -> 0
H4: =F4*G4 -> 0
H5: =F5*G5 -> 0
H6: =F6*G6 -> 0
H7: =F7*G7 -> 0
H8: =IF(F8=0,G8,G8*F8) -> 0
H9: =IF(F9=0,G9,G9*F9) -> 0
H10: =SUM(H3:H9) -> 0
B11: 설치/해체/시운전 | H11: =IF(F11=0,G11,G11*F11) -> 0
B12: 공사 관련 자재 | H12: =IF(F12=0,G12,G12*F12) -> 0
H13: =IF(F13=0,G13,G13*F13) -> 0
H14: =IF(F14=0,G14,G14*F14) -> 0
H15: =IF(F15=0,G15,G15*F15) -> 0
H16: =SUM(H11:H15) -> 0
B17: 구매품 | H17: =IF(F17=0,G17,G17*F17) -> 0
B18: (유공압품외) | H18: =IF(F18=0,G18,G18*F18) -> 0
B19: 항공료 | H19: =IF(F19=0,G19,G19*F19) -> 0
H20: =IF(F20=0,G20,G20*F20) -> 0
H21: =IF(F21=0,G21,G21*F21) -> 0
H22: =IF(F22=0,G22,G22*F22) -> 0
H23: =IF(F23=0,G23,G23*F23) -> 0
H24: =IF(F24=0,G24,G24*F24) -> 0
H25: =IF(F25=0,G25,G25*F25) -> 0
H26: =IF(F26=0,G26,G26*F26) -> 0
H27: =IF(F27=0,G27,G27*F27) -> 0
H28: =IF(F28=0,G28,G28*F28) -> 0
H29: =IF(F29=0,G29,G29*F29) -> 0
H30: =IF(F30=0,G30,G30*F30) -> 0
H31: =IF(F31=0,G31,G31*F31) -> 0
H32: =SUM(H17:H31) -> 0
B33: 외주제작품 | H33: =IF(F33=0,G33,G33*F33) -> 0
H34: =IF(F34=0,G34,G34*F34) -> 0
H35: =IF(F35=0,G35,G35*F35) -> 0
H36: =IF(F36=0,G36,G36*F36) -> 0
H37: =IF(F37=0,G37,G37*F37) -> 0
H38: =IF(F38=0,G38,G38*F38) -> 0
H39: =IF(F39=0,G39,G39*F39) -> 0
H40: =SUM(H33:H39) -> 0
...

Sheet 단위장비2
B1: □ 단위공사명(전기제외): | I1: (첨부)
A2: 구분 | C2: 품 명 | D2: 규격 | E2: 단위 | F2: 수량 | G2: 단가(원) | H2: 금액(원) | I2: 原MAKER
A3: 자 재 비 | B3: 철자재 | H3: =IF(F3=0,G3,G3*F3) -> 0
H4: =F4*G4 -> 0
H5: =F5*G5 -> 0
H6: =F6*G6 -> 0
H7: =F7*G7 -> 0
H8: =IF(F8=0,G8,G8*F8) -> 0
H9: =IF(F9=0,G9,G9*F9) -> 0
H10: =IF(F10=0,G10,G10*F10) -> 0
H11: =IF(F11=0,G11,G11*F11) -> 0
H12: =IF(F12=0,G12,G12*F12) -> 0
H13: =IF(F13=0,G13,G13*F13) -> 0
H14: =IF(F14=0,G14,G14*F14) -> 0
H15: =IF(F15=0,G15,G15*F15) -> 0
H16: =IF(F16=0,G16,G16*F16) -> 0
H17: =IF(F17=0,G17,G17*F17) -> 0
H18: =IF(F18=0,G18,G18*F18) -> 0
H19: =IF(F19=0,G19,G19*F19) -> 0
... H23: =IF(F23=0,G23,G23*F23) -> 0
H24: =SUM(H3:H23) -> 0
B25: 설치/해체/시운전 | H25: =IF(F25=0,G25,G25*F25) -> 0
B26: 공사 관련 자재 | H26: =IF(F26=0,G26,G26*F26) -> 0
H27: =IF(F27=0,G27,G27*F27) -> 0
H28: =IF(F28=0,G28,G28*F28) -> 0
H29: =IF(F29=0,G29,G29*F29) -> 0
H30: =SUM(H25:H29) -> 0
B31: 구매품 | H31: =IF(F31=0,G31,G31*F31) -> 0
B32: (유공압품외) | H32: =IF(F32=0,G32,G32*F32) -> 0
H33: =IF(F33=0,G33,G33*F33) -> 0
H34: =IF(F34=0,G34,G34*F34) -> 0
H35: =IF(F35=0,G35,G35*F35) -> 0
H36: =IF(F36=0,G36,G36*F36) -> 0
H37: =IF(F37=0,G37,G37*F37) -> 0
H38: =IF(F38=0,G38,G38*F38) -> 0
H39: =IF(F39=0,G39,G39*F39) -> 0
H40: =IF(F40=0,G40,G40*F40) -> 0
H41: =IF(F41=0,G41,G41*F41) -> 0
H42: =IF(F42=0,G42,G42*F42) -> 0
H43: =IF(F43=0,G43,G43*F43) -> 0
...

Sheet 단위장비3
B1: □ 단위공사명(전기제외): | I1: (첨부)
A2: 구분 | C2: 품 명 | D2: 규격 | E2: 단위 | F2: 수량 | G2: 단가(원) | H2: 금액(원) | I2: 原MAKER
A3: 자 재 비 | B3: 철자재 | I3: Manifold
H4: =IF(F4=0,G4,G4*F4) -> 0
H5: =IF(F5=0,G5,G5*F5) -> 0
H6: =IF(F6=0,G6,G6*F6) -> 0
H7: =IF(F7=0,G7,G7*F7) -> 0
H8: =IF(F8=0,G8,G8*F8) -> 0
H9: =IF(F9=0,G9,G9*F9) -> 0
H10: =IF(F10=0,G10,G10*F10) -> 0
H11: =IF(F11=0,G11,G11*F11) -> 0
H12: =IF(F12=0,G12,G12*F12) -> 0
H13: =IF(F13=0,G13,G13*F13) -> 0
H14: =IF(F14=0,G14,G14*F14) -> 0
H15: =IF(F15=0,G15,G15*F15) -> 0
... H23: =IF(F23=0,G23,G23*F23) -> 0
H24: =SUM(H3:H23) -> 0
B25: 설치/해체/시운전 | H25: =IF(F25=0,G25,G25*F25) -> 0
B26: 공사 관련 자재 | H26: =IF(F26=0,G26,G26*F26) -> 0
H27: =IF(F27=0,G27,G27*F27) -> 0
H28: =IF(F28=0,G28,G28*F28) -> 0
H29: =IF(F29=0,G29,G29*F29) -> 0
H30: =SUM(H25:H29) -> 0
B31: 구매품 | H31: =IF(F31=0,G31,G31*F31) -> 0
B32: (유공압품외) | H32: =IF(F32=0,G32,G32*F32) -> 0
H33: =IF(F33=0,G33,G33*F33) -> 0
H34: =IF(F34=0,G34,G34*F34) -> 0
H35: =IF(F35=0,G35,G35*F35) -> 0
H36: =IF(F36=0,G36,G36*F36) -> 0
H37: =IF(F37=0,G37,G37*F37) -> 0
H38: =IF(F38=0,G38,G38*F38) -> 0
H39: =IF(F39=0,G39,G39*F39) -> 0
H40: =IF(F40=0,G40,G40*F40) -> 0
H41: =IF(F41=0,G41,G41*F41) -> 0
H42: =IF(F42=0,G42,G42*F42) -> 0
H43: =IF(F43=0,G43,G43*F43) -> 0
H44: =IF(F44=0,G44,G44*F44) -> 0
... H46: =IF(F46=0,G46,G46*F46) -> 0
H47: =SUM(H31:H46) -> 0
B48: 외주제작품 | H48: =IF(F48=0,G48,G48*F48) -> 0
...

Sheet 단위장비4
B1: □ 단위공사명(전기제외): | I1: (첨부)
A2: 구분 | C2: 품 명 | D2: 규격 | E2: 단위 | F2: 수량 | G2: 단가(원) | H2: 금액(원) | I2: 原MAKER
A3: 자 재 비 | B3: 철자재 | H3: =IF(F3=0,G3,G3*F3) -> 0
H4: =IF(F4=0,G4,G4*F4) -> 0
H5: =IF(F5=0,G5,G5*F5) -> 0
H6: =IF(F6=0,G6,G6*F6) -> 0
H7: =IF(F7=0,G7,G7*F7) -> 0
H8: =IF(F8=0,G8,G8*F8) -> 0
H9: =IF(F9=0,G9,G9*F9) -> 0
H10: =IF(F10=0,G10,G10*F10) -> 0
H11: =IF(F11=0,G11,G11*F11) -> 0
H12: =IF(F12=0,G12,G12*F12) -> 0
H13: =IF(F13=0,G13,G13*F13) -> 0
H14: =IF(F14=0,G14,G14*F14) -> 0
H15: =IF(F15=0,G15,G15*F15) -> 0
... H23: =IF(F23=0,G23,G23*F23) -> 0
H24: =SUM(H3:H23) -> 0
B25: 설치/해체/시운전 | H25: =IF(F25=0,G25,G25*F25) -> 0
B26: 공사 관련 자재 | H26: =IF(F26=0,G26,G26*F26) -> 0
H27: =IF(F27=0,G27,G27*F27) -> 0
H28: =IF(F28=0,G28,G28*F28) -> 0
H29: =IF(F29=0,G29,G29*F29) -> 0
H30: =SUM(H25:H29) -> 0
B31: 구매품 | H31: =IF(F31=0,G31,G31*F31) -> 0
B32: (유공압품외) | H32: =IF(F32=0,G32,G32*F32) -> 0
H33: =IF(F33=0,G33,G33*F33) -> 0
H34: =IF(F34=0,G34,G34*F34) -> 0
H35: =IF(F35=0,G35,G35*F35) -> 0
H36: =IF(F36=0,G36,G36*F36) -> 0
H37: =IF(F37=0,G37,G37*F37) -> 0
H38: =IF(F38=0,G38,G38*F38) -> 0
H39: =IF(F39=0,G39,G39*F39) -> 0
H40: =IF(F40=0,G40,G40*F40) -> 0
H41: =IF(F41=0,G41,G41*F41) -> 0
H42: =IF(F42=0,G42,G42*F42) -> 0
H43: =IF(F43=0,G43,G43*F43) -> 0
H44: =IF(F44=0,G44,G44*F44) -> 0
... H46: =IF(F46=0,G46,G46*F46) -> 0
H47: =SUM(H31:H46) -> 0
B48: 외주제작품 | H48: =IF(F48=0,G48,G48*F48) -> 0
...

Sheet 단위장비5
B1: □ 단위공사명(전기제외): | I1: (첨부)
A2: 구분 | C2: 품 명 | D2: 규격 | E2: 단위 | F2: 수량 | G2: 단가(원) | H2: 금액(원) | I2: 原MAKER
A3: 자 재 비 | B3: 철자재 | H3: =IF(F3=0,G3,G3*F3) -> 0
H4: =IF(F4=0,G4,G4*F4) -> 0
H5: =IF(F5=0,G5,G5*F5) -> 0
H6: =IF(F6=0,G6,G6*F6) -> 0
H7: =IF(F7=0,G7,G7*F7) -> 0
H8: =IF(F8=0,G8,G8*F8) -> 0
H9: =IF(F9=0,G9,G9*F9) -> 0
H10: =IF(F10=0,G10,G10*F10) -> 0
H11: =IF(F11=0,G11,G11*F11) -> 0
H12: =IF(F12=0,G12,G12*F12) -> 0
H13: =IF(F13=0,G13,G13*F13) -> 0
H14: =IF(F14=0,G14,G14*F14) -> 0
H15: =IF(F15=0,G15,G15*F15) -> 0
... H22: =IF(F22=0,G22,G22*F22) -> 0
H23: =SUM(H3:H22) -> 0
B24: 설치/해체/시운전 | H24: =IF(F24=0,G24,G24*F24) -> 0
B25: 공사 관련 자재 | H25: =IF(F25=0,G25,G25*F25) -> 0
H26: =IF(F26=0,G26,G26*F26) -> 0
H27: =IF(F27=0,G27,G27*F27) -> 0
H28: =IF(F28=0,G28,G28*F28) -> 0
H29: =SUM(H24:H28) -> 0
B30: 구매품 | H30: =IF(F30=0,G30,G30*F30) -> 0
B31: (유공압품외) | H31: =IF(F31=0,G31,G31*F31) -> 0
H32: =IF(F32=0,G32,G32*F32) -> 0
H33: =IF(F33=0,G33,G33*F33) -> 0
H34: =IF(F34=0,G34,G34*F34) -> 0
H35: =IF(F35=0,G35,G35*F35) -> 0
H36: =IF(F36=0,G36,G36*F36) -> 0
H37: =IF(F37=0,G37,G37*F37) -> 0
H38: =IF(F38=0,G38,G38*F38) -> 0
H39: =IF(F39=0,G39,G39*F39) -> 0
H40: =IF(F40=0,G40,G40*F40) -> 0
H41: =IF(F41=0,G41,G41*F41) -> 0
H42: =IF(F42=0,G42,G42*F42) -> 0
H43: =IF(F43=0,G43,G43*F43) -> 0
... H45: =IF(F45=0,G45,G45*F45) -> 0
H46: =SUM(H30:H45) -> 0
B47: 외주제작품 | H47: =IF(F47=0,G47,G47*F47) -> 0
...

Sheet 단위장비6
B1: □ 단위공사명(전기제외): | I1: (첨부)
A2: 구분 | C2: 품 명 | D2: 규격 | E2: 단위 | F2: 수량 | G2: 단가(원) | H2: 금액(원) | I2: 原MAKER
A3: 자 재 비 | B3: 철자재 | H3: =IF(F3=0,G3,G3*F3) -> 0
H4: =IF(F4=0,G4,G4*F4) -> 0
H5: =IF(F5=0,G5,G5*F5) -> 0
H6: =IF(F6=0,G6,G6*F6) -> 0
H7: =IF(F7=0,G7,G7*F7) -> 0
H8: =IF(F8=0,G8,G8*F8) -> 0
H9: =IF(F9=0,G9,G9*F9) -> 0
H10: =IF(F10=0,G10,G10*F10) -> 0
H11: =IF(F11=0,G11,G11*F11) -> 0
H12: =IF(F12=0,G12,G12*F12) -> 0
H13: =IF(F13=0,G13,G13*F13) -> 0
H14: =IF(F14=0,G14,G14*F14) -> 0
H15: =IF(F15=0,G15,G15*F15) -> 0
... H22: =IF(F22=0,G22,G22*F22) -> 0
C23: 기타자재 | H23: =IF(F23=0,G23,G23*F23) -> 0
H24: =SUM(H3:H23) -> 0
B25: 설치/해체/시운전 | H25: =IF(F25=0,G25,G25*F25) -> 0
B26: 공사 관련 자재 | H26: =IF(F26=0,G26,G26*F26) -> 0
H27: =IF(F27=0,G27,G27*F27) -> 0
H28: =IF(F28=0,G28,G28*F28) -> 0
C29: 기타자재 | H29: =IF(F29=0,G29,G29*F29) -> 0
H30: =SUM(H25:H29) -> 0
B31: 구매품 | H31: =IF(F31=0,G31,G31*F31) -> 0
B32: (유공압품외) | H32: =IF(F32=0,G32,G32*F32) -> 0
H33: =IF(F33=0,G33,G33*F33) -> 0
H34: =IF(F34=0,G34,G34*F34) -> 0
H35: =IF(F35=0,G35,G35*F35) -> 0
H36: =IF(F36=0,G36,G36*F36) -> 0
H37: =IF(F37=0,G37,G37*F37) -> 0
H38: =IF(F38=0,G38,G38*F38) -> 0
H39: =IF(F39=0,G39,G39*F39) -> 0
H40: =IF(F40=0,G40,G40*F40) -> 0
H41: =IF(F41=0,G41,G41*F41) -> 0
H42: =IF(F42=0,G42,G42*F42) -> 0
H43: =IF(F43=0,G43,G43*F43) -> 0
H44: =IF(F44=0,G44,G44*F44) -> 0
H45: =IF(F45=0,G45,G45*F45) -> 0
C46: 기타자재 | E46: ST | H46: =IF(F46=0,G46,G46*F46) -> 0
...

Sheet 단위장비7
B1: □ 단위공사명(전기제외): | I1: (첨부)
A2: 구분 | C2: 품 명 | D2: 규격 | E2: 단위 | F2: 수량 | G2: 단가(원) | H2: 금액(원) | I2: 原MAKER
A3: 자 재 비 | B3: 철자재 | H3: =IF(F3=0,G3,G3*F3) -> 0
H4: =IF(F4=0,G4,G4*F4) -> 0
H5: =IF(F5=0,G5,G5*F5) -> 0
H6: =IF(F6=0,G6,G6*F6) -> 0
H7: =IF(F7=0,G7,G7*F7) -> 0
H8: =IF(F8=0,G8,G8*F8) -> 0
H9: =IF(F9=0,G9,G9*F9) -> 0
H10: =IF(F10=0,G10,G10*F10) -> 0
H11: =IF(F11=0,G11,G11*F11) -> 0
H12: =IF(F12=0,G12,G12*F12) -> 0
H13: =IF(F13=0,G13,G13*F13) -> 0
H14: =IF(F14=0,G14,G14*F14) -> 0
H15: =IF(F15=0,G15,G15*F15) -> 0
... H22: =IF(F22=0,G22,G22*F22) -> 0
C23: 기타자재 | E23: ST | H23: =IF(F23=0,G23,G23*F23) -> 0
H24: =SUM(H3:H23) -> 0
B25: 설치/해체/시운전 | H25: =IF(F25=0,G25,G25*F25) -> 0
B26: 공사 관련 자재 | H26: =IF(F26=0,G26,G26*F26) -> 0
H27: =IF(F27=0,G27,G27*F27) -> 0
H28: =IF(F28=0,G28,G28*F28) -> 0
C29: 기타자재 | H29: =IF(F29=0,G29,G29*F29) -> 0
H30: =SUM(H25:H29) -> 0
B31: 구매품 | H31: =IF(F31=0,G31,G31*F31) -> 0
B32: (유공압품외) | H32: =IF(F32=0,G32,G32*F32) -> 0
H33: =IF(F33=0,G33,G33*F33) -> 0
H34: =IF(F34=0,G34,G34*F34) -> 0
H35: =IF(F35=0,G35,G35*F35) -> 0
H36: =IF(F36=0,G36,G36*F36) -> 0
H37: =IF(F37=0,G37,G37*F37) -> 0
H38: =IF(F38=0,G38,G38*F38) -> 0
H39: =IF(F39=0,G39,G39*F39) -> 0
H40: =IF(F40=0,G40,G40*F40) -> 0
H41: =IF(F41=0,G41,G41*F41) -> 0
H42: =IF(F42=0,G42,G42*F42) -> 0
H43: =IF(F43=0,G43,G43*F43) -> 0
H44: =IF(F44=0,G44,G44*F44) -> 0
H45: =IF(F45=0,G45,G45*F45) -> 0
C46: 기타자재 | E46: ST | H46: =IF(F46=0,G46,G46*F46) -> 0
...

Sheet 단위장비8
B1: □ 단위공사명(전기제외): | I1: (첨부)
A2: 구분 | C2: 품 명 | D2: 규격 | E2: 단위 | F2: 수량 | G2: 단가(원) | H2: 금액(원) | I2: 原MAKER
A3: 자 재 비 | B3: 철자재 | H3: =IF(F3=0,G3,G3*F3) -> 0
H4: =IF(F4=0,G4,G4*F4) -> 0
H5: =IF(F5=0,G5,G5*F5) -> 0
H6: =IF(F6=0,G6,G6*F6) -> 0
H7: =IF(F7=0,G7,G7*F7) -> 0
H8: =IF(F8=0,G8,G8*F8) -> 0
H9: =IF(F9=0,G9,G9*F9) -> 0
H10: =IF(F10=0,G10,G10*F10) -> 0
H11: =IF(F11=0,G11,G11*F11) -> 0
H12: =IF(F12=0,G12,G12*F12) -> 0
H13: =IF(F13=0,G13,G13*F13) -> 0
H14: =IF(F14=0,G14,G14*F14) -> 0
H15: =IF(F15=0,G15,G15*F15) -> 0
... H22: =IF(F22=0,G22,G22*F22) -> 0
C23: 기타자재 | H23: =IF(F23=0,G23,G23*F23) -> 0
H24: =SUM(H3:H23) -> 0
B25: 설치/해체/시운전 | H25: =IF(F25=0,G25,G25*F25) -> 0
B26: 공사 관련 자재 | H26: =IF(F26=0,G26,G26*F26) -> 0
H27: =IF(F27=0,G27,G27*F27) -> 0
H28: =IF(F28=0,G28,G28*F28) -> 0
C29: 기타자재 | H29: =IF(F29=0,G29,G29*F29) -> 0
H30: =SUM(H25:H29) -> 0
B31: 구매품 | H31: =IF(F31=0,G31,G31*F31) -> 0
B32: (유공압품외) | H32: =IF(F32=0,G32,G32*F32) -> 0
H33: =IF(F33=0,G33,G33*F33) -> 0
H34: =IF(F34=0,G34,G34*F34) -> 0
H35: =IF(F35=0,G35,G35*F35) -> 0
H36: =IF(F36=0,G36,G36*F36) -> 0
H37: =IF(F37=0,G37,G37*F37) -> 0
H38: =IF(F38=0,G38,G38*F38) -> 0
H39: =IF(F39=0,G39,G39*F39) -> 0
H40: =IF(F40=0,G40,G40*F40) -> 0
H41: =IF(F41=0,G41,G41*F41) -> 0
H42: =IF(F42=0,G42,G42*F42) -> 0
H43: =IF(F43=0,G43,G43*F43) -> 0
H44: =IF(F44=0,G44,G44*F44) -> 0
H45: =IF(F45=0,G45,G45*F45) -> 0
C46: 기타자재 | H46: =IF(F46=0,G46,G46*F46) -> 0
...

Sheet 단위장비9
B1: □ 단위공사명(전기제외): | I1: (첨부)
A2: 구분 | C2: 품 명 | D2: 규격 | E2: 단위 | F2: 수량 | G2: 단가(원) | H2: 금액(원) | I2: 原MAKER
A3: 자 재 비 | B3: 철자재 | H3: =IF(F3=0,G3,G3*F3) -> 0
H4: =IF(F4=0,G4,G4*F4) -> 0
H5: =IF(F5=0,G5,G5*F5) -> 0
H6: =IF(F6=0,G6,G6*F6) -> 0
H7: =IF(F7=0,G7,G7*F7) -> 0
H8: =IF(F8=0,G8,G8*F8) -> 0
H9: =IF(F9=0,G9,G9*F9) -> 0
H10: =IF(F10=0,G10,G10*F10) -> 0
H11: =IF(F11=0,G11,G11*F11) -> 0
H12: =IF(F12=0,G12,G12*F12) -> 0
H13: =IF(F13=0,G13,G13*F13) -> 0
H14: =IF(F14=0,G14,G14*F14) -> 0
H15: =IF(F15=0,G15,G15*F15) -> 0
... H22: =IF(F22=0,G22,G22*F22) -> 0
C23: 기타자재 | H23: =IF(F23=0,G23,G23*F23) -> 0
H24: =SUM(H3:H23) -> 0
B25: 설치/해체/시운전 | H25: =IF(F25=0,G25,G25*F25) -> 0
B26: 공사 관련 자재 | H26: =IF(F26=0,G26,G26*F26) -> 0
H27: =IF(F27=0,G27,G27*F27) -> 0
H28: =IF(F28=0,G28,G28*F28) -> 0
C29: 기타자재 | H29: =IF(F29=0,G29,G29*F29) -> 0
H30: =SUM(H25:H29) -> 0
B31: 구매품 | H31: =IF(F31=0,G31,G31*F31) -> 0
B32: (유공압품외) | H32: =IF(F32=0,G32,G32*F32) -> 0
H33: =IF(F33=0,G33,G33*F33) -> 0
H34: =IF(F34=0,G34,G34*F34) -> 0
H35: =IF(F35=0,G35,G35*F35) -> 0
H36: =IF(F36=0,G36,G36*F36) -> 0
H37: =IF(F37=0,G37,G37*F37) -> 0
H38: =IF(F38=0,G38,G38*F38) -> 0
H39: =IF(F39=0,G39,G39*F39) -> 0
H40: =IF(F40=0,G40,G40*F40) -> 0
H41: =IF(F41=0,G41,G41*F41) -> 0
H42: =IF(F42=0,G42,G42*F42) -> 0
H43: =IF(F43=0,G43,G43*F43) -> 0
H44: =IF(F44=0,G44,G44*F44) -> 0
H45: =IF(F45=0,G45,G45*F45) -> 0
C46: 기타자재 | H46: =IF(F46=0,G46,G46*F46) -> 0
...

Sheet 단위장비10
B1: □ 단위공사명(전기제외): | I1: (첨부)
A2: 구분 | C2: 품 명 | D2: 규격 | E2: 단위 | F2: 수량 | G2: 단가(원) | H2: 금액(원) | I2: 原MAKER
A3: 자 재 비 | B3: 철자재 | H3: =IF(F3=0,G3,G3*F3) -> 0
H4: =IF(F4=0,G4,G4*F4) -> 0
H5: =IF(F5=0,G5,G5*F5) -> 0
H6: =IF(F6=0,G6,G6*F6) -> 0
H7: =IF(F7=0,G7,G7*F7) -> 0
H8: =IF(F8=0,G8,G8*F8) -> 0
H9: =IF(F9=0,G9,G9*F9) -> 0
H10: =IF(F10=0,G10,G10*F10) -> 0
H11: =IF(F11=0,G11,G11*F11) -> 0
H12: =IF(F12=0,G12,G12*F12) -> 0
H13: =IF(F13=0,G13,G13*F13) -> 0
H14: =IF(F14=0,G14,G14*F14) -> 0
H15: =IF(F15=0,G15,G15*F15) -> 0
... H22: =IF(F22=0,G22,G22*F22) -> 0
C23: 기타자재 | H23: =IF(F23=0,G23,G23*F23) -> 0
H24: =SUM(H3:H23) -> 0
B25: 설치/해체/시운전 | H25: =IF(F25=0,G25,G25*F25) -> 0
B26: 공사 관련 자재 | H26: =IF(F26=0,G26,G26*F26) -> 0
H27: =IF(F27=0,G27,G27*F27) -> 0
H28: =IF(F28=0,G28,G28*F28) -> 0
C29: 기타자재 | H29: =IF(F29=0,G29,G29*F29) -> 0
H30: =SUM(H25:H29) -> 0
B31: 구매품 | H31: =IF(F31=0,G31,G31*F31) -> 0
B32: (유공압품외) | H32: =IF(F32=0,G32,G32*F32) -> 0
H33: =IF(F33=0,G33,G33*F33) -> 0
H34: =IF(F34=0,G34,G34*F34) -> 0
H35: =IF(F35=0,G35,G35*F35) -> 0
H36: =IF(F36=0,G36,G36*F36) -> 0
H37: =IF(F37=0,G37,G37*F37) -> 0
H38: =IF(F38=0,G38,G38*F38) -> 0
H39: =IF(F39=0,G39,G39*F39) -> 0
H40: =IF(F40=0,G40,G40*F40) -> 0
H41: =IF(F41=0,G41,G41*F41) -> 0
H42: =IF(F42=0,G42,G42*F42) -> 0
H43: =IF(F43=0,G43,G43*F43) -> 0
H44: =IF(F44=0,G44,G44*F44) -> 0
H45: =IF(F45=0,G45,G45*F45) -> 0
C46: 기타자재 | H46: =IF(F46=0,G46,G46*F46) -> 0
...

Sheet 첨부(견적조건차이내역)
A1: ※ 현대/기아차의 요구사양과 업체견적사양이 다른경우만 작성
D2: (첨부)
A3: 현대/기아차 요구사양대비 견적조건 상이내역
A5: 항 목 | B5: 현대/기아차 요구사양 | C5: 업체 견적기준 사양 | D5: 비 고
