Workbook

Sheet 갑지
B1: (현대/기아차 설비협력업체 견적통일양식)
B2: 見 積 書
B4: 현대위아(주) 貴下 | G4: ㈜동서기전
B5: 견적일자 | D5: 45834 | G5: 대표 : 김 연 규 (인)
B6: 견적번호 | D6: QZ250626-01 | G6: 주소 : 창원시 의창구 팔용로346번길 34
B7: 납기 | C7: 입하 | D7: 45920 | G7: 전화: 82-55-297-3115
C8: 최종검수 | D8: 46112 | G8: Fax: 82-55-296-3669
B9: 견적유효기간 | D9: 견적일로부터30일 | G9: E-mail: chrcho@dongseomecha.co.kr
B10: 인도장소 | D10: 현대위아 - 인도법인 | G10: 견적담당: 조 충 래 상무
B11: 담 당 자 | D11: 샤시생기팀 / 정주완 책임 님 | G11: 연 락 처 : 82-55-290-3232
B13: 공 사 명: | D13: CG 그레이드 선별 및 SUB 조립기 개조 및 이설
B14: 최종견적금액: | D14: ="一金"&NUMBERSTRING(H68,1)&"원整 ("&TEXT(H68,"\#,#)") -> 一金육억팔천칠백만원整 (₩687,000,000)
B16: 번호 | C16: 상세품목내역 | E16: 견적금액 (원) | I16: 비 고
E17: 기계부문 | F17: 전기부문 | G17: 관리/이윤 (안전관리비포함) | H17: 합 계
B18: 1 | C18: =IF('단위공사별(집계)'!N7>0,'단위공사별(집계)'!B7,"") -> I/RACE GRAD 선별 | E18: =IF('단위공사별(집계)'!N7>1,('단위공사별(집계)'!D7+'단위공사별(집계)'!E7+'단위공사별(집계)'!F7+'단위공사별(집계)'!G7+'단위공사별(집계)'!H7+'단위공사별(집계)'!I7)," ") -> 15422360 | F18: =IF('단위공사별(집계)'!N7>0,'단위공사별(집계)'!K57,"") -> 125378750 | G18: =IF('단위공사별(집계)'!N7>0,('단위공사별(집계)'!L7+'단위공사별(집계)'!M7),"") -> 2311270.2 | H18: =IF('단위공사별(집계)'!N7>0,'단위공사별(집계)'!N7,"") -> 21692268
B19: 2 | C19: =IF('단위공사별(집계)'!N8>0,'단위공사별(집계)'!B8,"") -> O/RACE GRAD 선별 | E19: =IF('단위공사별(집계)'!N8>1,('단위공사별(집계)'!D8+'단위공사별(집계)'!E8+'단위공사별(집계)'!F8+'단위공사별(집계)'!G8+'단위공사별(집계)'!H8+'단위공사별(집계)'!I8)," ") -> 88797687 | G19: =IF('단위공사별(집계)'!N8>0,('단위공사별(집계)'!L8+'단위공사별(집계)'!M8),"") -> 13307655 | H19: =IF('단위공사별(집계)'!N8>0,'단위공사별(집계)'!N8,"") -> 1.2489808e+08
B20: 3 | C20: =IF('단위공사별(집계)'!N9>0,'단위공사별(집계)'!B9,"") | E20: =IF('단위공사별(집계)'!N9>1,('단위공사별(집계)'!D9+'단위공사별(집계)'!E9+'단위공사별(집계)'!F9+'단위공사별(집계)'!G9+'단위공사별(집계)'!H9+'단위공사별(집계)'!I9)," ") | G20: =IF('단위공사별(집계)'!N9>0,('단위공사별(집계)'!L9+'단위공사별(집계)'!M9),"") | H20: =IF('단위공사별(집계)'!N9>0,'단위공사별(집계)'!N9,"")
B21: 4 | C21: =IF('단위공사별(집계)'!N10>0,'단위공사별(집계)'!B10,"") -> 스테킹 MC | E21: =IF('단위공사별(집계)'!N10>1,('단위공사별(집계)'!D10+'단위공사별(집계)'!E10+'단위공사별(집계)'!F10+'단위공사별(집계)'!G10+'단위공사별(집계)'!H10+'단위공사별(집계)'!I10)," ") -> 32524880 | G21: =IF('단위공사별(집계)'!N10>0,('단위공사별(집계)'!L10+'단위공사별(집계)'!M10),"") -> 4874337.3 | H21: =IF('단위공사별(집계)'!N10>0,'단위공사별(집계)'!N10,"") -> 45747759
B22: 5 | C22: =IF('단위공사별(집계)'!N11>0,'단위공사별(집계)'!B11,"") -> CG SUB 조립기 | E22: =IF('단위공사별(집계)'!N11>1,('단위공사별(집계)'!D11+'단위공사별(집계)'!E11+'단위공사별(집계)'!F11+'단위공사별(집계)'!G11+'단위공사별(집계)'!H11+'단위공사별(집계)'!I11)," ") -> 1.7622617e+08 | G22: =IF('단위공사별(집계)'!N11>0,('단위공사별(집계)'!L11+'단위공사별(집계)'!M11),"") -> 26410114 | H22: =IF('단위공사별(집계)'!N11>0,'단위공사별(집계)'!N11,"") -> 2.4787032e+08
B23: 6 | C23: =IF('단위공사별(집계)'!N12>0,'단위공사별(집계)'!B12,"") -> 철거/시운전/현지 설치 및 시운전 | E23: =IF('단위공사별(집계)'!N12>1,('단위공사별(집계)'!D12+'단위공사별(집계)'!E12+'단위공사별(집계)'!F12+'단위공사별(집계)'!G12+'단위공사별(집계)'!H12+'단위공사별(집계)'!I12)," ") -> 1.754889e+08 | G23: =IF('단위공사별(집계)'!N12>0,('단위공사별(집계)'!L12+'단위공사별(집계)'!M12),"") -> 26299624 | H23: =IF('단위공사별(집계)'!N12>0,'단위공사별(집계)'!N12,"") -> 2.4683332e+08
B24: 7 | C24: =IF('단위공사별(집계)'!N13>0,'단위공사별(집계)'!B13,"") | E24: =IF('단위공사별(집계)'!N13>1,('단위공사별(집계)'!D13+'단위공사별(집계)'!E13+'단위공사별(집계)'!F13+'단위공사별(집계)'!G13+'단위공사별(집계)'!H13+'단위공사별(집계)'!I13)," ") | G24: =IF('단위공사별(집계)'!N13>0,('단위공사별(집계)'!L13+'단위공사별(집계)'!M13),"") | H24: =IF('단위공사별(집계)'!N13>0,'단위공사별(집계)'!N13,"")
B25: 8 | C25: =IF('단위공사별(집계)'!N14>0,'단위공사별(집계)'!B14,"") | E25: =IF('단위공사별(집계)'!N14>1,('단위공사별(집계)'!D14+'단위공사별(집계)'!E14+'단위공사별(집계)'!F14+'단위공사별(집계)'!G14+'단위공사별(집계)'!H14+'단위공사별(집계)'!I14)," ") | G25: =IF('단위공사별(집계)'!N14>0,('단위공사별(집계)'!L14+'단위공사별(집계)'!M14),"") | H25: =IF('단위공사별(집계)'!N14>0,'단위공사별(집계)'!N14,"")
B26: 9 | C26: =IF('단위공사별(집계)'!N15>0,'단위공사별(집계)'!B15,"") | E26: =IF('단위공사별(집계)'!N15>1,('단위공사별(집계)'!D15+'단위공사별(집계)'!E15+'단위공사별(집계)'!F15+'단위공사별(집계)'!G15+'단위공사별(집계)'!H15+'단위공사별(집계)'!I15)," ") | G26: =IF('단위공사별(집계)'!N15>0,('단위공사별(집계)'!L15+'단위공사별(집계)'!M15),"") | H26: =IF('단위공사별(집계)'!N15>0,'단위공사별(집계)'!N15,"")
B27: 10 | C27: =IF('단위공사별(집계)'!N16>0,'단위공사별(집계)'!B16,"") | E27: =IF('단위공사별(집계)'!N16>1,('단위공사별(집계)'!D16+'단위공사별(집계)'!E16+'단위공사별(집계)'!F16+'단위공사별(집계)'!G16+'단위공사별(집계)'!H16+'단위공사별(집계)'!I16)," ") | G27: =IF('단위공사별(집계)'!N16>0,('단위공사별(집계)'!L16+'단위공사별(집계)'!M16),"") | H27: =IF('단위공사별(집계)'!N16>0,'단위공사별(집계)'!N16,"")
B28: 11 | C28: =IF('단위공사별(집계)'!N17>0,'단위공사별(집계)'!B17,"") | E28: =IF('단위공사별(집계)'!N17>1,('단위공사별(집계)'!D17+'단위공사별(집계)'!E17+'단위공사별(집계)'!F17+'단위공사별(집계)'!G17+'단위공사별(집계)'!H17+'단위공사별(집계)'!I17)," ") | G28: =IF('단위공사별(집계)'!N17>0,('단위공사별(집계)'!L17+'단위공사별(집계)'!M17),"") | H28: =IF('단위공사별(집계)'!N17>0,'단위공사별(집계)'!N17,"")
B29: 12 | C29: =IF('단위공사별(집계)'!N18>0,'단위공사별(집계)'!B18,"") | E29: =IF('단위공사별(집계)'!N18>1,('단위공사별(집계)'!D18+'단위공사별(집계)'!E18+'단위공사별(집계)'!F18+'단위공사별(집계)'!G18+'단위공사별(집계)'!H18+'단위공사별(집계)'!I18)," ") | G29: =IF('단위공사별(집계)'!N18>0,('단위공사별(집계)'!L18+'단위공사별(집계)'!M18),"") | H29: =IF('단위공사별(집계)'!N18>0,'단위공사별(집계)'!N18,"")
B30: 13 | C30: =IF('단위공사별(집계)'!N19>0,'단위공사별(집계)'!B19,"") | E30: =IF('단위공사별(집계)'!N19>1,('단위공사별(집계)'!D19+'단위공사별(집계)'!E19+'단위공사별(집계)'!F19+'단위공사별(집계)'!G19+'단위공사별(집계)'!H19+'단위공사별(집계)'!I19)," ") | G30: =IF('단위공사별(집계)'!N19>0,('단위공사별(집계)'!L19+'단위공사별(집계)'!M19),"") | H30: =IF('단위공사별(집계)'!N19>0,'단위공사별(집계)'!N19,"")
... B67: 50 | C67: =IF('단위공사별(집계)'!N56>0,'단위공사별(집계)'!B56,"") | E67: =IF('단위공사별(집계)'!N56>1,('단위공사별(집계)'!D56+'단위공사별(집계)'!E56+'단위공사별(집계)'!F56+'단위공사별(집계)'!G56+'단위공사별(집계)'!H56+'단위공사별(집계)'!I56)," ") | G67: =IF('단위공사별(집계)'!N56>0,('단위공사별(집계)'!L56+'단위공사별(집계)'!M56),"") | H67: =IF('단위공사별(집계)'!N56>0,'단위공사별(집계)'!N56,"")
B68: 견적 합계 | E68: =SUM(E18:E67) -> 488460000 | F68: =SUM(F18:F67) -> 125378750 | G68: =SUM(G18:G67) -> 73203000 | H68: =SUM(H18:H67)-41750 -> 687000000
F70: 공개입찰가 (견적時 공란)
B72: 특기사항 | C72: 1. VAT 제외 | F72: 외주계획 업체명 (자작時 공란)
C73: 2. 기본 유틸리티공사 제외 | F73: 설계외주
F74: 제작외주
F75: 전기외주
F76: 설치외주

Sheet 원가항목별(집계)
C2: A. 원가항목별 견적가 종합(상세견적 첨부)
B4: □ 현대/기아 요구사양과 견적조건 일치여부 CHECK: 1.일치함 2.일부상이(상이내역 첨부참조)
B6: 순번 | C6: 원가구분 | F6: 단위 | G6: 수량 | H6: 단가 | I6: 금 액(원) | J6: 비 고
B7: 1 | C7: 기계 부문 | D7: 자재비 | E7: 철자재(SS.SUS등) | F7: kg | G7: 1 | I7: =SUM(단위장비1:단위장비50!H9) -> 1100000 | J7: 加工必要資材
E8: 일반구매품 | F8: 식 | G8: 1 | I8: =SUM(단위장비1:단위장비50!H47) -> 345460000 | J8: 加工不要資材
E9: 외주제작품 | F9: 식 | G9: 1 | I9: =SUM(단위장비1:단위장비50!H67) -> 81700000 | J9: 旣加工SUB資材
E10: 설치/해체 공사 자재 | F10: 식 | G10: 1 | I10: =SUM(단위장비1:단위장비50!H15) -> 0 | J10: 시운전 자재 포함
E11: 소계 | I11: =SUM(I7:I10) -> 428260000
D12: 노무비 | E12: 기존설비 철거 | F12: M/D | G12: =SUM(단위장비1:단위장비50!F69) -> 10 | H12: =IF(단위장비1!G69>0,단위장비1!G69,"") -> 300000 | I12: =SUM(단위장비1:단위장비50!H69) -> 3000000 | J12: 개조공사時
E13: 설계 | F13: M/D | G13: =SUM(단위장비1:단위장비50!F70) -> 82 | H13: =IF(단위장비1!G70>0,단위장비1!G70,"") -> 350000 | I13: =SUM(단위장비1:단위장비50!H70) -> 28700000
E14: 제작(제관,가공) | F14: M/D | G14: =SUM(단위장비1:단위장비50!F71) -> 52 | H14: =IF(단위장비1!G71>0,단위장비1!G71,"") -> 300000 | I14: =SUM(단위장비1:단위장비50!H71) -> 15600000
E15: 조립 | F15: M/D | G15: =SUM(단위장비1:단위장비50!F72) -> 38 | H15: =IF(단위장비1!G72>0,단위장비1!G72,"") -> 300000 | I15: =SUM(단위장비1:단위장비50!H72) -> 11400000 | J15: 정도검사포함
E16: 설치 | F16: M/D | G16: =SUM(단위장비1:단위장비50!F73) -> 0 | H16: =IF(단위장비1!G73>0,단위장비1!G73,"") -> 300000 | I16: =SUM(단위장비1:단위장비50!H73) -> 0
E17: 시운전 | F17: M/D | G17: =SUM(단위장비1:단위장비50!F74) -> 0 | H17: =IF(단위장비1!G74>0,단위장비1!G74,"") -> 300000 | I17: =SUM(단위장비1:단위장비50!H74) -> 0
E18: 양산대응 | F18: M/D | G18: =SUM(단위장비1:단위장비50!F75) -> 0 | H18: =IF(단위장비1!G75>0,단위장비1!G75,"") -> 300000 | I18: =SUM(단위장비1:단위장비50!H75) -> 0
E19: 도장 | F19: M/D | G19: =SUM(단위장비1:단위장비50!F76) -> 0 | H19: =IF(단위장비1!G76>0,단위장비1!G76,"") -> 300000 | I19: =SUM(단위장비1:단위장비50!H76) -> 0
E20: 소계 | I20: =SUM(I12:I19) -> 58700000
D21: 일반관리 및 이윤 | I21: =(SUM(단위장비1:단위장비50!H79))+(SUM(단위장비1:단위장비50!H80)) -> 73044000
E22: 기계 소계 | I22: =I20+I11+I21 -> 560004000
B23: 2 | C23: 전기 부문 | D23: 자재비 | E23: 기계/전기자재 | F23: 식 | G23: 1 | I23: =전기!H57-I24 -> 63825000
E24: 설치/해체 공사 자재 | F24: 식 | G24: 1 | I24: =전기!H14 -> 0 | J24: 시운전 자재 포함
D25: 노무비 | E25: 철거(개조시) | F25: M/D | G25: =전기!F58 -> 4 | H25: =IF(전기!G58>0,전기!G58,"") -> 300000 | I25: =전기!H58 -> 1200000
E26: 설계,프로그램 | F26: M/D | G26: =전기!F59 -> 100 | H26: =IF(전기!G59>0,전기!G59,"") -> 350000 | I26: =전기!H59 -> 35000000
E27: 제작 | F27: M/D | G27: =전기!F60 -> 10 | H27: =IF(전기!G60>0,전기!G60,"") -> 300000 | I27: =전기!H60 -> 3000000
E28: 조립 | F28: M/D | G28: =전기!F61 -> 20 | H28: =IF(전기!G61>0,전기!G61,"") -> 300000 | I28: =전기!H61 -> 6000000
E29: 설치 | F29: M/D | G29: =전기!F62 -> 0 | H29: =IF(전기!G62>0,전기!G62,"") -> 300000 | I29: =전기!H62 -> 0
E30: 시운전 | F30: M/D | G30: =전기!F63 -> 0 | H30: =IF(전기!G63>0,전기!G63,"") -> 300000 | I30: =전기!H63 -> 0
E31: 양산대응 | F31: M/D | G31: =전기!F64 -> 0 | H31: =IF(전기!G64>0,전기!G64,"") -> 300000 | I31: =전기!H64 -> 0
E32: 소계 | I32: =SUM(I25:I31) -> 45200000
D33: 일반관리 및 이윤 | I33: =전기!H67+전기!H68 -> 16353750
E34: 전기 소계 | I34: =I32+I23+I33+I24 -> 125378750
B35: 3 | C35: 자재비 합계 | I35: =I23+I11+I24 -> 492085000
C36: 노무비 합계 | I36: =I32+I20 -> 103900000
C37: 중간 합계 | I37: =I36+I35 -> 595985000
B38: 4 | C38: 포장,운송 및 중장비 사용료 | I38: 1500000
B39: 5 | C39: 표준안전관리비 | F39: 설치/철거/수리금액 기준 | I39: =CEILING(MIN(I47:I48),1000) -> 159000 | J39: =I30+I29+I25+I24+I17+I16+I12+I10 -> 4200000
B40: 6 | C40: 일반관리비 | I40: =전기!H67+(SUM(단위장비1:단위장비50!H79)) -> 29799250
B41: 7 | C41: 이 윤 | I41: =전기!H68+(SUM(단위장비1:단위장비50!H80)) -> 59598500
C42: 합 계 | F42: 3~7항 합계 | I42: =I22+I34+I38+I39-41750 -> 687000000
B43: 주1. 표준안전관리비:(설치/철거/시운전 공사 관련 금액)의 ⓐ2.66%,ⓑ1.95%+기초액,ⓒ2.02%(50억 이상일경우)
...

Sheet 단위공사별(집계)
A2: B. 단위장비별 견적가 종합(상세견적 첨부)
N3: 단위:원
I5: 포장/운송 | L5: 표준안전 | M5: 일반관리비
A6: 순번 | B6: 단위장비명 | C6: 수량 | D6: 자재비 | E6: 철거 | F6: 제작 | G6: 설치/시운전 | H6: 양산대응 | I6: 중장비사용 | J6: 기계소계 | K6: 전기소계 | L6: 관리비 | M6: 이윤 | N6: 합 계 | O6: 비 고
A7: =IF(B7>0,1,"") -> 1 | B7: =단위장비1!C$1 -> I/RACE GRAD 선별 | C7: 1식 | D7: =단위장비1!H68 -> 6575000 | E7: =단위장비1!H69 -> 600000 | F7: =단위장비1!$H$70+단위장비1!$H$71+단위장비1!$H$72+단위장비1!$H$76 -> 8200000 | G7: =단위장비1!$H$73+단위장비1!$H$74 -> 0 | H7: =단위장비1!H75 -> 0 | I7: =IF($B7>0,'원가항목별(집계)'!I$38*$P7/$P$57,0) -> 47360.153 | J7: =SUM(D7:I7) -> 15422360 | K7: =IF(B7>0,'원가항목별(집계)'!I$34*P7/P$57,0) -> 3958637.8 | L7: =IF($B7>0,'원가항목별(집계)'!I$39*$P7/$P$57,0) -> 5020.1762 | M7: =단위장비1!$H$79+단위장비1!$H$80 -> 2306250 | N7: =SUM(J7:M7) -> 21692268 | P7: =D7+E7+F7+G7+H7+M7 -> 17681250
A8: =IF(B8>0,A7+1,"") -> 2 | B8: =단위장비2!C$1 -> O/RACE GRAD 선별 | C8: 1식 | D8: =단위장비2!H68 -> 75525000 | E8: =단위장비2!H69 -> 600000 | F8: =단위장비2!$H$70+단위장비2!$H$71+단위장비2!$H$72+단위장비2!$H$76 -> 12400000 | G8: =단위장비2!$H$73+단위장비2!$H$74 -> 0 | H8: =단위장비2!H75 -> 0 | I8: =IF($B8>0,'원가항목별(집계)'!I$38*$P8/$P$57,0) -> 272686.67 | J8: =SUM(D8:I8) -> 88797687 | K8: =IF(B8>0,'원가항목별(집계)'!I$34*P8/P$57,0) -> 22792742 | L8: =IF($B8>0,'원가항목별(집계)'!I$39*$P8/$P$57,0) -> 28904.787 | M8: =단위장비2!$H$79+단위장비2!$H$80 -> 13278750 | N8: =SUM(J8:M8) -> 1.2489808e+08 | P8: =D8+E8+F8+G8+H8+M8 -> 101803750
A9: =IF(B9>0,A8+1,"") -> 3 | B9: =단위장비3!C$1 | C9: 1식 | D9: =단위장비3!H68 -> 0 | E9: =단위장비3!H69 -> 0 | F9: =단위장비3!$H$70+단위장비3!$H$71+단위장비3!$H$72+단위장비3!$H$76 -> 0 | G9: =단위장비3!$H$73+단위장비3!$H$74 -> 0 | H9: =단위장비3!H75 -> 0 | I9: =IF($B9>0,'원가항목별(집계)'!I$38*$P9/$P$57,0) -> 0 | J9: =SUM(D9:I9) -> 0 | K9: =IF(B9>0,'원가항목별(집계)'!I$34*P9/P$57,0) -> 0 | L9: =IF($B9>0,'원가항목별(집계)'!I$39*$P9/$P$57,0) -> 0 | M9: =단위장비3!$H$79+단위장비3!$H$80 -> 0 | N9: =SUM(J9:M9) -> 0 | P9: =D9+E9+F9+G9+H9+M9 -> 0
A10: =IF(B10>0,A9+1,"") -> 4 | B10: =단위장비4!C$1 -> 스테킹 MC | C10: 1식 | D10: =단위장비4!H68 -> 19625000 | E10: =단위장비4!H69 -> 900000 | F10: =단위장비4!$H$70+단위장비4!$H$71+단위장비4!$H$72+단위장비4!$H$76 -> 11900000 | G10: =단위장비4!$H$73+단위장비4!$H$74 -> 0 | H10: =단위장비4!H75 -> 0 | I10: =IF($B10>0,'원가항목별(집계)'!I$38*$P10/$P$57,0) -> 99879.867 | J10: =SUM(D10:I10) -> 32524880 | K10: =IF(B10>0,'원가항목별(집계)'!I$34*P10/P$57,0) -> 8348541.9 | L10: =IF($B10>0,'원가항목별(집계)'!I$39*$P10/$P$57,0) -> 10587.266 | M10: =단위장비4!$H$79+단위장비4!$H$80 -> 4863750 | N10: =SUM(J10:M10) -> 45747759 | P10: =D10+E10+F10+G10+H10+M10 -> 37288750
A11: =IF(B11>0,A10+1,"") -> 5 | B11: =단위장비5!C$1 -> CG SUB 조립기 | C11: 1식 | D11: =단위장비5!H68 -> 151585000 | E11: =단위장비5!H69 -> 900000 | F11: =단위장비5!$H$70+단위장비5!$H$71+단위장비5!$H$72+단위장비5!$H$76 -> 23200000 | G11: =단위장비5!$H$73+단위장비5!$H$74 -> 0 | H11: =단위장비5!H75 -> 0 | I11: =IF($B11>0,'원가항목별(집계)'!I$38*$P11/$P$57,0) -> 541168.68 | J11: =SUM(D11:I11) -> 1.7622617e+08 | K11: =IF(B11>0,'원가항목별(집계)'!I$34*P11/P$57,0) -> 45234035 | L11: =IF($B11>0,'원가항목별(집계)'!I$39*$P11/$P$57,0) -> 57363.88 | M11: =단위장비5!$H$79+단위장비5!$H$80 -> 26352750 | N11: =SUM(J11:M11) -> 2.4787032e+08 | P11: =D11+E11+F11+G11+H11+M11 -> 202037750
A12: =IF(B12>0,A11+1,"") -> 6 | B12: =단위장비6!C$1 -> 철거/시운전/현지 설치 및 시운전 | C12: 1식 | D12: =단위장비6!H68 -> 174950000 | E12: =단위장비6!H69 -> 0 | F12: =단위장비6!$H$70+단위장비6!$H$71+단위장비6!$H$72+단위장비6!$H$76 -> 0 | G12: =단위장비6!$H$73+단위장비6!$H$74 -> 0 | H12: =단위장비6!H75 -> 0 | I12: =IF($B12>0,'원가항목별(집계)'!I$38*$P12/$P$57,0) -> 538904.63 | J12: =SUM(D12:I12) -> 1.754889e+08 | K12: =IF(B12>0,'원가항목별(집계)'!I$34*P12/P$57,0) -> 45044793 | L12: =IF($B12>0,'원가항목별(집계)'!I$39*$P12/$P$57,0) -> 57123.891 | M12: =단위장비6!$H$79+단위장비6!$H$80 -> 26242500 | N12: =SUM(J12:M12) -> 2.4683332e+08 | P12: =D12+E12+F12+G12+H12+M12 -> 201192500
A13: =IF(B13>0,A12+1,"") | B13: =단위장비7!C$1 -> 0 | C13: 1식 | D13: =단위장비7!H68 -> 0 | E13: =단위장비7!H69 -> 0 | F13: =단위장비7!$H$70+단위장비7!$H$71+단위장비7!$H$72+단위장비7!$H$76 -> 0 | G13: =단위장비7!$H$73+단위장비7!$H$74 -> 0 | H13: =단위장비7!H75 -> 0 | I13: =IF($B13>0,'원가항목별(집계)'!I$38*$P13/$P$57,0) -> 0 | J13: =SUM(D13:I13) -> 0 | K13: =IF(B13>0,'원가항목별(집계)'!I$34*P13/P$57,0) -> 0 | L13: =IF($B13>0,'원가항목별(집계)'!I$39*$P13/$P$57,0) -> 0 | M13: =단위장비7!$H$79+단위장비7!$H$80 -> 0 | N13: =SUM(J13:M13) -> 0 | P13: =D13+E13+F13+G13+H13+M13 -> 0
A14: =IF(B14>0,A13+1,"") | B14: =단위장비8!C$1 -> 0 | C14: 1식 | D14: =단위장비8!H68 -> 0 | E14: =단위장비8!H69 -> 0 | F14: =단위장비8!$H$70+단위장비8!$H$71+단위장비8!$H$72+단위장비8!$H$76 -> 0 | G14: =단위장비8!$H$73+단위장비8!$H$74 -> 0 | H14: =단위장비8!H75 -> 0 | I14: =IF($B14>0,'원가항목별(집계)'!I$38*$P14/$P$57,0) -> 0 | J14: =SUM(D14:I14) -> 0 | K14: =IF(B14>0,'원가항목별(집계)'!I$34*P14/P$57,0) -> 0 | L14: =IF($B14>0,'원가항목별(집계)'!I$39*$P14/$P$57,0) -> 0 | M14: =단위장비8!$H$79+단위장비8!$H$80 -> 0 | N14: =SUM(J14:M14) -> 0 | P14: =D14+E14+F14+G14+H14+M14 -> 0
A15: =IF(B15>0,A14+1,"") | B15: =단위장비9!C$1 -> 0 | C15: 1식 | D15: =단위장비9!H68 -> 0 | E15: =단위장비9!H69 -> 0 | F15: =단위장비9!$H$70+단위장비9!$H$71+단위장비9!$H$72+단위장비9!$H$76 -> 0 | G15: =단위장비9!$H$73+단위장비9!$H$74 -> 0 | H15: =단위장비9!H75 -> 0 | I15: =IF($B15>0,'원가항목별(집계)'!I$38*$P15/$P$57,0) -> 0 | J15: =SUM(D15:I15) -> 0 | K15: =IF(B15>0,'원가항목별(집계)'!I$34*P15/P$57,0) -> 0 | L15: =IF($B15>0,'원가항목별(집계)'!I$39*$P15/$P$57,0) -> 0 | M15: =단위장비9!$H$79+단위장비9!$H$80 -> 0 | N15: =SUM(J15:M15) -> 0 | P15: =D15+E15+F15+G15+H15+M15 -> 0
A16: =IF(B16>0,A15+1,"") | B16: =단위장비10!C$1 -> 0 | C16: 1식 | D16: =단위장비10!H68 -> 0 | E16: =단위장비10!H69 -> 0 | F16: =단위장비10!$H$70+단위장비10!$H$71+단위장비10!$H$72+단위장비10!$H$76 -> 0 | G16: =단위장비10!$H$73+단위장비10!$H$74 -> 0 | H16: =단위장비10!H75 -> 0 | I16: =IF($B16>0,'원가항목별(집계)'!I$38*$P16/$P$57,0) -> 0 | J16: =SUM(D16:I16) -> 0 | K16: =IF(B16>0,'원가항목별(집계)'!I$34*P16/P$57,0) -> 0 | L16: =IF($B16>0,'원가항목별(집계)'!I$39*$P16/$P$57,0) -> 0 | M16: =단위장비10!$H$79+단위장비10!$H$80 -> 0 | N16: =SUM(J16:M16) -> 0 | P16: =D16+E16+F16+G16+H16+M16 -> 0 | AB16: [
A17: =IF(B17>0,A16+1,"") | B17: =단위장비11!C$1 -> 0 | C17: 1식 | D17: =단위장비11!H68 -> 0 | E17: =단위장비11!H69 -> 0 | F17: =단위장비11!$H$70+단위장비11!$H$71+단위장비11!$H$72+단위장비11!$H$76 -> 0 | G17: =단위장비11!$H$73+단위장비11!$H$74 -> 0 | H17: =단위장비11!H75 -> 0 | I17: =IF($B17>0,'원가항목별(집계)'!I$38*$P17/$P$57,0) -> 0 | J17: =SUM(D17:I17) -> 0 | K17: =IF(B17>0,'원가항목별(집계)'!I$34*P17/P$57,0) -> 0 | L17: =IF($B17>0,'원가항목별(집계)'!I$39*$P17/$P$57,0) -> 0 | M17: =단위장비11!$H$79+단위장비11!$H$80 -> 0 | N17: =SUM(J17:M17) -> 0 | P17: =D17+E17+F17+G17+H17+M17 -> 0
A18: =IF(B18>0,A17+1,"") | B18: =단위장비12!C$1 -> 0 | C18: 1식 | D18: =단위장비12!H68 -> 0 | E18: =단위장비12!H69 -> 0 | F18: =단위장비12!$H$70+단위장비12!$H$71+단위장비12!$H$72+단위장비12!$H$76 -> 0 | G18: =단위장비12!$H$73+단위장비12!$H$74 -> 0 | H18: =단위장비12!H75 -> 0 | I18: =IF($B18>0,'원가항목별(집계)'!I$38*$P18/$P$57,0) -> 0 | J18: =SUM(D18:I18) -> 0 | K18: =IF(B18>0,'원가항목별(집계)'!I$34*P18/P$57,0) -> 0 | L18: =IF($B18>0,'원가항목별(집계)'!I$39*$P18/$P$57,0) -> 0 | M18: =단위장비12!$H$79+단위장비12!$H$80 -> 0 | N18: =SUM(J18:M18) -> 0 | P18: =D18+E18+F18+G18+H18+M18 -> 0
A19: =IF(B19>0,A18+1,"") | B19: =단위장비13!C$1 -> 0 | C19: 1식 | D19: =단위장비13!H68 -> 0 | E19: =단위장비13!H69 -> 0 | F19: =단위장비13!$H$70+단위장비13!$H$71+단위장비13!$H$72+단위장비13!$H$76 -> 0 | G19: =단위장비13!$H$73+단위장비13!$H$74 -> 0 | H19: =단위장비13!H75 -> 0 | I19: =IF($B19>0,'원가항목별(집계)'!I$38*$P19/$P$57,0) -> 0 | J19: =SUM(D19:I19) -> 0 | K19: =IF(B19>0,'원가항목별(집계)'!I$34*P19/P$57,0) -> 0 | L19: =IF($B19>0,'원가항목별(집계)'!I$39*$P19/$P$57,0) -> 0 | M19: =단위장비13!$H$79+단위장비13!$H$80 -> 0 | N19: =SUM(J19:M19) -> 0 | P19: =D19+E19+F19+G19+H19+M19 -> 0
A20: =IF(B20>0,A19+1,"") | B20: =단위장비14!C$1 -> 0 | C20: 1식 | D20: =단위장비14!H68 -> 0 | E20: =단위장비14!H69 -> 0 | F20: =단위장비14!$H$70+단위장비14!$H$71+단위장비14!$H$72+단위장비14!$H$76 -> 0 | G20: =단위장비14!$H$73+단위장비14!$H$74 -> 0 | H20: =단위장비14!H75 -> 0 | I20: =IF($B20>0,'원가항목별(집계)'!I$38*$P20/$P$57,0) -> 0 | J20: =SUM(D20:I20) -> 0 | K20: =IF(B20>0,'원가항목별(집계)'!I$34*P20/P$57,0) -> 0 | L20: =IF($B20>0,'원가항목별(집계)'!I$39*$P20/$P$57,0) -> 0 | M20: =단위장비14!$H$79+단위장비14!$H$80 -> 0 | N20: =SUM(J20:M20) -> 0 | P20: =D20+E20+F20+G20+H20+M20 -> 0
A21: =IF(B21>0,A20+1,"") | B21: =단위장비15!C$1 -> 0 | C21: 1식 | D21: =단위장비15!H68 -> 0 | E21: =단위장비15!H69 -> 0 | F21: =단위장비15!$H$70+단위장비15!$H$71+단위장비15!$H$72+단위장비15!$H$76 -> 0 | G21: =단위장비15!$H$73+단위장비15!$H$74 -> 0 | H21: =단위장비15!H75 -> 0 | I21: =IF($B21>0,'원가항목별(집계)'!I$38*$P21/$P$57,0) -> 0 | J21: =SUM(D21:I21) -> 0 | K21: =IF(B21>0,'원가항목별(집계)'!I$34*P21/P$57,0) -> 0 | L21: =IF($B21>0,'원가항목별(집계)'!I$39*$P21/$P$57,0) -> 0 | M21: =단위장비15!$H$79+단위장비15!$H$80 -> 0 | N21: =SUM(J21:M21) -> 0 | P21: =D21+E21+F21+G21+H21+M21 -> 0
A22: =IF(B22>0,A21+1,"") | B22: =단위장비16!C$1 -> 0 | C22: 1식 | D22: =단위장비16!H68 -> 0 | E22: =단위장비16!H69 -> 0 | F22: =단위장비16!$H$70+단위장비16!$H$71+단위장비16!$H$72+단위장비16!$H$76 -> 0 | G22: =단위장비16!$H$73+단위장비16!$H$74 -> 0 | H22: =단위장비16!H75 -> 0 | I22: =IF($B22>0,'원가항목별(집계)'!I$38*$P22/$P$57,0) -> 0 | J22: =SUM(D22:I22) -> 0 | K22: =IF(B22>0,'원가항목별(집계)'!I$34*P22/P$57,0) -> 0 | L22: =IF($B22>0,'원가항목별(집계)'!I$39*$P22/$P$57,0) -> 0 | M22: =단위장비16!$H$79+단위장비16!$H$80 -> 0 | N22: =SUM(J22:M22) -> 0 | P22: =D22+E22+F22+G22+H22+M22 -> 0
A23: =IF(B23>0,A22+1,"") | B23: =단위장비17!C$1 -> 0 | C23: 1식 | D23: =단위장비17!H68 -> 0 | E23: =단위장비17!H69 -> 0 | F23: =단위장비17!$H$70+단위장비17!$H$71+단위장비17!$H$72+단위장비17!$H$76 -> 0 | G23: =단위장비17!$H$73+단위장비17!$H$74 -> 0 | H23: =단위장비17!H75 -> 0 | I23: =IF($B23>0,'원가항목별(집계)'!I$38*$P23/$P$57,0) -> 0 | J23: =SUM(D23:I23) -> 0 | K23: =IF(B23>0,'원가항목별(집계)'!I$34*P23/P$57,0) -> 0 | L23: =IF($B23>0,'원가항목별(집계)'!I$39*$P23/$P$57,0) -> 0 | M23: =단위장비17!$H$79+단위장비17!$H$80 -> 0 | N23: =SUM(J23:M23) -> 0 | P23: =D23+E23+F23+G23+H23+M23 -> 0
A24: =IF(B24>0,A23+1,"") | B24: =단위장비18!C$1 -> 0 | C24: 1식 | D24: =단위장비18!H68 -> 0 | E24: =단위장비18!H69 -> 0 | F24: =단위장비18!$H$70+단위장비18!$H$71+단위장비18!$H$72+단위장비18!$H$76 -> 0 | G24: =단위장비18!$H$73+단위장비18!$H$74 -> 0 | H24: =단위장비18!H75 -> 0 | I24: =IF($B24>0,'원가항목별(집계)'!I$38*$P24/$P$57,0) -> 0 | J24: =SUM(D24:I24) -> 0 | K24: =IF(B24>0,'원가항목별(집계)'!I$34*P24/P$57,0) -> 0 | L24: =IF($B24>0,'원가항목별(집계)'!I$39*$P24/$P$57,0) -> 0 | M24: =단위장비18!$H$79+단위장비18!$H$80 -> 0 | N24: =SUM(J24:M24) -> 0 | P24: =D24+E24+F24+G24+H24+M24 -> 0
A25: =IF(B25>0,A24+1,"") | B25: =단위장비19!C$1 -> 0 | C25: 1식 | D25: =단위장비19!H68 -> 0 | E25: =단위장비19!H69 -> 0 | F25: =단위장비19!$H$70+단위장비19!$H$71+단위장비19!$H$72+단위장비19!$H$76 -> 0 | G25: =단위장비19!$H$73+단위장비19!$H$74 -> 0 | H25: =단위장비19!H75 -> 0 | I25: =IF($B25>0,'원가항목별(집계)'!I$38*$P25/$P$57,0) -> 0 | J25: =SUM(D25:I25) -> 0 | K25: =IF(B25>0,'원가항목별(집계)'!I$34*P25/P$57,0) -> 0 | L25: =IF($B25>0,'원가항목별(집계)'!I$39*$P25/$P$57,0) -> 0 | M25: =단위장비19!$H$79+단위장비19!$H$80 -> 0 | N25: =SUM(J25:M25) -> 0 | P25: =D25+E25+F25+G25+H25+M25 -> 0
A26: =IF(B26>0,A25+1,"") | B26: =단위장비20!C$1 -> 0 | C26: 1식 | D26: =단위장비20!H68 -> 0 | E26: =단위장비20!H69 -> 0 | F26: =단위장비20!$H$70+단위장비20!$H$71+단위장비20!$H$72+단위장비20!$H$76 -> 0 | G26: =단위장비20!$H$73+단위장비20!$H$74 -> 0 | H26: =단위장비20!H75 -> 0 | I26: =IF($B26>0,'원가항목별(집계)'!I$38*$P26/$P$57,0) -> 0 | J26: =SUM(D26:I26) -> 0 | K26: =IF(B26>0,'원가항목별(집계)'!I$34*P26/P$57,0) -> 0 | L26: =IF($B26>0,'원가항목별(집계)'!I$39*$P26/$P$57,0) -> 0 | M26: =단위장비20!$H$79+단위장비20!$H$80 -> 0 | N26: =SUM(J26:M26) -> 0 | P26: =D26+E26+F26+G26+H26+M26 -> 0
A27: =IF(B27>0,A26+1,"") | B27: =단위장비21!C$1 -> 0 | C27: 1식 | D27: =단위장비21!H68 -> 0 | E27: =단위장비21!H69 -> 0 | F27: =단위장비21!$H$70+단위장비21!$H$71+단위장비21!$H$72+단위장비21!$H$76 -> 0 | G27: =단위장비21!$H$73+단위장비21!$H$74 -> 0 | H27: =단위장비21!H75 -> 0 | I27: =IF($B27>0,'원가항목별(집계)'!I$38*$P27/$P$57,0) -> 0 | J27: =SUM(D27:I27) -> 0 | K27: =IF(B27>0,'원가항목별(집계)'!I$34*P27/P$57,0) -> 0 | L27: =IF($B27>0,'원가항목별(집계)'!I$39*$P27/$P$57,0) -> 0 | M27: =단위장비21!$H$79+단위장비21!$H$80 -> 0 | N27: =SUM(J27:M27) -> 0 | P27: =D27+E27+F27+G27+H27+M27 -> 0
A28: =IF(B28>0,A27+1,"") | B28: =단위장비22!C$1 -> 0 | C28: 1식 | D28: =단위장비22!H68 -> 0 | E28: =단위장비22!H69 -> 0 | F28: =단위장비22!$H$70+단위장비22!$H$71+단위장비22!$H$72+단위장비22!$H$76 -> 0 | G28: =단위장비22!$H$73+단위장비22!$H$74 -> 0 | H28: =단위장비22!H75 -> 0 | I28: =IF($B28>0,'원가항목별(집계)'!I$38*$P28/$P$57,0) -> 0 | J28: =SUM(D28:I28) -> 0 | K28: =IF(B28>0,'원가항목별(집계)'!I$34*P28/P$57,0) -> 0 | L28: =IF($B28>0,'원가항목별(집계)'!I$39*$P28/$P$57,0) -> 0 | M28: =단위장비22!$H$79+단위장비22!$H$80 -> 0 | N28: =SUM(J28:M28) -> 0 | P28: =D28+E28+F28+G28+H28+M28 -> 0
A29: 23 | B29: =단위장비23!C$1 -> 0 | C29: 1식 | D29: =단위장비23!H68 -> 0 | E29: =단위장비23!H69 -> 0 | F29: =단위장비23!$H$70+단위장비23!$H$71+단위장비23!$H$72+단위장비23!$H$76 -> 0 | G29: =단위장비23!$H$73+단위장비23!$H$74 -> 0 | H29: =단위장비23!H75 -> 0 | I29: =IF($B29>0,'원가항목별(집계)'!I$38*$P29/$P$57,0) -> 0 | J29: =SUM(D29:I29) -> 0 | K29: =IF(B29>0,'원가항목별(집계)'!I$34*P29/P$57,0) -> 0 | L29: =IF($B29>0,'원가항목별(집계)'!I$39*$P29/$P$57,0) -> 0 | M29: =단위장비23!$H$79+단위장비23!$H$80 -> 0 | N29: =SUM(J29:M29) -> 0 | P29: =D29+E29+F29+G29+H29+M29 -> 0
A30: 24 | B30: =단위장비24!C$1 -> 0 | C30: 1식 | D30: =단위장비24!H68 -> 0 | E30: =단위장비24!H69 -> 0 | F30: =단위장비24!$H$70+단위장비24!$H$71+단위장비24!$H$72+단위장비24!$H$76 -> 0 | G30: =단위장비24!$H$73+단위장비24!$H$74 -> 0 | H30: =단위장비24!H75 -> 0 | I30: =IF($B30>0,'원가항목별(집계)'!I$38*$P30/$P$57,0) -> 0 | J30: =SUM(D30:I30) -> 0 | K30: =IF(B30>0,'원가항목별(집계)'!I$34*P30/P$57,0) -> 0 | L30: =IF($B30>0,'원가항목별(집계)'!I$39*$P30/$P$57,0) -> 0 | M30: =단위장비24!$H$79+단위장비24!$H$80 -> 0 | N30: =SUM(J30:M30) -> 0 | P30: =D30+E30+F30+G30+H30+M30 -> 0
A31: =IF(B31>0,A30+1,"") | B31: =단위장비25!C$1 -> 0 | C31: 1식 | D31: =단위장비25!H68 -> 0 | E31: =단위장비25!H69 -> 0 | F31: =단위장비25!$H$70+단위장비25!$H$71+단위장비25!$H$72+단위장비25!$H$76 -> 0 | G31: =단위장비25!$H$73+단위장비25!$H$74 -> 0 | H31: =단위장비25!H75 -> 0 | I31: =IF($B31>0,'원가항목별(집계)'!I$38*$P31/$P$57,0) -> 0 | J31: =SUM(D31:I31) -> 0 | K31: =IF(B31>0,'원가항목별(집계)'!I$34*P31/P$57,0) -> 0 | L31: =IF($B31>0,'원가항목별(집계)'!I$39*$P31/$P$57,0) -> 0 | M31: =단위장비25!$H$79+단위장비25!$H$80 -> 0 | N31: =SUM(J31:M31) -> 0 | P31: =D31+E31+F31+G31+H31+M31 -> 0
A32: =IF(B32>0,A31+1,"") | B32: =단위장비26!C$1 -> 0 | C32: 1식 | D32: =단위장비26!H68 -> 0 | E32: =단위장비26!H69 -> 0 | F32: =단위장비26!$H$70+단위장비26!$H$71+단위장비26!$H$72+단위장비26!$H$76 -> 0 | G32: =단위장비26!$H$73+단위장비26!$H$74 -> 0 | H32: =단위장비26!H75 -> 0 | I32: =IF($B32>0,'원가항목별(집계)'!I$38*$P32/$P$57,0) -> 0 | J32: =SUM(D32:I32) -> 0 | K32: =IF(B32>0,'원가항목별(집계)'!I$34*P32/P$57,0) -> 0 | L32: =IF($B32>0,'원가항목별(집계)'!I$39*$P32/$P$57,0) -> 0 | M32: =단위장비26!$H$79+단위장비26!$H$80 -> 0 | N32: =SUM(J32:M32) -> 0 | P32: =D32+E32+F32+G32+H32+M32 -> 0
A33: =IF(B33>0,A32+1,"") | B33: =단위장비27!C$1 -> 0 | C33: 1식 | D33: =단위장비27!H68 -> 0 | E33: =단위장비27!H69 -> 0 | F33: =단위장비27!$H$70+단위장비27!$H$71+단위장비27!$H$72+단위장비27!$H$76 -> 0 | G33: =단위장비27!$H$73+단위장비27!$H$74 -> 0 | H33: =단위장비27!H75 -> 0 | I33: =IF($B33>0,'원가항목별(집계)'!I$38*$P33/$P$57,0) -> 0 | J33: =SUM(D33:I33) -> 0 | K33: =IF(B33>0,'원가항목별(집계)'!I$34*P33/P$57,0) -> 0 | L33: =IF($B33>0,'원가항목별(집계)'!I$39*$P33/$P$57,0) -> 0 | M33: =단위장비27!$H$79+단위장비27!$H$80 -> 0 | N33: =SUM(J33:M33) -> 0 | P33: =D33+E33+F33+G33+H33+M33 -> 0
A34: =IF(B34>0,A33+1,"") | B34: =단위장비28!C$1 -> 0 | C34: 1식 | D34: =단위장비28!H68 -> 0 | E34: =단위장비28!H69 -> 0 | F34: =단위장비28!$H$70+단위장비28!$H$71+단위장비28!$H$72+단위장비28!$H$76 -> 0 | G34: =단위장비28!$H$73+단위장비28!$H$74 -> 0 | H34: =단위장비28!H75 -> 0 | I34: =IF($B34>0,'원가항목별(집계)'!I$38*$P34/$P$57,0) -> 0 | J34: =SUM(D34:I34) -> 0 | K34: =IF(B34>0,'원가항목별(집계)'!I$34*P34/P$57,0) -> 0 | L34: =IF($B34>0,'원가항목별(집계)'!I$39*$P34/$P$57,0) -> 0 | M34: =단위장비28!$H$79+단위장비28!$H$80 -> 0 | N34: =SUM(J34:M34) -> 0 | P34: =D34+E34+F34+G34+H34+M34 -> 0
A35: =IF(B35>0,A34+1,"") | B35: =단위장비29!C$1 -> 0 | C35: 1식 | D35: =단위장비29!H68 -> 0 | E35: =단위장비29!H69 -> 0 | F35: =단위장비29!$H$70+단위장비29!$H$71+단위장비29!$H$72+단위장비29!$H$76 -> 0 | G35: =단위장비29!$H$73+단위장비29!$H$74 -> 0 | H35: =단위장비29!H75 -> 0 | I35: =IF($B35>0,'원가항목별(집계)'!I$38*$P35/$P$57,0) -> 0 | J35: =SUM(D35:I35) -> 0 | K35: =IF(B35>0,'원가항목별(집계)'!I$34*P35/P$57,0) -> 0 | L35: =IF($B35>0,'원가항목별(집계)'!I$39*$P35/$P$57,0) -> 0 | M35: =단위장비29!$H$79+단위장비29!$H$80 -> 0 | N35: =SUM(J35:M35) -> 0 | P35: =D35+E35+F35+G35+H35+M35 -> 0
A36: =IF(B36>0,A35+1,"") | B36: =단위장비30!C$1 -> 0 | C36: 1식 | D36: =단위장비30!H68 -> 0 | E36: =단위장비30!H69 -> 0 | F36: =단위장비30!$H$70+단위장비30!$H$71+단위장비30!$H$72+단위장비30!$H$76 -> 0 | G36: =단위장비30!$H$73+단위장비30!$H$74 -> 0 | H36: =단위장비30!H75 -> 0 | I36: =IF($B36>0,'원가항목별(집계)'!I$38*$P36/$P$57,0) -> 0 | J36: =SUM(D36:I36) -> 0 | K36: =IF(B36>0,'원가항목별(집계)'!I$34*P36/P$57,0) -> 0 | L36: =IF($B36>0,'원가항목별(집계)'!I$39*$P36/$P$57,0) -> 0 | M36: =단위장비30!$H$79+단위장비30!$H$80 -> 0 | N36: =SUM(J36:M36) -> 0 | P36: =D36+E36+F36+G36+H36+M36 -> 0
A37: =IF(B37>0,A36+1,"") | B37: =단위장비31!C$1 -> 0 | C37: 1식 | D37: =단위장비31!H68 -> 0 | E37: =단위장비31!H69 -> 0 | F37: =단위장비31!$H$70+단위장비31!$H$71+단위장비31!$H$72+단위장비31!$H$76 -> 0 | G37: =단위장비31!$H$73+단위장비31!$H$74 -> 0 | H37: =단위장비31!H75 -> 0 | I37: =IF($B37>0,'원가항목별(집계)'!I$38*$P37/$P$57,0) -> 0 | J37: =SUM(D37:I37) -> 0 | K37: =IF(B37>0,'원가항목별(집계)'!I$34*P37/P$57,0) -> 0 | L37: =IF($B37>0,'원가항목별(집계)'!I$39*$P37/$P$57,0) -> 0 | M37: =단위장비31!$H$79+단위장비31!$H$80 -> 0 | N37: =SUM(J37:M37) -> 0 | P37: =D37+E37+F37+G37+H37+M37 -> 0
A38: =IF(B38>0,A37+1,"") | B38: =단위장비32!C$1 -> 0 | C38: 1식 | D38: =단위장비32!H68 -> 0 | E38: =단위장비32!H69 -> 0 | F38: =단위장비32!$H$70+단위장비32!$H$71+단위장비32!$H$72+단위장비32!$H$76 -> 0 | G38: =단위장비32!$H$73+단위장비32!$H$74 -> 0 | H38: =단위장비32!H75 -> 0 | I38: =IF($B38>0,'원가항목별(집계)'!I$38*$P38/$P$57,0) -> 0 | J38: =SUM(D38:I38) -> 0 | K38: =IF(B38>0,'원가항목별(집계)'!I$34*P38/P$57,0) -> 0 | L38: =IF($B38>0,'원가항목별(집계)'!I$39*$P38/$P$57,0) -> 0 | M38: =단위장비32!$H$79+단위장비32!$H$80 -> 0 | N38: =SUM(J38:M38) -> 0 | P38: =D38+E38+F38+G38+H38+M38 -> 0
A39: =IF(B39>0,A38+1,"") | B39: =단위장비33!C$1 -> 0 | C39: 1식 | D39: =단위장비33!H68 -> 0 | E39: =단위장비33!H69 -> 0 | F39: =단위장비33!$H$70+단위장비33!$H$71+단위장비33!$H$72+단위장비33!$H$76 -> 0 | G39: =단위장비33!$H$73+단위장비33!$H$74 -> 0 | H39: =단위장비33!H75 -> 0 | I39: =IF($B39>0,'원가항목별(집계)'!I$38*$P39/$P$57,0) -> 0 | J39: =SUM(D39:I39) -> 0 | K39: =IF(B39>0,'원가항목별(집계)'!I$34*P39/P$57,0) -> 0 | L39: =IF($B39>0,'원가항목별(집계)'!I$39*$P39/$P$57,0) -> 0 | M39: =단위장비33!$H$79+단위장비33!$H$80 -> 0 | N39: =SUM(J39:M39) -> 0 | P39: =D39+E39+F39+G39+H39+M39 -> 0
A40: 34 | B40: =단위장비34!C$1 -> 0 | C40: 1식 | D40: =단위장비34!H68 -> 0 | E40: =단위장비34!H69 -> 0 | F40: =단위장비34!$H$70+단위장비34!$H$71+단위장비34!$H$72+단위장비34!$H$76 -> 0 | G40: =단위장비34!$H$73+단위장비34!$H$74 -> 0 | H40: =단위장비34!H75 -> 0 | I40: =IF($B40>0,'원가항목별(집계)'!I$38*$P40/$P$57,0) -> 0 | J40: =SUM(D40:I40) -> 0 | K40: =IF(B40>0,'원가항목별(집계)'!I$34*P40/P$57,0) -> 0 | L40: =IF($B40>0,'원가항목별(집계)'!I$39*$P40/$P$57,0) -> 0 | M40: =단위장비34!$H$79+단위장비34!$H$80 -> 0 | N40: =SUM(J40:M40) -> 0 | P40: =D40+E40+F40+G40+H40+M40 -> 0
A41: 35 | B41: =단위장비35!C$1 -> 0 | C41: 1식 | D41: =단위장비35!H68 -> 0 | E41: =단위장비35!H69 -> 0 | F41: =단위장비35!$H$70+단위장비35!$H$71+단위장비35!$H$72+단위장비35!$H$76 -> 0 | G41: =단위장비35!$H$73+단위장비35!$H$74 -> 0 | H41: =단위장비35!H75 -> 0 | I41: =IF($B41>0,'원가항목별(집계)'!I$38*$P41/$P$57,0) -> 0 | J41: =SUM(D41:I41) -> 0 | K41: =IF(B41>0,'원가항목별(집계)'!I$34*P41/P$57,0) -> 0 | L41: =IF($B41>0,'원가항목별(집계)'!I$39*$P41/$P$57,0) -> 0 | M41: =단위장비35!$H$79+단위장비35!$H$80 -> 0 | N41: =SUM(J41:M41) -> 0 | P41: =D41+E41+F41+G41+H41+M41 -> 0
A42: 36 | B42: =단위장비36!C$1 -> 0 | C42: 1식 | D42: =단위장비36!H68 -> 0 | E42: =단위장비36!H69 -> 0 | F42: =단위장비36!$H$70+단위장비36!$H$71+단위장비36!$H$72+단위장비36!$H$76 -> 0 | G42: =단위장비36!$H$73+단위장비36!$H$74 -> 0 | H42: =단위장비36!H75 -> 0 | I42: =IF($B42>0,'원가항목별(집계)'!I$38*$P42/$P$57,0) -> 0 | J42: =SUM(D42:I42) -> 0 | K42: =IF(B42>0,'원가항목별(집계)'!I$34*P42/P$57,0) -> 0 | L42: =IF($B42>0,'원가항목별(집계)'!I$39*$P42/$P$57,0) -> 0 | M42: =단위장비36!$H$79+단위장비36!$H$80 -> 0 | N42: =SUM(J42:M42) -> 0 | P42: =D42+E42+F42+G42+H42+M42 -> 0
...

Sheet 전기
B1: □ 전기부문: | C1: 전기부문(공통) | I1: (첨부)
A2: 구분 | C2: 품 명 | D2: 규격 | E2: 단위 | F2: 수량 | G2: 단가(원) | H2: 금액(원) | I2: 原MAKER
A3: 자 재 비 | B3: 철자재 | H3: =IF(F3=0,G3,G3*F3) -> 0
H4: =IF(F4=0,G4,G4*F4) -> 0
H5: =IF(F5=0,G5,G5*F5) -> 0
H6: =IF(F6=0,G6,G6*F6) -> 0
H7: =SUM(H3:H6) -> 0
B8: 설치/해체/ | H8: =IF(F8=0,G8,G8*F8) -> 0
B9: 시운전 공사 | H9: =IF(F9=0,G9,G9*F9) -> 0
B10: 자재 | H10: =IF(F10=0,G10,G10*F10) -> 0
H11: =IF(F11=0,G11,G11*F11) -> 0
H12: =IF(F12=0,G12,G12*F12) -> 0
H13: =IF(F13=0,G13,G13*F13) -> 0
H14: =SUM(H8:H13) -> 0
B15: 전기자재 | C15: HMI | E15: EA | F15: 0 | G15: 1450000 | H15: =G15*F15 -> 0
C16: PLC BASE | E16: 식 | F16: 0 | G16: 255000 | H16: =G16*F16 -> 0
C17: PLC CPU | E17: 식 | F17: 2 | G17: 1550000 | H17: =G17*F17 -> 3100000
C18: PLC COMMUNICATON CARD | D18: E-NET | E18: 식 | F18: 2 | G18: 420000 | H18: =G18*F18 -> 840000
C19: PLC COMMUNICATON CARD | D19: CC-LINK | E19: 식 | F19: 0 | G19: 195000 | H19: =G19*F19 -> 0
C20: PLC COMMUNICATON CARD | D20: RS232C | E20: 식 | F20: 0 | G20: 450000 | H20: =G20*F20 -> 0
C21: PLC COMMUNICATON CARD | D21: COUNT | E21: 식 | F21: 0 | G21: 450000 | H21: =G21*F21 -> 0
C22: PLC 위치결정 CARD | D22: SERVO | E22: 식 | F22: 0 | G22: 1250000 | H22: =G22*F22 -> 0
C23: PLC POWER | E23: 식 | F23: 0 | G23: 215000 | H23: =G23*F23 -> 0
C24: IN PUT I/O CARD | E24: 식 | F24: 2 | G24: 205000 | H24: =G24*F24 -> 410000
C25: OUT PUT I/O CARD | E25: 식 | F25: 2 | G25: 205000 | H25: =G25*F25 -> 410000
C26: REMOTE I/O CARD | E26: 식 | F26: 2 | G26: 155000 | H26: =G26*F26 -> 310000
C27: CIRCUIT PROTECTER | E27: 식 | F27: 3 | G27: 35000 | H27: =G27*F27 -> 105000
C28: HUB | E28: 식 | F28: 0 | G28: 700000 | H28: =G28*F28 -> 0
C29: POWER SUPPLY | E29: 식 | F29: 0 | G29: 350000 | H29: =G29*F29 -> 0
C30: SWITCH | E30: 식 | F30: 1 | G30: 500000 | H30: =G30*F30 -> 500000
C31: AIR CON | E31: 식 | F31: 0 | G31: 2250000 | H31: =G31*F31 -> 0
C32: 조작반 자재류 | E32: 식 | F32: 0 | G32: 1000000 | H32: =G32*F32 -> 0
C33: 제어반 자재류 | E33: 식 | F33: 1 | G33: 1000000 | H33: =G33*F33 -> 1000000
C34: CABLE 류 | E34: 식 | F34: 1 | G34: 3500000 | H34: =G34*F34 -> 3500000
... C36: 기타 구매품 | E36: 식 | F36: 1 | G36: 700000 | H36: =G36*F36 -> 700000
C37: 산업용 공정 PC | D37: 측정/비젼 | E37: 식 | F37: 2 | G37: 3800000 | H37: =G37*F37 -> 7600000
C38: SERVER PC | D38: 통합 데이터 | E38: 식 | F38: 1 | G38: 9200000 | H38: =G38*F38 -> 9200000
C39: 산업용 PC RACK | E39: 식 | F39: 1 | G39: 2350000 | H39: =G39*F39 -> 2350000
C40: RACK AIRCON | E40: 식 | F40: 1 | G40: 1250000 | H40: =G40*F40 -> 1250000
C41: PC UPS | E41: 식 | F41: 1 | G41: 1350000 | H41: =G41*F41 -> 1350000
...

Sheet 단위장비1
B1: □ 단위공사명(전기제외): | C1: I/RACE GRAD 선별 | I1: (첨부)
A2: 구분 | C2: 품 명 | D2: 규격 | E2: 단위 | F2: 수량 | G2: 단가(원) | H2: 금액(원) | I2: 原MAKER
A3: 자 재 비 | B3: 철자재 | C3: FRAME 류 | D3: SS41 | E3: KG | F3: 50 | G3: 1300 | H3: =IF(F3=0,G3,G3*F3) -> 65000
C4: BASE 류 | D4: SS41 | E4: KG | F4: 50 | G4: 2500 | H4: =IF(F4=0,G4,G4*F4) -> 125000
C5: BRACKET 류 | D5: SS41 | E5: KG | F5: 50 | G5: 1300 | H5: =IF(F5=0,G5,G5*F5) -> 65000
C6: 배관 파이프 | E6: LOT | F6: 1 | G6: 20000 | H6: =IF(F6=0,G6,G6*F6) -> 20000
C7: 기타자재 | H7: =IF(F7=0,G7,G7*F7) -> 0
H8: =IF(F8=0,G8,G8*F8) -> 0
H9: =SUM(H3:H8) -> 275000
B10: 설치/해체/시운전 | H10: =IF(F10=0,G10,G10*F10) -> 0
B11: 공사 관련 자재 | H11: =IF(F11=0,G11,G11*F11) -> 0
H12: =IF(F12=0,G12,G12*F12) -> 0
H13: =IF(F13=0,G13,G13*F13) -> 0
H14: =IF(F14=0,G14,G14*F14) -> 0
H15: =SUM(H10:H14) -> 0
B16: 구매품 | C16: SOL VELVE 류 | E16: 식 | F16: 1 | G16: 800000 | H16: =IF(F16=0,G16,G16*F16) -> 800000
B17: (유공압품외) | H17: =IF(F17=0,G17,G17*F17) -> 0
H18: =IF(F18=0,G18,G18*F18) -> 0
H19: =IF(F19=0,G19,G19*F19) -> 0
H20: =IF(F20=0,G20,G20*F20) -> 0
H21: =IF(F21=0,G21,G21*F21) -> 0
H22: =IF(F22=0,G22,G22*F22) -> 0
H23: =IF(F23=0,G23,G23*F23) -> 0
H24: =IF(F24=0,G24,G24*F24) -> 0
H25: =IF(F25=0,G25,G25*F25) -> 0
H26: =IF(F26=0,G26,G26*F26) -> 0
H27: =IF(F27=0,G27,G27*F27) -> 0
H28: =IF(F28=0,G28,G28*F28) -> 0
H29: =IF(F29=0,G29,G29*F29) -> 0
... H46: =IF(F46=0,G46,G46*F46) -> 0
H47: =SUM(H16:H46) -> 800000
B48: 외주제작품 | C48: RACE JIG UNIT | E48: 식 | F48: 1 | G48: 1500000 | H48: =IF(F48=0,G48,G48*F48) -> 1500000
C49: RACE CHECK UNIT | E49: 식 | F49: 1 | G49: 3500000 | H49: =IF(F49=0,G49,G49*F49) -> 3500000
C50: 기타 가공품 | E50: 식 | F50: 1 | G50: 500000 | H50: =IF(F50=0,G50,G50*F50) -> 500000
H51: =IF(F51=0,G51,G51*F51) -> 0
H52: =IF(F52=0,G52,G52*F52) -> 0
H53: =IF(F53=0,G53,G53*F53) -> 0
H54: =IF(F54=0,G54,G54*F54) -> 0
H55: =IF(F55=0,G55,G55*F55) -> 0
H56: =IF(F56=0,G56,G56*F56) -> 0
...

Sheet 단위장비2
B1: □ 단위공사명(전기제외): | C1: O/RACE GRAD 선별 | I1: (첨부)
A2: 구분 | C2: 품 명 | D2: 규격 | E2: 단위 | F2: 수량 | G2: 단가(원) | H2: 금액(원) | I2: 原MAKER
A3: 자 재 비 | B3: 철자재 | C3: FRAME 류 | D3: SS41 | E3: KG | F3: 50 | G3: 1300 | H3: =IF(F3=0,G3,G3*F3) -> 65000
C4: BASE 류 | D4: SS41 | E4: KG | F4: 50 | G4: 2500 | H4: =IF(F4=0,G4,G4*F4) -> 125000
C5: BRACKET 류 | D5: SS41 | E5: KG | F5: 50 | G5: 1300 | H5: =IF(F5=0,G5,G5*F5) -> 65000
C6: 배관 파이프 | E6: LOT | F6: 1 | G6: 20000 | H6: =IF(F6=0,G6,G6*F6) -> 20000
C7: 기타자재 | H7: =IF(F7=0,G7,G7*F7) -> 0
H8: =IF(F8=0,G8,G8*F8) -> 0
H9: =SUM(H3:H8) -> 275000
B10: 설치/해체/시운전 | H10: =IF(F10=0,G10,G10*F10) -> 0
B11: 공사 관련 자재 | H11: =IF(F11=0,G11,G11*F11) -> 0
H12: =IF(F12=0,G12,G12*F12) -> 0
H13: =IF(F13=0,G13,G13*F13) -> 0
H14: =IF(F14=0,G14,G14*F14) -> 0
H15: =SUM(H10:H14) -> 0
B16: 구매품 | C16: AIR CYL' 류 | E16: 식 | F16: 1 | G16: 300000 | H16: =IF(F16=0,G16,G16*F16) -> 300000
B17: (유공압품외) | C17: 직선운동 류 ( LM GUIDE / BALL BUSH ) | E17: 식 | F17: 1 | G17: 500000 | H17: =G17*F17 -> 500000
C18: 회전운동 류 ( BEARING / SPROCKET ) | E18: 식 | F18: 1 | G18: 100000 | H18: =G18*F18 -> 100000
C19: 핸디 바코드 스캐너 | E19: 식 | F19: 2 | G19: 3850000 | H19: =G19*F19 -> 7700000
C20: SOL VELVE 류 | E20: 식 | F20: 1 | G20: 300000 | H20: =G20*F20 -> 300000
C21: LASER MARKING | E21: 식 | F21: 1 | G21: 47500000 | H21: =G21*F21 -> 47500000
C22: SERVO MOTOR & AMP | E22: 식 | F22: 1 | G22: 2300000 | H22: =G22*F22 -> 2300000
C23: BALL SCREW 주변 | E23: 식 | F23: 1 | G23: 750000 | H23: =G23*F23 -> 750000
C24: PRX' SENSOR | E24: 식 | F24: 10 | G24: 35000 | H24: =G24*F24 -> 350000
C25: SENSOR CABLE | E25: 식 | F25: 10 | G25: 15000 | H25: =G25*F25 -> 150000
C26: PHOTO' SENSOR | E26: 식 | F26: 2 | G26: 85000 | H26: =G26*F26 -> 170000
C27: SENSOR CABLE | E27: 식 | F27: 2 | G27: 15000 | H27: =G27*F27 -> 30000
C28: 기타 구매품 | E28: 식 | F28: 1 | G28: 1000000 | H28: =G28*F28 -> 1000000
H29: =G29*F29 -> 0
H30: =IF(F30=0,G30,G30*F30) -> 0
H31: =IF(F31=0,G31,G31*F31) -> 0
H32: =IF(F32=0,G32,G32*F32) -> 0
H33: =IF(F33=0,G33,G33*F33) -> 0
H34: =IF(F34=0,G34,G34*F34) -> 0
H35: =IF(F35=0,G35,G35*F35) -> 0
H36: =IF(F36=0,G36,G36*F36) -> 0
H37: =IF(F37=0,G37,G37*F37) -> 0
H38: =IF(F38=0,G38,G38*F38) -> 0
H39: =IF(F39=0,G39,G39*F39) -> 0
H40: =IF(F40=0,G40,G40*F40) -> 0
...

Sheet 단위장비3
B1: □ 단위공사명(전기제외): | I1: (첨부)
A2: 구분 | C2: 품 명 | D2: 규격 | E2: 단위 | F2: 수량 | G2: 단가(원) | H2: 금액(원) | I2: 原MAKER
A3: 자 재 비 | B3: 철자재 | H3: =IF(F3=0,G3,G3*F3) -> 0
H4: =IF(F4=0,G4,G4*F4) -> 0
H5: =IF(F5=0,G5,G5*F5) -> 0
H6: =IF(F6=0,G6,G6*F6) -> 0
H7: =IF(F7=0,G7,G7*F7) -> 0
H8: =IF(F8=0,G8,G8*F8) -> 0
H9: =SUM(H3:H8) -> 0
B10: 설치/해체/시운전 | H10: =IF(F10=0,G10,G10*F10) -> 0
B11: 공사 관련 자재 | H11: =IF(F11=0,G11,G11*F11) -> 0
H12: =IF(F12=0,G12,G12*F12) -> 0
H13: =IF(F13=0,G13,G13*F13) -> 0
H14: =IF(F14=0,G14,G14*F14) -> 0
H15: =SUM(H10:H14) -> 0
B16: 구매품 | H16: =IF(F16=0,G16,G16*F16) -> 0
B17: (유공압품외) | H17: =G17*F17 -> 0
H18: =IF(F18=0,G18,G18*F18) -> 0
H19: =IF(F19=0,G19,G19*F19) -> 0
H20: =IF(F20=0,G20,G20*F20) -> 0
H21: =G21*F21 -> 0
H22: =G22*F22 -> 0
H23: =G23*F23 -> 0
H24: =G24*F24 -> 0
H25: =G25*F25 -> 0
H26: =G26*F26 -> 0
H27: =G27*F27 -> 0
H28: =G28*F28 -> 0
H29: =G29*F29 -> 0
H30: =G30*F30 -> 0
H31: =G31*F31 -> 0
H32: =G32*F32 -> 0
... H39: =G39*F39 -> 0
H40: =IF(F40=0,G40,G40*F40) -> 0
H41: =IF(F41=0,G41,G41*F41) -> 0
H42: =IF(F42=0,G42,G42*F42) -> 0
H43: =IF(F43=0,G43,G43*F43) -> 0
H44: =IF(F44=0,G44,G44*F44) -> 0
H45: =IF(F45=0,G45,G45*F45) -> 0
H46: =IF(F46=0,G46,G46*F46) -> 0
...

Sheet 단위장비4
B1: □ 단위공사명(전기제외): | C1: 스테킹 MC | I1: (첨부)
A2: 구분 | C2: 품 명 | D2: 규격 | E2: 단위 | F2: 수량 | G2: 단가(원) | H2: 금액(원) | I2: 原MAKER
A3: 자 재 비 | B3: 철자재 | C3: FRAME 류 | D3: SS41 | E3: KG | F3: 50 | G3: 1300 | H3: =IF(F3=0,G3,G3*F3) -> 65000
C4: BASE 류 | D4: SS41 | E4: KG | F4: 50 | G4: 2500 | H4: =IF(F4=0,G4,G4*F4) -> 125000
C5: BRACKET 류 | D5: SS41 | E5: KG | F5: 50 | G5: 1300 | H5: =IF(F5=0,G5,G5*F5) -> 65000
C6: 배관 파이프 | E6: LOT | F6: 1 | G6: 20000 | H6: =IF(F6=0,G6,G6*F6) -> 20000
C7: 기타자재 | H7: =IF(F7=0,G7,G7*F7) -> 0
H8: =IF(F8=0,G8,G8*F8) -> 0
H9: =SUM(H3:H8) -> 275000
B10: 설치/해체/시운전 | H10: =IF(F10=0,G10,G10*F10) -> 0
B11: 공사 관련 자재 | H11: =IF(F11=0,G11,G11*F11) -> 0
H12: =IF(F12=0,G12,G12*F12) -> 0
H13: =IF(F13=0,G13,G13*F13) -> 0
H14: =IF(F14=0,G14,G14*F14) -> 0
H15: =SUM(H10:H14) -> 0
B16: 구매품 | C16: AIR CYL' 류 | E16: 식 | F16: 1 | G16: 1000000 | H16: =IF(F16=0,G16,G16*F16) -> 1000000
B17: (유공압품외) | C17: SERVO MOTOR & AMP | E17: 식 | F17: 1 | G17: 2500000 | H17: =G17*F17 -> 2500000
C18: SERVO REDUCER | E18: 식 | F18: 1 | G18: 750000 | H18: =G18*F18 -> 750000
C19: SERVO PRESS PC & 컨트롤러 | E19: 식 | F19: 1 | G19: 5000000 | H19: =G19*F19 -> 5000000
C20: 기타 구매품 | E20: 식 | F20: 1 | G20: 1200000 | H20: =G20*F20 -> 1200000
H21: =G21*F21 -> 0
H22: =G22*F22 -> 0
H23: =G23*F23 -> 0
H24: =G24*F24 -> 0
H25: =G25*F25 -> 0
H26: =G26*F26 -> 0
H27: =G27*F27 -> 0
H28: =G28*F28 -> 0
H29: =G29*F29 -> 0
H30: =G30*F30 -> 0
H31: =G31*F31 -> 0
H32: =G32*F32 -> 0
... H36: =G36*F36 -> 0
H37: =IF(F37=0,G37,G37*F37) -> 0
H38: =IF(F38=0,G38,G38*F38) -> 0
H39: =IF(F39=0,G39,G39*F39) -> 0
H40: =IF(F40=0,G40,G40*F40) -> 0
H41: =IF(F41=0,G41,G41*F41) -> 0
H42: =IF(F42=0,G42,G42*F42) -> 0
H43: =IF(F43=0,G43,G43*F43) -> 0
...

Sheet 단위장비5
B1: □ 단위공사명(전기제외): | C1: CG SUB 조립기 | I1: (첨부)
A2: 구분 | C2: 품 명 | D2: 규격 | E2: 단위 | F2: 수량 | G2: 단가(원) | H2: 금액(원) | I2: 原MAKER
A3: 자 재 비 | B3: 철자재 | C3: FRAME 류 | D3: SS41 | E3: KG | F3: 50 | G3: 1300 | H3: =IF(F3=0,G3,G3*F3) -> 65000
C4: BASE 류 | D4: SS41 | E4: KG | F4: 50 | G4: 2500 | H4: =IF(F4=0,G4,G4*F4) -> 125000
C5: BRACKET 류 | D5: SS41 | E5: KG | F5: 50 | G5: 1300 | H5: =IF(F5=0,G5,G5*F5) -> 65000
C6: 배관 파이프 | E6: LOT | F6: 1 | G6: 20000 | H6: =IF(F6=0,G6,G6*F6) -> 20000
C7: 기타자재 | H7: =IF(F7=0,G7,G7*F7) -> 0
H8: =IF(F8=0,G8,G8*F8) -> 0
H9: =SUM(H3:H8) -> 275000
B10: 설치/해체/시운전 | H10: =IF(F10=0,G10,G10*F10) -> 0
B11: 공사 관련 자재 | H11: =IF(F11=0,G11,G11*F11) -> 0
H12: =IF(F12=0,G12,G12*F12) -> 0
H13: =IF(F13=0,G13,G13*F13) -> 0
H14: =IF(F14=0,G14,G14*F14) -> 0
H15: =SUM(H10:H14) -> 0
B16: 구매품 | C16: AIR CYL' 류 | E16: 식 | F16: 1 | G16: 1000000 | H16: =IF(F16=0,G16,G16*F16) -> 1000000
B17: (유공압품외) | C17: FINGER CYL' 류 | E17: 식 | F17: 4 | G17: 385000 | H17: =G17*F17 -> 1540000
C18: 직선운동 류 ( LM GUIDE / BALL BUSH ) | E18: 식 | F18: 1 | G18: 4000000 | H18: =G18*F18 -> 4000000
C19: 회전운동 류 ( BEARING / SPROCKET ) | E19: 식 | F19: 1 | G19: 1000000 | H19: =G19*F19 -> 1000000
C20: CHAIN 류 | E20: 식 | F20: 1 | G20: 5500000 | H20: =G20*F20 -> 5500000
C21: 바코드 스캐너 | E21: 식 | F21: 1 | G21: 3850000 | H21: =G21*F21 -> 3850000
C22: 나사검사 UNIT | E22: 식 | F22: 1 | G22: 24800000 | H22: =G22*F22 -> 24800000
C23: 방청 PUMP & TANK SYSTEM | E23: 식 | F23: 1 | G23: 13500000 | H23: =G23*F23 -> 13500000
C24: VISION UNIT | E24: 식 | F24: 1 | G24: 26000000 | H24: =G24*F24 -> 26000000
C25: GEARD MOTOR 류 | E25: 식 | F25: 1 | G25: 700000 | H25: =G25*F25 -> 700000
C26: SERVO MOTOR & AMP | E26: 식 | F26: 1 | G26: 1650000 | H26: =G26*F26 -> 1650000
C27: SERVO REDUCER | E27: 식 | F27: 1 | G27: 750000 | H27: =G27*F27 -> 750000
C28: BALL SCREW & 주변 | E28: 식 | F28: 1 | G28: 850000 | H28: =G28*F28 -> 850000
C29: SERVO PRESS PC & 컨트롤러 | E29: 식 | F29: 1 | G29: 5500000 | H29: =G29*F29 -> 5500000
... C35: PHOTO' SENSOR | E35: 식 | F35: 6 | G35: 85000 | H35: =G35*F35 -> 510000
C36: SENSOR CABLE | E36: 식 | F36: 6 | G36: 15000 | H36: =IF(F36=0,G36,G36*F36) -> 90000
C37: 기타 구매품 | E37: 식 | F37: 1 | G37: 1200000 | H37: =IF(F37=0,G37,G37*F37) -> 1200000
H38: =IF(F38=0,G38,G38*F38) -> 0
H39: =IF(F39=0,G39,G39*F39) -> 0
H40: =IF(F40=0,G40,G40*F40) -> 0
H41: =IF(F41=0,G41,G41*F41) -> 0
H42: =IF(F42=0,G42,G42*F42) -> 0
H43: =IF(F43=0,G43,G43*F43) -> 0
H44: =IF(F44=0,G44,G44*F44) -> 0
H45: =IF(F45=0,G45,G45*F45) -> 0
...

Sheet 단위장비6
B1: □ 단위공사명(전기제외): | C1: 철거/시운전/현지 설치 및 시운전 | I1: (첨부)
A2: 구분 | C2: 품 명 | D2: 규격 | E2: 단위 | F2: 수량 | G2: 단가(원) | H2: 금액(원) | I2: 原MAKER
A3: 자 재 비 | B3: 철자재 | H3: =IF(F3=0,G3,G3*F3) -> 0
H4: =IF(F4=0,G4,G4*F4) -> 0
H5: =IF(F5=0,G5,G5*F5) -> 0
H6: =IF(F6=0,G6,G6*F6) -> 0
H7: =IF(F7=0,G7,G7*F7) -> 0
H8: =IF(F8=0,G8,G8*F8) -> 0
H9: =SUM(H3:H8) -> 0
B10: 설치/해체/시운전 | H10: =IF(F10=0,G10,G10*F10) -> 0
B11: 공사 관련 자재 | H11: =IF(F11=0,G11,G11*F11) -> 0
H12: =IF(F12=0,G12,G12*F12) -> 0
H13: =IF(F13=0,G13,G13*F13) -> 0
H14: =IF(F14=0,G14,G14*F14) -> 0
H15: =SUM(H10:H14) -> 0
B16: 구매품 | H16: =IF(F16=0,G16,G16*F16) -> 0
B17: (유공압품외) | C17: ■ 철거 지원 - 강소법인 출장 | H17: =G17*F17 -> 0
C18: - 기계 | D18: 1人*5日(이동시간2日) | E18: M/D | F18: 7 | G18: 450000 | H18: =G18*F18 -> 3150000
C19: - 전기 | D19: 2人*4日(이동시간2日) | E19: M/D | F19: 8 | G19: 450000 | H19: =G19*F19 -> 3600000
C20: - 항공권 및 경비 | D20: 3人 | E20: 식 | F20: 3 | G20: 1500000 | H20: =G20*F20 -> 4500000
H21: =G21*F21 -> 0
C22: ■ 개조 및 시운전 - 국내 | H22: =G22*F22 -> 0
C23: - 기계 | E23: M/D | F23: 160 | G23: 300000 | H23: =G23*F23 -> 48000000
C24: - 전기 | E24: M/D | F24: 80 | G24: 300000 | H24: =G24*F24 -> 24000000
C25: - PLC | E25: 식 | F25: 60 | G25: 300000 | H25: =G25*F25 -> 18000000
C26: - PC | E26: 식 | F26: 30 | G26: 300000 | H26: =G26*F26 -> 9000000
H27: =G27*F27 -> 0
C28: ■ 인도법인 FOB | H28: =G28*F28 -> 0
C29: - 포장 및 운송 | E29: 식 | F29: 1 | G29: 12000000 | H29: =G29*F29 -> 12000000
H30: =G30*F30 -> 0
C31: ■ 인도법인 설치 및 시운전 | H31: =G31*F31 -> 0
C32: - 기계 | D32: 2人*16日(이동시간2日) | E32: M/D | F32: 32 | G32: 450000 | H32: =G32*F32 -> 14400000
C33: - 전기 ( 결선 ) | D33: 2人*7日(이동시간2日) | E33: M/D | F33: 14 | G33: 450000 | H33: =G33*F33 -> 6300000
C34: - 전기 ( PLC ) | D34: 1人*16日(이동시간2日) | E34: M/D | F34: 16 | G34: 450000 | H34: =G34*F34 -> 7200000
C35: - 항공권 및 경비 | D35: 5人 | E35: 식 | F35: 5 | G35: 2000000 | H35: =G35*F35 -> 10000000
H36: =G36*F36 -> 0
C37: ■ 인도법인 양산대응 | H37: =IF(F37=0,G37,G37*F37) -> 0
C38: - 기계 | D38: 1人*10日(이동시간2日) | E38: M/D | F38: 12 | G38: 450000 | H38: =IF(F38=0,G38,G38*F38) -> 5400000
C39: - 전기 | D39: 1人*10日(이동시간2日) | E39: M/D | F39: 12 | G39: 450000 | H39: =IF(F39=0,G39,G39*F39) -> 5400000
C40: - 항공권 및 경비 | D40: 2人 | E40: 식 | F40: 2 | G40: 2000000 | H40: =IF(F40=0,G40,G40*F40) -> 4000000
...

Sheet 단위장비7
B1: □ 단위공사명(전기제외): | I1: (첨부)
A2: 구분 | C2: 품 명 | D2: 규격 | E2: 단위 | F2: 수량 | G2: 단가(원) | H2: 금액(원) | I2: 原MAKER
A3: 자 재 비 | B3: 철자재 | H3: =IF(F3=0,G3,G3*F3) -> 0
H4: =IF(F4=0,G4,G4*F4) -> 0
H5: =IF(F5=0,G5,G5*F5) -> 0
H6: =IF(F6=0,G6,G6*F6) -> 0
H7: =IF(F7=0,G7,G7*F7) -> 0
H8: =IF(F8=0,G8,G8*F8) -> 0
H9: =SUM(H3:H8) -> 0
B10: 설치/해체/시운전 | H10: =IF(F10=0,G10,G10*F10) -> 0
B11: 공사 관련 자재 | H11: =IF(F11=0,G11,G11*F11) -> 0
H12: =IF(F12=0,G12,G12*F12) -> 0
H13: =IF(F13=0,G13,G13*F13) -> 0
H14: =IF(F14=0,G14,G14*F14) -> 0
H15: =SUM(H10:H14) -> 0
B16: 구매품 | H16: =IF(F16=0,G16,G16*F16) -> 0
B17: (유공압품외) | H17: =G17*F17 -> 0
H18: =G18*F18 -> 0
H19: =G19*F19 -> 0
H20: =G20*F20 -> 0
H21: =G21*F21 -> 0
H22: =G22*F22 -> 0
H23: =G23*F23 -> 0
H24: =G24*F24 -> 0
H25: =G25*F25 -> 0
H26: =G26*F26 -> 0
H27: =G27*F27 -> 0
H28: =G28*F28 -> 0
H29: =G29*F29 -> 0
... H36: =G36*F36 -> 0
H37: =IF(F37=0,G37,G37*F37) -> 0
H38: =IF(F38=0,G38,G38*F38) -> 0
H39: =IF(F39=0,G39,G39*F39) -> 0
H40: =IF(F40=0,G40,G40*F40) -> 0
H41: =IF(F41=0,G41,G41*F41) -> 0
H42: =IF(F42=0,G42,G42*F42) -> 0
H43: =IF(F43=0,G43,G43*F43) -> 0
H44: =IF(F44=0,G44,G44*F44) -> 0
H45: =IF(F45=0,G45,G45*F45) -> 0
H46: =IF(F46=0,G46,G46*F46) -> 0
...

Sheet 단위장비8
B1: □ 단위공사명(전기제외): | I1: (첨부)
A2: 구분 | C2: 품 명 | D2: 규격 | E2: 단위 | F2: 수량 | G2: 단가(원) | H2: 금액(원) | I2: 原MAKER
A3: 자 재 비 | B3: 철자재 | H3: =IF(F3=0,G3,G3*F3) -> 0
H4: =IF(F4=0,G4,G4*F4) -> 0
H5: =IF(F5=0,G5,G5*F5) -> 0
H6: =IF(F6=0,G6,G6*F6) -> 0
H7: =IF(F7=0,G7,G7*F7) -> 0
H8: =IF(F8=0,G8,G8*F8) -> 0
H9: =SUM(H3:H8) -> 0
B10: 설치/해체/시운전 | H10: =IF(F10=0,G10,G10*F10) -> 0
B11: 공사 관련 자재 | H11: =IF(F11=0,G11,G11*F11) -> 0
H12: =IF(F12=0,G12,G12*F12) -> 0
H13: =IF(F13=0,G13,G13*F13) -> 0
H14: =IF(F14=0,G14,G14*F14) -> 0
H15: =SUM(H10:H14) -> 0
B16: 구매품 | H16: =IF(F16=0,G16,G16*F16) -> 0
B17: (유공압품외) | H17: =G17*F17 -> 0
H18: =G18*F18 -> 0
H19: =G19*F19 -> 0
H20: =G20*F20 -> 0
H21: =G21*F21 -> 0
H22: =G22*F22 -> 0
H23: =G23*F23 -> 0
H24: =G24*F24 -> 0
H25: =G25*F25 -> 0
H26: =G26*F26 -> 0
H27: =G27*F27 -> 0
H28: =G28*F28 -> 0
H29: =G29*F29 -> 0
... H35: =G35*F35 -> 0
H36: =IF(F36=0,G36,G36*F36) -> 0
H37: =IF(F37=0,G37,G37*F37) -> 0
H38: =IF(F38=0,G38,G38*F38) -> 0
H39: =IF(F39=0,G39,G39*F39) -> 0
H40: =IF(F40=0,G40,G40*F40) -> 0
H41: =IF(F41=0,G41,G41*F41) -> 0
H42: =IF(F42=0,G42,G42*F42) -> 0
H43: =IF(F43=0,G43,G43*F43) -> 0
H44: =IF(F44=0,G44,G44*F44) -> 0
H45: =IF(F45=0,G45,G45*F45) -> 0
...

Sheet 단위장비9
B1: □ 단위공사명(전기제외): | I1: (첨부)
A2: 구분 | C2: 품 명 | D2: 규격 | E2: 단위 | F2: 수량 | G2: 단가(원) | H2: 금액(원) | I2: 原MAKER
A3: 자 재 비 | B3: 철자재 | H3: =IF(F3=0,G3,G3*F3) -> 0
H4: =IF(F4=0,G4,G4*F4) -> 0
H5: =IF(F5=0,G5,G5*F5) -> 0
H6: =IF(F6=0,G6,G6*F6) -> 0
H7: =IF(F7=0,G7,G7*F7) -> 0
H8: =IF(F8=0,G8,G8*F8) -> 0
H9: =SUM(H3:H8) -> 0
B10: 설치/해체/시운전 | H10: =IF(F10=0,G10,G10*F10) -> 0
B11: 공사 관련 자재 | H11: =IF(F11=0,G11,G11*F11) -> 0
H12: =IF(F12=0,G12,G12*F12) -> 0
H13: =IF(F13=0,G13,G13*F13) -> 0
H14: =IF(F14=0,G14,G14*F14) -> 0
H15: =SUM(H10:H14) -> 0
B16: 구매품 | H16: =IF(F16=0,G16,G16*F16) -> 0
B17: (유공압품외) | H17: =F17*G17 -> 0
H18: =F18*G18 -> 0
H19: =F19*G19 -> 0
H20: =F20*G20 -> 0
H21: =F21*G21 -> 0
H22: =F22*G22 -> 0
H23: =F23*G23 -> 0
H24: =F24*G24 -> 0
H25: =F25*G25 -> 0
H26: =F26*G26 -> 0
H27: =F27*G27 -> 0
H28: =F28*G28 -> 0
H29: =F29*G29 -> 0
... H34: =F34*G34 -> 0
H35: =IF(F35=0,G35,G35*F35) -> 0
H36: =IF(F36=0,G36,G36*F36) -> 0
H37: =IF(F37=0,G37,G37*F37) -> 0
H38: =IF(F38=0,G38,G38*F38) -> 0
H39: =IF(F39=0,G39,G39*F39) -> 0
H40: =IF(F40=0,G40,G40*F40) -> 0
H41: =IF(F41=0,G41,G41*F41) -> 0
H42: =IF(F42=0,G42,G42*F42) -> 0
H43: =IF(F43=0,G43,G43*F43) -> 0
H44: =IF(F44=0,G44,G44*F44) -> 0
...

Sheet 단위장비10
B1: □ 단위공사명(전기제외): | I1: (첨부)
A2: 구분 | C2: 품 명 | D2: 규격 | E2: 단위 | F2: 수량 | G2: 단가(원) | H2: 금액(원) | I2: 原MAKER
A3: 자 재 비 | B3: 철자재 | H3: =IF(F3=0,G3,G3*F3) -> 0
H4: =IF(F4=0,G4,G4*F4) -> 0
H5: =IF(F5=0,G5,G5*F5) -> 0
H6: =IF(F6=0,G6,G6*F6) -> 0
H7: =IF(F7=0,G7,G7*F7) -> 0
H8: =IF(F8=0,G8,G8*F8) -> 0
H9: =SUM(H3:H8) -> 0
B10: 설치/해체/시운전 | H10: =IF(F10=0,G10,G10*F10) -> 0
B11: 공사 관련 자재 | H11: =IF(F11=0,G11,G11*F11) -> 0
H12: =IF(F12=0,G12,G12*F12) -> 0
H13: =IF(F13=0,G13,G13*F13) -> 0
H14: =IF(F14=0,G14,G14*F14) -> 0
H15: =SUM(H10:H14) -> 0
B16: 구매품 | H16: =IF(F16=0,G16,G16*F16) -> 0
B17: (유공압품외) | H17: =G17*F17 -> 0
H18: =G18*F18 -> 0
H19: =G19*F19 -> 0
H20: =G20*F20 -> 0
H21: =G21*F21 -> 0
H22: =G22*F22 -> 0
H23: =G23*F23 -> 0
H24: =G24*F24 -> 0
H25: =G25*F25 -> 0
H26: =G26*F26 -> 0
H27: =G27*F27 -> 0
H28: =G28*F28 -> 0
H29: =G29*F29 -> 0
... H38: =G38*F38 -> 0
H39: =IF(F39=0,G39,G39*F39) -> 0
H40: =IF(F40=0,G40,G40*F40) -> 0
H41: =IF(F41=0,G41,G41*F41) -> 0
H42: =IF(F42=0,G42,G42*F42) -> 0
H43: =IF(F43=0,G43,G43*F43) -> 0
H44: =IF(F44=0,G44,G44*F44) -> 0
H45: =IF(F45=0,G45,G45*F45) -> 0
H46: =IF(F46=0,G46,G46*F46) -> 0
H47: =SUM(H16:H46) -> 0
B48: 외주제작품 | H48: =IF(F48=0,G48,G48*F48) -> 0
...

Sheet 단위장비11
B1: □ 단위공사명(전기제외): | I1: (첨부)
A2: 구분 | C2: 품 명 | D2: 규격 | E2: 단위 | F2: 수량 | G2: 단가(원) | H2: 금액(원) | I2: 原MAKER
A3: 자 재 비 | B3: 철자재 | H3: =IF(F3=0,G3,G3*F3) -> 0
H4: =IF(F4=0,G4,G4*F4) -> 0
H5: =IF(F5=0,G5,G5*F5) -> 0
H6: =IF(F6=0,G6,G6*F6) -> 0
H7: =IF(F7=0,G7,G7*F7) -> 0
H8: =IF(F8=0,G8,G8*F8) -> 0
H9: =SUM(H3:H8) -> 0
B10: 설치/해체/시운전 | H10: =IF(F10=0,G10,G10*F10) -> 0
B11: 공사 관련 자재 | H11: =IF(F11=0,G11,G11*F11) -> 0
H12: =IF(F12=0,G12,G12*F12) -> 0
H13: =IF(F13=0,G13,G13*F13) -> 0
H14: =IF(F14=0,G14,G14*F14) -> 0
H15: =SUM(H10:H14) -> 0
B16: 구매품 | H16: =IF(F16=0,G16,G16*F16) -> 0
B17: (유공압품외) | H17: =G17*F17 -> 0
H18: =G18*F18 -> 0
H19: =G19*F19 -> 0
H20: =G20*F20 -> 0
H21: =G21*F21 -> 0
H22: =G22*F22 -> 0
H23: =G23*F23 -> 0
H24: =G24*F24 -> 0
H25: =G25*F25 -> 0
H26: =G26*F26 -> 0
H27: =G27*F27 -> 0
H28: =G28*F28 -> 0
H29: =G29*F29 -> 0
... H34: =G34*F34 -> 0
H35: =IF(F35=0,G35,G35*F35) -> 0
H36: =IF(F36=0,G36,G36*F36) -> 0
H37: =IF(F37=0,G37,G37*F37) -> 0
H38: =IF(F38=0,G38,G38*F38) -> 0
H39: =IF(F39=0,G39,G39*F39) -> 0
H40: =IF(F40=0,G40,G40*F40) -> 0
H41: =IF(F41=0,G41,G41*F41) -> 0
H42: =IF(F42=0,G42,G42*F42) -> 0
H43: =IF(F43=0,G43,G43*F43) -> 0
H44: =IF(F44=0,G44,G44*F44) -> 0
...

Sheet 단위장비12
B1: □ 단위공사명(전기제외): | I1: (첨부)
A2: 구분 | C2: 품 명 | D2: 규격 | E2: 단위 | F2: 수량 | G2: 단가(원) | H2: 금액(원) | I2: 原MAKER
A3: 자 재 비 | B3: 철자재 | H3: =IF(F3=0,G3,G3*F3) -> 0
H4: =IF(F4=0,G4,G4*F4) -> 0
H5: =IF(F5=0,G5,G5*F5) -> 0
H6: =IF(F6=0,G6,G6*F6) -> 0
H7: =IF(F7=0,G7,G7*F7) -> 0
H8: =IF(F8=0,G8,G8*F8) -> 0
H9: =SUM(H3:H8) -> 0
B10: 설치/해체/시운전 | H10: =IF(F10=0,G10,G10*F10) -> 0
B11: 공사 관련 자재 | H11: =IF(F11=0,G11,G11*F11) -> 0
H12: =IF(F12=0,G12,G12*F12) -> 0
H13: =IF(F13=0,G13,G13*F13) -> 0
H14: =IF(F14=0,G14,G14*F14) -> 0
H15: =SUM(H10:H14) -> 0
B16: 구매품 | H16: =IF(F16=0,G16,G16*F16) -> 0
B17: (유공압품외) | H17: =G17*F17 -> 0
H18: =G18*F18 -> 0
H19: =G19*F19 -> 0
H20: =G20*F20 -> 0
H21: =G21*F21 -> 0
H22: =G22*F22 -> 0
H23: =G23*F23 -> 0
H24: =G24*F24 -> 0
H25: =G25*F25 -> 0
H26: =G26*F26 -> 0
H27: =G27*F27 -> 0
H28: =G28*F28 -> 0
H29: =G29*F29 -> 0
... H36: =G36*F36 -> 0
H37: =IF(F37=0,G37,G37*F37) -> 0
H38: =IF(F38=0,G38,G38*F38) -> 0
H39: =IF(F39=0,G39,G39*F39) -> 0
H40: =IF(F40=0,G40,G40*F40) -> 0
H41: =IF(F41=0,G41,G41*F41) -> 0
H42: =IF(F42=0,G42,G42*F42) -> 0
H43: =IF(F43=0,G43,G43*F43) -> 0
H44: =IF(F44=0,G44,G44*F44) -> 0
H45: =IF(F45=0,G45,G45*F45) -> 0
H46: =IF(F46=0,G46,G46*F46) -> 0
...

Sheet 단위장비13
B1: □ 단위공사명(전기제외): | I1: (첨부)
A2: 구분 | C2: 품 명 | D2: 규격 | E2: 단위 | F2: 수량 | G2: 단가(원) | H2: 금액(원) | I2: 原MAKER
A3: 자 재 비 | B3: 철자재 | H3: =IF(F3=0,G3,G3*F3) -> 0
H4: =IF(F4=0,G4,G4*F4) -> 0
H5: =IF(F5=0,G5,G5*F5) -> 0
H6: =IF(F6=0,G6,G6*F6) -> 0
H7: =IF(F7=0,G7,G7*F7) -> 0
H8: =IF(F8=0,G8,G8*F8) -> 0
H9: =SUM(H3:H8) -> 0
B10: 설치/해체/시운전 | H10: =IF(F10=0,G10,G10*F10) -> 0
B11: 공사 관련 자재 | H11: =IF(F11=0,G11,G11*F11) -> 0
H12: =IF(F12=0,G12,G12*F12) -> 0
H13: =IF(F13=0,G13,G13*F13) -> 0
H14: =IF(F14=0,G14,G14*F14) -> 0
H15: =SUM(H10:H14) -> 0
B16: 구매품 | H16: =IF(F16=0,G16,G16*F16) -> 0
B17: (유공압품외) | H17: =G17*F17 -> 0
H18: =G18*F18 -> 0
H19: =G19*F19 -> 0
H20: =G20*F20 -> 0
H21: =G21*F21 -> 0
H22: =G22*F22 -> 0
H23: =G23*F23 -> 0
H24: =G24*F24 -> 0
H25: =G25*F25 -> 0
H26: =G26*F26 -> 0
H27: =G27*F27 -> 0
H28: =G28*F28 -> 0
H29: =G29*F29 -> 0
... H38: =G38*F38 -> 0
H39: =IF(F39=0,G39,G39*F39) -> 0
H40: =IF(F40=0,G40,G40*F40) -> 0
H41: =IF(F41=0,G41,G41*F41) -> 0
H42: =IF(F42=0,G42,G42*F42) -> 0
H43: =IF(F43=0,G43,G43*F43) -> 0
H44: =IF(F44=0,G44,G44*F44) -> 0
H45: =IF(F45=0,G45,G45*F45) -> 0
H46: =IF(F46=0,G46,G46*F46) -> 0
H47: =SUM(H16:H46) -> 0
B48: 외주제작품 | H48: =IF(F48=0,G48,G48*F48) -> 0
...

Sheet 단위장비14
B1: □ 단위공사명(전기제외): | I1: (첨부)
A2: 구분 | C2: 품 명 | D2: 규격 | E2: 단위 | F2: 수량 | G2: 단가(원) | H2: 금액(원) | I2: 原MAKER
A3: 자 재 비 | B3: 철자재 | H3: =IF(F3=0,G3,G3*F3) -> 0
H4: =IF(F4=0,G4,G4*F4) -> 0
H5: =IF(F5=0,G5,G5*F5) -> 0
H6: =IF(F6=0,G6,G6*F6) -> 0
H7: =IF(F7=0,G7,G7*F7) -> 0
H8: =IF(F8=0,G8,G8*F8) -> 0
H9: =SUM(H3:H8) -> 0
B10: 설치/해체/시운전 | H10: =IF(F10=0,G10,G10*F10) -> 0
B11: 공사 관련 자재 | H11: =IF(F11=0,G11,G11*F11) -> 0
H12: =IF(F12=0,G12,G12*F12) -> 0
H13: =IF(F13=0,G13,G13*F13) -> 0
H14: =IF(F14=0,G14,G14*F14) -> 0
H15: =SUM(H10:H14) -> 0
B16: 구매품 | H16: =IF(F16=0,G16,G16*F16) -> 0
B17: (유공압품외) | H17: =G17*F17 -> 0
H18: =G18*F18 -> 0
H19: =G19*F19 -> 0
H20: =G20*F20 -> 0
H21: =G21*F21 -> 0
H22: =G22*F22 -> 0
H23: =G23*F23 -> 0
H24: =G24*F24 -> 0
H25: =G25*F25 -> 0
H26: =G26*F26 -> 0
H27: =G27*F27 -> 0
H28: =G28*F28 -> 0
H29: =G29*F29 -> 0
... H36: =G36*F36 -> 0
H37: =IF(F37=0,G37,G37*F37) -> 0
H38: =IF(F38=0,G38,G38*F38) -> 0
H39: =IF(F39=0,G39,G39*F39) -> 0
H40: =IF(F40=0,G40,G40*F40) -> 0
H41: =IF(F41=0,G41,G41*F41) -> 0
H42: =IF(F42=0,G42,G42*F42) -> 0
H43: =IF(F43=0,G43,G43*F43) -> 0
H44: =IF(F44=0,G44,G44*F44) -> 0
H45: =IF(F45=0,G45,G45*F45) -> 0
H46: =IF(F46=0,G46,G46*F46) -> 0
...

Sheet 단위장비15
B1: □ 단위공사명(전기제외): | I1: (첨부)
A2: 구분 | C2: 품 명 | D2: 규격 | E2: 단위 | F2: 수량 | G2: 단가(원) | H2: 금액(원) | I2: 原MAKER
A3: 자 재 비 | B3: 철자재 | H3: =IF(F3=0,G3,G3*F3) -> 0
H4: =IF(F4=0,G4,G4*F4) -> 0
H5: =IF(F5=0,G5,G5*F5) -> 0
H6: =IF(F6=0,G6,G6*F6) -> 0
H7: =IF(F7=0,G7,G7*F7) -> 0
H8: =IF(F8=0,G8,G8*F8) -> 0
H9: =SUM(H3:H8) -> 0
B10: 설치/해체/시운전 | H10: =IF(F10=0,G10,G10*F10) -> 0
B11: 공사 관련 자재 | H11: =IF(F11=0,G11,G11*F11) -> 0
H12: =IF(F12=0,G12,G12*F12) -> 0
H13: =IF(F13=0,G13,G13*F13) -> 0
H14: =IF(F14=0,G14,G14*F14) -> 0
H15: =SUM(H10:H14) -> 0
B16: 구매품 | H16: =IF(F16=0,G16,G16*F16) -> 0
B17: (유공압품외) | H17: =G17*F17 -> 0
H18: =G18*F18 -> 0
H19: =G19*F19 -> 0
H20: =G20*F20 -> 0
H21: =G21*F21 -> 0
H22: =G22*F22 -> 0
H23: =G23*F23 -> 0
H24: =G24*F24 -> 0
H25: =G25*F25 -> 0
H26: =G26*F26 -> 0
H27: =G27*F27 -> 0
H28: =G28*F28 -> 0
H29: =G29*F29 -> 0
... H36: =G36*F36 -> 0
H37: =IF(F37=0,G37,G37*F37) -> 0
H38: =IF(F38=0,G38,G38*F38) -> 0
H39: =IF(F39=0,G39,G39*F39) -> 0
H40: =IF(F40=0,G40,G40*F40) -> 0
H41: =IF(F41=0,G41,G41*F41) -> 0
H42: =IF(F42=0,G42,G42*F42) -> 0
H43: =IF(F43=0,G43,G43*F43) -> 0
H44: =IF(F44=0,G44,G44*F44) -> 0
H45: =IF(F45=0,G45,G45*F45) -> 0
H46: =IF(F46=0,G46,G46*F46) -> 0
...

Sheet 단위장비16
B1: □ 단위공사명(전기제외): | I1: (첨부)
A2: 구분 | C2: 품 명 | D2: 규격 | E2: 단위 | F2: 수량 | G2: 단가(원) | H2: 금액(원) | I2: 原MAKER
A3: 자 재 비 | B3: 철자재 | H3: =IF(F3=0,G3,G3*F3) -> 0
H4: =IF(F4=0,G4,G4*F4) -> 0
H5: =IF(F5=0,G5,G5*F5) -> 0
H6: =IF(F6=0,G6,G6*F6) -> 0
H7: =IF(F7=0,G7,G7*F7) -> 0
H8: =IF(F8=0,G8,G8*F8) -> 0
H9: =SUM(H3:H8) -> 0
B10: 설치/해체/시운전 | H10: =IF(F10=0,G10,G10*F10) -> 0
B11: 공사 관련 자재 | H11: =IF(F11=0,G11,G11*F11) -> 0
H12: =IF(F12=0,G12,G12*F12) -> 0
H13: =IF(F13=0,G13,G13*F13) -> 0
H14: =IF(F14=0,G14,G14*F14) -> 0
H15: =SUM(H10:H14) -> 0
B16: 구매품 | H16: =IF(F16=0,G16,G16*F16) -> 0
B17: (유공압품외) | H17: =G17*F17 -> 0
H18: =G18*F18 -> 0
H19: =G19*F19 -> 0
H20: =G20*F20 -> 0
H21: =G21*F21 -> 0
H22: =G22*F22 -> 0
H23: =G23*F23 -> 0
H24: =G24*F24 -> 0
H25: =G25*F25 -> 0
H26: =G26*F26 -> 0
H27: =G27*F27 -> 0
H28: =G28*F28 -> 0
H29: =G29*F29 -> 0
... H38: =G38*F38 -> 0
H39: =IF(F39=0,G39,G39*F39) -> 0
H40: =IF(F40=0,G40,G40*F40) -> 0
H41: =IF(F41=0,G41,G41*F41) -> 0
H42: =IF(F42=0,G42,G42*F42) -> 0
H43: =IF(F43=0,G43,G43*F43) -> 0
H44: =IF(F44=0,G44,G44*F44) -> 0
H45: =IF(F45=0,G45,G45*F45) -> 0
H46: =IF(F46=0,G46,G46*F46) -> 0
H47: =SUM(H16:H46) -> 0
B48: 외주제작품 | H48: =IF(F48=0,G48,G48*F48) -> 0
...

Sheet 단위장비17
B1: □ 단위공사명(전기제외): | I1: (첨부)
A2: 구분 | C2: 품 명 | D2: 규격 | E2: 단위 | F2: 수량 | G2: 단가(원) | H2: 금액(원) | I2: 原MAKER
A3: 자 재 비 | B3: 철자재 | H3: =IF(F3=0,G3,G3*F3) -> 0
H4: =IF(F4=0,G4,G4*F4) -> 0
H5: =IF(F5=0,G5,G5*F5) -> 0
H6: =IF(F6=0,G6,G6*F6) -> 0
H7: =IF(F7=0,G7,G7*F7) -> 0
H8: =IF(F8=0,G8,G8*F8) -> 0
H9: =SUM(H3:H8) -> 0
B10: 설치/해체/시운전 | H10: =IF(F10=0,G10,G10*F10) -> 0
B11: 공사 관련 자재 | H11: =IF(F11=0,G11,G11*F11) -> 0
H12: =IF(F12=0,G12,G12*F12) -> 0
H13: =IF(F13=0,G13,G13*F13) -> 0
H14: =IF(F14=0,G14,G14*F14) -> 0
H15: =SUM(H10:H14) -> 0
B16: 구매품 | H16: =IF(F16=0,G16,G16*F16) -> 0
B17: (유공압품외) | H17: =F17*G17 -> 0
H18: =IF(F18=0,G18,G18*F18) -> 0
H19: =IF(F19=0,G19,G19*F19) -> 0
H20: =F20*G20 -> 0
H21: =F21*G21 -> 0
H22: =F22*G22 -> 0
H23: =F23*G23 -> 0
H24: =F24*G24 -> 0
H25: =F25*G25 -> 0
H26: =F26*G26 -> 0
H27: =F27*G27 -> 0
H28: =F28*G28 -> 0
H29: =F29*G29 -> 0
H30: =F30*G30 -> 0
H31: =F31*G31 -> 0
... H36: =F36*G36 -> 0
H37: =IF(F37=0,G37,G37*F37) -> 0
H38: =IF(F38=0,G38,G38*F38) -> 0
H39: =IF(F39=0,G39,G39*F39) -> 0
H40: =IF(F40=0,G40,G40*F40) -> 0
H41: =IF(F41=0,G41,G41*F41) -> 0
H42: =IF(F42=0,G42,G42*F42) -> 0
H43: =IF(F43=0,G43,G43*F43) -> 0
H44: =IF(F44=0,G44,G44*F44) -> 0
...

Sheet 단위장비18
B1: □ 단위공사명(전기제외): | I1: (첨부)
A2: 구분 | C2: 품 명 | D2: 규격 | E2: 단위 | F2: 수량 | G2: 단가(원) | H2: 금액(원) | I2: 原MAKER
A3: 자 재 비 | B3: 철자재 | H3: =IF(F3=0,G3,G3*F3) -> 0
H4: =IF(F4=0,G4,G4*F4) -> 0
H5: =IF(F5=0,G5,G5*F5) -> 0
H6: =IF(F6=0,G6,G6*F6) -> 0
H7: =IF(F7=0,G7,G7*F7) -> 0
H8: =IF(F8=0,G8,G8*F8) -> 0
H9: =SUM(H3:H8) -> 0
B10: 설치/해체/시운전 | H10: =IF(F10=0,G10,G10*F10) -> 0
B11: 공사 관련 자재 | H11: =IF(F11=0,G11,G11*F11) -> 0
H12: =IF(F12=0,G12,G12*F12) -> 0
H13: =IF(F13=0,G13,G13*F13) -> 0
H14: =IF(F14=0,G14,G14*F14) -> 0
H15: =SUM(H10:H14) -> 0
B16: 구매품 | H16: =IF(F16=0,G16,G16*F16) -> 0
B17: (유공압품외) | H17: =G17*F17 -> 0
H18: =G18*F18 -> 0
H19: =G19*F19 -> 0
H20: =G20*F20 -> 0
H21: =G21*F21 -> 0
H22: =G22*F22 -> 0
H23: =G23*F23 -> 0
H24: =G24*F24 -> 0
H25: =G25*F25 -> 0
H26: =G26*F26 -> 0
H27: =G27*F27 -> 0
H28: =G28*F28 -> 0
H29: =G29*F29 -> 0
... H38: =G38*F38 -> 0
H39: =IF(F39=0,G39,G39*F39) -> 0
H40: =IF(F40=0,G40,G40*F40) -> 0
H41: =IF(F41=0,G41,G41*F41) -> 0
H42: =IF(F42=0,G42,G42*F42) -> 0
H43: =IF(F43=0,G43,G43*F43) -> 0
H44: =IF(F44=0,G44,G44*F44) -> 0
H45: =IF(F45=0,G45,G45*F45) -> 0
H46: =IF(F46=0,G46,G46*F46) -> 0
H47: =SUM(H16:H46) -> 0
B48: 외주제작품 | H48: =IF(F48=0,G48,G48*F48) -> 0
...

Sheet 단위장비19
B1: □ 단위공사명(전기제외): | I1: (첨부)
A2: 구분 | C2: 품 명 | D2: 규격 | E2: 단위 | F2: 수량 | G2: 단가(원) | H2: 금액(원) | I2: 原MAKER
A3: 자 재 비 | B3: 철자재 | H3: =IF(F3=0,G3,G3*F3) -> 0
H4: =IF(F4=0,G4,G4*F4) -> 0
H5: =IF(F5=0,G5,G5*F5) -> 0
H6: =IF(F6=0,G6,G6*F6) -> 0
H7: =IF(F7=0,G7,G7*F7) -> 0
H8: =IF(F8=0,G8,G8*F8) -> 0
H9: =SUM(H3:H8) -> 0
B10: 설치/해체/시운전 | H10: =IF(F10=0,G10,G10*F10) -> 0
B11: 공사 관련 자재 | H11: =IF(F11=0,G11,G11*F11) -> 0
H12: =IF(F12=0,G12,G12*F12) -> 0
H13: =IF(F13=0,G13,G13*F13) -> 0
H14: =IF(F14=0,G14,G14*F14) -> 0
H15: =SUM(H10:H14) -> 0
B16: 구매품 | H16: =IF(F16=0,G16,G16*F16) -> 0
B17: (유공압품외) | H17: =G17*F17 -> 0
H18: =G18*F18 -> 0
H19: =G19*F19 -> 0
H20: =G20*F20 -> 0
H21: =G21*F21 -> 0
H22: =G22*F22 -> 0
H23: =G23*F23 -> 0
H24: =G24*F24 -> 0
H25: =G25*F25 -> 0
H26: =G26*F26 -> 0
H27: =G27*F27 -> 0
H28: =G28*F28 -> 0
H29: =G29*F29 -> 0
... H37: =G37*F37 -> 0
H38: =IF(F38=0,G38,G38*F38) -> 0
H39: =IF(F39=0,G39,G39*F39) -> 0
H40: =IF(F40=0,G40,G40*F40) -> 0
H41: =IF(F41=0,G41,G41*F41) -> 0
H42: =IF(F42=0,G42,G42*F42) -> 0
H43: =IF(F43=0,G43,G43*F43) -> 0
H44: =IF(F44=0,G44,G44*F44) -> 0
H45: =IF(F45=0,G45,G45*F45) -> 0
H46: =IF(F46=0,G46,G46*F46) -> 0
H47: =SUM(H16:H46) -> 0
...

Sheet 단위장비20
B1: □ 단위공사명(전기제외): | I1: (첨부)
A2: 구분 | C2: 품 명 | D2: 규격 | E2: 단위 | F2: 수량 | G2: 단가(원) | H2: 금액(원) | I2: 原MAKER
A3: 자 재 비 | B3: 철자재 | H3: =IF(F3=0,G3,G3*F3) -> 0
H4: =IF(F4=0,G4,G4*F4) -> 0
H5: =IF(F5=0,G5,G5*F5) -> 0
H6: =IF(F6=0,G6,G6*F6) -> 0
H7: =IF(F7=0,G7,G7*F7) -> 0
H8: =IF(F8=0,G8,G8*F8) -> 0
H9: =SUM(H3:H8) -> 0
B10: 설치/해체/시운전 | H10: =IF(F10=0,G10,G10*F10) -> 0
B11: 공사 관련 자재 | H11: =IF(F11=0,G11,G11*F11) -> 0
H12: =IF(F12=0,G12,G12*F12) -> 0
H13: =IF(F13=0,G13,G13*F13) -> 0
H14: =IF(F14=0,G14,G14*F14) -> 0
H15: =SUM(H10:H14) -> 0
B16: 구매품 | H16: =IF(F16=0,G16,G16*F16) -> 0
B17: (유공압품외) | H17: =G17*F17 -> 0
H18: =G18*F18 -> 0
H19: =G19*F19 -> 0
H20: =G20*F20 -> 0
H21: =G21*F21 -> 0
H22: =G22*F22 -> 0
H23: =G23*F23 -> 0
H24: =G24*F24 -> 0
H25: =G25*F25 -> 0
H26: =G26*F26 -> 0
H27: =G27*F27 -> 0
H28: =G28*F28 -> 0
H29: =G29*F29 -> 0
... H36: =G36*F36 -> 0
H37: =IF(F37=0,G37,G37*F37) -> 0
H38: =IF(F38=0,G38,G38*F38) -> 0
H39: =IF(F39=0,G39,G39*F39) -> 0
H40: =IF(F40=0,G40,G40*F40) -> 0
H41: =IF(F41=0,G41,G41*F41) -> 0
H42: =IF(F42=0,G42,G42*F42) -> 0
H43: =IF(F43=0,G43,G43*F43) -> 0
H44: =IF(F44=0,G44,G44*F44) -> 0
H45: =IF(F45=0,G45,G45*F45) -> 0
H46: =IF(F46=0,G46,G46*F46) -> 0
...

Sheet 단위장비21
B1: □ 단위공사명(전기제외): | I1: (첨부)
